ts_recv,ts_event,rtype,publisher_id,instrument_id,action,side,depth,price,size,flags,ts_in_delta,sequence,bid_px_00,bid_sz_00,bid_ct_00,ask_px_00,ask_sz_00,ask_ct_00,bid_px_01,bid_sz_01,bid_ct_01,ask_px_01,ask_sz_01,ask_ct_01,bid_px_02,bid_sz_02,bid_ct_02,ask_px_02,ask_sz_02,ask_ct_02,bid_px_03,bid_sz_03,bid_ct_03,ask_px_03,ask_sz_03,ask_ct_03,bid_px_04,bid_sz_04,bid_ct_04,ask_px_04,ask_sz_04,ask_ct_04,bid_px_05,bid_sz_05,bid_ct_05,ask_px_05,ask_sz_05,ask_ct_05,bid_px_06,bid_sz_06,bid_ct_06,ask_px_06,ask_sz_06,ask_ct_06,bid_px_07,bid_sz_07,bid_ct_07,ask_px_07,ask_sz_07,ask_ct_07,bid_px_08,bid_sz_08,bid_ct_08,ask_px_08,ask_sz_08,ask_ct_08,bid_px_09,bid_sz_09,bid_ct_09,ask_px_09,ask_sz_09,ask_ct_09,symbol,order_id
2025-07-17T14:02:01.157986499Z,2025-07-17T14:02:01.157820985Z,160,2,1108,A,A,10,13.40,0,0,13.40,23,1,13.26,2,1,14.36,2,1,13.11,100,1,14.51,100,1,12.99,100,1,14.59,100,1,12.73,100,1,14.83,100,1,12.67,100,1,14.87,100,1,12.51,200,2,14.95,700,1,12.47,100,1,14.99,700,1,12.46,100,1,15.07,700,1,12.43,700,1,15.09,100,1,ARL,121098341
2025-07-17T14:02:01.283528838Z,2025-07-17T14:02:01.283363185Z,160,2,1108,C,B,10,13.40,0,0,13.40,23,1,13.26,2,1,14.36,2,1,12.99,100,1,14.51,100,1,12.73,100,1,14.59,100,1,12.67,100,1,14.83,100,1,12.51,200,2,14.87,100,1,12.47,100,1,14.95,700,1,12.46,100,1,14.99,700,1,12.43,700,1,15.07,700,1,12.42,700,1,15.09,100,1,ARL,115813253
2025-07-17T14:02:01.283528838Z,2025-07-17T14:02:01.283363185Z,160,2,1108,A,B,10,13.40,0,0,13.40,23,1,13.26,2,1,14.36,2,1,13.25,100,1,14.51,100,1,12.99,100,1,14.59,100,1,12.73,100,1,14.83,100,1,12.67,100,1,14.87,100,1,12.51,200,2,14.95,700,1,12.47,100,1,14.99,700,1,12.46,100,1,15.07,700,1,12.43,700,1,15.09,100,1,ARL,121107957
2025-07-17T14:02:01.283544588Z,2025-07-17T14:02:01.283378637Z,160,2,1108,C,A,10,13.40,0,0,13.40,23,1,13.26,2,1,14.36,2,1,13.25,100,1,14.59,100,1,12.99,100,1,14.83,100,1,12.73,100,1,14.87,100,1,12.67,100,1,14.95,700,1,12.51,200,2,14.99,700,1,12.47,100,1,15.07,700,1,12.46,100,1,15.09,100,1,12.43,700,1,15.14,700,1,ARL,115813261
2025-07-17T14:02:01.283544588Z,2025-07-17T14:02:01.283378637Z,160,2,1108,A,A,10,13.40,0,0,13.40,23,1,13.26,2,1,14.36,2,1,13.25,100,1,14.37,100,1,12.99,100,1,14.59,100,1,12.73,100,1,14.83,100,1,12.67,100,1,14.87,100,1,12.51,200,2,14.95,700,1,12.47,100,1,14.99,700,1,12.46,100,1,15.07,700,1,12.43,700,1,15.09,100,1,ARL,121107961
2025-07-17T14:04:21.248906318Z,2025-07-17T14:04:21.248740930Z,160,2,1108,A,A,10,13.40,0,0,13.40,23,1,13.26,2,1,14.35,1,1,13.25,100,1,14.36,2,1,12.99,100,1,14.37,100,1,12.73,100,1,14.59,100,1,12.67,100,1,14.83,100,1,12.51,200,2,14.87,100,1,12.47,100,1,14.95,700,1,12.46,100,1,14.99,700,1,12.43,700,1,15.07,700,1,ARL,126872197
2025-07-17T14:04:21.250325900Z,2025-07-17T14:04:21.250160548Z,160,2,1108,C,B,10,13.40,0,0,13.40,23,1,13.26,2,1,14.35,1,1,13.25,100,1,14.36,2,1,12.99,100,1,14.37,100,1,12.73,100,1,14.59,100,1,12.67,100,1,14.83,100,1,12.51,100,1,14.87,100,1,12.47,100,1,14.95,700,1,12.46,100,1,14.99,700,1,12.43,700,1,15.07,700,1,ARL,115474357
2025-07-17T14:04:21.250325900Z,2025-07-17T14:04:21.250160548Z,160,2,1108,A,B,10,13.40,0,0,13.40,23,1,13.26,2,1,14.35,1,1,13.25,100,1,14.36,2,1,12.99,100,1,14.37,100,1,12.73,100,1,14.59,100,1,12.67,100,1,14.83,100,1,12.51,100,1,14.87,100,1,12.47,100,1,14.95,700,1,12.46,100,1,14.99,700,1,12.43,700,1,15.07,700,1,ARL,126872345
2025-07-17T14:04:21.250797741Z,2025-07-17T14:04:21.250632048Z,160,2,1108,C,B,10,13.40,0,0,13.40,23,1,13.26,2,1,14.35,1,1,13.25,100,1,14.36,2,1,12.99,100,1,14.37,100,1,12.73,100,1,14.59,100,1,12.67,100,1,14.83,100,1,12.47,100,1,14.87,100,1,12.46,100,1,14.95,700,1,12.43,700,1,14.99,700,1,12.42,700,1,15.07,700,1,ARL,115474337
2025-07-17T14:04:21.250797741Z,2025-07-17T14:04:21.250632048Z,160,2,1108,A,B,10,13.40,0,0,13.40,23,1,13.26,2,1,14.35,1,1,13.25,100,1,14.36,2,1,12.99,100,1,14.37,100,1,12.73,100,1,14.59,100,1,12.67,100,1,14.83,100,1,12.47,100,1,14.87,100,1,12.46,100,1,14.95,700,1,12.43,700,1,14.99,700,1,12.42,700,1,15.07,700,1,ARL,126872361
2025-07-17T14:04:21.350207939Z,2025-07-17T14:04:21.350041949Z,160,2,1108,C,A,10,13.40,0,0,13.40,23,1,13.26,2,1,14.36,2,1,13.25,100,1,14.37,100,1,12.99,100,1,14.59,100,1,12.73,100,1,14.83,100,1,12.67,100,1,14.87,100,1,12.47,100,1,14.95,700,1,12.46,100,1,14.99,700,1,12.43,700,1,15.07,700,1,12.42,700,1,15.09,100,1,ARL,126872197
2025-07-17T14:04:54.699926747Z,2025-07-17T14:04:54.699761263Z,160,2,1108,C,A,10,13.40,0,0,13.40,23,1,13.26,2,1,14.36,2,1,13.25,100,1,14.37,100,1,12.99,100,1,14.59,100,1,12.73,100,1,14.83,100,1,12.67,100,1,14.87,100,1,12.47,100,1,14.95,700,1,12.46,100,1,14.99,700,1,12.43,700,1,15.07,700,1,12.42,700,1,15.09,100,1,ARL,92510753
2025-07-17T14:04:54.699926747Z,2025-07-17T14:04:54.699761263Z,160,2,1108,A,A,10,13.40,0,0,13.40,23,1,13.26,2,1,14.36,2,1,13.25,100,1,14.37,100,1,12.99,100,1,14.59,100,1,12.73,100,1,14.83,100,1,12.67,100,1,14.87,100,1,12.47,100,1,14.95,700,1,12.46,100,1,14.99,700,1,12.43,700,1,15.07,700,1,12.42,700,1,15.09,100,1,ARL,127999501
2025-07-17T14:05:10.258855609Z,2025-07-17T14:05:10.258689253Z,160,2,1108,A,A,10,13.40,0,0,13.40,23,1,13.26,2,1,14.08,1,1,13.25,100,1,14.36,2,1,12.99,100,1,14.37,100,1,12.73,100,1,14.59,100,1,12.67,100,1,14.83,100,1,12.47,100,1,14.87,100,1,12.46,100,1,14.95,700,1,12.43,700,1,14.99,700,1,12.42,700,1,15.07,700,1,ARL,128570149
2025-07-17T14:05:10.259513876Z,2025-07-17T14:05:10.259348471Z,160,2,1108,C,A,10,13.40,0,0,13.40,23,1,13.26,2,1,14.08,1,1,13.25,100,1,14.36,2,1,12.99,100,1,14.37,100,1,12.73,100,1,14.59,100,1,12.67,100,1,14.83,100,1,12.47,100,1,14.87,100,1,12.46,100,1,14.95,700,1,12.43,700,1,14.99,700,1,12.42,700,1,15.07,700,1,ARL,108217173
2025-07-17T14:05:10.259513876Z,2025-07-17T14:05:10.259348471Z,160,2,1108,A,A,10,13.40,0,0,13.40,23,1,13.26,2,1,14.08,1,1,13.25,100,1,14.36,2,1,12.99,100,1,14.37,100,1,12.73,100,1,14.59,100,1,12.67,100,1,14.83,100,1,12.47,100,1,14.87,100,1,12.46,100,1,14.95,700,1,12.43,700,1,14.98,100,1,12.42,700,1,14.99,700,1,ARL,128570229
2025-07-17T14:05:10.259895236Z,2025-07-17T14:05:10.259729446Z,160,2,1108,C,A,10,13.40,0,0,13.40,23,1,13.26,2,1,14.08,1,1,13.25,100,1,14.36,2,1,12.99,100,1,14.37,100,1,12.73,100,1,14.59,100,1,12.67,100,1,14.83,100,1,12.47,100,1,14.87,100,1,12.46,100,1,14.95,700,1,12.43,700,1,14.98,100,1,12.42,700,1,14.99,700,1,ARL,108217045
2025-07-17T14:05:10.259895236Z,2025-07-17T14:05:10.259729446Z,160,2,1108,A,A,10,13.40,0,0,13.40,23,1,13.26,2,1,14.08,1,1,13.25,100,1,14.36,2,1,12.99,100,1,14.37,100,1,12.73,100,1,14.59,100,1,12.67,100,1,14.83,100,1,12.47,100,1,14.87,100,1,12.46,100,1,14.95,700,1,12.43,700,1,14.98,200,2,12.42,700,1,14.99,700,1,ARL,128570237
2025-07-17T14:05:10.262461863Z,2025-07-17T14:05:10.262295631Z,160,2,1108,C,A,10,13.40,0,0,13.40,23,1,13.26,2,1,14.08,1,1,13.25,100,1,14.36,2,1,12.99,100,1,14.59,100,1,12.73,100,1,14.83,100,1,12.67,100,1,14.87,100,1,12.47,100,1,14.95,700,1,12.46,100,1,14.98,200,2,12.43,700,1,14.99,700,1,12.42,700,1,15.07,700,1,ARL,121107961
2025-07-17T14:05:10.262461863Z,2025-07-17T14:05:10.262295631Z,160,2,1108,A,A,10,13.40,0,0,13.40,23,1,13.26,2,1,14.08,1,1,13.25,100,1,14.09,100,1,12.99,100,1,14.36,2,1,12.73,100,1,14.59,100,1,12.67,100,1,14.83,100,1,12.47,100,1,14.87,100,1,12.46,100,1,14.95,700,1,12.43,700,1,14.98,200,2,12.42,700,1,14.99,700,1,ARL,128570317
2025-07-17T14:05:10.262866527Z,2025-07-17T14:05:10.262701351Z,160,2,1108,C,A,10,13.40,0,0,13.40,23,1,13.26,2,1,14.09,100,1,13.25,100,1,14.36,2,1,12.99,100,1,14.59,100,1,12.73,100,1,14.83,100,1,12.67,100,1,14.87,100,1,12.47,100,1,14.95,700,1,12.46,100,1,14.98,200,2,12.43,700,1,14.99,700,1,12.42,700,1,15.07,700,1,ARL,128570149
2025-07-17T14:05:10.263188035Z,2025-07-17T14:05:10.263022539Z,160,2,1108,C,A,10,13.40,0,0,13.40,23,1,13.26,2,1,14.09,100,1,13.25,100,1,14.36,2,1,12.99,100,1,14.59,100,1,12.73,100,1,14.83,100,1,12.67,100,1,14.87,100,1,12.47,100,1,14.95,700,1,12.46,100,1,14.98,200,2,12.43,700,1,14.99,700,1,12.42,700,1,15.07,700,1,ARL,127999501
2025-07-17T14:05:10.263188035Z,2025-07-17T14:05:10.263022539Z,160,2,1108,A,A,10,13.40,0,0,13.40,23,1,13.26,2,1,14.09,100,1,13.25,100,1,14.36,2,1,12.99,100,1,14.59,100,1,12.73,100,1,14.83,100,1,12.67,100,1,14.87,100,1,12.47,100,1,14.95,700,1,12.46,100,1,14.98,200,2,12.43,700,1,14.99,700,1,12.42,700,1,15.07,700,1,ARL,128570417
2025-07-17T14:05:10.264495078Z,2025-07-17T14:05:10.264329670Z,160,2,1108,C,A,10,13.40,0,0,13.40,23,1,13.26,2,1,14.09,100,1,13.25,100,1,14.36,2,1,12.99,100,1,14.59,100,1,12.73,100,1,14.83,100,1,12.67,100,1,14.87,100,1,12.47,100,1,14.95,700,1,12.46,100,1,14.98,200,2,12.43,700,1,14.99,700,1,12.42,700,1,15.07,700,1,ARL,92510761
2025-07-17T14:05:10.264495078Z,2025-07-17T14:05:10.264329670Z,160,2,1108,A,A,10,13.40,0,0,13.40,23,1,13.26,2,1,14.09,100,1,13.25,100,1,14.36,2,1,12.99,100,1,14.59,100,1,12.73,100,1,14.83,100,1,12.67,100,1,14.87,100,1,12.47,100,1,14.95,700,1,12.46,100,1,14.98,200,2,12.43,700,1,14.99,700,1,12.42,700,1,15.07,700,1,ARL,128570449
2025-07-17T14:05:10.264590318Z,2025-07-17T14:05:10.264425026Z,160,2,1108,C,A,10,13.40,0,0,13.40,23,1,13.26,2,1,14.09,100,1,13.25,100,1,14.36,2,1,12.99,100,1,14.59,100,1,12.73,100,1,14.83,100,1,12.67,100,1,14.87,100,1,12.47,100,1,14.95,700,1,12.46,100,1,14.98,200,2,12.43,700,1,14.99,700,1,12.42,700,1,15.07,700,1,ARL,84650629
2025-07-17T14:05:10.264715723Z,2025-07-17T14:05:10.264550510Z,160,2,1108,A,A,10,13.40,0,0,13.40,23,1,13.26,2,1,14.09,100,1,13.25,100,1,14.36,2,1,12.99,100,1,14.59,100,1,12.73,100,1,14.83,100,1,12.67,100,1,14.87,100,1,12.47,100,1,14.89,100,1,12.46,100,1,14.95,700,1,12.43,700,1,14.98,200,2,12.42,700,1,14.99,700,1,ARL,128570453
2025-07-17T14:05:10.269943051Z,2025-07-17T14:05:10.269777131Z,160,2,1108,C,A,10,13.40,0,0,13.40,23,1,13.26,2,1,14.09,100,1,13.25,100,1,14.36,2,1,12.99,100,1,14.83,100,1,12.73,100,1,14.87,100,1,12.67,100,1,14.89,100,1,12.47,100,1,14.95,700,1,12.46,100,1,14.98,200,2,12.43,700,1,14.99,700,1,12.42,700,1,15.07,700,1,ARL,84629329
2025-07-17T14:05:10.269997960Z,2025-07-17T14:05:10.269832842Z,160,2,1108,A,A,10,13.40,0,0,13.40,23,1,13.26,2,1,14.09,100,1,13.25,100,1,14.36,2,1,12.99,100,1,14.37,100,1,12.73,100,1,14.83,100,1,12.67,100,1,14.87,100,1,12.47,100,1,14.89,100,1,12.46,100,1,14.95,700,1,12.43,700,1,14.98,200,2,12.42,700,1,14.99,700,1,ARL,128570621
2025-07-17T14:05:10.271865423Z,2025-07-17T14:05:10.271699633Z,160,2,1108,C,A,10,13.40,0,0,13.40,23,1,13.26,2,1,14.09,100,1,13.25,100,1,14.36,2,1,12.99,100,1,14.37,100,1,12.73,100,1,14.83,100,1,12.67,100,1,14.87,100,1,12.47,100,1,14.89,100,1,12.46,100,1,14.95,700,1,12.43,700,1,14.98,200,2,12.42,700,1,14.99,700,1,ARL,92510841
2025-07-17T14:05:10.271865423Z,2025-07-17T14:05:10.271699633Z,160,2,1108,A,A,10,13.40,0,0,13.40,23,1,13.26,2,1,14.09,100,1,13.25,100,1,14.36,2,1,12.99,100,1,14.37,100,1,12.73,100,1,14.83,100,1,12.67,100,1,14.87,100,1,12.47,100,1,14.89,100,1,12.46,100,1,14.95,700,1,12.43,700,1,14.98,200,2,12.42,700,1,14.99,700,1,ARL,128570685
2025-07-17T14:05:10.276320920Z,2025-07-17T14:05:10.276155439Z,160,2,1108,C,A,10,13.40,0,0,13.40,23,1,13.26,2,1,14.09,100,1,13.25,100,1,14.36,2,1,12.99,100,1,14.37,100,1,12.73,100,1,14.83,100,1,12.67,100,1,14.87,100,1,12.47,100,1,14.89,100,1,12.46,100,1,14.95,700,1,12.43,700,1,14.98,200,2,12.42,700,1,14.99,700,1,ARL,92510813
2025-07-17T14:05:10.276320920Z,2025-07-17T14:05:10.276155439Z,160,2,1108,A,A,10,13.40,0,0,13.40,23,1,13.26,2,1,14.09,100,1,13.25,100,1,14.36,2,1,12.99,100,1,14.37,100,1,12.73,100,1,14.83,100,1,12.67,100,1,14.87,100,1,12.47,100,1,14.89,100,1,12.46,100,1,14.95,700,1,12.43,700,1,14.98,200,2,12.42,700,1,14.99,700,1,ARL,128570977
2025-07-17T14:05:10.342982797Z,2025-07-17T14:05:10.342817229Z,160,2,1108,C,A,10,13.40,0,0,13.40,23,1,13.26,2,1,14.09,100,1,13.25,100,1,14.36,2,1,12.99,100,1,14.37,100,1,12.73,100,1,14.83,100,1,12.67,100,1,14.87,100,1,12.47,100,1,14.89,100,1,12.46,100,1,14.95,700,1,12.43,700,1,14.98,200,2,12.42,700,1,14.99,700,1,ARL,84630849
2025-07-17T14:05:10.342982797Z,2025-07-17T14:05:10.342817229Z,160,2,1108,A,A,10,13.40,0,0,13.40,23,1,13.26,2,1,14.09,100,1,13.25,100,1,14.36,2,1,12.99,100,1,14.37,100,1,12.73,100,1,14.83,100,1,12.67,100,1,14.87,100,1,12.47,100,1,14.89,100,1,12.46,100,1,14.95,700,1,12.43,700,1,14.98,200,2,12.42,700,1,14.99,700,1,ARL,128573957
2025-07-17T14:05:31.418741362Z,2025-07-17T14:05:31.418575692Z,160,2,1108,C,A,10,13.40,0,0,13.40,23,1,13.26,2,1,14.09,100,1,13.25,100,1,14.37,100,1,12.99,100,1,14.83,100,1,12.73,100,1,14.87,100,1,12.67,100,1,14.89,100,1,12.47,100,1,14.95,700,1,12.46,100,1,14.98,200,2,12.43,700,1,14.99,700,1,12.42,700,1,15.07,700,1,ARL,121098341
2025-07-17T14:05:31.418741362Z,2025-07-17T14:05:31.418575692Z,160,2,1108,A,A,10,13.40,0,0,13.40,23,1,13.26,2,1,14.09,100,1,13.25,100,1,14.26,2,1,12.99,100,1,14.37,100,1,12.73,100,1,14.83,100,1,12.67,100,1,14.87,100,1,12.47,100,1,14.89,100,1,12.46,100,1,14.95,700,1,12.43,700,1,14.98,200,2,12.42,700,1,14.99,700,1,ARL,129518753
2025-07-17T14:06:01.386006059Z,2025-07-17T14:06:01.385840471Z,160,2,1108,C,B,10,13.40,0,0,13.40,23,1,13.25,100,1,14.09,100,1,12.99,100,1,14.26,2,1,12.73,100,1,14.37,100,1,12.67,100,1,14.83,100,1,12.47,100,1,14.87,100,1,12.46,100,1,14.89,100,1,12.43,700,1,14.95,700,1,12.42,700,1,14.98,200,2,12.37,700,1,14.99,700,1,ARL,121098337
2025-07-17T14:06:01.386006059Z,2025-07-17T14:06:01.385840471Z,160,2,1108,A,B,10,13.40,0,0,13.40,23,1,13.25,100,1,14.09,100,1,13.15,2,1,14.26,2,1,12.99,100,1,14.37,100,1,12.73,100,1,14.83,100,1,12.67,100,1,14.87,100,1,12.47,100,1,14.89,100,1,12.46,100,1,14.95,700,1,12.43,700,1,14.98,200,2,12.42,700,1,14.99,700,1,ARL,130693973
2025-07-17T14:13:11.346377890Z,2025-07-17T14:13:11.346212166Z,160,2,1108,C,A,10,13.40,0,0,13.40,23,1,13.25,100,1,14.09,100,1,13.15,2,1,14.26,2,1,12.99,100,1,14.37,100,1,12.73,100,1,14.83,100,1,12.67,100,1,14.87,100,1,12.47,100,1,14.89,100,1,12.46,100,1,14.95,700,1,12.43,700,1,14.98,200,2,12.42,700,1,14.99,700,1,ARL,128570417
2025-07-17T14:13:11.346377890Z,2025-07-17T14:13:11.346212166Z,160,2,1108,A,A,10,13.40,0,0,13.40,23,1,13.25,100,1,14.09,100,1,13.15,2,1,14.26,2,1,12.99,100,1,14.37,100,1,12.73,100,1,14.83,100,1,12.67,100,1,14.87,100,1,12.47,100,1,14.89,100,1,12.46,100,1,14.95,700,1,12.43,700,1,14.98,200,2,12.42,700,1,14.99,700,1,ARL,146955361
2025-07-17T14:13:11.358916626Z,2025-07-17T14:13:11.358751092Z,160,2,1108,C,A,10,13.40,0,0,13.40,23,1,13.25,100,1,14.09,100,1,13.15,2,1,14.26,2,1,12.99,100,1,14.83,100,1,12.73,100,1,14.87,100,1,12.67,100,1,14.89,100,1,12.47,100,1,14.95,700,1,12.46,100,1,14.98,200,2,12.43,700,1,14.99,700,1,12.42,700,1,15.07,700,1,ARL,128570621
2025-07-17T14:13:11.358968656Z,2025-07-17T14:13:11.358802966Z,160,2,1108,A,A,10,13.40,0,0,13.40,23,1,13.25,100,1,14.09,100,1,13.15,2,1,14.26,2,1,12.99,100,1,14.28,100,1,12.73,100,1,14.83,100,1,12.67,100,1,14.87,100,1,12.47,100,1,14.89,100,1,12.46,100,1,14.95,700,1,12.43,700,1,14.98,200,2,12.42,700,1,14.99,700,1,ARL,146956357
2025-07-17T14:13:11.393088913Z,2025-07-17T14:13:11.392923396Z,160,2,1108,C,A,10,13.40,0,0,13.40,23,1,13.25,100,1,14.09,100,1,13.15,2,1,14.26,2,1,12.99,100,1,14.28,100,1,12.73,100,1,14.83,100,1,12.67,100,1,14.87,100,1,12.47,100,1,14.89,100,1,12.46,100,1,14.95,700,1,12.43,700,1,14.98,200,2,12.42,700,1,14.99,700,1,ARL,84629953
2025-07-17T14:13:11.393088913Z,2025-07-17T14:13:11.392923396Z,160,2,1108,A,A,10,13.40,0,0,13.40,23,1,13.25,100,1,14.09,100,1,13.15,2,1,14.26,2,1,12.99,100,1,14.28,100,1,12.73,100,1,14.83,100,1,12.67,100,1,14.87,100,1,12.47,100,1,14.89,100,1,12.46,100,1,14.95,700,1,12.43,700,1,14.98,200,2,12.42,700,1,14.99,700,1,ARL,146959177
2025-07-17T14:13:11.423482323Z,2025-07-17T14:13:11.423316840Z,160,2,1108,A,A,10,13.40,0,0,13.40,23,1,13.25,100,1,14.09,100,1,13.15,2,1,14.26,2,1,12.99,100,1,14.28,100,1,12.73,100,1,14.56,100,1,12.67,100,1,14.83,100,1,12.47,100,1,14.87,100,1,12.46,100,1,14.89,100,1,12.43,700,1,14.95,700,1,12.42,700,1,14.98,200,2,ARL,146960005
2025-07-17T14:13:11.423483431Z,2025-07-17T14:13:11.423317922Z,160,2,1108,C,A,10,13.40,0,0,13.40,23,1,13.25,100,1,14.09,100,1,13.15,2,1,14.26,2,1,12.99,100,1,14.28,100,1,12.73,100,1,14.56,100,1,12.67,100,1,14.83,100,1,12.47,100,1,14.89,100,1,12.46,100,1,14.95,700,1,12.43,700,1,14.98,200,2,12.42,700,1,14.99,700,1,ARL,84708037
2025-07-17T14:13:11.555808541Z,2025-07-17T14:13:11.555642984Z,160,2,1108,A,A,10,13.40,0,0,13.40,23,1,13.25,100,1,14.09,100,1,13.15,2,1,14.26,2,1,12.99,100,1,14.28,100,1,12.73,100,1,14.56,100,1,12.67,100,1,14.83,100,1,12.47,100,1,14.84,100,1,12.46,100,1,14.89,100,1,12.43,700,1,14.95,700,1,12.42,700,1,14.98,200,2,ARL,146962993
2025-07-17T14:13:11.555828856Z,2025-07-17T14:13:11.555663413Z,160,2,1108,C,A,10,13.40,0,0,13.40,23,1,13.25,100,1,14.09,100,1,13.15,2,1,14.26,2,1,12.99,100,1,14.28,100,1,12.73,100,1,14.56,100,1,12.67,100,1,14.83,100,1,12.47,100,1,14.84,100,1,12.46,100,1,14.89,100,1,12.43,700,1,14.95,700,1,12.42,700,1,14.98,200,2,ARL,84668677
2025-07-17T14:13:19.230983072Z,2025-07-17T14:13:19.230817808Z,160,2,1108,A,A,10,13.40,0,0,13.40,23,1,13.25,100,1,14.09,100,1,13.15,2,1,14.26,2,1,12.99,100,1,14.28,100,1,12.73,100,1,14.56,100,1,12.67,100,1,14.83,100,1,12.47,100,1,14.84,100,1,12.46,100,1,14.89,100,1,12.43,700,1,14.91,700,1,12.42,700,1,14.95,700,1,ARL,147217629
2025-07-17T14:13:19.231778755Z,2025-07-17T14:13:19.231613044Z,160,2,1108,C,A,10,13.40,0,0,13.40,23,1,13.25,100,1,14.09,100,1,13.15,2,1,14.26,2,1,12.99,100,1,14.28,100,1,12.73,100,1,14.56,100,1,12.67,100,1,14.83,100,1,12.47,100,1,14.84,100,1,12.46,100,1,14.89,100,1,12.43,700,1,14.91,700,1,12.42,700,1,14.95,700,1,ARL,84628829
2025-07-17T14:22:28.338174848Z,2025-07-17T14:22:28.338009329Z,160,2,1108,A,A,10,13.40,0,0,13.40,23,1,13.25,100,1,14.00,1,1,13.15,2,1,14.09,100,1,12.99,100,1,14.26,2,1,12.73,100,1,14.28,100,1,12.67,100,1,14.56,100,1,12.47,100,1,14.83,100,1,12.46,100,1,14.84,100,1,12.43,700,1,14.89,100,1,12.42,700,1,14.91,700,1,ARL,168073025
2025-07-17T14:22:29.994011311Z,2025-07-17T14:22:29.993845812Z,160,2,1108,C,A,10,13.40,0,0,13.40,23,1,13.25,100,1,14.00,1,1,13.15,2,1,14.26,2,1,12.99,100,1,14.28,100,1,12.73,100,1,14.56,100,1,12.67,100,1,14.83,100,1,12.47,100,1,14.84,100,1,12.46,100,1,14.89,100,1,12.43,700,1,14.91,700,1,12.42,700,1,14.95,700,1,ARL,128570317
2025-07-17T14:22:29.994011311Z,2025-07-17T14:22:29.993845812Z,160,2,1108,A,A,10,13.40,0,0,13.40,23,1,13.25,100,1,14.00,1,1,13.15,2,1,14.01,100,1,12.99,100,1,14.26,2,1,12.73,100,1,14.28,100,1,12.67,100,1,14.56,100,1,12.47,100,1,14.83,100,1,12.46,100,1,14.84,100,1,12.43,700,1,14.89,100,1,12.42,700,1,14.91,700,1,ARL,168141389
2025-07-17T14:32:58.233129156Z,2025-07-17T14:32:58.232963791Z,160,2,1108,C,B,10,13.40,0,0,13.40,23,1,13.15,2,1,14.00,1,1,12.99,100,1,14.01,100,1,12.73,100,1,14.26,2,1,12.67,100,1,14.28,100,1,12.47,100,1,14.56,100,1,12.46,100,1,14.83,100,1,12.43,700,1,14.84,100,1,12.42,700,1,14.89,100,1,12.37,700,1,14.91,700,1,ARL,121107957
2025-07-17T14:32:58.714015555Z,2025-07-17T14:32:58.713850212Z,160,2,1108,A,B,10,13.40,0,0,13.40,23,1,13.15,2,1,14.00,1,1,13.14,100,1,14.01,100,1,12.99,100,1,14.26,2,1,12.73,100,1,14.28,100,1,12.67,100,1,14.56,100,1,12.47,100,1,14.83,100,1,12.46,100,1,14.84,100,1,12.43,700,1,14.89,100,1,12.42,700,1,14.91,700,1,ARL,190326921
2025-07-17T14:34:48.346344959Z,2025-07-17T14:34:48.346179643Z,160,2,1108,C,A,10,13.40,0,0,13.40,23,1,13.15,2,1,14.01,100,1,13.14,100,1,14.26,2,1,12.99,100,1,14.28,100,1,12.73,100,1,14.56,100,1,12.67,100,1,14.83,100,1,12.47,100,1,14.84,100,1,12.46,100,1,14.89,100,1,12.43,700,1,14.91,700,1,12.42,700,1,14.95,700,1,ARL,168073025
2025-07-17T14:47:30.548081358Z,2025-07-17T14:47:30.547915870Z,160,2,1108,A,B,10,13.40,0,0,13.40,23,1,13.38,33,1,14.01,100,1,13.15,2,1,14.26,2,1,13.14,100,1,14.28,100,1,12.99,100,1,14.56,100,1,12.73,100,1,14.83,100,1,12.67,100,1,14.84,100,1,12.47,100,1,14.89,100,1,12.46,100,1,14.91,700,1,12.43,700,1,14.95,700,1,ARL,215999733
2025-07-17T14:47:30.548346701Z,2025-07-17T14:47:30.548180936Z,160,2,1108,C,B,10,13.40,0,0,13.40,23,1,13.38,33,1,14.01,100,1,13.15,2,1,14.26,2,1,12.99,100,1,14.28,100,1,12.73,100,1,14.56,100,1,12.67,100,1,14.83,100,1,12.47,100,1,14.84,100,1,12.46,100,1,14.89,100,1,12.43,700,1,14.91,700,1,12.42,700,1,14.95,700,1,ARL,190326921
2025-07-17T14:47:30.548346701Z,2025-07-17T14:47:30.548180936Z,160,2,1108,A,B,10,13.40,0,0,13.40,23,1,13.38,33,1,14.01,100,1,13.37,100,1,14.26,2,1,13.15,2,1,14.28,100,1,12.99,100,1,14.56,100,1,12.73,100,1,14.83,100,1,12.67,100,1,14.84,100,1,12.47,100,1,14.89,100,1,12.46,100,1,14.91,700,1,12.43,700,1,14.95,700,1,ARL,215999737
2025-07-17T14:47:30.548831608Z,2025-07-17T14:47:30.548666035Z,160,2,1108,C,B,10,13.40,0,0,13.40,23,1,13.38,33,1,14.01,100,1,13.37,100,1,14.26,2,1,13.15,2,1,14.28,100,1,12.99,100,1,14.56,100,1,12.73,100,1,14.83,100,1,12.67,100,1,14.84,100,1,12.47,100,1,14.89,100,1,12.46,100,1,14.91,700,1,12.43,700,1,14.95,700,1,ARL,126872345
2025-07-17T14:47:30.548831608Z,2025-07-17T14:47:30.548666035Z,160,2,1108,A,B,10,13.40,0,0,13.40,23,1,13.38,33,1,14.01,100,1,13.37,100,1,14.26,2,1,13.15,2,1,14.28,100,1,12.99,100,1,14.56,100,1,12.73,100,1,14.83,100,1,12.67,100,1,14.84,100,1,12.48,100,1,14.89,100,1,12.47,100,1,14.91,700,1,12.46,100,1,14.95,700,1,ARL,215999741
2025-07-17T14:47:30.549090785Z,2025-07-17T14:47:30.548925394Z,160,2,1108,C,B,10,13.40,0,0,13.40,23,1,13.38,33,1,14.01,100,1,13.37,100,1,14.26,2,1,13.15,2,1,14.28,100,1,12.99,100,1,14.56,100,1,12.73,100,1,14.83,100,1,12.67,100,1,14.84,100,1,12.48,100,1,14.89,100,1,12.47,100,1,14.91,700,1,12.46,100,1,14.95,700,1,ARL,43317473
2025-07-17T14:47:30.549090785Z,2025-07-17T14:47:30.548925394Z,160,2,1108,A,B,10,13.40,0,0,13.40,23,1,13.38,33,1,14.01,100,1,13.37,100,1,14.26,2,1,13.15,2,1,14.28,100,1,12.99,100,1,14.56,100,1,12.73,100,1,14.83,100,1,12.67,100,1,14.84,100,1,12.48,100,1,14.89,100,1,12.47,100,1,14.91,700,1,12.46,100,1,14.95,700,1,ARL,215999753
2025-07-17T14:47:30.549341156Z,2025-07-17T14:47:30.549175659Z,160,2,1108,C,B,10,13.40,0,0,13.40,23,1,13.38,33,1,14.01,100,1,13.37,100,1,14.26,2,1,13.15,2,1,14.28,100,1,12.99,100,1,14.56,100,1,12.73,100,1,14.83,100,1,12.67,100,1,14.84,100,1,12.48,100,1,14.89,100,1,12.47,100,1,14.91,700,1,12.46,100,1,14.95,700,1,ARL,126872361
2025-07-17T14:47:30.549341156Z,2025-07-17T14:47:30.549175659Z,160,2,1108,A,B,10,13.40,0,0,13.40,23,1,13.38,33,1,14.01,100,1,13.37,100,1,14.26,2,1,13.15,2,1,14.28,100,1,12.99,100,1,14.56,100,1,12.73,100,1,14.83,100,1,12.67,100,1,14.84,100,1,12.48,200,2,14.89,100,1,12.47,100,1,14.91,700,1,12.46,100,1,14.95,700,1,ARL,215999761
2025-07-17T14:47:30.571385383Z,2025-07-17T14:47:30.571220121Z,160,2,1108,C,B,10,13.40,0,0,13.40,23,1,13.38,33,1,14.01,100,1,13.37,100,1,14.26,2,1,13.15,2,1,14.28,100,1,12.73,100,1,14.56,100,1,12.67,100,1,14.83,100,1,12.48,200,2,14.84,100,1,12.47,100,1,14.89,100,1,12.46,100,1,14.91,700,1,12.43,700,1,14.95,700,1,ARL,43805737
2025-07-17T14:47:30.571436944Z,2025-07-17T14:47:30.571271737Z,160,2,1108,A,B,10,13.40,0,0,13.40,23,1,13.38,33,1,14.01,100,1,13.37,100,1,14.26,2,1,13.15,2,1,14.28,100,1,13.10,100,1,14.56,100,1,12.73,100,1,14.83,100,1,12.67,100,1,14.84,100,1,12.48,200,2,14.89,100,1,12.47,100,1,14.91,700,1,12.46,100,1,14.95,700,1,ARL,216001413
2025-07-17T14:47:37.384610677Z,2025-07-17T14:47:37.384441232Z,160,2,1108,A,B,10,13.40,0,0,13.40,23,1,13.38,33,1,14.01,100,1,13.37,100,1,14.26,2,1,13.15,2,1,14.28,100,1,13.10,100,1,14.56,100,1,12.73,100,1,14.83,100,1,12.67,100,1,14.84,100,1,12.50,700,1,14.89,100,1,12.48,200,2,14.91,700,1,12.47,100,1,14.95,700,1,ARL,216223005
2025-07-17T14:47:37.385400265Z,2025-07-17T14:47:37.385234288Z,160,2,1108,C,B,10,13.40,0,0,13.40,23,1,13.38,33,1,14.01,100,1,13.37,100,1,14.26,2,1,13.15,2,1,14.28,100,1,13.10,100,1,14.56,100,1,12.73,100,1,14.83,100,1,12.67,100,1,14.84,100,1,12.50,700,1,14.89,100,1,12.48,200,2,14.91,700,1,12.47,100,1,14.95,700,1,ARL,44570585
2025-07-17T14:52:02.610481877Z,2025-07-17T14:52:02.610315566Z,160,2,1108,T,N,10,13.40,0,0,13.40,23,1,13.38,33,1,14.01,100,1,13.37,100,1,14.26,2,1,13.15,2,1,14.28,100,1,13.10,100,1,14.56,100,1,12.73,100,1,14.83,100,1,12.67,100,1,14.84,100,1,12.50,700,1,14.89,100,1,12.48,200,2,14.91,700,1,12.47,100,1,14.95,700,1,ARL,0
2025-07-17T14:52:02.610509102Z,2025-07-17T14:52:02.610343819Z,160,2,1108,A,A,10,13.40,0,0,13.40,23,1,13.38,33,1,13.71,1,1,13.37,100,1,14.01,100,1,13.15,2,1,14.26,2,1,13.10,100,1,14.28,100,1,12.73,100,1,14.56,100,1,12.67,100,1,14.83,100,1,12.50,700,1,14.84,100,1,12.48,200,2,14.89,100,1,12.47,100,1,14.91,700,1,ARL,223347833
2025-07-17T14:52:02.611701408Z,2025-07-17T14:52:02.611536221Z,160,2,1108,C,A,10,13.40,0,0,13.40,23,1,13.38,33,1,14.01,100,1,13.37,100,1,14.26,2,1,13.15,2,1,14.28,100,1,13.10,100,1,14.56,100,1,12.73,100,1,14.83,100,1,12.67,100,1,14.84,100,1,12.50,700,1,14.89,100,1,12.48,200,2,14.91,700,1,12.47,100,1,14.95,700,1,ARL,223347833
2025-07-17T15:00:11.560678862Z,2025-07-17T15:00:11.560513555Z,160,2,1108,C,B,10,13.40,0,0,13.40,23,1,13.37,100,1,14.01,100,1,13.15,2,1,14.26,2,1,13.10,100,1,14.28,100,1,12.73,100,1,14.56,100,1,12.67,100,1,14.83,100,1,12.50,700,1,14.84,100,1,12.48,200,2,14.89,100,1,12.47,100,1,14.91,700,1,12.46,100,1,14.95,700,1,ARL,215999733
2025-07-17T15:00:11.563053782Z,2025-07-17T15:00:11.562887948Z,160,2,1108,C,B,10,13.40,0,0,13.40,23,1,13.37,100,1,14.01,100,1,13.15,2,1,14.26,2,1,13.10,100,1,14.28,100,1,12.73,100,1,14.56,100,1,12.67,100,1,14.83,100,1,12.50,700,1,14.84,100,1,12.48,100,1,14.89,100,1,12.47,100,1,14.91,700,1,12.46,100,1,14.95,700,1,ARL,215999761
2025-07-17T15:00:11.563053782Z,2025-07-17T15:00:11.562887948Z,160,2,1108,A,B,10,13.40,0,0,13.40,23,1,13.37,100,1,14.01,100,1,13.15,2,1,14.26,2,1,13.10,100,1,14.28,100,1,12.73,100,1,14.56,100,1,12.67,100,1,14.83,100,1,12.65,100,1,14.84,100,1,12.50,700,1,14.89,100,1,12.48,100,1,14.91,700,1,12.47,100,1,14.95,700,1,ARL,236179089
2025-07-17T15:00:12.536218524Z,2025-07-17T15:00:12.536052536Z,160,2,1108,C,B,10,13.40,0,0,13.40,23,1,13.37,100,1,14.01,100,1,13.15,2,1,14.26,2,1,13.10,100,1,14.28,100,1,12.73,100,1,14.56,100,1,12.67,100,1,14.83,100,1,12.65,100,1,14.84,100,1,12.50,700,1,14.89,100,1,12.47,100,1,14.91,700,1,12.46,100,1,14.95,700,1,ARL,215999741
2025-07-17T15:00:12.536218524Z,2025-07-17T15:00:12.536052536Z,160,2,1108,A,B,10,13.40,0,0,13.40,23,1,13.37,100,1,14.01,100,1,13.15,2,1,14.26,2,1,13.10,100,1,14.28,100,1,12.73,100,1,14.56,100,1,12.67,100,1,14.83,100,1,12.65,200,2,14.84,100,1,12.50,700,1,14.89,100,1,12.47,100,1,14.91,700,1,12.46,100,1,14.95,700,1,ARL,236206261
2025-07-17T15:01:11.658789910Z,2025-07-17T15:01:11.658624662Z,160,2,1108,A,A,10,13.40,0,0,13.40,23,1,13.37,100,1,13.98,10,1,13.15,2,1,14.01,100,1,13.10,100,1,14.26,2,1,12.73,100,1,14.28,100,1,12.67,100,1,14.56,100,1,12.65,200,2,14.83,100,1,12.50,700,1,14.84,100,1,12.47,100,1,14.89,100,1,12.46,100,1,14.91,700,1,ARL,237940713
2025-07-17T15:01:12.948386121Z,2025-07-17T15:01:12.948220412Z,160,2,1108,C,A,10,13.40,0,0,13.40,23,1,13.37,100,1,13.98,10,1,13.15,2,1,14.26,2,1,13.10,100,1,14.28,100,1,12.73,100,1,14.56,100,1,12.67,100,1,14.83,100,1,12.65,200,2,14.84,100,1,12.50,700,1,14.89,100,1,12.47,100,1,14.91,700,1,12.46,100,1,14.95,700,1,ARL,168141389
2025-07-17T15:01:12.948386121Z,2025-07-17T15:01:12.948220412Z,160,2,1108,A,A,10,13.40,0,0,13.40,23,1,13.37,100,1,13.98,10,1,13.15,2,1,13.99,100,1,13.10,100,1,14.26,2,1,12.73,100,1,14.28,100,1,12.67,100,1,14.56,100,1,12.65,200,2,14.83,100,1,12.50,700,1,14.84,100,1,12.47,100,1,14.89,100,1,12.46,100,1,14.91,700,1,ARL,237978541
2025-07-17T15:01:12.949124493Z,2025-07-17T15:01:12.948959226Z,160,2,1108,C,A,10,13.40,0,0,13.40,23,1,13.37,100,1,13.98,10,1,13.15,2,1,13.99,100,1,13.10,100,1,14.26,2,1,12.73,100,1,14.28,100,1,12.67,100,1,14.56,100,1,12.65,200,2,14.84,100,1,12.50,700,1,14.89,100,1,12.47,100,1,14.91,700,1,12.46,100,1,14.95,700,1,ARL,84628793
2025-07-17T15:01:12.949484115Z,2025-07-17T15:01:12.949317198Z,160,2,1108,A,A,10,13.40,0,0,13.40,23,1,13.37,100,1,13.98,10,1,13.15,2,1,13.99,100,1,13.10,100,1,14.26,2,1,12.73,100,1,14.28,100,1,12.67,100,1,14.56,100,1,12.65,200,2,14.61,100,1,12.50,700,1,14.84,100,1,12.47,100,1,14.89,100,1,12.46,100,1,14.91,700,1,ARL,237978629
2025-07-17T15:01:26.963916368Z,2025-07-17T15:01:26.963746832Z,160,2,1108,C,A,10,13.40,0,0,13.40,23,1,13.37,100,1,13.99,100,1,13.15,2,1,14.26,2,1,13.10,100,1,14.28,100,1,12.73,100,1,14.56,100,1,12.67,100,1,14.61,100,1,12.65,200,2,14.84,100,1,12.50,700,1,14.89,100,1,12.47,100,1,14.91,700,1,12.46,100,1,14.95,700,1,ARL,237940713
2025-07-17T15:01:37.513312432Z,2025-07-17T15:01:37.513147090Z,160,2,1108,A,A,10,13.40,0,0,13.40,23,1,13.37,100,1,13.98,10,1,13.15,2,1,13.99,100,1,13.10,100,1,14.26,2,1,12.73,100,1,14.28,100,1,12.67,100,1,14.56,100,1,12.65,200,2,14.61,100,1,12.50,700,1,14.84,100,1,12.47,100,1,14.89,100,1,12.46,100,1,14.91,700,1,ARL,238668633
2025-07-17T15:05:36.047202557Z,2025-07-17T15:05:36.047029298Z,160,2,1108,C,A,10,13.40,0,0,13.40,23,1,13.37,100,1,13.99,100,1,13.15,2,1,14.26,2,1,13.10,100,1,14.28,100,1,12.73,100,1,14.56,100,1,12.67,100,1,14.61,100,1,12.65,200,2,14.84,100,1,12.50,700,1,14.89,100,1,12.47,100,1,14.91,700,1,12.46,100,1,14.95,700,1,ARL,238668633
2025-07-17T15:10:34.469866273Z,2025-07-17T15:10:34.469700487Z,160,2,1108,C,A,10,13.40,0,0,13.40,23,1,13.37,100,1,13.99,100,1,13.15,2,1,14.28,100,1,13.10,100,1,14.56,100,1,12.73,100,1,14.61,100,1,12.67,100,1,14.84,100,1,12.65,200,2,14.89,100,1,12.50,700,1,14.91,700,1,12.47,100,1,14.95,700,1,12.46,100,1,14.98,200,2,ARL,129518753
2025-07-17T15:10:34.469866273Z,2025-07-17T15:10:34.469700487Z,160,2,1108,A,A,10,13.40,0,0,13.40,23,1,13.37,100,1,13.99,100,1,13.15,2,1,14.17,2,1,13.10,100,1,14.28,100,1,12.73,100,1,14.56,100,1,12.67,100,1,14.61,100,1,12.65,200,2,14.84,100,1,12.50,700,1,14.89,100,1,12.47,100,1,14.91,700,1,12.46,100,1,14.95,700,1,ARL,252720897
2025-07-17T15:12:52.735414592Z,2025-07-17T15:12:52.735249178Z,160,2,1108,A,A,10,13.40,0,0,13.40,23,1,13.37,100,1,13.99,100,1,13.15,2,1,14.03,100,1,13.10,100,1,14.17,2,1,12.73,100,1,14.28,100,1,12.67,100,1,14.56,100,1,12.65,200,2,14.61,100,1,12.50,700,1,14.84,100,1,12.47,100,1,14.89,100,1,12.46,100,1,14.91,700,1,ARL,256325129
2025-07-17T15:13:06.511853457Z,2025-07-17T15:13:06.511687613Z,160,2,1108,A,A,10,13.40,0,0,13.40,23,1,13.37,100,1,13.98,10,1,13.15,2,1,13.99,100,1,13.10,100,1,14.03,100,1,12.73,100,1,14.17,2,1,12.67,100,1,14.28,100,1,12.65,200,2,14.56,100,1,12.50,700,1,14.61,100,1,12.47,100,1,14.84,100,1,12.46,100,1,14.89,100,1,ARL,256739841
2025-07-17T15:13:08.654089411Z,2025-07-17T15:13:08.653923821Z,160,2,1108,A,A,10,13.40,0,0,13.40,23,1,13.37,100,1,13.98,10,1,13.15,2,1,13.99,100,1,13.10,100,1,14.01,100,1,12.73,100,1,14.03,100,1,12.67,100,1,14.17,2,1,12.65,200,2,14.28,100,1,12.50,700,1,14.56,100,1,12.47,100,1,14.61,100,1,12.46,100,1,14.84,100,1,ARL,256818881
2025-07-17T15:13:08.661686458Z,2025-07-17T15:13:08.661521116Z,160,2,1108,C,A,10,13.40,0,0,13.40,23,1,13.37,100,1,13.98,10,1,13.15,2,1,13.99,100,1,13.10,100,1,14.01,100,1,12.73,100,1,14.17,2,1,12.67,100,1,14.28,100,1,12.65,200,2,14.56,100,1,12.50,700,1,14.61,100,1,12.47,100,1,14.84,100,1,12.46,100,1,14.89,100,1,ARL,256325129
2025-07-17T15:14:00.440728359Z,2025-07-17T15:14:00.440563034Z,160,2,1108,C,A,10,13.40,0,0,13.40,23,1,13.37,100,1,13.99,100,1,13.15,2,1,14.01,100,1,13.10,100,1,14.17,2,1,12.73,100,1,14.28,100,1,12.67,100,1,14.56,100,1,12.65,200,2,14.61,100,1,12.50,700,1,14.84,100,1,12.47,100,1,14.89,100,1,12.46,100,1,14.91,700,1,ARL,256739841
2025-07-17T15:14:52.382139830Z,2025-07-17T15:14:52.381974473Z,160,2,1108,A,A,10,13.40,0,0,13.40,23,1,13.37,100,1,13.98,10,1,13.15,2,1,13.99,100,1,13.10,100,1,14.01,100,1,12.73,100,1,14.17,2,1,12.67,100,1,14.28,100,1,12.65,200,2,14.56,100,1,12.50,700,1,14.61,100,1,12.47,100,1,14.84,100,1,12.46,100,1,14.89,100,1,ARL,259546169
2025-07-17T15:14:56.683309707Z,2025-07-17T15:14:56.683144163Z,160,2,1108,C,A,10,13.40,0,0,13.40,23,1,13.37,100,1,13.98,10,1,13.15,2,1,13.99,100,1,13.10,100,1,14.17,2,1,12.73,100,1,14.28,100,1,12.67,100,1,14.56,100,1,12.65,200,2,14.61,100,1,12.50,700,1,14.84,100,1,12.47,100,1,14.89,100,1,12.46,100,1,14.91,700,1,ARL,256818881
2025-07-17T15:15:11.661118778Z,2025-07-17T15:15:11.660953613Z,160,2,1108,A,A,10,13.40,0,0,13.40,23,1,13.37,100,1,13.98,10,1,13.15,2,1,13.99,100,1,13.10,100,1,14.02,100,1,12.73,100,1,14.17,2,1,12.67,100,1,14.28,100,1,12.65,200,2,14.56,100,1,12.50,700,1,14.61,100,1,12.47,100,1,14.84,100,1,12.46,100,1,14.89,100,1,ARL,260184621
2025-07-17T15:15:32.408863263Z,2025-07-17T15:15:32.408694312Z,160,2,1108,C,A,10,13.40,0,0,13.40,23,1,13.37,100,1,13.99,100,1,13.15,2,1,14.02,100,1,13.10,100,1,14.17,2,1,12.73,100,1,14.28,100,1,12.67,100,1,14.56,100,1,12.65,200,2,14.61,100,1,12.50,700,1,14.84,100,1,12.47,100,1,14.89,100,1,12.46,100,1,14.91,700,1,ARL,259546169
2025-07-17T15:16:31.607242914Z,2025-07-17T15:16:31.607077080Z,160,2,1108,A,A,10,13.40,0,0,13.40,23,1,13.37,100,1,13.99,100,1,13.15,2,1,14.00,100,1,13.10,100,1,14.02,100,1,12.73,100,1,14.17,2,1,12.67,100,1,14.28,100,1,12.65,200,2,14.56,100,1,12.50,700,1,14.61,100,1,12.47,100,1,14.84,100,1,12.46,100,1,14.89,100,1,ARL,262279553
2025-07-17T15:16:31.614370696Z,2025-07-17T15:16:31.614205345Z,160,2,1108,C,A,10,13.40,0,0,13.40,23,1,13.37,100,1,13.99,100,1,13.15,2,1,14.00,100,1,13.10,100,1,14.17,2,1,12.73,100,1,14.28,100,1,12.67,100,1,14.56,100,1,12.65,200,2,14.61,100,1,12.50,700,1,14.84,100,1,12.47,100,1,14.89,100,1,12.46,100,1,14.91,700,1,ARL,260184621
2025-07-17T15:16:39.373467449Z,2025-07-17T15:16:39.373301585Z,160,2,1108,A,A,10,13.40,0,0,13.40,23,1,13.37,100,1,13.98,10,1,13.15,2,1,13.99,100,1,13.10,100,1,14.00,100,1,12.73,100,1,14.17,2,1,12.67,100,1,14.28,100,1,12.65,200,2,14.56,100,1,12.50,700,1,14.61,100,1,12.47,100,1,14.84,100,1,12.46,100,1,14.89,100,1,ARL,262432821
2025-07-17T15:17:50.916325497Z,2025-07-17T15:17:50.916157330Z,160,2,1108,C,A,10,13.40,0,0,13.40,23,1,13.37,100,1,13.99,100,1,13.15,2,1,14.00,100,1,13.10,100,1,14.17,2,1,12.73,100,1,14.28,100,1,12.67,100,1,14.56,100,1,12.65,200,2,14.61,100,1,12.50,700,1,14.84,100,1,12.47,100,1,14.89,100,1,12.46,100,1,14.91,700,1,ARL,262432821
2025-07-17T15:17:51.938467389Z,2025-07-17T15:17:51.938301087Z,160,2,1108,C,A,10,13.40,0,0,13.40,23,1,13.37,100,1,13.99,100,1,13.15,2,1,14.17,2,1,13.10,100,1,14.28,100,1,12.73,100,1,14.56,100,1,12.67,100,1,14.61,100,1,12.65,200,2,14.84,100,1,12.50,700,1,14.89,100,1,12.47,100,1,14.91,700,1,12.46,100,1,14.95,700,1,ARL,262279553
2025-07-17T15:17:55.957423821Z,2025-07-17T15:17:55.957258362Z,160,2,1108,A,A,10,13.40,0,0,13.40,23,1,13.37,100,1,13.99,100,1,13.15,2,1,14.01,100,1,13.10,100,1,14.17,2,1,12.73,100,1,14.28,100,1,12.67,100,1,14.56,100,1,12.65,200,2,14.61,100,1,12.50,700,1,14.84,100,1,12.47,100,1,14.89,100,1,12.46,100,1,14.91,700,1,ARL,264420961
2025-07-17T15:19:23.618380576Z,2025-07-17T15:19:23.618215364Z,160,2,1108,C,A,10,13.40,0,0,13.40,23,1,13.37,100,1,13.99,100,1,13.15,2,1,14.17,2,1,13.10,100,1,14.28,100,1,12.73,100,1,14.56,100,1,12.67,100,1,14.61,100,1,12.65,200,2,14.84,100,1,12.50,700,1,14.89,100,1,12.47,100,1,14.91,700,1,12.46,100,1,14.95,700,1,ARL,264420961
2025-07-17T15:19:27.663790911Z,2025-07-17T15:19:27.663625107Z,160,2,1108,A,A,10,13.40,0,0,13.40,23,1,13.37,100,1,13.99,100,1,13.15,2,1,14.03,100,1,13.10,100,1,14.17,2,1,12.73,100,1,14.28,100,1,12.67,100,1,14.56,100,1,12.65,200,2,14.61,100,1,12.50,700,1,14.84,100,1,12.47,100,1,14.89,100,1,12.46,100,1,14.91,700,1,ARL,266714557
2025-07-17T15:20:46.705145876Z,2025-07-17T15:20:46.704980311Z,160,2,1108,A,A,10,13.40,0,0,13.40,23,1,13.37,100,1,13.99,100,1,13.15,2,1,14.01,100,1,13.10,100,1,14.03,100,1,12.73,100,1,14.17,2,1,12.67,100,1,14.28,100,1,12.65,200,2,14.56,100,1,12.50,700,1,14.61,100,1,12.47,100,1,14.84,100,1,12.46,100,1,14.89,100,1,ARL,269075833
2025-07-17T15:20:46.716698477Z,2025-07-17T15:20:46.716532886Z,160,2,1108,C,A,10,13.40,0,0,13.40,23,1,13.37,100,1,13.99,100,1,13.15,2,1,14.01,100,1,13.10,100,1,14.17,2,1,12.73,100,1,14.28,100,1,12.67,100,1,14.56,100,1,12.65,200,2,14.61,100,1,12.50,700,1,14.84,100,1,12.47,100,1,14.89,100,1,12.46,100,1,14.91,700,1,ARL,266714557
2025-07-17T15:23:00.249962772Z,2025-07-17T15:23:00.249796874Z,160,2,1108,C,B,10,13.40,0,0,13.40,23,1,13.37,100,1,13.99,100,1,13.10,100,1,14.01,100,1,12.73,100,1,14.17,2,1,12.67,100,1,14.28,100,1,12.65,200,2,14.56,100,1,12.50,700,1,14.61,100,1,12.47,100,1,14.84,100,1,12.46,100,1,14.89,100,1,12.43,700,1,14.91,700,1,ARL,130693973
2025-07-17T15:23:00.249962772Z,2025-07-17T15:23:00.249796874Z,160,2,1108,A,B,10,13.40,0,0,13.40,23,1,13.37,100,1,13.99,100,1,13.23,2,1,14.01,100,1,13.10,100,1,14.17,2,1,12.73,100,1,14.28,100,1,12.67,100,1,14.56,100,1,12.65,200,2,14.61,100,1,12.50,700,1,14.84,100,1,12.47,100,1,14.89,100,1,12.46,100,1,14.91,700,1,ARL,272263853
2025-07-17T15:26:04.666158860Z,2025-07-17T15:26:04.665993515Z,160,2,1108,C,A,10,13.40,0,0,13.40,23,1,13.37,100,1,13.99,100,1,13.23,2,1,14.01,100,1,13.10,100,1,14.28,100,1,12.73,100,1,14.56,100,1,12.67,100,1,14.61,100,1,12.65,200,2,14.84,100,1,12.50,700,1,14.89,100,1,12.47,100,1,14.91,700,1,12.46,100,1,14.95,700,1,ARL,252720897
2025-07-17T15:26:04.666158860Z,2025-07-17T15:26:04.665993515Z,160,2,1108,A,A,10,13.40,0,0,13.40,23,1,13.37,100,1,13.99,100,1,13.23,2,1,14.01,100,1,13.10,100,1,14.09,2,1,12.73,100,1,14.28,100,1,12.67,100,1,14.56,100,1,12.65,200,2,14.61,100,1,12.50,700,1,14.84,100,1,12.47,100,1,14.89,100,1,12.46,100,1,14.91,700,1,ARL,276751517
2025-07-17T15:28:38.882985923Z,2025-07-17T15:28:38.882820591Z,160,2,1108,A,A,10,13.40,0,0,13.40,23,1,13.37,100,1,13.99,200,2,13.23,2,1,14.01,100,1,13.10,100,1,14.09,2,1,12.73,100,1,14.28,100,1,12.67,100,1,14.56,100,1,12.65,200,2,14.61,100,1,12.50,700,1,14.84,100,1,12.47,100,1,14.89,100,1,12.46,100,1,14.91,700,1,ARL,280387693
2025-07-17T15:28:38.890789214Z,2025-07-17T15:28:38.890623989Z,160,2,1108,C,A,10,13.40,0,0,13.40,23,1,13.37,100,1,13.99,200,2,13.23,2,1,14.09,2,1,13.10,100,1,14.28,100,1,12.73,100,1,14.56,100,1,12.67,100,1,14.61,100,1,12.65,200,2,14.84,100,1,12.50,700,1,14.89,100,1,12.47,100,1,14.91,700,1,12.46,100,1,14.95,700,1,ARL,269075833
2025-07-17T15:28:44.820934614Z,2025-07-17T15:28:44.820769301Z,160,2,1108,C,A,10,13.40,0,0,13.40,23,1,13.37,100,1,13.99,100,1,13.23,2,1,14.09,2,1,13.10,100,1,14.28,100,1,12.73,100,1,14.56,100,1,12.67,100,1,14.61,100,1,12.65,200,2,14.84,100,1,12.50,700,1,14.89,100,1,12.47,100,1,14.91,700,1,12.46,100,1,14.95,700,1,ARL,280387693
2025-07-17T15:28:48.918811203Z,2025-07-17T15:28:48.918645728Z,160,2,1108,A,A,10,13.40,0,0,13.40,23,1,13.37,100,1,13.99,100,1,13.23,2,1,14.01,100,1,13.10,100,1,14.09,2,1,12.73,100,1,14.28,100,1,12.67,100,1,14.56,100,1,12.65,200,2,14.61,100,1,12.50,700,1,14.84,100,1,12.47,100,1,14.89,100,1,12.46,100,1,14.91,700,1,ARL,280580873
2025-07-17T15:30:23.573233259Z,2025-07-17T15:30:23.573067851Z,160,2,1108,A,A,10,13.40,0,0,13.40,23,1,13.37,100,1,13.82,10,1,13.23,2,1,13.99,100,1,13.10,100,1,14.01,100,1,12.73,100,1,14.09,2,1,12.67,100,1,14.28,100,1,12.65,200,2,14.56,100,1,12.50,700,1,14.61,100,1,12.47,100,1,14.84,100,1,12.46,100,1,14.89,100,1,ARL,282775557
2025-07-17T15:30:23.573528359Z,2025-07-17T15:30:23.573362522Z,160,2,1108,C,A,10,13.40,0,0,13.40,23,1,13.37,100,1,13.82,10,1,13.23,2,1,13.99,100,1,13.10,100,1,14.01,100,1,12.73,100,1,14.09,2,1,12.67,100,1,14.28,100,1,12.65,200,2,14.56,100,1,12.50,700,1,14.61,100,1,12.47,100,1,14.84,100,1,12.46,100,1,14.89,100,1,ARL,128570237
2025-07-17T15:30:23.573528359Z,2025-07-17T15:30:23.573362522Z,160,2,1108,A,A,10,13.40,0,0,13.40,23,1,13.37,100,1,13.82,10,1,13.23,2,1,13.99,100,1,13.10,100,1,14.01,100,1,12.73,100,1,14.09,2,1,12.67,100,1,14.28,100,1,12.65,200,2,14.56,100,1,12.50,700,1,14.61,100,1,12.47,100,1,14.72,100,1,12.46,100,1,14.84,100,1,ARL,282775561
2025-07-17T15:30:23.574854165Z,2025-07-17T15:30:23.574688647Z,160,2,1108,C,A,10,13.40,0,0,13.40,23,1,13.37,100,1,13.82,10,1,13.23,2,1,13.99,100,1,13.10,100,1,14.01,100,1,12.73,100,1,14.09,2,1,12.67,100,1,14.28,100,1,12.65,200,2,14.56,100,1,12.50,700,1,14.61,100,1,12.47,100,1,14.72,100,1,12.46,100,1,14.84,100,1,ARL,128570229
2025-07-17T15:30:23.574854165Z,2025-07-17T15:30:23.574688647Z,160,2,1108,A,A,10,13.40,0,0,13.40,23,1,13.37,100,1,13.82,10,1,13.23,2,1,13.99,100,1,13.10,100,1,14.01,100,1,12.73,100,1,14.09,2,1,12.67,100,1,14.28,100,1,12.65,200,2,14.56,100,1,12.50,700,1,14.61,100,1,12.47,100,1,14.72,200,2,12.46,100,1,14.84,100,1,ARL,282775577
2025-07-17T15:30:23.585191081Z,2025-07-17T15:30:23.585025490Z,160,2,1108,A,A,10,13.40,0,0,13.40,23,1,13.37,100,1,13.82,10,1,13.23,2,1,13.84,100,1,13.10,100,1,13.99,100,1,12.73,100,1,14.01,100,1,12.67,100,1,14.09,2,1,12.65,200,2,14.28,100,1,12.50,700,1,14.56,100,1,12.47,100,1,14.61,100,1,12.46,100,1,14.72,200,2,ARL,282775973
2025-07-17T15:30:23.585960886Z,2025-07-17T15:30:23.585795327Z,160,2,1108,C,A,10,13.40,0,0,13.40,23,1,13.37,100,1,13.82,10,1,13.23,2,1,13.84,100,1,13.10,100,1,13.99,100,1,12.73,100,1,14.01,100,1,12.67,100,1,14.09,2,1,12.65,200,2,14.28,100,1,12.50,700,1,14.56,100,1,12.47,100,1,14.61,100,1,12.46,100,1,14.72,200,2,ARL,146955361
2025-07-17T15:30:23.585960886Z,2025-07-17T15:30:23.585795327Z,160,2,1108,A,A,10,13.40,0,0,13.40,23,1,13.37,100,1,13.82,10,1,13.23,2,1,13.84,100,1,13.10,100,1,13.99,100,1,12.73,100,1,14.01,100,1,12.67,100,1,14.09,2,1,12.65,200,2,14.28,100,1,12.50,700,1,14.56,100,1,12.47,100,1,14.61,100,1,12.46,100,1,14.72,200,2,ARL,282776009
2025-07-17T15:30:23.586719371Z,2025-07-17T15:30:23.586553674Z,160,2,1108,C,A,10,13.40,0,0,13.40,23,1,13.37,100,1,13.82,10,1,13.23,2,1,13.84,100,1,13.10,100,1,13.99,100,1,12.73,100,1,14.01,100,1,12.67,100,1,14.09,2,1,12.65,200,2,14.28,100,1,12.50,700,1,14.56,100,1,12.47,100,1,14.61,100,1,12.46,100,1,14.72,200,2,ARL,128570453
2025-07-17T15:30:23.586719371Z,2025-07-17T15:30:23.586553674Z,160,2,1108,A,A,10,13.40,0,0,13.40,23,1,13.37,100,1,13.82,10,1,13.23,2,1,13.84,100,1,13.10,100,1,13.99,100,1,12.73,100,1,14.01,100,1,12.67,100,1,14.09,2,1,12.65,200,2,14.28,100,1,12.50,700,1,14.56,100,1,12.47,100,1,14.61,100,1,12.46,100,1,14.65,100,1,ARL,282776013
2025-07-17T15:30:23.586762105Z,2025-07-17T15:30:23.586596452Z,160,2,1108,C,A,10,13.40,0,0,13.40,23,1,13.37,100,1,13.82,10,1,13.23,2,1,13.84,100,1,13.10,100,1,13.99,100,1,12.73,100,1,14.01,100,1,12.67,100,1,14.09,2,1,12.65,200,2,14.28,100,1,12.50,700,1,14.56,100,1,12.47,100,1,14.61,100,1,12.46,100,1,14.65,100,1,ARL,84628833
2025-07-17T15:30:23.586762105Z,2025-07-17T15:30:23.586596452Z,160,2,1108,A,A,10,13.40,0,0,13.40,23,1,13.37,100,1,13.82,10,1,13.23,2,1,13.84,100,1,13.10,100,1,13.99,100,1,12.73,100,1,14.01,100,1,12.67,100,1,14.09,2,1,12.65,200,2,14.28,100,1,12.50,700,1,14.56,100,1,12.47,100,1,14.61,100,1,12.46,100,1,14.65,100,1,ARL,282776017
2025-07-17T15:30:23.587432517Z,2025-07-17T15:30:23.587267064Z,160,2,1108,C,A,10,13.40,0,0,13.40,23,1,13.37,100,1,13.82,10,1,13.23,2,1,13.84,100,1,13.10,100,1,13.99,100,1,12.73,100,1,14.01,100,1,12.67,100,1,14.09,2,1,12.65,200,2,14.28,100,1,12.50,700,1,14.56,100,1,12.47,100,1,14.61,100,1,12.46,100,1,14.65,100,1,ARL,128570685
2025-07-17T15:30:23.587432517Z,2025-07-17T15:30:23.587267064Z,160,2,1108,A,A,10,13.40,0,0,13.40,23,1,13.37,100,1,13.82,10,1,13.23,2,1,13.84,100,1,13.10,100,1,13.99,100,1,12.73,100,1,14.01,100,1,12.67,100,1,14.09,2,1,12.65,200,2,14.28,100,1,12.50,700,1,14.56,100,1,12.47,100,1,14.61,100,1,12.46,100,1,14.65,100,1,ARL,282776025
2025-07-17T15:30:23.587581881Z,2025-07-17T15:30:23.587416236Z,160,2,1108,C,A,10,13.40,0,0,13.40,23,1,13.37,100,1,13.82,10,1,13.23,2,1,13.84,100,1,13.10,100,1,13.99,100,1,12.73,100,1,14.01,100,1,12.67,100,1,14.09,2,1,12.65,200,2,14.28,100,1,12.50,700,1,14.56,100,1,12.47,100,1,14.61,100,1,12.46,100,1,14.65,100,1,ARL,128570449
2025-07-17T15:30:23.587581881Z,2025-07-17T15:30:23.587416236Z,160,2,1108,A,A,10,13.40,0,0,13.40,23,1,13.37,100,1,13.82,10,1,13.23,2,1,13.84,100,1,13.10,100,1,13.99,100,1,12.73,100,1,14.01,100,1,12.67,100,1,14.09,2,1,12.65,200,2,14.28,100,1,12.50,700,1,14.56,100,1,12.47,100,1,14.61,100,1,12.46,100,1,14.65,100,1,ARL,282776029
2025-07-17T15:30:23.587611440Z,2025-07-17T15:30:23.587445922Z,160,2,1108,C,A,10,13.40,0,0,13.40,23,1,13.37,100,1,13.82,10,1,13.23,2,1,13.84,100,1,13.10,100,1,13.99,100,1,12.73,100,1,14.01,100,1,12.67,100,1,14.09,2,1,12.65,200,2,14.28,100,1,12.50,700,1,14.56,100,1,12.47,100,1,14.61,100,1,12.46,100,1,14.65,100,1,ARL,128570977
2025-07-17T15:30:23.587611440Z,2025-07-17T15:30:23.587445922Z,160,2,1108,A,A,10,13.40,0,0,13.40,23,1,13.37,100,1,13.82,10,1,13.23,2,1,13.84,100,1,13.10,100,1,13.99,100,1,12.73,100,1,14.01,100,1,12.67,100,1,14.09,2,1,12.65,200,2,14.28,100,1,12.50,700,1,14.56,100,1,12.47,100,1,14.61,100,1,12.46,100,1,14.65,100,1,ARL,282776033
2025-07-17T15:30:23.590261792Z,2025-07-17T15:30:23.590096343Z,160,2,1108,C,A,10,13.40,0,0,13.40,23,1,13.37,100,1,13.82,10,1,13.23,2,1,13.84,100,1,13.10,100,1,13.99,100,1,12.73,100,1,14.01,100,1,12.67,100,1,14.09,2,1,12.65,200,2,14.28,100,1,12.50,700,1,14.56,100,1,12.47,100,1,14.61,100,1,12.46,100,1,14.65,100,1,ARL,128573957
2025-07-17T15:30:23.590261792Z,2025-07-17T15:30:23.590096343Z,160,2,1108,A,A,10,13.40,0,0,13.40,23,1,13.37,100,1,13.82,10,1,13.23,2,1,13.84,100,1,13.10,100,1,13.99,100,1,12.73,100,1,14.01,100,1,12.67,100,1,14.09,2,1,12.65,200,2,14.28,100,1,12.50,700,1,14.56,100,1,12.47,100,1,14.61,100,1,12.46,100,1,14.65,100,1,ARL,282776089
2025-07-17T15:30:23.591959120Z,2025-07-17T15:30:23.591793735Z,160,2,1108,C,A,10,13.40,0,0,13.40,23,1,13.37,100,1,13.82,10,1,13.23,2,1,13.84,100,1,13.10,100,1,13.99,100,1,12.73,100,1,14.09,2,1,12.67,100,1,14.28,100,1,12.65,200,2,14.56,100,1,12.50,700,1,14.61,100,1,12.47,100,1,14.65,100,1,12.46,100,1,14.72,200,2,ARL,280580873
2025-07-17T15:30:23.602992439Z,2025-07-17T15:30:23.602827102Z,160,2,1108,C,A,10,13.40,0,0,13.40,23,1,13.37,100,1,13.82,10,1,13.23,2,1,13.84,100,1,13.10,100,1,13.99,100,1,12.73,100,1,14.09,2,1,12.67,100,1,14.56,100,1,12.65,200,2,14.61,100,1,12.50,700,1,14.65,100,1,12.47,100,1,14.72,200,2,12.46,100,1,14.81,200,2,ARL,146956357
2025-07-17T15:30:23.603046460Z,2025-07-17T15:30:23.602881129Z,160,2,1108,A,A,10,13.40,0,0,13.40,23,1,13.37,100,1,13.82,10,1,13.23,2,1,13.84,100,1,13.10,100,1,13.99,100,1,12.73,100,1,14.09,2,1,12.67,100,1,14.12,100,1,12.65,200,2,14.56,100,1,12.50,700,1,14.61,100,1,12.47,100,1,14.65,100,1,12.46,100,1,14.72,200,2,ARL,282776285
2025-07-17T15:30:23.628720816Z,2025-07-17T15:30:23.628555135Z,160,2,1108,A,A,10,13.40,0,0,13.40,23,1,13.37,100,1,13.82,10,1,13.23,2,1,13.84,100,1,13.10,100,1,13.99,100,1,12.73,100,1,14.09,2,1,12.67,100,1,14.12,100,1,12.65,200,2,14.56,100,1,12.50,700,1,14.61,100,1,12.47,100,1,14.65,100,1,12.46,100,1,14.72,200,2,ARL,282776733
2025-07-17T15:30:23.628732597Z,2025-07-17T15:30:23.628567293Z,160,2,1108,C,A,10,13.40,0,0,13.40,23,1,13.37,100,1,13.82,10,1,13.23,2,1,13.84,100,1,13.10,100,1,13.99,100,1,12.73,100,1,14.09,2,1,12.67,100,1,14.12,100,1,12.65,200,2,14.56,100,1,12.50,700,1,14.61,100,1,12.47,100,1,14.65,100,1,12.46,100,1,14.72,200,2,ARL,84628765
2025-07-17T15:30:23.952122580Z,2025-07-17T15:30:23.951957017Z,160,2,1108,C,A,10,13.40,0,0,13.40,23,1,13.37,100,1,13.82,10,1,13.23,2,1,13.84,100,1,13.10,100,1,14.09,2,1,12.73,100,1,14.12,100,1,12.67,100,1,14.56,100,1,12.65,200,2,14.61,100,1,12.50,700,1,14.65,100,1,12.47,100,1,14.72,200,2,12.46,100,1,14.81,200,2,ARL,237978541
2025-07-17T15:30:23.952122580Z,2025-07-17T15:30:23.951957017Z,160,2,1108,A,A,10,13.40,0,0,13.40,23,1,13.37,100,1,13.82,10,1,13.23,2,1,13.83,100,1,13.10,100,1,13.84,100,1,12.73,100,1,14.09,2,1,12.67,100,1,14.12,100,1,12.65,200,2,14.56,100,1,12.50,700,1,14.61,100,1,12.47,100,1,14.65,100,1,12.46,100,1,14.72,200,2,ARL,282781741
2025-07-17T15:30:24.769074814Z,2025-07-17T15:30:24.768909757Z,160,2,1108,C,A,10,13.40,0,0,13.40,23,1,13.37,100,1,13.83,100,1,13.23,2,1,13.84,100,1,13.10,100,1,14.09,2,1,12.73,100,1,14.12,100,1,12.67,100,1,14.56,100,1,12.65,200,2,14.61,100,1,12.50,700,1,14.65,100,1,12.47,100,1,14.72,200,2,12.46,100,1,14.81,200,2,ARL,282775557
2025-07-17T15:30:28.617337198Z,2025-07-17T15:30:28.617171810Z,160,2,1108,A,A,10,13.40,0,0,13.40,23,1,13.37,100,1,13.83,100,1,13.23,2,1,13.84,100,1,13.10,100,1,14.09,2,1,12.73,100,1,14.12,100,1,12.67,100,1,14.53,700,1,12.65,200,2,14.56,100,1,12.50,700,1,14.61,100,1,12.47,100,1,14.65,100,1,12.46,100,1,14.72,200,2,ARL,282881853
2025-07-17T15:30:28.617387294Z,2025-07-17T15:30:28.617221981Z,160,2,1108,C,A,10,13.40,0,0,13.40,23,1,13.37,100,1,13.83,100,1,13.23,2,1,13.84,100,1,13.10,100,1,14.09,2,1,12.73,100,1,14.12,100,1,12.67,100,1,14.53,700,1,12.65,200,2,14.56,100,1,12.50,700,1,14.61,100,1,12.47,100,1,14.65,100,1,12.46,100,1,14.72,200,2,ARL,92510741
2025-07-17T15:30:30.767213907Z,2025-07-17T15:30:30.767048606Z,160,2,1108,A,A,10,13.40,0,0,13.40,23,1,13.37,100,1,13.83,100,1,13.23,2,1,13.84,100,1,13.10,100,1,14.09,2,1,12.73,100,1,14.12,100,1,12.67,100,1,14.53,700,1,12.65,200,2,14.56,100,1,12.50,700,1,14.60,700,1,12.47,100,1,14.61,100,1,12.46,100,1,14.65,100,1,ARL,282920685
2025-07-17T15:30:30.767267001Z,2025-07-17T15:30:30.767101317Z,160,2,1108,C,A,10,13.40,0,0,13.40,23,1,13.37,100,1,13.83,100,1,13.23,2,1,13.84,100,1,13.10,100,1,14.09,2,1,12.73,100,1,14.12,100,1,12.67,100,1,14.53,700,1,12.65,200,2,14.56,100,1,12.50,700,1,14.60,700,1,12.47,100,1,14.61,100,1,12.46,100,1,14.65,100,1,ARL,84628757
2025-07-17T15:30:33.016987097Z,2025-07-17T15:30:33.016821395Z,160,2,1108,A,A,10,13.40,0,0,13.40,23,1,13.37,100,1,13.83,100,1,13.23,2,1,13.84,100,1,13.10,100,1,14.09,2,1,12.73,100,1,14.12,100,1,12.67,100,1,14.53,700,1,12.65,200,2,14.56,800,2,12.50,700,1,14.60,700,1,12.47,100,1,14.61,100,1,12.46,100,1,14.65,100,1,ARL,282969973
2025-07-17T15:30:33.017384279Z,2025-07-17T15:30:33.017218657Z,160,2,1108,C,A,10,13.40,0,0,13.40,23,1,13.37,100,1,13.83,100,1,13.23,2,1,13.84,100,1,13.10,100,1,14.09,2,1,12.73,100,1,14.12,100,1,12.67,100,1,14.53,700,1,12.65,200,2,14.56,800,2,12.50,700,1,14.60,700,1,12.47,100,1,14.61,100,1,12.46,100,1,14.65,100,1,ARL,84628797
2025-07-17T15:30:49.985906754Z,2025-07-17T15:30:49.985741094Z,160,2,1108,C,A,10,13.40,0,0,13.40,23,1,13.37,100,1,13.83,100,1,13.23,2,1,13.84,100,1,13.10,100,1,14.12,100,1,12.73,100,1,14.53,700,1,12.67,100,1,14.56,800,2,12.65,200,2,14.60,700,1,12.50,700,1,14.61,100,1,12.47,100,1,14.65,100,1,12.46,100,1,14.72,200,2,ARL,276751517
2025-07-17T15:30:49.985906754Z,2025-07-17T15:30:49.985741094Z,160,2,1108,A,A,10,13.40,0,0,13.40,23,1,13.37,100,1,13.83,100,1,13.23,2,1,13.84,100,1,13.10,100,1,14.02,2,1,12.73,100,1,14.12,100,1,12.67,100,1,14.53,700,1,12.65,200,2,14.56,800,2,12.50,700,1,14.60,700,1,12.47,100,1,14.61,100,1,12.46,100,1,14.65,100,1,ARL,283348193
2025-07-17T15:30:59.996516554Z,2025-07-17T15:30:59.996351383Z,160,2,1108,C,A,10,13.40,0,0,13.40,23,1,13.37,100,1,13.84,100,1,13.23,2,1,14.02,2,1,13.10,100,1,14.12,100,1,12.73,100,1,14.53,700,1,12.67,100,1,14.56,800,2,12.65,200,2,14.60,700,1,12.50,700,1,14.61,100,1,12.47,100,1,14.65,100,1,12.46,100,1,14.72,200,2,ARL,282781741
2025-07-17T15:31:00.002203922Z,2025-07-17T15:31:00.002038446Z,160,2,1108,C,A,10,13.40,0,0,13.40,23,1,13.37,100,1,14.02,2,1,13.23,2,1,14.12,100,1,13.10,100,1,14.53,700,1,12.73,100,1,14.56,800,2,12.67,100,1,14.60,700,1,12.65,200,2,14.61,100,1,12.50,700,1,14.65,100,1,12.47,100,1,14.72,200,2,12.46,100,1,14.81,200,2,ARL,282775973
2025-07-17T15:31:00.002478393Z,2025-07-17T15:31:00.002313250Z,160,2,1108,C,A,10,13.40,0,0,13.40,23,1,13.37,100,1,14.02,2,1,13.23,2,1,14.12,100,1,13.10,100,1,14.56,800,2,12.73,100,1,14.60,700,1,12.67,100,1,14.61,100,1,12.65,200,2,14.65,100,1,12.50,700,1,14.72,200,2,12.47,100,1,14.81,200,2,12.46,100,1,14.84,100,1,ARL,282881853
2025-07-17T15:31:00.002525213Z,2025-07-17T15:31:00.002359969Z,160,2,1108,A,A,10,13.40,0,0,13.40,23,1,13.37,100,1,14.02,2,1,13.23,2,1,14.12,100,1,13.10,100,1,14.56,800,2,12.73,100,1,14.60,700,1,12.67,100,1,14.61,100,1,12.65,200,2,14.65,100,1,12.50,700,1,14.68,700,1,12.47,100,1,14.72,200,2,12.46,100,1,14.81,200,2,ARL,283592941
2025-07-17T15:31:00.002938332Z,2025-07-17T15:31:00.002772683Z,160,2,1108,C,A,10,13.40,0,0,13.40,23,1,13.37,100,1,14.02,2,1,13.23,2,1,14.12,100,1,13.10,100,1,14.56,800,2,12.73,100,1,14.60,700,1,12.67,100,1,14.61,100,1,12.65,200,2,14.65,100,1,12.50,700,1,14.68,700,1,12.47,100,1,14.72,100,1,12.46,100,1,14.81,200,2,ARL,282775577
2025-07-17T15:31:00.002938332Z,2025-07-17T15:31:00.002772683Z,160,2,1108,A,A,10,13.40,0,0,13.40,23,1,13.37,100,1,14.02,2,1,13.23,2,1,14.12,100,1,13.10,100,1,14.56,800,2,12.73,100,1,14.60,700,1,12.67,100,1,14.61,100,1,12.65,200,2,14.65,100,1,12.50,700,1,14.68,700,1,12.47,100,1,14.72,100,1,12.46,100,1,14.81,200,2,ARL,283592993
2025-07-17T15:31:00.002953704Z,2025-07-17T15:31:00.002788190Z,160,2,1108,C,A,10,13.40,0,0,13.40,23,1,13.37,100,1,14.02,2,1,13.23,2,1,14.12,100,1,13.10,100,1,14.56,800,2,12.73,100,1,14.60,700,1,12.67,100,1,14.61,100,1,12.65,200,2,14.65,100,1,12.50,700,1,14.68,700,1,12.47,100,1,14.72,100,1,12.46,100,1,14.81,200,2,ARL,282776009
2025-07-17T15:31:00.002953704Z,2025-07-17T15:31:00.002788190Z,160,2,1108,A,A,10,13.40,0,0,13.40,23,1,13.37,100,1,14.02,2,1,13.23,2,1,14.12,100,1,13.10,100,1,14.56,800,2,12.73,100,1,14.60,700,1,12.67,100,1,14.61,100,1,12.65,200,2,14.65,100,1,12.50,700,1,14.68,700,1,12.47,100,1,14.72,100,1,12.46,100,1,14.81,200,2,ARL,283592997
2025-07-17T15:31:00.003368272Z,2025-07-17T15:31:00.003202003Z,160,2,1108,C,A,10,13.40,0,0,13.40,23,1,13.37,100,1,14.02,2,1,13.23,2,1,14.12,100,1,13.10,100,1,14.56,800,2,12.73,100,1,14.60,700,1,12.67,100,1,14.61,100,1,12.65,200,2,14.65,100,1,12.50,700,1,14.68,700,1,12.47,100,1,14.81,200,2,12.46,100,1,14.84,100,1,ARL,282775561
2025-07-17T15:31:00.003368272Z,2025-07-17T15:31:00.003202003Z,160,2,1108,A,A,10,13.40,0,0,13.40,23,1,13.37,100,1,14.02,2,1,13.23,2,1,14.12,100,1,13.10,100,1,14.56,800,2,12.73,100,1,14.60,700,1,12.67,100,1,14.61,100,1,12.65,200,2,14.65,100,1,12.50,700,1,14.68,700,1,12.47,100,1,14.81,200,2,12.46,100,1,14.84,100,1,ARL,283593041
2025-07-17T15:31:00.006784947Z,2025-07-17T15:31:00.006618398Z,160,2,1108,C,A,10,13.40,0,0,13.40,23,1,13.37,100,1,14.02,2,1,13.23,2,1,14.12,100,1,13.10,100,1,14.56,800,2,12.73,100,1,14.60,700,1,12.67,100,1,14.61,100,1,12.65,200,2,14.68,700,1,12.50,700,1,14.81,200,2,12.47,100,1,14.84,100,1,12.46,100,1,14.91,700,1,ARL,282776013
2025-07-17T15:31:00.006950491Z,2025-07-17T15:31:00.006784814Z,160,2,1108,A,A,10,13.40,0,0,13.40,23,1,13.37,100,1,14.02,2,1,13.23,2,1,14.12,100,1,13.10,100,1,14.56,800,2,12.73,100,1,14.60,700,1,12.67,100,1,14.61,100,1,12.65,200,2,14.68,700,1,12.50,700,1,14.79,100,1,12.47,100,1,14.81,200,2,12.46,100,1,14.84,100,1,ARL,283593313
2025-07-17T15:31:00.017759891Z,2025-07-17T15:31:00.017594312Z,160,2,1108,C,A,10,13.40,0,0,13.40,23,1,13.37,100,1,14.02,2,1,13.23,2,1,14.12,100,1,13.10,100,1,14.56,800,2,12.73,100,1,14.60,700,1,12.67,100,1,14.61,100,1,12.65,200,2,14.68,700,1,12.50,700,1,14.79,100,1,12.47,100,1,14.81,200,2,12.46,100,1,14.84,100,1,ARL,282776025
2025-07-17T15:31:00.017759891Z,2025-07-17T15:31:00.017594312Z,160,2,1108,A,A,10,13.40,0,0,13.40,23,1,13.37,100,1,14.02,2,1,13.23,2,1,14.12,100,1,13.10,100,1,14.56,800,2,12.73,100,1,14.60,700,1,12.67,100,1,14.61,100,1,12.65,200,2,14.68,700,1,12.50,700,1,14.79,100,1,12.47,100,1,14.81,200,2,12.46,100,1,14.84,100,1,ARL,283594173
2025-07-17T15:31:00.028894478Z,2025-07-17T15:31:00.028729168Z,160,2,1108,C,A,10,13.40,0,0,13.40,23,1,13.37,100,1,14.02,2,1,13.23,2,1,14.56,800,2,13.10,100,1,14.60,700,1,12.73,100,1,14.61,100,1,12.67,100,1,14.68,700,1,12.65,200,2,14.79,100,1,12.50,700,1,14.81,200,2,12.47,100,1,14.84,100,1,12.46,100,1,14.91,700,1,ARL,282776285
2025-07-17T15:31:00.028947312Z,2025-07-17T15:31:00.028782030Z,160,2,1108,A,A,10,13.40,0,0,13.40,23,1,13.37,100,1,14.02,2,1,13.23,2,1,14.26,100,1,13.10,100,1,14.56,800,2,12.73,100,1,14.60,700,1,12.67,100,1,14.61,100,1,12.65,200,2,14.68,700,1,12.50,700,1,14.79,100,1,12.47,100,1,14.81,200,2,12.46,100,1,14.84,100,1,ARL,283595181
2025-07-17T15:31:00.053107210Z,2025-07-17T15:31:00.052941898Z,160,2,1108,C,A,10,13.40,0,0,13.40,23,1,13.37,100,1,14.02,2,1,13.23,2,1,14.26,100,1,13.10,100,1,14.56,800,2,12.73,100,1,14.60,700,1,12.67,100,1,14.61,100,1,12.65,200,2,14.68,700,1,12.50,700,1,14.79,100,1,12.47,100,1,14.81,200,2,12.46,100,1,14.84,100,1,ARL,283592997
2025-07-17T15:31:00.053107210Z,2025-07-17T15:31:00.052941898Z,160,2,1108,A,A,10,13.40,0,0,13.40,23,1,13.37,100,1,14.02,2,1,13.23,2,1,14.26,100,1,13.10,100,1,14.56,800,2,12.73,100,1,14.60,700,1,12.67,100,1,14.61,100,1,12.65,200,2,14.68,700,1,12.50,700,1,14.79,100,1,12.47,100,1,14.81,200,2,12.46,100,1,14.84,100,1,ARL,283596673
2025-07-17T15:31:00.054830847Z,2025-07-17T15:31:00.054665340Z,160,2,1108,C,A,10,13.40,0,0,13.40,23,1,13.37,100,1,14.02,2,1,13.23,2,1,14.26,100,1,13.10,100,1,14.56,800,2,12.73,100,1,14.60,700,1,12.67,100,1,14.61,100,1,12.65,200,2,14.68,700,1,12.50,700,1,14.79,100,1,12.47,100,1,14.81,100,1,12.46,100,1,14.84,100,1,ARL,282776089
2025-07-17T15:31:00.054830847Z,2025-07-17T15:31:00.054665340Z,160,2,1108,A,A,10,13.40,0,0,13.40,23,1,13.37,100,1,14.02,2,1,13.23,2,1,14.26,100,1,13.10,100,1,14.56,800,2,12.73,100,1,14.60,700,1,12.67,100,1,14.61,100,1,12.65,200,2,14.68,700,1,12.50,700,1,14.79,100,1,12.47,100,1,14.81,100,1,12.46,100,1,14.84,100,1,ARL,283596721
2025-07-17T15:31:00.071409275Z,2025-07-17T15:31:00.071243665Z,160,2,1108,C,A,10,13.40,0,0,13.40,23,1,13.37,100,1,14.02,2,1,13.23,2,1,14.26,100,1,13.10,100,1,14.56,800,2,12.73,100,1,14.60,700,1,12.67,100,1,14.61,100,1,12.65,200,2,14.68,700,1,12.50,700,1,14.79,100,1,12.47,100,1,14.84,100,1,12.46,100,1,14.91,700,1,ARL,282776029
2025-07-17T15:31:00.071409275Z,2025-07-17T15:31:00.071243665Z,160,2,1108,A,A,10,13.40,0,0,13.40,23,1,13.37,100,1,14.02,2,1,13.23,2,1,14.26,100,1,13.10,100,1,14.56,800,2,12.73,100,1,14.60,700,1,12.67,100,1,14.61,100,1,12.65,200,2,14.68,700,1,12.50,700,1,14.79,100,1,12.47,100,1,14.84,100,1,12.46,100,1,14.91,700,1,ARL,283596945
2025-07-17T15:31:00.243369582Z,2025-07-17T15:31:00.243203860Z,160,2,1108,C,A,10,13.40,0,0,13.40,23,1,13.37,100,1,14.02,2,1,13.23,2,1,14.26,100,1,13.10,100,1,14.56,800,2,12.73,100,1,14.60,700,1,12.67,100,1,14.61,100,1,12.65,200,2,14.68,700,1,12.50,700,1,14.79,100,1,12.47,100,1,14.84,100,1,12.46,100,1,14.91,700,1,ARL,282776033
2025-07-17T15:31:00.243369582Z,2025-07-17T15:31:00.243203860Z,160,2,1108,A,A,10,13.40,0,0,13.40,23,1,13.37,100,1,14.02,2,1,13.23,2,1,14.26,100,1,13.10,100,1,14.56,800,2,12.73,100,1,14.60,700,1,12.67,100,1,14.61,100,1,12.65,200,2,14.68,700,1,12.50,700,1,14.79,100,1,12.47,100,1,14.84,100,1,12.46,100,1,14.91,700,1,ARL,283599609
2025-07-17T15:31:00.347828545Z,2025-07-17T15:31:00.347663441Z,160,2,1108,A,A,10,13.40,0,0,13.40,23,1,13.37,100,1,14.02,2,1,13.23,2,1,14.03,100,1,13.10,100,1,14.26,100,1,12.73,100,1,14.56,800,2,12.67,100,1,14.60,700,1,12.65,200,2,14.61,100,1,12.50,700,1,14.68,700,1,12.47,100,1,14.79,100,1,12.46,100,1,14.84,100,1,ARL,283604173
2025-07-17T15:31:04.014590575Z,2025-07-17T15:31:04.014425425Z,160,2,1108,A,A,10,13.40,0,0,13.40,23,1,13.37,100,1,14.00,100,1,13.23,2,1,14.02,2,1,13.10,100,1,14.03,100,1,12.73,100,1,14.26,100,1,12.67,100,1,14.56,800,2,12.65,200,2,14.60,700,1,12.50,700,1,14.61,100,1,12.47,100,1,14.68,700,1,12.46,100,1,14.79,100,1,ARL,283694233
2025-07-17T15:31:04.124577845Z,2025-07-17T15:31:04.124411850Z,160,2,1108,C,A,10,13.40,0,0,13.40,23,1,13.37,100,1,14.00,100,1,13.23,2,1,14.02,2,1,13.10,100,1,14.26,100,1,12.73,100,1,14.56,800,2,12.67,100,1,14.60,700,1,12.65,200,2,14.61,100,1,12.50,700,1,14.68,700,1,12.47,100,1,14.79,100,1,12.46,100,1,14.84,100,1,ARL,283604173
2025-07-17T15:31:04.124577845Z,2025-07-17T15:31:04.124411850Z,160,2,1108,A,A,10,13.40,0,0,13.40,23,1,13.37,100,1,14.00,100,1,13.23,2,1,14.01,100,1,13.10,100,1,14.02,2,1,12.73,100,1,14.26,100,1,12.67,100,1,14.56,800,2,12.65,200,2,14.60,700,1,12.50,700,1,14.61,100,1,12.47,100,1,14.68,700,1,12.46,100,1,14.79,100,1,ARL,283695933
2025-07-17T15:32:28.644506279Z,2025-07-17T15:32:28.644335983Z,160,2,1108,A,B,10,13.55,10,1,13.40,23,1,13.40,0,0,14.00,100,1,13.37,100,1,14.01,100,1,13.23,2,1,14.02,2,1,13.10,100,1,14.26,100,1,12.73,100,1,14.56,800,2,12.67,100,1,14.60,700,1,12.65,200,2,14.61,100,1,12.50,700,1,14.68,700,1,12.47,100,1,14.79,100,1,ARL,285545121
2025-07-17T15:32:28.653238729Z,2025-07-17T15:32:28.653073176Z,160,2,1108,C,B,10,13.55,10,1,13.40,23,1,13.40,0,0,14.00,100,1,13.23,2,1,14.01,100,1,13.10,100,1,14.02,2,1,12.73,100,1,14.26,100,1,12.67,100,1,14.56,800,2,12.65,200,2,14.60,700,1,12.50,700,1,14.61,100,1,12.47,100,1,14.68,700,1,12.46,100,1,14.79,100,1,ARL,215999737
2025-07-17T15:32:28.653238729Z,2025-07-17T15:32:28.653073176Z,160,2,1108,A,B,10,13.55,10,1,13.40,23,1,13.54,100,1,14.00,100,1,13.40,0,0,14.01,100,1,13.23,2,1,14.02,2,1,13.10,100,1,14.26,100,1,12.73,100,1,14.56,800,2,12.67,100,1,14.60,700,1,12.65,200,2,14.61,100,1,12.50,700,1,14.68,700,1,12.47,100,1,14.79,100,1,ARL,285545885
2025-07-17T15:32:28.653978501Z,2025-07-17T15:32:28.653812889Z,160,2,1108,C,B,10,13.55,10,1,13.40,23,1,13.54,100,1,14.00,100,1,13.40,0,0,14.01,100,1,13.23,2,1,14.02,2,1,13.10,100,1,14.26,100,1,12.73,100,1,14.56,800,2,12.67,100,1,14.60,700,1,12.65,200,2,14.61,100,1,12.50,700,1,14.68,700,1,12.47,100,1,14.79,100,1,ARL,215999753
2025-07-17T15:32:28.653978501Z,2025-07-17T15:32:28.653812889Z,160,2,1108,A,B,10,13.55,10,1,13.40,23,1,13.54,100,1,14.00,100,1,13.40,0,0,14.01,100,1,13.23,2,1,14.02,2,1,13.10,100,1,14.26,100,1,12.73,100,1,14.56,800,2,12.67,100,1,14.60,700,1,12.65,200,2,14.61,100,1,12.50,700,1,14.68,700,1,12.49,100,1,14.79,100,1,ARL,285545945
2025-07-17T15:32:28.653980648Z,2025-07-17T15:32:28.653815154Z,160,2,1108,C,B,10,13.55,10,1,13.40,23,1,13.54,100,1,14.00,100,1,13.40,0,0,14.01,100,1,13.23,2,1,14.02,2,1,13.10,100,1,14.26,100,1,12.73,100,1,14.56,800,2,12.65,200,2,14.60,700,1,12.50,700,1,14.61,100,1,12.49,100,1,14.68,700,1,12.47,100,1,14.79,100,1,ARL,43663229
2025-07-17T15:32:28.654336987Z,2025-07-17T15:32:28.654171723Z,160,2,1108,A,B,10,13.55,10,1,13.40,23,1,13.54,100,1,14.00,100,1,13.40,0,0,14.01,100,1,13.23,2,1,14.02,2,1,13.10,100,1,14.26,100,1,12.94,100,1,14.56,800,2,12.73,100,1,14.60,700,1,12.65,200,2,14.61,100,1,12.50,700,1,14.68,700,1,12.49,100,1,14.79,100,1,ARL,285545953
2025-07-17T15:32:28.657073743Z,2025-07-17T15:32:28.656908386Z,160,2,1108,C,B,10,13.55,10,1,13.40,23,1,13.54,100,1,14.00,100,1,13.40,0,0,14.01,100,1,13.23,2,1,14.02,2,1,13.10,100,1,14.26,100,1,12.94,100,1,14.56,800,2,12.73,100,1,14.60,700,1,12.65,200,2,14.61,100,1,12.50,700,1,14.68,700,1,12.49,100,1,14.79,100,1,ARL,43554133
2025-07-17T15:32:28.657173856Z,2025-07-17T15:32:28.657008222Z,160,2,1108,A,B,10,13.55,10,1,13.40,23,1,13.54,100,1,14.00,100,1,13.40,0,0,14.01,100,1,13.23,2,1,14.02,2,1,13.10,100,1,14.26,100,1,12.94,100,1,14.56,800,2,12.73,200,2,14.60,700,1,12.65,200,2,14.61,100,1,12.50,700,1,14.68,700,1,12.49,100,1,14.79,100,1,ARL,285546061
2025-07-17T15:32:28.667074437Z,2025-07-17T15:32:28.666909194Z,160,2,1108,C,B,10,13.55,10,1,13.40,23,1,13.54,100,1,14.00,100,1,13.40,0,0,14.01,100,1,13.23,2,1,14.02,2,1,12.94,100,1,14.26,100,1,12.73,200,2,14.56,800,2,12.65,200,2,14.60,700,1,12.50,700,1,14.61,100,1,12.49,100,1,14.68,700,1,12.46,100,1,14.79,100,1,ARL,216001413
2025-07-17T15:32:28.667126637Z,2025-07-17T15:32:28.666961018Z,160,2,1108,A,B,10,13.55,10,1,13.40,23,1,13.54,100,1,14.00,100,1,13.40,0,0,14.01,100,1,13.27,100,1,14.02,2,1,13.23,2,1,14.26,100,1,12.94,100,1,14.56,800,2,12.73,200,2,14.60,700,1,12.65,200,2,14.61,100,1,12.50,700,1,14.68,700,1,12.49,100,1,14.79,100,1,ARL,285546673
2025-07-17T15:32:28.674444711Z,2025-07-17T15:32:28.674279259Z,160,2,1108,C,B,10,13.55,10,1,13.40,23,1,13.54,100,1,14.00,100,1,13.40,0,0,14.01,100,1,13.27,100,1,14.02,2,1,13.23,2,1,14.26,100,1,12.94,100,1,14.56,800,2,12.73,200,2,14.60,700,1,12.65,200,2,14.61,100,1,12.50,700,1,14.68,700,1,12.49,100,1,14.79,100,1,ARL,43755813
2025-07-17T15:32:28.674444711Z,2025-07-17T15:32:28.674279259Z,160,2,1108,A,B,10,13.55,10,1,13.40,23,1,13.54,100,1,14.00,100,1,13.40,0,0,14.01,100,1,13.27,100,1,14.02,2,1,13.23,2,1,14.26,100,1,12.94,100,1,14.56,800,2,12.73,200,2,14.60,700,1,12.65,200,2,14.61,100,1,12.59,100,1,14.68,700,1,12.50,700,1,14.79,100,1,ARL,285546893
2025-07-17T15:32:28.691264796Z,2025-07-17T15:32:28.691099298Z,160,2,1108,C,B,10,13.55,10,1,13.40,23,1,13.54,100,1,14.00,100,1,13.40,0,0,14.01,100,1,13.27,100,1,14.02,2,1,13.23,2,1,14.26,100,1,12.94,100,1,14.56,800,2,12.73,200,2,14.60,700,1,12.65,200,2,14.61,100,1,12.59,100,1,14.68,700,1,12.50,700,1,14.79,100,1,ARL,44082961
2025-07-17T15:32:28.691264796Z,2025-07-17T15:32:28.691099298Z,160,2,1108,A,B,10,13.55,10,1,13.40,23,1,13.54,100,1,14.00,100,1,13.40,0,0,14.01,100,1,13.27,100,1,14.02,2,1,13.23,2,1,14.26,100,1,12.94,100,1,14.56,800,2,12.73,200,2,14.60,700,1,12.65,200,2,14.61,100,1,12.59,100,1,14.68,700,1,12.50,700,1,14.79,100,1,ARL,285548137
2025-07-17T15:32:28.711494526Z,2025-07-17T15:32:28.711329066Z,160,2,1108,C,B,10,13.55,10,1,13.40,23,1,13.54,100,1,14.00,100,1,13.40,0,0,14.01,100,1,13.27,100,1,14.02,2,1,13.23,2,1,14.26,100,1,12.94,100,1,14.56,800,2,12.73,200,2,14.60,700,1,12.65,200,2,14.61,100,1,12.59,100,1,14.68,700,1,12.50,700,1,14.79,100,1,ARL,43826785
2025-07-17T15:32:28.711494526Z,2025-07-17T15:32:28.711329066Z,160,2,1108,A,B,10,13.55,10,1,13.40,23,1,13.54,100,1,14.00,100,1,13.40,0,0,14.01,100,1,13.27,100,1,14.02,2,1,13.23,2,1,14.26,100,1,12.94,100,1,14.56,800,2,12.73,200,2,14.60,700,1,12.65,200,2,14.61,100,1,12.59,100,1,14.68,700,1,12.50,700,1,14.79,100,1,ARL,285549537
2025-07-17T15:32:28.771995987Z,2025-07-17T15:32:28.771830554Z,160,2,1108,C,B,10,13.54,100,1,13.40,23,1,13.40,0,0,14.00,100,1,13.27,100,1,14.01,100,1,13.23,2,1,14.02,2,1,12.94,100,1,14.26,100,1,12.73,200,2,14.56,800,2,12.65,200,2,14.60,700,1,12.59,100,1,14.61,100,1,12.50,700,1,14.68,700,1,12.49,100,1,14.79,100,1,ARL,285545121
2025-07-17T15:32:28.806930722Z,2025-07-17T15:32:28.806765209Z,160,2,1108,C,B,10,13.54,100,1,13.40,23,1,13.40,0,0,14.00,100,1,13.27,100,1,14.01,100,1,13.23,2,1,14.02,2,1,12.94,100,1,14.26,100,1,12.73,200,2,14.56,800,2,12.65,200,2,14.60,700,1,12.59,100,1,14.61,100,1,12.50,700,1,14.68,700,1,12.49,100,1,14.79,100,1,ARL,44088633
2025-07-17T15:32:28.806930722Z,2025-07-17T15:32:28.806765209Z,160,2,1108,A,B,10,13.54,100,1,13.40,23,1,13.40,0,0,14.00,100,1,13.27,100,1,14.01,100,1,13.23,2,1,14.02,2,1,12.94,100,1,14.26,100,1,12.73,200,2,14.56,800,2,12.65,200,2,14.60,700,1,12.59,200,2,14.61,100,1,12.50,700,1,14.68,700,1,12.49,100,1,14.79,100,1,ARL,285553901
2025-07-17T15:32:28.850288215Z,2025-07-17T15:32:28.850122877Z,160,2,1108,A,A,10,13.54,100,1,13.40,23,1,13.40,0,0,13.98,100,1,13.27,100,1,14.00,100,1,13.23,2,1,14.01,100,1,12.94,100,1,14.02,2,1,12.73,200,2,14.26,100,1,12.65,200,2,14.56,800,2,12.59,200,2,14.60,700,1,12.50,700,1,14.61,100,1,12.49,100,1,14.68,700,1,ARL,285556869
2025-07-17T15:32:28.857140107Z,2025-07-17T15:32:28.856973845Z,160,2,1108,C,A,10,13.54,100,1,13.40,23,1,13.40,0,0,13.98,100,1,13.27,100,1,14.01,100,1,13.23,2,1,14.02,2,1,12.94,100,1,14.26,100,1,12.73,200,2,14.56,800,2,12.65,200,2,14.60,700,1,12.59,200,2,14.61,100,1,12.50,700,1,14.68,700,1,12.49,100,1,14.79,100,1,ARL,283694233
2025-07-17T15:32:29.573634202Z,2025-07-17T15:32:29.573469021Z,160,2,1108,C,B,10,13.40,0,0,13.40,23,1,13.27,100,1,13.98,100,1,13.23,2,1,14.01,100,1,12.94,100,1,14.02,2,1,12.73,200,2,14.26,100,1,12.65,200,2,14.56,800,2,12.59,200,2,14.60,700,1,12.50,700,1,14.61,100,1,12.49,100,1,14.68,700,1,12.46,100,1,14.79,100,1,ARL,285545885
2025-07-17T15:32:29.574368326Z,2025-07-17T15:32:29.574202467Z,160,2,1108,C,B,10,13.40,0,0,13.40,23,1,13.27,100,1,13.98,100,1,13.23,2,1,14.01,100,1,12.94,100,1,14.02,2,1,12.73,200,2,14.26,100,1,12.65,200,2,14.56,800,2,12.59,200,2,14.60,700,1,12.50,700,1,14.61,100,1,12.46,100,1,14.68,700,1,12.43,700,1,14.79,100,1,ARL,285545945
2025-07-17T15:32:29.574368326Z,2025-07-17T15:32:29.574202467Z,160,2,1108,A,B,10,13.40,0,0,13.40,23,1,13.27,100,1,13.98,100,1,13.23,2,1,14.01,100,1,12.94,100,1,14.02,2,1,12.73,200,2,14.26,100,1,12.65,200,2,14.56,800,2,12.59,200,2,14.60,700,1,12.50,700,1,14.61,100,1,12.46,100,1,14.68,700,1,12.43,700,1,14.79,100,1,ARL,285586089
2025-07-17T15:32:29.574371866Z,2025-07-17T15:32:29.574206685Z,160,2,1108,C,B,10,13.40,0,0,13.40,23,1,13.27,100,1,13.98,100,1,13.23,2,1,14.01,100,1,12.73,200,2,14.02,2,1,12.65,200,2,14.26,100,1,12.59,200,2,14.56,800,2,12.50,700,1,14.60,700,1,12.46,100,1,14.61,100,1,12.43,700,1,14.68,700,1,12.42,700,1,14.79,100,1,ARL,285545953
2025-07-17T15:32:29.574722141Z,2025-07-17T15:32:29.574556760Z,160,2,1108,A,B,10,13.40,0,0,13.40,23,1,13.27,100,1,13.98,100,1,13.23,2,1,14.01,100,1,12.73,200,2,14.02,2,1,12.71,100,1,14.26,100,1,12.65,200,2,14.56,800,2,12.59,200,2,14.60,700,1,12.50,700,1,14.61,100,1,12.46,100,1,14.68,700,1,12.43,700,1,14.79,100,1,ARL,285586093
2025-07-17T15:32:29.575134655Z,2025-07-17T15:32:29.574968914Z,160,2,1108,C,B,10,13.40,0,0,13.40,23,1,13.27,100,1,13.98,100,1,13.23,2,1,14.01,100,1,12.73,200,2,14.02,2,1,12.71,100,1,14.26,100,1,12.65,200,2,14.56,800,2,12.59,100,1,14.60,700,1,12.50,700,1,14.61,100,1,12.46,100,1,14.68,700,1,12.43,700,1,14.79,100,1,ARL,285546893
2025-07-17T15:32:29.575134655Z,2025-07-17T15:32:29.574968914Z,160,2,1108,A,B,10,13.40,0,0,13.40,23,1,13.27,100,1,13.98,100,1,13.23,2,1,14.01,100,1,12.73,200,2,14.02,2,1,12.71,100,1,14.26,100,1,12.65,200,2,14.56,800,2,12.59,100,1,14.60,700,1,12.50,700,1,14.61,100,1,12.46,100,1,14.68,700,1,12.43,700,1,14.79,100,1,ARL,285586113
2025-07-17T15:32:29.575550333Z,2025-07-17T15:32:29.575384940Z,160,2,1108,C,B,10,13.40,0,0,13.40,23,1,13.27,100,1,13.98,100,1,13.23,2,1,14.01,100,1,12.73,200,2,14.02,2,1,12.71,100,1,14.26,100,1,12.65,200,2,14.56,800,2,12.59,100,1,14.60,700,1,12.50,700,1,14.61,100,1,12.46,100,1,14.68,700,1,12.43,700,1,14.79,100,1,ARL,285549537
2025-07-17T15:32:29.575550333Z,2025-07-17T15:32:29.575384940Z,160,2,1108,A,B,10,13.40,0,0,13.40,23,1,13.27,100,1,13.98,100,1,13.23,2,1,14.01,100,1,12.73,200,2,14.02,2,1,12.71,100,1,14.26,100,1,12.65,200,2,14.56,800,2,12.59,100,1,14.60,700,1,12.50,700,1,14.61,100,1,12.46,100,1,14.68,700,1,12.43,700,1,14.79,100,1,ARL,285586145
2025-07-17T15:32:29.575821091Z,2025-07-17T15:32:29.575655631Z,160,2,1108,C,B,10,13.40,0,0,13.40,23,1,13.27,100,1,13.98,100,1,13.23,2,1,14.01,100,1,12.73,200,2,14.02,2,1,12.71,100,1,14.26,100,1,12.65,200,2,14.56,800,2,12.59,100,1,14.60,700,1,12.50,700,1,14.61,100,1,12.46,100,1,14.68,700,1,12.43,700,1,14.79,100,1,ARL,285548137
2025-07-17T15:32:29.575821091Z,2025-07-17T15:32:29.575655631Z,160,2,1108,A,B,10,13.40,0,0,13.40,23,1,13.27,100,1,13.98,100,1,13.23,2,1,14.01,100,1,12.73,200,2,14.02,2,1,12.71,100,1,14.26,100,1,12.65,200,2,14.56,800,2,12.59,100,1,14.60,700,1,12.50,700,1,14.61,100,1,12.46,100,1,14.68,700,1,12.43,700,1,14.79,100,1,ARL,285586157
2025-07-17T15:32:29.578317238Z,2025-07-17T15:32:29.578151593Z,160,2,1108,C,B,10,13.40,0,0,13.40,23,1,13.27,100,1,13.98,100,1,13.23,2,1,14.01,100,1,12.73,200,2,14.02,2,1,12.71,100,1,14.26,100,1,12.65,200,2,14.56,800,2,12.50,700,1,14.60,700,1,12.46,100,1,14.61,100,1,12.43,700,1,14.68,700,1,12.42,700,1,14.79,100,1,ARL,285553901
2025-07-17T15:32:29.578317238Z,2025-07-17T15:32:29.578151593Z,160,2,1108,A,B,10,13.40,0,0,13.40,23,1,13.27,100,1,13.98,100,1,13.23,2,1,14.01,100,1,12.73,200,2,14.02,2,1,12.71,100,1,14.26,100,1,12.65,200,2,14.56,800,2,12.50,700,1,14.60,700,1,12.46,100,1,14.61,100,1,12.43,700,1,14.68,700,1,12.42,700,1,14.79,100,1,ARL,285586189
2025-07-17T15:32:29.580933155Z,2025-07-17T15:32:29.580767960Z,160,2,1108,A,B,10,13.40,0,0,13.40,23,1,13.27,100,1,13.98,100,1,13.26,100,1,14.01,100,1,13.23,2,1,14.02,2,1,12.73,200,2,14.26,100,1,12.71,100,1,14.56,800,2,12.65,200,2,14.60,700,1,12.50,700,1,14.61,100,1,12.46,100,1,14.68,700,1,12.43,700,1,14.79,100,1,ARL,285586221
2025-07-17T15:32:29.580952045Z,2025-07-17T15:32:29.580786478Z,160,2,1108,C,A,10,13.40,0,0,13.40,23,1,13.27,100,1,13.98,100,1,13.26,100,1,14.02,2,1,13.23,2,1,14.26,100,1,12.73,200,2,14.56,800,2,12.71,100,1,14.60,700,1,12.65,200,2,14.61,100,1,12.50,700,1,14.68,700,1,12.46,100,1,14.79,100,1,12.43,700,1,14.84,100,1,ARL,283695933
2025-07-17T15:32:29.580952045Z,2025-07-17T15:32:29.580786478Z,160,2,1108,A,A,10,13.40,0,0,13.40,23,1,13.27,100,1,13.98,100,1,13.26,100,1,13.99,100,1,13.23,2,1,14.02,2,1,12.73,200,2,14.26,100,1,12.71,100,1,14.56,800,2,12.65,200,2,14.60,700,1,12.50,700,1,14.61,100,1,12.46,100,1,14.68,700,1,12.43,700,1,14.79,100,1,ARL,285586225
2025-07-17T15:32:29.587192852Z,2025-07-17T15:32:29.587027681Z,160,2,1108,C,B,10,13.40,0,0,13.40,23,1,13.26,100,1,13.98,100,1,13.23,2,1,13.99,100,1,12.73,200,2,14.02,2,1,12.71,100,1,14.26,100,1,12.65,200,2,14.56,800,2,12.50,700,1,14.60,700,1,12.46,100,1,14.61,100,1,12.43,700,1,14.68,700,1,12.42,700,1,14.79,100,1,ARL,285546673
2025-07-17T15:32:29.587246470Z,2025-07-17T15:32:29.587081086Z,160,2,1108,A,B,10,13.40,0,0,13.40,23,1,13.26,100,1,13.98,100,1,13.23,2,1,13.99,100,1,13.03,100,1,14.02,2,1,12.73,200,2,14.26,100,1,12.71,100,1,14.56,800,2,12.65,200,2,14.60,700,1,12.50,700,1,14.61,100,1,12.46,100,1,14.68,700,1,12.43,700,1,14.79,100,1,ARL,285586293
2025-07-17T15:32:29.659679280Z,2025-07-17T15:32:29.659513918Z,160,2,1108,C,B,10,13.40,0,0,13.40,23,1,13.26,100,1,13.98,100,1,13.23,2,1,13.99,100,1,13.03,100,1,14.02,2,1,12.73,100,1,14.26,100,1,12.71,100,1,14.56,800,2,12.65,200,2,14.60,700,1,12.50,700,1,14.61,100,1,12.46,100,1,14.68,700,1,12.43,700,1,14.79,100,1,ARL,285546061
2025-07-17T15:32:29.659679280Z,2025-07-17T15:32:29.659513918Z,160,2,1108,A,B,10,13.40,0,0,13.40,23,1,13.26,100,1,13.98,100,1,13.23,2,1,13.99,100,1,13.03,100,1,14.02,2,1,12.73,100,1,14.26,100,1,12.71,100,1,14.56,800,2,12.65,200,2,14.60,700,1,12.50,700,1,14.61,100,1,12.46,200,2,14.68,700,1,12.43,700,1,14.79,100,1,ARL,285587281
2025-07-17T15:33:04.248156868Z,2025-07-17T15:33:04.247990788Z,160,2,1108,C,A,10,13.40,0,0,13.40,23,1,13.26,100,1,13.98,100,1,13.23,2,1,13.99,100,1,13.03,100,1,14.02,2,1,12.73,100,1,14.26,100,1,12.71,100,1,14.56,800,2,12.65,200,2,14.60,700,1,12.50,700,1,14.61,100,1,12.46,200,2,14.68,700,1,12.43,700,1,14.79,100,1,ARL,283592993
2025-07-17T15:33:04.248156868Z,2025-07-17T15:33:04.247990788Z,160,2,1108,A,A,10,13.40,0,0,13.40,23,1,13.26,100,1,13.98,100,1,13.23,2,1,13.99,100,1,13.03,100,1,14.02,2,1,12.73,100,1,14.26,100,1,12.71,100,1,14.56,800,2,12.65,200,2,14.60,700,1,12.50,700,1,14.61,100,1,12.46,200,2,14.68,700,1,12.43,700,1,14.72,100,1,ARL,286680573
2025-07-17T15:33:04.248189408Z,2025-07-17T15:33:04.248023883Z,160,2,1108,C,A,10,13.40,0,0,13.40,23,1,13.26,100,1,13.98,100,1,13.23,2,1,13.99,100,1,13.03,100,1,14.02,2,1,12.73,100,1,14.26,100,1,12.71,100,1,14.56,800,2,12.65,200,2,14.60,700,1,12.50,700,1,14.61,100,1,12.46,200,2,14.68,700,1,12.43,700,1,14.72,100,1,ARL,283593041
2025-07-17T15:33:04.248189408Z,2025-07-17T15:33:04.248023883Z,160,2,1108,A,A,10,13.40,0,0,13.40,23,1,13.26,100,1,13.98,100,1,13.23,2,1,13.99,100,1,13.03,100,1,14.02,2,1,12.73,100,1,14.26,100,1,12.71,100,1,14.56,800,2,12.65,200,2,14.60,700,1,12.50,700,1,14.61,100,1,12.46,200,2,14.68,700,1,12.43,700,1,14.72,200,2,ARL,286680577
2025-07-17T15:33:04.255712050Z,2025-07-17T15:33:04.255546094Z,160,2,1108,A,A,10,13.40,0,0,13.40,23,1,13.26,100,1,13.84,100,1,13.23,2,1,13.98,100,1,13.03,100,1,13.99,100,1,12.73,100,1,14.02,2,1,12.71,100,1,14.26,100,1,12.65,200,2,14.56,800,2,12.50,700,1,14.60,700,1,12.46,200,2,14.61,100,1,12.43,700,1,14.68,700,1,ARL,286680685
2025-07-17T15:33:04.255777981Z,2025-07-17T15:33:04.255612126Z,160,2,1108,C,B,10,13.40,0,0,13.40,23,1,13.26,100,1,13.84,100,1,13.23,2,1,13.98,100,1,13.03,100,1,13.99,100,1,12.73,100,1,14.02,2,1,12.71,100,1,14.26,100,1,12.65,200,2,14.56,800,2,12.50,700,1,14.60,700,1,12.46,200,2,14.61,100,1,12.43,700,1,14.68,700,1,ARL,285586089
2025-07-17T15:33:04.255777981Z,2025-07-17T15:33:04.255612126Z,160,2,1108,A,B,10,13.40,0,0,13.40,23,1,13.26,100,1,13.84,100,1,13.23,2,1,13.98,100,1,13.03,100,1,13.99,100,1,12.73,100,1,14.02,2,1,12.71,100,1,14.26,100,1,12.65,200,2,14.56,800,2,12.50,700,1,14.60,700,1,12.46,200,2,14.61,100,1,12.43,700,1,14.68,700,1,ARL,286680693
2025-07-17T15:33:04.256438228Z,2025-07-17T15:33:04.256272676Z,160,2,1108,C,A,10,13.40,0,0,13.40,23,1,13.26,100,1,13.84,100,1,13.23,2,1,13.98,100,1,13.03,100,1,13.99,100,1,12.73,100,1,14.02,2,1,12.71,100,1,14.26,100,1,12.65,200,2,14.56,800,2,12.50,700,1,14.60,700,1,12.46,200,2,14.61,100,1,12.43,700,1,14.68,700,1,ARL,283596673
2025-07-17T15:33:04.256438228Z,2025-07-17T15:33:04.256272676Z,160,2,1108,A,A,10,13.40,0,0,13.40,23,1,13.26,100,1,13.84,100,1,13.23,2,1,13.98,100,1,13.03,100,1,13.99,100,1,12.73,100,1,14.02,2,1,12.71,100,1,14.26,100,1,12.65,200,2,14.56,800,2,12.50,700,1,14.60,700,1,12.46,200,2,14.61,100,1,12.43,700,1,14.68,700,1,ARL,286680721
2025-07-17T15:33:04.258080504Z,2025-07-17T15:33:04.257914956Z,160,2,1108,C,A,10,13.40,0,0,13.40,23,1,13.26,100,1,13.84,100,1,13.23,2,1,13.98,100,1,13.03,100,1,13.99,100,1,12.73,100,1,14.02,2,1,12.71,100,1,14.26,100,1,12.65,200,2,14.56,800,2,12.50,700,1,14.60,700,1,12.46,200,2,14.61,100,1,12.43,700,1,14.68,700,1,ARL,283596945
2025-07-17T15:33:04.258080504Z,2025-07-17T15:33:04.257914956Z,160,2,1108,A,A,10,13.40,0,0,13.40,23,1,13.26,100,1,13.84,100,1,13.23,2,1,13.98,100,1,13.03,100,1,13.99,100,1,12.73,100,1,14.02,2,1,12.71,100,1,14.26,100,1,12.65,200,2,14.56,800,2,12.50,700,1,14.60,700,1,12.46,200,2,14.61,100,1,12.43,700,1,14.68,700,1,ARL,286680741
2025-07-17T15:33:04.261684319Z,2025-07-17T15:33:04.261518776Z,160,2,1108,C,A,10,13.40,0,0,13.40,23,1,13.26,100,1,13.84,100,1,13.23,2,1,13.98,100,1,13.03,100,1,13.99,100,1,12.73,100,1,14.02,2,1,12.71,100,1,14.26,100,1,12.65,200,2,14.56,800,2,12.50,700,1,14.60,700,1,12.46,200,2,14.61,100,1,12.43,700,1,14.68,700,1,ARL,283593313
2025-07-17T15:33:04.261684319Z,2025-07-17T15:33:04.261518776Z,160,2,1108,A,A,10,13.40,0,0,13.40,23,1,13.26,100,1,13.84,100,1,13.23,2,1,13.98,100,1,13.03,100,1,13.99,100,1,12.73,100,1,14.02,2,1,12.71,100,1,14.26,100,1,12.65,200,2,14.56,800,2,12.50,700,1,14.60,700,1,12.46,200,2,14.61,100,1,12.43,700,1,14.65,100,1,ARL,286680905
2025-07-17T15:33:04.263011314Z,2025-07-17T15:33:04.262845834Z,160,2,1108,C,A,10,13.40,0,0,13.40,23,1,13.26,100,1,13.84,100,1,13.23,2,1,13.98,100,1,13.03,100,1,13.99,100,1,12.73,100,1,14.02,2,1,12.71,100,1,14.56,800,2,12.65,200,2,14.60,700,1,12.50,700,1,14.61,100,1,12.46,200,2,14.65,100,1,12.43,700,1,14.68,700,1,ARL,283595181
2025-07-17T15:33:04.263052660Z,2025-07-17T15:33:04.262887184Z,160,2,1108,C,A,10,13.40,0,0,13.40,23,1,13.26,100,1,13.84,100,1,13.23,2,1,13.99,100,1,13.03,100,1,14.02,2,1,12.73,100,1,14.56,800,2,12.71,100,1,14.60,700,1,12.65,200,2,14.61,100,1,12.50,700,1,14.65,100,1,12.46,200,2,14.68,700,1,12.43,700,1,14.72,200,2,ARL,285556869
2025-07-17T15:33:04.263065252Z,2025-07-17T15:33:04.262899981Z,160,2,1108,A,A,10,13.40,0,0,13.40,23,1,13.26,100,1,13.84,100,1,13.23,2,1,13.99,100,1,13.03,100,1,14.02,2,1,12.73,100,1,14.12,100,1,12.71,100,1,14.56,800,2,12.65,200,2,14.60,700,1,12.50,700,1,14.61,100,1,12.46,200,2,14.65,100,1,12.43,700,1,14.68,700,1,ARL,286680917
2025-07-17T15:33:04.271212113Z,2025-07-17T15:33:04.271046430Z,160,2,1108,C,A,10,13.40,0,0,13.40,23,1,13.26,100,1,13.84,100,1,13.23,2,1,13.99,100,1,13.03,100,1,14.02,2,1,12.73,100,1,14.12,100,1,12.71,100,1,14.56,800,2,12.65,200,2,14.60,700,1,12.50,700,1,14.61,100,1,12.46,200,2,14.65,100,1,12.43,700,1,14.68,700,1,ARL,283594173
2025-07-17T15:33:04.271212113Z,2025-07-17T15:33:04.271046430Z,160,2,1108,A,A,10,13.40,0,0,13.40,23,1,13.26,100,1,13.84,100,1,13.23,2,1,13.99,100,1,13.03,100,1,14.02,2,1,12.73,100,1,14.12,100,1,12.71,100,1,14.56,800,2,12.65,200,2,14.60,700,1,12.50,700,1,14.61,100,1,12.46,200,2,14.65,100,1,12.43,700,1,14.68,700,1,ARL,286681057
2025-07-17T15:33:04.277880725Z,2025-07-17T15:33:04.277715123Z,160,2,1108,C,A,10,13.40,0,0,13.40,23,1,13.26,100,1,13.84,100,1,13.23,2,1,13.99,100,1,13.03,100,1,14.02,2,1,12.73,100,1,14.12,100,1,12.71,100,1,14.56,800,2,12.65,200,2,14.60,700,1,12.50,700,1,14.61,100,1,12.46,200,2,14.65,100,1,12.43,700,1,14.68,700,1,ARL,283599609
2025-07-17T15:33:04.277880725Z,2025-07-17T15:33:04.277715123Z,160,2,1108,A,A,10,13.40,0,0,13.40,23,1,13.26,100,1,13.84,100,1,13.23,2,1,13.99,100,1,13.03,100,1,14.02,2,1,12.73,100,1,14.12,100,1,12.71,100,1,14.56,800,2,12.65,200,2,14.60,700,1,12.50,700,1,14.61,100,1,12.46,200,2,14.65,100,1,12.43,700,1,14.68,700,1,ARL,286681229
2025-07-17T15:33:04.418840148Z,2025-07-17T15:33:04.418674487Z,160,2,1108,C,A,10,13.40,0,0,13.40,23,1,13.26,100,1,13.84,100,1,13.23,2,1,13.99,100,1,13.03,100,1,14.02,2,1,12.73,100,1,14.12,100,1,12.71,100,1,14.56,800,2,12.65,200,2,14.60,700,1,12.50,700,1,14.61,100,1,12.46,200,2,14.65,100,1,12.43,700,1,14.68,700,1,ARL,283596721
2025-07-17T15:33:04.418840148Z,2025-07-17T15:33:04.418674487Z,160,2,1108,A,A,10,13.40,0,0,13.40,23,1,13.26,100,1,13.84,100,1,13.23,2,1,13.99,100,1,13.03,100,1,14.02,2,1,12.73,100,1,14.12,100,1,12.71,100,1,14.56,800,2,12.65,200,2,14.60,700,1,12.50,700,1,14.61,100,1,12.46,200,2,14.65,100,1,12.43,700,1,14.68,700,1,ARL,286684005
2025-07-17T15:33:05.330854217Z,2025-07-17T15:33:05.330688486Z,160,2,1108,C,A,10,13.40,0,0,13.40,23,1,13.26,100,1,13.84,100,1,13.23,2,1,14.02,2,1,13.03,100,1,14.12,100,1,12.73,100,1,14.56,800,2,12.71,100,1,14.60,700,1,12.65,200,2,14.61,100,1,12.50,700,1,14.65,100,1,12.46,200,2,14.68,700,1,12.43,700,1,14.72,200,2,ARL,285586225
2025-07-17T15:33:05.330854217Z,2025-07-17T15:33:05.330688486Z,160,2,1108,A,A,10,13.40,0,0,13.40,23,1,13.26,100,1,13.84,100,1,13.23,2,1,13.85,100,1,13.03,100,1,14.02,2,1,12.73,100,1,14.12,100,1,12.71,100,1,14.56,800,2,12.65,200,2,14.60,700,1,12.50,700,1,14.61,100,1,12.46,200,2,14.65,100,1,12.43,700,1,14.68,700,1,ARL,286704785
2025-07-17T15:33:06.455979270Z,2025-07-17T15:33:06.455814002Z,160,2,1108,C,A,10,13.40,0,0,13.40,23,1,13.26,100,1,13.85,100,1,13.23,2,1,14.02,2,1,13.03,100,1,14.12,100,1,12.73,100,1,14.56,800,2,12.71,100,1,14.60,700,1,12.65,200,2,14.61,100,1,12.50,700,1,14.65,100,1,12.46,200,2,14.68,700,1,12.43,700,1,14.72,200,2,ARL,286680685
2025-07-17T15:33:10.468005342Z,2025-07-17T15:33:10.467840054Z,160,2,1108,A,A,10,13.40,0,0,13.40,23,1,13.26,100,1,13.85,100,1,13.23,2,1,13.87,100,1,13.03,100,1,14.02,2,1,12.73,100,1,14.12,100,1,12.71,100,1,14.56,800,2,12.65,200,2,14.60,700,1,12.50,700,1,14.61,100,1,12.46,200,2,14.65,100,1,12.43,700,1,14.68,700,1,ARL,286828253
2025-07-17T15:33:40.986585803Z,2025-07-17T15:33:40.986420127Z,160,2,1108,C,A,10,13.40,0,0,13.40,23,1,13.26,100,1,13.85,100,1,13.23,2,1,13.87,100,1,13.03,100,1,14.12,100,1,12.73,100,1,14.56,800,2,12.71,100,1,14.60,700,1,12.65,200,2,14.61,100,1,12.50,700,1,14.65,100,1,12.46,200,2,14.68,700,1,12.43,700,1,14.72,200,2,ARL,283348193
2025-07-17T15:33:40.986585803Z,2025-07-17T15:33:40.986420127Z,160,2,1108,A,A,10,13.40,0,0,13.40,23,1,13.26,100,1,13.85,100,1,13.23,2,1,13.87,100,1,13.03,100,1,13.95,2,1,12.73,100,1,14.12,100,1,12.71,100,1,14.56,800,2,12.65,200,2,14.60,700,1,12.50,700,1,14.61,100,1,12.46,200,2,14.65,100,1,12.43,700,1,14.68,700,1,ARL,287540393
2025-07-17T15:33:41.766184571Z,2025-07-17T15:33:41.766018916Z,160,2,1108,A,A,10,13.40,0,0,13.40,23,1,13.26,100,1,13.82,10,1,13.23,2,1,13.85,100,1,13.03,100,1,13.87,100,1,12.73,100,1,13.95,2,1,12.71,100,1,14.12,100,1,12.65,200,2,14.56,800,2,12.50,700,1,14.60,700,1,12.46,200,2,14.61,100,1,12.43,700,1,14.65,100,1,ARL,287560109
2025-07-17T15:33:41.766265703Z,2025-07-17T15:33:41.766100204Z,160,2,1108,C,A,10,13.40,0,0,13.40,23,1,13.26,100,1,13.82,10,1,13.23,2,1,13.87,100,1,13.03,100,1,13.95,2,1,12.73,100,1,14.12,100,1,12.71,100,1,14.56,800,2,12.65,200,2,14.60,700,1,12.50,700,1,14.61,100,1,12.46,200,2,14.65,100,1,12.43,700,1,14.68,700,1,ARL,286704785
2025-07-17T15:33:41.766265703Z,2025-07-17T15:33:41.766100204Z,160,2,1108,A,A,10,13.40,0,0,13.40,23,1,13.26,100,1,13.82,10,1,13.23,2,1,13.83,100,1,13.03,100,1,13.87,100,1,12.73,100,1,13.95,2,1,12.71,100,1,14.12,100,1,12.65,200,2,14.56,800,2,12.50,700,1,14.60,700,1,12.46,200,2,14.61,100,1,12.43,700,1,14.65,100,1,ARL,287560121
2025-07-17T15:33:41.777404666Z,2025-07-17T15:33:41.777239400Z,160,2,1108,A,A,10,13.40,0,0,13.40,23,1,13.26,100,1,13.82,10,1,13.23,2,1,13.83,100,1,13.03,100,1,13.85,100,1,12.73,100,1,13.87,100,1,12.71,100,1,13.95,2,1,12.65,200,2,14.12,100,1,12.50,700,1,14.56,800,2,12.46,200,2,14.60,700,1,12.43,700,1,14.61,100,1,ARL,287560333
2025-07-17T15:33:41.784121031Z,2025-07-17T15:33:41.783955668Z,160,2,1108,C,A,10,13.40,0,0,13.40,23,1,13.26,100,1,13.82,10,1,13.23,2,1,13.83,100,1,13.03,100,1,13.85,100,1,12.73,100,1,13.95,2,1,12.71,100,1,14.12,100,1,12.65,200,2,14.56,800,2,12.50,700,1,14.60,700,1,12.46,200,2,14.61,100,1,12.43,700,1,14.65,100,1,ARL,286828253
2025-07-17T15:33:42.773141775Z,2025-07-17T15:33:42.772976862Z,160,2,1108,C,A,10,13.40,0,0,13.40,23,1,13.26,100,1,13.83,100,1,13.23,2,1,13.85,100,1,13.03,100,1,13.95,2,1,12.73,100,1,14.12,100,1,12.71,100,1,14.56,800,2,12.65,200,2,14.60,700,1,12.50,700,1,14.61,100,1,12.46,200,2,14.65,100,1,12.43,700,1,14.68,700,1,ARL,287560109
2025-07-17T15:34:28.155773560Z,2025-07-17T15:34:28.155608087Z,160,2,1108,A,A,10,13.40,0,0,13.40,23,1,13.26,100,1,13.83,100,1,13.23,2,1,13.85,100,1,13.03,100,1,13.95,2,1,12.73,100,1,14.12,100,1,12.71,100,1,14.20,50,1,12.65,200,2,14.56,800,2,12.50,700,1,14.60,700,1,12.46,200,2,14.61,100,1,12.43,700,1,14.65,100,1,ARL,288723725
2025-07-17T15:34:28.156815057Z,2025-07-17T15:34:28.156649544Z,160,2,1108,C,B,10,13.40,0,0,13.40,23,1,13.26,100,1,13.83,100,1,13.23,2,1,13.85,100,1,13.03,100,1,13.95,2,1,12.73,100,1,14.12,100,1,12.71,100,1,14.20,50,1,12.65,100,1,14.56,800,2,12.50,700,1,14.60,700,1,12.46,200,2,14.61,100,1,12.43,700,1,14.65,100,1,ARL,236206261
2025-07-17T15:34:28.156815057Z,2025-07-17T15:34:28.156649544Z,160,2,1108,A,B,10,13.40,0,0,13.40,23,1,13.26,100,1,13.83,100,1,13.23,2,1,13.85,100,1,13.03,100,1,13.95,2,1,12.73,100,1,14.12,100,1,12.71,100,1,14.20,50,1,12.65,100,1,14.56,800,2,12.50,700,1,14.60,700,1,12.46,200,2,14.61,100,1,12.43,700,1,14.65,100,1,ARL,288723813
2025-07-17T15:34:28.156884900Z,2025-07-17T15:34:28.156719339Z,160,2,1108,C,B,10,13.40,0,0,13.40,23,1,13.26,100,1,13.83,100,1,13.23,2,1,13.85,100,1,13.03,100,1,13.95,2,1,12.73,100,1,14.12,100,1,12.71,100,1,14.20,50,1,12.50,700,1,14.56,800,2,12.46,200,2,14.60,700,1,12.43,700,1,14.61,100,1,12.42,700,1,14.65,100,1,ARL,236179089
2025-07-17T15:34:28.156884900Z,2025-07-17T15:34:28.156719339Z,160,2,1108,A,B,10,13.40,0,0,13.40,23,1,13.26,100,1,13.83,100,1,13.23,2,1,13.85,100,1,13.03,100,1,13.95,2,1,12.73,100,1,14.12,100,1,12.71,100,1,14.20,50,1,12.50,700,1,14.56,800,2,12.46,200,2,14.60,700,1,12.43,700,1,14.61,100,1,12.42,700,1,14.65,100,1,ARL,288723817
2025-07-17T15:34:28.164796058Z,2025-07-17T15:34:28.164629965Z,160,2,1108,T,N,10,13.40,0,0,13.40,23,1,13.26,100,1,13.83,100,1,13.23,2,1,13.85,100,1,13.03,100,1,13.95,2,1,12.73,100,1,14.12,100,1,12.71,100,1,14.20,50,1,12.50,700,1,14.56,800,2,12.46,200,2,14.60,700,1,12.43,700,1,14.61,100,1,12.42,700,1,14.65,100,1,ARL,0
2025-07-17T15:34:28.165386986Z,2025-07-17T15:34:28.165221345Z,160,2,1108,T,N,10,13.40,0,0,13.40,23,1,13.26,100,1,13.83,100,1,13.23,2,1,13.85,100,1,13.03,100,1,13.95,2,1,12.73,100,1,14.12,100,1,12.71,100,1,14.20,50,1,12.50,700,1,14.56,800,2,12.46,200,2,14.60,700,1,12.43,700,1,14.61,100,1,12.42,700,1,14.65,100,1,ARL,0
2025-07-17T15:34:28.166683461Z,2025-07-17T15:34:28.166516235Z,160,2,1108,T,N,10,13.40,0,0,13.40,23,1,13.26,100,1,13.83,100,1,13.23,2,1,13.85,100,1,13.03,100,1,13.95,2,1,12.73,100,1,14.12,100,1,12.71,100,1,14.20,50,1,12.50,700,1,14.56,800,2,12.46,200,2,14.60,700,1,12.43,700,1,14.61,100,1,12.42,700,1,14.65,100,1,ARL,0
2025-07-17T15:34:28.166683461Z,2025-07-17T15:34:28.166516235Z,160,2,1108,T,N,10,13.40,0,0,13.40,23,1,13.26,100,1,13.83,100,1,13.23,2,1,13.85,100,1,13.03,100,1,13.95,2,1,12.73,100,1,14.12,100,1,12.71,100,1,14.20,50,1,12.50,700,1,14.56,800,2,12.46,200,2,14.60,700,1,12.43,700,1,14.61,100,1,12.42,700,1,14.65,100,1,ARL,0
2025-07-17T15:34:28.170740864Z,2025-07-17T15:34:28.170575785Z,160,2,1108,A,A,10,13.40,0,0,13.40,23,1,13.26,100,1,13.81,50,1,13.23,2,1,13.83,100,1,13.03,100,1,13.85,100,1,12.73,100,1,13.95,2,1,12.71,100,1,14.12,100,1,12.50,700,1,14.20,50,1,12.46,200,2,14.56,800,2,12.43,700,1,14.60,700,1,12.42,700,1,14.61,100,1,ARL,288724173
2025-07-17T15:34:28.170792211Z,2025-07-17T15:34:28.170626756Z,160,2,1108,C,B,10,13.40,0,0,13.40,23,1,13.23,2,1,13.81,50,1,13.03,100,1,13.83,100,1,12.73,100,1,13.85,100,1,12.71,100,1,13.95,2,1,12.50,700,1,14.12,100,1,12.46,200,2,14.20,50,1,12.43,700,1,14.56,800,2,12.42,700,1,14.60,700,1,12.37,700,1,14.61,100,1,ARL,285586221
2025-07-17T15:34:28.171437442Z,2025-07-17T15:34:28.171272157Z,160,2,1108,A,A,10,13.40,0,0,13.40,23,1,13.23,2,1,13.78,2,1,13.03,100,1,13.81,50,1,12.73,100,1,13.83,100,1,12.71,100,1,13.85,100,1,12.50,700,1,13.95,2,1,12.46,200,2,14.12,100,1,12.43,700,1,14.20,50,1,12.42,700,1,14.56,800,2,12.37,700,1,14.60,700,1,ARL,288724201
2025-07-17T15:34:28.171604993Z,2025-07-17T15:34:28.171439252Z,160,2,1108,T,N,10,13.40,0,0,13.40,23,1,13.23,2,1,13.78,2,1,13.03,100,1,13.81,50,1,12.73,100,1,13.83,100,1,12.71,100,1,13.85,100,1,12.50,700,1,13.95,2,1,12.46,200,2,14.12,100,1,12.43,700,1,14.20,50,1,12.42,700,1,14.56,800,2,12.37,700,1,14.60,700,1,ARL,0
2025-07-17T15:34:28.172057926Z,2025-07-17T15:34:28.171892519Z,160,2,1108,A,B,10,13.40,0,0,13.40,23,1,13.31,10,1,13.78,2,1,13.23,2,1,13.81,50,1,13.03,100,1,13.83,100,1,12.73,100,1,13.85,100,1,12.71,100,1,13.95,2,1,12.50,700,1,14.12,100,1,12.46,200,2,14.20,50,1,12.43,700,1,14.56,800,2,12.42,700,1,14.60,700,1,ARL,288724225
2025-07-17T15:34:28.172058708Z,2025-07-17T15:34:28.171893498Z,160,2,1108,A,A,10,13.40,0,0,13.40,23,1,13.31,10,1,13.78,2,1,13.23,2,1,13.81,50,1,13.03,100,1,13.82,10,1,12.73,100,1,13.83,100,1,12.71,100,1,13.85,100,1,12.50,700,1,13.95,2,1,12.46,200,2,14.12,100,1,12.43,700,1,14.20,50,1,12.42,700,1,14.56,800,2,ARL,288724229
2025-07-17T15:34:28.175011712Z,2025-07-17T15:34:28.174846475Z,160,2,1108,A,B,10,13.40,0,0,13.40,23,1,13.31,10,1,13.78,2,1,13.30,100,1,13.81,50,1,13.23,2,1,13.82,10,1,13.03,100,1,13.83,100,1,12.73,100,1,13.85,100,1,12.71,100,1,13.95,2,1,12.50,700,1,14.12,100,1,12.46,200,2,14.20,50,1,12.43,700,1,14.56,800,2,ARL,288724429
2025-07-17T15:34:28.175030125Z,2025-07-17T15:34:28.174864618Z,160,2,1108,C,A,10,13.40,0,0,13.40,23,1,13.31,10,1,13.78,2,1,13.30,100,1,13.81,50,1,13.23,2,1,13.82,10,1,13.03,100,1,13.85,100,1,12.73,100,1,13.95,2,1,12.71,100,1,14.12,100,1,12.50,700,1,14.20,50,1,12.46,200,2,14.56,800,2,12.43,700,1,14.60,700,1,ARL,287560121
2025-07-17T15:34:28.175030125Z,2025-07-17T15:34:28.174864618Z,160,2,1108,A,A,10,13.40,0,0,13.40,23,1,13.31,10,1,13.78,2,1,13.30,100,1,13.79,100,1,13.23,2,1,13.81,50,1,13.03,100,1,13.82,10,1,12.73,100,1,13.85,100,1,12.71,100,1,13.95,2,1,12.50,700,1,14.12,100,1,12.46,200,2,14.20,50,1,12.43,700,1,14.56,800,2,ARL,288724433
2025-07-17T15:34:28.175329569Z,2025-07-17T15:34:28.175164464Z,160,2,1108,C,A,10,13.40,0,0,13.40,23,1,13.31,10,1,13.79,100,1,13.30,100,1,13.81,50,1,13.23,2,1,13.82,10,1,13.03,100,1,13.85,100,1,12.73,100,1,13.95,2,1,12.71,100,1,14.12,100,1,12.50,700,1,14.20,50,1,12.46,200,2,14.56,800,2,12.43,700,1,14.60,700,1,ARL,288724201
2025-07-17T15:34:28.175752130Z,2025-07-17T15:34:28.175586497Z,160,2,1108,C,B,10,13.40,0,0,13.40,23,1,13.31,10,1,13.79,100,1,13.30,100,1,13.81,50,1,13.23,2,1,13.82,10,1,13.03,100,1,13.85,100,1,12.73,100,1,13.95,2,1,12.71,100,1,14.12,100,1,12.50,700,1,14.20,50,1,12.46,200,2,14.56,800,2,12.43,700,1,14.60,700,1,ARL,286680693
2025-07-17T15:34:28.175752130Z,2025-07-17T15:34:28.175586497Z,160,2,1108,A,B,10,13.40,0,0,13.40,23,1,13.31,10,1,13.79,100,1,13.30,100,1,13.81,50,1,13.23,2,1,13.82,10,1,13.03,100,1,13.85,100,1,12.73,100,1,13.95,2,1,12.71,100,1,14.12,100,1,12.50,700,1,14.20,50,1,12.46,200,2,14.56,800,2,12.43,700,1,14.60,700,1,ARL,288724485
2025-07-17T15:34:28.175767666Z,2025-07-17T15:34:28.175602100Z,160,2,1108,C,A,10,13.40,0,0,13.40,23,1,13.31,10,1,13.79,100,1,13.30,100,1,13.81,50,1,13.23,2,1,13.82,10,1,13.03,100,1,13.85,100,1,12.73,100,1,13.95,2,1,12.71,100,1,14.12,100,1,12.50,700,1,14.20,50,1,12.46,200,2,14.56,800,2,12.43,700,1,14.60,700,1,ARL,286680721
2025-07-17T15:34:28.175767666Z,2025-07-17T15:34:28.175602100Z,160,2,1108,A,A,10,13.40,0,0,13.40,23,1,13.31,10,1,13.79,100,1,13.30,100,1,13.81,50,1,13.23,2,1,13.82,10,1,13.03,100,1,13.85,100,1,12.73,100,1,13.95,2,1,12.71,100,1,14.12,100,1,12.50,700,1,14.20,50,1,12.46,200,2,14.56,800,2,12.43,700,1,14.60,700,1,ARL,288724489
2025-07-17T15:34:28.180356536Z,2025-07-17T15:34:28.180191067Z,160,2,1108,A,A,10,13.40,0,0,13.40,23,1,13.31,10,1,13.79,100,1,13.30,100,1,13.80,100,1,13.23,2,1,13.81,50,1,13.03,100,1,13.82,10,1,12.73,100,1,13.85,100,1,12.71,100,1,13.95,2,1,12.50,700,1,14.12,100,1,12.46,200,2,14.20,50,1,12.43,700,1,14.56,800,2,ARL,288724565
2025-07-17T15:34:28.187237384Z,2025-07-17T15:34:28.187072050Z,160,2,1108,C,A,10,13.40,0,0,13.40,23,1,13.31,10,1,13.79,100,1,13.30,100,1,13.80,100,1,13.23,2,1,13.81,50,1,13.03,100,1,13.82,10,1,12.73,100,1,13.95,2,1,12.71,100,1,14.12,100,1,12.50,700,1,14.20,50,1,12.46,200,2,14.56,800,2,12.43,700,1,14.60,700,1,ARL,287560333
2025-07-17T15:34:28.192269421Z,2025-07-17T15:34:28.192104387Z,160,2,1108,C,A,10,13.40,0,0,13.40,23,1,13.31,10,1,13.80,100,1,13.30,100,1,13.81,50,1,13.23,2,1,13.82,10,1,13.03,100,1,13.95,2,1,12.73,100,1,14.12,100,1,12.71,100,1,14.20,50,1,12.50,700,1,14.56,800,2,12.46,200,2,14.60,700,1,12.43,700,1,14.61,100,1,ARL,288724433
2025-07-17T15:34:28.231601320Z,2025-07-17T15:34:28.231436134Z,160,2,1108,A,A,10,13.40,0,0,13.40,23,1,13.31,10,1,13.80,100,1,13.30,100,1,13.81,50,1,13.23,2,1,13.82,10,1,13.03,100,1,13.83,100,1,12.73,100,1,13.95,2,1,12.71,100,1,14.12,100,1,12.50,700,1,14.20,50,1,12.46,200,2,14.56,800,2,12.43,700,1,14.60,700,1,ARL,288725173
2025-07-17T15:34:28.256123809Z,2025-07-17T15:34:28.255958718Z,160,2,1108,C,A,10,13.40,0,0,13.40,23,1,13.31,10,1,13.80,100,1,13.30,100,1,13.81,50,1,13.23,2,1,13.82,10,1,13.03,100,1,13.83,100,1,12.73,100,1,13.95,2,1,12.71,100,1,14.12,100,1,12.50,700,1,14.56,800,2,12.46,200,2,14.60,700,1,12.43,700,1,14.61,100,1,ARL,288723725
2025-07-17T15:34:28.271275449Z,2025-07-17T15:34:28.271110273Z,160,2,1108,C,A,10,13.40,0,0,13.40,23,1,13.31,10,1,13.80,100,1,13.30,100,1,13.82,10,1,13.23,2,1,13.83,100,1,13.03,100,1,13.95,2,1,12.73,100,1,14.12,100,1,12.71,100,1,14.56,800,2,12.50,700,1,14.60,700,1,12.46,200,2,14.61,100,1,12.43,700,1,14.65,100,1,ARL,288724173
2025-07-17T15:34:28.281217370Z,2025-07-17T15:34:28.281052249Z,160,2,1108,C,A,10,13.40,0,0,13.40,23,1,13.31,10,1,13.82,10,1,13.30,100,1,13.83,100,1,13.23,2,1,13.95,2,1,13.03,100,1,14.12,100,1,12.73,100,1,14.56,800,2,12.71,100,1,14.60,700,1,12.50,700,1,14.61,100,1,12.46,200,2,14.65,100,1,12.43,700,1,14.68,700,1,ARL,288724565
2025-07-17T15:34:28.281945481Z,2025-07-17T15:34:28.281780230Z,160,2,1108,C,A,10,13.40,0,0,13.40,23,1,13.31,10,1,13.82,10,1,13.30,100,1,13.83,100,1,13.23,2,1,13.95,2,1,13.03,100,1,14.12,100,1,12.73,100,1,14.56,800,2,12.71,100,1,14.60,700,1,12.50,700,1,14.61,100,1,12.46,200,2,14.65,100,1,12.43,700,1,14.68,700,1,ARL,288724489
2025-07-17T15:34:28.281945481Z,2025-07-17T15:34:28.281780230Z,160,2,1108,A,A,10,13.40,0,0,13.40,23,1,13.31,10,1,13.82,10,1,13.30,100,1,13.83,100,1,13.23,2,1,13.95,2,1,13.03,100,1,14.12,100,1,12.73,100,1,14.56,800,2,12.71,100,1,14.60,700,1,12.50,700,1,14.61,100,1,12.46,200,2,14.65,100,1,12.43,700,1,14.68,700,1,ARL,288726085
2025-07-17T15:34:32.289409612Z,2025-07-17T15:34:32.289244370Z,160,2,1108,A,A,10,13.40,0,0,13.40,23,1,13.31,10,1,13.82,10,1,13.30,100,1,13.83,100,1,13.23,2,1,13.84,100,1,13.03,100,1,13.95,2,1,12.73,100,1,14.12,100,1,12.71,100,1,14.56,800,2,12.50,700,1,14.60,700,1,12.46,200,2,14.61,100,1,12.43,700,1,14.65,100,1,ARL,288845417
2025-07-17T15:34:39.864692027Z,2025-07-17T15:34:39.864526516Z,160,2,1108,A,A,10,13.40,0,0,13.40,23,1,13.31,10,1,13.80,15,1,13.30,100,1,13.82,10,1,13.23,2,1,13.83,100,1,13.03,100,1,13.84,100,1,12.73,100,1,13.95,2,1,12.71,100,1,14.12,100,1,12.50,700,1,14.56,800,2,12.46,200,2,14.60,700,1,12.43,700,1,14.61,100,1,ARL,289055901
2025-07-17T15:34:39.865337932Z,2025-07-17T15:34:39.865171719Z,160,2,1108,C,A,10,13.40,0,0,13.40,23,1,13.31,10,1,13.80,15,1,13.30,100,1,13.82,10,1,13.23,2,1,13.84,100,1,13.03,100,1,13.95,2,1,12.73,100,1,14.12,100,1,12.71,100,1,14.56,800,2,12.50,700,1,14.60,700,1,12.46,200,2,14.61,100,1,12.43,700,1,14.65,100,1,ARL,288725173
2025-07-17T15:34:39.865337932Z,2025-07-17T15:34:39.865171719Z,160,2,1108,A,A,10,13.40,0,0,13.40,23,1,13.31,10,1,13.80,15,1,13.30,100,1,13.81,100,1,13.23,2,1,13.82,10,1,13.03,100,1,13.84,100,1,12.73,100,1,13.95,2,1,12.71,100,1,14.12,100,1,12.50,700,1,14.56,800,2,12.46,200,2,14.60,700,1,12.43,700,1,14.61,100,1,ARL,289056097
2025-07-17T15:34:39.869175972Z,2025-07-17T15:34:39.869009668Z,160,2,1108,T,N,10,13.40,0,0,13.40,23,1,13.31,10,1,13.80,15,1,13.30,100,1,13.81,100,1,13.23,2,1,13.82,10,1,13.03,100,1,13.84,100,1,12.73,100,1,13.95,2,1,12.71,100,1,14.12,100,1,12.50,700,1,14.56,800,2,12.46,200,2,14.60,700,1,12.43,700,1,14.61,100,1,ARL,0
2025-07-17T15:34:39.871606986Z,2025-07-17T15:34:39.871441822Z,160,2,1108,A,A,10,13.40,0,0,13.40,23,1,13.31,10,1,13.80,15,1,13.30,100,1,13.81,200,2,13.23,2,1,13.82,10,1,13.03,100,1,13.84,100,1,12.73,100,1,13.95,2,1,12.71,100,1,14.12,100,1,12.50,700,1,14.56,800,2,12.46,200,2,14.60,700,1,12.43,700,1,14.61,100,1,ARL,289056353
2025-07-17T15:34:39.878645012Z,2025-07-17T15:34:39.878479562Z,160,2,1108,C,A,10,13.40,0,0,13.40,23,1,13.31,10,1,13.80,15,1,13.30,100,1,13.81,200,2,13.23,2,1,13.82,10,1,13.03,100,1,13.95,2,1,12.73,100,1,14.12,100,1,12.71,100,1,14.56,800,2,12.50,700,1,14.60,700,1,12.46,200,2,14.61,100,1,12.43,700,1,14.65,100,1,ARL,288845417
2025-07-17T15:34:42.774190041Z,2025-07-17T15:34:42.774024574Z,160,2,1108,C,B,10,13.40,0,0,13.40,23,1,13.30,100,1,13.80,15,1,13.23,2,1,13.81,200,2,13.03,100,1,13.82,10,1,12.73,100,1,13.95,2,1,12.71,100,1,14.12,100,1,12.50,700,1,14.56,800,2,12.46,200,2,14.60,700,1,12.43,700,1,14.61,100,1,12.42,700,1,14.65,100,1,ARL,288724225
2025-07-17T15:34:42.775304741Z,2025-07-17T15:34:42.775139521Z,160,2,1108,C,A,10,13.40,0,0,13.40,23,1,13.30,100,1,13.80,15,1,13.23,2,1,13.81,100,1,13.03,100,1,13.82,10,1,12.73,100,1,13.95,2,1,12.71,100,1,14.12,100,1,12.50,700,1,14.56,800,2,12.46,200,2,14.60,700,1,12.43,700,1,14.61,100,1,12.42,700,1,14.65,100,1,ARL,289056353
2025-07-17T15:34:46.774087945Z,2025-07-17T15:34:46.773922586Z,160,2,1108,C,A,10,13.40,0,0,13.40,23,1,13.30,100,1,13.81,100,1,13.23,2,1,13.82,10,1,13.03,100,1,13.95,2,1,12.73,100,1,14.12,100,1,12.71,100,1,14.56,800,2,12.50,700,1,14.60,700,1,12.46,200,2,14.61,100,1,12.43,700,1,14.65,100,1,12.42,700,1,14.68,700,1,ARL,289055901
2025-07-17T15:34:46.800955057Z,2025-07-17T15:34:46.800789632Z,160,2,1108,A,A,10,13.40,0,0,13.40,23,1,13.30,100,1,13.81,100,1,13.23,2,1,13.82,10,1,13.03,100,1,13.83,100,1,12.73,100,1,13.95,2,1,12.71,100,1,14.12,100,1,12.50,700,1,14.56,800,2,12.46,200,2,14.60,700,1,12.43,700,1,14.61,100,1,12.42,700,1,14.65,100,1,ARL,289199221
2025-07-17T15:34:53.545830704Z,2025-07-17T15:34:53.545665068Z,160,2,1108,C,A,10,13.40,0,0,13.40,23,1,13.30,100,1,13.81,100,1,13.23,2,1,13.83,100,1,13.03,100,1,13.95,2,1,12.73,100,1,14.12,100,1,12.71,100,1,14.56,800,2,12.50,700,1,14.60,700,1,12.46,200,2,14.61,100,1,12.43,700,1,14.65,100,1,12.42,700,1,14.68,700,1,ARL,288724229
2025-07-17T15:35:05.620763928Z,2025-07-17T15:35:05.620598378Z,160,2,1108,A,A,10,13.40,0,0,13.40,23,1,13.30,100,1,13.77,15,1,13.23,2,1,13.81,100,1,13.03,100,1,13.83,100,1,12.73,100,1,13.95,2,1,12.71,100,1,14.12,100,1,12.50,700,1,14.56,800,2,12.46,200,2,14.60,700,1,12.43,700,1,14.61,100,1,12.42,700,1,14.65,100,1,ARL,289722397
2025-07-17T15:35:05.712575243Z,2025-07-17T15:35:05.712409728Z,160,2,1108,C,A,10,13.40,0,0,13.40,23,1,13.30,100,1,13.77,15,1,13.23,2,1,13.83,100,1,13.03,100,1,13.95,2,1,12.73,100,1,14.12,100,1,12.71,100,1,14.56,800,2,12.50,700,1,14.60,700,1,12.46,200,2,14.61,100,1,12.43,700,1,14.65,100,1,12.42,700,1,14.68,700,1,ARL,289056097
2025-07-17T15:35:05.712575243Z,2025-07-17T15:35:05.712409728Z,160,2,1108,A,A,10,13.40,0,0,13.40,23,1,13.30,100,1,13.77,15,1,13.23,2,1,13.78,100,1,13.03,100,1,13.83,100,1,12.73,100,1,13.95,2,1,12.71,100,1,14.12,100,1,12.50,700,1,14.56,800,2,12.46,200,2,14.60,700,1,12.43,700,1,14.61,100,1,12.42,700,1,14.65,100,1,ARL,289726281
2025-07-17T15:35:05.713315450Z,2025-07-17T15:35:05.713150123Z,160,2,1108,C,A,10,13.40,0,0,13.40,23,1,13.30,100,1,13.77,15,1,13.23,2,1,13.78,100,1,13.03,100,1,13.83,100,1,12.73,100,1,13.95,2,1,12.71,100,1,14.12,100,1,12.50,700,1,14.56,800,2,12.46,200,2,14.60,700,1,12.43,700,1,14.65,100,1,12.42,700,1,14.68,700,1,ARL,237978629
2025-07-17T15:35:05.713322577Z,2025-07-17T15:35:05.713157077Z,160,2,1108,C,A,10,13.40,0,0,13.40,23,1,13.30,100,1,13.77,15,1,13.23,2,1,13.78,100,1,13.03,100,1,13.83,100,1,12.73,100,1,13.95,2,1,12.71,100,1,14.12,100,1,12.50,700,1,14.56,800,2,12.46,200,2,14.60,700,1,12.43,700,1,14.65,100,1,12.42,700,1,14.68,700,1,ARL,288726085
2025-07-17T15:35:05.713322577Z,2025-07-17T15:35:05.713157077Z,160,2,1108,A,A,10,13.40,0,0,13.40,23,1,13.30,100,1,13.77,15,1,13.23,2,1,13.78,100,1,13.03,100,1,13.83,100,1,12.73,100,1,13.95,2,1,12.71,100,1,14.12,100,1,12.50,700,1,14.56,800,2,12.46,200,2,14.60,700,1,12.43,700,1,14.65,100,1,12.42,700,1,14.68,700,1,ARL,289726349
2025-07-17T15:35:05.713677091Z,2025-07-17T15:35:05.713508657Z,160,2,1108,A,A,10,13.40,0,0,13.40,23,1,13.30,100,1,13.77,15,1,13.23,2,1,13.78,100,1,13.03,100,1,13.83,100,1,12.73,100,1,13.95,2,1,12.71,100,1,14.12,100,1,12.50,700,1,14.40,100,1,12.46,200,2,14.56,800,2,12.43,700,1,14.60,700,1,12.42,700,1,14.65,100,1,ARL,289726421
2025-07-17T15:35:05.729568877Z,2025-07-17T15:35:05.729398505Z,160,2,1108,A,A,10,13.40,0,0,13.40,23,1,13.30,100,1,13.77,15,1,13.23,2,1,13.78,100,1,13.03,100,1,13.80,100,1,12.73,100,1,13.83,100,1,12.71,100,1,13.95,2,1,12.50,700,1,14.12,100,1,12.46,200,2,14.40,100,1,12.43,700,1,14.56,800,2,12.42,700,1,14.60,700,1,ARL,289730309
2025-07-17T15:35:05.737967956Z,2025-07-17T15:35:05.737802616Z,160,2,1108,C,A,10,13.40,0,0,13.40,23,1,13.30,100,1,13.77,15,1,13.23,2,1,13.78,100,1,13.03,100,1,13.80,100,1,12.73,100,1,13.95,2,1,12.71,100,1,14.12,100,1,12.50,700,1,14.40,100,1,12.46,200,2,14.56,800,2,12.43,700,1,14.60,700,1,12.42,700,1,14.65,100,1,ARL,289199221
2025-07-17T15:35:06.286572335Z,2025-07-17T15:35:06.286407017Z,160,2,1108,C,A,10,13.40,0,0,13.40,23,1,13.30,100,1,13.78,100,1,13.23,2,1,13.80,100,1,13.03,100,1,13.95,2,1,12.73,100,1,14.12,100,1,12.71,100,1,14.40,100,1,12.50,700,1,14.56,800,2,12.46,200,2,14.60,700,1,12.43,700,1,14.65,100,1,12.42,700,1,14.68,700,1,ARL,289722397
2025-07-17T15:35:09.788280931Z,2025-07-17T15:35:09.788115219Z,160,2,1108,C,B,10,13.40,0,0,13.40,23,1,13.30,100,1,13.78,100,1,13.03,100,1,13.80,100,1,12.73,100,1,13.95,2,1,12.71,100,1,14.12,100,1,12.50,700,1,14.40,100,1,12.46,200,2,14.56,800,2,12.43,700,1,14.60,700,1,12.42,700,1,14.65,100,1,12.37,700,1,14.68,700,1,ARL,272263853
2025-07-17T15:35:09.788280931Z,2025-07-17T15:35:09.788115219Z,160,2,1108,A,B,10,13.40,0,0,13.40,23,1,13.30,100,1,13.78,100,1,13.14,2,1,13.80,100,1,13.03,100,1,13.95,2,1,12.73,100,1,14.12,100,1,12.71,100,1,14.40,100,1,12.50,700,1,14.56,800,2,12.46,200,2,14.60,700,1,12.43,700,1,14.65,100,1,12.42,700,1,14.68,700,1,ARL,289828293
2025-07-17T15:35:11.891867009Z,2025-07-17T15:35:11.891701845Z,160,2,1108,C,A,10,13.40,0,0,13.40,23,1,13.30,100,1,13.78,100,1,13.14,2,1,13.95,2,1,13.03,100,1,14.12,100,1,12.73,100,1,14.40,100,1,12.71,100,1,14.56,800,2,12.50,700,1,14.60,700,1,12.46,200,2,14.65,100,1,12.43,700,1,14.68,700,1,12.42,700,1,14.72,200,2,ARL,289730309
2025-07-17T15:35:14.301647013Z,2025-07-17T15:35:14.301481698Z,160,2,1108,A,A,10,13.40,0,0,13.40,23,1,13.30,100,1,13.78,100,1,13.14,2,1,13.95,2,1,13.03,100,1,14.12,100,1,12.73,100,1,14.40,100,1,12.71,100,1,14.56,800,2,12.50,700,1,14.60,700,1,12.46,200,2,14.65,100,1,12.43,700,1,14.68,1400,2,12.42,700,1,14.72,200,2,ARL,289932801
2025-07-17T15:35:14.302443648Z,2025-07-17T15:35:14.302278179Z,160,2,1108,C,A,10,13.40,0,0,13.40,23,1,13.30,100,1,13.78,100,1,13.14,2,1,13.95,2,1,13.03,100,1,14.12,100,1,12.73,100,1,14.40,100,1,12.71,100,1,14.56,800,2,12.50,700,1,14.60,700,1,12.46,200,2,14.65,100,1,12.43,700,1,14.68,1400,2,12.42,700,1,14.72,200,2,ARL,147217629
2025-07-17T15:35:15.940644416Z,2025-07-17T15:35:15.940479233Z,160,2,1108,A,A,10,13.40,0,0,13.40,23,1,13.30,100,1,13.78,100,1,13.14,2,1,13.82,100,1,13.03,100,1,13.95,2,1,12.73,100,1,14.12,100,1,12.71,100,1,14.40,100,1,12.50,700,1,14.56,800,2,12.46,200,2,14.60,700,1,12.43,700,1,14.65,100,1,12.42,700,1,14.68,1400,2,ARL,289976125
2025-07-17T15:35:23.746674314Z,2025-07-17T15:35:23.746509184Z,160,2,1108,A,A,10,13.40,0,0,13.40,23,1,13.30,100,1,13.78,100,1,13.14,2,1,13.80,100,1,13.03,100,1,13.82,100,1,12.73,100,1,13.95,2,1,12.71,100,1,14.12,100,1,12.50,700,1,14.40,100,1,12.46,200,2,14.56,800,2,12.43,700,1,14.60,700,1,12.42,700,1,14.65,100,1,ARL,290159301
2025-07-17T15:35:23.754618546Z,2025-07-17T15:35:23.754453294Z,160,2,1108,C,A,10,13.40,0,0,13.40,23,1,13.30,100,1,13.78,100,1,13.14,2,1,13.80,100,1,13.03,100,1,13.95,2,1,12.73,100,1,14.12,100,1,12.71,100,1,14.40,100,1,12.50,700,1,14.56,800,2,12.46,200,2,14.60,700,1,12.43,700,1,14.65,100,1,12.42,700,1,14.68,1400,2,ARL,289976125
2025-07-17T15:35:39.056679600Z,2025-07-17T15:35:39.056513985Z,160,2,1108,C,A,10,13.40,0,0,13.40,23,1,13.30,100,1,13.78,100,1,13.14,2,1,13.95,2,1,13.03,100,1,14.12,100,1,12.73,100,1,14.40,100,1,12.71,100,1,14.56,800,2,12.50,700,1,14.60,700,1,12.46,200,2,14.65,100,1,12.43,700,1,14.68,1400,2,12.42,700,1,14.72,200,2,ARL,290159301
2025-07-17T15:35:43.128809717Z,2025-07-17T15:35:43.128644252Z,160,2,1108,A,A,10,13.40,0,0,13.40,23,1,13.30,100,1,13.78,100,1,13.14,2,1,13.82,100,1,13.03,100,1,13.95,2,1,12.73,100,1,14.12,100,1,12.71,100,1,14.40,100,1,12.50,700,1,14.56,800,2,12.46,200,2,14.60,700,1,12.43,700,1,14.65,100,1,12.42,700,1,14.68,1400,2,ARL,290630573
2025-07-17T15:36:30.044094509Z,2025-07-17T15:36:30.043928872Z,160,2,1108,A,A,10,13.40,0,0,13.40,23,1,13.30,100,1,13.78,100,1,13.14,2,1,13.80,100,1,13.03,100,1,13.82,100,1,12.73,100,1,13.95,2,1,12.71,100,1,14.12,100,1,12.50,700,1,14.40,100,1,12.46,200,2,14.56,800,2,12.43,700,1,14.60,700,1,12.42,700,1,14.65,100,1,ARL,291778909
2025-07-17T15:36:30.051045453Z,2025-07-17T15:36:30.050880126Z,160,2,1108,C,A,10,13.40,0,0,13.40,23,1,13.30,100,1,13.78,100,1,13.14,2,1,13.80,100,1,13.03,100,1,13.95,2,1,12.73,100,1,14.12,100,1,12.71,100,1,14.40,100,1,12.50,700,1,14.56,800,2,12.46,200,2,14.60,700,1,12.43,700,1,14.65,100,1,12.42,700,1,14.68,1400,2,ARL,290630573
2025-07-17T15:36:34.298010005Z,2025-07-17T15:36:34.297844579Z,160,2,1108,C,B,10,13.40,0,0,13.40,23,1,13.14,2,1,13.78,100,1,13.03,100,1,13.80,100,1,12.73,100,1,13.95,2,1,12.71,100,1,14.12,100,1,12.50,700,1,14.40,100,1,12.46,200,2,14.56,800,2,12.43,700,1,14.60,700,1,12.42,700,1,14.65,100,1,12.37,700,1,14.68,1400,2,ARL,288724429
2025-07-17T15:36:35.381330809Z,2025-07-17T15:36:35.381165559Z,160,2,1108,A,B,10,13.40,0,0,13.40,23,1,13.14,2,1,13.78,100,1,13.13,100,1,13.80,100,1,13.03,100,1,13.95,2,1,12.73,100,1,14.12,100,1,12.71,100,1,14.40,100,1,12.50,700,1,14.56,800,2,12.46,200,2,14.60,700,1,12.43,700,1,14.65,100,1,12.42,700,1,14.68,1400,2,ARL,291951937
2025-07-17T15:36:35.532851032Z,2025-07-17T15:36:35.532685683Z,160,2,1108,A,B,10,13.40,0,0,13.40,23,1,13.27,10,1,13.78,100,1,13.14,2,1,13.80,100,1,13.13,100,1,13.95,2,1,13.03,100,1,14.12,100,1,12.73,100,1,14.40,100,1,12.71,100,1,14.56,800,2,12.50,700,1,14.60,700,1,12.46,200,2,14.65,100,1,12.43,700,1,14.68,1400,2,ARL,291964737
2025-07-17T15:36:35.532926951Z,2025-07-17T15:36:35.532761335Z,160,2,1108,C,B,10,13.40,0,0,13.40,23,1,13.27,10,1,13.78,100,1,13.14,2,1,13.80,100,1,13.13,100,1,13.95,2,1,13.03,100,1,14.12,100,1,12.73,100,1,14.40,100,1,12.71,100,1,14.56,800,2,12.50,700,1,14.60,700,1,12.46,200,2,14.65,100,1,12.43,700,1,14.68,1400,2,ARL,288724485
2025-07-17T15:36:35.532926951Z,2025-07-17T15:36:35.532761335Z,160,2,1108,A,B,10,13.40,0,0,13.40,23,1,13.27,10,1,13.78,100,1,13.14,2,1,13.80,100,1,13.13,100,1,13.95,2,1,13.03,100,1,14.12,100,1,12.73,100,1,14.40,100,1,12.71,100,1,14.56,800,2,12.50,700,1,14.60,700,1,12.46,200,2,14.65,100,1,12.43,700,1,14.68,1400,2,ARL,291964745
2025-07-17T15:36:36.152132527Z,2025-07-17T15:36:36.151966883Z,160,2,1108,C,B,10,13.40,0,0,13.40,23,1,13.27,10,1,13.78,100,1,13.14,2,1,13.80,100,1,13.03,100,1,13.95,2,1,12.73,100,1,14.12,100,1,12.71,100,1,14.40,100,1,12.50,700,1,14.56,800,2,12.46,200,2,14.60,700,1,12.43,700,1,14.65,100,1,12.42,700,1,14.68,1400,2,ARL,291951937
2025-07-17T15:36:36.152132527Z,2025-07-17T15:36:36.151966883Z,160,2,1108,A,B,10,13.40,0,0,13.40,23,1,13.27,10,1,13.78,100,1,13.26,100,1,13.80,100,1,13.14,2,1,13.95,2,1,13.03,100,1,14.12,100,1,12.73,100,1,14.40,100,1,12.71,100,1,14.56,800,2,12.50,700,1,14.60,700,1,12.46,200,2,14.65,100,1,12.43,700,1,14.68,1400,2,ARL,291975017
2025-07-17T15:36:46.889917278Z,2025-07-17T15:36:46.889749756Z,160,2,1108,C,B,10,13.40,0,0,13.40,23,1,13.26,100,1,13.78,100,1,13.14,2,1,13.80,100,1,13.03,100,1,13.95,2,1,12.73,100,1,14.12,100,1,12.71,100,1,14.40,100,1,12.50,700,1,14.56,800,2,12.46,200,2,14.60,700,1,12.43,700,1,14.65,100,1,12.42,700,1,14.68,1400,2,ARL,291964737
2025-07-17T15:36:46.986820391Z,2025-07-17T15:36:46.986655137Z,160,2,1108,C,A,10,13.40,0,0,13.40,23,1,13.26,100,1,13.78,100,1,13.14,2,1,13.95,2,1,13.03,100,1,14.12,100,1,12.73,100,1,14.40,100,1,12.71,100,1,14.56,800,2,12.50,700,1,14.60,700,1,12.46,200,2,14.65,100,1,12.43,700,1,14.68,1400,2,12.42,700,1,14.72,200,2,ARL,291778909
2025-07-17T15:36:50.997434689Z,2025-07-17T15:36:50.997269299Z,160,2,1108,A,A,10,13.40,0,0,13.40,23,1,13.26,100,1,13.78,100,1,13.14,2,1,13.82,100,1,13.03,100,1,13.95,2,1,12.73,100,1,14.12,100,1,12.71,100,1,14.40,100,1,12.50,700,1,14.56,800,2,12.46,200,2,14.60,700,1,12.43,700,1,14.65,100,1,12.42,700,1,14.68,1400,2,ARL,292434813
2025-07-17T15:37:40.389737573Z,2025-07-17T15:37:40.389572053Z,160,2,1108,C,B,10,13.40,0,0,13.40,23,1,13.26,100,1,13.78,100,1,13.03,100,1,13.82,100,1,12.73,100,1,13.95,2,1,12.71,100,1,14.12,100,1,12.50,700,1,14.40,100,1,12.46,200,2,14.56,800,2,12.43,700,1,14.60,700,1,12.42,700,1,14.65,100,1,12.37,700,1,14.68,1400,2,ARL,289828293
2025-07-17T15:37:40.389737573Z,2025-07-17T15:37:40.389572053Z,160,2,1108,A,B,10,13.40,0,0,13.40,23,1,13.26,100,1,13.78,100,1,13.04,2,1,13.82,100,1,13.03,100,1,13.95,2,1,12.73,100,1,14.12,100,1,12.71,100,1,14.40,100,1,12.50,700,1,14.56,800,2,12.46,200,2,14.60,700,1,12.43,700,1,14.65,100,1,12.42,700,1,14.68,1400,2,ARL,293594281
2025-07-17T15:39:27.070109669Z,2025-07-17T15:39:27.069942913Z,160,2,1108,A,A,10,13.40,0,0,13.40,23,1,13.26,100,1,13.78,100,1,13.04,2,1,13.80,100,1,13.03,100,1,13.82,100,1,12.73,100,1,13.95,2,1,12.71,100,1,14.12,100,1,12.50,700,1,14.40,100,1,12.46,200,2,14.56,800,2,12.43,700,1,14.60,700,1,12.42,700,1,14.65,100,1,ARL,296059685
2025-07-17T15:39:27.077565902Z,2025-07-17T15:39:27.077400388Z,160,2,1108,C,A,10,13.40,0,0,13.40,23,1,13.26,100,1,13.78,100,1,13.04,2,1,13.80,100,1,13.03,100,1,13.95,2,1,12.73,100,1,14.12,100,1,12.71,100,1,14.40,100,1,12.50,700,1,14.56,800,2,12.46,200,2,14.60,700,1,12.43,700,1,14.65,100,1,12.42,700,1,14.68,1400,2,ARL,292434813
2025-07-17T15:39:30.509853083Z,2025-07-17T15:39:30.509687817Z,160,2,1108,A,A,10,13.40,0,0,13.40,23,1,13.26,100,1,13.76,15,1,13.04,2,1,13.78,100,1,13.03,100,1,13.80,100,1,12.73,100,1,13.95,2,1,12.71,100,1,14.12,100,1,12.50,700,1,14.40,100,1,12.46,200,2,14.56,800,2,12.43,700,1,14.60,700,1,12.42,700,1,14.65,100,1,ARL,296136617
2025-07-17T15:39:30.573217843Z,2025-07-17T15:39:30.573052284Z,160,2,1108,C,A,10,13.40,0,0,13.40,23,1,13.26,100,1,13.76,15,1,13.04,2,1,13.80,100,1,13.03,100,1,13.95,2,1,12.73,100,1,14.12,100,1,12.71,100,1,14.40,100,1,12.50,700,1,14.56,800,2,12.46,200,2,14.60,700,1,12.43,700,1,14.65,100,1,12.42,700,1,14.68,1400,2,ARL,289726281
2025-07-17T15:39:30.573217843Z,2025-07-17T15:39:30.573052284Z,160,2,1108,A,A,10,13.40,0,0,13.40,23,1,13.26,100,1,13.76,15,1,13.04,2,1,13.77,100,1,13.03,100,1,13.80,100,1,12.73,100,1,13.95,2,1,12.71,100,1,14.12,100,1,12.50,700,1,14.40,100,1,12.46,200,2,14.56,800,2,12.43,700,1,14.60,700,1,12.42,700,1,14.65,100,1,ARL,296137537
2025-07-17T15:39:30.589169820Z,2025-07-17T15:39:30.589004378Z,160,2,1108,C,A,10,13.40,0,0,13.40,23,1,13.26,100,1,13.76,15,1,13.04,2,1,13.77,100,1,13.03,100,1,13.80,100,1,12.73,100,1,13.95,2,1,12.71,100,1,14.40,100,1,12.50,700,1,14.56,800,2,12.46,200,2,14.60,700,1,12.43,700,1,14.65,100,1,12.42,700,1,14.68,1400,2,ARL,286680917
2025-07-17T15:39:30.589224596Z,2025-07-17T15:39:30.589059301Z,160,2,1108,A,A,10,13.40,0,0,13.40,23,1,13.26,100,1,13.76,15,1,13.04,2,1,13.77,100,1,13.03,100,1,13.80,100,1,12.73,100,1,13.95,2,1,12.71,100,1,14.05,100,1,12.50,700,1,14.40,100,1,12.46,200,2,14.56,800,2,12.43,700,1,14.60,700,1,12.42,700,1,14.65,100,1,ARL,296137769
2025-07-17T15:39:31.092010369Z,2025-07-17T15:39:31.091844988Z,160,2,1108,A,A,10,13.40,0,0,13.40,23,1,13.26,100,1,13.76,15,1,13.04,2,1,13.77,100,1,13.03,100,1,13.78,100,1,12.73,100,1,13.80,100,1,12.71,100,1,13.95,2,1,12.50,700,1,14.05,100,1,12.46,200,2,14.40,100,1,12.43,700,1,14.56,800,2,12.42,700,1,14.60,700,1,ARL,296149845
2025-07-17T15:39:31.098856641Z,2025-07-17T15:39:31.098691429Z,160,2,1108,C,A,10,13.40,0,0,13.40,23,1,13.26,100,1,13.76,15,1,13.04,2,1,13.77,100,1,13.03,100,1,13.78,100,1,12.73,100,1,13.95,2,1,12.71,100,1,14.05,100,1,12.50,700,1,14.40,100,1,12.46,200,2,14.56,800,2,12.43,700,1,14.60,700,1,12.42,700,1,14.65,100,1,ARL,296059685
2025-07-17T15:39:40.691151435Z,2025-07-17T15:39:40.690971606Z,160,2,1108,A,A,10,13.40,0,0,13.40,23,1,13.26,100,1,13.73,15,1,13.04,2,1,13.76,15,1,13.03,100,1,13.77,100,1,12.73,100,1,13.78,100,1,12.71,100,1,13.95,2,1,12.50,700,1,14.05,100,1,12.46,200,2,14.40,100,1,12.43,700,1,14.56,800,2,12.42,700,1,14.60,700,1,ARL,296365029
2025-07-17T15:39:40.696349429Z,2025-07-17T15:39:40.696182148Z,160,2,1108,C,A,10,13.40,0,0,13.40,23,1,13.26,100,1,13.73,15,1,13.04,2,1,13.76,15,1,13.03,100,1,13.78,100,1,12.73,100,1,13.95,2,1,12.71,100,1,14.05,100,1,12.50,700,1,14.40,100,1,12.46,200,2,14.56,800,2,12.43,700,1,14.60,700,1,12.42,700,1,14.65,100,1,ARL,296137537
2025-07-17T15:39:40.696349429Z,2025-07-17T15:39:40.696182148Z,160,2,1108,A,A,10,13.40,0,0,13.40,23,1,13.26,100,1,13.73,15,1,13.04,2,1,13.74,100,1,13.03,100,1,13.76,15,1,12.73,100,1,13.78,100,1,12.71,100,1,13.95,2,1,12.50,700,1,14.05,100,1,12.46,200,2,14.40,100,1,12.43,700,1,14.56,800,2,12.42,700,1,14.60,700,1,ARL,296368281
2025-07-17T15:39:40.697414147Z,2025-07-17T15:39:40.697247480Z,160,2,1108,C,A,10,13.40,0,0,13.40,23,1,13.26,100,1,13.73,15,1,13.04,2,1,13.74,100,1,13.03,100,1,13.76,15,1,12.73,100,1,13.78,100,1,12.71,100,1,13.95,2,1,12.50,700,1,14.05,100,1,12.46,200,2,14.40,100,1,12.43,700,1,14.56,800,2,12.42,700,1,14.60,700,1,ARL,289726349
2025-07-17T15:39:40.697414147Z,2025-07-17T15:39:40.697247480Z,160,2,1108,A,A,10,13.40,0,0,13.40,23,1,13.26,100,1,13.73,15,1,13.04,2,1,13.74,100,1,13.03,100,1,13.76,15,1,12.73,100,1,13.78,100,1,12.71,100,1,13.95,2,1,12.50,700,1,14.05,100,1,12.46,200,2,14.40,100,1,12.43,700,1,14.56,800,2,12.42,700,1,14.60,700,1,ARL,296368709
2025-07-17T15:39:40.708810377Z,2025-07-17T15:39:40.708645114Z,160,2,1108,A,A,10,13.40,0,0,13.40,23,1,13.26,100,1,13.73,15,1,13.04,2,1,13.74,100,1,13.03,100,1,13.76,115,2,12.73,100,1,13.78,100,1,12.71,100,1,13.95,2,1,12.50,700,1,14.05,100,1,12.46,200,2,14.40,100,1,12.43,700,1,14.56,800,2,12.42,700,1,14.60,700,1,ARL,296372577
2025-07-17T15:39:40.731431547Z,2025-07-17T15:39:40.731266408Z,160,2,1108,C,A,10,13.40,0,0,13.40,23,1,13.26,100,1,13.73,15,1,13.04,2,1,13.74,100,1,13.03,100,1,13.76,115,2,12.73,100,1,13.95,2,1,12.71,100,1,14.05,100,1,12.50,700,1,14.40,100,1,12.46,200,2,14.56,800,2,12.43,700,1,14.60,700,1,12.42,700,1,14.65,100,1,ARL,296149845
2025-07-17T15:39:40.908095999Z,2025-07-17T15:39:40.907929975Z,160,2,1108,C,A,10,13.40,0,0,13.40,23,1,13.26,100,1,13.73,15,1,13.04,2,1,13.74,100,1,13.03,100,1,13.76,115,2,12.73,100,1,13.95,2,1,12.71,100,1,14.05,100,1,12.50,700,1,14.40,100,1,12.46,200,2,14.56,800,2,12.43,700,1,14.60,700,1,12.42,700,1,14.65,100,1,ARL,146959177
2025-07-17T15:39:40.908095999Z,2025-07-17T15:39:40.907929975Z,160,2,1108,A,A,10,13.40,0,0,13.40,23,1,13.26,100,1,13.73,15,1,13.04,2,1,13.74,100,1,13.03,100,1,13.76,115,2,12.73,100,1,13.95,2,1,12.71,100,1,14.05,100,1,12.50,700,1,14.40,100,1,12.46,200,2,14.56,800,2,12.43,700,1,14.60,700,1,12.42,700,1,14.65,100,1,ARL,296387089
2025-07-17T15:39:41.085864728Z,2025-07-17T15:39:41.085699437Z,160,2,1108,A,A,10,13.40,0,0,13.40,23,1,13.26,100,1,13.73,15,1,13.04,2,1,13.74,100,1,13.03,100,1,13.76,115,2,12.73,100,1,13.95,2,1,12.71,100,1,14.05,100,1,12.50,700,1,14.40,100,1,12.46,200,2,14.56,900,3,12.43,700,1,14.60,700,1,12.42,700,1,14.65,100,1,ARL,296391881
2025-07-17T15:39:41.085877317Z,2025-07-17T15:39:41.085711985Z,160,2,1108,C,A,10,13.40,0,0,13.40,23,1,13.26,100,1,13.73,15,1,13.04,2,1,13.74,100,1,13.03,100,1,13.76,115,2,12.73,100,1,13.95,2,1,12.71,100,1,14.05,100,1,12.50,700,1,14.40,100,1,12.46,200,2,14.56,900,3,12.43,700,1,14.60,700,1,12.42,700,1,14.65,100,1,ARL,146962993
2025-07-17T15:39:43.773811774Z,2025-07-17T15:39:43.773645905Z,160,2,1108,C,A,10,13.40,0,0,13.40,23,1,13.26,100,1,13.73,15,1,13.04,2,1,13.74,100,1,13.03,100,1,13.76,115,2,12.73,100,1,13.95,2,1,12.71,100,1,14.05,100,1,12.50,700,1,14.40,100,1,12.46,200,2,14.56,900,3,12.43,700,1,14.60,700,1,12.42,700,1,14.65,100,1,ARL,286680577
2025-07-17T15:39:43.773811774Z,2025-07-17T15:39:43.773645905Z,160,2,1108,A,A,10,13.40,0,0,13.40,23,1,13.26,100,1,13.73,15,1,13.04,2,1,13.74,100,1,13.03,100,1,13.76,115,2,12.73,100,1,13.95,2,1,12.71,100,1,14.05,100,1,12.50,700,1,14.40,100,1,12.46,200,2,14.56,900,3,12.43,700,1,14.60,700,1,12.42,700,1,14.61,100,1,ARL,296455037
2025-07-17T15:39:43.773904473Z,2025-07-17T15:39:43.773738855Z,160,2,1108,C,A,10,13.40,0,0,13.40,23,1,13.26,100,1,13.73,15,1,13.04,2,1,13.74,100,1,13.03,100,1,13.76,115,2,12.73,100,1,13.95,2,1,12.71,100,1,14.05,100,1,12.50,700,1,14.40,100,1,12.46,200,2,14.56,900,3,12.43,700,1,14.60,700,1,12.42,700,1,14.61,100,1,ARL,286680573
2025-07-17T15:39:43.773904473Z,2025-07-17T15:39:43.773738855Z,160,2,1108,A,A,10,13.40,0,0,13.40,23,1,13.26,100,1,13.73,15,1,13.04,2,1,13.74,100,1,13.03,100,1,13.76,115,2,12.73,100,1,13.95,2,1,12.71,100,1,14.05,100,1,12.50,700,1,14.40,100,1,12.46,200,2,14.56,900,3,12.43,700,1,14.60,700,1,12.42,700,1,14.61,200,2,ARL,296455041
2025-07-17T15:39:44.428670900Z,2025-07-17T15:39:44.428505546Z,160,2,1108,C,A,10,13.40,0,0,13.40,23,1,13.26,100,1,13.73,15,1,13.04,2,1,13.74,100,1,13.03,100,1,13.76,100,1,12.73,100,1,13.95,2,1,12.71,100,1,14.05,100,1,12.50,700,1,14.40,100,1,12.46,200,2,14.56,900,3,12.43,700,1,14.60,700,1,12.42,700,1,14.61,200,2,ARL,296136617
2025-07-17T15:39:44.433539292Z,2025-07-17T15:39:44.433372235Z,160,2,1108,C,A,10,13.40,0,0,13.40,23,1,13.26,100,1,13.74,100,1,13.04,2,1,13.76,100,1,13.03,100,1,13.95,2,1,12.73,100,1,14.05,100,1,12.71,100,1,14.40,100,1,12.50,700,1,14.56,900,3,12.46,200,2,14.60,700,1,12.43,700,1,14.61,200,2,12.42,700,1,14.65,100,1,ARL,296365029
2025-07-17T15:39:44.436054885Z,2025-07-17T15:39:44.435889060Z,160,2,1108,C,A,10,13.40,0,0,13.40,23,1,13.26,100,1,13.76,100,1,13.04,2,1,13.95,2,1,13.03,100,1,14.05,100,1,12.73,100,1,14.40,100,1,12.71,100,1,14.56,900,3,12.50,700,1,14.60,700,1,12.46,200,2,14.61,200,2,12.43,700,1,14.65,100,1,12.42,700,1,14.68,1400,2,ARL,296368281
2025-07-17T15:39:44.450239090Z,2025-07-17T15:39:44.450073949Z,160,2,1108,C,A,10,13.40,0,0,13.40,23,1,13.26,100,1,13.95,2,1,13.04,2,1,14.05,100,1,13.03,100,1,14.40,100,1,12.73,100,1,14.56,900,3,12.71,100,1,14.60,700,1,12.50,700,1,14.61,200,2,12.46,200,2,14.65,100,1,12.43,700,1,14.68,1400,2,12.42,700,1,14.81,300,3,ARL,296372577
2025-07-17T15:39:44.450972330Z,2025-07-17T15:39:44.450806746Z,160,2,1108,C,A,10,13.40,0,0,13.40,23,1,13.26,100,1,13.95,2,1,13.04,2,1,14.05,100,1,13.03,100,1,14.40,100,1,12.73,100,1,14.56,900,3,12.71,100,1,14.60,700,1,12.50,700,1,14.61,200,2,12.46,200,2,14.65,100,1,12.43,700,1,14.68,1400,2,12.42,700,1,14.81,200,2,ARL,296368709
2025-07-17T15:39:44.450972330Z,2025-07-17T15:39:44.450806746Z,160,2,1108,A,A,10,13.40,0,0,13.40,23,1,13.26,100,1,13.95,2,1,13.04,2,1,14.05,100,1,13.03,100,1,14.40,100,1,12.73,100,1,14.56,900,3,12.71,100,1,14.60,700,1,12.50,700,1,14.61,200,2,12.46,200,2,14.65,100,1,12.43,700,1,14.68,1400,2,12.42,700,1,14.81,200,2,ARL,296478965
2025-07-17T15:39:44.451075992Z,2025-07-17T15:39:44.450910591Z,160,2,1108,C,A,10,13.40,0,0,13.40,23,1,13.26,100,1,14.05,100,1,13.04,2,1,14.40,100,1,13.03,100,1,14.56,900,3,12.73,100,1,14.60,700,1,12.71,100,1,14.61,200,2,12.50,700,1,14.65,100,1,12.46,200,2,14.68,1400,2,12.43,700,1,14.81,200,2,12.42,700,1,15.06,100,1,ARL,287540393
2025-07-17T15:39:44.451075992Z,2025-07-17T15:39:44.450910591Z,160,2,1108,A,A,10,13.40,0,0,13.40,23,1,13.26,100,1,14.05,100,1,13.04,2,1,14.07,2,1,13.03,100,1,14.40,100,1,12.73,100,1,14.56,900,3,12.71,100,1,14.60,700,1,12.50,700,1,14.61,200,2,12.46,200,2,14.65,100,1,12.43,700,1,14.68,1400,2,12.42,700,1,14.81,200,2,ARL,296478973
2025-07-17T15:39:44.455130297Z,2025-07-17T15:39:44.454964327Z,160,2,1108,C,A,10,13.40,0,0,13.40,23,1,13.26,100,1,14.05,100,1,13.04,2,1,14.07,2,1,13.03,100,1,14.40,100,1,12.73,100,1,14.56,900,3,12.71,100,1,14.60,700,1,12.50,700,1,14.61,200,2,12.46,200,2,14.65,100,1,12.43,700,1,14.68,1400,2,12.42,700,1,14.81,100,1,ARL,286680741
2025-07-17T15:39:44.455130297Z,2025-07-17T15:39:44.454964327Z,160,2,1108,A,A,10,13.40,0,0,13.40,23,1,13.26,100,1,14.05,100,1,13.04,2,1,14.07,2,1,13.03,100,1,14.40,100,1,12.73,100,1,14.56,900,3,12.71,100,1,14.60,700,1,12.50,700,1,14.61,200,2,12.46,200,2,14.65,100,1,12.43,700,1,14.68,1400,2,12.42,700,1,14.81,100,1,ARL,296479053
2025-07-17T15:39:44.456288062Z,2025-07-17T15:39:44.456122660Z,160,2,1108,C,A,10,13.40,0,0,13.40,23,1,13.26,100,1,14.05,100,1,13.04,2,1,14.07,2,1,13.03,100,1,14.40,100,1,12.73,100,1,14.56,900,3,12.71,100,1,14.60,700,1,12.50,700,1,14.61,200,2,12.46,200,2,14.68,1400,2,12.43,700,1,14.81,100,1,12.42,700,1,14.96,100,1,ARL,286680905
2025-07-17T15:39:44.456377500Z,2025-07-17T15:39:44.456211953Z,160,2,1108,A,A,10,13.40,0,0,13.40,23,1,13.26,100,1,14.05,100,1,13.04,2,1,14.07,2,1,13.03,100,1,14.40,100,1,12.73,100,1,14.56,900,3,12.71,100,1,14.60,700,1,12.50,700,1,14.61,200,2,12.46,200,2,14.68,1400,2,12.43,700,1,14.78,100,1,12.42,700,1,14.81,100,1,ARL,296479285
2025-07-17T15:39:44.462055094Z,2025-07-17T15:39:44.461889886Z,160,2,1108,C,A,10,13.40,0,0,13.40,23,1,13.26,100,1,14.07,2,1,13.04,2,1,14.40,100,1,13.03,100,1,14.56,900,3,12.73,100,1,14.60,700,1,12.71,100,1,14.61,200,2,12.50,700,1,14.68,1400,2,12.46,200,2,14.78,100,1,12.43,700,1,14.81,100,1,12.42,700,1,14.96,100,1,ARL,296137769
2025-07-17T15:39:44.462108809Z,2025-07-17T15:39:44.461943584Z,160,2,1108,A,A,10,13.40,0,0,13.40,23,1,13.26,100,1,14.07,2,1,13.04,2,1,14.26,100,1,13.03,100,1,14.40,100,1,12.73,100,1,14.56,900,3,12.71,100,1,14.60,700,1,12.50,700,1,14.61,200,2,12.46,200,2,14.68,1400,2,12.43,700,1,14.78,100,1,12.42,700,1,14.81,100,1,ARL,296479425
2025-07-17T15:39:44.478923366Z,2025-07-17T15:39:44.478757958Z,160,2,1108,C,A,10,13.40,0,0,13.40,23,1,13.26,100,1,14.07,2,1,13.04,2,1,14.26,100,1,13.03,100,1,14.40,100,1,12.73,100,1,14.56,900,3,12.71,100,1,14.60,700,1,12.50,700,1,14.61,200,2,12.46,200,2,14.68,1400,2,12.43,700,1,14.78,100,1,12.42,700,1,14.81,100,1,ARL,286681057
2025-07-17T15:39:44.478923366Z,2025-07-17T15:39:44.478757958Z,160,2,1108,A,A,10,13.40,0,0,13.40,23,1,13.26,100,1,14.07,2,1,13.04,2,1,14.26,100,1,13.03,100,1,14.40,100,1,12.73,100,1,14.56,900,3,12.71,100,1,14.60,700,1,12.50,700,1,14.61,200,2,12.46,200,2,14.68,1400,2,12.43,700,1,14.78,100,1,12.42,700,1,14.81,100,1,ARL,296479893
2025-07-17T15:39:44.491018431Z,2025-07-17T15:39:44.490852860Z,160,2,1108,C,A,10,13.40,0,0,13.40,23,1,13.26,100,1,14.07,2,1,13.04,2,1,14.26,100,1,13.03,100,1,14.40,100,1,12.73,100,1,14.56,900,3,12.71,100,1,14.60,700,1,12.50,700,1,14.61,200,2,12.46,200,2,14.68,1400,2,12.43,700,1,14.78,100,1,12.42,700,1,14.81,100,1,ARL,286681229
2025-07-17T15:39:44.491018431Z,2025-07-17T15:39:44.490852860Z,160,2,1108,A,A,10,13.40,0,0,13.40,23,1,13.26,100,1,14.07,2,1,13.04,2,1,14.26,100,1,13.03,100,1,14.40,100,1,12.73,100,1,14.56,900,3,12.71,100,1,14.60,700,1,12.50,700,1,14.61,200,2,12.46,200,2,14.68,1400,2,12.43,700,1,14.78,100,1,12.42,700,1,14.81,100,1,ARL,296480097
2025-07-17T15:39:44.593773213Z,2025-07-17T15:39:44.593607433Z,160,2,1108,C,A,10,13.40,0,0,13.40,23,1,13.26,100,1,14.07,2,1,13.04,2,1,14.26,100,1,13.03,100,1,14.40,100,1,12.73,100,1,14.56,900,3,12.71,100,1,14.60,700,1,12.50,700,1,14.61,200,2,12.46,200,2,14.68,1400,2,12.43,700,1,14.78,100,1,12.42,700,1,14.96,100,1,ARL,286684005
2025-07-17T15:39:44.593773213Z,2025-07-17T15:39:44.593607433Z,160,2,1108,A,A,10,13.40,0,0,13.40,23,1,13.26,100,1,14.07,2,1,13.04,2,1,14.26,100,1,13.03,100,1,14.40,100,1,12.73,100,1,14.56,900,3,12.71,100,1,14.60,700,1,12.50,700,1,14.61,200,2,12.46,200,2,14.68,1400,2,12.43,700,1,14.78,100,1,12.42,700,1,14.96,200,2,ARL,296482509
2025-07-17T15:39:44.859886562Z,2025-07-17T15:39:44.859720946Z,160,2,1108,C,A,10,13.40,0,0,13.40,23,1,13.26,100,1,14.07,2,1,13.04,2,1,14.26,100,1,13.03,100,1,14.40,100,1,12.73,100,1,14.56,900,3,12.71,100,1,14.60,700,1,12.50,700,1,14.61,100,1,12.46,200,2,14.68,1400,2,12.43,700,1,14.78,100,1,12.42,700,1,14.96,200,2,ARL,296455041
2025-07-17T15:39:44.859886562Z,2025-07-17T15:39:44.859720946Z,160,2,1108,A,A,10,13.40,0,0,13.40,23,1,13.26,100,1,14.07,2,1,13.04,2,1,14.26,100,1,13.03,100,1,14.40,100,1,12.73,100,1,14.56,900,3,12.71,100,1,14.60,700,1,12.50,700,1,14.61,100,1,12.46,200,2,14.68,1400,2,12.43,700,1,14.78,100,1,12.42,700,1,14.96,200,2,ARL,296485621
2025-07-17T15:39:44.860160096Z,2025-07-17T15:39:44.859994671Z,160,2,1108,A,A,10,13.40,0,0,13.40,23,1,13.26,100,1,14.07,2,1,13.04,2,1,14.08,100,1,13.03,100,1,14.26,100,1,12.73,100,1,14.40,100,1,12.71,100,1,14.56,900,3,12.50,700,1,14.60,700,1,12.46,200,2,14.61,100,1,12.43,700,1,14.68,1400,2,12.42,700,1,14.78,100,1,ARL,296485629
2025-07-17T15:39:44.863678795Z,2025-07-17T15:39:44.863513587Z,160,2,1108,C,A,10,13.40,0,0,13.40,23,1,13.26,100,1,14.07,2,1,13.04,2,1,14.08,100,1,13.03,100,1,14.26,100,1,12.73,100,1,14.40,100,1,12.71,100,1,14.56,900,3,12.50,700,1,14.60,700,1,12.46,200,2,14.68,1400,2,12.43,700,1,14.78,100,1,12.42,700,1,14.96,200,2,ARL,296455037
2025-07-17T15:39:44.863678795Z,2025-07-17T15:39:44.863513587Z,160,2,1108,A,A,10,13.40,0,0,13.40,23,1,13.26,100,1,14.07,2,1,13.04,2,1,14.08,100,1,13.03,100,1,14.26,100,1,12.73,100,1,14.40,100,1,12.71,100,1,14.56,900,3,12.50,700,1,14.60,700,1,12.46,200,2,14.68,1400,2,12.43,700,1,14.78,100,1,12.42,700,1,14.96,200,2,ARL,296485649
2025-07-17T15:39:54.187008224Z,2025-07-17T15:39:54.186842327Z,160,2,1108,C,A,10,13.40,0,0,13.40,23,1,13.26,100,1,14.07,2,1,13.04,2,1,14.08,100,1,13.03,100,1,14.26,100,1,12.73,100,1,14.40,100,1,12.71,100,1,14.56,900,3,12.50,700,1,14.60,700,1,12.46,200,2,14.68,1400,2,12.43,700,1,14.78,100,1,12.42,700,1,14.96,200,2,ARL,296485649
2025-07-17T15:39:54.187008224Z,2025-07-17T15:39:54.186842327Z,160,2,1108,A,A,10,13.40,0,0,13.40,23,1,13.26,100,1,14.07,2,1,13.04,2,1,14.08,100,1,13.03,100,1,14.26,100,1,12.73,100,1,14.40,100,1,12.71,100,1,14.56,900,3,12.50,700,1,14.60,700,1,12.46,200,2,14.68,1400,2,12.43,700,1,14.78,100,1,12.42,700,1,14.88,100,1,ARL,296679277
2025-07-17T15:39:54.187557412Z,2025-07-17T15:39:54.187391707Z,160,2,1108,C,A,10,13.40,0,0,13.40,23,1,13.26,100,1,14.07,2,1,13.04,2,1,14.08,100,1,13.03,100,1,14.26,100,1,12.73,100,1,14.40,100,1,12.71,100,1,14.56,900,3,12.50,700,1,14.60,700,1,12.46,200,2,14.68,1400,2,12.43,700,1,14.78,100,1,12.42,700,1,14.88,100,1,ARL,296485621
2025-07-17T15:39:54.187557412Z,2025-07-17T15:39:54.187391707Z,160,2,1108,A,A,10,13.40,0,0,13.40,23,1,13.26,100,1,14.07,2,1,13.04,2,1,14.08,100,1,13.03,100,1,14.26,100,1,12.73,100,1,14.40,100,1,12.71,100,1,14.56,900,3,12.50,700,1,14.60,700,1,12.46,200,2,14.68,1400,2,12.43,700,1,14.78,100,1,12.42,700,1,14.88,200,2,ARL,296679285
2025-07-17T15:42:06.780503054Z,2025-07-17T15:42:06.780337543Z,160,2,1108,A,A,10,13.40,0,0,13.40,23,1,13.26,100,1,13.90,15,1,13.04,2,1,14.07,2,1,13.03,100,1,14.08,100,1,12.73,100,1,14.26,100,1,12.71,100,1,14.40,100,1,12.50,700,1,14.56,900,3,12.46,200,2,14.60,700,1,12.43,700,1,14.68,1400,2,12.42,700,1,14.78,100,1,ARL,299689753
2025-07-17T15:42:06.780767761Z,2025-07-17T15:42:06.780602350Z,160,2,1108,C,A,10,13.40,0,0,13.40,23,1,13.26,100,1,13.90,15,1,13.04,2,1,14.07,2,1,13.03,100,1,14.26,100,1,12.73,100,1,14.40,100,1,12.71,100,1,14.56,900,3,12.50,700,1,14.60,700,1,12.46,200,2,14.68,1400,2,12.43,700,1,14.78,100,1,12.42,700,1,14.88,200,2,ARL,296485629
2025-07-17T15:42:06.780767761Z,2025-07-17T15:42:06.780602350Z,160,2,1108,A,A,10,13.40,0,0,13.40,23,1,13.26,100,1,13.90,15,1,13.04,2,1,13.91,100,1,13.03,100,1,14.07,2,1,12.73,100,1,14.26,100,1,12.71,100,1,14.40,100,1,12.50,700,1,14.56,900,3,12.46,200,2,14.60,700,1,12.43,700,1,14.68,1400,2,12.42,700,1,14.78,100,1,ARL,299689769
2025-07-17T15:42:06.781502831Z,2025-07-17T15:42:06.781336642Z,160,2,1108,C,A,10,13.40,0,0,13.40,23,1,13.26,100,1,13.90,15,1,13.04,2,1,13.91,100,1,13.03,100,1,14.07,2,1,12.73,100,1,14.26,100,1,12.71,100,1,14.40,100,1,12.50,700,1,14.56,900,3,12.46,200,2,14.60,700,1,12.43,700,1,14.68,1400,2,12.42,700,1,14.78,100,1,ARL,296478965
2025-07-17T15:42:06.781502831Z,2025-07-17T15:42:06.781336642Z,160,2,1108,A,A,10,13.40,0,0,13.40,23,1,13.26,100,1,13.90,15,1,13.04,2,1,13.91,100,1,13.03,100,1,14.07,2,1,12.73,100,1,14.26,100,1,12.71,100,1,14.40,100,1,12.50,700,1,14.56,900,3,12.46,200,2,14.60,700,1,12.43,700,1,14.68,1400,2,12.42,700,1,14.78,100,1,ARL,299689857
2025-07-17T15:42:06.795521307Z,2025-07-17T15:42:06.795355762Z,160,2,1108,C,A,10,13.40,0,0,13.40,23,1,13.26,100,1,13.90,15,1,13.04,2,1,13.91,100,1,13.03,100,1,14.07,2,1,12.73,100,1,14.40,100,1,12.71,100,1,14.56,900,3,12.50,700,1,14.60,700,1,12.46,200,2,14.68,1400,2,12.43,700,1,14.78,100,1,12.42,700,1,14.88,200,2,ARL,296479425
2025-07-17T15:42:06.795573392Z,2025-07-17T15:42:06.795408057Z,160,2,1108,A,A,10,13.40,0,0,13.40,23,1,13.26,100,1,13.90,15,1,13.04,2,1,13.91,100,1,13.03,100,1,14.07,2,1,12.73,100,1,14.19,100,1,12.71,100,1,14.40,100,1,12.50,700,1,14.56,900,3,12.46,200,2,14.60,700,1,12.43,700,1,14.68,1400,2,12.42,700,1,14.78,100,1,ARL,299690593
2025-07-17T15:42:16.264132159Z,2025-07-17T15:42:16.263966448Z,160,2,1108,C,A,10,13.40,0,0,13.40,23,1,13.26,100,1,13.90,15,1,13.04,2,1,13.91,100,1,13.03,100,1,14.07,2,1,12.73,100,1,14.19,100,1,12.71,100,1,14.40,100,1,12.50,700,1,14.56,900,3,12.46,200,2,14.60,700,1,12.43,700,1,14.68,1400,2,12.42,700,1,14.78,100,1,ARL,296679285
2025-07-17T15:42:16.264132159Z,2025-07-17T15:42:16.263966448Z,160,2,1108,A,A,10,13.40,0,0,13.40,23,1,13.26,100,1,13.90,15,1,13.04,2,1,13.91,100,1,13.03,100,1,14.07,2,1,12.73,100,1,14.19,100,1,12.71,100,1,14.40,100,1,12.50,700,1,14.56,900,3,12.46,200,2,14.60,700,1,12.43,700,1,14.68,1400,2,12.42,700,1,14.76,100,1,ARL,299903169
2025-07-17T15:42:17.356766715Z,2025-07-17T15:42:17.356601231Z,160,2,1108,A,A,10,13.40,0,0,13.40,23,1,13.26,100,1,13.83,15,1,13.04,2,1,13.90,15,1,13.03,100,1,13.91,100,1,12.73,100,1,14.07,2,1,12.71,100,1,14.19,100,1,12.50,700,1,14.40,100,1,12.46,200,2,14.56,900,3,12.43,700,1,14.60,700,1,12.42,700,1,14.68,1400,2,ARL,299923773
2025-07-17T15:42:17.577474246Z,2025-07-17T15:42:17.577308779Z,160,2,1108,C,A,10,13.40,0,0,13.40,23,1,13.26,100,1,13.83,15,1,13.04,2,1,13.90,15,1,13.03,100,1,14.07,2,1,12.73,100,1,14.19,100,1,12.71,100,1,14.40,100,1,12.50,700,1,14.56,900,3,12.46,200,2,14.60,700,1,12.43,700,1,14.68,1400,2,12.42,700,1,14.76,100,1,ARL,299689769
2025-07-17T15:42:17.577474246Z,2025-07-17T15:42:17.577308779Z,160,2,1108,A,A,10,13.40,0,0,13.40,23,1,13.26,100,1,13.83,15,1,13.04,2,1,13.84,100,1,13.03,100,1,13.90,15,1,12.73,100,1,14.07,2,1,12.71,100,1,14.19,100,1,12.50,700,1,14.40,100,1,12.46,200,2,14.56,900,3,12.43,700,1,14.60,700,1,12.42,700,1,14.68,1400,2,ARL,299926781
2025-07-17T15:42:17.578219175Z,2025-07-17T15:42:17.578053644Z,160,2,1108,C,A,10,13.40,0,0,13.40,23,1,13.26,100,1,13.83,15,1,13.04,2,1,13.84,100,1,13.03,100,1,13.90,15,1,12.73,100,1,14.07,2,1,12.71,100,1,14.19,100,1,12.50,700,1,14.40,100,1,12.46,200,2,14.56,900,3,12.43,700,1,14.60,700,1,12.42,700,1,14.68,1400,2,ARL,299689857
2025-07-17T15:42:17.578219175Z,2025-07-17T15:42:17.578053644Z,160,2,1108,A,A,10,13.40,0,0,13.40,23,1,13.26,100,1,13.83,15,1,13.04,2,1,13.84,100,1,13.03,100,1,13.90,15,1,12.73,100,1,14.07,2,1,12.71,100,1,14.19,100,1,12.50,700,1,14.40,100,1,12.46,200,2,14.56,900,3,12.43,700,1,14.60,700,1,12.42,700,1,14.68,1400,2,ARL,299926801
2025-07-17T15:42:17.579343189Z,2025-07-17T15:42:17.579177582Z,160,2,1108,C,A,10,13.40,0,0,13.40,23,1,13.26,100,1,13.83,15,1,13.04,2,1,13.84,100,1,13.03,100,1,13.90,15,1,12.73,100,1,14.07,2,1,12.71,100,1,14.19,100,1,12.50,700,1,14.40,100,1,12.46,200,2,14.56,900,3,12.43,700,1,14.60,700,1,12.42,700,1,14.68,1400,2,ARL,296479285
2025-07-17T15:42:17.579343189Z,2025-07-17T15:42:17.579177582Z,160,2,1108,A,A,10,13.40,0,0,13.40,23,1,13.26,100,1,13.83,15,1,13.04,2,1,13.84,100,1,13.03,100,1,13.90,15,1,12.73,100,1,14.07,2,1,12.71,100,1,14.19,100,1,12.50,700,1,14.40,100,1,12.46,200,2,14.56,900,3,12.43,700,1,14.60,700,1,12.42,700,1,14.64,100,1,ARL,299926813
2025-07-17T15:42:17.580008869Z,2025-07-17T15:42:17.579843331Z,160,2,1108,C,A,10,13.40,0,0,13.40,23,1,13.26,100,1,13.83,15,1,13.04,2,1,13.84,100,1,13.03,100,1,13.90,15,1,12.73,100,1,14.07,2,1,12.71,100,1,14.19,100,1,12.50,700,1,14.40,100,1,12.46,200,2,14.56,900,3,12.43,700,1,14.60,700,1,12.42,700,1,14.64,100,1,ARL,296479053
2025-07-17T15:42:17.580008869Z,2025-07-17T15:42:17.579843331Z,160,2,1108,A,A,10,13.40,0,0,13.40,23,1,13.26,100,1,13.83,15,1,13.04,2,1,13.84,100,1,13.03,100,1,13.90,15,1,12.73,100,1,14.07,2,1,12.71,100,1,14.19,100,1,12.50,700,1,14.40,100,1,12.46,200,2,14.56,900,3,12.43,700,1,14.60,700,1,12.42,700,1,14.64,100,1,ARL,299926849
2025-07-17T15:42:17.580035793Z,2025-07-17T15:42:17.579870309Z,160,2,1108,C,A,10,13.40,0,0,13.40,23,1,13.26,100,1,13.83,15,1,13.04,2,1,13.84,100,1,13.03,100,1,13.90,15,1,12.73,100,1,14.07,2,1,12.71,100,1,14.19,100,1,12.50,700,1,14.40,100,1,12.46,200,2,14.56,900,3,12.43,700,1,14.60,700,1,12.42,700,1,14.64,100,1,ARL,296480097
2025-07-17T15:42:17.580035793Z,2025-07-17T15:42:17.579870309Z,160,2,1108,A,A,10,13.40,0,0,13.40,23,1,13.26,100,1,13.83,15,1,13.04,2,1,13.84,100,1,13.03,100,1,13.90,15,1,12.73,100,1,14.07,2,1,12.71,100,1,14.19,100,1,12.50,700,1,14.40,100,1,12.46,200,2,14.56,900,3,12.43,700,1,14.60,700,1,12.42,700,1,14.64,100,1,ARL,299926853
2025-07-17T15:42:17.580061097Z,2025-07-17T15:42:17.579895610Z,160,2,1108,C,A,10,13.40,0,0,13.40,23,1,13.26,100,1,13.83,15,1,13.04,2,1,13.84,100,1,13.03,100,1,13.90,15,1,12.73,100,1,14.07,2,1,12.71,100,1,14.19,100,1,12.50,700,1,14.40,100,1,12.46,200,2,14.56,900,3,12.43,700,1,14.60,700,1,12.42,700,1,14.64,100,1,ARL,296482509
2025-07-17T15:42:17.580061097Z,2025-07-17T15:42:17.579895610Z,160,2,1108,A,A,10,13.40,0,0,13.40,23,1,13.26,100,1,13.83,15,1,13.04,2,1,13.84,100,1,13.03,100,1,13.90,15,1,12.73,100,1,14.07,2,1,12.71,100,1,14.19,100,1,12.50,700,1,14.40,100,1,12.46,200,2,14.56,900,3,12.43,700,1,14.60,700,1,12.42,700,1,14.64,100,1,ARL,299926857
2025-07-17T15:42:17.580093535Z,2025-07-17T15:42:17.579928136Z,160,2,1108,C,A,10,13.40,0,0,13.40,23,1,13.26,100,1,13.83,15,1,13.04,2,1,13.84,100,1,13.03,100,1,13.90,15,1,12.73,100,1,14.07,2,1,12.71,100,1,14.19,100,1,12.50,700,1,14.40,100,1,12.46,200,2,14.56,900,3,12.43,700,1,14.60,700,1,12.42,700,1,14.64,100,1,ARL,296479893
2025-07-17T15:42:17.580093535Z,2025-07-17T15:42:17.579928136Z,160,2,1108,A,A,10,13.40,0,0,13.40,23,1,13.26,100,1,13.83,15,1,13.04,2,1,13.84,100,1,13.03,100,1,13.90,15,1,12.73,100,1,14.07,2,1,12.71,100,1,14.19,100,1,12.50,700,1,14.40,100,1,12.46,200,2,14.56,900,3,12.43,700,1,14.60,700,1,12.42,700,1,14.64,100,1,ARL,299926861
2025-07-17T15:42:17.589263550Z,2025-07-17T15:42:17.589098227Z,160,2,1108,C,A,10,13.40,0,0,13.40,23,1,13.26,100,1,13.83,15,1,13.04,2,1,13.84,100,1,13.03,100,1,13.90,15,1,12.73,100,1,14.07,2,1,12.71,100,1,14.40,100,1,12.50,700,1,14.56,900,3,12.46,200,2,14.60,700,1,12.43,700,1,14.64,100,1,12.42,700,1,14.68,1400,2,ARL,299690593
2025-07-17T15:42:17.589316911Z,2025-07-17T15:42:17.589151325Z,160,2,1108,A,A,10,13.40,0,0,13.40,23,1,13.26,100,1,13.83,15,1,13.04,2,1,13.84,100,1,13.03,100,1,13.90,15,1,12.73,100,1,14.07,2,1,12.71,100,1,14.12,100,1,12.50,700,1,14.40,100,1,12.46,200,2,14.56,900,3,12.43,700,1,14.60,700,1,12.42,700,1,14.64,100,1,ARL,299926965
2025-07-17T15:42:18.398220000Z,2025-07-17T15:42:18.398054465Z,160,2,1108,C,A,10,13.40,0,0,13.40,23,1,13.26,100,1,13.83,15,1,13.04,2,1,13.84,100,1,13.03,100,1,13.90,15,1,12.73,100,1,14.07,2,1,12.71,100,1,14.12,100,1,12.50,700,1,14.40,100,1,12.46,200,2,14.56,900,3,12.43,700,1,14.60,700,1,12.42,700,1,14.64,100,1,ARL,296679277
2025-07-17T15:42:18.398220000Z,2025-07-17T15:42:18.398054465Z,160,2,1108,A,A,10,13.40,0,0,13.40,23,1,13.26,100,1,13.83,15,1,13.04,2,1,13.84,100,1,13.03,100,1,13.90,15,1,12.73,100,1,14.07,2,1,12.71,100,1,14.12,100,1,12.50,700,1,14.40,100,1,12.46,200,2,14.56,900,3,12.43,700,1,14.60,700,1,12.42,700,1,14.64,100,1,ARL,299945073
2025-07-17T15:42:21.517871714Z,2025-07-17T15:42:21.517706139Z,160,2,1108,C,A,10,13.40,0,0,13.40,23,1,13.26,100,1,13.83,15,1,13.04,2,1,13.84,100,1,13.03,100,1,14.07,2,1,12.73,100,1,14.12,100,1,12.71,100,1,14.40,100,1,12.50,700,1,14.56,900,3,12.46,200,2,14.60,700,1,12.43,700,1,14.64,100,1,12.42,700,1,14.68,1400,2,ARL,299689753
2025-07-17T15:42:22.522744242Z,2025-07-17T15:42:22.522578675Z,160,2,1108,A,A,10,13.40,0,0,13.40,23,1,13.26,100,1,13.79,15,1,13.04,2,1,13.83,15,1,13.03,100,1,13.84,100,1,12.73,100,1,14.07,2,1,12.71,100,1,14.12,100,1,12.50,700,1,14.40,100,1,12.46,200,2,14.56,900,3,12.43,700,1,14.60,700,1,12.42,700,1,14.64,100,1,ARL,300042293
2025-07-17T15:42:22.533681479Z,2025-07-17T15:42:22.533515955Z,160,2,1108,A,A,10,13.40,0,0,13.40,23,1,13.26,100,1,13.79,15,1,13.04,2,1,13.82,100,1,13.03,100,1,13.83,15,1,12.73,100,1,13.84,100,1,12.71,100,1,14.07,2,1,12.50,700,1,14.12,100,1,12.46,200,2,14.40,100,1,12.43,700,1,14.56,900,3,12.42,700,1,14.60,700,1,ARL,300042385
2025-07-17T15:42:23.490247121Z,2025-07-17T15:42:23.490079821Z,160,2,1108,C,A,10,13.40,0,0,13.40,23,1,13.26,100,1,13.79,15,1,13.04,2,1,13.82,100,1,13.03,100,1,13.83,15,1,12.73,100,1,14.07,2,1,12.71,100,1,14.12,100,1,12.50,700,1,14.40,100,1,12.46,200,2,14.56,900,3,12.43,700,1,14.60,700,1,12.42,700,1,14.64,100,1,ARL,299926781
2025-07-17T15:42:23.490247121Z,2025-07-17T15:42:23.490079821Z,160,2,1108,A,A,10,13.40,0,0,13.40,23,1,13.26,100,1,13.79,15,1,13.04,2,1,13.80,100,1,13.03,100,1,13.82,100,1,12.73,100,1,13.83,15,1,12.71,100,1,14.07,2,1,12.50,700,1,14.12,100,1,12.46,200,2,14.40,100,1,12.43,700,1,14.56,900,3,12.42,700,1,14.60,700,1,ARL,300061581
2025-07-17T15:42:23.491451368Z,2025-07-17T15:42:23.491285065Z,160,2,1108,C,A,10,13.40,0,0,13.40,23,1,13.26,100,1,13.79,15,1,13.04,2,1,13.80,100,1,13.03,100,1,13.82,100,1,12.73,100,1,13.83,15,1,12.71,100,1,14.07,2,1,12.50,700,1,14.12,100,1,12.46,200,2,14.40,100,1,12.43,700,1,14.56,900,3,12.42,700,1,14.60,700,1,ARL,299926801
2025-07-17T15:42:23.491451368Z,2025-07-17T15:42:23.491285065Z,160,2,1108,A,A,10,13.40,0,0,13.40,23,1,13.26,100,1,13.79,15,1,13.04,2,1,13.80,100,1,13.03,100,1,13.82,100,1,12.73,100,1,13.83,15,1,12.71,100,1,14.07,2,1,12.50,700,1,14.12,100,1,12.46,200,2,14.40,100,1,12.43,700,1,14.56,900,3,12.42,700,1,14.60,700,1,ARL,300061989
2025-07-17T15:42:23.589065154Z,2025-07-17T15:42:23.588899941Z,160,2,1108,C,A,10,13.40,0,0,13.40,23,1,13.26,100,1,13.80,100,1,13.04,2,1,13.82,100,1,13.03,100,1,13.83,15,1,12.73,100,1,14.07,2,1,12.71,100,1,14.12,100,1,12.50,700,1,14.40,100,1,12.46,200,2,14.56,900,3,12.43,700,1,14.60,700,1,12.42,700,1,14.64,100,1,ARL,300042293
2025-07-17T15:42:23.589220778Z,2025-07-17T15:42:23.589055082Z,160,2,1108,C,A,10,13.40,0,0,13.40,23,1,13.26,100,1,13.80,100,1,13.04,2,1,13.82,100,1,13.03,100,1,14.07,2,1,12.73,100,1,14.12,100,1,12.71,100,1,14.40,100,1,12.50,700,1,14.56,900,3,12.46,200,2,14.60,700,1,12.43,700,1,14.64,100,1,12.42,700,1,14.68,1400,2,ARL,299923773
2025-07-17T15:42:34.003710081Z,2025-07-17T15:42:34.003544527Z,160,2,1108,C,A,10,13.40,0,0,13.40,23,1,13.26,100,1,13.82,100,1,13.04,2,1,14.07,2,1,13.03,100,1,14.12,100,1,12.73,100,1,14.40,100,1,12.71,100,1,14.56,900,3,12.50,700,1,14.60,700,1,12.46,200,2,14.64,100,1,12.43,700,1,14.68,1400,2,12.42,700,1,14.73,100,1,ARL,300061581
2025-07-17T15:42:34.003949340Z,2025-07-17T15:42:34.003783950Z,160,2,1108,C,A,10,13.40,0,0,13.40,23,1,13.26,100,1,14.07,2,1,13.04,2,1,14.12,100,1,13.03,100,1,14.40,100,1,12.73,100,1,14.56,900,3,12.71,100,1,14.60,700,1,12.50,700,1,14.64,100,1,12.46,200,2,14.68,1400,2,12.43,700,1,14.73,100,1,12.42,700,1,14.76,100,1,ARL,300042385
2025-07-17T15:42:34.004225180Z,2025-07-17T15:42:34.004059450Z,160,2,1108,C,A,10,13.40,0,0,13.40,23,1,13.26,100,1,14.07,2,1,13.04,2,1,14.12,100,1,13.03,100,1,14.40,100,1,12.73,100,1,14.56,900,3,12.71,100,1,14.60,700,1,12.50,700,1,14.64,100,1,12.46,200,2,14.68,1400,2,12.43,700,1,14.76,100,1,12.42,700,1,14.81,200,2,ARL,299945073
2025-07-17T15:42:34.004225180Z,2025-07-17T15:42:34.004059450Z,160,2,1108,A,A,10,13.40,0,0,13.40,23,1,13.26,100,1,14.07,2,1,13.04,2,1,14.12,100,1,13.03,100,1,14.40,100,1,12.73,100,1,14.56,900,3,12.71,100,1,14.60,700,1,12.50,700,1,14.64,100,1,12.46,200,2,14.68,1400,2,12.43,700,1,14.76,100,1,12.42,700,1,14.81,200,2,ARL,300280745
2025-07-17T15:42:34.004671652Z,2025-07-17T15:42:34.004506043Z,160,2,1108,C,A,10,13.40,0,0,13.40,23,1,13.26,100,1,14.07,2,1,13.04,2,1,14.12,100,1,13.03,100,1,14.40,100,1,12.73,100,1,14.56,900,3,12.71,100,1,14.60,700,1,12.50,700,1,14.64,100,1,12.46,200,2,14.68,1400,2,12.43,700,1,14.76,100,1,12.42,700,1,14.81,200,2,ARL,300061989
2025-07-17T15:42:34.004671652Z,2025-07-17T15:42:34.004506043Z,160,2,1108,A,A,10,13.40,0,0,13.40,23,1,13.26,100,1,14.07,2,1,13.04,2,1,14.12,100,1,13.03,100,1,14.40,100,1,12.73,100,1,14.56,900,3,12.71,100,1,14.60,700,1,12.50,700,1,14.64,100,1,12.46,200,2,14.68,1400,2,12.43,700,1,14.76,100,1,12.42,700,1,14.81,200,2,ARL,300280757
2025-07-17T15:42:34.004677786Z,2025-07-17T15:42:34.004512153Z,160,2,1108,C,A,10,13.40,0,0,13.40,23,1,13.26,100,1,14.07,2,1,13.04,2,1,14.12,100,1,13.03,100,1,14.40,100,1,12.73,100,1,14.56,900,3,12.71,100,1,14.60,700,1,12.50,700,1,14.64,100,1,12.46,200,2,14.68,1400,2,12.43,700,1,14.81,200,2,12.42,700,1,14.88,100,1,ARL,299903169
2025-07-17T15:42:34.004677786Z,2025-07-17T15:42:34.004512153Z,160,2,1108,A,A,10,13.40,0,0,13.40,23,1,13.26,100,1,14.07,2,1,13.04,2,1,14.12,100,1,13.03,100,1,14.40,100,1,12.73,100,1,14.56,900,3,12.71,100,1,14.60,700,1,12.50,700,1,14.64,100,1,12.46,200,2,14.68,1400,2,12.43,700,1,14.81,200,2,12.42,700,1,14.88,200,2,ARL,300280761
2025-07-17T15:42:34.005574760Z,2025-07-17T15:42:34.005409139Z,160,2,1108,C,A,10,13.40,0,0,13.40,23,1,13.26,100,1,14.07,2,1,13.04,2,1,14.12,100,1,13.03,100,1,14.40,100,1,12.73,100,1,14.56,900,3,12.71,100,1,14.60,700,1,12.50,700,1,14.64,100,1,12.46,200,2,14.68,1400,2,12.43,700,1,14.81,200,2,12.42,700,1,14.88,200,2,ARL,299926853
2025-07-17T15:42:34.005574760Z,2025-07-17T15:42:34.005409139Z,160,2,1108,A,A,10,13.40,0,0,13.40,23,1,13.26,100,1,14.07,2,1,13.04,2,1,14.12,100,1,13.03,100,1,14.40,100,1,12.73,100,1,14.56,900,3,12.71,100,1,14.60,700,1,12.50,700,1,14.64,100,1,12.46,200,2,14.68,1400,2,12.43,700,1,14.81,200,2,12.42,700,1,14.88,200,2,ARL,300280773
2025-07-17T15:42:34.005832926Z,2025-07-17T15:42:34.005667449Z,160,2,1108,C,A,10,13.40,0,0,13.40,23,1,13.26,100,1,14.07,2,1,13.04,2,1,14.12,100,1,13.03,100,1,14.40,100,1,12.73,100,1,14.56,900,3,12.71,100,1,14.60,700,1,12.50,700,1,14.64,100,1,12.46,200,2,14.68,1400,2,12.43,700,1,14.81,100,1,12.42,700,1,14.88,200,2,ARL,299926849
2025-07-17T15:42:34.005832926Z,2025-07-17T15:42:34.005667449Z,160,2,1108,A,A,10,13.40,0,0,13.40,23,1,13.26,100,1,14.07,2,1,13.04,2,1,14.12,100,1,13.03,100,1,14.40,100,1,12.73,100,1,14.56,900,3,12.71,100,1,14.60,700,1,12.50,700,1,14.64,100,1,12.46,200,2,14.68,1400,2,12.43,700,1,14.81,100,1,12.42,700,1,14.88,200,2,ARL,300280777
2025-07-17T15:42:34.006831024Z,2025-07-17T15:42:34.006665512Z,160,2,1108,C,A,10,13.40,0,0,13.40,23,1,13.26,100,1,14.07,2,1,13.04,2,1,14.12,100,1,13.03,100,1,14.40,100,1,12.73,100,1,14.56,900,3,12.71,100,1,14.60,700,1,12.50,700,1,14.64,100,1,12.46,200,2,14.68,1400,2,12.43,700,1,14.81,100,1,12.42,700,1,14.88,200,2,ARL,299926861
2025-07-17T15:42:34.006831024Z,2025-07-17T15:42:34.006665512Z,160,2,1108,A,A,10,13.40,0,0,13.40,23,1,13.26,100,1,14.07,2,1,13.04,2,1,14.12,100,1,13.03,100,1,14.40,100,1,12.73,100,1,14.56,900,3,12.71,100,1,14.60,700,1,12.50,700,1,14.64,100,1,12.46,200,2,14.68,1400,2,12.43,700,1,14.81,100,1,12.42,700,1,14.88,200,2,ARL,300280797
2025-07-17T15:42:34.007908678Z,2025-07-17T15:42:34.007743383Z,160,2,1108,C,A,10,13.40,0,0,13.40,23,1,13.26,100,1,14.07,2,1,13.04,2,1,14.12,100,1,13.03,100,1,14.40,100,1,12.73,100,1,14.56,900,3,12.71,100,1,14.60,700,1,12.50,700,1,14.68,1400,2,12.46,200,2,14.81,100,1,12.43,700,1,14.88,200,2,12.42,700,1,14.96,100,1,ARL,299926813
2025-07-17T15:42:34.008072663Z,2025-07-17T15:42:34.007907269Z,160,2,1108,A,A,10,13.40,0,0,13.40,23,1,13.26,100,1,14.07,2,1,13.04,2,1,14.12,100,1,13.03,100,1,14.40,100,1,12.73,100,1,14.56,900,3,12.71,100,1,14.60,700,1,12.50,700,1,14.68,1400,2,12.46,200,2,14.78,100,1,12.43,700,1,14.81,100,1,12.42,700,1,14.88,200,2,ARL,300280825
2025-07-17T15:42:34.010196831Z,2025-07-17T15:42:34.010031518Z,160,2,1108,C,A,10,13.40,0,0,13.40,23,1,13.26,100,1,14.07,2,1,13.04,2,1,14.40,100,1,13.03,100,1,14.56,900,3,12.73,100,1,14.60,700,1,12.71,100,1,14.68,1400,2,12.50,700,1,14.78,100,1,12.46,200,2,14.81,100,1,12.43,700,1,14.88,200,2,12.42,700,1,14.96,100,1,ARL,299926965
2025-07-17T15:42:34.010248842Z,2025-07-17T15:42:34.010083409Z,160,2,1108,A,A,10,13.40,0,0,13.40,23,1,13.26,100,1,14.07,2,1,13.04,2,1,14.26,100,1,13.03,100,1,14.40,100,1,12.73,100,1,14.56,900,3,12.71,100,1,14.60,700,1,12.50,700,1,14.68,1400,2,12.46,200,2,14.78,100,1,12.43,700,1,14.81,100,1,12.42,700,1,14.88,200,2,ARL,300280857
2025-07-17T15:42:34.010572370Z,2025-07-17T15:42:34.010406771Z,160,2,1108,C,A,10,13.40,0,0,13.40,23,1,13.26,100,1,14.07,2,1,13.04,2,1,14.26,100,1,13.03,100,1,14.40,100,1,12.73,100,1,14.56,900,3,12.71,100,1,14.60,700,1,12.50,700,1,14.68,1400,2,12.46,200,2,14.78,100,1,12.43,700,1,14.88,200,2,12.42,700,1,14.96,100,1,ARL,299926857
2025-07-17T15:42:34.010572370Z,2025-07-17T15:42:34.010406771Z,160,2,1108,A,A,10,13.40,0,0,13.40,23,1,13.26,100,1,14.07,2,1,13.04,2,1,14.26,100,1,13.03,100,1,14.40,100,1,12.73,100,1,14.56,900,3,12.71,100,1,14.60,700,1,12.50,700,1,14.68,1400,2,12.46,200,2,14.78,100,1,12.43,700,1,14.88,200,2,12.42,700,1,14.96,200,2,ARL,300280873
2025-07-17T15:42:34.952098027Z,2025-07-17T15:42:34.951932909Z,160,2,1108,A,A,10,13.40,0,0,13.40,23,1,13.26,100,1,14.07,2,1,13.04,2,1,14.08,100,1,13.03,100,1,14.26,100,1,12.73,100,1,14.40,100,1,12.71,100,1,14.56,900,3,12.50,700,1,14.60,700,1,12.46,200,2,14.68,1400,2,12.43,700,1,14.78,100,1,12.42,700,1,14.88,200,2,ARL,300294885
2025-07-17T15:43:21.513838949Z,2025-07-17T15:43:21.513673603Z,160,2,1108,A,A,10,13.40,0,0,13.40,23,1,13.26,100,1,13.92,15,1,13.04,2,1,14.07,2,1,13.03,100,1,14.08,100,1,12.73,100,1,14.26,100,1,12.71,100,1,14.40,100,1,12.50,700,1,14.56,900,3,12.46,200,2,14.60,700,1,12.43,700,1,14.68,1400,2,12.42,700,1,14.78,100,1,ARL,301218889
2025-07-17T15:43:24.878236760Z,2025-07-17T15:43:24.878071152Z,160,2,1108,C,A,10,13.40,0,0,13.40,23,1,13.26,100,1,13.92,15,1,13.04,2,1,14.07,2,1,13.03,100,1,14.26,100,1,12.73,100,1,14.40,100,1,12.71,100,1,14.56,900,3,12.50,700,1,14.60,700,1,12.46,200,2,14.68,1400,2,12.43,700,1,14.78,100,1,12.42,700,1,14.88,200,2,ARL,300294885
2025-07-17T15:43:24.878236760Z,2025-07-17T15:43:24.878071152Z,160,2,1108,A,A,10,13.40,0,0,13.40,23,1,13.26,100,1,13.92,15,1,13.04,2,1,13.93,100,1,13.03,100,1,14.07,2,1,12.73,100,1,14.26,100,1,12.71,100,1,14.40,100,1,12.50,700,1,14.56,900,3,12.46,200,2,14.60,700,1,12.43,700,1,14.68,1400,2,12.42,700,1,14.78,100,1,ARL,301295841
2025-07-17T15:43:24.879003443Z,2025-07-17T15:43:24.878837670Z,160,2,1108,C,A,10,13.40,0,0,13.40,23,1,13.26,100,1,13.92,15,1,13.04,2,1,13.93,100,1,13.03,100,1,14.07,2,1,12.73,100,1,14.26,100,1,12.71,100,1,14.40,100,1,12.50,700,1,14.56,900,3,12.46,200,2,14.60,700,1,12.43,700,1,14.68,1400,2,12.42,700,1,14.78,100,1,ARL,300280757
2025-07-17T15:43:24.879003443Z,2025-07-17T15:43:24.878837670Z,160,2,1108,A,A,10,13.40,0,0,13.40,23,1,13.26,100,1,13.92,15,1,13.04,2,1,13.93,100,1,13.03,100,1,14.07,2,1,12.73,100,1,14.26,100,1,12.71,100,1,14.40,100,1,12.50,700,1,14.56,900,3,12.46,200,2,14.60,700,1,12.43,700,1,14.68,1400,2,12.42,700,1,14.78,100,1,ARL,301295873
2025-07-17T15:43:32.780372412Z,2025-07-17T15:43:32.780206927Z,160,2,1108,A,A,10,13.40,0,0,13.40,23,1,13.26,100,1,13.88,15,1,13.04,2,1,13.92,15,1,13.03,100,1,13.93,100,1,12.73,100,1,14.07,2,1,12.71,100,1,14.26,100,1,12.50,700,1,14.40,100,1,12.46,200,2,14.56,900,3,12.43,700,1,14.60,700,1,12.42,700,1,14.68,1400,2,ARL,301451057
2025-07-17T15:43:32.780639619Z,2025-07-17T15:43:32.780474141Z,160,2,1108,C,A,10,13.40,0,0,13.40,23,1,13.26,100,1,13.88,15,1,13.04,2,1,13.92,15,1,13.03,100,1,14.07,2,1,12.73,100,1,14.26,100,1,12.71,100,1,14.40,100,1,12.50,700,1,14.56,900,3,12.46,200,2,14.60,700,1,12.43,700,1,14.68,1400,2,12.42,700,1,14.78,100,1,ARL,301295841
2025-07-17T15:43:32.780639619Z,2025-07-17T15:43:32.780474141Z,160,2,1108,A,A,10,13.40,0,0,13.40,23,1,13.26,100,1,13.88,15,1,13.04,2,1,13.89,100,1,13.03,100,1,13.92,15,1,12.73,100,1,14.07,2,1,12.71,100,1,14.26,100,1,12.50,700,1,14.40,100,1,12.46,200,2,14.56,900,3,12.43,700,1,14.60,700,1,12.42,700,1,14.68,1400,2,ARL,301451061
2025-07-17T15:43:32.781382162Z,2025-07-17T15:43:32.781216589Z,160,2,1108,C,A,10,13.40,0,0,13.40,23,1,13.26,100,1,13.88,15,1,13.04,2,1,13.89,100,1,13.03,100,1,13.92,15,1,12.73,100,1,14.07,2,1,12.71,100,1,14.26,100,1,12.50,700,1,14.40,100,1,12.46,200,2,14.56,900,3,12.43,700,1,14.60,700,1,12.42,700,1,14.68,1400,2,ARL,301295873
2025-07-17T15:43:32.781382162Z,2025-07-17T15:43:32.781216589Z,160,2,1108,A,A,10,13.40,0,0,13.40,23,1,13.26,100,1,13.88,15,1,13.04,2,1,13.89,100,1,13.03,100,1,13.92,15,1,12.73,100,1,14.07,2,1,12.71,100,1,14.26,100,1,12.50,700,1,14.40,100,1,12.46,200,2,14.56,900,3,12.43,700,1,14.60,700,1,12.42,700,1,14.68,1400,2,ARL,301451077
2025-07-17T15:43:32.792119698Z,2025-07-17T15:43:32.791954053Z,160,2,1108,C,A,10,13.40,0,0,13.40,23,1,13.26,100,1,13.88,15,1,13.04,2,1,13.89,100,1,13.03,100,1,13.92,15,1,12.73,100,1,14.07,2,1,12.71,100,1,14.40,100,1,12.50,700,1,14.56,900,3,12.46,200,2,14.60,700,1,12.43,700,1,14.68,1400,2,12.42,700,1,14.78,100,1,ARL,300280857
2025-07-17T15:43:32.792174617Z,2025-07-17T15:43:32.792008881Z,160,2,1108,A,A,10,13.40,0,0,13.40,23,1,13.26,100,1,13.88,15,1,13.04,2,1,13.89,100,1,13.03,100,1,13.92,15,1,12.73,100,1,14.07,2,1,12.71,100,1,14.17,100,1,12.50,700,1,14.40,100,1,12.46,200,2,14.56,900,3,12.43,700,1,14.60,700,1,12.42,700,1,14.68,1400,2,ARL,301452785
2025-07-17T15:43:44.004832641Z,2025-07-17T15:43:44.004667259Z,160,2,1108,C,A,10,13.40,0,0,13.40,23,1,13.26,100,1,13.88,15,1,13.04,2,1,13.89,100,1,13.03,100,1,14.07,2,1,12.73,100,1,14.17,100,1,12.71,100,1,14.40,100,1,12.50,700,1,14.56,900,3,12.46,200,2,14.60,700,1,12.43,700,1,14.68,1400,2,12.42,700,1,14.78,100,1,ARL,301218889
2025-07-17T15:43:44.005191111Z,2025-07-17T15:43:44.005025587Z,160,2,1108,C,A,10,13.40,0,0,13.40,23,1,13.26,100,1,13.88,15,1,13.04,2,1,13.89,100,1,13.03,100,1,14.07,2,1,12.73,100,1,14.17,100,1,12.71,100,1,14.40,100,1,12.50,700,1,14.56,900,3,12.46,200,2,14.60,700,1,12.43,700,1,14.68,1400,2,12.42,700,1,14.78,100,1,ARL,300280761
2025-07-17T15:43:44.005191111Z,2025-07-17T15:43:44.005025587Z,160,2,1108,A,A,10,13.40,0,0,13.40,23,1,13.26,100,1,13.88,15,1,13.04,2,1,13.89,100,1,13.03,100,1,14.07,2,1,12.73,100,1,14.17,100,1,12.71,100,1,14.40,100,1,12.50,700,1,14.56,900,3,12.46,200,2,14.60,700,1,12.43,700,1,14.68,1400,2,12.42,700,1,14.77,100,1,ARL,301671709
2025-07-17T15:43:44.005313071Z,2025-07-17T15:43:44.005147707Z,160,2,1108,C,A,10,13.40,0,0,13.40,23,1,13.26,100,1,13.88,15,1,13.04,2,1,13.89,100,1,13.03,100,1,14.07,2,1,12.73,100,1,14.17,100,1,12.71,100,1,14.40,100,1,12.50,700,1,14.56,900,3,12.46,200,2,14.60,700,1,12.43,700,1,14.68,1400,2,12.42,700,1,14.77,100,1,ARL,300280745
2025-07-17T15:43:44.005313071Z,2025-07-17T15:43:44.005147707Z,160,2,1108,A,A,10,13.40,0,0,13.40,23,1,13.26,100,1,13.88,15,1,13.04,2,1,13.89,100,1,13.03,100,1,14.07,2,1,12.73,100,1,14.17,100,1,12.71,100,1,14.40,100,1,12.50,700,1,14.56,900,3,12.46,200,2,14.60,700,1,12.43,700,1,14.68,1400,2,12.42,700,1,14.77,200,2,ARL,301671713
2025-07-17T15:43:48.787497664Z,2025-07-17T15:43:48.787332399Z,160,2,1108,A,A,10,13.40,0,0,13.40,23,1,13.26,100,1,13.83,15,1,13.04,2,1,13.88,15,1,13.03,100,1,13.89,100,1,12.73,100,1,14.07,2,1,12.71,100,1,14.17,100,1,12.50,700,1,14.40,100,1,12.46,200,2,14.56,900,3,12.43,700,1,14.60,700,1,12.42,700,1,14.68,1400,2,ARL,301746941
2025-07-17T15:43:48.787766907Z,2025-07-17T15:43:48.787601640Z,160,2,1108,C,A,10,13.40,0,0,13.40,23,1,13.26,100,1,13.83,15,1,13.04,2,1,13.88,15,1,13.03,100,1,14.07,2,1,12.73,100,1,14.17,100,1,12.71,100,1,14.40,100,1,12.50,700,1,14.56,900,3,12.46,200,2,14.60,700,1,12.43,700,1,14.68,1400,2,12.42,700,1,14.77,200,2,ARL,301451061
2025-07-17T15:43:48.787766907Z,2025-07-17T15:43:48.787601640Z,160,2,1108,A,A,10,13.40,0,0,13.40,23,1,13.26,100,1,13.83,15,1,13.04,2,1,13.84,100,1,13.03,100,1,13.88,15,1,12.73,100,1,14.07,2,1,12.71,100,1,14.17,100,1,12.50,700,1,14.40,100,1,12.46,200,2,14.56,900,3,12.43,700,1,14.60,700,1,12.42,700,1,14.68,1400,2,ARL,301746949
2025-07-17T15:43:48.788512022Z,2025-07-17T15:43:48.788345787Z,160,2,1108,C,A,10,13.40,0,0,13.40,23,1,13.26,100,1,13.83,15,1,13.04,2,1,13.84,100,1,13.03,100,1,13.88,15,1,12.73,100,1,14.07,2,1,12.71,100,1,14.17,100,1,12.50,700,1,14.40,100,1,12.46,200,2,14.56,900,3,12.43,700,1,14.60,700,1,12.42,700,1,14.68,1400,2,ARL,301451077
2025-07-17T15:43:48.788512022Z,2025-07-17T15:43:48.788345787Z,160,2,1108,A,A,10,13.40,0,0,13.40,23,1,13.26,100,1,13.83,15,1,13.04,2,1,13.84,100,1,13.03,100,1,13.88,15,1,12.73,100,1,14.07,2,1,12.71,100,1,14.17,100,1,12.50,700,1,14.40,100,1,12.46,200,2,14.56,900,3,12.43,700,1,14.60,700,1,12.42,700,1,14.68,1400,2,ARL,301746969
2025-07-17T15:43:48.790573820Z,2025-07-17T15:43:48.790408191Z,160,2,1108,C,A,10,13.40,0,0,13.40,23,1,13.26,100,1,13.83,15,1,13.04,2,1,13.84,100,1,13.03,100,1,13.88,15,1,12.73,100,1,14.07,2,1,12.71,100,1,14.17,100,1,12.50,700,1,14.40,100,1,12.46,200,2,14.56,900,3,12.43,700,1,14.60,700,1,12.42,700,1,14.68,1400,2,ARL,300280777
2025-07-17T15:43:48.790573820Z,2025-07-17T15:43:48.790408191Z,160,2,1108,A,A,10,13.40,0,0,13.40,23,1,13.26,100,1,13.83,15,1,13.04,2,1,13.84,100,1,13.03,100,1,13.88,15,1,12.73,100,1,14.07,2,1,12.71,100,1,14.17,100,1,12.50,700,1,14.40,100,1,12.46,200,2,14.56,900,3,12.43,700,1,14.60,700,1,12.42,700,1,14.68,1400,2,ARL,301747001
2025-07-17T15:43:48.790600546Z,2025-07-17T15:43:48.790434947Z,160,2,1108,C,A,10,13.40,0,0,13.40,23,1,13.26,100,1,13.83,15,1,13.04,2,1,13.84,100,1,13.03,100,1,13.88,15,1,12.73,100,1,14.07,2,1,12.71,100,1,14.17,100,1,12.50,700,1,14.40,100,1,12.46,200,2,14.56,900,3,12.43,700,1,14.60,700,1,12.42,700,1,14.68,1400,2,ARL,300280825
2025-07-17T15:43:48.790600546Z,2025-07-17T15:43:48.790434947Z,160,2,1108,A,A,10,13.40,0,0,13.40,23,1,13.26,100,1,13.83,15,1,13.04,2,1,13.84,100,1,13.03,100,1,13.88,15,1,12.73,100,1,14.07,2,1,12.71,100,1,14.17,100,1,12.50,700,1,14.40,100,1,12.46,200,2,14.56,900,3,12.43,700,1,14.60,700,1,12.42,700,1,14.64,100,1,ARL,301747005
2025-07-17T15:43:48.800959598Z,2025-07-17T15:43:48.800794196Z,160,2,1108,C,A,10,13.40,0,0,13.40,23,1,13.26,100,1,13.83,15,1,13.04,2,1,13.84,100,1,13.03,100,1,13.88,15,1,12.73,100,1,14.07,2,1,12.71,100,1,14.17,100,1,12.50,700,1,14.40,100,1,12.46,200,2,14.56,900,3,12.43,700,1,14.60,700,1,12.42,700,1,14.64,100,1,ARL,300280797
2025-07-17T15:43:48.800959598Z,2025-07-17T15:43:48.800794196Z,160,2,1108,A,A,10,13.40,0,0,13.40,23,1,13.26,100,1,13.83,15,1,13.04,2,1,13.84,100,1,13.03,100,1,13.88,15,1,12.73,100,1,14.07,2,1,12.71,100,1,14.17,100,1,12.50,700,1,14.40,100,1,12.46,200,2,14.56,900,3,12.43,700,1,14.60,700,1,12.42,700,1,14.64,100,1,ARL,301747261
2025-07-17T15:43:48.806845249Z,2025-07-17T15:43:48.806679708Z,160,2,1108,C,A,10,13.40,0,0,13.40,23,1,13.26,100,1,13.83,15,1,13.04,2,1,13.84,100,1,13.03,100,1,13.88,15,1,12.73,100,1,14.07,2,1,12.71,100,1,14.17,100,1,12.50,700,1,14.40,100,1,12.46,200,2,14.56,900,3,12.43,700,1,14.60,700,1,12.42,700,1,14.64,100,1,ARL,300280773
2025-07-17T15:43:48.806845249Z,2025-07-17T15:43:48.806679708Z,160,2,1108,A,A,10,13.40,0,0,13.40,23,1,13.26,100,1,13.83,15,1,13.04,2,1,13.84,100,1,13.03,100,1,13.88,15,1,12.73,100,1,14.07,2,1,12.71,100,1,14.17,100,1,12.50,700,1,14.40,100,1,12.46,200,2,14.56,900,3,12.43,700,1,14.60,700,1,12.42,700,1,14.64,100,1,ARL,301747301
2025-07-17T15:43:48.852570853Z,2025-07-17T15:43:48.852405047Z,160,2,1108,C,A,10,13.40,0,0,13.40,23,1,13.26,100,1,13.83,15,1,13.04,2,1,13.84,100,1,13.03,100,1,13.88,15,1,12.73,100,1,14.07,2,1,12.71,100,1,14.17,100,1,12.50,700,1,14.40,100,1,12.46,200,2,14.56,900,3,12.43,700,1,14.60,700,1,12.42,700,1,14.64,100,1,ARL,300280873
2025-07-17T15:43:48.852570853Z,2025-07-17T15:43:48.852405047Z,160,2,1108,A,A,10,13.40,0,0,13.40,23,1,13.26,100,1,13.83,15,1,13.04,2,1,13.84,100,1,13.03,100,1,13.88,15,1,12.73,100,1,14.07,2,1,12.71,100,1,14.17,100,1,12.50,700,1,14.40,100,1,12.46,200,2,14.56,900,3,12.43,700,1,14.60,700,1,12.42,700,1,14.64,100,1,ARL,301747957
2025-07-17T15:43:53.123817759Z,2025-07-17T15:43:53.123652480Z,160,2,1108,C,A,10,13.40,0,0,13.40,23,1,13.26,100,1,13.83,15,1,13.04,2,1,13.84,100,1,13.03,100,1,14.07,2,1,12.73,100,1,14.17,100,1,12.71,100,1,14.40,100,1,12.50,700,1,14.56,900,3,12.46,200,2,14.60,700,1,12.43,700,1,14.64,100,1,12.42,700,1,14.68,1400,2,ARL,301451057
2025-07-17T15:43:54.126276976Z,2025-07-17T15:43:54.126111293Z,160,2,1108,A,A,10,13.40,0,0,13.40,23,1,13.26,100,1,13.81,15,1,13.04,2,1,13.83,15,1,13.03,100,1,13.84,100,1,12.73,100,1,14.07,2,1,12.71,100,1,14.17,100,1,12.50,700,1,14.40,100,1,12.46,200,2,14.56,900,3,12.43,700,1,14.60,700,1,12.42,700,1,14.64,100,1,ARL,301867541
2025-07-17T15:43:54.998238933Z,2025-07-17T15:43:54.998073317Z,160,2,1108,C,A,10,13.40,0,0,13.40,23,1,13.26,100,1,13.81,15,1,13.04,2,1,13.83,15,1,13.03,100,1,14.07,2,1,12.73,100,1,14.17,100,1,12.71,100,1,14.40,100,1,12.50,700,1,14.56,900,3,12.46,200,2,14.60,700,1,12.43,700,1,14.64,100,1,12.42,700,1,14.68,1400,2,ARL,301746949
2025-07-17T15:43:54.998238933Z,2025-07-17T15:43:54.998073317Z,160,2,1108,A,A,10,13.40,0,0,13.40,23,1,13.26,100,1,13.81,15,1,13.04,2,1,13.82,100,1,13.03,100,1,13.83,15,1,12.73,100,1,14.07,2,1,12.71,100,1,14.17,100,1,12.50,700,1,14.40,100,1,12.46,200,2,14.56,900,3,12.43,700,1,14.60,700,1,12.42,700,1,14.64,100,1,ARL,301885353
2025-07-17T15:43:55.019172741Z,2025-07-17T15:43:55.019007300Z,160,2,1108,C,A,10,13.40,0,0,13.40,23,1,13.26,100,1,13.81,15,1,13.04,2,1,13.82,100,1,13.03,100,1,13.83,15,1,12.73,100,1,14.07,2,1,12.71,100,1,14.40,100,1,12.50,700,1,14.56,900,3,12.46,200,2,14.60,700,1,12.43,700,1,14.64,100,1,12.42,700,1,14.68,1400,2,ARL,301452785
2025-07-17T15:43:55.019225935Z,2025-07-17T15:43:55.019060515Z,160,2,1108,A,A,10,13.40,0,0,13.40,23,1,13.26,100,1,13.81,15,1,13.04,2,1,13.82,100,1,13.03,100,1,13.83,15,1,12.73,100,1,14.07,2,1,12.71,100,1,14.10,100,1,12.50,700,1,14.40,100,1,12.46,200,2,14.56,900,3,12.43,700,1,14.60,700,1,12.42,700,1,14.64,100,1,ARL,301886057
2025-07-17T15:44:01.698791467Z,2025-07-17T15:44:01.698626200Z,160,2,1108,C,A,10,13.40,0,0,13.40,23,1,13.26,100,1,13.81,15,1,13.04,2,1,13.82,100,1,13.03,100,1,14.07,2,1,12.73,100,1,14.10,100,1,12.71,100,1,14.40,100,1,12.50,700,1,14.56,900,3,12.46,200,2,14.60,700,1,12.43,700,1,14.64,100,1,12.42,700,1,14.68,1400,2,ARL,301746941
2025-07-17T15:44:04.014878156Z,2025-07-17T15:44:04.014712730Z,160,2,1108,A,A,10,13.40,0,0,13.40,23,1,13.26,100,1,13.81,15,1,13.04,2,1,13.82,100,1,13.03,100,1,13.83,100,1,12.73,100,1,14.07,2,1,12.71,100,1,14.10,100,1,12.50,700,1,14.40,100,1,12.46,200,2,14.56,900,3,12.43,700,1,14.60,700,1,12.42,700,1,14.64,100,1,ARL,302078553
2025-07-17T15:44:05.055626948Z,2025-07-17T15:44:05.055461574Z,160,2,1108,A,A,10,13.40,0,0,13.40,23,1,13.26,100,1,13.81,115,2,13.04,2,1,13.82,100,1,13.03,100,1,13.83,100,1,12.73,100,1,14.07,2,1,12.71,100,1,14.10,100,1,12.50,700,1,14.40,100,1,12.46,200,2,14.56,900,3,12.43,700,1,14.60,700,1,12.42,700,1,14.64,100,1,ARL,302100649
2025-07-17T15:44:05.062431949Z,2025-07-17T15:44:05.062266845Z,160,2,1108,C,A,10,13.40,0,0,13.40,23,1,13.26,100,1,13.81,115,2,13.04,2,1,13.82,100,1,13.03,100,1,14.07,2,1,12.73,100,1,14.10,100,1,12.71,100,1,14.40,100,1,12.50,700,1,14.56,900,3,12.46,200,2,14.60,700,1,12.43,700,1,14.64,100,1,12.42,700,1,14.68,1400,2,ARL,302078553
2025-07-17T15:44:09.389713730Z,2025-07-17T15:44:09.389548394Z,160,2,1108,A,A,10,13.40,0,0,13.40,23,1,13.26,100,1,13.76,15,1,13.04,2,1,13.81,115,2,13.03,100,1,13.82,100,1,12.73,100,1,14.07,2,1,12.71,100,1,14.10,100,1,12.50,700,1,14.40,100,1,12.46,200,2,14.56,900,3,12.43,700,1,14.60,700,1,12.42,700,1,14.64,100,1,ARL,302205249
2025-07-17T15:44:09.390496140Z,2025-07-17T15:44:09.390329935Z,160,2,1108,C,A,10,13.40,0,0,13.40,23,1,13.26,100,1,13.76,15,1,13.04,2,1,13.81,115,2,13.03,100,1,13.82,100,1,12.73,100,1,14.07,2,1,12.71,100,1,14.10,100,1,12.50,700,1,14.40,100,1,12.46,200,2,14.56,900,3,12.43,700,1,14.60,700,1,12.42,700,1,14.64,100,1,ARL,301671709
2025-07-17T15:44:09.390496140Z,2025-07-17T15:44:09.390329935Z,160,2,1108,A,A,10,13.40,0,0,13.40,23,1,13.26,100,1,13.76,15,1,13.04,2,1,13.81,115,2,13.03,100,1,13.82,100,1,12.73,100,1,14.07,2,1,12.71,100,1,14.10,100,1,12.50,700,1,14.40,100,1,12.46,200,2,14.56,900,3,12.43,700,1,14.60,700,1,12.42,700,1,14.64,100,1,ARL,302205289
2025-07-17T15:44:09.391058486Z,2025-07-17T15:44:09.390893172Z,160,2,1108,C,A,10,13.40,0,0,13.40,23,1,13.26,100,1,13.76,15,1,13.04,2,1,13.81,115,2,13.03,100,1,13.82,100,1,12.73,100,1,14.07,2,1,12.71,100,1,14.10,100,1,12.50,700,1,14.40,100,1,12.46,200,2,14.56,900,3,12.43,700,1,14.60,700,1,12.42,700,1,14.64,100,1,ARL,301671713
2025-07-17T15:44:09.391058486Z,2025-07-17T15:44:09.390893172Z,160,2,1108,A,A,10,13.40,0,0,13.40,23,1,13.26,100,1,13.76,15,1,13.04,2,1,13.81,115,2,13.03,100,1,13.82,100,1,12.73,100,1,14.07,2,1,12.71,100,1,14.10,100,1,12.50,700,1,14.40,100,1,12.46,200,2,14.56,900,3,12.43,700,1,14.60,700,1,12.42,700,1,14.64,100,1,ARL,302205309
2025-07-17T15:44:09.395447612Z,2025-07-17T15:44:09.395281780Z,160,2,1108,C,A,10,13.40,0,0,13.40,23,1,13.26,100,1,13.76,15,1,13.04,2,1,13.81,115,2,13.03,100,1,14.07,2,1,12.73,100,1,14.10,100,1,12.71,100,1,14.40,100,1,12.50,700,1,14.56,900,3,12.46,200,2,14.60,700,1,12.43,700,1,14.64,100,1,12.42,700,1,14.66,200,2,ARL,301885353
2025-07-17T15:44:09.395447612Z,2025-07-17T15:44:09.395281780Z,160,2,1108,A,A,10,13.40,0,0,13.40,23,1,13.26,100,1,13.76,15,1,13.04,2,1,13.77,100,1,13.03,100,1,13.81,115,2,12.73,100,1,14.07,2,1,12.71,100,1,14.10,100,1,12.50,700,1,14.40,100,1,12.46,200,2,14.56,900,3,12.43,700,1,14.60,700,1,12.42,700,1,14.64,100,1,ARL,302205493
2025-07-17T15:44:09.396195647Z,2025-07-17T15:44:09.396030225Z,160,2,1108,C,A,10,13.40,0,0,13.40,23,1,13.26,100,1,13.76,15,1,13.04,2,1,13.77,100,1,13.03,100,1,13.81,115,2,12.73,100,1,14.07,2,1,12.71,100,1,14.10,100,1,12.50,700,1,14.40,100,1,12.46,200,2,14.56,900,3,12.43,700,1,14.60,700,1,12.42,700,1,14.64,100,1,ARL,301746969
2025-07-17T15:44:09.396195647Z,2025-07-17T15:44:09.396030225Z,160,2,1108,A,A,10,13.40,0,0,13.40,23,1,13.26,100,1,13.76,15,1,13.04,2,1,13.77,100,1,13.03,100,1,13.81,115,2,12.73,100,1,14.07,2,1,12.71,100,1,14.10,100,1,12.50,700,1,14.40,100,1,12.46,200,2,14.56,900,3,12.43,700,1,14.60,700,1,12.42,700,1,14.64,100,1,ARL,302205537
2025-07-17T15:44:09.398011186Z,2025-07-17T15:44:09.397845986Z,160,2,1108,A,A,10,13.40,0,0,13.40,23,1,13.26,100,1,13.76,15,1,13.04,2,1,13.77,100,1,13.03,100,1,13.79,100,1,12.73,100,1,13.81,115,2,12.71,100,1,14.07,2,1,12.50,700,1,14.10,100,1,12.46,200,2,14.40,100,1,12.43,700,1,14.56,900,3,12.42,700,1,14.60,700,1,ARL,302205561
2025-07-17T15:44:09.404828956Z,2025-07-17T15:44:09.404663816Z,160,2,1108,C,A,10,13.40,0,0,13.40,23,1,13.26,100,1,13.76,15,1,13.04,2,1,13.77,100,1,13.03,100,1,13.79,100,1,12.73,100,1,13.81,15,1,12.71,100,1,14.07,2,1,12.50,700,1,14.10,100,1,12.46,200,2,14.40,100,1,12.43,700,1,14.56,900,3,12.42,700,1,14.60,700,1,ARL,302100649
2025-07-17T15:44:20.402535831Z,2025-07-17T15:44:20.402370565Z,160,2,1108,C,A,10,13.40,0,0,13.40,23,1,13.26,100,1,13.76,15,1,13.04,2,1,13.77,100,1,13.03,100,1,13.79,100,1,12.73,100,1,14.07,2,1,12.71,100,1,14.10,100,1,12.50,700,1,14.40,100,1,12.46,200,2,14.56,900,3,12.43,700,1,14.60,700,1,12.42,700,1,14.64,100,1,ARL,301867541
2025-07-17T15:44:21.405486122Z,2025-07-17T15:44:21.405320730Z,160,2,1108,A,A,10,13.40,0,0,13.40,23,1,13.26,100,1,13.74,15,1,13.04,2,1,13.76,15,1,13.03,100,1,13.77,100,1,12.73,100,1,13.79,100,1,12.71,100,1,14.07,2,1,12.50,700,1,14.10,100,1,12.46,200,2,14.40,100,1,12.43,700,1,14.56,900,3,12.42,700,1,14.60,700,1,ARL,302458113
2025-07-17T15:44:21.843235911Z,2025-07-17T15:44:21.843070079Z,160,2,1108,C,A,10,13.40,0,0,13.40,23,1,13.26,100,1,13.74,15,1,13.04,2,1,13.76,15,1,13.03,100,1,13.79,100,1,12.73,100,1,14.07,2,1,12.71,100,1,14.10,100,1,12.50,700,1,14.40,100,1,12.46,200,2,14.56,900,3,12.43,700,1,14.60,700,1,12.42,700,1,14.64,100,1,ARL,302205493
2025-07-17T15:44:21.843235911Z,2025-07-17T15:44:21.843070079Z,160,2,1108,A,A,10,13.40,0,0,13.40,23,1,13.26,100,1,13.74,15,1,13.04,2,1,13.75,100,1,13.03,100,1,13.76,15,1,12.73,100,1,13.79,100,1,12.71,100,1,14.07,2,1,12.50,700,1,14.10,100,1,12.46,200,2,14.40,100,1,12.43,700,1,14.56,900,3,12.42,700,1,14.60,700,1,ARL,302466045
2025-07-17T15:44:21.855416093Z,2025-07-17T15:44:21.855250804Z,160,2,1108,C,A,10,13.40,0,0,13.40,23,1,13.26,100,1,13.74,15,1,13.04,2,1,13.75,100,1,13.03,100,1,13.76,15,1,12.73,100,1,13.79,100,1,12.71,100,1,14.07,2,1,12.50,700,1,14.40,100,1,12.46,200,2,14.56,900,3,12.43,700,1,14.60,700,1,12.42,700,1,14.64,100,1,ARL,301886057
2025-07-17T15:44:21.855471158Z,2025-07-17T15:44:21.855305995Z,160,2,1108,A,A,10,13.40,0,0,13.40,23,1,13.26,100,1,13.74,15,1,13.04,2,1,13.75,100,1,13.03,100,1,13.76,15,1,12.73,100,1,13.79,100,1,12.71,100,1,14.03,100,1,12.50,700,1,14.07,2,1,12.46,200,2,14.40,100,1,12.43,700,1,14.56,900,3,12.42,700,1,14.60,700,1,ARL,302466157
2025-07-17T15:44:24.447075532Z,2025-07-17T15:44:24.446910206Z,160,2,1108,A,A,10,13.40,0,0,13.40,23,1,13.26,100,1,13.74,15,1,13.04,2,1,13.75,100,1,13.03,100,1,13.76,15,1,12.73,100,1,13.77,100,1,12.71,100,1,13.79,100,1,12.50,700,1,14.03,100,1,12.46,200,2,14.07,2,1,12.43,700,1,14.40,100,1,12.42,700,1,14.56,900,3,ARL,302500469
2025-07-17T15:44:24.465555818Z,2025-07-17T15:44:24.465390625Z,160,2,1108,C,A,10,13.40,0,0,13.40,23,1,13.26,100,1,13.74,15,1,13.04,2,1,13.75,100,1,13.03,100,1,13.76,15,1,12.73,100,1,13.77,100,1,12.71,100,1,14.03,100,1,12.50,700,1,14.07,2,1,12.46,200,2,14.40,100,1,12.43,700,1,14.56,900,3,12.42,700,1,14.60,700,1,ARL,302205561
2025-07-17T15:44:30.846822983Z,2025-07-17T15:44:30.846657613Z,160,2,1108,C,A,10,13.40,0,0,13.40,23,1,13.26,100,1,13.74,15,1,13.04,2,1,13.75,100,1,13.03,100,1,13.77,100,1,12.73,100,1,14.03,100,1,12.71,100,1,14.07,2,1,12.50,700,1,14.40,100,1,12.46,200,2,14.56,900,3,12.43,700,1,14.60,700,1,12.42,700,1,14.64,100,1,ARL,302205249
2025-07-17T15:44:31.849784693Z,2025-07-17T15:44:31.849618640Z,160,2,1108,A,A,10,13.40,0,0,13.40,23,1,13.26,100,1,13.72,15,1,13.04,2,1,13.74,15,1,13.03,100,1,13.75,100,1,12.73,100,1,13.77,100,1,12.71,100,1,14.03,100,1,12.50,700,1,14.07,2,1,12.46,200,2,14.40,100,1,12.43,700,1,14.56,900,3,12.42,700,1,14.60,700,1,ARL,302649021
2025-07-17T15:44:31.849921857Z,2025-07-17T15:44:31.849756452Z,160,2,1108,A,A,10,13.40,0,0,13.40,23,1,13.26,100,1,13.72,15,1,13.04,2,1,13.74,15,1,13.03,100,1,13.75,200,2,12.73,100,1,13.77,100,1,12.71,100,1,14.03,100,1,12.50,700,1,14.07,2,1,12.46,200,2,14.40,100,1,12.43,700,1,14.56,900,3,12.42,700,1,14.60,700,1,ARL,302649029
2025-07-17T15:44:31.910124978Z,2025-07-17T15:44:31.909959614Z,160,2,1108,C,A,10,13.40,0,0,13.40,23,1,13.26,100,1,13.72,15,1,13.04,2,1,13.74,15,1,13.03,100,1,13.75,200,2,12.73,100,1,14.03,100,1,12.71,100,1,14.07,2,1,12.50,700,1,14.40,100,1,12.46,200,2,14.56,900,3,12.43,700,1,14.60,700,1,12.42,700,1,14.64,100,1,ARL,302500469
2025-07-17T15:44:32.484497230Z,2025-07-17T15:44:32.484331764Z,160,2,1108,C,A,10,13.40,0,0,13.40,23,1,13.26,100,1,13.72,15,1,13.04,2,1,13.74,15,1,13.03,100,1,13.75,100,1,12.73,100,1,14.03,100,1,12.71,100,1,14.07,2,1,12.50,700,1,14.40,100,1,12.46,200,2,14.56,900,3,12.43,700,1,14.60,700,1,12.42,700,1,14.64,100,1,ARL,302466045
2025-07-17T15:44:32.484497230Z,2025-07-17T15:44:32.484331764Z,160,2,1108,A,A,10,13.40,0,0,13.40,23,1,13.26,100,1,13.72,15,1,13.04,2,1,13.73,100,1,13.03,100,1,13.74,15,1,12.73,100,1,13.75,100,1,12.71,100,1,14.03,100,1,12.50,700,1,14.07,2,1,12.46,200,2,14.40,100,1,12.43,700,1,14.56,900,3,12.42,700,1,14.60,700,1,ARL,302662769
2025-07-17T15:44:32.485238209Z,2025-07-17T15:44:32.485072552Z,160,2,1108,C,A,10,13.40,0,0,13.40,23,1,13.26,100,1,13.72,15,1,13.04,2,1,13.73,100,1,13.03,100,1,13.74,15,1,12.73,100,1,13.75,100,1,12.71,100,1,14.03,100,1,12.50,700,1,14.07,2,1,12.46,200,2,14.40,100,1,12.43,700,1,14.56,900,3,12.42,700,1,14.60,700,1,ARL,302205537
2025-07-17T15:44:32.485238209Z,2025-07-17T15:44:32.485072552Z,160,2,1108,A,A,10,13.40,0,0,13.40,23,1,13.26,100,1,13.72,15,1,13.04,2,1,13.73,100,1,13.03,100,1,13.74,15,1,12.73,100,1,13.75,100,1,12.71,100,1,14.03,100,1,12.50,700,1,14.07,2,1,12.46,200,2,14.40,100,1,12.43,700,1,14.56,900,3,12.42,700,1,14.60,700,1,ARL,302662821
2025-07-17T15:44:33.389387814Z,2025-07-17T15:44:33.389222513Z,160,2,1108,A,A,10,13.40,0,0,13.40,23,1,13.26,100,1,13.72,15,1,13.04,2,1,13.73,100,1,13.03,100,1,13.74,15,1,12.73,100,1,13.75,100,1,12.71,100,1,14.03,100,1,12.50,700,1,14.07,2,1,12.46,200,2,14.28,100,1,12.43,700,1,14.40,100,1,12.42,700,1,14.56,900,3,ARL,302681357
2025-07-17T15:44:33.389389030Z,2025-07-17T15:44:33.389223581Z,160,2,1108,C,A,10,13.40,0,0,13.40,23,1,13.26,100,1,13.72,15,1,13.04,2,1,13.73,100,1,13.03,100,1,13.74,15,1,12.73,100,1,13.75,100,1,12.71,100,1,14.03,100,1,12.50,700,1,14.07,2,1,12.46,200,2,14.28,100,1,12.43,700,1,14.40,100,1,12.42,700,1,14.56,800,2,ARL,146960005
2025-07-17T15:44:36.362187673Z,2025-07-17T15:44:36.362022168Z,160,2,1108,C,A,10,13.40,0,0,13.40,23,1,13.26,100,1,13.72,15,1,13.04,2,1,13.73,100,1,13.03,100,1,13.75,100,1,12.73,100,1,14.03,100,1,12.71,100,1,14.07,2,1,12.50,700,1,14.28,100,1,12.46,200,2,14.40,100,1,12.43,700,1,14.56,800,2,12.42,700,1,14.60,700,1,ARL,302458113
2025-07-17T15:44:37.364377419Z,2025-07-17T15:44:37.364212109Z,160,2,1108,A,A,10,13.40,0,0,13.40,23,1,13.26,100,1,13.70,15,1,13.04,2,1,13.72,15,1,13.03,100,1,13.73,100,1,12.73,100,1,13.75,100,1,12.71,100,1,14.03,100,1,12.50,700,1,14.07,2,1,12.46,200,2,14.28,100,1,12.43,700,1,14.40,100,1,12.42,700,1,14.56,800,2,ARL,302750929
2025-07-17T15:44:37.364519067Z,2025-07-17T15:44:37.364353897Z,160,2,1108,A,A,10,13.40,0,0,13.40,23,1,13.26,100,1,13.70,15,1,13.04,2,1,13.72,15,1,13.03,100,1,13.73,200,2,12.73,100,1,13.75,100,1,12.71,100,1,14.03,100,1,12.50,700,1,14.07,2,1,12.46,200,2,14.28,100,1,12.43,700,1,14.40,100,1,12.42,700,1,14.56,800,2,ARL,302750937
2025-07-17T15:44:37.458119494Z,2025-07-17T15:44:37.457954350Z,160,2,1108,C,A,10,13.40,0,0,13.40,23,1,13.26,100,1,13.70,15,1,13.04,2,1,13.72,15,1,13.03,100,1,13.73,200,2,12.73,100,1,14.03,100,1,12.71,100,1,14.07,2,1,12.50,700,1,14.28,100,1,12.46,200,2,14.40,100,1,12.43,700,1,14.56,800,2,12.42,700,1,14.60,700,1,ARL,302649029
2025-07-17T15:44:38.432460509Z,2025-07-17T15:44:38.432294362Z,160,2,1108,C,A,10,13.40,0,0,13.40,23,1,13.26,100,1,13.70,15,1,13.04,2,1,13.72,15,1,13.03,100,1,13.73,100,1,12.73,100,1,14.03,100,1,12.71,100,1,14.07,2,1,12.50,700,1,14.28,100,1,12.46,200,2,14.40,100,1,12.43,700,1,14.56,800,2,12.42,700,1,14.60,700,1,ARL,302662769
2025-07-17T15:44:38.432460509Z,2025-07-17T15:44:38.432294362Z,160,2,1108,A,A,10,13.40,0,0,13.40,23,1,13.26,100,1,13.70,15,1,13.04,2,1,13.71,100,1,13.03,100,1,13.72,15,1,12.73,100,1,13.73,100,1,12.71,100,1,14.03,100,1,12.50,700,1,14.07,2,1,12.46,200,2,14.28,100,1,12.43,700,1,14.40,100,1,12.42,700,1,14.56,800,2,ARL,302763889
2025-07-17T15:44:38.439253975Z,2025-07-17T15:44:38.439088042Z,160,2,1108,C,A,10,13.40,0,0,13.40,23,1,13.26,100,1,13.70,15,1,13.04,2,1,13.71,100,1,13.03,100,1,13.72,15,1,12.73,100,1,13.73,100,1,12.71,100,1,14.03,100,1,12.50,700,1,14.07,2,1,12.46,200,2,14.28,100,1,12.43,700,1,14.40,100,1,12.42,700,1,14.56,800,2,ARL,301747301
2025-07-17T15:44:38.439253975Z,2025-07-17T15:44:38.439088042Z,160,2,1108,A,A,10,13.40,0,0,13.40,23,1,13.26,100,1,13.70,15,1,13.04,2,1,13.71,100,1,13.03,100,1,13.72,15,1,12.73,100,1,13.73,100,1,12.71,100,1,14.03,100,1,12.50,700,1,14.07,2,1,12.46,200,2,14.28,100,1,12.43,700,1,14.40,100,1,12.42,700,1,14.56,800,2,ARL,302764121
2025-07-17T15:44:38.440321697Z,2025-07-17T15:44:38.440156077Z,160,2,1108,C,A,10,13.40,0,0,13.40,23,1,13.26,100,1,13.70,15,1,13.04,2,1,13.71,100,1,13.03,100,1,13.72,15,1,12.73,100,1,13.73,100,1,12.71,100,1,14.03,100,1,12.50,700,1,14.07,2,1,12.46,200,2,14.28,100,1,12.43,700,1,14.40,100,1,12.42,700,1,14.56,800,2,ARL,301747261
2025-07-17T15:44:38.440321697Z,2025-07-17T15:44:38.440156077Z,160,2,1108,A,A,10,13.40,0,0,13.40,23,1,13.26,100,1,13.70,15,1,13.04,2,1,13.71,100,1,13.03,100,1,13.72,15,1,12.73,100,1,13.73,100,1,12.71,100,1,14.03,100,1,12.50,700,1,14.07,2,1,12.46,200,2,14.28,100,1,12.43,700,1,14.40,100,1,12.42,700,1,14.56,800,2,ARL,302764137
2025-07-17T15:44:43.019262217Z,2025-07-17T15:44:43.019083502Z,160,2,1108,C,A,10,13.40,0,0,13.40,23,1,13.26,100,1,13.71,100,1,13.04,2,1,13.72,15,1,13.03,100,1,13.73,100,1,12.73,100,1,14.03,100,1,12.71,100,1,14.07,2,1,12.50,700,1,14.28,100,1,12.46,200,2,14.40,100,1,12.43,700,1,14.56,800,2,12.42,700,1,14.60,700,1,ARL,302750929
2025-07-17T15:44:43.019352658Z,2025-07-17T15:44:43.019184132Z,160,2,1108,C,A,10,13.40,0,0,13.40,23,1,13.26,100,1,13.71,100,1,13.04,2,1,13.73,100,1,13.03,100,1,14.03,100,1,12.73,100,1,14.07,2,1,12.71,100,1,14.28,100,1,12.50,700,1,14.40,100,1,12.46,200,2,14.56,800,2,12.43,700,1,14.60,700,1,12.42,700,1,14.64,100,1,ARL,302649021
2025-07-17T15:44:44.076009999Z,2025-07-17T15:44:44.075843113Z,160,2,1108,A,A,10,13.40,0,0,13.40,23,1,13.26,100,1,13.70,15,1,13.04,2,1,13.71,100,1,13.03,100,1,13.73,100,1,12.73,100,1,14.03,100,1,12.71,100,1,14.07,2,1,12.50,700,1,14.28,100,1,12.46,200,2,14.40,100,1,12.43,700,1,14.56,800,2,12.42,700,1,14.60,700,1,ARL,302867209
2025-07-17T15:44:44.781630732Z,2025-07-17T15:44:44.781464821Z,160,2,1108,C,A,10,13.40,0,0,13.40,23,1,13.26,100,1,13.71,100,1,13.04,2,1,13.73,100,1,13.03,100,1,14.03,100,1,12.73,100,1,14.07,2,1,12.71,100,1,14.28,100,1,12.50,700,1,14.40,100,1,12.46,200,2,14.56,800,2,12.43,700,1,14.60,700,1,12.42,700,1,14.64,100,1,ARL,302867209
2025-07-17T15:44:53.143249270Z,2025-07-17T15:44:53.143083969Z,160,2,1108,C,A,10,13.40,0,0,13.40,23,1,13.26,100,1,13.71,100,1,13.04,2,1,14.03,100,1,13.03,100,1,14.07,2,1,12.73,100,1,14.28,100,1,12.71,100,1,14.40,100,1,12.50,700,1,14.56,800,2,12.46,200,2,14.60,700,1,12.43,700,1,14.64,100,1,12.42,700,1,14.66,200,2,ARL,302750937
2025-07-17T15:44:57.191188470Z,2025-07-17T15:44:57.191023026Z,160,2,1108,A,A,10,13.40,0,0,13.40,23,1,13.26,100,1,13.71,100,1,13.04,2,1,13.75,100,1,13.03,100,1,14.03,100,1,12.73,100,1,14.07,2,1,12.71,100,1,14.28,100,1,12.50,700,1,14.40,100,1,12.46,200,2,14.56,800,2,12.43,700,1,14.60,700,1,12.42,700,1,14.64,100,1,ARL,303118785
2025-07-17T15:45:07.065756574Z,2025-07-17T15:45:07.065587919Z,160,2,1108,C,A,10,13.40,0,0,13.40,23,1,13.26,100,1,13.75,100,1,13.04,2,1,14.03,100,1,13.03,100,1,14.07,2,1,12.73,100,1,14.28,100,1,12.71,100,1,14.40,100,1,12.50,700,1,14.56,800,2,12.46,200,2,14.60,700,1,12.43,700,1,14.64,100,1,12.42,700,1,14.66,200,2,ARL,302763889
2025-07-17T15:45:07.080131505Z,2025-07-17T15:45:07.079966224Z,160,2,1108,C,A,10,13.40,0,0,13.40,23,1,13.26,100,1,14.03,100,1,13.04,2,1,14.07,2,1,13.03,100,1,14.28,100,1,12.73,100,1,14.40,100,1,12.71,100,1,14.56,800,2,12.50,700,1,14.60,700,1,12.46,200,2,14.64,100,1,12.43,700,1,14.66,200,2,12.42,700,1,14.68,1400,2,ARL,303118785
2025-07-17T15:45:07.080687215Z,2025-07-17T15:45:07.080521807Z,160,2,1108,C,A,10,13.40,0,0,13.40,23,1,13.26,100,1,14.03,100,1,13.04,2,1,14.07,2,1,13.03,100,1,14.28,100,1,12.73,100,1,14.40,100,1,12.71,100,1,14.56,800,2,12.50,700,1,14.60,700,1,12.46,200,2,14.64,100,1,12.43,700,1,14.66,100,1,12.42,700,1,14.68,1400,2,ARL,302205289
2025-07-17T15:45:07.080687215Z,2025-07-17T15:45:07.080521807Z,160,2,1108,A,A,10,13.40,0,0,13.40,23,1,13.26,100,1,14.03,100,1,13.04,2,1,14.07,2,1,13.03,100,1,14.28,100,1,12.73,100,1,14.40,100,1,12.71,100,1,14.56,800,2,12.50,700,1,14.60,700,1,12.46,200,2,14.64,100,1,12.43,700,1,14.66,100,1,12.42,700,1,14.68,1400,2,ARL,303330477
2025-07-17T15:45:07.080872245Z,2025-07-17T15:45:07.080706110Z,160,2,1108,C,A,10,13.40,0,0,13.40,23,1,13.26,100,1,14.03,100,1,13.04,2,1,14.07,2,1,13.03,100,1,14.28,100,1,12.73,100,1,14.40,100,1,12.71,100,1,14.56,800,2,12.50,700,1,14.60,700,1,12.46,200,2,14.64,100,1,12.43,700,1,14.66,100,1,12.42,700,1,14.68,1400,2,ARL,302662821
2025-07-17T15:45:07.080872245Z,2025-07-17T15:45:07.080706110Z,160,2,1108,A,A,10,13.40,0,0,13.40,23,1,13.26,100,1,14.03,100,1,13.04,2,1,14.07,2,1,13.03,100,1,14.28,100,1,12.73,100,1,14.40,100,1,12.71,100,1,14.56,800,2,12.50,700,1,14.60,700,1,12.46,200,2,14.64,100,1,12.43,700,1,14.66,100,1,12.42,700,1,14.68,1400,2,ARL,303330485
2025-07-17T15:45:07.081578064Z,2025-07-17T15:45:07.081407507Z,160,2,1108,C,A,10,13.40,0,0,13.40,23,1,13.26,100,1,14.03,100,1,13.04,2,1,14.07,2,1,13.03,100,1,14.28,100,1,12.73,100,1,14.40,100,1,12.71,100,1,14.56,800,2,12.50,700,1,14.60,700,1,12.46,200,2,14.64,100,1,12.43,700,1,14.66,100,1,12.42,700,1,14.68,1400,2,ARL,301747001
2025-07-17T15:45:07.081578064Z,2025-07-17T15:45:07.081407507Z,160,2,1108,A,A,10,13.40,0,0,13.40,23,1,13.26,100,1,14.03,100,1,13.04,2,1,14.07,2,1,13.03,100,1,14.28,100,1,12.73,100,1,14.40,100,1,12.71,100,1,14.56,800,2,12.50,700,1,14.60,700,1,12.46,200,2,14.64,100,1,12.43,700,1,14.66,100,1,12.42,700,1,14.68,1400,2,ARL,303330509
2025-07-17T15:45:07.081607970Z,2025-07-17T15:45:07.081441134Z,160,2,1108,C,A,10,13.40,0,0,13.40,23,1,13.26,100,1,14.03,100,1,13.04,2,1,14.07,2,1,13.03,100,1,14.28,100,1,12.73,100,1,14.40,100,1,12.71,100,1,14.56,800,2,12.50,700,1,14.60,700,1,12.46,200,2,14.64,100,1,12.43,700,1,14.68,1400,2,12.42,700,1,14.81,100,1,ARL,302205309
2025-07-17T15:45:07.081607970Z,2025-07-17T15:45:07.081441134Z,160,2,1108,A,A,10,13.40,0,0,13.40,23,1,13.26,100,1,14.03,100,1,13.04,2,1,14.07,2,1,13.03,100,1,14.28,100,1,12.73,100,1,14.40,100,1,12.71,100,1,14.56,800,2,12.50,700,1,14.60,700,1,12.46,200,2,14.64,100,1,12.43,700,1,14.68,1400,2,12.42,700,1,14.81,100,1,ARL,303330521
2025-07-17T15:45:07.083898999Z,2025-07-17T15:45:07.083732443Z,160,2,1108,C,A,10,13.40,0,0,13.40,23,1,13.26,100,1,14.03,100,1,13.04,2,1,14.07,2,1,13.03,100,1,14.28,100,1,12.73,100,1,14.40,100,1,12.71,100,1,14.56,800,2,12.50,700,1,14.60,700,1,12.46,200,2,14.64,100,1,12.43,700,1,14.68,1400,2,12.42,700,1,14.81,100,1,ARL,302764137
2025-07-17T15:45:07.083898999Z,2025-07-17T15:45:07.083732443Z,160,2,1108,A,A,10,13.40,0,0,13.40,23,1,13.26,100,1,14.03,100,1,13.04,2,1,14.07,2,1,13.03,100,1,14.28,100,1,12.73,100,1,14.40,100,1,12.71,100,1,14.56,800,2,12.50,700,1,14.60,700,1,12.46,200,2,14.64,100,1,12.43,700,1,14.68,1400,2,12.42,700,1,14.81,100,1,ARL,303331309
2025-07-17T15:45:07.085222525Z,2025-07-17T15:45:07.085057258Z,160,2,1108,C,A,10,13.40,0,0,13.40,23,1,13.26,100,1,14.07,2,1,13.04,2,1,14.28,100,1,13.03,100,1,14.40,100,1,12.73,100,1,14.56,800,2,12.71,100,1,14.60,700,1,12.50,700,1,14.64,100,1,12.46,200,2,14.68,1400,2,12.43,700,1,14.81,100,1,12.42,700,1,14.89,200,2,ARL,302466157
2025-07-17T15:45:07.085274852Z,2025-07-17T15:45:07.085109545Z,160,2,1108,A,A,10,13.40,0,0,13.40,23,1,13.26,100,1,14.07,2,1,13.04,2,1,14.26,100,1,13.03,100,1,14.28,100,1,12.73,100,1,14.40,100,1,12.71,100,1,14.56,800,2,12.50,700,1,14.60,700,1,12.46,200,2,14.64,100,1,12.43,700,1,14.68,1400,2,12.42,700,1,14.81,100,1,ARL,303331401
2025-07-17T15:45:07.086534700Z,2025-07-17T15:45:07.086368957Z,160,2,1108,C,A,10,13.40,0,0,13.40,23,1,13.26,100,1,14.07,2,1,13.04,2,1,14.26,100,1,13.03,100,1,14.28,100,1,12.73,100,1,14.40,100,1,12.71,100,1,14.56,800,2,12.50,700,1,14.60,700,1,12.46,200,2,14.68,1400,2,12.43,700,1,14.81,100,1,12.42,700,1,14.89,200,2,ARL,301747005
2025-07-17T15:45:07.086660325Z,2025-07-17T15:45:07.086494745Z,160,2,1108,A,A,10,13.40,0,0,13.40,23,1,13.26,100,1,14.07,2,1,13.04,2,1,14.26,100,1,13.03,100,1,14.28,100,1,12.73,100,1,14.40,100,1,12.71,100,1,14.56,800,2,12.50,700,1,14.60,700,1,12.46,200,2,14.68,1400,2,12.43,700,1,14.78,100,1,12.42,700,1,14.81,100,1,ARL,303331425
2025-07-17T15:45:07.087389466Z,2025-07-17T15:45:07.087223859Z,160,2,1108,C,A,10,13.40,0,0,13.40,23,1,13.26,100,1,14.07,2,1,13.04,2,1,14.26,100,1,13.03,100,1,14.28,100,1,12.73,100,1,14.40,100,1,12.71,100,1,14.56,800,2,12.50,700,1,14.60,700,1,12.46,200,2,14.68,1400,2,12.43,700,1,14.78,100,1,12.42,700,1,14.81,100,1,ARL,302764121
2025-07-17T15:45:07.087389466Z,2025-07-17T15:45:07.087223859Z,160,2,1108,A,A,10,13.40,0,0,13.40,23,1,13.26,100,1,14.07,2,1,13.04,2,1,14.26,100,1,13.03,100,1,14.28,100,1,12.73,100,1,14.40,100,1,12.71,100,1,14.56,800,2,12.50,700,1,14.60,700,1,12.46,200,2,14.68,1400,2,12.43,700,1,14.78,100,1,12.42,700,1,14.81,100,1,ARL,303331429
2025-07-17T15:45:07.133978488Z,2025-07-17T15:45:07.133812895Z,160,2,1108,C,A,10,13.40,0,0,13.40,23,1,13.26,100,1,14.07,2,1,13.04,2,1,14.26,100,1,13.03,100,1,14.28,100,1,12.73,100,1,14.40,100,1,12.71,100,1,14.56,800,2,12.50,700,1,14.60,700,1,12.46,200,2,14.68,1400,2,12.43,700,1,14.78,100,1,12.42,700,1,14.89,200,2,ARL,301747957
2025-07-17T15:45:07.133978488Z,2025-07-17T15:45:07.133812895Z,160,2,1108,A,A,10,13.40,0,0,13.40,23,1,13.26,100,1,14.07,2,1,13.04,2,1,14.26,100,1,13.03,100,1,14.28,100,1,12.73,100,1,14.40,100,1,12.71,100,1,14.56,800,2,12.50,700,1,14.60,700,1,12.46,200,2,14.68,1400,2,12.43,700,1,14.78,100,1,12.42,700,1,14.89,200,2,ARL,303334253
2025-07-17T15:45:07.469961302Z,2025-07-17T15:45:07.469796155Z,160,2,1108,A,A,10,13.40,0,0,13.40,23,1,13.26,100,1,14.07,2,1,13.04,2,1,14.08,100,1,13.03,100,1,14.26,100,1,12.73,100,1,14.28,100,1,12.71,100,1,14.40,100,1,12.50,700,1,14.56,800,2,12.46,200,2,14.60,700,1,12.43,700,1,14.68,1400,2,12.42,700,1,14.78,100,1,ARL,303340405
2025-07-17T15:45:08.094768552Z,2025-07-17T15:45:08.094603115Z,160,2,1108,C,A,10,13.40,0,0,13.40,23,1,13.26,100,1,14.07,2,1,13.04,2,1,14.08,100,1,13.03,100,1,14.26,100,1,12.73,100,1,14.28,100,1,12.71,100,1,14.40,100,1,12.50,700,1,14.56,800,2,12.46,200,2,14.60,700,1,12.43,700,1,14.68,1400,2,12.42,700,1,14.78,100,1,ARL,303330521
2025-07-17T15:45:08.094768552Z,2025-07-17T15:45:08.094603115Z,160,2,1108,A,A,10,13.40,0,0,13.40,23,1,13.26,100,1,14.07,2,1,13.04,2,1,14.08,100,1,13.03,100,1,14.26,100,1,12.73,100,1,14.28,100,1,12.71,100,1,14.40,100,1,12.50,700,1,14.56,800,2,12.46,200,2,14.60,700,1,12.43,700,1,14.68,1400,2,12.42,700,1,14.78,100,1,ARL,303349309
2025-07-17T15:45:08.103306644Z,2025-07-17T15:45:08.103141155Z,160,2,1108,C,A,10,13.40,0,0,13.40,23,1,13.26,100,1,14.07,2,1,13.04,2,1,14.08,100,1,13.03,100,1,14.26,100,1,12.73,100,1,14.28,100,1,12.71,100,1,14.40,100,1,12.50,700,1,14.56,800,2,12.46,200,2,14.60,700,1,12.43,700,1,14.68,1400,2,12.42,700,1,14.78,100,1,ARL,303330477
2025-07-17T15:45:08.103306644Z,2025-07-17T15:45:08.103141155Z,160,2,1108,A,A,10,13.40,0,0,13.40,23,1,13.26,100,1,14.07,2,1,13.04,2,1,14.08,100,1,13.03,100,1,14.26,100,1,12.73,100,1,14.28,100,1,12.71,100,1,14.40,100,1,12.50,700,1,14.56,800,2,12.46,200,2,14.60,700,1,12.43,700,1,14.68,1400,2,12.42,700,1,14.78,100,1,ARL,303349377
2025-07-17T15:45:24.187008278Z,2025-07-17T15:45:24.186842413Z,160,2,1108,C,A,10,13.40,0,0,13.40,23,1,13.26,100,1,14.07,2,1,13.04,2,1,14.08,100,1,13.03,100,1,14.26,100,1,12.73,100,1,14.28,100,1,12.71,100,1,14.40,100,1,12.50,700,1,14.56,800,2,12.46,200,2,14.60,700,1,12.43,700,1,14.68,1400,2,12.42,700,1,14.78,100,1,ARL,303349309
2025-07-17T15:45:24.187008278Z,2025-07-17T15:45:24.186842413Z,160,2,1108,A,A,10,13.40,0,0,13.40,23,1,13.26,100,1,14.07,2,1,13.04,2,1,14.08,100,1,13.03,100,1,14.26,100,1,12.73,100,1,14.28,100,1,12.71,100,1,14.40,100,1,12.50,700,1,14.56,800,2,12.46,200,2,14.60,700,1,12.43,700,1,14.68,1400,2,12.42,700,1,14.78,100,1,ARL,303682385
2025-07-17T15:45:24.187441892Z,2025-07-17T15:45:24.187276389Z,160,2,1108,C,A,10,13.40,0,0,13.40,23,1,13.26,100,1,14.07,2,1,13.04,2,1,14.08,100,1,13.03,100,1,14.26,100,1,12.73,100,1,14.28,100,1,12.71,100,1,14.40,100,1,12.50,700,1,14.56,800,2,12.46,200,2,14.60,700,1,12.43,700,1,14.68,1400,2,12.42,700,1,14.78,100,1,ARL,303349377
2025-07-17T15:45:24.187441892Z,2025-07-17T15:45:24.187276389Z,160,2,1108,A,A,10,13.40,0,0,13.40,23,1,13.26,100,1,14.07,2,1,13.04,2,1,14.08,100,1,13.03,100,1,14.26,100,1,12.73,100,1,14.28,100,1,12.71,100,1,14.40,100,1,12.50,700,1,14.56,800,2,12.46,200,2,14.60,700,1,12.43,700,1,14.68,1400,2,12.42,700,1,14.78,100,1,ARL,303682389
2025-07-17T15:45:37.509454888Z,2025-07-17T15:45:37.509289536Z,160,2,1108,A,A,10,13.40,0,0,13.40,23,1,13.26,100,1,13.94,15,1,13.04,2,1,14.07,2,1,13.03,100,1,14.08,100,1,12.73,100,1,14.26,100,1,12.71,100,1,14.28,100,1,12.50,700,1,14.40,100,1,12.46,200,2,14.56,800,2,12.43,700,1,14.60,700,1,12.42,700,1,14.68,1400,2,ARL,304056997
2025-07-17T15:45:37.998133497Z,2025-07-17T15:45:37.997967775Z,160,2,1108,C,A,10,13.40,0,0,13.40,23,1,13.26,100,1,13.94,15,1,13.04,2,1,14.07,2,1,13.03,100,1,14.26,100,1,12.73,100,1,14.28,100,1,12.71,100,1,14.40,100,1,12.50,700,1,14.56,800,2,12.46,200,2,14.60,700,1,12.43,700,1,14.68,1400,2,12.42,700,1,14.78,100,1,ARL,303340405
2025-07-17T15:45:37.998133497Z,2025-07-17T15:45:37.997967775Z,160,2,1108,A,A,10,13.40,0,0,13.40,23,1,13.26,100,1,13.94,15,1,13.04,2,1,13.95,100,1,13.03,100,1,14.07,2,1,12.73,100,1,14.26,100,1,12.71,100,1,14.28,100,1,12.50,700,1,14.40,100,1,12.46,200,2,14.56,800,2,12.43,700,1,14.60,700,1,12.42,700,1,14.68,1400,2,ARL,304072245
2025-07-17T15:45:44.700593408Z,2025-07-17T15:45:44.700428155Z,160,2,1108,A,A,10,13.40,0,0,13.40,23,1,13.26,100,1,13.89,15,1,13.04,2,1,13.94,15,1,13.03,100,1,13.95,100,1,12.73,100,1,14.07,2,1,12.71,100,1,14.26,100,1,12.50,700,1,14.28,100,1,12.46,200,2,14.40,100,1,12.43,700,1,14.56,800,2,12.42,700,1,14.60,700,1,ARL,304238913
2025-07-17T15:45:45.262537122Z,2025-07-17T15:45:45.262371701Z,160,2,1108,C,A,10,13.40,0,0,13.40,23,1,13.26,100,1,13.89,15,1,13.04,2,1,13.94,15,1,13.03,100,1,14.07,2,1,12.73,100,1,14.26,100,1,12.71,100,1,14.28,100,1,12.50,700,1,14.40,100,1,12.46,200,2,14.56,800,2,12.43,700,1,14.60,700,1,12.42,700,1,14.68,1400,2,ARL,304072245
2025-07-17T15:45:45.262537122Z,2025-07-17T15:45:45.262371701Z,160,2,1108,A,A,10,13.40,0,0,13.40,23,1,13.26,100,1,13.89,15,1,13.04,2,1,13.90,100,1,13.03,100,1,13.94,15,1,12.73,100,1,14.07,2,1,12.71,100,1,14.26,100,1,12.50,700,1,14.28,100,1,12.46,200,2,14.40,100,1,12.43,700,1,14.56,800,2,12.42,700,1,14.60,700,1,ARL,304252313
2025-07-17T15:45:45.263289023Z,2025-07-17T15:45:45.263123432Z,160,2,1108,C,A,10,13.40,0,0,13.40,23,1,13.26,100,1,13.89,15,1,13.04,2,1,13.90,100,1,13.03,100,1,13.94,15,1,12.73,100,1,14.07,2,1,12.71,100,1,14.26,100,1,12.50,700,1,14.28,100,1,12.46,200,2,14.40,100,1,12.43,700,1,14.56,800,2,12.42,700,1,14.60,700,1,ARL,303330485
2025-07-17T15:45:45.263289023Z,2025-07-17T15:45:45.263123432Z,160,2,1108,A,A,10,13.40,0,0,13.40,23,1,13.26,100,1,13.89,15,1,13.04,2,1,13.90,100,1,13.03,100,1,13.94,15,1,12.73,100,1,14.07,2,1,12.71,100,1,14.26,100,1,12.50,700,1,14.28,100,1,12.46,200,2,14.40,100,1,12.43,700,1,14.56,800,2,12.42,700,1,14.60,700,1,ARL,304252333
2025-07-17T15:45:45.274360382Z,2025-07-17T15:45:45.274194870Z,160,2,1108,C,A,10,13.40,0,0,13.40,23,1,13.26,100,1,13.89,15,1,13.04,2,1,13.90,100,1,13.03,100,1,13.94,15,1,12.73,100,1,14.07,2,1,12.71,100,1,14.28,100,1,12.50,700,1,14.40,100,1,12.46,200,2,14.56,800,2,12.43,700,1,14.60,700,1,12.42,700,1,14.68,1400,2,ARL,303331401
2025-07-17T15:45:45.274410721Z,2025-07-17T15:45:45.274245387Z,160,2,1108,A,A,10,13.40,0,0,13.40,23,1,13.26,100,1,13.89,15,1,13.04,2,1,13.90,100,1,13.03,100,1,13.94,15,1,12.73,100,1,14.07,2,1,12.71,100,1,14.18,100,1,12.50,700,1,14.28,100,1,12.46,200,2,14.40,100,1,12.43,700,1,14.56,800,2,12.42,700,1,14.60,700,1,ARL,304252469
2025-07-17T15:45:58.419783333Z,2025-07-17T15:45:58.419617935Z,160,2,1108,C,A,10,13.40,0,0,13.40,23,1,13.26,100,1,13.89,15,1,13.04,2,1,13.90,100,1,13.03,100,1,14.07,2,1,12.73,100,1,14.18,100,1,12.71,100,1,14.28,100,1,12.50,700,1,14.40,100,1,12.46,200,2,14.56,800,2,12.43,700,1,14.60,700,1,12.42,700,1,14.68,1400,2,ARL,304056997
2025-07-17T15:45:58.420278691Z,2025-07-17T15:45:58.420113307Z,160,2,1108,C,A,10,13.40,0,0,13.40,23,1,13.26,100,1,13.89,15,1,13.04,2,1,13.90,100,1,13.03,100,1,14.07,2,1,12.73,100,1,14.18,100,1,12.71,100,1,14.28,100,1,12.50,700,1,14.40,100,1,12.46,200,2,14.56,800,2,12.43,700,1,14.60,700,1,12.42,700,1,14.68,1400,2,ARL,303682389
2025-07-17T15:45:58.420278691Z,2025-07-17T15:45:58.420113307Z,160,2,1108,A,A,10,13.40,0,0,13.40,23,1,13.26,100,1,13.89,15,1,13.04,2,1,13.90,100,1,13.03,100,1,14.07,2,1,12.73,100,1,14.18,100,1,12.71,100,1,14.28,100,1,12.50,700,1,14.40,100,1,12.46,200,2,14.56,800,2,12.43,700,1,14.60,700,1,12.42,700,1,14.68,1400,2,ARL,304503585
2025-07-17T15:45:58.420755889Z,2025-07-17T15:45:58.420590199Z,160,2,1108,C,A,10,13.40,0,0,13.40,23,1,13.26,100,1,13.89,15,1,13.04,2,1,13.90,100,1,13.03,100,1,14.07,2,1,12.73,100,1,14.18,100,1,12.71,100,1,14.28,100,1,12.50,700,1,14.40,100,1,12.46,200,2,14.56,800,2,12.43,700,1,14.60,700,1,12.42,700,1,14.68,1400,2,ARL,303682385
2025-07-17T15:45:58.420755889Z,2025-07-17T15:45:58.420590199Z,160,2,1108,A,A,10,13.40,0,0,13.40,23,1,13.26,100,1,13.89,15,1,13.04,2,1,13.90,100,1,13.03,100,1,14.07,2,1,12.73,100,1,14.18,100,1,12.71,100,1,14.28,100,1,12.50,700,1,14.40,100,1,12.46,200,2,14.56,800,2,12.43,700,1,14.60,700,1,12.42,700,1,14.68,1400,2,ARL,304503593
2025-07-17T15:45:58.782892109Z,2025-07-17T15:45:58.782726994Z,160,2,1108,C,A,10,13.40,0,0,13.40,23,1,13.26,100,1,13.90,100,1,13.04,2,1,14.07,2,1,13.03,100,1,14.18,100,1,12.73,100,1,14.28,100,1,12.71,100,1,14.40,100,1,12.50,700,1,14.56,800,2,12.46,200,2,14.60,700,1,12.43,700,1,14.68,1400,2,12.42,700,1,14.77,200,2,ARL,304238913
2025-07-17T15:46:16.783057616Z,2025-07-17T15:46:16.782892334Z,160,2,1108,A,A,10,13.40,0,0,13.40,23,1,13.26,100,1,13.88,15,1,13.04,2,1,13.90,100,1,13.03,100,1,14.07,2,1,12.73,100,1,14.18,100,1,12.71,100,1,14.28,100,1,12.50,700,1,14.40,100,1,12.46,200,2,14.56,800,2,12.43,700,1,14.60,700,1,12.42,700,1,14.68,1400,2,ARL,304949689
2025-07-17T15:46:16.783326241Z,2025-07-17T15:46:16.783160795Z,160,2,1108,C,A,10,13.40,0,0,13.40,23,1,13.26,100,1,13.88,15,1,13.04,2,1,14.07,2,1,13.03,100,1,14.18,100,1,12.73,100,1,14.28,100,1,12.71,100,1,14.40,100,1,12.50,700,1,14.56,800,2,12.46,200,2,14.60,700,1,12.43,700,1,14.68,1400,2,12.42,700,1,14.77,200,2,ARL,304252313
2025-07-17T15:46:16.783326241Z,2025-07-17T15:46:16.783160795Z,160,2,1108,A,A,10,13.40,0,0,13.40,23,1,13.26,100,1,13.88,15,1,13.04,2,1,13.89,100,1,13.03,100,1,14.07,2,1,12.73,100,1,14.18,100,1,12.71,100,1,14.28,100,1,12.50,700,1,14.40,100,1,12.46,200,2,14.56,800,2,12.43,700,1,14.60,700,1,12.42,700,1,14.68,1400,2,ARL,304949697
2025-07-17T15:46:18.782897570Z,2025-07-17T15:46:18.782732218Z,160,2,1108,C,A,10,13.40,0,0,13.40,23,1,13.26,100,1,13.89,100,1,13.04,2,1,14.07,2,1,13.03,100,1,14.18,100,1,12.73,100,1,14.28,100,1,12.71,100,1,14.40,100,1,12.50,700,1,14.56,800,2,12.46,200,2,14.60,700,1,12.43,700,1,14.68,1400,2,12.42,700,1,14.77,200,2,ARL,304949689
2025-07-17T15:46:28.474166897Z,2025-07-17T15:46:28.474001551Z,160,2,1108,C,A,10,13.40,0,0,13.40,23,1,13.26,100,1,14.07,2,1,13.04,2,1,14.18,100,1,13.03,100,1,14.28,100,1,12.73,100,1,14.40,100,1,12.71,100,1,14.56,800,2,12.50,700,1,14.60,700,1,12.46,200,2,14.68,1400,2,12.43,700,1,14.77,200,2,12.42,700,1,14.78,100,1,ARL,304949697
2025-07-17T15:46:28.474726594Z,2025-07-17T15:46:28.474561156Z,160,2,1108,C,A,10,13.40,0,0,13.40,23,1,13.26,100,1,14.07,2,1,13.04,2,1,14.18,100,1,13.03,100,1,14.28,100,1,12.73,100,1,14.40,100,1,12.71,100,1,14.56,800,2,12.50,700,1,14.60,700,1,12.46,200,2,14.68,1400,2,12.43,700,1,14.77,100,1,12.42,700,1,14.78,100,1,ARL,304503593
2025-07-17T15:46:28.474726594Z,2025-07-17T15:46:28.474561156Z,160,2,1108,A,A,10,13.40,0,0,13.40,23,1,13.26,100,1,14.07,2,1,13.04,2,1,14.18,100,1,13.03,100,1,14.28,100,1,12.73,100,1,14.40,100,1,12.71,100,1,14.56,800,2,12.50,700,1,14.60,700,1,12.46,200,2,14.68,1400,2,12.43,700,1,14.77,100,1,12.42,700,1,14.78,100,1,ARL,305184937
2025-07-17T15:46:28.474896460Z,2025-07-17T15:46:28.474730225Z,160,2,1108,C,A,10,13.40,0,0,13.40,23,1,13.26,100,1,14.07,2,1,13.04,2,1,14.18,100,1,13.03,100,1,14.28,100,1,12.73,100,1,14.40,100,1,12.71,100,1,14.56,800,2,12.50,700,1,14.60,700,1,12.46,200,2,14.68,1400,2,12.43,700,1,14.78,100,1,12.42,700,1,14.88,100,1,ARL,304503585
2025-07-17T15:46:28.474896460Z,2025-07-17T15:46:28.474730225Z,160,2,1108,A,A,10,13.40,0,0,13.40,23,1,13.26,100,1,14.07,2,1,13.04,2,1,14.18,100,1,13.03,100,1,14.28,100,1,12.73,100,1,14.40,100,1,12.71,100,1,14.56,800,2,12.50,700,1,14.60,700,1,12.46,200,2,14.68,1400,2,12.43,700,1,14.78,100,1,12.42,700,1,14.88,200,2,ARL,305184953
2025-07-17T15:46:28.474902154Z,2025-07-17T15:46:28.474736101Z,160,2,1108,C,A,10,13.40,0,0,13.40,23,1,13.26,100,1,14.07,2,1,13.04,2,1,14.18,100,1,13.03,100,1,14.28,100,1,12.73,100,1,14.40,100,1,12.71,100,1,14.56,800,2,12.50,700,1,14.60,700,1,12.46,200,2,14.68,1400,2,12.43,700,1,14.78,100,1,12.42,700,1,14.88,200,2,ARL,304252333
2025-07-17T15:46:28.474902154Z,2025-07-17T15:46:28.474736101Z,160,2,1108,A,A,10,13.40,0,0,13.40,23,1,13.26,100,1,14.07,2,1,13.04,2,1,14.18,100,1,13.03,100,1,14.28,100,1,12.73,100,1,14.40,100,1,12.71,100,1,14.56,800,2,12.50,700,1,14.60,700,1,12.46,200,2,14.68,1400,2,12.43,700,1,14.78,100,1,12.42,700,1,14.88,200,2,ARL,305184957
2025-07-17T15:46:28.492881980Z,2025-07-17T15:46:28.492716775Z,160,2,1108,C,A,10,13.40,0,0,13.40,23,1,13.26,100,1,14.07,2,1,13.04,2,1,14.28,100,1,13.03,100,1,14.40,100,1,12.73,100,1,14.56,800,2,12.71,100,1,14.60,700,1,12.50,700,1,14.68,1400,2,12.46,200,2,14.78,100,1,12.43,700,1,14.88,200,2,12.42,700,1,14.96,200,2,ARL,304252469
2025-07-17T15:46:28.492931279Z,2025-07-17T15:46:28.492765859Z,160,2,1108,A,A,10,13.40,0,0,13.40,23,1,13.26,100,1,14.07,2,1,13.04,2,1,14.26,100,1,13.03,100,1,14.28,100,1,12.73,100,1,14.40,100,1,12.71,100,1,14.56,800,2,12.50,700,1,14.60,700,1,12.46,200,2,14.68,1400,2,12.43,700,1,14.78,100,1,12.42,700,1,14.88,200,2,ARL,305185529
2025-07-17T15:46:28.646273467Z,2025-07-17T15:46:28.646108242Z,160,2,1108,A,A,10,13.40,0,0,13.40,23,1,13.26,100,1,14.07,2,1,13.04,2,1,14.08,100,1,13.03,100,1,14.26,100,1,12.73,100,1,14.28,100,1,12.71,100,1,14.40,100,1,12.50,700,1,14.56,800,2,12.46,200,2,14.60,700,1,12.43,700,1,14.68,1400,2,12.42,700,1,14.78,100,1,ARL,305187077
2025-07-17T15:46:57.524024658Z,2025-07-17T15:46:57.523859388Z,160,2,1108,A,A,10,13.40,0,0,13.40,23,1,13.26,100,1,13.92,15,1,13.04,2,1,14.07,2,1,13.03,100,1,14.08,100,1,12.73,100,1,14.26,100,1,12.71,100,1,14.28,100,1,12.50,700,1,14.40,100,1,12.46,200,2,14.56,800,2,12.43,700,1,14.60,700,1,12.42,700,1,14.68,1400,2,ARL,305862145
2025-07-17T15:46:57.932842994Z,2025-07-17T15:46:57.932677299Z,160,2,1108,C,A,10,13.40,0,0,13.40,23,1,13.26,100,1,13.92,15,1,13.04,2,1,14.07,2,1,13.03,100,1,14.26,100,1,12.73,100,1,14.28,100,1,12.71,100,1,14.40,100,1,12.50,700,1,14.56,800,2,12.46,200,2,14.60,700,1,12.43,700,1,14.68,1400,2,12.42,700,1,14.78,100,1,ARL,305187077
2025-07-17T15:46:57.932842994Z,2025-07-17T15:46:57.932677299Z,160,2,1108,A,A,10,13.40,0,0,13.40,23,1,13.26,100,1,13.92,15,1,13.04,2,1,13.93,100,1,13.03,100,1,14.07,2,1,12.73,100,1,14.26,100,1,12.71,100,1,14.28,100,1,12.50,700,1,14.40,100,1,12.46,200,2,14.56,800,2,12.43,700,1,14.60,700,1,12.42,700,1,14.68,1400,2,ARL,305878881
2025-07-17T15:47:06.609456251Z,2025-07-17T15:47:06.609290857Z,160,2,1108,A,A,10,13.40,0,0,13.40,23,1,13.26,100,1,13.88,15,1,13.04,2,1,13.92,15,1,13.03,100,1,13.93,100,1,12.73,100,1,14.07,2,1,12.71,100,1,14.26,100,1,12.50,700,1,14.28,100,1,12.46,200,2,14.40,100,1,12.43,700,1,14.56,800,2,12.42,700,1,14.60,700,1,ARL,306121113
2025-07-17T15:47:08.787695144Z,2025-07-17T15:47:08.787529505Z,160,2,1108,C,A,10,13.40,0,0,13.40,23,1,13.26,100,1,13.88,15,1,13.04,2,1,13.92,15,1,13.03,100,1,14.07,2,1,12.73,100,1,14.26,100,1,12.71,100,1,14.28,100,1,12.50,700,1,14.40,100,1,12.46,200,2,14.56,800,2,12.43,700,1,14.60,700,1,12.42,700,1,14.68,1400,2,ARL,305878881
2025-07-17T15:47:08.787695144Z,2025-07-17T15:47:08.787529505Z,160,2,1108,A,A,10,13.40,0,0,13.40,23,1,13.26,100,1,13.88,15,1,13.04,2,1,13.89,100,1,13.03,100,1,13.92,15,1,12.73,100,1,14.07,2,1,12.71,100,1,14.26,100,1,12.50,700,1,14.28,100,1,12.46,200,2,14.40,100,1,12.43,700,1,14.56,800,2,12.42,700,1,14.60,700,1,ARL,306170837
2025-07-17T15:47:08.788440762Z,2025-07-17T15:47:08.788275184Z,160,2,1108,C,A,10,13.40,0,0,13.40,23,1,13.26,100,1,13.88,15,1,13.04,2,1,13.89,100,1,13.03,100,1,13.92,15,1,12.73,100,1,14.07,2,1,12.71,100,1,14.26,100,1,12.50,700,1,14.28,100,1,12.46,200,2,14.40,100,1,12.43,700,1,14.56,800,2,12.42,700,1,14.60,700,1,ARL,305184957
2025-07-17T15:47:08.788440762Z,2025-07-17T15:47:08.788275184Z,160,2,1108,A,A,10,13.40,0,0,13.40,23,1,13.26,100,1,13.88,15,1,13.04,2,1,13.89,100,1,13.03,100,1,13.92,15,1,12.73,100,1,14.07,2,1,12.71,100,1,14.26,100,1,12.50,700,1,14.28,100,1,12.46,200,2,14.40,100,1,12.43,700,1,14.56,800,2,12.42,700,1,14.60,700,1,ARL,306170869
2025-07-17T15:47:08.805983406Z,2025-07-17T15:47:08.805818249Z,160,2,1108,C,A,10,13.40,0,0,13.40,23,1,13.26,100,1,13.88,15,1,13.04,2,1,13.89,100,1,13.03,100,1,13.92,15,1,12.73,100,1,14.07,2,1,12.71,100,1,14.28,100,1,12.50,700,1,14.40,100,1,12.46,200,2,14.56,800,2,12.43,700,1,14.60,700,1,12.42,700,1,14.68,1400,2,ARL,305185529
2025-07-17T15:47:08.806033773Z,2025-07-17T15:47:08.805868059Z,160,2,1108,A,A,10,13.40,0,0,13.40,23,1,13.26,100,1,13.88,15,1,13.04,2,1,13.89,100,1,13.03,100,1,13.92,15,1,12.73,100,1,14.07,2,1,12.71,100,1,14.17,100,1,12.50,700,1,14.28,100,1,12.46,200,2,14.40,100,1,12.43,700,1,14.56,800,2,12.42,700,1,14.60,700,1,ARL,306171457
2025-07-17T15:47:13.121454355Z,2025-07-17T15:47:13.121288953Z,160,2,1108,C,A,10,13.40,0,0,13.40,23,1,13.26,100,1,13.89,100,1,13.04,2,1,13.92,15,1,13.03,100,1,14.07,2,1,12.73,100,1,14.17,100,1,12.71,100,1,14.28,100,1,12.50,700,1,14.40,100,1,12.46,200,2,14.56,800,2,12.43,700,1,14.60,700,1,12.42,700,1,14.68,1400,2,ARL,306121113
2025-07-17T15:47:13.122562533Z,2025-07-17T15:47:13.122396816Z,160,2,1108,C,A,10,13.40,0,0,13.40,23,1,13.26,100,1,13.89,100,1,13.04,2,1,14.07,2,1,13.03,100,1,14.17,100,1,12.73,100,1,14.28,100,1,12.71,100,1,14.40,100,1,12.50,700,1,14.56,800,2,12.46,200,2,14.60,700,1,12.43,700,1,14.68,1400,2,12.42,700,1,14.78,100,1,ARL,305862145
2025-07-17T15:47:24.786476266Z,2025-07-17T15:47:24.786310694Z,160,2,1108,A,A,10,13.40,0,0,13.40,23,1,13.26,100,1,13.87,15,1,13.04,2,1,13.89,100,1,13.03,100,1,14.07,2,1,12.73,100,1,14.17,100,1,12.71,100,1,14.28,100,1,12.50,700,1,14.40,100,1,12.46,200,2,14.56,800,2,12.43,700,1,14.60,700,1,12.42,700,1,14.68,1400,2,ARL,306519385
2025-07-17T15:47:24.786745657Z,2025-07-17T15:47:24.786580061Z,160,2,1108,C,A,10,13.40,0,0,13.40,23,1,13.26,100,1,13.87,15,1,13.04,2,1,14.07,2,1,13.03,100,1,14.17,100,1,12.73,100,1,14.28,100,1,12.71,100,1,14.40,100,1,12.50,700,1,14.56,800,2,12.46,200,2,14.60,700,1,12.43,700,1,14.68,1400,2,12.42,700,1,14.78,100,1,ARL,306170837
2025-07-17T15:47:24.786745657Z,2025-07-17T15:47:24.786580061Z,160,2,1108,A,A,10,13.40,0,0,13.40,23,1,13.26,100,1,13.87,15,1,13.04,2,1,13.88,100,1,13.03,100,1,14.07,2,1,12.73,100,1,14.17,100,1,12.71,100,1,14.28,100,1,12.50,700,1,14.40,100,1,12.46,200,2,14.56,800,2,12.43,700,1,14.60,700,1,12.42,700,1,14.68,1400,2,ARL,306519397
2025-07-17T15:47:24.786925729Z,2025-07-17T15:47:24.786759805Z,160,2,1108,C,A,10,13.40,0,0,13.40,23,1,13.26,100,1,13.87,15,1,13.04,2,1,13.88,100,1,13.03,100,1,14.07,2,1,12.73,100,1,14.17,100,1,12.71,100,1,14.28,100,1,12.50,700,1,14.40,100,1,12.46,200,2,14.56,800,2,12.43,700,1,14.60,700,1,12.42,700,1,14.68,1400,2,ARL,305184937
2025-07-17T15:47:24.786925729Z,2025-07-17T15:47:24.786759805Z,160,2,1108,A,A,10,13.40,0,0,13.40,23,1,13.26,100,1,13.87,15,1,13.04,2,1,13.88,100,1,13.03,100,1,14.07,2,1,12.73,100,1,14.17,100,1,12.71,100,1,14.28,100,1,12.50,700,1,14.40,100,1,12.46,200,2,14.56,800,2,12.43,700,1,14.60,700,1,12.42,700,1,14.68,1400,2,ARL,306519409
2025-07-17T15:47:24.800616004Z,2025-07-17T15:47:24.800449950Z,160,2,1108,C,A,10,13.40,0,0,13.40,23,1,13.26,100,1,13.87,15,1,13.04,2,1,13.88,100,1,13.03,100,1,14.07,2,1,12.73,100,1,14.17,100,1,12.71,100,1,14.28,100,1,12.50,700,1,14.40,100,1,12.46,200,2,14.56,800,2,12.43,700,1,14.60,700,1,12.42,700,1,14.68,1400,2,ARL,305184953
2025-07-17T15:47:24.800616004Z,2025-07-17T15:47:24.800449950Z,160,2,1108,A,A,10,13.40,0,0,13.40,23,1,13.26,100,1,13.87,15,1,13.04,2,1,13.88,100,1,13.03,100,1,14.07,2,1,12.73,100,1,14.17,100,1,12.71,100,1,14.28,100,1,12.50,700,1,14.40,100,1,12.46,200,2,14.56,800,2,12.43,700,1,14.60,700,1,12.42,700,1,14.68,1400,2,ARL,306519741
2025-07-17T15:47:27.860272892Z,2025-07-17T15:47:27.860107552Z,160,2,1108,A,A,10,13.40,0,0,13.40,23,1,13.26,100,1,13.83,15,1,13.04,2,1,13.87,15,1,13.03,100,1,13.88,100,1,12.73,100,1,14.07,2,1,12.71,100,1,14.17,100,1,12.50,700,1,14.28,100,1,12.46,200,2,14.40,100,1,12.43,700,1,14.56,800,2,12.42,700,1,14.60,700,1,ARL,306587393
2025-07-17T15:47:31.407029312Z,2025-07-17T15:47:31.406863918Z,160,2,1108,C,A,10,13.40,0,0,13.40,23,1,13.26,100,1,13.83,15,1,13.04,2,1,13.87,15,1,13.03,100,1,14.07,2,1,12.73,100,1,14.17,100,1,12.71,100,1,14.28,100,1,12.50,700,1,14.40,100,1,12.46,200,2,14.56,800,2,12.43,700,1,14.60,700,1,12.42,700,1,14.68,1400,2,ARL,306519397
2025-07-17T15:47:31.407029312Z,2025-07-17T15:47:31.406863918Z,160,2,1108,A,A,10,13.40,0,0,13.40,23,1,13.26,100,1,13.83,15,1,13.04,2,1,13.84,100,1,13.03,100,1,13.87,15,1,12.73,100,1,14.07,2,1,12.71,100,1,14.17,100,1,12.50,700,1,14.28,100,1,12.46,200,2,14.40,100,1,12.43,700,1,14.56,800,2,12.42,700,1,14.60,700,1,ARL,306647425
