ts_recv,ts_event,rtype,publisher_id,instrument_id,action,side,depth,price,size,flags,ts_in_delta,sequence,bid_px_00,bid_sz_00,bid_ct_00,ask_px_00,ask_sz_00,ask_ct_00,bid_px_01,bid_sz_01,bid_ct_01,ask_px_01,ask_sz_01,ask_ct_01,bid_px_02,bid_sz_02,bid_ct_02,ask_px_02,ask_sz_02,ask_ct_02,bid_px_03,bid_sz_03,bid_ct_03,ask_px_03,ask_sz_03,ask_ct_03,bid_px_04,bid_sz_04,bid_ct_04,ask_px_04,ask_sz_04,ask_ct_04,bid_px_05,bid_sz_05,bid_ct_05,ask_px_05,ask_sz_05,ask_ct_05,bid_px_06,bid_sz_06,bid_ct_06,ask_px_06,ask_sz_06,ask_ct_06,bid_px_07,bid_sz_07,bid_ct_07,ask_px_07,ask_sz_07,ask_ct_07,bid_px_08,bid_sz_08,bid_ct_08,ask_px_08,ask_sz_08,ask_ct_08,bid_px_09,bid_sz_09,bid_ct_09,ask_px_09,ask_sz_09,ask_ct_09,symbol,order_id
2025-07-17T16:04:06.805500523Z,2025-07-17T16:04:06.805335354Z,160,2,1108,C,A,10,13.40,0,0,13.40,23,1,13.12,200,2,13.73,100,1,13.11,100,1,13.80,15,1,13.00,2,1,13.87,200,2,12.86,100,1,14.00,100,1,12.73,100,1,14.03,2,1,12.71,100,1,14.28,100,1,12.50,700,1,14.45,100,1,12.46,100,1,14.52,100,1,12.43,700,1,14.56,800,2,ARL,327863853
2025-07-17T16:04:06.806217584Z,2025-07-17T16:04:06.806052396Z,160,2,1108,C,A,10,13.40,0,0,13.40,23,1,13.12,200,2,13.73,100,1,13.11,100,1,13.87,200,2,13.00,2,1,14.00,100,1,12.86,100,1,14.03,2,1,12.73,100,1,14.28,100,1,12.71,100,1,14.45,100,1,12.50,700,1,14.52,100,1,12.46,100,1,14.56,800,2,12.43,700,1,14.60,700,1,ARL,327675057
2025-07-17T16:04:21.277142662Z,2025-07-17T16:04:21.276976977Z,160,2,1108,A,A,10,13.40,0,0,13.40,23,1,13.12,200,2,13.73,100,1,13.11,100,1,13.77,100,1,13.00,2,1,13.87,200,2,12.86,100,1,14.00,100,1,12.73,100,1,14.03,2,1,12.71,100,1,14.28,100,1,12.50,700,1,14.45,100,1,12.46,100,1,14.52,100,1,12.43,700,1,14.56,800,2,ARL,328239293
2025-07-17T16:04:27.791055146Z,2025-07-17T16:04:27.790889618Z,160,2,1108,C,A,10,13.40,0,0,13.40,23,1,13.12,200,2,13.73,100,1,13.11,100,1,13.77,100,1,13.00,2,1,13.87,200,2,12.86,100,1,14.00,100,1,12.73,100,1,14.28,100,1,12.71,100,1,14.45,100,1,12.50,700,1,14.52,100,1,12.46,100,1,14.56,800,2,12.43,700,1,14.60,700,1,ARL,326159041
2025-07-17T16:04:27.791055146Z,2025-07-17T16:04:27.790889618Z,160,2,1108,A,A,10,13.40,0,0,13.40,23,1,13.12,200,2,13.73,100,1,13.11,100,1,13.77,100,1,13.00,2,1,13.87,200,2,12.86,100,1,13.94,2,1,12.73,100,1,14.00,100,1,12.71,100,1,14.28,100,1,12.50,700,1,14.45,100,1,12.46,100,1,14.52,100,1,12.43,700,1,14.56,800,2,ARL,328351217
2025-07-17T16:04:31.232053154Z,2025-07-17T16:04:31.231887784Z,160,2,1108,A,A,10,13.40,0,0,13.40,23,1,13.12,200,2,13.68,15,1,13.11,100,1,13.73,100,1,13.00,2,1,13.77,100,1,12.86,100,1,13.87,200,2,12.73,100,1,13.94,2,1,12.71,100,1,14.00,100,1,12.50,700,1,14.28,100,1,12.46,100,1,14.45,100,1,12.43,700,1,14.52,100,1,ARL,328437797
2025-07-17T16:04:31.232606440Z,2025-07-17T16:04:31.232440773Z,160,2,1108,A,A,10,13.40,0,0,13.40,23,1,13.12,200,2,13.68,15,1,13.11,100,1,13.72,100,1,13.00,2,1,13.73,100,1,12.86,100,1,13.77,100,1,12.73,100,1,13.87,200,2,12.71,100,1,13.94,2,1,12.50,700,1,14.00,100,1,12.46,100,1,14.28,100,1,12.43,700,1,14.45,100,1,ARL,328437805
2025-07-17T16:04:31.246681162Z,2025-07-17T16:04:31.246515467Z,160,2,1108,C,A,10,13.40,0,0,13.40,23,1,13.12,200,2,13.68,15,1,13.11,100,1,13.72,100,1,13.00,2,1,13.73,100,1,12.86,100,1,13.87,200,2,12.73,100,1,13.94,2,1,12.71,100,1,14.00,100,1,12.50,700,1,14.28,100,1,12.46,100,1,14.45,100,1,12.43,700,1,14.52,100,1,ARL,328239293
2025-07-17T16:04:32.836802111Z,2025-07-17T16:04:32.836635838Z,160,2,1108,C,A,10,13.40,0,0,13.40,23,1,13.12,200,2,13.68,15,1,13.11,100,1,13.72,100,1,13.00,2,1,13.87,200,2,12.86,100,1,13.94,2,1,12.73,100,1,14.00,100,1,12.71,100,1,14.28,100,1,12.50,700,1,14.45,100,1,12.46,100,1,14.52,100,1,12.43,700,1,14.56,800,2,ARL,327864137
2025-07-17T16:04:32.836802111Z,2025-07-17T16:04:32.836635838Z,160,2,1108,A,A,10,13.40,0,0,13.40,23,1,13.12,200,2,13.68,15,1,13.11,100,1,13.69,100,1,13.00,2,1,13.72,100,1,12.86,100,1,13.87,200,2,12.73,100,1,13.94,2,1,12.71,100,1,14.00,100,1,12.50,700,1,14.28,100,1,12.46,100,1,14.45,100,1,12.43,700,1,14.52,100,1,ARL,328489153
2025-07-17T16:04:32.837165431Z,2025-07-17T16:04:32.837000154Z,160,2,1108,C,B,10,13.40,0,0,13.40,23,1,13.12,100,1,13.68,15,1,13.11,100,1,13.69,100,1,13.00,2,1,13.72,100,1,12.86,100,1,13.87,200,2,12.73,100,1,13.94,2,1,12.71,100,1,14.00,100,1,12.50,700,1,14.28,100,1,12.46,100,1,14.45,100,1,12.43,700,1,14.52,100,1,ARL,325718833
2025-07-17T16:04:32.837169083Z,2025-07-17T16:04:32.837002825Z,160,2,1108,C,B,10,13.40,0,0,13.40,23,1,13.11,100,1,13.68,15,1,13.00,2,1,13.69,100,1,12.86,100,1,13.72,100,1,12.73,100,1,13.87,200,2,12.71,100,1,13.94,2,1,12.50,700,1,14.00,100,1,12.46,100,1,14.28,100,1,12.43,700,1,14.45,100,1,12.42,700,1,14.52,100,1,ARL,325718837
2025-07-17T16:04:32.837179568Z,2025-07-17T16:04:32.837013456Z,160,2,1108,A,B,10,13.40,0,0,13.40,23,1,13.11,100,1,13.68,15,1,13.00,2,1,13.69,100,1,12.98,100,1,13.72,100,1,12.86,100,1,13.87,200,2,12.73,100,1,13.94,2,1,12.71,100,1,14.00,100,1,12.50,700,1,14.28,100,1,12.46,100,1,14.45,100,1,12.43,700,1,14.52,100,1,ARL,328489377
2025-07-17T16:04:32.837181582Z,2025-07-17T16:04:32.837016087Z,160,2,1108,A,B,10,13.40,0,0,13.40,23,1,13.11,100,1,13.68,15,1,13.00,2,1,13.69,100,1,12.98,200,2,13.72,100,1,12.86,100,1,13.87,200,2,12.73,100,1,13.94,2,1,12.71,100,1,14.00,100,1,12.50,700,1,14.28,100,1,12.46,100,1,14.45,100,1,12.43,700,1,14.52,100,1,ARL,328489385
2025-07-17T16:04:32.837536434Z,2025-07-17T16:04:32.837369811Z,160,2,1108,C,A,10,13.40,0,0,13.40,23,1,13.11,100,1,13.68,15,1,13.00,2,1,13.69,100,1,12.98,200,2,13.72,100,1,12.86,100,1,13.87,200,2,12.73,100,1,13.94,2,1,12.71,100,1,14.00,100,1,12.50,700,1,14.28,100,1,12.46,100,1,14.45,100,1,12.43,700,1,14.52,100,1,ARL,327864893
2025-07-17T16:04:32.837536434Z,2025-07-17T16:04:32.837369811Z,160,2,1108,A,A,10,13.40,0,0,13.40,23,1,13.11,100,1,13.68,15,1,13.00,2,1,13.69,100,1,12.98,200,2,13.72,100,1,12.86,100,1,13.87,200,2,12.73,100,1,13.94,2,1,12.71,100,1,14.00,100,1,12.50,700,1,14.28,100,1,12.46,100,1,14.45,100,1,12.43,700,1,14.52,100,1,ARL,328489481
2025-07-17T16:04:36.810717146Z,2025-07-17T16:04:36.810551890Z,160,2,1108,A,A,10,13.40,0,0,13.40,23,1,13.11,100,1,13.65,15,1,13.00,2,1,13.68,15,1,12.98,200,2,13.69,100,1,12.86,100,1,13.72,100,1,12.73,100,1,13.87,200,2,12.71,100,1,13.94,2,1,12.50,700,1,14.00,100,1,12.46,100,1,14.28,100,1,12.43,700,1,14.45,100,1,ARL,328603377
2025-07-17T16:04:37.026937493Z,2025-07-17T16:04:37.026771973Z,160,2,1108,A,A,10,13.40,0,0,13.40,23,1,13.11,100,1,13.65,15,1,13.00,2,1,13.68,15,1,12.98,200,2,13.69,200,2,12.86,100,1,13.72,100,1,12.73,100,1,13.87,200,2,12.71,100,1,13.94,2,1,12.50,700,1,14.00,100,1,12.46,100,1,14.28,100,1,12.43,700,1,14.45,100,1,ARL,328606289
2025-07-17T16:04:37.033554557Z,2025-07-17T16:04:37.033389265Z,160,2,1108,C,A,10,13.40,0,0,13.40,23,1,13.11,100,1,13.65,15,1,13.00,2,1,13.68,15,1,12.98,200,2,13.69,200,2,12.86,100,1,13.87,200,2,12.73,100,1,13.94,2,1,12.71,100,1,14.00,100,1,12.50,700,1,14.28,100,1,12.46,100,1,14.45,100,1,12.43,700,1,14.52,100,1,ARL,328437805
2025-07-17T16:04:37.542961161Z,2025-07-17T16:04:37.542795711Z,160,2,1108,C,A,10,13.40,0,0,13.40,23,1,13.11,100,1,13.65,15,1,13.00,2,1,13.68,15,1,12.98,200,2,13.69,100,1,12.86,100,1,13.87,200,2,12.73,100,1,13.94,2,1,12.71,100,1,14.00,100,1,12.50,700,1,14.28,100,1,12.46,100,1,14.45,100,1,12.43,700,1,14.52,100,1,ARL,328489153
2025-07-17T16:04:37.542961161Z,2025-07-17T16:04:37.542795711Z,160,2,1108,A,A,10,13.40,0,0,13.40,23,1,13.11,100,1,13.65,15,1,13.00,2,1,13.66,100,1,12.98,200,2,13.68,15,1,12.86,100,1,13.69,100,1,12.73,100,1,13.87,200,2,12.71,100,1,13.94,2,1,12.50,700,1,14.00,100,1,12.46,100,1,14.28,100,1,12.43,700,1,14.45,100,1,ARL,328614509
2025-07-17T16:04:37.543230680Z,2025-07-17T16:04:37.543063240Z,160,2,1108,C,A,10,13.40,0,0,13.40,23,1,13.11,100,1,13.65,15,1,13.00,2,1,13.66,100,1,12.98,200,2,13.68,15,1,12.86,100,1,13.69,100,1,12.73,100,1,13.87,100,1,12.71,100,1,13.94,2,1,12.50,700,1,14.00,100,1,12.46,100,1,14.28,100,1,12.43,700,1,14.45,100,1,ARL,326730517
2025-07-17T16:04:37.543230680Z,2025-07-17T16:04:37.543064690Z,160,2,1108,C,A,10,13.40,0,0,13.40,23,1,13.11,100,1,13.65,15,1,13.00,2,1,13.66,100,1,12.98,200,2,13.68,15,1,12.86,100,1,13.69,100,1,12.73,100,1,13.94,2,1,12.71,100,1,14.00,100,1,12.50,700,1,14.28,100,1,12.46,100,1,14.45,100,1,12.43,700,1,14.52,100,1,ARL,326730521
2025-07-17T16:04:37.543242390Z,2025-07-17T16:04:37.543077174Z,160,2,1108,A,A,10,13.40,0,0,13.40,23,1,13.11,100,1,13.65,15,1,13.00,2,1,13.66,100,1,12.98,200,2,13.68,15,1,12.86,100,1,13.69,100,1,12.73,100,1,13.80,100,1,12.71,100,1,13.94,2,1,12.50,700,1,14.00,100,1,12.46,100,1,14.28,100,1,12.43,700,1,14.45,100,1,ARL,328614525
2025-07-17T16:04:37.543244193Z,2025-07-17T16:04:37.543078532Z,160,2,1108,A,A,10,13.40,0,0,13.40,23,1,13.11,100,1,13.65,15,1,13.00,2,1,13.66,100,1,12.98,200,2,13.68,15,1,12.86,100,1,13.69,100,1,12.73,100,1,13.80,200,2,12.71,100,1,13.94,2,1,12.50,700,1,14.00,100,1,12.46,100,1,14.28,100,1,12.43,700,1,14.45,100,1,ARL,328614529
2025-07-17T16:04:37.549684713Z,2025-07-17T16:04:37.549519006Z,160,2,1108,C,A,10,13.40,0,0,13.40,23,1,13.11,100,1,13.65,15,1,13.00,2,1,13.66,100,1,12.98,200,2,13.68,15,1,12.86,100,1,13.69,100,1,12.73,100,1,13.80,200,2,12.71,100,1,13.94,2,1,12.50,700,1,14.28,100,1,12.46,100,1,14.45,100,1,12.43,700,1,14.52,100,1,ARL,327869193
2025-07-17T16:04:37.549735824Z,2025-07-17T16:04:37.549570649Z,160,2,1108,A,A,10,13.40,0,0,13.40,23,1,13.11,100,1,13.65,15,1,13.00,2,1,13.66,100,1,12.98,200,2,13.68,15,1,12.86,100,1,13.69,100,1,12.73,100,1,13.80,200,2,12.71,100,1,13.93,100,1,12.50,700,1,13.94,2,1,12.46,100,1,14.28,100,1,12.43,700,1,14.45,100,1,ARL,328616925
2025-07-17T16:04:44.524526545Z,2025-07-17T16:04:44.524360626Z,160,2,1108,C,A,10,13.40,0,0,13.40,23,1,13.11,100,1,13.65,15,1,13.00,2,1,13.66,100,1,12.98,200,2,13.69,100,1,12.86,100,1,13.80,200,2,12.73,100,1,13.93,100,1,12.71,100,1,13.94,2,1,12.50,700,1,14.28,100,1,12.46,100,1,14.45,100,1,12.43,700,1,14.52,100,1,ARL,328437797
2025-07-17T16:04:45.528000143Z,2025-07-17T16:04:45.527835033Z,160,2,1108,A,A,10,13.40,0,0,13.40,23,1,13.11,100,1,13.63,15,1,13.00,2,1,13.65,15,1,12.98,200,2,13.66,100,1,12.86,100,1,13.69,100,1,12.73,100,1,13.80,200,2,12.71,100,1,13.93,100,1,12.50,700,1,13.94,2,1,12.46,100,1,14.28,100,1,12.43,700,1,14.45,100,1,ARL,328780565
2025-07-17T16:04:45.528629613Z,2025-07-17T16:04:45.528464092Z,160,2,1108,C,A,10,13.40,0,0,13.40,23,1,13.11,100,1,13.63,15,1,13.00,2,1,13.65,15,1,12.98,200,2,13.66,100,1,12.86,100,1,13.69,100,1,12.73,100,1,13.80,200,2,12.71,100,1,13.93,100,1,12.50,700,1,13.94,2,1,12.46,100,1,14.28,100,1,12.43,700,1,14.45,100,1,ARL,327856309
2025-07-17T16:04:45.528629613Z,2025-07-17T16:04:45.528464092Z,160,2,1108,A,A,10,13.40,0,0,13.40,23,1,13.11,100,1,13.63,15,1,13.00,2,1,13.65,15,1,12.98,200,2,13.66,100,1,12.86,100,1,13.69,100,1,12.73,100,1,13.80,200,2,12.71,100,1,13.93,100,1,12.50,700,1,13.94,2,1,12.46,100,1,14.28,100,1,12.43,700,1,14.45,100,1,ARL,328780577
2025-07-17T16:04:45.530418278Z,2025-07-17T16:04:45.530252804Z,160,2,1108,C,A,10,13.40,0,0,13.40,23,1,13.11,100,1,13.63,15,1,13.00,2,1,13.65,15,1,12.98,200,2,13.66,100,1,12.86,100,1,13.69,100,1,12.73,100,1,13.80,200,2,12.71,100,1,13.93,100,1,12.50,700,1,13.94,2,1,12.46,100,1,14.28,100,1,12.43,700,1,14.45,100,1,ARL,327856297
2025-07-17T16:04:45.530418278Z,2025-07-17T16:04:45.530252804Z,160,2,1108,A,A,10,13.40,0,0,13.40,23,1,13.11,100,1,13.63,15,1,13.00,2,1,13.65,15,1,12.98,200,2,13.66,100,1,12.86,100,1,13.69,100,1,12.73,100,1,13.80,200,2,12.71,100,1,13.93,100,1,12.50,700,1,13.94,2,1,12.46,100,1,14.28,100,1,12.43,700,1,14.45,100,1,ARL,328780597
2025-07-17T16:04:45.533067029Z,2025-07-17T16:04:45.532901874Z,160,2,1108,C,A,10,13.40,0,0,13.40,23,1,13.11,100,1,13.63,15,1,13.00,2,1,13.65,15,1,12.98,200,2,13.69,100,1,12.86,100,1,13.80,200,2,12.73,100,1,13.93,100,1,12.71,100,1,13.94,2,1,12.50,700,1,14.28,100,1,12.46,100,1,14.45,100,1,12.43,700,1,14.52,300,3,ARL,328614509
2025-07-17T16:04:45.533067029Z,2025-07-17T16:04:45.532901874Z,160,2,1108,A,A,10,13.40,0,0,13.40,23,1,13.11,100,1,13.63,15,1,13.00,2,1,13.64,100,1,12.98,200,2,13.65,15,1,12.86,100,1,13.69,100,1,12.73,100,1,13.80,200,2,12.71,100,1,13.93,100,1,12.50,700,1,13.94,2,1,12.46,100,1,14.28,100,1,12.43,700,1,14.45,100,1,ARL,328780669
2025-07-17T16:04:45.533804768Z,2025-07-17T16:04:45.533639142Z,160,2,1108,C,A,10,13.40,0,0,13.40,23,1,13.11,100,1,13.63,15,1,13.00,2,1,13.64,100,1,12.98,200,2,13.65,15,1,12.86,100,1,13.69,100,1,12.73,100,1,13.80,200,2,12.71,100,1,13.93,100,1,12.50,700,1,13.94,2,1,12.46,100,1,14.28,100,1,12.43,700,1,14.45,100,1,ARL,328489481
2025-07-17T16:04:45.533804768Z,2025-07-17T16:04:45.533639142Z,160,2,1108,A,A,10,13.40,0,0,13.40,23,1,13.11,100,1,13.63,15,1,13.00,2,1,13.64,100,1,12.98,200,2,13.65,15,1,12.86,100,1,13.69,100,1,12.73,100,1,13.80,200,2,12.71,100,1,13.93,100,1,12.50,700,1,13.94,2,1,12.46,100,1,14.28,100,1,12.43,700,1,14.45,100,1,ARL,328780685
2025-07-17T16:04:45.533870711Z,2025-07-17T16:04:45.533705428Z,160,2,1108,A,A,10,13.40,0,0,13.40,23,1,13.11,100,1,13.63,15,1,13.00,2,1,13.64,100,1,12.98,200,2,13.65,15,1,12.86,100,1,13.67,100,1,12.73,100,1,13.69,100,1,12.71,100,1,13.80,200,2,12.50,700,1,13.93,100,1,12.46,100,1,13.94,2,1,12.43,700,1,14.28,100,1,ARL,328780689
2025-07-17T16:04:45.563137443Z,2025-07-17T16:04:45.562972204Z,160,2,1108,C,A,10,13.40,0,0,13.40,23,1,13.11,100,1,13.63,15,1,13.00,2,1,13.64,100,1,12.98,200,2,13.65,15,1,12.86,100,1,13.67,100,1,12.73,100,1,13.80,200,2,12.71,100,1,13.93,100,1,12.50,700,1,13.94,2,1,12.46,100,1,14.28,100,1,12.43,700,1,14.45,100,1,ARL,328606289
2025-07-17T16:04:56.809749973Z,2025-07-17T16:04:56.809584701Z,160,2,1108,C,A,10,13.40,0,0,13.40,23,1,13.11,100,1,13.63,15,1,13.00,2,1,13.64,100,1,12.98,200,2,13.67,100,1,12.86,100,1,13.80,200,2,12.73,100,1,13.93,100,1,12.71,100,1,13.94,2,1,12.50,700,1,14.28,100,1,12.46,100,1,14.45,100,1,12.43,700,1,14.52,300,3,ARL,328603377
2025-07-17T16:04:57.827079009Z,2025-07-17T16:04:57.826913717Z,160,2,1108,A,A,10,13.40,0,0,13.40,23,1,13.11,100,1,13.61,15,1,13.00,2,1,13.63,15,1,12.98,200,2,13.64,100,1,12.86,100,1,13.67,100,1,12.73,100,1,13.80,200,2,12.71,100,1,13.93,100,1,12.50,700,1,13.94,2,1,12.46,100,1,14.28,100,1,12.43,700,1,14.45,100,1,ARL,329068341
2025-07-17T16:04:57.970616610Z,2025-07-17T16:04:57.970451236Z,160,2,1108,C,A,10,13.40,0,0,13.40,23,1,13.11,100,1,13.61,15,1,13.00,2,1,13.63,15,1,12.98,200,2,13.67,100,1,12.86,100,1,13.80,200,2,12.73,100,1,13.93,100,1,12.71,100,1,13.94,2,1,12.50,700,1,14.28,100,1,12.46,100,1,14.45,100,1,12.43,700,1,14.52,300,3,ARL,328780669
2025-07-17T16:04:57.970616610Z,2025-07-17T16:04:57.970451236Z,160,2,1108,A,A,10,13.40,0,0,13.40,23,1,13.11,100,1,13.61,15,1,13.00,2,1,13.62,100,1,12.98,200,2,13.63,15,1,12.86,100,1,13.67,100,1,12.73,100,1,13.80,200,2,12.71,100,1,13.93,100,1,12.50,700,1,13.94,2,1,12.46,100,1,14.28,100,1,12.43,700,1,14.45,100,1,ARL,329074609
2025-07-17T16:04:57.971360344Z,2025-07-17T16:04:57.971193734Z,160,2,1108,C,A,10,13.40,0,0,13.40,23,1,13.11,100,1,13.61,15,1,13.00,2,1,13.62,100,1,12.98,200,2,13.63,15,1,12.86,100,1,13.67,100,1,12.73,100,1,13.80,200,2,12.71,100,1,13.93,100,1,12.50,700,1,13.94,2,1,12.46,100,1,14.28,100,1,12.43,700,1,14.52,300,3,ARL,325714601
2025-07-17T16:04:57.971717511Z,2025-07-17T16:04:57.971552262Z,160,2,1108,A,A,10,13.40,0,0,13.40,23,1,13.11,100,1,13.61,15,1,13.00,2,1,13.62,100,1,12.98,200,2,13.63,15,1,12.86,100,1,13.67,100,1,12.73,100,1,13.80,200,2,12.71,100,1,13.93,100,1,12.50,700,1,13.94,2,1,12.46,100,1,14.23,100,1,12.43,700,1,14.28,100,1,ARL,329074833
2025-07-17T16:04:57.992131878Z,2025-07-17T16:04:57.991966904Z,160,2,1108,C,A,10,13.40,0,0,13.40,23,1,13.11,100,1,13.62,100,1,13.00,2,1,13.63,15,1,12.98,200,2,13.67,100,1,12.86,100,1,13.80,200,2,12.73,100,1,13.93,100,1,12.71,100,1,13.94,2,1,12.50,700,1,14.23,100,1,12.46,100,1,14.28,100,1,12.43,700,1,14.52,300,3,ARL,329068341
2025-07-17T16:04:57.993141438Z,2025-07-17T16:04:57.992976406Z,160,2,1108,C,A,10,13.40,0,0,13.40,23,1,13.11,100,1,13.63,15,1,13.00,2,1,13.67,100,1,12.98,200,2,13.80,200,2,12.86,100,1,13.93,100,1,12.73,100,1,13.94,2,1,12.71,100,1,14.23,100,1,12.50,700,1,14.28,100,1,12.46,100,1,14.52,300,3,12.43,700,1,14.56,800,2,ARL,329074609
2025-07-17T16:04:57.993309561Z,2025-07-17T16:04:57.993143873Z,160,2,1108,C,A,10,13.40,0,0,13.40,23,1,13.11,100,1,13.67,100,1,13.00,2,1,13.80,200,2,12.98,200,2,13.93,100,1,12.86,100,1,13.94,2,1,12.73,100,1,14.23,100,1,12.71,100,1,14.28,100,1,12.50,700,1,14.52,300,3,12.46,100,1,14.56,800,2,12.43,700,1,14.60,700,1,ARL,328780565
2025-07-17T16:04:58.002259715Z,2025-07-17T16:04:58.002094377Z,160,2,1108,C,A,10,13.40,0,0,13.40,23,1,13.11,100,1,13.80,200,2,13.00,2,1,13.93,100,1,12.98,200,2,13.94,2,1,12.86,100,1,14.23,100,1,12.73,100,1,14.28,100,1,12.71,100,1,14.52,300,3,12.50,700,1,14.56,800,2,12.46,100,1,14.60,700,1,12.43,700,1,14.68,1400,2,ARL,328780689
2025-07-17T16:04:58.002989430Z,2025-07-17T16:04:58.002823841Z,160,2,1108,C,A,10,13.40,0,0,13.40,23,1,13.11,100,1,13.80,200,2,13.00,2,1,13.93,100,1,12.98,200,2,13.94,2,1,12.86,100,1,14.23,100,1,12.73,100,1,14.28,100,1,12.71,100,1,14.52,300,3,12.50,700,1,14.56,800,2,12.46,100,1,14.60,700,1,12.43,700,1,14.68,1400,2,ARL,328780685
2025-07-17T16:04:58.002989430Z,2025-07-17T16:04:58.002823841Z,160,2,1108,A,A,10,13.40,0,0,13.40,23,1,13.11,100,1,13.80,200,2,13.00,2,1,13.93,100,1,12.98,200,2,13.94,2,1,12.86,100,1,14.23,100,1,12.73,100,1,14.28,100,1,12.71,100,1,14.52,300,3,12.50,700,1,14.56,800,2,12.46,100,1,14.60,700,1,12.43,700,1,14.68,1400,2,ARL,329078553
2025-07-17T16:04:58.013904697Z,2025-07-17T16:04:58.013739242Z,160,2,1108,C,A,10,13.40,0,0,13.40,23,1,13.11,100,1,13.80,200,2,13.00,2,1,13.94,2,1,12.98,200,2,14.23,100,1,12.86,100,1,14.28,100,1,12.73,100,1,14.52,300,3,12.71,100,1,14.56,800,2,12.50,700,1,14.60,700,1,12.46,100,1,14.68,1400,2,12.43,700,1,14.70,200,2,ARL,328616925
2025-07-17T16:04:58.013959233Z,2025-07-17T16:04:58.013793974Z,160,2,1108,A,A,10,13.40,0,0,13.40,23,1,13.11,100,1,13.80,200,2,13.00,2,1,13.94,2,1,12.98,200,2,14.08,100,1,12.86,100,1,14.23,100,1,12.73,100,1,14.28,100,1,12.71,100,1,14.52,300,3,12.50,700,1,14.56,800,2,12.46,100,1,14.60,700,1,12.43,700,1,14.68,1400,2,ARL,329078953
2025-07-17T16:04:58.536617917Z,2025-07-17T16:04:58.536452621Z,160,2,1108,A,A,10,13.40,0,0,13.40,23,1,13.11,100,1,13.80,200,2,13.00,2,1,13.81,100,1,12.98,200,2,13.94,2,1,12.86,100,1,14.08,100,1,12.73,100,1,14.23,100,1,12.71,100,1,14.28,100,1,12.50,700,1,14.52,300,3,12.46,100,1,14.56,800,2,12.43,700,1,14.60,700,1,ARL,329088265
2025-07-17T16:05:46.594131664Z,2025-07-17T16:05:46.593966383Z,160,2,1108,A,A,10,13.40,0,0,13.40,23,1,13.11,100,1,13.76,100,1,13.00,2,1,13.80,200,2,12.98,200,2,13.81,100,1,12.86,100,1,13.94,2,1,12.73,100,1,14.08,100,1,12.71,100,1,14.23,100,1,12.50,700,1,14.28,100,1,12.46,100,1,14.52,300,3,12.43,700,1,14.56,800,2,ARL,330066537
2025-07-17T16:05:46.594871336Z,2025-07-17T16:05:46.594705962Z,160,2,1108,C,A,10,13.40,0,0,13.40,23,1,13.11,100,1,13.76,100,1,13.00,2,1,13.80,200,2,12.98,200,2,13.81,100,1,12.86,100,1,13.94,2,1,12.73,100,1,14.08,100,1,12.71,100,1,14.23,100,1,12.50,700,1,14.28,100,1,12.46,100,1,14.52,300,3,12.43,700,1,14.56,800,2,ARL,329078553
2025-07-17T16:05:46.594871336Z,2025-07-17T16:05:46.594705962Z,160,2,1108,A,A,10,13.40,0,0,13.40,23,1,13.11,100,1,13.76,100,1,13.00,2,1,13.80,200,2,12.98,200,2,13.81,100,1,12.86,100,1,13.94,2,1,12.73,100,1,14.08,100,1,12.71,100,1,14.23,100,1,12.50,700,1,14.28,100,1,12.46,100,1,14.52,300,3,12.43,700,1,14.56,800,2,ARL,330066553
2025-07-17T16:05:46.996003552Z,2025-07-17T16:05:46.995837526Z,160,2,1108,C,A,10,13.40,0,0,13.40,23,1,13.11,100,1,13.76,100,1,13.00,2,1,13.80,200,2,12.98,200,2,13.94,2,1,12.86,100,1,14.08,100,1,12.73,100,1,14.23,100,1,12.71,100,1,14.28,100,1,12.50,700,1,14.52,300,3,12.46,100,1,14.56,800,2,12.43,700,1,14.60,700,1,ARL,329088265
2025-07-17T16:05:46.996003552Z,2025-07-17T16:05:46.995837526Z,160,2,1108,A,A,10,13.40,0,0,13.40,23,1,13.11,100,1,13.76,100,1,13.00,2,1,13.77,100,1,12.98,200,2,13.80,200,2,12.86,100,1,13.94,2,1,12.73,100,1,14.08,100,1,12.71,100,1,14.23,100,1,12.50,700,1,14.28,100,1,12.46,100,1,14.52,300,3,12.43,700,1,14.56,800,2,ARL,330075425
2025-07-17T16:05:50.680333151Z,2025-07-17T16:05:50.680167632Z,160,2,1108,A,A,10,13.40,0,0,13.40,23,1,13.11,100,1,13.68,15,1,13.00,2,1,13.76,100,1,12.98,200,2,13.77,100,1,12.86,100,1,13.80,200,2,12.73,100,1,13.94,2,1,12.71,100,1,14.08,100,1,12.50,700,1,14.23,100,1,12.46,100,1,14.28,100,1,12.43,700,1,14.52,300,3,ARL,330143813
2025-07-17T16:05:50.697170320Z,2025-07-17T16:05:50.697005084Z,160,2,1108,A,A,10,13.40,0,0,13.40,23,1,13.11,100,1,13.68,15,1,13.00,2,1,13.72,100,1,12.98,200,2,13.76,100,1,12.86,100,1,13.77,100,1,12.73,100,1,13.80,200,2,12.71,100,1,13.94,2,1,12.50,700,1,14.08,100,1,12.46,100,1,14.23,100,1,12.43,700,1,14.28,100,1,ARL,330144301
2025-07-17T16:05:50.697905372Z,2025-07-17T16:05:50.697739933Z,160,2,1108,C,A,10,13.40,0,0,13.40,23,1,13.11,100,1,13.68,15,1,13.00,2,1,13.72,100,1,12.98,200,2,13.76,100,1,12.86,100,1,13.77,100,1,12.73,100,1,13.80,200,2,12.71,100,1,13.94,2,1,12.50,700,1,14.08,100,1,12.46,100,1,14.23,100,1,12.43,700,1,14.28,100,1,ARL,330066553
2025-07-17T16:05:50.697905372Z,2025-07-17T16:05:50.697739933Z,160,2,1108,A,A,10,13.40,0,0,13.40,23,1,13.11,100,1,13.68,15,1,13.00,2,1,13.72,100,1,12.98,200,2,13.76,100,1,12.86,100,1,13.77,100,1,12.73,100,1,13.80,200,2,12.71,100,1,13.94,2,1,12.50,700,1,14.08,100,1,12.46,100,1,14.23,100,1,12.43,700,1,14.28,100,1,ARL,330144321
2025-07-17T16:05:50.704531748Z,2025-07-17T16:05:50.704366332Z,160,2,1108,C,A,10,13.40,0,0,13.40,23,1,13.11,100,1,13.68,15,1,13.00,2,1,13.72,100,1,12.98,200,2,13.77,100,1,12.86,100,1,13.80,200,2,12.73,100,1,13.94,2,1,12.71,100,1,14.08,100,1,12.50,700,1,14.23,100,1,12.46,100,1,14.28,100,1,12.43,700,1,14.52,300,3,ARL,330066537
2025-07-17T16:05:50.708879311Z,2025-07-17T16:05:50.708714027Z,160,2,1108,C,A,10,13.40,0,0,13.40,23,1,13.11,100,1,13.68,15,1,13.00,2,1,13.72,100,1,12.98,200,2,13.77,100,1,12.86,100,1,13.80,200,2,12.73,100,1,13.94,2,1,12.71,100,1,14.23,100,1,12.50,700,1,14.28,100,1,12.46,100,1,14.52,300,3,12.43,700,1,14.56,800,2,ARL,329078953
2025-07-17T16:05:50.708931189Z,2025-07-17T16:05:50.708766050Z,160,2,1108,A,A,10,13.40,0,0,13.40,23,1,13.11,100,1,13.68,15,1,13.00,2,1,13.72,100,1,12.98,200,2,13.77,100,1,12.86,100,1,13.80,200,2,12.73,100,1,13.94,2,1,12.71,100,1,13.99,100,1,12.50,700,1,14.23,100,1,12.46,100,1,14.28,100,1,12.43,700,1,14.52,300,3,ARL,330144513
2025-07-17T16:05:50.913476268Z,2025-07-17T16:05:50.913310799Z,160,2,1108,C,A,10,13.40,0,0,13.40,23,1,13.11,100,1,13.68,15,1,13.00,2,1,13.72,100,1,12.98,200,2,13.80,200,2,12.86,100,1,13.94,2,1,12.73,100,1,13.99,100,1,12.71,100,1,14.23,100,1,12.50,700,1,14.28,100,1,12.46,100,1,14.52,300,3,12.43,700,1,14.56,800,2,ARL,330075425
2025-07-17T16:05:50.913476268Z,2025-07-17T16:05:50.913310799Z,160,2,1108,A,A,10,13.40,0,0,13.40,23,1,13.11,100,1,13.68,15,1,13.00,2,1,13.69,100,1,12.98,200,2,13.72,100,1,12.86,100,1,13.80,200,2,12.73,100,1,13.94,2,1,12.71,100,1,13.99,100,1,12.50,700,1,14.23,100,1,12.46,100,1,14.28,100,1,12.43,700,1,14.52,300,3,ARL,330151389
2025-07-17T16:05:59.704955970Z,2025-07-17T16:05:59.704790753Z,160,2,1108,A,A,10,13.40,0,0,13.40,23,1,13.11,100,1,13.64,15,1,13.00,2,1,13.68,15,1,12.98,200,2,13.69,100,1,12.86,100,1,13.72,100,1,12.73,100,1,13.80,200,2,12.71,100,1,13.94,2,1,12.50,700,1,13.99,100,1,12.46,100,1,14.23,100,1,12.43,700,1,14.28,100,1,ARL,330357473
2025-07-17T16:05:59.715090662Z,2025-07-17T16:05:59.714925412Z,160,2,1108,A,A,10,13.40,0,0,13.40,23,1,13.11,100,1,13.64,15,1,13.00,2,1,13.68,115,2,12.98,200,2,13.69,100,1,12.86,100,1,13.72,100,1,12.73,100,1,13.80,200,2,12.71,100,1,13.94,2,1,12.50,700,1,13.99,100,1,12.46,100,1,14.23,100,1,12.43,700,1,14.28,100,1,ARL,330357633
2025-07-17T16:05:59.722895750Z,2025-07-17T16:05:59.722730507Z,160,2,1108,C,A,10,13.40,0,0,13.40,23,1,13.11,100,1,13.64,15,1,13.00,2,1,13.68,115,2,12.98,200,2,13.69,100,1,12.86,100,1,13.80,200,2,12.73,100,1,13.94,2,1,12.71,100,1,13.99,100,1,12.50,700,1,14.23,100,1,12.46,100,1,14.28,100,1,12.43,700,1,14.52,300,3,ARL,330144301
2025-07-17T16:05:59.802762087Z,2025-07-17T16:05:59.802596747Z,160,2,1108,C,A,10,13.40,0,0,13.40,23,1,13.11,100,1,13.64,15,1,13.00,2,1,13.68,115,2,12.98,200,2,13.80,200,2,12.86,100,1,13.94,2,1,12.73,100,1,13.99,100,1,12.71,100,1,14.23,100,1,12.50,700,1,14.28,100,1,12.46,100,1,14.52,300,3,12.43,700,1,14.56,800,2,ARL,330151389
2025-07-17T16:05:59.802762087Z,2025-07-17T16:05:59.802596747Z,160,2,1108,A,A,10,13.40,0,0,13.40,23,1,13.11,100,1,13.64,15,1,13.00,2,1,13.65,100,1,12.98,200,2,13.68,115,2,12.86,100,1,13.80,200,2,12.73,100,1,13.94,2,1,12.71,100,1,13.99,100,1,12.50,700,1,14.23,100,1,12.46,100,1,14.28,100,1,12.43,700,1,14.52,300,3,ARL,330359197
2025-07-17T16:05:59.803504658Z,2025-07-17T16:05:59.803338996Z,160,2,1108,C,A,10,13.40,0,0,13.40,23,1,13.11,100,1,13.64,15,1,13.00,2,1,13.65,100,1,12.98,200,2,13.68,115,2,12.86,100,1,13.80,200,2,12.73,100,1,13.94,2,1,12.71,100,1,13.99,100,1,12.50,700,1,14.23,100,1,12.46,100,1,14.28,100,1,12.43,700,1,14.52,300,3,ARL,330144321
2025-07-17T16:05:59.803504658Z,2025-07-17T16:05:59.803338996Z,160,2,1108,A,A,10,13.40,0,0,13.40,23,1,13.11,100,1,13.64,15,1,13.00,2,1,13.65,100,1,12.98,200,2,13.68,115,2,12.86,100,1,13.80,200,2,12.73,100,1,13.94,2,1,12.71,100,1,13.99,100,1,12.50,700,1,14.23,100,1,12.46,100,1,14.28,100,1,12.43,700,1,14.52,300,3,ARL,330359225
2025-07-17T16:05:59.827787837Z,2025-07-17T16:05:59.827622529Z,160,2,1108,C,A,10,13.40,0,0,13.40,23,1,13.11,100,1,13.64,15,1,13.00,2,1,13.65,100,1,12.98,200,2,13.68,115,2,12.86,100,1,13.80,200,2,12.73,100,1,13.94,2,1,12.71,100,1,14.23,100,1,12.50,700,1,14.28,100,1,12.46,100,1,14.52,300,3,12.43,700,1,14.56,800,2,ARL,330144513
2025-07-17T16:05:59.827839802Z,2025-07-17T16:05:59.827674437Z,160,2,1108,A,A,10,13.40,0,0,13.40,23,1,13.11,100,1,13.64,15,1,13.00,2,1,13.65,100,1,12.98,200,2,13.68,115,2,12.86,100,1,13.80,200,2,12.73,100,1,13.92,100,1,12.71,100,1,13.94,2,1,12.50,700,1,14.23,100,1,12.46,100,1,14.28,100,1,12.43,700,1,14.52,300,3,ARL,330359625
2025-07-17T16:06:02.724446337Z,2025-07-17T16:06:02.724280161Z,160,2,1108,C,A,10,13.40,0,0,13.40,23,1,13.11,100,1,13.64,15,1,13.00,2,1,13.65,100,1,12.98,200,2,13.68,100,1,12.86,100,1,13.80,200,2,12.73,100,1,13.92,100,1,12.71,100,1,13.94,2,1,12.50,700,1,14.23,100,1,12.46,100,1,14.28,100,1,12.43,700,1,14.52,300,3,ARL,330143813
2025-07-17T16:06:03.729377770Z,2025-07-17T16:06:03.729212428Z,160,2,1108,A,A,10,13.40,0,0,13.40,23,1,13.11,100,1,13.62,15,1,13.00,2,1,13.64,15,1,12.98,200,2,13.65,100,1,12.86,100,1,13.68,100,1,12.73,100,1,13.80,200,2,12.71,100,1,13.92,100,1,12.50,700,1,13.94,2,1,12.46,100,1,14.23,100,1,12.43,700,1,14.28,100,1,ARL,330577045
2025-07-17T16:06:03.738497645Z,2025-07-17T16:06:03.738332427Z,160,2,1108,A,A,10,13.40,0,0,13.40,23,1,13.11,100,1,13.62,15,1,13.00,2,1,13.64,15,1,12.98,200,2,13.65,200,2,12.86,100,1,13.68,100,1,12.73,100,1,13.80,200,2,12.71,100,1,13.92,100,1,12.50,700,1,13.94,2,1,12.46,100,1,14.23,100,1,12.43,700,1,14.28,100,1,ARL,330577773
2025-07-17T16:06:03.747495669Z,2025-07-17T16:06:03.747330178Z,160,2,1108,C,A,10,13.40,0,0,13.40,23,1,13.11,100,1,13.62,15,1,13.00,2,1,13.64,15,1,12.98,200,2,13.65,200,2,12.86,100,1,13.80,200,2,12.73,100,1,13.92,100,1,12.71,100,1,13.94,2,1,12.50,700,1,14.23,100,1,12.46,100,1,14.28,100,1,12.43,700,1,14.52,300,3,ARL,330357633
2025-07-17T16:06:03.887274670Z,2025-07-17T16:06:03.887107153Z,160,2,1108,C,A,10,13.40,0,0,13.40,23,1,13.11,100,1,13.62,15,1,13.00,2,1,13.64,15,1,12.98,200,2,13.65,100,1,12.86,100,1,13.80,200,2,12.73,100,1,13.92,100,1,12.71,100,1,13.94,2,1,12.50,700,1,14.23,100,1,12.46,100,1,14.28,100,1,12.43,700,1,14.52,300,3,ARL,330359197
2025-07-17T16:06:03.887274670Z,2025-07-17T16:06:03.887107153Z,160,2,1108,A,A,10,13.40,0,0,13.40,23,1,13.11,100,1,13.62,15,1,13.00,2,1,13.63,100,1,12.98,200,2,13.64,15,1,12.86,100,1,13.65,100,1,12.73,100,1,13.80,200,2,12.71,100,1,13.92,100,1,12.50,700,1,13.94,2,1,12.46,100,1,14.23,100,1,12.43,700,1,14.28,100,1,ARL,330592465
2025-07-17T16:06:07.510050758Z,2025-07-17T16:06:07.509885114Z,160,2,1108,C,A,10,13.40,0,0,13.40,23,1,13.11,100,1,13.62,15,1,13.00,2,1,13.63,100,1,12.98,200,2,13.65,100,1,12.86,100,1,13.80,200,2,12.73,100,1,13.92,100,1,12.71,100,1,13.94,2,1,12.50,700,1,14.23,100,1,12.46,100,1,14.28,100,1,12.43,700,1,14.52,300,3,ARL,330357473
2025-07-17T16:06:09.885143909Z,2025-07-17T16:06:09.884978592Z,160,2,1108,A,A,10,13.40,0,0,13.40,23,1,13.11,100,1,13.60,15,1,13.00,2,1,13.62,15,1,12.98,200,2,13.63,100,1,12.86,100,1,13.65,100,1,12.73,100,1,13.80,200,2,12.71,100,1,13.92,100,1,12.50,700,1,13.94,2,1,12.46,100,1,14.23,100,1,12.43,700,1,14.28,100,1,ARL,330788421
2025-07-17T16:06:09.967608061Z,2025-07-17T16:06:09.967442600Z,160,2,1108,C,A,10,13.40,0,0,13.40,23,1,13.11,100,1,13.60,15,1,13.00,2,1,13.62,15,1,12.98,200,2,13.65,100,1,12.86,100,1,13.80,200,2,12.73,100,1,13.92,100,1,12.71,100,1,13.94,2,1,12.50,700,1,14.23,100,1,12.46,100,1,14.28,100,1,12.43,700,1,14.52,300,3,ARL,330592465
2025-07-17T16:06:09.967608061Z,2025-07-17T16:06:09.967442600Z,160,2,1108,A,A,10,13.40,0,0,13.40,23,1,13.11,100,1,13.60,15,1,13.00,2,1,13.61,100,1,12.98,200,2,13.62,15,1,12.86,100,1,13.65,100,1,12.73,100,1,13.80,200,2,12.71,100,1,13.92,100,1,12.50,700,1,13.94,2,1,12.46,100,1,14.23,100,1,12.43,700,1,14.28,100,1,ARL,330789481
2025-07-17T16:06:09.968352066Z,2025-07-17T16:06:09.968186617Z,160,2,1108,C,A,10,13.40,0,0,13.40,23,1,13.11,100,1,13.60,15,1,13.00,2,1,13.61,100,1,12.98,200,2,13.62,15,1,12.86,100,1,13.65,100,1,12.73,100,1,13.80,200,2,12.71,100,1,13.92,100,1,12.50,700,1,13.94,2,1,12.46,100,1,14.23,100,1,12.43,700,1,14.28,100,1,ARL,330359225
2025-07-17T16:06:09.968352066Z,2025-07-17T16:06:09.968186617Z,160,2,1108,A,A,10,13.40,0,0,13.40,23,1,13.11,100,1,13.60,15,1,13.00,2,1,13.61,100,1,12.98,200,2,13.62,15,1,12.86,100,1,13.65,100,1,12.73,100,1,13.80,200,2,12.71,100,1,13.92,100,1,12.50,700,1,13.94,2,1,12.46,100,1,14.23,100,1,12.43,700,1,14.28,100,1,ARL,330789501
2025-07-17T16:06:09.970040686Z,2025-07-17T16:06:09.969875190Z,160,2,1108,C,A,10,13.40,0,0,13.40,23,1,13.11,100,1,13.60,15,1,13.00,2,1,13.61,100,1,12.98,200,2,13.62,15,1,12.86,100,1,13.65,100,1,12.73,100,1,13.80,200,2,12.71,100,1,13.92,100,1,12.50,700,1,13.94,2,1,12.46,100,1,14.23,100,1,12.43,700,1,14.28,100,1,ARL,327870217
2025-07-17T16:06:09.970040686Z,2025-07-17T16:06:09.969875190Z,160,2,1108,A,A,10,13.40,0,0,13.40,23,1,13.11,100,1,13.60,15,1,13.00,2,1,13.61,100,1,12.98,200,2,13.62,15,1,12.86,100,1,13.65,100,1,12.73,100,1,13.80,200,2,12.71,100,1,13.92,100,1,12.50,700,1,13.94,2,1,12.46,100,1,14.23,100,1,12.43,700,1,14.28,100,1,ARL,330789509
2025-07-17T16:06:20.470889851Z,2025-07-17T16:06:20.470724464Z,160,2,1108,A,A,10,13.40,0,0,13.40,23,1,13.11,100,1,13.60,15,1,13.00,2,1,13.61,100,1,12.98,200,2,13.62,15,1,12.86,100,1,13.63,100,1,12.73,100,1,13.65,100,1,12.71,100,1,13.80,200,2,12.50,700,1,13.92,100,1,12.46,100,1,13.94,2,1,12.43,700,1,14.23,100,1,ARL,331018065
2025-07-17T16:06:20.477598578Z,2025-07-17T16:06:20.477432988Z,160,2,1108,C,A,10,13.40,0,0,13.40,23,1,13.11,100,1,13.60,15,1,13.00,2,1,13.61,100,1,12.98,200,2,13.62,15,1,12.86,100,1,13.63,100,1,12.73,100,1,13.80,200,2,12.71,100,1,13.92,100,1,12.50,700,1,13.94,2,1,12.46,100,1,14.23,100,1,12.43,700,1,14.28,100,1,ARL,330577773
2025-07-17T16:06:20.811164178Z,2025-07-17T16:06:20.810998706Z,160,2,1108,C,A,10,13.40,0,0,13.40,23,1,13.11,100,1,13.60,15,1,13.00,2,1,13.61,100,1,12.98,200,2,13.63,100,1,12.86,100,1,13.80,200,2,12.73,100,1,13.92,100,1,12.71,100,1,13.94,2,1,12.50,700,1,14.23,100,1,12.46,100,1,14.28,100,1,12.43,700,1,14.52,300,3,ARL,330577045
2025-07-17T16:06:22.151222819Z,2025-07-17T16:06:22.151057292Z,160,2,1108,A,A,10,13.40,0,0,13.40,23,1,13.11,100,1,13.58,15,1,13.00,2,1,13.60,15,1,12.98,200,2,13.61,100,1,12.86,100,1,13.63,100,1,12.73,100,1,13.80,200,2,12.71,100,1,13.92,100,1,12.50,700,1,13.94,2,1,12.46,100,1,14.23,100,1,12.43,700,1,14.28,100,1,ARL,331050981
2025-07-17T16:06:22.151491832Z,2025-07-17T16:06:22.151326300Z,160,2,1108,C,A,10,13.40,0,0,13.40,23,1,13.11,100,1,13.58,15,1,13.00,2,1,13.60,15,1,12.98,200,2,13.63,100,1,12.86,100,1,13.80,200,2,12.73,100,1,13.92,100,1,12.71,100,1,13.94,2,1,12.50,700,1,14.23,100,1,12.46,100,1,14.28,100,1,12.43,700,1,14.52,300,3,ARL,330789481
2025-07-17T16:06:22.151491832Z,2025-07-17T16:06:22.151326300Z,160,2,1108,A,A,10,13.40,0,0,13.40,23,1,13.11,100,1,13.58,15,1,13.00,2,1,13.59,100,1,12.98,200,2,13.60,15,1,12.86,100,1,13.63,100,1,12.73,100,1,13.80,200,2,12.71,100,1,13.92,100,1,12.50,700,1,13.94,2,1,12.46,100,1,14.23,100,1,12.43,700,1,14.28,100,1,ARL,331050989
2025-07-17T16:06:22.151761329Z,2025-07-17T16:06:22.151595415Z,160,2,1108,C,A,10,13.40,0,0,13.40,23,1,13.11,100,1,13.58,15,1,13.00,2,1,13.59,100,1,12.98,200,2,13.60,15,1,12.86,100,1,13.63,100,1,12.73,100,1,13.80,100,1,12.71,100,1,13.92,100,1,12.50,700,1,13.94,2,1,12.46,100,1,14.23,100,1,12.43,700,1,14.28,100,1,ARL,328614525
2025-07-17T16:06:22.151761329Z,2025-07-17T16:06:22.151595781Z,160,2,1108,C,A,10,13.40,0,0,13.40,23,1,13.11,100,1,13.58,15,1,13.00,2,1,13.59,100,1,12.98,200,2,13.60,15,1,12.86,100,1,13.63,100,1,12.73,100,1,13.92,100,1,12.71,100,1,13.94,2,1,12.50,700,1,14.23,100,1,12.46,100,1,14.28,100,1,12.43,700,1,14.52,300,3,ARL,328614529
2025-07-17T16:06:22.153148893Z,2025-07-17T16:06:22.152983326Z,160,2,1108,C,A,10,13.40,0,0,13.40,23,1,13.11,100,1,13.58,15,1,13.00,2,1,13.59,100,1,12.98,200,2,13.60,15,1,12.86,100,1,13.63,100,1,12.73,100,1,13.92,100,1,12.71,100,1,13.94,2,1,12.50,700,1,14.23,100,1,12.46,100,1,14.28,100,1,12.43,700,1,14.52,300,3,ARL,327870361
2025-07-17T16:06:22.153148893Z,2025-07-17T16:06:22.152983326Z,160,2,1108,A,A,10,13.40,0,0,13.40,23,1,13.11,100,1,13.58,15,1,13.00,2,1,13.59,100,1,12.98,200,2,13.60,15,1,12.86,100,1,13.63,100,1,12.73,100,1,13.92,100,1,12.71,100,1,13.94,2,1,12.50,700,1,14.23,100,1,12.46,100,1,14.28,100,1,12.43,700,1,14.52,300,3,ARL,331051145
2025-07-17T16:06:22.153916169Z,2025-07-17T16:06:22.153749481Z,160,2,1108,C,A,10,13.40,0,0,13.40,23,1,13.11,100,1,13.58,15,1,13.00,2,1,13.59,100,1,12.98,200,2,13.60,15,1,12.86,100,1,13.63,100,1,12.73,100,1,13.92,100,1,12.71,100,1,13.94,2,1,12.50,700,1,14.23,100,1,12.46,100,1,14.28,100,1,12.43,700,1,14.52,300,3,ARL,327868421
2025-07-17T16:06:22.153916169Z,2025-07-17T16:06:22.153749481Z,160,2,1108,A,A,10,13.40,0,0,13.40,23,1,13.11,100,1,13.58,15,1,13.00,2,1,13.59,100,1,12.98,200,2,13.60,15,1,12.86,100,1,13.63,100,1,12.73,100,1,13.92,100,1,12.71,100,1,13.94,2,1,12.50,700,1,14.23,100,1,12.46,100,1,14.28,100,1,12.43,700,1,14.52,300,3,ARL,331051173
2025-07-17T16:06:22.156070698Z,2025-07-17T16:06:22.155905240Z,160,2,1108,C,A,10,13.40,0,0,13.40,23,1,13.11,100,1,13.58,15,1,13.00,2,1,13.59,100,1,12.98,200,2,13.60,15,1,12.86,100,1,13.63,100,1,12.73,100,1,13.92,100,1,12.71,100,1,13.94,2,1,12.50,700,1,14.23,100,1,12.46,100,1,14.28,100,1,12.43,700,1,14.52,200,2,ARL,327869529
2025-07-17T16:06:22.156070698Z,2025-07-17T16:06:22.155905240Z,160,2,1108,A,A,10,13.40,0,0,13.40,23,1,13.11,100,1,13.58,15,1,13.00,2,1,13.59,100,1,12.98,200,2,13.60,15,1,12.86,100,1,13.63,100,1,12.73,100,1,13.92,100,1,12.71,100,1,13.94,2,1,12.50,700,1,14.23,100,1,12.46,100,1,14.28,100,1,12.43,700,1,14.38,100,1,ARL,331051369
2025-07-17T16:06:22.178044675Z,2025-07-17T16:06:22.177879233Z,160,2,1108,C,A,10,13.40,0,0,13.40,23,1,13.11,100,1,13.58,15,1,13.00,2,1,13.59,100,1,12.98,200,2,13.60,15,1,12.86,100,1,13.63,100,1,12.73,100,1,13.92,100,1,12.71,100,1,13.94,2,1,12.50,700,1,14.23,100,1,12.46,100,1,14.28,100,1,12.43,700,1,14.38,100,1,ARL,327873009
2025-07-17T16:06:22.178044675Z,2025-07-17T16:06:22.177879233Z,160,2,1108,A,A,10,13.40,0,0,13.40,23,1,13.11,100,1,13.58,15,1,13.00,2,1,13.59,100,1,12.98,200,2,13.60,15,1,12.86,100,1,13.63,100,1,12.73,100,1,13.92,100,1,12.71,100,1,13.94,2,1,12.50,700,1,14.23,100,1,12.46,100,1,14.28,100,1,12.43,700,1,14.38,100,1,ARL,331052197
2025-07-17T16:06:24.519511128Z,2025-07-17T16:06:24.519345743Z,160,2,1108,A,A,10,13.40,0,0,13.40,23,1,13.11,100,1,13.58,15,1,13.00,2,1,13.59,100,1,12.98,200,2,13.60,115,2,12.86,100,1,13.63,100,1,12.73,100,1,13.92,100,1,12.71,100,1,13.94,2,1,12.50,700,1,14.23,100,1,12.46,100,1,14.28,100,1,12.43,700,1,14.38,100,1,ARL,331104725
2025-07-17T16:06:24.526359716Z,2025-07-17T16:06:24.526194457Z,160,2,1108,C,A,10,13.40,0,0,13.40,23,1,13.11,100,1,13.58,15,1,13.00,2,1,13.59,100,1,12.98,200,2,13.60,115,2,12.86,100,1,13.92,100,1,12.73,100,1,13.94,2,1,12.71,100,1,14.23,100,1,12.50,700,1,14.28,100,1,12.46,100,1,14.38,100,1,12.43,700,1,14.52,200,2,ARL,331018065
2025-07-17T16:06:26.610345800Z,2025-07-17T16:06:26.610180184Z,160,2,1108,C,A,10,13.40,0,0,13.40,23,1,13.11,100,1,13.58,15,1,13.00,2,1,13.59,100,1,12.98,200,2,13.60,115,2,12.86,100,1,13.92,100,1,12.73,100,1,14.23,100,1,12.71,100,1,14.28,100,1,12.50,700,1,14.38,100,1,12.46,100,1,14.52,200,2,12.43,700,1,14.55,200,2,ARL,328351217
2025-07-17T16:06:26.610345800Z,2025-07-17T16:06:26.610180184Z,160,2,1108,A,A,10,13.40,0,0,13.40,23,1,13.11,100,1,13.58,15,1,13.00,2,1,13.59,100,1,12.98,200,2,13.60,115,2,12.86,100,1,13.85,2,1,12.73,100,1,13.92,100,1,12.71,100,1,14.23,100,1,12.50,700,1,14.28,100,1,12.46,100,1,14.38,100,1,12.43,700,1,14.52,200,2,ARL,331155889
2025-07-17T16:06:30.625877214Z,2025-07-17T16:06:30.625711923Z,160,2,1108,A,A,10,13.40,0,0,13.40,23,1,13.11,100,1,13.58,15,1,13.00,2,1,13.59,100,1,12.98,200,2,13.60,115,2,12.86,100,1,13.85,2,1,12.73,100,1,13.92,100,1,12.71,100,1,14.23,100,1,12.50,700,1,14.27,700,1,12.46,100,1,14.28,100,1,12.43,700,1,14.38,100,1,ARL,331257169
2025-07-17T16:06:30.625956307Z,2025-07-17T16:06:30.625790910Z,160,2,1108,C,A,10,13.40,0,0,13.40,23,1,13.11,100,1,13.58,15,1,13.00,2,1,13.59,100,1,12.98,200,2,13.60,115,2,12.86,100,1,13.85,2,1,12.73,100,1,13.92,100,1,12.71,100,1,14.23,100,1,12.50,700,1,14.27,700,1,12.46,100,1,14.28,100,1,12.43,700,1,14.38,100,1,ARL,325716945
2025-07-17T16:06:31.127827805Z,2025-07-17T16:06:31.127662311Z,160,2,1108,A,A,10,13.40,0,0,13.40,23,1,13.11,100,1,13.58,15,1,13.00,2,1,13.59,100,1,12.98,200,2,13.60,115,2,12.86,100,1,13.85,2,1,12.73,100,1,13.92,100,1,12.71,100,1,14.23,100,1,12.50,700,1,14.27,700,1,12.46,100,1,14.28,100,1,12.43,700,1,14.38,100,1,ARL,331272997
2025-07-17T16:06:31.128581831Z,2025-07-17T16:06:31.128416336Z,160,2,1108,C,A,10,13.40,0,0,13.40,23,1,13.11,100,1,13.58,15,1,13.00,2,1,13.59,100,1,12.98,200,2,13.60,115,2,12.86,100,1,13.85,2,1,12.73,100,1,13.92,100,1,12.71,100,1,14.23,100,1,12.50,700,1,14.27,700,1,12.46,100,1,14.28,100,1,12.43,700,1,14.38,100,1,ARL,289932801
2025-07-17T16:06:31.990649229Z,2025-07-17T16:06:31.990483799Z,160,2,1108,C,A,10,13.40,0,0,13.40,23,1,13.11,100,1,13.58,15,1,13.00,2,1,13.59,100,1,12.98,200,2,13.60,100,1,12.86,100,1,13.85,2,1,12.73,100,1,13.92,100,1,12.71,100,1,14.23,100,1,12.50,700,1,14.27,700,1,12.46,100,1,14.28,100,1,12.43,700,1,14.38,100,1,ARL,330788421
2025-07-17T16:06:42.812807096Z,2025-07-17T16:06:42.812641697Z,160,2,1108,A,A,10,13.40,0,0,13.40,23,1,13.11,100,1,13.56,15,1,13.00,2,1,13.58,15,1,12.98,200,2,13.59,100,1,12.86,100,1,13.60,100,1,12.73,100,1,13.85,2,1,12.71,100,1,13.92,100,1,12.50,700,1,14.23,100,1,12.46,100,1,14.27,700,1,12.43,700,1,14.28,100,1,ARL,331488089
2025-07-17T16:06:43.012965957Z,2025-07-17T16:06:43.012799164Z,160,2,1108,C,A,10,13.40,0,0,13.40,23,1,13.11,100,1,13.56,15,1,13.00,2,1,13.58,15,1,12.98,200,2,13.60,100,1,12.86,100,1,13.85,2,1,12.73,100,1,13.92,100,1,12.71,100,1,14.23,100,1,12.50,700,1,14.27,700,1,12.46,100,1,14.28,100,1,12.43,700,1,14.38,100,1,ARL,331050989
2025-07-17T16:06:43.012965957Z,2025-07-17T16:06:43.012799164Z,160,2,1108,A,A,10,13.40,0,0,13.40,23,1,13.11,100,1,13.56,15,1,13.00,2,1,13.57,100,1,12.98,200,2,13.58,15,1,12.86,100,1,13.60,100,1,12.73,100,1,13.85,2,1,12.71,100,1,13.92,100,1,12.50,700,1,14.23,100,1,12.46,100,1,14.27,700,1,12.43,700,1,14.28,100,1,ARL,331491049
2025-07-17T16:06:43.013716205Z,2025-07-17T16:06:43.013550575Z,160,2,1108,C,A,10,13.40,0,0,13.40,23,1,13.11,100,1,13.56,15,1,13.00,2,1,13.57,100,1,12.98,200,2,13.58,15,1,12.86,100,1,13.60,100,1,12.73,100,1,13.85,2,1,12.71,100,1,13.92,100,1,12.50,700,1,14.23,100,1,12.46,100,1,14.27,700,1,12.43,700,1,14.28,100,1,ARL,330789501
2025-07-17T16:06:43.013716205Z,2025-07-17T16:06:43.013550575Z,160,2,1108,A,A,10,13.40,0,0,13.40,23,1,13.11,100,1,13.56,15,1,13.00,2,1,13.57,100,1,12.98,200,2,13.58,15,1,12.86,100,1,13.60,100,1,12.73,100,1,13.85,2,1,12.71,100,1,13.92,100,1,12.50,700,1,14.23,100,1,12.46,100,1,14.27,700,1,12.43,700,1,14.28,100,1,ARL,331491077
2025-07-17T16:06:43.024656023Z,2025-07-17T16:06:43.024490355Z,160,2,1108,C,A,10,13.40,0,0,13.40,23,1,13.11,100,1,13.56,15,1,13.00,2,1,13.57,100,1,12.98,200,2,13.58,15,1,12.86,100,1,13.60,100,1,12.73,100,1,13.85,2,1,12.71,100,1,14.23,100,1,12.50,700,1,14.27,700,1,12.46,100,1,14.28,100,1,12.43,700,1,14.38,100,1,ARL,330359625
2025-07-17T16:06:43.024708304Z,2025-07-17T16:06:43.024543099Z,160,2,1108,A,A,10,13.40,0,0,13.40,23,1,13.11,100,1,13.56,15,1,13.00,2,1,13.57,100,1,12.98,200,2,13.58,15,1,12.86,100,1,13.60,100,1,12.73,100,1,13.84,100,1,12.71,100,1,13.85,2,1,12.50,700,1,14.23,100,1,12.46,100,1,14.27,700,1,12.43,700,1,14.28,100,1,ARL,331491269
2025-07-17T16:06:49.613941821Z,2025-07-17T16:06:49.613776144Z,160,2,1108,C,A,10,13.40,0,0,13.40,23,1,13.11,100,1,13.56,15,1,13.00,2,1,13.57,100,1,12.98,200,2,13.60,100,1,12.86,100,1,13.84,100,1,12.73,100,1,13.85,2,1,12.71,100,1,14.23,100,1,12.50,700,1,14.27,700,1,12.46,100,1,14.28,100,1,12.43,700,1,14.38,100,1,ARL,331050981
2025-07-17T16:06:50.618669843Z,2025-07-17T16:06:50.618504506Z,160,2,1108,A,A,10,13.40,0,0,13.40,23,1,13.11,100,1,13.54,15,1,13.00,2,1,13.56,15,1,12.98,200,2,13.57,100,1,12.86,100,1,13.60,100,1,12.73,100,1,13.84,100,1,12.71,100,1,13.85,2,1,12.50,700,1,14.23,100,1,12.46,100,1,14.27,700,1,12.43,700,1,14.28,100,1,ARL,331666961
2025-07-17T16:06:50.626438205Z,2025-07-17T16:06:50.626272828Z,160,2,1108,A,A,10,13.40,0,0,13.40,23,1,13.11,100,1,13.54,15,1,13.00,2,1,13.56,15,1,12.98,200,2,13.57,100,1,12.86,100,1,13.58,100,1,12.73,100,1,13.60,100,1,12.71,100,1,13.84,100,1,12.50,700,1,13.85,2,1,12.46,100,1,14.23,100,1,12.43,700,1,14.27,700,1,ARL,331667121
2025-07-17T16:06:50.633113557Z,2025-07-17T16:06:50.632947998Z,160,2,1108,C,A,10,13.40,0,0,13.40,23,1,13.11,100,1,13.54,15,1,13.00,2,1,13.56,15,1,12.98,200,2,13.57,100,1,12.86,100,1,13.58,100,1,12.73,100,1,13.84,100,1,12.71,100,1,13.85,2,1,12.50,700,1,14.23,100,1,12.46,100,1,14.27,700,1,12.43,700,1,14.28,100,1,ARL,331104725
2025-07-17T16:06:51.754576322Z,2025-07-17T16:06:51.754410704Z,160,2,1108,C,A,10,13.40,0,0,13.40,23,1,13.11,100,1,13.54,15,1,13.00,2,1,13.56,15,1,12.98,200,2,13.58,100,1,12.86,100,1,13.84,100,1,12.73,100,1,13.85,2,1,12.71,100,1,14.23,100,1,12.50,700,1,14.27,700,1,12.46,100,1,14.28,100,1,12.43,700,1,14.38,100,1,ARL,331491049
2025-07-17T16:06:51.754576322Z,2025-07-17T16:06:51.754410704Z,160,2,1108,A,A,10,13.40,0,0,13.40,23,1,13.11,100,1,13.54,15,1,13.00,2,1,13.55,100,1,12.98,200,2,13.56,15,1,12.86,100,1,13.58,100,1,12.73,100,1,13.84,100,1,12.71,100,1,13.85,2,1,12.50,700,1,14.23,100,1,12.46,100,1,14.27,700,1,12.43,700,1,14.28,100,1,ARL,331694265
2025-07-17T16:06:51.757403109Z,2025-07-17T16:06:51.757237300Z,160,2,1108,C,B,10,13.40,0,0,13.40,23,1,13.11,100,1,13.54,15,1,12.98,200,2,13.55,100,1,12.86,100,1,13.56,15,1,12.73,100,1,13.58,100,1,12.71,100,1,13.84,100,1,12.50,700,1,13.85,2,1,12.46,100,1,14.23,100,1,12.43,700,1,14.27,700,1,12.42,700,1,14.28,100,1,ARL,325967705
2025-07-17T16:06:51.757403109Z,2025-07-17T16:06:51.757237300Z,160,2,1108,A,B,10,13.40,0,0,13.40,23,1,13.11,100,1,13.54,15,1,12.98,200,2,13.55,100,1,12.90,2,1,13.56,15,1,12.86,100,1,13.58,100,1,12.73,100,1,13.84,100,1,12.71,100,1,13.85,2,1,12.50,700,1,14.23,100,1,12.46,100,1,14.27,700,1,12.43,700,1,14.28,100,1,ARL,331694297
2025-07-17T16:06:55.056300861Z,2025-07-17T16:06:55.056135380Z,160,2,1108,C,A,10,13.40,0,0,13.40,23,1,13.11,100,1,13.55,100,1,12.98,200,2,13.56,15,1,12.90,2,1,13.58,100,1,12.86,100,1,13.84,100,1,12.73,100,1,13.85,2,1,12.71,100,1,14.23,100,1,12.50,700,1,14.27,700,1,12.46,100,1,14.28,100,1,12.43,700,1,14.38,100,1,ARL,331666961
2025-07-17T16:06:55.056466231Z,2025-07-17T16:06:55.056301001Z,160,2,1108,C,A,10,13.40,0,0,13.40,23,1,13.11,100,1,13.55,100,1,12.98,200,2,13.58,100,1,12.90,2,1,13.84,100,1,12.86,100,1,13.85,2,1,12.73,100,1,14.23,100,1,12.71,100,1,14.27,700,1,12.50,700,1,14.28,100,1,12.46,100,1,14.38,100,1,12.43,700,1,14.48,700,1,ARL,331488089
2025-07-17T16:07:00.010995558Z,2025-07-17T16:07:00.010829521Z,160,2,1108,C,A,10,13.40,0,0,13.40,23,1,13.11,100,1,13.58,100,1,12.98,200,2,13.84,100,1,12.90,2,1,13.85,2,1,12.86,100,1,14.23,100,1,12.73,100,1,14.27,700,1,12.71,100,1,14.28,100,1,12.50,700,1,14.38,100,1,12.46,100,1,14.48,700,1,12.43,700,1,14.52,200,2,ARL,331694265
2025-07-17T16:07:00.023849180Z,2025-07-17T16:07:00.023683961Z,160,2,1108,C,A,10,13.40,0,0,13.40,23,1,13.11,100,1,13.84,100,1,12.98,200,2,13.85,2,1,12.90,2,1,14.23,100,1,12.86,100,1,14.27,700,1,12.73,100,1,14.28,100,1,12.71,100,1,14.38,100,1,12.50,700,1,14.48,700,1,12.46,100,1,14.52,200,2,12.43,700,1,14.55,200,2,ARL,331667121
2025-07-17T16:07:00.023917543Z,2025-07-17T16:07:00.023752163Z,160,2,1108,C,A,10,13.40,0,0,13.40,23,1,13.11,100,1,13.84,100,1,12.98,200,2,13.85,2,1,12.90,2,1,14.23,100,1,12.86,100,1,14.28,100,1,12.73,100,1,14.38,100,1,12.71,100,1,14.48,700,1,12.50,700,1,14.52,200,2,12.46,100,1,14.55,200,2,12.43,700,1,14.56,800,2,ARL,331257169
2025-07-17T16:07:00.023980805Z,2025-07-17T16:07:00.023815326Z,160,2,1108,A,A,10,13.40,0,0,13.40,23,1,13.11,100,1,13.84,100,1,12.98,200,2,13.85,2,1,12.90,2,1,14.23,100,1,12.86,100,1,14.28,100,1,12.73,100,1,14.38,100,1,12.71,100,1,14.48,700,1,12.50,700,1,14.51,700,1,12.46,100,1,14.52,200,2,12.43,700,1,14.55,200,2,ARL,331926981
2025-07-17T16:07:00.024590283Z,2025-07-17T16:07:00.024424816Z,160,2,1108,C,A,10,13.40,0,0,13.40,23,1,13.11,100,1,13.84,100,1,12.98,200,2,13.85,2,1,12.90,2,1,14.23,100,1,12.86,100,1,14.28,100,1,12.73,100,1,14.38,100,1,12.71,100,1,14.48,700,1,12.50,700,1,14.51,700,1,12.46,100,1,14.52,200,2,12.43,700,1,14.55,200,2,ARL,331491077
2025-07-17T16:07:00.024590283Z,2025-07-17T16:07:00.024424816Z,160,2,1108,A,A,10,13.40,0,0,13.40,23,1,13.11,100,1,13.84,100,1,12.98,200,2,13.85,2,1,12.90,2,1,14.23,100,1,12.86,100,1,14.28,100,1,12.73,100,1,14.38,100,1,12.71,100,1,14.48,700,1,12.50,700,1,14.51,700,1,12.46,100,1,14.52,200,2,12.43,700,1,14.55,200,2,ARL,331927017
2025-07-17T16:07:00.025231164Z,2025-07-17T16:07:00.025064913Z,160,2,1108,C,A,10,13.40,0,0,13.40,23,1,13.11,100,1,13.84,100,1,12.98,200,2,13.85,2,1,12.90,2,1,14.28,100,1,12.86,100,1,14.38,100,1,12.73,100,1,14.48,700,1,12.71,100,1,14.51,700,1,12.50,700,1,14.52,200,2,12.46,100,1,14.55,200,2,12.43,700,1,14.56,800,2,ARL,329074833
2025-07-17T16:07:00.025587549Z,2025-07-17T16:07:00.025422082Z,160,2,1108,A,A,10,13.40,0,0,13.40,23,1,13.11,100,1,13.84,100,1,12.98,200,2,13.85,2,1,12.90,2,1,14.28,100,1,12.86,100,1,14.38,100,1,12.73,100,1,14.46,100,1,12.71,100,1,14.48,700,1,12.50,700,1,14.51,700,1,12.46,100,1,14.52,200,2,12.43,700,1,14.55,200,2,ARL,331927161
2025-07-17T16:07:00.025793260Z,2025-07-17T16:07:00.025628157Z,160,2,1108,A,A,10,13.40,0,0,13.40,23,1,13.11,100,1,13.59,100,1,12.98,200,2,13.84,100,1,12.90,2,1,13.85,2,1,12.86,100,1,14.28,100,1,12.73,100,1,14.38,100,1,12.71,100,1,14.46,100,1,12.50,700,1,14.48,700,1,12.46,100,1,14.51,700,1,12.43,700,1,14.52,200,2,ARL,331927177
2025-07-17T16:07:00.026998695Z,2025-07-17T16:07:00.026833761Z,160,2,1108,C,A,10,13.40,0,0,13.40,23,1,13.11,100,1,13.84,100,1,12.98,200,2,13.85,2,1,12.90,2,1,14.28,100,1,12.86,100,1,14.38,100,1,12.73,100,1,14.46,100,1,12.71,100,1,14.48,700,1,12.50,700,1,14.51,700,1,12.46,100,1,14.52,200,2,12.43,700,1,14.55,200,2,ARL,331927177
2025-07-17T16:07:00.032762182Z,2025-07-17T16:07:00.032596898Z,160,2,1108,C,A,10,13.40,0,0,13.40,23,1,13.11,100,1,13.84,100,1,12.98,200,2,13.85,2,1,12.90,2,1,14.28,100,1,12.86,100,1,14.46,100,1,12.73,100,1,14.48,700,1,12.71,100,1,14.51,700,1,12.50,700,1,14.52,200,2,12.46,100,1,14.55,200,2,12.43,700,1,14.56,800,2,ARL,331051369
2025-07-17T16:07:00.032876947Z,2025-07-17T16:07:00.032711777Z,160,2,1108,A,A,10,13.40,0,0,13.40,23,1,13.11,100,1,13.84,100,1,12.98,200,2,13.85,2,1,12.90,2,1,14.28,100,1,12.86,100,1,14.46,100,1,12.73,100,1,14.48,700,1,12.71,100,1,14.51,700,1,12.50,700,1,14.52,200,2,12.46,100,1,14.55,200,2,12.43,700,1,14.56,800,2,ARL,331927477
2025-07-17T16:07:00.045525047Z,2025-07-17T16:07:00.045359807Z,160,2,1108,C,A,10,13.40,0,0,13.40,23,1,13.11,100,1,13.85,2,1,12.98,200,2,14.28,100,1,12.90,2,1,14.46,100,1,12.86,100,1,14.48,700,1,12.73,100,1,14.51,700,1,12.71,100,1,14.52,200,2,12.50,700,1,14.55,200,2,12.46,100,1,14.56,800,2,12.43,700,1,14.60,700,1,ARL,331491269
2025-07-17T16:07:00.045559272Z,2025-07-17T16:07:00.045394317Z,160,2,1108,C,A,10,13.40,0,0,13.40,23,1,13.11,100,1,13.85,2,1,12.98,200,2,14.28,100,1,12.90,2,1,14.46,100,1,12.86,100,1,14.48,700,1,12.73,100,1,14.52,200,2,12.71,100,1,14.55,200,2,12.50,700,1,14.56,800,2,12.46,100,1,14.60,700,1,12.43,700,1,14.63,100,1,ARL,331926981
2025-07-17T16:07:00.045574786Z,2025-07-17T16:07:00.045409635Z,160,2,1108,A,A,10,13.40,0,0,13.40,23,1,13.11,100,1,13.85,2,1,12.98,200,2,14.09,100,1,12.90,2,1,14.28,100,1,12.86,100,1,14.46,100,1,12.73,100,1,14.48,700,1,12.71,100,1,14.52,200,2,12.50,700,1,14.55,200,2,12.46,100,1,14.56,800,2,12.43,700,1,14.60,700,1,ARL,331927857
2025-07-17T16:07:00.046838602Z,2025-07-17T16:07:00.046672908Z,160,2,1108,C,A,10,13.40,0,0,13.40,23,1,13.11,100,1,13.85,2,1,12.98,200,2,14.28,100,1,12.90,2,1,14.46,100,1,12.86,100,1,14.48,700,1,12.73,100,1,14.52,200,2,12.71,100,1,14.55,200,2,12.50,700,1,14.56,800,2,12.46,100,1,14.60,700,1,12.43,700,1,14.63,100,1,ARL,331927857
2025-07-17T16:07:00.046887005Z,2025-07-17T16:07:00.046721624Z,160,2,1108,A,A,10,13.40,0,0,13.40,23,1,13.11,100,1,13.85,2,1,12.98,200,2,13.86,100,1,12.90,2,1,14.28,100,1,12.86,100,1,14.46,100,1,12.73,100,1,14.48,700,1,12.71,100,1,14.52,200,2,12.50,700,1,14.55,200,2,12.46,100,1,14.56,800,2,12.43,700,1,14.60,700,1,ARL,331927877
2025-07-17T16:07:00.047708936Z,2025-07-17T16:07:00.047544064Z,160,2,1108,C,A,10,13.40,0,0,13.40,23,1,13.11,100,1,13.85,2,1,12.98,200,2,14.28,100,1,12.90,2,1,14.46,100,1,12.86,100,1,14.48,700,1,12.73,100,1,14.52,200,2,12.71,100,1,14.55,200,2,12.50,700,1,14.56,800,2,12.46,100,1,14.60,700,1,12.43,700,1,14.63,100,1,ARL,331927877
2025-07-17T16:07:00.047755498Z,2025-07-17T16:07:00.047590313Z,160,2,1108,A,A,10,13.40,0,0,13.40,23,1,13.11,100,1,13.85,2,1,12.98,200,2,14.12,100,1,12.90,2,1,14.28,100,1,12.86,100,1,14.46,100,1,12.73,100,1,14.48,700,1,12.71,100,1,14.52,200,2,12.50,700,1,14.55,200,2,12.46,100,1,14.56,800,2,12.43,700,1,14.60,700,1,ARL,331927921
2025-07-17T16:07:00.053448670Z,2025-07-17T16:07:00.053283700Z,160,2,1108,C,A,10,13.40,0,0,13.40,23,1,13.11,100,1,13.85,2,1,12.98,200,2,14.28,100,1,12.90,2,1,14.46,100,1,12.86,100,1,14.48,700,1,12.73,100,1,14.52,200,2,12.71,100,1,14.55,200,2,12.50,700,1,14.56,800,2,12.46,100,1,14.60,700,1,12.43,700,1,14.63,100,1,ARL,331927921
2025-07-17T16:07:00.053495095Z,2025-07-17T16:07:00.053329959Z,160,2,1108,A,A,10,13.40,0,0,13.40,23,1,13.11,100,1,13.85,2,1,12.98,200,2,14.26,100,1,12.90,2,1,14.28,100,1,12.86,100,1,14.46,100,1,12.73,100,1,14.48,700,1,12.71,100,1,14.52,200,2,12.50,700,1,14.55,200,2,12.46,100,1,14.56,800,2,12.43,700,1,14.60,700,1,ARL,331928009
2025-07-17T16:07:00.057809857Z,2025-07-17T16:07:00.057644427Z,160,2,1108,C,A,10,13.40,0,0,13.40,23,1,13.11,100,1,13.85,2,1,12.98,200,2,14.26,100,1,12.90,2,1,14.28,100,1,12.86,100,1,14.46,100,1,12.73,100,1,14.48,700,1,12.71,100,1,14.52,200,2,12.50,700,1,14.55,100,1,12.46,100,1,14.56,800,2,12.43,700,1,14.60,700,1,ARL,331052197
2025-07-17T16:07:00.057809857Z,2025-07-17T16:07:00.057644427Z,160,2,1108,A,A,10,13.40,0,0,13.40,23,1,13.11,100,1,13.85,2,1,12.98,200,2,14.26,100,1,12.90,2,1,14.28,100,1,12.86,100,1,14.46,100,1,12.73,100,1,14.48,700,1,12.71,100,1,14.52,200,2,12.50,700,1,14.55,100,1,12.46,100,1,14.56,800,2,12.43,700,1,14.60,700,1,ARL,331928129
2025-07-17T16:07:00.070490835Z,2025-07-17T16:07:00.070325784Z,160,2,1108,C,A,10,13.40,0,0,13.40,23,1,13.11,100,1,13.85,2,1,12.98,200,2,14.28,100,1,12.90,2,1,14.46,100,1,12.86,100,1,14.48,700,1,12.73,100,1,14.52,200,2,12.71,100,1,14.55,100,1,12.50,700,1,14.56,800,2,12.46,100,1,14.60,700,1,12.43,700,1,14.63,100,1,ARL,331928009
2025-07-17T16:07:00.070539222Z,2025-07-17T16:07:00.070373975Z,160,2,1108,A,A,10,13.40,0,0,13.40,23,1,13.11,100,1,13.85,2,1,12.98,200,2,14.14,100,1,12.90,2,1,14.28,100,1,12.86,100,1,14.46,100,1,12.73,100,1,14.48,700,1,12.71,100,1,14.52,200,2,12.50,700,1,14.55,100,1,12.46,100,1,14.56,800,2,12.43,700,1,14.60,700,1,ARL,331929033
2025-07-17T16:07:00.071359350Z,2025-07-17T16:07:00.071194493Z,160,2,1108,C,A,10,13.40,0,0,13.40,23,1,13.11,100,1,13.85,2,1,12.98,200,2,14.28,100,1,12.90,2,1,14.46,100,1,12.86,100,1,14.48,700,1,12.73,100,1,14.52,200,2,12.71,100,1,14.55,100,1,12.50,700,1,14.56,800,2,12.46,100,1,14.60,700,1,12.43,700,1,14.63,100,1,ARL,331929033
2025-07-17T16:07:00.071405105Z,2025-07-17T16:07:00.071239867Z,160,2,1108,A,A,10,13.40,0,0,13.40,23,1,13.11,100,1,13.85,2,1,12.98,200,2,14.26,100,1,12.90,2,1,14.28,100,1,12.86,100,1,14.46,100,1,12.73,100,1,14.48,700,1,12.71,100,1,14.52,200,2,12.50,700,1,14.55,100,1,12.46,100,1,14.56,800,2,12.43,700,1,14.60,700,1,ARL,331929041
2025-07-17T16:07:00.074580946Z,2025-07-17T16:07:00.074415631Z,160,2,1108,C,A,10,13.40,0,0,13.40,23,1,13.11,100,1,13.85,2,1,12.98,200,2,14.26,100,1,12.90,2,1,14.28,100,1,12.86,100,1,14.46,100,1,12.73,100,1,14.48,700,1,12.71,100,1,14.52,200,2,12.50,700,1,14.55,100,1,12.46,100,1,14.56,800,2,12.43,700,1,14.60,700,1,ARL,331927017
2025-07-17T16:07:00.074580946Z,2025-07-17T16:07:00.074415631Z,160,2,1108,A,A,10,13.40,0,0,13.40,23,1,13.11,100,1,13.85,2,1,12.98,200,2,14.26,100,1,12.90,2,1,14.28,100,1,12.86,100,1,14.46,100,1,12.73,100,1,14.48,700,1,12.71,100,1,14.52,200,2,12.50,700,1,14.55,100,1,12.46,100,1,14.56,800,2,12.43,700,1,14.60,700,1,ARL,331929065
2025-07-17T16:07:00.085131263Z,2025-07-17T16:07:00.084965637Z,160,2,1108,C,A,10,13.40,0,0,13.40,23,1,13.11,100,1,13.85,2,1,12.98,200,2,14.26,100,1,12.90,2,1,14.28,100,1,12.86,100,1,14.46,100,1,12.73,100,1,14.48,700,1,12.71,100,1,14.52,200,2,12.50,700,1,14.55,100,1,12.46,100,1,14.56,800,2,12.43,700,1,14.60,700,1,ARL,326837501
2025-07-17T16:07:00.085131263Z,2025-07-17T16:07:00.084965637Z,160,2,1108,A,A,10,13.40,0,0,13.40,23,1,13.11,100,1,13.85,2,1,12.98,200,2,14.26,100,1,12.90,2,1,14.28,100,1,12.86,100,1,14.46,100,1,12.73,100,1,14.48,700,1,12.71,100,1,14.52,200,2,12.50,700,1,14.55,100,1,12.46,100,1,14.56,800,2,12.43,700,1,14.60,700,1,ARL,331929445
2025-07-17T16:07:00.090359757Z,2025-07-17T16:07:00.090194106Z,160,2,1108,C,A,10,13.40,0,0,13.40,23,1,13.11,100,1,13.85,2,1,12.98,200,2,14.26,100,1,12.90,2,1,14.28,100,1,12.86,100,1,14.46,100,1,12.73,100,1,14.48,700,1,12.71,100,1,14.52,200,2,12.50,700,1,14.56,800,2,12.46,100,1,14.60,700,1,12.43,700,1,14.63,100,1,ARL,331051173
2025-07-17T16:07:00.090359757Z,2025-07-17T16:07:00.090194106Z,160,2,1108,A,A,10,13.40,0,0,13.40,23,1,13.11,100,1,13.85,2,1,12.98,200,2,14.26,100,1,12.90,2,1,14.28,100,1,12.86,100,1,14.46,100,1,12.73,100,1,14.48,700,1,12.71,100,1,14.52,200,2,12.50,700,1,14.56,800,2,12.46,100,1,14.60,700,1,12.43,700,1,14.63,100,1,ARL,331929633
2025-07-17T16:07:00.102092147Z,2025-07-17T16:07:00.101927028Z,160,2,1108,A,A,10,13.40,0,0,13.40,23,1,13.11,100,1,13.85,2,1,12.98,200,2,14.26,100,1,12.90,2,1,14.28,100,1,12.86,100,1,14.46,100,1,12.73,100,1,14.48,700,1,12.71,100,1,14.52,200,2,12.50,700,1,14.56,800,2,12.46,100,1,14.60,700,1,12.43,700,1,14.63,100,1,ARL,331929977
2025-07-17T16:07:00.287582448Z,2025-07-17T16:07:00.287416733Z,160,2,1108,C,A,10,13.40,0,0,13.40,23,1,13.11,100,1,13.85,2,1,12.98,200,2,14.26,100,1,12.90,2,1,14.28,100,1,12.86,100,1,14.46,100,1,12.73,100,1,14.48,700,1,12.71,100,1,14.52,200,2,12.50,700,1,14.56,800,2,12.46,100,1,14.60,700,1,12.43,700,1,14.63,100,1,ARL,330789509
2025-07-17T16:07:00.287582448Z,2025-07-17T16:07:00.287416733Z,160,2,1108,A,A,10,13.40,0,0,13.40,23,1,13.11,100,1,13.85,2,1,12.98,200,2,14.26,100,1,12.90,2,1,14.28,100,1,12.86,100,1,14.46,100,1,12.73,100,1,14.48,700,1,12.71,100,1,14.52,200,2,12.50,700,1,14.56,800,2,12.46,100,1,14.60,700,1,12.43,700,1,14.63,100,1,ARL,331934277
2025-07-17T16:07:00.293620434Z,2025-07-17T16:07:00.293454856Z,160,2,1108,C,A,10,13.40,0,0,13.40,23,1,13.11,100,1,13.85,2,1,12.98,200,2,14.26,100,1,12.90,2,1,14.28,100,1,12.86,100,1,14.46,100,1,12.73,100,1,14.48,700,1,12.71,100,1,14.52,200,2,12.50,700,1,14.56,800,2,12.46,100,1,14.60,700,1,12.43,700,1,14.63,100,1,ARL,331051145
2025-07-17T16:07:00.293620434Z,2025-07-17T16:07:00.293454856Z,160,2,1108,A,A,10,13.40,0,0,13.40,23,1,13.11,100,1,13.85,2,1,12.98,200,2,14.26,100,1,12.90,2,1,14.28,100,1,12.86,100,1,14.46,100,1,12.73,100,1,14.48,700,1,12.71,100,1,14.52,200,2,12.50,700,1,14.56,800,2,12.46,100,1,14.60,700,1,12.43,700,1,14.63,100,1,ARL,331934377
2025-07-17T16:07:00.494657495Z,2025-07-17T16:07:00.494492099Z,160,2,1108,A,A,10,13.40,0,0,13.40,23,1,13.11,100,1,13.85,2,1,12.98,200,2,13.86,100,1,12.90,2,1,14.26,100,1,12.86,100,1,14.28,100,1,12.73,100,1,14.46,100,1,12.71,100,1,14.48,700,1,12.50,700,1,14.52,200,2,12.46,100,1,14.56,800,2,12.43,700,1,14.60,700,1,ARL,331942821
2025-07-17T16:07:00.495318245Z,2025-07-17T16:07:00.495152219Z,160,2,1108,C,B,10,13.40,0,0,13.40,23,1,13.11,100,1,13.85,2,1,12.98,200,2,13.86,100,1,12.90,2,1,14.26,100,1,12.86,100,1,14.28,100,1,12.73,100,1,14.46,100,1,12.71,100,1,14.48,700,1,12.50,700,1,14.52,200,2,12.46,100,1,14.56,800,2,12.43,700,1,14.60,700,1,ARL,288723817
2025-07-17T16:07:00.495318245Z,2025-07-17T16:07:00.495152219Z,160,2,1108,A,B,10,13.40,0,0,13.40,23,1,13.11,100,1,13.85,2,1,12.98,200,2,13.86,100,1,12.90,2,1,14.26,100,1,12.86,100,1,14.28,100,1,12.73,100,1,14.46,100,1,12.71,100,1,14.48,700,1,12.50,700,1,14.52,200,2,12.49,100,1,14.56,800,2,12.46,100,1,14.60,700,1,ARL,331942901
2025-07-17T16:07:00.495398644Z,2025-07-17T16:07:00.495233001Z,160,2,1108,C,A,10,13.40,0,0,13.40,23,1,13.11,100,1,13.85,2,1,12.98,200,2,13.86,100,1,12.90,2,1,14.26,100,1,12.86,100,1,14.28,100,1,12.73,100,1,14.46,100,1,12.71,100,1,14.48,700,1,12.50,700,1,14.52,200,2,12.49,100,1,14.56,800,2,12.46,100,1,14.60,700,1,ARL,331929065
2025-07-17T16:07:00.495398644Z,2025-07-17T16:07:00.495233001Z,160,2,1108,A,A,10,13.40,0,0,13.40,23,1,13.11,100,1,13.85,2,1,12.98,200,2,13.86,100,1,12.90,2,1,14.26,100,1,12.86,100,1,14.28,100,1,12.73,100,1,14.46,100,1,12.71,100,1,14.48,700,1,12.50,700,1,14.52,200,2,12.49,100,1,14.56,800,2,12.46,100,1,14.60,700,1,ARL,331942913
2025-07-17T16:07:00.495989598Z,2025-07-17T16:07:00.495823953Z,160,2,1108,C,B,10,13.40,0,0,13.40,23,1,13.11,100,1,13.85,2,1,12.98,200,2,13.86,100,1,12.90,2,1,14.26,100,1,12.86,100,1,14.28,100,1,12.73,100,1,14.46,100,1,12.71,100,1,14.48,700,1,12.50,700,1,14.52,200,2,12.49,100,1,14.56,800,2,12.46,100,1,14.60,700,1,ARL,288723813
2025-07-17T16:07:00.495989598Z,2025-07-17T16:07:00.495823953Z,160,2,1108,A,B,10,13.40,0,0,13.40,23,1,13.11,100,1,13.85,2,1,12.98,200,2,13.86,100,1,12.90,2,1,14.26,100,1,12.86,100,1,14.28,100,1,12.73,100,1,14.46,100,1,12.71,100,1,14.48,700,1,12.50,700,1,14.52,200,2,12.49,200,2,14.56,800,2,12.46,100,1,14.60,700,1,ARL,331942945
2025-07-17T16:07:00.496483460Z,2025-07-17T16:07:00.496317847Z,160,2,1108,C,A,10,13.40,0,0,13.40,23,1,13.11,100,1,13.85,2,1,12.98,200,2,13.86,100,1,12.90,2,1,14.26,100,1,12.86,100,1,14.28,100,1,12.73,100,1,14.46,100,1,12.71,100,1,14.48,700,1,12.50,700,1,14.52,200,2,12.49,200,2,14.56,800,2,12.46,100,1,14.60,700,1,ARL,331934277
2025-07-17T16:07:00.496483460Z,2025-07-17T16:07:00.496317847Z,160,2,1108,A,A,10,13.40,0,0,13.40,23,1,13.11,100,1,13.85,2,1,12.98,200,2,13.86,100,1,12.90,2,1,14.26,100,1,12.86,100,1,14.28,100,1,12.73,100,1,14.46,100,1,12.71,100,1,14.48,700,1,12.50,700,1,14.52,200,2,12.49,200,2,14.56,800,2,12.46,100,1,14.60,700,1,ARL,331942981
2025-07-17T16:07:00.499666149Z,2025-07-17T16:07:00.499501052Z,160,2,1108,C,A,10,13.40,0,0,13.40,23,1,13.11,100,1,13.85,2,1,12.98,200,2,13.86,100,1,12.90,2,1,14.28,100,1,12.86,100,1,14.46,100,1,12.73,100,1,14.48,700,1,12.71,100,1,14.52,200,2,12.50,700,1,14.56,800,2,12.49,200,2,14.60,700,1,12.46,100,1,14.63,100,1,ARL,331929041
2025-07-17T16:07:00.499714918Z,2025-07-17T16:07:00.499549738Z,160,2,1108,A,A,10,13.40,0,0,13.40,23,1,13.11,100,1,13.85,2,1,12.98,200,2,13.86,100,1,12.90,2,1,14.14,100,1,12.86,100,1,14.28,100,1,12.73,100,1,14.46,100,1,12.71,100,1,14.48,700,1,12.50,700,1,14.52,200,2,12.49,200,2,14.56,800,2,12.46,100,1,14.60,700,1,ARL,331943133
2025-07-17T16:07:22.814941809Z,2025-07-17T16:07:22.814776694Z,160,2,1108,A,A,10,13.40,0,0,13.40,23,1,13.11,100,1,13.69,15,1,12.98,200,2,13.85,2,1,12.90,2,1,13.86,100,1,12.86,100,1,14.14,100,1,12.73,100,1,14.28,100,1,12.71,100,1,14.46,100,1,12.50,700,1,14.48,700,1,12.49,200,2,14.52,200,2,12.46,100,1,14.56,800,2,ARL,332385317
2025-07-17T16:07:22.815057507Z,2025-07-17T16:07:22.814891345Z,160,2,1108,C,A,10,13.40,0,0,13.40,23,1,13.11,100,1,13.69,15,1,12.98,200,2,13.85,2,1,12.90,2,1,14.14,100,1,12.86,100,1,14.28,100,1,12.73,100,1,14.46,100,1,12.71,100,1,14.48,700,1,12.50,700,1,14.52,200,2,12.49,200,2,14.56,800,2,12.46,100,1,14.60,700,1,ARL,331942821
2025-07-17T16:07:22.815057507Z,2025-07-17T16:07:22.814891345Z,160,2,1108,A,A,10,13.40,0,0,13.40,23,1,13.11,100,1,13.69,15,1,12.98,200,2,13.70,100,1,12.90,2,1,13.85,2,1,12.86,100,1,14.14,100,1,12.73,100,1,14.28,100,1,12.71,100,1,14.46,100,1,12.50,700,1,14.48,700,1,12.49,200,2,14.52,200,2,12.46,100,1,14.56,800,2,ARL,332385325
2025-07-17T16:07:22.815790890Z,2025-07-17T16:07:22.815625345Z,160,2,1108,C,A,10,13.40,0,0,13.40,23,1,13.11,100,1,13.69,15,1,12.98,200,2,13.70,100,1,12.90,2,1,13.85,2,1,12.86,100,1,14.14,100,1,12.73,100,1,14.28,100,1,12.71,100,1,14.46,100,1,12.50,700,1,14.48,700,1,12.49,200,2,14.52,200,2,12.46,100,1,14.56,800,2,ARL,331942913
2025-07-17T16:07:22.815790890Z,2025-07-17T16:07:22.815625345Z,160,2,1108,A,A,10,13.40,0,0,13.40,23,1,13.11,100,1,13.69,15,1,12.98,200,2,13.70,100,1,12.90,2,1,13.85,2,1,12.86,100,1,14.14,100,1,12.73,100,1,14.28,100,1,12.71,100,1,14.46,100,1,12.50,700,1,14.48,700,1,12.49,200,2,14.52,200,2,12.46,100,1,14.56,800,2,ARL,332385501
2025-07-17T16:07:22.817507809Z,2025-07-17T16:07:22.817341789Z,160,2,1108,C,A,10,13.40,0,0,13.40,23,1,13.11,100,1,13.69,15,1,12.98,200,2,13.70,100,1,12.90,2,1,13.85,2,1,12.86,100,1,14.14,100,1,12.73,100,1,14.28,100,1,12.71,100,1,14.46,100,1,12.50,700,1,14.48,700,1,12.49,200,2,14.52,200,2,12.46,100,1,14.56,800,2,ARL,331929633
2025-07-17T16:07:22.817507809Z,2025-07-17T16:07:22.817341789Z,160,2,1108,A,A,10,13.40,0,0,13.40,23,1,13.11,100,1,13.69,15,1,12.98,200,2,13.70,100,1,12.90,2,1,13.85,2,1,12.86,100,1,14.14,100,1,12.73,100,1,14.28,100,1,12.71,100,1,14.46,100,1,12.50,700,1,14.48,700,1,12.49,200,2,14.52,200,2,12.46,100,1,14.56,800,2,ARL,332385565
2025-07-17T16:07:22.817624699Z,2025-07-17T16:07:22.817459170Z,160,2,1108,C,A,10,13.40,0,0,13.40,23,1,13.11,100,1,13.69,15,1,12.98,200,2,13.70,100,1,12.90,2,1,13.85,2,1,12.86,100,1,14.14,100,1,12.73,100,1,14.28,100,1,12.71,100,1,14.46,100,1,12.50,700,1,14.48,700,1,12.49,200,2,14.52,200,2,12.46,100,1,14.56,800,2,ARL,331929445
2025-07-17T16:07:22.817624699Z,2025-07-17T16:07:22.817459170Z,160,2,1108,A,A,10,13.40,0,0,13.40,23,1,13.11,100,1,13.69,15,1,12.98,200,2,13.70,100,1,12.90,2,1,13.85,2,1,12.86,100,1,14.14,100,1,12.73,100,1,14.28,100,1,12.71,100,1,14.46,100,1,12.50,700,1,14.48,700,1,12.49,200,2,14.52,200,2,12.46,100,1,14.56,800,2,ARL,332385569
2025-07-17T16:07:22.818565766Z,2025-07-17T16:07:22.818400003Z,160,2,1108,C,A,10,13.40,0,0,13.40,23,1,13.11,100,1,13.69,15,1,12.98,200,2,13.70,100,1,12.90,2,1,13.85,2,1,12.86,100,1,14.14,100,1,12.73,100,1,14.28,100,1,12.71,100,1,14.46,100,1,12.50,700,1,14.48,700,1,12.49,200,2,14.52,200,2,12.46,100,1,14.56,800,2,ARL,331934377
2025-07-17T16:07:22.818565766Z,2025-07-17T16:07:22.818400003Z,160,2,1108,A,A,10,13.40,0,0,13.40,23,1,13.11,100,1,13.69,15,1,12.98,200,2,13.70,100,1,12.90,2,1,13.85,2,1,12.86,100,1,14.14,100,1,12.73,100,1,14.28,100,1,12.71,100,1,14.46,100,1,12.50,700,1,14.48,700,1,12.49,200,2,14.52,200,2,12.46,100,1,14.56,800,2,ARL,332385585
2025-07-17T16:07:22.819710983Z,2025-07-17T16:07:22.819545360Z,160,2,1108,C,A,10,13.40,0,0,13.40,23,1,13.11,100,1,13.69,15,1,12.98,200,2,13.70,100,1,12.90,2,1,13.85,2,1,12.86,100,1,14.14,100,1,12.73,100,1,14.28,100,1,12.71,100,1,14.46,100,1,12.50,700,1,14.48,700,1,12.49,200,2,14.52,200,2,12.46,100,1,14.56,800,2,ARL,331942981
2025-07-17T16:07:22.819710983Z,2025-07-17T16:07:22.819545360Z,160,2,1108,A,A,10,13.40,0,0,13.40,23,1,13.11,100,1,13.69,15,1,12.98,200,2,13.70,100,1,12.90,2,1,13.85,2,1,12.86,100,1,14.14,100,1,12.73,100,1,14.28,100,1,12.71,100,1,14.46,100,1,12.50,700,1,14.48,700,1,12.49,200,2,14.52,200,2,12.46,100,1,14.56,800,2,ARL,332385593
2025-07-17T16:07:22.819772408Z,2025-07-17T16:07:22.819606945Z,160,2,1108,C,A,10,13.40,0,0,13.40,23,1,13.11,100,1,13.69,15,1,12.98,200,2,13.70,100,1,12.90,2,1,13.85,2,1,12.86,100,1,14.14,100,1,12.73,100,1,14.28,100,1,12.71,100,1,14.46,100,1,12.50,700,1,14.48,700,1,12.49,200,2,14.52,200,2,12.46,100,1,14.56,800,2,ARL,331927477
2025-07-17T16:07:22.819772408Z,2025-07-17T16:07:22.819606945Z,160,2,1108,A,A,10,13.40,0,0,13.40,23,1,13.11,100,1,13.69,15,1,12.98,200,2,13.70,100,1,12.90,2,1,13.85,2,1,12.86,100,1,14.14,100,1,12.73,100,1,14.28,100,1,12.71,100,1,14.46,100,1,12.50,700,1,14.48,700,1,12.49,200,2,14.49,100,1,12.46,100,1,14.52,200,2,ARL,332385597
2025-07-17T16:07:22.821165451Z,2025-07-17T16:07:22.821000003Z,160,2,1108,C,A,10,13.40,0,0,13.40,23,1,13.11,100,1,13.69,15,1,12.98,200,2,13.70,100,1,12.90,2,1,13.85,2,1,12.86,100,1,14.28,100,1,12.73,100,1,14.46,100,1,12.71,100,1,14.48,700,1,12.50,700,1,14.49,100,1,12.49,200,2,14.52,200,2,12.46,100,1,14.56,800,2,ARL,331943133
2025-07-17T16:07:22.821218207Z,2025-07-17T16:07:22.821052982Z,160,2,1108,A,A,10,13.40,0,0,13.40,23,1,13.11,100,1,13.69,15,1,12.98,200,2,13.70,100,1,12.90,2,1,13.85,2,1,12.86,100,1,13.97,100,1,12.73,100,1,14.28,100,1,12.71,100,1,14.46,100,1,12.50,700,1,14.48,700,1,12.49,200,2,14.49,100,1,12.46,100,1,14.52,200,2,ARL,332385613
2025-07-17T16:07:22.832119220Z,2025-07-17T16:07:22.831949887Z,160,2,1108,C,A,10,13.40,0,0,13.40,23,1,13.11,100,1,13.69,15,1,12.98,200,2,13.70,100,1,12.90,2,1,13.85,2,1,12.86,100,1,13.97,100,1,12.73,100,1,14.28,100,1,12.71,100,1,14.46,100,1,12.50,700,1,14.48,700,1,12.49,200,2,14.49,100,1,12.46,100,1,14.52,200,2,ARL,331928129
2025-07-17T16:07:22.832119220Z,2025-07-17T16:07:22.831949887Z,160,2,1108,A,A,10,13.40,0,0,13.40,23,1,13.11,100,1,13.69,15,1,12.98,200,2,13.70,100,1,12.90,2,1,13.85,2,1,12.86,100,1,13.97,100,1,12.73,100,1,14.28,100,1,12.71,100,1,14.46,100,1,12.50,700,1,14.48,700,1,12.49,200,2,14.49,100,1,12.46,100,1,14.52,200,2,ARL,332386121
2025-07-17T16:07:28.273823608Z,2025-07-17T16:07:28.273658191Z,160,2,1108,C,A,10,13.40,0,0,13.40,23,1,13.11,100,1,13.70,100,1,12.98,200,2,13.85,2,1,12.90,2,1,13.97,100,1,12.86,100,1,14.28,100,1,12.73,100,1,14.46,100,1,12.71,100,1,14.48,700,1,12.50,700,1,14.49,100,1,12.49,200,2,14.52,200,2,12.46,100,1,14.56,800,2,ARL,332385317
2025-07-17T16:07:28.700981149Z,2025-07-17T16:07:28.700815737Z,160,2,1108,C,A,10,13.40,0,0,13.40,23,1,13.11,100,1,13.85,2,1,12.98,200,2,13.97,100,1,12.90,2,1,14.28,100,1,12.86,100,1,14.46,100,1,12.73,100,1,14.48,700,1,12.71,100,1,14.49,100,1,12.50,700,1,14.52,200,2,12.49,200,2,14.56,800,2,12.46,100,1,14.60,700,1,ARL,332385325
2025-07-17T16:07:28.701396669Z,2025-07-17T16:07:28.701230409Z,160,2,1108,C,B,10,13.40,0,0,13.40,23,1,13.11,100,1,13.85,2,1,12.98,200,2,13.97,100,1,12.86,100,1,14.28,100,1,12.73,100,1,14.46,100,1,12.71,100,1,14.48,700,1,12.50,700,1,14.49,100,1,12.49,200,2,14.52,200,2,12.46,100,1,14.56,800,2,12.43,700,1,14.60,700,1,ARL,331694297
2025-07-17T16:07:28.701396669Z,2025-07-17T16:07:28.701230409Z,160,2,1108,A,B,10,13.40,0,0,13.40,23,1,13.11,100,1,13.85,2,1,13.01,2,1,13.97,100,1,12.98,200,2,14.28,100,1,12.86,100,1,14.46,100,1,12.73,100,1,14.48,700,1,12.71,100,1,14.49,100,1,12.50,700,1,14.52,200,2,12.49,200,2,14.56,800,2,12.46,100,1,14.60,700,1,ARL,332494213
2025-07-17T16:07:28.701713232Z,2025-07-17T16:07:28.701547540Z,160,2,1108,C,A,10,13.40,0,0,13.40,23,1,13.11,100,1,13.85,2,1,13.01,2,1,13.97,100,1,12.98,200,2,14.28,100,1,12.86,100,1,14.46,100,1,12.73,100,1,14.48,700,1,12.71,100,1,14.49,100,1,12.50,700,1,14.52,200,2,12.49,200,2,14.56,800,2,12.46,100,1,14.60,700,1,ARL,332385501
2025-07-17T16:07:28.701713232Z,2025-07-17T16:07:28.701547540Z,160,2,1108,A,A,10,13.40,0,0,13.40,23,1,13.11,100,1,13.85,2,1,13.01,2,1,13.97,100,1,12.98,200,2,14.28,100,1,12.86,100,1,14.46,100,1,12.73,100,1,14.48,700,1,12.71,100,1,14.49,100,1,12.50,700,1,14.52,200,2,12.49,200,2,14.56,800,2,12.46,100,1,14.60,700,1,ARL,332494229
2025-07-17T16:07:28.702166297Z,2025-07-17T16:07:28.702000772Z,160,2,1108,C,A,10,13.40,0,0,13.40,23,1,13.11,100,1,13.85,2,1,13.01,2,1,13.97,100,1,12.98,200,2,14.28,100,1,12.86,100,1,14.46,100,1,12.73,100,1,14.48,700,1,12.71,100,1,14.49,100,1,12.50,700,1,14.52,200,2,12.49,200,2,14.56,800,2,12.46,100,1,14.60,700,1,ARL,332385585
2025-07-17T16:07:28.702166297Z,2025-07-17T16:07:28.702000772Z,160,2,1108,A,A,10,13.40,0,0,13.40,23,1,13.11,100,1,13.85,2,1,13.01,2,1,13.97,100,1,12.98,200,2,14.28,100,1,12.86,100,1,14.46,100,1,12.73,100,1,14.48,700,1,12.71,100,1,14.49,100,1,12.50,700,1,14.52,200,2,12.49,200,2,14.56,800,2,12.46,100,1,14.60,700,1,ARL,332494245
2025-07-17T16:07:28.702642020Z,2025-07-17T16:07:28.702476699Z,160,2,1108,C,A,10,13.40,0,0,13.40,23,1,13.11,100,1,13.85,2,1,13.01,2,1,13.97,100,1,12.98,200,2,14.28,100,1,12.86,100,1,14.46,100,1,12.73,100,1,14.48,700,1,12.71,100,1,14.49,100,1,12.50,700,1,14.52,200,2,12.49,200,2,14.56,800,2,12.46,100,1,14.60,700,1,ARL,332386121
2025-07-17T16:07:28.702642020Z,2025-07-17T16:07:28.702476699Z,160,2,1108,A,A,10,13.40,0,0,13.40,23,1,13.11,100,1,13.85,2,1,13.01,2,1,13.97,100,1,12.98,200,2,14.28,100,1,12.86,100,1,14.46,100,1,12.73,100,1,14.48,700,1,12.71,100,1,14.49,100,1,12.50,700,1,14.52,200,2,12.49,200,2,14.56,800,2,12.46,100,1,14.60,700,1,ARL,332494281
2025-07-17T16:07:28.703523092Z,2025-07-17T16:07:28.703357714Z,160,2,1108,C,A,10,13.40,0,0,13.40,23,1,13.11,100,1,13.85,2,1,13.01,2,1,13.97,100,1,12.98,200,2,14.28,100,1,12.86,100,1,14.46,100,1,12.73,100,1,14.48,700,1,12.71,100,1,14.49,100,1,12.50,700,1,14.52,200,2,12.49,200,2,14.56,800,2,12.46,100,1,14.60,700,1,ARL,332385565
2025-07-17T16:07:28.703523092Z,2025-07-17T16:07:28.703357714Z,160,2,1108,A,A,10,13.40,0,0,13.40,23,1,13.11,100,1,13.85,2,1,13.01,2,1,13.97,100,1,12.98,200,2,14.28,100,1,12.86,100,1,14.46,100,1,12.73,100,1,14.48,700,1,12.71,100,1,14.49,100,1,12.50,700,1,14.52,200,2,12.49,200,2,14.56,800,2,12.46,100,1,14.60,700,1,ARL,332494285
2025-07-17T16:07:28.703920336Z,2025-07-17T16:07:28.703754662Z,160,2,1108,C,A,10,13.40,0,0,13.40,23,1,13.11,100,1,13.85,2,1,13.01,2,1,13.97,100,1,12.98,200,2,14.28,100,1,12.86,100,1,14.46,100,1,12.73,100,1,14.48,700,1,12.71,100,1,14.49,100,1,12.50,700,1,14.52,200,2,12.49,200,2,14.56,800,2,12.46,100,1,14.60,700,1,ARL,332385569
2025-07-17T16:07:28.703920336Z,2025-07-17T16:07:28.703754662Z,160,2,1108,A,A,10,13.40,0,0,13.40,23,1,13.11,100,1,13.85,2,1,13.01,2,1,13.97,100,1,12.98,200,2,14.28,100,1,12.86,100,1,14.46,100,1,12.73,100,1,14.48,700,1,12.71,100,1,14.49,100,1,12.50,700,1,14.52,200,2,12.49,200,2,14.56,800,2,12.46,100,1,14.60,700,1,ARL,332494289
2025-07-17T16:07:28.704198103Z,2025-07-17T16:07:28.704032725Z,160,2,1108,C,A,10,13.40,0,0,13.40,23,1,13.11,100,1,13.85,2,1,13.01,2,1,13.97,100,1,12.98,200,2,14.28,100,1,12.86,100,1,14.46,100,1,12.73,100,1,14.48,700,1,12.71,100,1,14.49,100,1,12.50,700,1,14.52,200,2,12.49,200,2,14.56,800,2,12.46,100,1,14.60,700,1,ARL,332385593
2025-07-17T16:07:28.704198103Z,2025-07-17T16:07:28.704032725Z,160,2,1108,A,A,10,13.40,0,0,13.40,23,1,13.11,100,1,13.85,2,1,13.01,2,1,13.97,100,1,12.98,200,2,14.28,100,1,12.86,100,1,14.46,100,1,12.73,100,1,14.48,700,1,12.71,100,1,14.49,100,1,12.50,700,1,14.52,200,2,12.49,200,2,14.56,800,2,12.46,100,1,14.60,700,1,ARL,332494297
2025-07-17T16:07:28.724201840Z,2025-07-17T16:07:28.724036175Z,160,2,1108,C,A,10,13.40,0,0,13.40,23,1,13.11,100,1,13.85,2,1,13.01,2,1,14.28,100,1,12.98,200,2,14.46,100,1,12.86,100,1,14.48,700,1,12.73,100,1,14.49,100,1,12.71,100,1,14.52,200,2,12.50,700,1,14.56,800,2,12.49,200,2,14.60,700,1,12.46,100,1,14.68,700,1,ARL,332385613
2025-07-17T16:07:28.724250835Z,2025-07-17T16:07:28.724085453Z,160,2,1108,A,A,10,13.40,0,0,13.40,23,1,13.11,100,1,13.85,2,1,13.01,2,1,14.20,100,1,12.98,200,2,14.28,100,1,12.86,100,1,14.46,100,1,12.73,100,1,14.48,700,1,12.71,100,1,14.49,100,1,12.50,700,1,14.52,200,2,12.49,200,2,14.56,800,2,12.46,100,1,14.60,700,1,ARL,332494893
2025-07-17T16:07:28.751828120Z,2025-07-17T16:07:28.751662660Z,160,2,1108,C,A,10,13.40,0,0,13.40,23,1,13.11,100,1,13.85,2,1,13.01,2,1,14.20,100,1,12.98,200,2,14.28,100,1,12.86,100,1,14.46,100,1,12.73,100,1,14.48,700,1,12.71,100,1,14.49,100,1,12.50,700,1,14.52,200,2,12.49,200,2,14.56,800,2,12.46,100,1,14.60,700,1,ARL,332494229
2025-07-17T16:07:28.751828120Z,2025-07-17T16:07:28.751662660Z,160,2,1108,A,A,10,13.40,0,0,13.40,23,1,13.11,100,1,13.85,2,1,13.01,2,1,14.20,100,1,12.98,200,2,14.28,100,1,12.86,100,1,14.46,100,1,12.73,100,1,14.48,700,1,12.71,100,1,14.49,100,1,12.50,700,1,14.52,200,2,12.49,200,2,14.56,800,2,12.46,100,1,14.60,700,1,ARL,332495781
2025-07-17T16:07:28.831160987Z,2025-07-17T16:07:28.830995364Z,160,2,1108,C,A,10,13.40,0,0,13.40,23,1,13.11,100,1,13.85,2,1,13.01,2,1,14.20,100,1,12.98,200,2,14.28,100,1,12.86,100,1,14.46,100,1,12.73,100,1,14.48,700,1,12.71,100,1,14.52,200,2,12.50,700,1,14.56,800,2,12.49,200,2,14.60,700,1,12.46,100,1,14.68,700,1,ARL,332385597
2025-07-17T16:07:28.831291377Z,2025-07-17T16:07:28.831125667Z,160,2,1108,A,A,10,13.40,0,0,13.40,23,1,13.11,100,1,13.85,2,1,13.01,2,1,14.20,100,1,12.98,200,2,14.28,100,1,12.86,100,1,14.46,100,1,12.73,100,1,14.48,700,1,12.71,100,1,14.52,200,2,12.50,700,1,14.56,800,2,12.49,200,2,14.60,700,1,12.46,100,1,14.68,700,1,ARL,332497653
2025-07-17T16:07:29.214667270Z,2025-07-17T16:07:29.214500816Z,160,2,1108,A,A,10,13.40,0,0,13.40,23,1,13.11,100,1,13.85,2,1,13.01,2,1,13.86,100,1,12.98,200,2,14.20,100,1,12.86,100,1,14.28,100,1,12.73,100,1,14.46,100,1,12.71,100,1,14.48,700,1,12.50,700,1,14.52,200,2,12.49,200,2,14.56,800,2,12.46,100,1,14.60,700,1,ARL,332508813
2025-07-17T16:07:29.215458844Z,2025-07-17T16:07:29.215292291Z,160,2,1108,C,A,10,13.40,0,0,13.40,23,1,13.11,100,1,13.85,2,1,13.01,2,1,13.86,100,1,12.98,200,2,14.20,100,1,12.86,100,1,14.28,100,1,12.73,100,1,14.46,100,1,12.71,100,1,14.48,700,1,12.50,700,1,14.52,200,2,12.49,200,2,14.56,800,2,12.46,100,1,14.60,700,1,ARL,332495781
2025-07-17T16:07:29.215458844Z,2025-07-17T16:07:29.215292291Z,160,2,1108,A,A,10,13.40,0,0,13.40,23,1,13.11,100,1,13.85,2,1,13.01,2,1,13.86,100,1,12.98,200,2,14.20,100,1,12.86,100,1,14.28,100,1,12.73,100,1,14.46,100,1,12.71,100,1,14.48,700,1,12.50,700,1,14.52,200,2,12.49,200,2,14.56,800,2,12.46,100,1,14.60,700,1,ARL,332508997
2025-07-17T16:08:20.816252850Z,2025-07-17T16:08:20.816087447Z,160,2,1108,A,A,10,13.40,0,0,13.40,23,1,13.11,100,1,13.68,15,1,13.01,2,1,13.85,2,1,12.98,200,2,13.86,100,1,12.86,100,1,14.20,100,1,12.73,100,1,14.28,100,1,12.71,100,1,14.46,100,1,12.50,700,1,14.48,700,1,12.49,200,2,14.52,200,2,12.46,100,1,14.56,800,2,ARL,333436357
2025-07-17T16:08:20.816366205Z,2025-07-17T16:08:20.816200644Z,160,2,1108,C,A,10,13.40,0,0,13.40,23,1,13.11,100,1,13.68,15,1,13.01,2,1,13.85,2,1,12.98,200,2,14.20,100,1,12.86,100,1,14.28,100,1,12.73,100,1,14.46,100,1,12.71,100,1,14.48,700,1,12.50,700,1,14.52,200,2,12.49,200,2,14.56,800,2,12.46,100,1,14.60,700,1,ARL,332508813
2025-07-17T16:08:20.816366205Z,2025-07-17T16:08:20.816200644Z,160,2,1108,A,A,10,13.40,0,0,13.40,23,1,13.11,100,1,13.68,15,1,13.01,2,1,13.69,100,1,12.98,200,2,13.85,2,1,12.86,100,1,14.20,100,1,12.73,100,1,14.28,100,1,12.71,100,1,14.46,100,1,12.50,700,1,14.48,700,1,12.49,200,2,14.52,200,2,12.46,100,1,14.56,800,2,ARL,333436361
2025-07-17T16:08:20.817097587Z,2025-07-17T16:08:20.816932150Z,160,2,1108,C,A,10,13.40,0,0,13.40,23,1,13.11,100,1,13.68,15,1,13.01,2,1,13.69,100,1,12.98,200,2,13.85,2,1,12.86,100,1,14.20,100,1,12.73,100,1,14.28,100,1,12.71,100,1,14.46,100,1,12.50,700,1,14.48,700,1,12.49,200,2,14.52,200,2,12.46,100,1,14.56,800,2,ARL,332508997
2025-07-17T16:08:20.817097587Z,2025-07-17T16:08:20.816932150Z,160,2,1108,A,A,10,13.40,0,0,13.40,23,1,13.11,100,1,13.68,15,1,13.01,2,1,13.69,100,1,12.98,200,2,13.85,2,1,12.86,100,1,14.20,100,1,12.73,100,1,14.28,100,1,12.71,100,1,14.46,100,1,12.50,700,1,14.48,700,1,12.49,200,2,14.52,200,2,12.46,100,1,14.56,800,2,ARL,333436397
2025-07-17T16:08:20.818725102Z,2025-07-17T16:08:20.818559377Z,160,2,1108,C,A,10,13.40,0,0,13.40,23,1,13.11,100,1,13.68,15,1,13.01,2,1,13.69,100,1,12.98,200,2,13.85,2,1,12.86,100,1,14.20,100,1,12.73,100,1,14.28,100,1,12.71,100,1,14.46,100,1,12.50,700,1,14.48,700,1,12.49,200,2,14.52,200,2,12.46,100,1,14.56,800,2,ARL,332494289
2025-07-17T16:08:20.818725102Z,2025-07-17T16:08:20.818559377Z,160,2,1108,A,A,10,13.40,0,0,13.40,23,1,13.11,100,1,13.68,15,1,13.01,2,1,13.69,100,1,12.98,200,2,13.85,2,1,12.86,100,1,14.20,100,1,12.73,100,1,14.28,100,1,12.71,100,1,14.46,100,1,12.50,700,1,14.48,700,1,12.49,200,2,14.52,200,2,12.46,100,1,14.56,800,2,ARL,333436421
2025-07-17T16:08:20.819130820Z,2025-07-17T16:08:20.818965359Z,160,2,1108,C,A,10,13.40,0,0,13.40,23,1,13.11,100,1,13.68,15,1,13.01,2,1,13.69,100,1,12.98,200,2,13.85,2,1,12.86,100,1,14.20,100,1,12.73,100,1,14.28,100,1,12.71,100,1,14.46,100,1,12.50,700,1,14.48,700,1,12.49,200,2,14.52,200,2,12.46,100,1,14.56,800,2,ARL,332494285
2025-07-17T16:08:20.819130820Z,2025-07-17T16:08:20.818965359Z,160,2,1108,A,A,10,13.40,0,0,13.40,23,1,13.11,100,1,13.68,15,1,13.01,2,1,13.69,100,1,12.98,200,2,13.85,2,1,12.86,100,1,14.20,100,1,12.73,100,1,14.28,100,1,12.71,100,1,14.46,100,1,12.50,700,1,14.48,700,1,12.49,200,2,14.52,200,2,12.46,100,1,14.56,800,2,ARL,333436425
2025-07-17T16:08:20.819767091Z,2025-07-17T16:08:20.819601669Z,160,2,1108,C,A,10,13.40,0,0,13.40,23,1,13.11,100,1,13.68,15,1,13.01,2,1,13.69,100,1,12.98,200,2,13.85,2,1,12.86,100,1,14.20,100,1,12.73,100,1,14.28,100,1,12.71,100,1,14.46,100,1,12.50,700,1,14.48,700,1,12.49,200,2,14.52,200,2,12.46,100,1,14.56,800,2,ARL,332494297
2025-07-17T16:08:20.819767091Z,2025-07-17T16:08:20.819601669Z,160,2,1108,A,A,10,13.40,0,0,13.40,23,1,13.11,100,1,13.68,15,1,13.01,2,1,13.69,100,1,12.98,200,2,13.85,2,1,12.86,100,1,14.20,100,1,12.73,100,1,14.28,100,1,12.71,100,1,14.46,100,1,12.50,700,1,14.48,700,1,12.49,200,2,14.52,200,2,12.46,100,1,14.56,800,2,ARL,333436441
2025-07-17T16:08:20.820666169Z,2025-07-17T16:08:20.820500575Z,160,2,1108,C,A,10,13.40,0,0,13.40,23,1,13.11,100,1,13.68,15,1,13.01,2,1,13.69,100,1,12.98,200,2,13.85,2,1,12.86,100,1,14.20,100,1,12.73,100,1,14.28,100,1,12.71,100,1,14.46,100,1,12.50,700,1,14.48,700,1,12.49,200,2,14.52,200,2,12.46,100,1,14.56,800,2,ARL,332494245
2025-07-17T16:08:20.820666169Z,2025-07-17T16:08:20.820500575Z,160,2,1108,A,A,10,13.40,0,0,13.40,23,1,13.11,100,1,13.68,15,1,13.01,2,1,13.69,100,1,12.98,200,2,13.85,2,1,12.86,100,1,14.20,100,1,12.73,100,1,14.28,100,1,12.71,100,1,14.46,100,1,12.50,700,1,14.48,700,1,12.49,200,2,14.52,200,2,12.46,100,1,14.56,800,2,ARL,333436449
2025-07-17T16:08:20.822089544Z,2025-07-17T16:08:20.821924168Z,160,2,1108,C,A,10,13.40,0,0,13.40,23,1,13.11,100,1,13.68,15,1,13.01,2,1,13.69,100,1,12.98,200,2,13.85,2,1,12.86,100,1,14.28,100,1,12.73,100,1,14.46,100,1,12.71,100,1,14.48,700,1,12.50,700,1,14.52,200,2,12.49,200,2,14.56,800,2,12.46,100,1,14.60,700,1,ARL,332494893
2025-07-17T16:08:20.822139541Z,2025-07-17T16:08:20.821974299Z,160,2,1108,A,A,10,13.40,0,0,13.40,23,1,13.11,100,1,13.68,15,1,13.01,2,1,13.69,100,1,12.98,200,2,13.85,2,1,12.86,100,1,13.96,100,1,12.73,100,1,14.28,100,1,12.71,100,1,14.46,100,1,12.50,700,1,14.48,700,1,12.49,200,2,14.52,200,2,12.46,100,1,14.56,800,2,ARL,333436473
2025-07-17T16:08:20.830110499Z,2025-07-17T16:08:20.829945074Z,160,2,1108,C,A,10,13.40,0,0,13.40,23,1,13.11,100,1,13.68,15,1,13.01,2,1,13.69,100,1,12.98,200,2,13.85,2,1,12.86,100,1,13.96,100,1,12.73,100,1,14.28,100,1,12.71,100,1,14.46,100,1,12.50,700,1,14.48,700,1,12.49,200,2,14.52,200,2,12.46,100,1,14.56,800,2,ARL,332494281
2025-07-17T16:08:20.830110499Z,2025-07-17T16:08:20.829945074Z,160,2,1108,A,A,10,13.40,0,0,13.40,23,1,13.11,100,1,13.68,15,1,13.01,2,1,13.69,100,1,12.98,200,2,13.85,2,1,12.86,100,1,13.96,100,1,12.73,100,1,14.28,100,1,12.71,100,1,14.46,100,1,12.50,700,1,14.48,700,1,12.49,200,2,14.52,200,2,12.46,100,1,14.56,800,2,ARL,333436589
2025-07-17T16:08:20.966229266Z,2025-07-17T16:08:20.966063681Z,160,2,1108,C,A,10,13.40,0,0,13.40,23,1,13.11,100,1,13.68,15,1,13.01,2,1,13.69,100,1,12.98,200,2,13.85,2,1,12.86,100,1,13.96,100,1,12.73,100,1,14.28,100,1,12.71,100,1,14.46,100,1,12.50,700,1,14.48,700,1,12.49,200,2,14.52,200,2,12.46,100,1,14.56,800,2,ARL,332497653
2025-07-17T16:08:20.966229266Z,2025-07-17T16:08:20.966063681Z,160,2,1108,A,A,10,13.40,0,0,13.40,23,1,13.11,100,1,13.68,15,1,13.01,2,1,13.69,100,1,12.98,200,2,13.85,2,1,12.86,100,1,13.96,100,1,12.73,100,1,14.28,100,1,12.71,100,1,14.46,100,1,12.50,700,1,14.48,800,2,12.49,200,2,14.52,200,2,12.46,100,1,14.56,800,2,ARL,333438545
2025-07-17T16:08:22.998168186Z,2025-07-17T16:08:22.998002821Z,160,2,1108,C,A,10,13.40,0,0,13.40,23,1,13.11,100,1,13.69,100,1,13.01,2,1,13.85,2,1,12.98,200,2,13.96,100,1,12.86,100,1,14.28,100,1,12.73,100,1,14.46,100,1,12.71,100,1,14.48,800,2,12.50,700,1,14.52,200,2,12.49,200,2,14.56,800,2,12.46,100,1,14.60,700,1,ARL,333436357
2025-07-17T16:08:27.482509684Z,2025-07-17T16:08:27.482344236Z,160,2,1108,C,A,10,13.40,0,0,13.40,23,1,13.11,100,1,13.85,2,1,13.01,2,1,13.96,100,1,12.98,200,2,14.28,100,1,12.86,100,1,14.46,100,1,12.73,100,1,14.48,800,2,12.71,100,1,14.52,200,2,12.50,700,1,14.56,800,2,12.49,200,2,14.60,700,1,12.46,100,1,14.65,200,2,ARL,333436361
2025-07-17T16:08:27.483241007Z,2025-07-17T16:08:27.483075481Z,160,2,1108,C,A,10,13.40,0,0,13.40,23,1,13.11,100,1,13.85,2,1,13.01,2,1,13.96,100,1,12.98,200,2,14.28,100,1,12.86,100,1,14.46,100,1,12.73,100,1,14.48,800,2,12.71,100,1,14.52,200,2,12.50,700,1,14.56,800,2,12.49,200,2,14.60,700,1,12.46,100,1,14.65,200,2,ARL,333436397
2025-07-17T16:08:27.483241007Z,2025-07-17T16:08:27.483075481Z,160,2,1108,A,A,10,13.40,0,0,13.40,23,1,13.11,100,1,13.85,2,1,13.01,2,1,13.96,100,1,12.98,200,2,14.28,100,1,12.86,100,1,14.46,100,1,12.73,100,1,14.48,800,2,12.71,100,1,14.52,200,2,12.50,700,1,14.56,800,2,12.49,200,2,14.60,700,1,12.46,100,1,14.65,200,2,ARL,333581389
2025-07-17T16:08:27.483585892Z,2025-07-17T16:08:27.483420069Z,160,2,1108,C,A,10,13.40,0,0,13.40,23,1,13.11,100,1,13.85,2,1,13.01,2,1,13.96,100,1,12.98,200,2,14.28,100,1,12.86,100,1,14.46,100,1,12.73,100,1,14.48,800,2,12.71,100,1,14.52,100,1,12.50,700,1,14.56,800,2,12.49,200,2,14.60,700,1,12.46,100,1,14.65,200,2,ARL,328780577
2025-07-17T16:08:27.483585892Z,2025-07-17T16:08:27.483420069Z,160,2,1108,A,A,10,13.40,0,0,13.40,23,1,13.11,100,1,13.85,2,1,13.01,2,1,13.96,100,1,12.98,200,2,14.28,100,1,12.86,100,1,14.46,100,1,12.73,100,1,14.48,800,2,12.71,100,1,14.52,100,1,12.50,700,1,14.56,800,2,12.49,200,2,14.60,700,1,12.46,100,1,14.65,200,2,ARL,333581393
2025-07-17T16:08:27.484079224Z,2025-07-17T16:08:27.483913735Z,160,2,1108,C,A,10,13.40,0,0,13.40,23,1,13.11,100,1,13.85,2,1,13.01,2,1,13.96,100,1,12.98,200,2,14.28,100,1,12.86,100,1,14.46,100,1,12.73,100,1,14.48,800,2,12.71,100,1,14.52,100,1,12.50,700,1,14.56,800,2,12.49,200,2,14.60,700,1,12.46,100,1,14.65,100,1,ARL,333436589
2025-07-17T16:08:27.484079224Z,2025-07-17T16:08:27.483913735Z,160,2,1108,A,A,10,13.40,0,0,13.40,23,1,13.11,100,1,13.85,2,1,13.01,2,1,13.96,100,1,12.98,200,2,14.28,100,1,12.86,100,1,14.46,100,1,12.73,100,1,14.48,800,2,12.71,100,1,14.52,100,1,12.50,700,1,14.56,800,2,12.49,200,2,14.60,700,1,12.46,100,1,14.65,100,1,ARL,333581409
2025-07-17T16:08:27.484859188Z,2025-07-17T16:08:27.484693568Z,160,2,1108,C,A,10,13.40,0,0,13.40,23,1,13.11,100,1,13.85,2,1,13.01,2,1,13.96,100,1,12.98,200,2,14.28,100,1,12.86,100,1,14.46,100,1,12.73,100,1,14.48,800,2,12.71,100,1,14.52,100,1,12.50,700,1,14.56,800,2,12.49,200,2,14.60,700,1,12.46,100,1,14.65,100,1,ARL,333436441
2025-07-17T16:08:27.484859188Z,2025-07-17T16:08:27.484693568Z,160,2,1108,A,A,10,13.40,0,0,13.40,23,1,13.11,100,1,13.85,2,1,13.01,2,1,13.96,100,1,12.98,200,2,14.28,100,1,12.86,100,1,14.46,100,1,12.73,100,1,14.48,800,2,12.71,100,1,14.52,100,1,12.50,700,1,14.56,800,2,12.49,200,2,14.60,700,1,12.46,100,1,14.65,100,1,ARL,333581425
2025-07-17T16:08:27.484965957Z,2025-07-17T16:08:27.484800296Z,160,2,1108,C,A,10,13.40,0,0,13.40,23,1,13.11,100,1,13.85,2,1,13.01,2,1,13.96,100,1,12.98,200,2,14.28,100,1,12.86,100,1,14.46,100,1,12.73,100,1,14.48,800,2,12.71,100,1,14.52,100,1,12.50,700,1,14.56,800,2,12.49,200,2,14.60,700,1,12.46,100,1,14.68,700,1,ARL,333436425
2025-07-17T16:08:27.484965957Z,2025-07-17T16:08:27.484800296Z,160,2,1108,A,A,10,13.40,0,0,13.40,23,1,13.11,100,1,13.85,2,1,13.01,2,1,13.96,100,1,12.98,200,2,14.28,100,1,12.86,100,1,14.46,100,1,12.73,100,1,14.48,800,2,12.71,100,1,14.52,100,1,12.50,700,1,14.56,800,2,12.49,200,2,14.60,700,1,12.46,100,1,14.68,700,1,ARL,333581429
2025-07-17T16:08:27.484978859Z,2025-07-17T16:08:27.484813280Z,160,2,1108,C,A,10,13.40,0,0,13.40,23,1,13.11,100,1,13.85,2,1,13.01,2,1,13.96,100,1,12.98,200,2,14.28,100,1,12.86,100,1,14.46,100,1,12.73,100,1,14.48,800,2,12.71,100,1,14.52,100,1,12.50,700,1,14.56,800,2,12.49,200,2,14.60,700,1,12.46,100,1,14.68,700,1,ARL,333436449
2025-07-17T16:08:27.484978859Z,2025-07-17T16:08:27.484813280Z,160,2,1108,A,A,10,13.40,0,0,13.40,23,1,13.11,100,1,13.85,2,1,13.01,2,1,13.96,100,1,12.98,200,2,14.28,100,1,12.86,100,1,14.46,100,1,12.73,100,1,14.48,800,2,12.71,100,1,14.52,100,1,12.50,700,1,14.56,800,2,12.49,200,2,14.60,700,1,12.46,100,1,14.68,700,1,ARL,333581433
2025-07-17T16:08:27.485352204Z,2025-07-17T16:08:27.485186411Z,160,2,1108,C,A,10,13.40,0,0,13.40,23,1,13.11,100,1,13.85,2,1,13.01,2,1,13.96,100,1,12.98,200,2,14.28,100,1,12.86,100,1,14.46,100,1,12.73,100,1,14.48,800,2,12.71,100,1,14.52,100,1,12.50,700,1,14.56,800,2,12.49,200,2,14.60,700,1,12.46,100,1,14.68,700,1,ARL,333436421
2025-07-17T16:08:27.485352204Z,2025-07-17T16:08:27.485186411Z,160,2,1108,A,A,10,13.40,0,0,13.40,23,1,13.11,100,1,13.85,2,1,13.01,2,1,13.96,100,1,12.98,200,2,14.28,100,1,12.86,100,1,14.46,100,1,12.73,100,1,14.48,800,2,12.71,100,1,14.52,100,1,12.50,700,1,14.56,800,2,12.49,200,2,14.60,700,1,12.46,100,1,14.68,700,1,ARL,333581441
2025-07-17T16:08:27.487263276Z,2025-07-17T16:08:27.487097702Z,160,2,1108,C,A,10,13.40,0,0,13.40,23,1,13.11,100,1,13.85,2,1,13.01,2,1,13.96,100,1,12.98,200,2,14.28,100,1,12.86,100,1,14.46,100,1,12.73,100,1,14.48,800,2,12.71,100,1,14.56,800,2,12.50,700,1,14.60,700,1,12.49,200,2,14.68,700,1,12.46,100,1,14.74,100,1,ARL,328780597
2025-07-17T16:08:27.487263276Z,2025-07-17T16:08:27.487097702Z,160,2,1108,A,A,10,13.40,0,0,13.40,23,1,13.11,100,1,13.85,2,1,13.01,2,1,13.96,100,1,12.98,200,2,14.28,100,1,12.86,100,1,14.46,100,1,12.73,100,1,14.48,800,2,12.71,100,1,14.56,800,2,12.50,700,1,14.60,700,1,12.49,200,2,14.68,700,1,12.46,100,1,14.74,200,2,ARL,333581481
2025-07-17T16:08:27.492258906Z,2025-07-17T16:08:27.492093401Z,160,2,1108,C,A,10,13.40,0,0,13.40,23,1,13.11,100,1,13.85,2,1,13.01,2,1,13.96,100,1,12.98,200,2,14.28,100,1,12.86,100,1,14.46,100,1,12.73,100,1,14.48,700,1,12.71,100,1,14.56,800,2,12.50,700,1,14.60,700,1,12.49,200,2,14.68,700,1,12.46,100,1,14.74,200,2,ARL,333438545
2025-07-17T16:08:27.492385750Z,2025-07-17T16:08:27.492220454Z,160,2,1108,A,A,10,13.40,0,0,13.40,23,1,13.11,100,1,13.85,2,1,13.01,2,1,13.96,100,1,12.98,200,2,14.28,100,1,12.86,100,1,14.46,100,1,12.73,100,1,14.48,700,1,12.71,100,1,14.56,800,2,12.50,700,1,14.60,700,1,12.49,200,2,14.68,700,1,12.46,100,1,14.74,200,2,ARL,333581569
2025-07-17T16:08:27.496936122Z,2025-07-17T16:08:27.496770678Z,160,2,1108,C,A,10,13.40,0,0,13.40,23,1,13.11,100,1,13.85,2,1,13.01,2,1,14.28,100,1,12.98,200,2,14.46,100,1,12.86,100,1,14.48,700,1,12.73,100,1,14.56,800,2,12.71,100,1,14.60,700,1,12.50,700,1,14.68,700,1,12.49,200,2,14.74,200,2,12.46,100,1,14.75,100,1,ARL,333436473
2025-07-17T16:08:27.496987832Z,2025-07-17T16:08:27.496822540Z,160,2,1108,A,A,10,13.40,0,0,13.40,23,1,13.11,100,1,13.85,2,1,13.01,2,1,14.19,100,1,12.98,200,2,14.28,100,1,12.86,100,1,14.46,100,1,12.73,100,1,14.48,700,1,12.71,100,1,14.56,800,2,12.50,700,1,14.60,700,1,12.49,200,2,14.68,700,1,12.46,100,1,14.74,200,2,ARL,333581625
2025-07-17T16:08:27.501093618Z,2025-07-17T16:08:27.500928061Z,160,2,1108,C,A,10,13.40,0,0,13.40,23,1,13.11,100,1,14.19,100,1,13.01,2,1,14.28,100,1,12.98,200,2,14.46,100,1,12.86,100,1,14.48,700,1,12.73,100,1,14.56,800,2,12.71,100,1,14.60,700,1,12.50,700,1,14.68,700,1,12.49,200,2,14.74,200,2,12.46,100,1,14.75,100,1,ARL,331155889
2025-07-17T16:08:27.501093618Z,2025-07-17T16:08:27.500928061Z,160,2,1108,A,A,10,13.40,0,0,13.40,23,1,13.11,100,1,13.98,2,1,13.01,2,1,14.19,100,1,12.98,200,2,14.28,100,1,12.86,100,1,14.46,100,1,12.73,100,1,14.48,700,1,12.71,100,1,14.56,800,2,12.50,700,1,14.60,700,1,12.49,200,2,14.68,700,1,12.46,100,1,14.74,200,2,ARL,333581677
2025-07-17T16:08:27.516614373Z,2025-07-17T16:08:27.516449334Z,160,2,1108,C,A,10,13.40,0,0,13.40,23,1,13.11,100,1,13.98,2,1,13.01,2,1,14.28,100,1,12.98,200,2,14.46,100,1,12.86,100,1,14.48,700,1,12.73,100,1,14.56,800,2,12.71,100,1,14.60,700,1,12.50,700,1,14.68,700,1,12.49,200,2,14.74,200,2,12.46,100,1,14.75,100,1,ARL,333581625
2025-07-17T16:08:27.516662099Z,2025-07-17T16:08:27.516496962Z,160,2,1108,A,A,10,13.40,0,0,13.40,23,1,13.11,100,1,13.98,2,1,13.01,2,1,14.26,100,1,12.98,200,2,14.28,100,1,12.86,100,1,14.46,100,1,12.73,100,1,14.48,700,1,12.71,100,1,14.56,800,2,12.50,700,1,14.60,700,1,12.49,200,2,14.68,700,1,12.46,100,1,14.74,200,2,ARL,333581765
2025-07-17T16:08:27.533938450Z,2025-07-17T16:08:27.533773259Z,160,2,1108,C,A,10,13.40,0,0,13.40,23,1,13.11,100,1,13.98,2,1,13.01,2,1,14.26,100,1,12.98,200,2,14.28,100,1,12.86,100,1,14.46,100,1,12.73,100,1,14.48,700,1,12.71,100,1,14.56,800,2,12.50,700,1,14.60,700,1,12.49,200,2,14.68,700,1,12.46,100,1,14.74,200,2,ARL,333581389
2025-07-17T16:08:27.533938450Z,2025-07-17T16:08:27.533773259Z,160,2,1108,A,A,10,13.40,0,0,13.40,23,1,13.11,100,1,13.98,2,1,13.01,2,1,14.26,100,1,12.98,200,2,14.28,100,1,12.86,100,1,14.46,100,1,12.73,100,1,14.48,700,1,12.71,100,1,14.56,800,2,12.50,700,1,14.60,700,1,12.49,200,2,14.68,700,1,12.46,100,1,14.74,200,2,ARL,333581845
2025-07-17T16:08:27.987678739Z,2025-07-17T16:08:27.987513451Z,160,2,1108,A,A,10,13.40,0,0,13.40,23,1,13.11,100,1,13.98,2,1,13.01,2,1,13.99,100,1,12.98,200,2,14.26,100,1,12.86,100,1,14.28,100,1,12.73,100,1,14.46,100,1,12.71,100,1,14.48,700,1,12.50,700,1,14.56,800,2,12.49,200,2,14.60,700,1,12.46,100,1,14.68,700,1,ARL,333590057
2025-07-17T16:08:58.024979382Z,2025-07-17T16:08:58.024814068Z,160,2,1108,A,A,10,13.40,0,0,13.40,23,1,13.11,100,1,13.81,15,1,13.01,2,1,13.98,2,1,12.98,200,2,13.99,100,1,12.86,100,1,14.26,100,1,12.73,100,1,14.28,100,1,12.71,100,1,14.46,100,1,12.50,700,1,14.48,700,1,12.49,200,2,14.56,800,2,12.46,100,1,14.60,700,1,ARL,334141429
2025-07-17T16:09:00.222675234Z,2025-07-17T16:09:00.222509491Z,160,2,1108,C,A,10,13.40,0,0,13.40,23,1,13.11,100,1,13.81,15,1,13.01,2,1,13.98,2,1,12.98,200,2,14.26,100,1,12.86,100,1,14.28,100,1,12.73,100,1,14.46,100,1,12.71,100,1,14.48,700,1,12.50,700,1,14.56,800,2,12.49,200,2,14.60,700,1,12.46,100,1,14.68,700,1,ARL,333590057
2025-07-17T16:09:00.222675234Z,2025-07-17T16:09:00.222509491Z,160,2,1108,A,A,10,13.40,0,0,13.40,23,1,13.11,100,1,13.81,15,1,13.01,2,1,13.82,100,1,12.98,200,2,13.98,2,1,12.86,100,1,14.26,100,1,12.73,100,1,14.28,100,1,12.71,100,1,14.46,100,1,12.50,700,1,14.48,700,1,12.49,200,2,14.56,800,2,12.46,100,1,14.60,700,1,ARL,334189729
2025-07-17T16:09:00.223436757Z,2025-07-17T16:09:00.223269382Z,160,2,1108,C,A,10,13.40,0,0,13.40,23,1,13.11,100,1,13.81,15,1,13.01,2,1,13.82,100,1,12.98,200,2,13.98,2,1,12.86,100,1,14.26,100,1,12.73,100,1,14.28,100,1,12.71,100,1,14.46,100,1,12.50,700,1,14.48,700,1,12.49,200,2,14.56,800,2,12.46,100,1,14.60,700,1,ARL,333581845
2025-07-17T16:09:00.223436757Z,2025-07-17T16:09:00.223269382Z,160,2,1108,A,A,10,13.40,0,0,13.40,23,1,13.11,100,1,13.81,15,1,13.01,2,1,13.82,100,1,12.98,200,2,13.98,2,1,12.86,100,1,14.26,100,1,12.73,100,1,14.28,100,1,12.71,100,1,14.46,100,1,12.50,700,1,14.48,700,1,12.49,200,2,14.56,800,2,12.46,100,1,14.60,700,1,ARL,334189777
2025-07-17T16:09:00.226504346Z,2025-07-17T16:09:00.226338384Z,160,2,1108,C,A,10,13.40,0,0,13.40,23,1,13.11,100,1,13.81,15,1,13.01,2,1,13.82,100,1,12.98,200,2,13.98,2,1,12.86,100,1,14.26,100,1,12.73,100,1,14.28,100,1,12.71,100,1,14.46,100,1,12.50,700,1,14.48,700,1,12.49,200,2,14.56,800,2,12.46,100,1,14.60,700,1,ARL,333581569
2025-07-17T16:09:00.226504346Z,2025-07-17T16:09:00.226338384Z,160,2,1108,A,A,10,13.40,0,0,13.40,23,1,13.11,100,1,13.81,15,1,13.01,2,1,13.82,100,1,12.98,200,2,13.98,2,1,12.86,100,1,14.26,100,1,12.73,100,1,14.28,100,1,12.71,100,1,14.46,100,1,12.50,700,1,14.48,700,1,12.49,200,2,14.56,800,2,12.46,100,1,14.60,700,1,ARL,334190189
2025-07-17T16:09:00.227929061Z,2025-07-17T16:09:00.227763275Z,160,2,1108,C,A,10,13.40,0,0,13.40,23,1,13.11,100,1,13.81,15,1,13.01,2,1,13.82,100,1,12.98,200,2,13.98,2,1,12.86,100,1,14.28,100,1,12.73,100,1,14.46,100,1,12.71,100,1,14.48,700,1,12.50,700,1,14.56,800,2,12.49,200,2,14.60,700,1,12.46,100,1,14.61,100,1,ARL,333581765
2025-07-17T16:09:00.227983483Z,2025-07-17T16:09:00.227818153Z,160,2,1108,A,A,10,13.40,0,0,13.40,23,1,13.11,100,1,13.81,15,1,13.01,2,1,13.82,100,1,12.98,200,2,13.98,2,1,12.86,100,1,14.10,100,1,12.73,100,1,14.28,100,1,12.71,100,1,14.46,100,1,12.50,700,1,14.48,700,1,12.49,200,2,14.56,800,2,12.46,100,1,14.60,700,1,ARL,334190225
2025-07-17T16:09:00.232908882Z,2025-07-17T16:09:00.232743323Z,160,2,1108,C,A,10,13.40,0,0,13.40,23,1,13.11,100,1,13.81,15,1,13.01,2,1,13.82,100,1,12.98,200,2,13.98,2,1,12.86,100,1,14.10,100,1,12.73,100,1,14.28,100,1,12.71,100,1,14.46,100,1,12.50,700,1,14.48,700,1,12.49,200,2,14.56,800,2,12.46,100,1,14.60,700,1,ARL,333581429
2025-07-17T16:09:00.232908882Z,2025-07-17T16:09:00.232743323Z,160,2,1108,A,A,10,13.40,0,0,13.40,23,1,13.11,100,1,13.81,15,1,13.01,2,1,13.82,100,1,12.98,200,2,13.98,2,1,12.86,100,1,14.10,100,1,12.73,100,1,14.28,100,1,12.71,100,1,14.46,100,1,12.50,700,1,14.48,700,1,12.49,200,2,14.56,800,2,12.46,100,1,14.60,700,1,ARL,334190353
2025-07-17T16:09:00.326293286Z,2025-07-17T16:09:00.326127587Z,160,2,1108,C,A,10,13.40,0,0,13.40,23,1,13.11,100,1,13.81,15,1,13.01,2,1,13.82,100,1,12.98,200,2,13.98,2,1,12.86,100,1,14.10,100,1,12.73,100,1,14.28,100,1,12.71,100,1,14.46,100,1,12.50,700,1,14.48,700,1,12.49,200,2,14.56,800,2,12.46,100,1,14.60,700,1,ARL,333581425
2025-07-17T16:09:00.326293286Z,2025-07-17T16:09:00.326127587Z,160,2,1108,A,A,10,13.40,0,0,13.40,23,1,13.11,100,1,13.81,15,1,13.01,2,1,13.82,100,1,12.98,200,2,13.98,2,1,12.86,100,1,14.10,100,1,12.73,100,1,14.28,100,1,12.71,100,1,14.46,100,1,12.50,700,1,14.48,700,1,12.49,200,2,14.56,800,2,12.46,100,1,14.60,700,1,ARL,334192253
2025-07-17T16:09:00.335607827Z,2025-07-17T16:09:00.335442266Z,160,2,1108,C,A,10,13.40,0,0,13.40,23,1,13.11,100,1,13.81,15,1,13.01,2,1,13.82,100,1,12.98,200,2,13.98,2,1,12.86,100,1,14.10,100,1,12.73,100,1,14.28,100,1,12.71,100,1,14.46,100,1,12.50,700,1,14.48,700,1,12.49,200,2,14.56,800,2,12.46,100,1,14.60,700,1,ARL,333581433
2025-07-17T16:09:00.335607827Z,2025-07-17T16:09:00.335442266Z,160,2,1108,A,A,10,13.40,0,0,13.40,23,1,13.11,100,1,13.81,15,1,13.01,2,1,13.82,100,1,12.98,200,2,13.98,2,1,12.86,100,1,14.10,100,1,12.73,100,1,14.28,100,1,12.71,100,1,14.46,100,1,12.50,700,1,14.48,700,1,12.49,200,2,14.56,800,2,12.46,100,1,14.60,700,1,ARL,334192405
2025-07-17T16:09:00.695776010Z,2025-07-17T16:09:00.695610142Z,160,2,1108,C,A,10,13.40,0,0,13.40,23,1,13.11,100,1,13.81,15,1,13.01,2,1,13.82,100,1,12.98,200,2,13.98,2,1,12.86,100,1,14.10,100,1,12.73,100,1,14.28,100,1,12.71,100,1,14.46,100,1,12.50,700,1,14.48,700,1,12.49,200,2,14.56,800,2,12.46,100,1,14.60,700,1,ARL,333581409
2025-07-17T16:09:00.695776010Z,2025-07-17T16:09:00.695610142Z,160,2,1108,A,A,10,13.40,0,0,13.40,23,1,13.11,100,1,13.81,15,1,13.01,2,1,13.82,100,1,12.98,200,2,13.98,2,1,12.86,100,1,14.10,100,1,12.73,100,1,14.28,100,1,12.71,100,1,14.46,100,1,12.50,700,1,14.48,700,1,12.49,200,2,14.56,800,2,12.46,100,1,14.60,700,1,ARL,334199009
2025-07-17T16:09:08.719690693Z,2025-07-17T16:09:08.719524374Z,160,2,1108,A,A,10,13.40,0,0,13.40,23,1,13.11,100,1,13.75,15,1,13.01,2,1,13.81,15,1,12.98,200,2,13.82,100,1,12.86,100,1,13.98,2,1,12.73,100,1,14.10,100,1,12.71,100,1,14.28,100,1,12.50,700,1,14.46,100,1,12.49,200,2,14.48,700,1,12.46,100,1,14.56,800,2,ARL,334366613
2025-07-17T16:09:08.719871410Z,2025-07-17T16:09:08.719706070Z,160,2,1108,C,A,10,13.40,0,0,13.40,23,1,13.11,100,1,13.75,15,1,13.01,2,1,13.81,15,1,12.98,200,2,13.98,2,1,12.86,100,1,14.10,100,1,12.73,100,1,14.28,100,1,12.71,100,1,14.46,100,1,12.50,700,1,14.48,700,1,12.49,200,2,14.56,800,2,12.46,100,1,14.60,700,1,ARL,334189729
2025-07-17T16:09:08.719871410Z,2025-07-17T16:09:08.719706070Z,160,2,1108,A,A,10,13.40,0,0,13.40,23,1,13.11,100,1,13.75,15,1,13.01,2,1,13.76,100,1,12.98,200,2,13.81,15,1,12.86,100,1,13.98,2,1,12.73,100,1,14.10,100,1,12.71,100,1,14.28,100,1,12.50,700,1,14.46,100,1,12.49,200,2,14.48,700,1,12.46,100,1,14.56,800,2,ARL,334366617
2025-07-17T16:09:08.720607932Z,2025-07-17T16:09:08.720442245Z,160,2,1108,C,A,10,13.40,0,0,13.40,23,1,13.11,100,1,13.75,15,1,13.01,2,1,13.76,100,1,12.98,200,2,13.81,15,1,12.86,100,1,13.98,2,1,12.73,100,1,14.10,100,1,12.71,100,1,14.28,100,1,12.50,700,1,14.46,100,1,12.49,200,2,14.48,700,1,12.46,100,1,14.56,800,2,ARL,334189777
2025-07-17T16:09:08.720607932Z,2025-07-17T16:09:08.720442245Z,160,2,1108,A,A,10,13.40,0,0,13.40,23,1,13.11,100,1,13.75,15,1,13.01,2,1,13.76,100,1,12.98,200,2,13.81,15,1,12.86,100,1,13.98,2,1,12.73,100,1,14.10,100,1,12.71,100,1,14.28,100,1,12.50,700,1,14.46,100,1,12.49,200,2,14.48,700,1,12.46,100,1,14.56,800,2,ARL,334366645
2025-07-17T16:09:18.819300735Z,2025-07-17T16:09:18.819135505Z,160,2,1108,C,A,10,13.40,0,0,13.40,23,1,13.11,100,1,13.75,15,1,13.01,2,1,13.76,100,1,12.98,200,2,13.98,2,1,12.86,100,1,14.10,100,1,12.73,100,1,14.28,100,1,12.71,100,1,14.46,100,1,12.50,700,1,14.48,700,1,12.49,200,2,14.56,800,2,12.46,100,1,14.60,700,1,ARL,334141429
2025-07-17T16:09:19.927205023Z,2025-07-17T16:09:19.927039122Z,160,2,1108,A,A,10,13.40,0,0,13.40,23,1,13.11,100,1,13.73,15,1,13.01,2,1,13.75,15,1,12.98,200,2,13.76,100,1,12.86,100,1,13.98,2,1,12.73,100,1,14.10,100,1,12.71,100,1,14.28,100,1,12.50,700,1,14.46,100,1,12.49,200,2,14.48,700,1,12.46,100,1,14.56,800,2,ARL,334583329
2025-07-17T16:09:19.927910703Z,2025-07-17T16:09:19.927745104Z,160,2,1108,C,A,10,13.40,0,0,13.40,23,1,13.11,100,1,13.73,15,1,13.01,2,1,13.75,15,1,12.98,200,2,13.76,100,1,12.86,100,1,13.98,2,1,12.73,100,1,14.10,100,1,12.71,100,1,14.28,100,1,12.50,700,1,14.46,100,1,12.49,200,2,14.48,700,1,12.46,100,1,14.56,800,2,ARL,333581393
2025-07-17T16:09:19.927910703Z,2025-07-17T16:09:19.927745104Z,160,2,1108,A,A,10,13.40,0,0,13.40,23,1,13.11,100,1,13.73,15,1,13.01,2,1,13.75,15,1,12.98,200,2,13.76,100,1,12.86,100,1,13.98,2,1,12.73,100,1,14.10,100,1,12.71,100,1,14.28,100,1,12.50,700,1,14.46,100,1,12.49,200,2,14.48,700,1,12.46,100,1,14.56,800,2,ARL,334583349
2025-07-17T16:09:19.928319369Z,2025-07-17T16:09:19.928153837Z,160,2,1108,C,A,10,13.40,0,0,13.40,23,1,13.11,100,1,13.73,15,1,13.01,2,1,13.75,15,1,12.98,200,2,13.76,100,1,12.86,100,1,13.98,2,1,12.73,100,1,14.10,100,1,12.71,100,1,14.28,100,1,12.50,700,1,14.46,100,1,12.49,200,2,14.48,700,1,12.46,100,1,14.56,800,2,ARL,333581481
2025-07-17T16:09:19.928319369Z,2025-07-17T16:09:19.928153837Z,160,2,1108,A,A,10,13.40,0,0,13.40,23,1,13.11,100,1,13.73,15,1,13.01,2,1,13.75,15,1,12.98,200,2,13.76,100,1,12.86,100,1,13.98,2,1,12.73,100,1,14.10,100,1,12.71,100,1,14.28,100,1,12.50,700,1,14.46,100,1,12.49,200,2,14.48,700,1,12.46,100,1,14.56,800,2,ARL,334583361
2025-07-17T16:09:20.284861075Z,2025-07-17T16:09:20.284695585Z,160,2,1108,C,A,10,13.40,0,0,13.40,23,1,13.11,100,1,13.73,15,1,13.01,2,1,13.75,15,1,12.98,200,2,13.98,2,1,12.86,100,1,14.10,100,1,12.73,100,1,14.28,100,1,12.71,100,1,14.46,100,1,12.50,700,1,14.48,700,1,12.49,200,2,14.56,800,2,12.46,100,1,14.60,700,1,ARL,334366617
2025-07-17T16:09:20.284861075Z,2025-07-17T16:09:20.284695585Z,160,2,1108,A,A,10,13.40,0,0,13.40,23,1,13.11,100,1,13.73,15,1,13.01,2,1,13.74,100,1,12.98,200,2,13.75,15,1,12.86,100,1,13.98,2,1,12.73,100,1,14.10,100,1,12.71,100,1,14.28,100,1,12.50,700,1,14.46,100,1,12.49,200,2,14.48,700,1,12.46,100,1,14.56,800,2,ARL,334593569
2025-07-17T16:09:20.293271620Z,2025-07-17T16:09:20.293106270Z,160,2,1108,C,A,10,13.40,0,0,13.40,23,1,13.11,100,1,13.73,15,1,13.01,2,1,13.74,100,1,12.98,200,2,13.75,15,1,12.86,100,1,13.98,2,1,12.73,100,1,14.28,100,1,12.71,100,1,14.46,100,1,12.50,700,1,14.48,700,1,12.49,200,2,14.56,800,2,12.46,100,1,14.60,700,1,ARL,334190225
2025-07-17T16:09:20.293326641Z,2025-07-17T16:09:20.293161454Z,160,2,1108,A,A,10,13.40,0,0,13.40,23,1,13.11,100,1,13.73,15,1,13.01,2,1,13.74,100,1,12.98,200,2,13.75,15,1,12.86,100,1,13.98,2,1,12.73,100,1,14.01,100,1,12.71,100,1,14.28,100,1,12.50,700,1,14.46,100,1,12.49,200,2,14.48,700,1,12.46,100,1,14.56,800,2,ARL,334593753
2025-07-17T16:09:20.818813935Z,2025-07-17T16:09:20.818648795Z,160,2,1108,C,A,10,13.40,0,0,13.40,23,1,13.11,100,1,13.74,100,1,13.01,2,1,13.75,15,1,12.98,200,2,13.98,2,1,12.86,100,1,14.01,100,1,12.73,100,1,14.28,100,1,12.71,100,1,14.46,100,1,12.50,700,1,14.48,700,1,12.49,200,2,14.56,800,2,12.46,100,1,14.60,700,1,ARL,334583329
2025-07-17T16:09:20.818926356Z,2025-07-17T16:09:20.818761228Z,160,2,1108,C,A,10,13.40,0,0,13.40,23,1,13.11,100,1,13.74,100,1,13.01,2,1,13.98,2,1,12.98,200,2,14.01,100,1,12.86,100,1,14.28,100,1,12.73,100,1,14.46,100,1,12.71,100,1,14.48,700,1,12.50,700,1,14.56,800,2,12.49,200,2,14.60,700,1,12.46,100,1,14.61,100,1,ARL,334366613
2025-07-17T16:09:28.986122432Z,2025-07-17T16:09:28.985956629Z,160,2,1108,C,A,10,13.40,0,0,13.40,23,1,13.11,100,1,13.74,100,1,13.01,2,1,14.01,100,1,12.98,200,2,14.28,100,1,12.86,100,1,14.46,100,1,12.73,100,1,14.48,700,1,12.71,100,1,14.56,800,2,12.50,700,1,14.60,700,1,12.49,200,2,14.61,100,1,12.46,100,1,14.62,200,2,ARL,333581677
2025-07-17T16:09:28.986122432Z,2025-07-17T16:09:28.985956629Z,160,2,1108,A,A,10,13.40,0,0,13.40,23,1,13.11,100,1,13.74,100,1,13.01,2,1,13.90,2,1,12.98,200,2,14.01,100,1,12.86,100,1,14.28,100,1,12.73,100,1,14.46,100,1,12.71,100,1,14.48,700,1,12.50,700,1,14.56,800,2,12.49,200,2,14.60,700,1,12.46,100,1,14.61,100,1,ARL,334804177
2025-07-17T16:09:40.821687905Z,2025-07-17T16:09:40.821522565Z,160,2,1108,A,A,10,13.40,0,0,13.40,23,1,13.11,100,1,13.70,15,1,13.01,2,1,13.74,100,1,12.98,200,2,13.90,2,1,12.86,100,1,14.01,100,1,12.73,100,1,14.28,100,1,12.71,100,1,14.46,100,1,12.50,700,1,14.48,700,1,12.49,200,2,14.56,800,2,12.46,100,1,14.60,700,1,ARL,335003269
2025-07-17T16:09:40.853604577Z,2025-07-17T16:09:40.853439053Z,160,2,1108,C,A,10,13.40,0,0,13.40,23,1,13.11,100,1,13.70,15,1,13.01,2,1,13.90,2,1,12.98,200,2,14.01,100,1,12.86,100,1,14.28,100,1,12.73,100,1,14.46,100,1,12.71,100,1,14.48,700,1,12.50,700,1,14.56,800,2,12.49,200,2,14.60,700,1,12.46,100,1,14.61,100,1,ARL,334593569
2025-07-17T16:09:40.853604577Z,2025-07-17T16:09:40.853439053Z,160,2,1108,A,A,10,13.40,0,0,13.40,23,1,13.11,100,1,13.70,15,1,13.01,2,1,13.71,100,1,12.98,200,2,13.90,2,1,12.86,100,1,14.01,100,1,12.73,100,1,14.28,100,1,12.71,100,1,14.46,100,1,12.50,700,1,14.48,700,1,12.49,200,2,14.56,800,2,12.46,100,1,14.60,700,1,ARL,335003813
2025-07-17T16:09:40.854356022Z,2025-07-17T16:09:40.854190408Z,160,2,1108,C,A,10,13.40,0,0,13.40,23,1,13.11,100,1,13.70,15,1,13.01,2,1,13.71,100,1,12.98,200,2,13.90,2,1,12.86,100,1,14.01,100,1,12.73,100,1,14.28,100,1,12.71,100,1,14.46,100,1,12.50,700,1,14.48,700,1,12.49,200,2,14.56,800,2,12.46,100,1,14.60,700,1,ARL,334366645
2025-07-17T16:09:40.854356022Z,2025-07-17T16:09:40.854190408Z,160,2,1108,A,A,10,13.40,0,0,13.40,23,1,13.11,100,1,13.70,15,1,13.01,2,1,13.71,100,1,12.98,200,2,13.90,2,1,12.86,100,1,14.01,100,1,12.73,100,1,14.28,100,1,12.71,100,1,14.46,100,1,12.50,700,1,14.48,700,1,12.49,200,2,14.56,800,2,12.46,100,1,14.60,700,1,ARL,335003845
2025-07-17T16:09:40.855724422Z,2025-07-17T16:09:40.855558831Z,160,2,1108,C,A,10,13.40,0,0,13.40,23,1,13.11,100,1,13.70,15,1,13.01,2,1,13.71,100,1,12.98,200,2,13.90,2,1,12.86,100,1,14.01,100,1,12.73,100,1,14.28,100,1,12.71,100,1,14.46,100,1,12.50,700,1,14.48,700,1,12.49,200,2,14.56,800,2,12.46,100,1,14.60,700,1,ARL,334192253
2025-07-17T16:09:40.855724422Z,2025-07-17T16:09:40.855558831Z,160,2,1108,A,A,10,13.40,0,0,13.40,23,1,13.11,100,1,13.70,15,1,13.01,2,1,13.71,100,1,12.98,200,2,13.90,2,1,12.86,100,1,14.01,100,1,12.73,100,1,14.28,100,1,12.71,100,1,14.46,100,1,12.50,700,1,14.48,700,1,12.49,200,2,14.56,800,2,12.46,100,1,14.60,700,1,ARL,335003849
2025-07-17T16:09:50.820949131Z,2025-07-17T16:09:50.820783486Z,160,2,1108,A,A,10,13.40,0,0,13.40,23,1,13.11,100,1,13.67,15,1,13.01,2,1,13.70,15,1,12.98,200,2,13.71,100,1,12.86,100,1,13.90,2,1,12.73,100,1,14.01,100,1,12.71,100,1,14.28,100,1,12.50,700,1,14.46,100,1,12.49,200,2,14.48,700,1,12.46,100,1,14.56,800,2,ARL,335178437
2025-07-17T16:09:52.678777358Z,2025-07-17T16:09:52.678611805Z,160,2,1108,C,A,10,13.40,0,0,13.40,23,1,13.11,100,1,13.67,15,1,13.01,2,1,13.70,15,1,12.98,200,2,13.90,2,1,12.86,100,1,14.01,100,1,12.73,100,1,14.28,100,1,12.71,100,1,14.46,100,1,12.50,700,1,14.48,700,1,12.49,200,2,14.56,800,2,12.46,100,1,14.60,700,1,ARL,335003813
2025-07-17T16:09:52.678777358Z,2025-07-17T16:09:52.678611805Z,160,2,1108,A,A,10,13.40,0,0,13.40,23,1,13.11,100,1,13.67,15,1,13.01,2,1,13.68,100,1,12.98,200,2,13.70,15,1,12.86,100,1,13.90,2,1,12.73,100,1,14.01,100,1,12.71,100,1,14.28,100,1,12.50,700,1,14.46,100,1,12.49,200,2,14.48,700,1,12.46,100,1,14.56,800,2,ARL,335220349
2025-07-17T16:09:52.679844338Z,2025-07-17T16:09:52.679678566Z,160,2,1108,C,A,10,13.40,0,0,13.40,23,1,13.11,100,1,13.67,15,1,13.01,2,1,13.68,100,1,12.98,200,2,13.70,15,1,12.86,100,1,13.90,2,1,12.73,100,1,14.01,100,1,12.71,100,1,14.28,100,1,12.50,700,1,14.46,100,1,12.49,200,2,14.48,700,1,12.46,100,1,14.56,800,2,ARL,334192405
2025-07-17T16:09:52.679844338Z,2025-07-17T16:09:52.679678566Z,160,2,1108,A,A,10,13.40,0,0,13.40,23,1,13.11,100,1,13.67,15,1,13.01,2,1,13.68,100,1,12.98,200,2,13.70,15,1,12.86,100,1,13.90,2,1,12.73,100,1,14.01,100,1,12.71,100,1,14.28,100,1,12.50,700,1,14.46,100,1,12.49,200,2,14.48,700,1,12.46,100,1,14.56,800,2,ARL,335220497
2025-07-17T16:09:52.679936826Z,2025-07-17T16:09:52.679769832Z,160,2,1108,C,A,10,13.40,0,0,13.40,23,1,13.11,100,1,13.67,15,1,13.01,2,1,13.68,100,1,12.98,200,2,13.70,15,1,12.86,100,1,13.90,2,1,12.73,100,1,14.01,100,1,12.71,100,1,14.28,100,1,12.50,700,1,14.46,100,1,12.49,200,2,14.48,700,1,12.46,100,1,14.56,800,2,ARL,334190353
2025-07-17T16:09:52.679936826Z,2025-07-17T16:09:52.679769832Z,160,2,1108,A,A,10,13.40,0,0,13.40,23,1,13.11,100,1,13.67,15,1,13.01,2,1,13.68,100,1,12.98,200,2,13.70,15,1,12.86,100,1,13.90,2,1,12.73,100,1,14.01,100,1,12.71,100,1,14.28,100,1,12.50,700,1,14.46,100,1,12.49,200,2,14.48,700,1,12.46,100,1,14.56,800,2,ARL,335220525
2025-07-17T16:09:52.680837736Z,2025-07-17T16:09:52.680672148Z,160,2,1108,C,A,10,13.40,0,0,13.40,23,1,13.11,100,1,13.67,15,1,13.01,2,1,13.68,100,1,12.98,200,2,13.70,15,1,12.86,100,1,13.90,2,1,12.73,100,1,14.01,100,1,12.71,100,1,14.28,100,1,12.50,700,1,14.46,100,1,12.49,200,2,14.48,700,1,12.46,100,1,14.56,800,2,ARL,333581441
2025-07-17T16:09:52.680837736Z,2025-07-17T16:09:52.680672148Z,160,2,1108,A,A,10,13.40,0,0,13.40,23,1,13.11,100,1,13.67,15,1,13.01,2,1,13.68,100,1,12.98,200,2,13.70,15,1,12.86,100,1,13.90,2,1,12.73,100,1,14.01,100,1,12.71,100,1,14.28,100,1,12.50,700,1,14.46,100,1,12.49,200,2,14.48,700,1,12.46,100,1,14.56,800,2,ARL,335220549
2025-07-17T16:09:52.682009938Z,2025-07-17T16:09:52.681844377Z,160,2,1108,C,A,10,13.40,0,0,13.40,23,1,13.11,100,1,13.67,15,1,13.01,2,1,13.68,100,1,12.98,200,2,13.70,15,1,12.86,100,1,13.90,2,1,12.73,100,1,14.01,100,1,12.71,100,1,14.28,100,1,12.50,700,1,14.46,100,1,12.49,200,2,14.48,700,1,12.46,100,1,14.56,800,2,ARL,334190189
2025-07-17T16:09:52.682127530Z,2025-07-17T16:09:52.681961200Z,160,2,1108,A,A,10,13.40,0,0,13.40,23,1,13.11,100,1,13.67,15,1,13.01,2,1,13.68,100,1,12.98,200,2,13.70,15,1,12.86,100,1,13.90,2,1,12.73,100,1,14.01,100,1,12.71,100,1,14.28,100,1,12.50,700,1,14.46,100,1,12.49,200,2,14.47,100,1,12.46,100,1,14.48,700,1,ARL,335220561
2025-07-17T16:09:52.683922707Z,2025-07-17T16:09:52.683757265Z,160,2,1108,C,A,10,13.40,0,0,13.40,23,1,13.11,100,1,13.67,15,1,13.01,2,1,13.68,100,1,12.98,200,2,13.70,15,1,12.86,100,1,13.90,2,1,12.73,100,1,14.01,100,1,12.71,100,1,14.28,100,1,12.50,700,1,14.46,100,1,12.49,200,2,14.47,100,1,12.46,100,1,14.48,700,1,ARL,334199009
2025-07-17T16:09:52.683922707Z,2025-07-17T16:09:52.683757265Z,160,2,1108,A,A,10,13.40,0,0,13.40,23,1,13.11,100,1,13.67,15,1,13.01,2,1,13.68,100,1,12.98,200,2,13.70,15,1,12.86,100,1,13.90,2,1,12.73,100,1,14.01,100,1,12.71,100,1,14.28,100,1,12.50,700,1,14.46,100,1,12.49,200,2,14.47,100,1,12.46,100,1,14.48,700,1,ARL,335220629
2025-07-17T16:10:04.521471804Z,2025-07-17T16:10:04.521306513Z,160,2,1108,C,A,10,13.40,0,0,13.40,23,1,13.11,100,1,13.68,100,1,13.01,2,1,13.70,15,1,12.98,200,2,13.90,2,1,12.86,100,1,14.01,100,1,12.73,100,1,14.28,100,1,12.71,100,1,14.46,100,1,12.50,700,1,14.47,100,1,12.49,200,2,14.48,700,1,12.46,100,1,14.56,800,2,ARL,335178437
2025-07-17T16:10:04.561854856Z,2025-07-17T16:10:04.561688313Z,160,2,1108,C,A,10,13.40,0,0,13.40,23,1,13.11,100,1,13.68,100,1,13.01,2,1,13.90,2,1,12.98,200,2,14.01,100,1,12.86,100,1,14.28,100,1,12.73,100,1,14.46,100,1,12.71,100,1,14.47,100,1,12.50,700,1,14.48,700,1,12.49,200,2,14.56,800,2,12.46,100,1,14.60,700,1,ARL,335003269
2025-07-17T16:10:32.822660498Z,2025-07-17T16:10:32.822495087Z,160,2,1108,A,A,10,13.40,0,0,13.40,23,1,13.11,100,1,13.65,15,1,13.01,2,1,13.68,100,1,12.98,200,2,13.90,2,1,12.86,100,1,14.01,100,1,12.73,100,1,14.28,100,1,12.71,100,1,14.46,100,1,12.50,700,1,14.47,100,1,12.49,200,2,14.48,700,1,12.46,100,1,14.56,800,2,ARL,335996705
2025-07-17T16:10:32.822923138Z,2025-07-17T16:10:32.822757517Z,160,2,1108,C,A,10,13.40,0,0,13.40,23,1,13.11,100,1,13.65,15,1,13.01,2,1,13.90,2,1,12.98,200,2,14.01,100,1,12.86,100,1,14.28,100,1,12.73,100,1,14.46,100,1,12.71,100,1,14.47,100,1,12.50,700,1,14.48,700,1,12.49,200,2,14.56,800,2,12.46,100,1,14.60,700,1,ARL,335220349
2025-07-17T16:10:32.822923138Z,2025-07-17T16:10:32.822757517Z,160,2,1108,A,A,10,13.40,0,0,13.40,23,1,13.11,100,1,13.65,15,1,13.01,2,1,13.66,100,1,12.98,200,2,13.90,2,1,12.86,100,1,14.01,100,1,12.73,100,1,14.28,100,1,12.71,100,1,14.46,100,1,12.50,700,1,14.47,100,1,12.49,200,2,14.48,700,1,12.46,100,1,14.56,800,2,ARL,335996709
2025-07-17T16:10:32.823656903Z,2025-07-17T16:10:32.823491276Z,160,2,1108,C,A,10,13.40,0,0,13.40,23,1,13.11,100,1,13.65,15,1,13.01,2,1,13.66,100,1,12.98,200,2,13.90,2,1,12.86,100,1,14.01,100,1,12.73,100,1,14.28,100,1,12.71,100,1,14.46,100,1,12.50,700,1,14.47,100,1,12.49,200,2,14.48,700,1,12.46,100,1,14.56,800,2,ARL,335003845
2025-07-17T16:10:32.823656903Z,2025-07-17T16:10:32.823491276Z,160,2,1108,A,A,10,13.40,0,0,13.40,23,1,13.11,100,1,13.65,15,1,13.01,2,1,13.66,100,1,12.98,200,2,13.90,2,1,12.86,100,1,14.01,100,1,12.73,100,1,14.28,100,1,12.71,100,1,14.46,100,1,12.50,700,1,14.47,100,1,12.49,200,2,14.48,700,1,12.46,100,1,14.56,800,2,ARL,335996725
2025-07-17T16:10:32.830200844Z,2025-07-17T16:10:32.830032662Z,160,2,1108,C,A,10,13.40,0,0,13.40,23,1,13.11,100,1,13.65,15,1,13.01,2,1,13.66,100,1,12.98,200,2,13.90,2,1,12.86,100,1,14.28,100,1,12.73,100,1,14.46,100,1,12.71,100,1,14.47,100,1,12.50,700,1,14.48,700,1,12.49,200,2,14.56,800,2,12.46,100,1,14.60,700,1,ARL,334593753
2025-07-17T16:10:32.830250720Z,2025-07-17T16:10:32.830085472Z,160,2,1108,A,A,10,13.40,0,0,13.40,23,1,13.11,100,1,13.65,15,1,13.01,2,1,13.66,100,1,12.98,200,2,13.90,2,1,12.86,100,1,13.93,100,1,12.73,100,1,14.28,100,1,12.71,100,1,14.46,100,1,12.50,700,1,14.47,100,1,12.49,200,2,14.48,700,1,12.46,100,1,14.56,800,2,ARL,335996777
2025-07-17T16:10:42.822354869Z,2025-07-17T16:10:42.822189504Z,160,2,1108,A,A,10,13.40,0,0,13.40,23,1,13.11,100,1,13.63,15,1,13.01,2,1,13.65,15,1,12.98,200,2,13.66,100,1,12.86,100,1,13.90,2,1,12.73,100,1,13.93,100,1,12.71,100,1,14.28,100,1,12.50,700,1,14.46,100,1,12.49,200,2,14.47,100,1,12.46,100,1,14.48,700,1,ARL,336161333
2025-07-17T16:10:42.822424663Z,2025-07-17T16:10:42.822258887Z,160,2,1108,C,A,10,13.40,0,0,13.40,23,1,13.11,100,1,13.63,15,1,13.01,2,1,13.65,15,1,12.98,200,2,13.90,2,1,12.86,100,1,13.93,100,1,12.73,100,1,14.28,100,1,12.71,100,1,14.46,100,1,12.50,700,1,14.47,100,1,12.49,200,2,14.48,700,1,12.46,100,1,14.56,800,2,ARL,335996709
2025-07-17T16:10:42.822424663Z,2025-07-17T16:10:42.822258887Z,160,2,1108,A,A,10,13.40,0,0,13.40,23,1,13.11,100,1,13.63,15,1,13.01,2,1,13.64,100,1,12.98,200,2,13.65,15,1,12.86,100,1,13.90,2,1,12.73,100,1,13.93,100,1,12.71,100,1,14.28,100,1,12.50,700,1,14.46,100,1,12.49,200,2,14.47,100,1,12.46,100,1,14.48,700,1,ARL,336161337
2025-07-17T16:10:42.823163929Z,2025-07-17T16:10:42.822998664Z,160,2,1108,C,A,10,13.40,0,0,13.40,23,1,13.11,100,1,13.63,15,1,13.01,2,1,13.64,100,1,12.98,200,2,13.65,15,1,12.86,100,1,13.90,2,1,12.73,100,1,13.93,100,1,12.71,100,1,14.28,100,1,12.50,700,1,14.47,100,1,12.49,200,2,14.48,700,1,12.46,100,1,14.56,800,2,ARL,331927161
2025-07-17T16:10:42.823517444Z,2025-07-17T16:10:42.823352130Z,160,2,1108,A,A,10,13.40,0,0,13.40,23,1,13.11,100,1,13.63,15,1,13.01,2,1,13.64,100,1,12.98,200,2,13.65,15,1,12.86,100,1,13.90,2,1,12.73,100,1,13.93,100,1,12.71,100,1,14.25,100,1,12.50,700,1,14.28,100,1,12.49,200,2,14.47,100,1,12.46,100,1,14.48,700,1,ARL,336161365
2025-07-17T16:10:46.534055942Z,2025-07-17T16:10:46.533890361Z,160,2,1108,C,A,10,13.40,0,0,13.40,23,1,13.11,100,1,13.63,15,1,13.01,2,1,13.64,100,1,12.98,200,2,13.65,15,1,12.86,100,1,13.90,2,1,12.73,100,1,13.93,100,1,12.71,100,1,14.25,100,1,12.50,700,1,14.28,100,1,12.49,200,2,14.47,100,1,12.46,100,1,14.48,700,1,ARL,334583349
2025-07-17T16:10:46.534055942Z,2025-07-17T16:10:46.533890361Z,160,2,1108,A,A,10,13.40,0,0,13.40,23,1,13.11,100,1,13.63,15,1,13.01,2,1,13.64,100,1,12.98,200,2,13.65,15,1,12.86,100,1,13.90,2,1,12.73,100,1,13.93,100,1,12.71,100,1,14.25,100,1,12.50,700,1,14.28,100,1,12.49,200,2,14.47,100,1,12.46,100,1,14.48,700,1,ARL,336259225
2025-07-17T16:10:46.538158874Z,2025-07-17T16:10:46.537992315Z,160,2,1108,C,A,10,13.40,0,0,13.40,23,1,13.11,100,1,13.63,15,1,13.01,2,1,13.64,100,1,12.98,200,2,13.90,2,1,12.86,100,1,13.93,100,1,12.73,100,1,14.25,100,1,12.71,100,1,14.28,100,1,12.50,700,1,14.47,100,1,12.49,200,2,14.48,700,1,12.46,100,1,14.51,100,1,ARL,335996705
2025-07-17T16:10:46.561246030Z,2025-07-17T16:10:46.561080616Z,160,2,1108,C,A,10,13.40,0,0,13.40,23,1,13.11,100,1,13.63,15,1,13.01,2,1,13.64,100,1,12.98,200,2,13.90,2,1,12.86,100,1,13.93,100,1,12.73,100,1,14.25,100,1,12.71,100,1,14.28,100,1,12.50,700,1,14.47,100,1,12.49,200,2,14.48,700,1,12.46,100,1,14.51,100,1,ARL,334583361
2025-07-17T16:10:46.561246030Z,2025-07-17T16:10:46.561080616Z,160,2,1108,A,A,10,13.40,0,0,13.40,23,1,13.11,100,1,13.63,15,1,13.01,2,1,13.64,100,1,12.98,200,2,13.90,2,1,12.86,100,1,13.93,100,1,12.73,100,1,14.25,100,1,12.71,100,1,14.28,100,1,12.50,700,1,14.47,100,1,12.49,200,2,14.48,700,1,12.46,100,1,14.51,200,2,ARL,336261905
2025-07-17T16:10:47.543404001Z,2025-07-17T16:10:47.543238729Z,160,2,1108,A,A,10,13.40,0,0,13.40,23,1,13.11,100,1,13.61,15,1,13.01,2,1,13.63,15,1,12.98,200,2,13.64,100,1,12.86,100,1,13.90,2,1,12.73,100,1,13.93,100,1,12.71,100,1,14.25,100,1,12.50,700,1,14.28,100,1,12.49,200,2,14.47,100,1,12.46,100,1,14.48,700,1,ARL,336278197
2025-07-17T16:10:48.657456395Z,2025-07-17T16:10:48.657290980Z,160,2,1108,C,A,10,13.40,0,0,13.40,23,1,13.11,100,1,13.61,15,1,13.01,2,1,13.63,15,1,12.98,200,2,13.90,2,1,12.86,100,1,13.93,100,1,12.73,100,1,14.25,100,1,12.71,100,1,14.28,100,1,12.50,700,1,14.47,100,1,12.49,200,2,14.48,700,1,12.46,100,1,14.51,200,2,ARL,336161337
2025-07-17T16:10:48.657456395Z,2025-07-17T16:10:48.657290980Z,160,2,1108,A,A,10,13.40,0,0,13.40,23,1,13.11,100,1,13.61,15,1,13.01,2,1,13.62,100,1,12.98,200,2,13.63,15,1,12.86,100,1,13.90,2,1,12.73,100,1,13.93,100,1,12.71,100,1,14.25,100,1,12.50,700,1,14.28,100,1,12.49,200,2,14.47,100,1,12.46,100,1,14.48,700,1,ARL,336295769
2025-07-17T16:10:48.658199425Z,2025-07-17T16:10:48.658033954Z,160,2,1108,C,A,10,13.40,0,0,13.40,23,1,13.11,100,1,13.61,15,1,13.01,2,1,13.62,100,1,12.98,200,2,13.63,15,1,12.86,100,1,13.90,2,1,12.73,100,1,13.93,100,1,12.71,100,1,14.25,100,1,12.50,700,1,14.28,100,1,12.49,200,2,14.47,100,1,12.46,100,1,14.48,700,1,ARL,335996725
2025-07-17T16:10:48.658199425Z,2025-07-17T16:10:48.658033954Z,160,2,1108,A,A,10,13.40,0,0,13.40,23,1,13.11,100,1,13.61,15,1,13.01,2,1,13.62,100,1,12.98,200,2,13.63,15,1,12.86,100,1,13.90,2,1,12.73,100,1,13.93,100,1,12.71,100,1,14.25,100,1,12.50,700,1,14.28,100,1,12.49,200,2,14.47,100,1,12.46,100,1,14.48,700,1,ARL,336295845
2025-07-17T16:10:51.059044292Z,2025-07-17T16:10:51.058878264Z,160,2,1108,C,A,10,13.40,0,0,13.40,23,1,13.11,100,1,13.62,100,1,13.01,2,1,13.63,15,1,12.98,200,2,13.90,2,1,12.86,100,1,13.93,100,1,12.73,100,1,14.25,100,1,12.71,100,1,14.28,100,1,12.50,700,1,14.47,100,1,12.49,200,2,14.48,700,1,12.46,100,1,14.51,200,2,ARL,336278197
2025-07-17T16:10:51.059183923Z,2025-07-17T16:10:51.059016199Z,160,2,1108,C,A,10,13.40,0,0,13.40,23,1,13.11,100,1,13.62,100,1,13.01,2,1,13.90,2,1,12.98,200,2,13.93,100,1,12.86,100,1,14.25,100,1,12.73,100,1,14.28,100,1,12.71,100,1,14.47,100,1,12.50,700,1,14.48,700,1,12.49,200,2,14.51,200,2,12.46,100,1,14.56,800,2,ARL,336161333
2025-07-17T16:10:51.059608753Z,2025-07-17T16:10:51.059443298Z,160,2,1108,C,A,10,13.40,0,0,13.40,23,1,13.11,100,1,13.90,2,1,13.01,2,1,13.93,100,1,12.98,200,2,14.25,100,1,12.86,100,1,14.28,100,1,12.73,100,1,14.47,100,1,12.71,100,1,14.48,700,1,12.50,700,1,14.51,200,2,12.49,200,2,14.56,800,2,12.46,100,1,14.60,700,1,ARL,336295769
2025-07-17T16:10:51.170710609Z,2025-07-17T16:10:51.170545251Z,160,2,1108,A,A,10,13.40,0,0,13.40,23,1,13.11,100,1,13.90,2,1,13.01,2,1,13.91,100,1,12.98,200,2,13.93,100,1,12.86,100,1,14.25,100,1,12.73,100,1,14.28,100,1,12.71,100,1,14.47,100,1,12.50,700,1,14.48,700,1,12.49,200,2,14.51,200,2,12.46,100,1,14.56,800,2,ARL,336351081
2025-07-17T16:10:52.958453641Z,2025-07-17T16:10:52.958288317Z,160,2,1108,A,A,10,13.40,0,0,13.40,23,1,13.11,100,1,13.60,15,1,13.01,2,1,13.90,2,1,12.98,200,2,13.91,100,1,12.86,100,1,13.93,100,1,12.73,100,1,14.25,100,1,12.71,100,1,14.28,100,1,12.50,700,1,14.47,100,1,12.49,200,2,14.48,700,1,12.46,100,1,14.51,200,2,ARL,336402845
2025-07-17T16:10:53.102037173Z,2025-07-17T16:10:53.101871639Z,160,2,1108,C,A,10,13.40,0,0,13.40,23,1,13.11,100,1,13.60,15,1,13.01,2,1,13.90,2,1,12.98,200,2,13.93,100,1,12.86,100,1,14.25,100,1,12.73,100,1,14.28,100,1,12.71,100,1,14.47,100,1,12.50,700,1,14.48,700,1,12.49,200,2,14.51,200,2,12.46,100,1,14.56,800,2,ARL,336351081
2025-07-17T16:10:53.102037173Z,2025-07-17T16:10:53.101871639Z,160,2,1108,A,A,10,13.40,0,0,13.40,23,1,13.11,100,1,13.60,15,1,13.01,2,1,13.61,100,1,12.98,200,2,13.90,2,1,12.86,100,1,13.93,100,1,12.73,100,1,14.25,100,1,12.71,100,1,14.28,100,1,12.50,700,1,14.47,100,1,12.49,200,2,14.48,700,1,12.46,100,1,14.51,200,2,ARL,336410125
2025-07-17T16:10:54.959307592Z,2025-07-17T16:10:54.959141873Z,160,2,1108,C,A,10,13.40,0,0,13.40,23,1,13.11,100,1,13.60,15,1,13.01,2,1,13.61,100,1,12.98,200,2,13.93,100,1,12.86,100,1,14.25,100,1,12.73,100,1,14.28,100,1,12.71,100,1,14.47,100,1,12.50,700,1,14.48,700,1,12.49,200,2,14.51,200,2,12.46,100,1,14.56,800,2,ARL,334804177
2025-07-17T16:10:54.959307592Z,2025-07-17T16:10:54.959141873Z,160,2,1108,A,A,10,13.40,0,0,13.40,23,1,13.11,100,1,13.60,15,1,13.01,2,1,13.61,100,1,12.98,200,2,13.82,2,1,12.86,100,1,13.93,100,1,12.73,100,1,14.25,100,1,12.71,100,1,14.28,100,1,12.50,700,1,14.47,100,1,12.49,200,2,14.48,700,1,12.46,100,1,14.51,200,2,ARL,336447325
2025-07-17T16:10:59.518035805Z,2025-07-17T16:10:59.517870358Z,160,2,1108,A,A,10,13.40,0,0,13.40,23,1,13.11,100,1,13.58,15,1,13.01,2,1,13.60,15,1,12.98,200,2,13.61,100,1,12.86,100,1,13.82,2,1,12.73,100,1,13.93,100,1,12.71,100,1,14.25,100,1,12.50,700,1,14.28,100,1,12.49,200,2,14.47,100,1,12.46,100,1,14.48,700,1,ARL,336555153
2025-07-17T16:11:00.215885294Z,2025-07-17T16:11:00.215719725Z,160,2,1108,C,A,10,13.40,0,0,13.40,23,1,13.11,100,1,13.58,15,1,13.01,2,1,13.60,15,1,12.98,200,2,13.82,2,1,12.86,100,1,13.93,100,1,12.73,100,1,14.25,100,1,12.71,100,1,14.28,100,1,12.50,700,1,14.47,100,1,12.49,200,2,14.48,700,1,12.46,100,1,14.51,200,2,ARL,336410125
2025-07-17T16:11:00.215885294Z,2025-07-17T16:11:00.215719725Z,160,2,1108,A,A,10,13.40,0,0,13.40,23,1,13.11,100,1,13.58,15,1,13.01,2,1,13.59,100,1,12.98,200,2,13.60,15,1,12.86,100,1,13.82,2,1,12.73,100,1,13.93,100,1,12.71,100,1,14.25,100,1,12.50,700,1,14.28,100,1,12.49,200,2,14.47,100,1,12.46,100,1,14.48,700,1,ARL,336567189
2025-07-17T16:11:00.216622121Z,2025-07-17T16:11:00.216456547Z,160,2,1108,C,A,10,13.40,0,0,13.40,23,1,13.11,100,1,13.58,15,1,13.01,2,1,13.59,100,1,12.98,200,2,13.60,15,1,12.86,100,1,13.82,2,1,12.73,100,1,13.93,100,1,12.71,100,1,14.25,100,1,12.50,700,1,14.28,100,1,12.49,200,2,14.47,100,1,12.46,100,1,14.48,700,1,ARL,336295845
2025-07-17T16:11:00.216622121Z,2025-07-17T16:11:00.216456547Z,160,2,1108,A,A,10,13.40,0,0,13.40,23,1,13.11,100,1,13.58,15,1,13.01,2,1,13.59,100,1,12.98,200,2,13.60,15,1,12.86,100,1,13.82,2,1,12.73,100,1,13.93,100,1,12.71,100,1,14.25,100,1,12.50,700,1,14.28,100,1,12.49,200,2,14.47,100,1,12.46,100,1,14.48,700,1,ARL,336567213
2025-07-17T16:11:00.228999377Z,2025-07-17T16:11:00.228833925Z,160,2,1108,C,A,10,13.40,0,0,13.40,23,1,13.11,100,1,13.58,15,1,13.01,2,1,13.59,100,1,12.98,200,2,13.60,15,1,12.86,100,1,13.82,2,1,12.73,100,1,14.25,100,1,12.71,100,1,14.28,100,1,12.50,700,1,14.47,100,1,12.49,200,2,14.48,700,1,12.46,100,1,14.51,200,2,ARL,335996777
2025-07-17T16:11:00.229051124Z,2025-07-17T16:11:00.228885790Z,160,2,1108,A,A,10,13.40,0,0,13.40,23,1,13.11,100,1,13.58,15,1,13.01,2,1,13.59,100,1,12.98,200,2,13.60,15,1,12.86,100,1,13.82,2,1,12.73,100,1,13.86,100,1,12.71,100,1,14.25,100,1,12.50,700,1,14.28,100,1,12.49,200,2,14.47,100,1,12.46,100,1,14.48,700,1,ARL,336567333
2025-07-17T16:11:00.313087129Z,2025-07-17T16:11:00.312921679Z,160,2,1108,C,A,10,13.40,0,0,13.40,23,1,13.11,100,1,13.58,15,1,13.01,2,1,13.59,100,1,12.98,200,2,13.60,15,1,12.86,100,1,13.82,2,1,12.73,100,1,13.86,100,1,12.71,100,1,14.25,100,1,12.50,700,1,14.28,100,1,12.49,200,2,14.47,100,1,12.46,100,1,14.48,700,1,ARL,335003849
2025-07-17T16:11:00.313087129Z,2025-07-17T16:11:00.312921679Z,160,2,1108,A,A,10,13.40,0,0,13.40,23,1,13.11,100,1,13.58,15,1,13.01,2,1,13.59,100,1,12.98,200,2,13.60,15,1,12.86,100,1,13.82,2,1,12.73,100,1,13.86,100,1,12.71,100,1,14.25,100,1,12.50,700,1,14.28,100,1,12.49,200,2,14.47,100,1,12.46,100,1,14.48,700,1,ARL,336570921
2025-07-17T16:11:00.366811541Z,2025-07-17T16:11:00.366645846Z,160,2,1108,A,A,10,13.40,0,0,13.40,23,1,13.11,100,1,13.58,15,1,13.01,2,1,13.59,100,1,12.98,200,2,13.60,15,1,12.86,100,1,13.62,1,1,12.73,100,1,13.82,2,1,12.71,100,1,13.86,100,1,12.50,700,1,14.25,100,1,12.49,200,2,14.28,100,1,12.46,100,1,14.47,100,1,ARL,336572049
2025-07-17T16:11:00.367374773Z,2025-07-17T16:11:00.367209243Z,160,2,1108,C,B,10,13.40,0,0,13.40,23,1,13.11,100,1,13.58,15,1,13.01,2,1,13.59,100,1,12.98,200,2,13.60,15,1,12.86,100,1,13.62,1,1,12.73,100,1,13.82,2,1,12.71,100,1,13.86,100,1,12.50,700,1,14.25,100,1,12.49,100,1,14.28,100,1,12.46,100,1,14.47,100,1,ARL,331942945
2025-07-17T16:11:00.367374773Z,2025-07-17T16:11:00.367209243Z,160,2,1108,A,B,10,13.40,0,0,13.40,23,1,13.11,100,1,13.58,15,1,13.01,2,1,13.59,100,1,12.98,200,2,13.60,15,1,12.86,100,1,13.62,1,1,12.73,100,1,13.82,2,1,12.71,100,1,13.86,100,1,12.50,700,1,14.25,100,1,12.49,100,1,14.28,100,1,12.46,100,1,14.47,100,1,ARL,336572057
2025-07-17T16:11:00.367485094Z,2025-07-17T16:11:00.367319059Z,160,2,1108,C,B,10,13.40,0,0,13.40,23,1,13.11,100,1,13.58,15,1,13.01,2,1,13.59,100,1,12.98,200,2,13.60,15,1,12.86,100,1,13.62,1,1,12.73,100,1,13.82,2,1,12.71,100,1,13.86,100,1,12.50,700,1,14.25,100,1,12.46,100,1,14.28,100,1,12.43,700,1,14.47,100,1,ARL,331942901
2025-07-17T16:11:00.367485094Z,2025-07-17T16:11:00.367319059Z,160,2,1108,A,B,10,13.40,0,0,13.40,23,1,13.11,100,1,13.58,15,1,13.01,2,1,13.59,100,1,12.98,200,2,13.60,15,1,12.86,100,1,13.62,1,1,12.73,100,1,13.82,2,1,12.71,100,1,13.86,100,1,12.50,700,1,14.25,100,1,12.46,100,1,14.28,100,1,12.43,700,1,14.47,100,1,ARL,336572069
2025-07-17T16:11:00.466868624Z,2025-07-17T16:11:00.466703632Z,160,2,1108,C,A,10,13.40,0,0,13.40,23,1,13.11,100,1,13.58,15,1,13.01,2,1,13.59,100,1,12.98,200,2,13.60,15,1,12.86,100,1,13.82,2,1,12.73,100,1,13.86,100,1,12.71,100,1,14.25,100,1,12.50,700,1,14.28,100,1,12.46,100,1,14.47,100,1,12.43,700,1,14.48,700,1,ARL,336572049
2025-07-17T16:11:06.626831799Z,2025-07-17T16:11:06.626666474Z,160,2,1108,A,A,10,13.40,0,0,13.40,23,1,13.11,100,1,13.58,15,1,13.01,2,1,13.59,100,1,12.98,200,2,13.60,15,1,12.86,100,1,13.82,2,1,12.73,100,1,13.86,100,1,12.71,100,1,14.25,100,1,12.50,700,1,14.27,700,1,12.46,100,1,14.28,100,1,12.43,700,1,14.47,100,1,ARL,336747457
2025-07-17T16:11:06.626906700Z,2025-07-17T16:11:06.626741446Z,160,2,1108,C,A,10,13.40,0,0,13.40,23,1,13.11,100,1,13.58,15,1,13.01,2,1,13.59,100,1,12.98,200,2,13.60,15,1,12.86,100,1,13.82,2,1,12.73,100,1,13.86,100,1,12.71,100,1,14.25,100,1,12.50,700,1,14.27,700,1,12.46,100,1,14.28,100,1,12.43,700,1,14.47,100,1,ARL,331929977
2025-07-17T16:11:08.308034538Z,2025-07-17T16:11:08.307868957Z,160,2,1108,C,A,10,13.40,0,0,13.40,23,1,13.11,100,1,13.58,15,1,13.01,2,1,13.59,100,1,12.98,200,2,13.82,2,1,12.86,100,1,13.86,100,1,12.73,100,1,14.25,100,1,12.71,100,1,14.27,700,1,12.50,700,1,14.28,100,1,12.46,100,1,14.47,100,1,12.43,700,1,14.48,700,1,ARL,336402845
2025-07-17T16:11:09.568536292Z,2025-07-17T16:11:09.568370995Z,160,2,1108,A,A,10,13.40,0,0,13.40,23,1,13.11,100,1,13.56,15,1,13.01,2,1,13.58,15,1,12.98,200,2,13.59,100,1,12.86,100,1,13.82,2,1,12.73,100,1,13.86,100,1,12.71,100,1,14.25,100,1,12.50,700,1,14.27,700,1,12.46,100,1,14.28,100,1,12.43,700,1,14.47,100,1,ARL,336816813
2025-07-17T16:11:10.341953971Z,2025-07-17T16:11:10.341788521Z,160,2,1108,C,A,10,13.40,0,0,13.40,23,1,13.11,100,1,13.56,15,1,13.01,2,1,13.58,15,1,12.98,200,2,13.82,2,1,12.86,100,1,13.86,100,1,12.73,100,1,14.25,100,1,12.71,100,1,14.27,700,1,12.50,700,1,14.28,100,1,12.46,100,1,14.47,100,1,12.43,700,1,14.48,700,1,ARL,336567189
2025-07-17T16:11:10.341953971Z,2025-07-17T16:11:10.341788521Z,160,2,1108,A,A,10,13.40,0,0,13.40,23,1,13.11,100,1,13.56,15,1,13.01,2,1,13.57,100,1,12.98,200,2,13.58,15,1,12.86,100,1,13.82,2,1,12.73,100,1,13.86,100,1,12.71,100,1,14.25,100,1,12.50,700,1,14.27,700,1,12.46,100,1,14.28,100,1,12.43,700,1,14.47,100,1,ARL,336828765
2025-07-17T16:11:14.610701450Z,2025-07-17T16:11:14.610535763Z,160,2,1108,C,A,10,13.40,0,0,13.40,23,1,13.11,100,1,13.56,15,1,13.01,2,1,13.57,100,1,12.98,200,2,13.82,2,1,12.86,100,1,13.86,100,1,12.73,100,1,14.25,100,1,12.71,100,1,14.27,700,1,12.50,700,1,14.28,100,1,12.46,100,1,14.47,100,1,12.43,700,1,14.48,700,1,ARL,336555153
2025-07-17T16:11:16.025458231Z,2025-07-17T16:11:16.025292936Z,160,2,1108,C,A,10,13.40,0,0,13.40,23,1,13.11,100,1,13.57,100,1,13.01,2,1,13.82,2,1,12.98,200,2,13.86,100,1,12.86,100,1,14.25,100,1,12.73,100,1,14.27,700,1,12.71,100,1,14.28,100,1,12.50,700,1,14.47,100,1,12.46,100,1,14.48,700,1,12.43,700,1,14.51,200,2,ARL,336816813
2025-07-17T16:11:50.026837358Z,2025-07-17T16:11:50.026672014Z,160,2,1108,A,A,10,13.40,0,0,13.40,23,1,13.11,100,1,13.55,15,1,13.01,2,1,13.57,100,1,12.98,200,2,13.82,2,1,12.86,100,1,13.86,100,1,12.73,100,1,14.25,100,1,12.71,100,1,14.27,700,1,12.50,700,1,14.28,100,1,12.46,100,1,14.47,100,1,12.43,700,1,14.48,700,1,ARL,337690189
2025-07-17T16:11:50.027004977Z,2025-07-17T16:11:50.026839463Z,160,2,1108,C,A,10,13.40,0,0,13.40,23,1,13.11,100,1,13.55,15,1,13.01,2,1,13.82,2,1,12.98,200,2,13.86,100,1,12.86,100,1,14.25,100,1,12.73,100,1,14.27,700,1,12.71,100,1,14.28,100,1,12.50,700,1,14.47,100,1,12.46,100,1,14.48,700,1,12.43,700,1,14.51,200,2,ARL,336828765
2025-07-17T16:11:50.027004977Z,2025-07-17T16:11:50.026839463Z,160,2,1108,A,A,10,13.40,0,0,13.40,23,1,13.11,100,1,13.55,15,1,13.01,2,1,13.56,100,1,12.98,200,2,13.82,2,1,12.86,100,1,13.86,100,1,12.73,100,1,14.25,100,1,12.71,100,1,14.27,700,1,12.50,700,1,14.28,100,1,12.46,100,1,14.47,100,1,12.43,700,1,14.48,700,1,ARL,337690193
2025-07-17T16:11:50.033010798Z,2025-07-17T16:11:50.032845393Z,160,2,1108,C,A,10,13.40,0,0,13.40,23,1,13.11,100,1,13.55,15,1,13.01,2,1,13.56,100,1,12.98,200,2,13.82,2,1,12.86,100,1,13.86,100,1,12.73,100,1,14.25,100,1,12.71,100,1,14.27,700,1,12.50,700,1,14.28,100,1,12.46,100,1,14.47,100,1,12.43,700,1,14.48,700,1,ARL,335220497
2025-07-17T16:11:50.033010798Z,2025-07-17T16:11:50.032845393Z,160,2,1108,A,A,10,13.40,0,0,13.40,23,1,13.11,100,1,13.55,15,1,13.01,2,1,13.56,100,1,12.98,200,2,13.82,2,1,12.86,100,1,13.86,100,1,12.73,100,1,14.25,100,1,12.71,100,1,14.27,700,1,12.50,700,1,14.28,100,1,12.46,100,1,14.47,100,1,12.43,700,1,14.48,700,1,ARL,337690641
2025-07-17T16:11:53.859909462Z,2025-07-17T16:11:53.859743991Z,160,2,1108,A,A,10,13.40,0,0,13.40,23,1,13.11,100,1,13.53,15,1,13.01,2,1,13.55,15,1,12.98,200,2,13.56,100,1,12.86,100,1,13.82,2,1,12.73,100,1,13.86,100,1,12.71,100,1,14.25,100,1,12.50,700,1,14.27,700,1,12.46,100,1,14.28,100,1,12.43,700,1,14.47,100,1,ARL,337772837
2025-07-17T16:11:54.662527332Z,2025-07-17T16:11:54.662361841Z,160,2,1108,C,A,10,13.40,0,0,13.40,23,1,13.11,100,1,13.53,15,1,13.01,2,1,13.55,15,1,12.98,200,2,13.82,2,1,12.86,100,1,13.86,100,1,12.73,100,1,14.25,100,1,12.71,100,1,14.27,700,1,12.50,700,1,14.28,100,1,12.46,100,1,14.47,100,1,12.43,700,1,14.48,700,1,ARL,337690193
2025-07-17T16:11:54.662527332Z,2025-07-17T16:11:54.662361841Z,160,2,1108,A,A,10,13.40,0,0,13.40,23,1,13.11,100,1,13.53,15,1,13.01,2,1,13.54,100,1,12.98,200,2,13.55,15,1,12.86,100,1,13.82,2,1,12.73,100,1,13.86,100,1,12.71,100,1,14.25,100,1,12.50,700,1,14.27,700,1,12.46,100,1,14.28,100,1,12.43,700,1,14.47,100,1,ARL,337790717
2025-07-17T16:11:54.663278200Z,2025-07-17T16:11:54.663112543Z,160,2,1108,C,A,10,13.40,0,0,13.40,23,1,13.11,100,1,13.53,15,1,13.01,2,1,13.54,100,1,12.98,200,2,13.55,15,1,12.86,100,1,13.82,2,1,12.73,100,1,13.86,100,1,12.71,100,1,14.25,100,1,12.50,700,1,14.27,700,1,12.46,100,1,14.28,100,1,12.43,700,1,14.47,100,1,ARL,336567213
2025-07-17T16:11:54.663278200Z,2025-07-17T16:11:54.663112543Z,160,2,1108,A,A,10,13.40,0,0,13.40,23,1,13.11,100,1,13.53,15,1,13.01,2,1,13.54,100,1,12.98,200,2,13.55,15,1,12.86,100,1,13.82,2,1,12.73,100,1,13.86,100,1,12.71,100,1,14.25,100,1,12.50,700,1,14.27,700,1,12.46,100,1,14.28,100,1,12.43,700,1,14.47,100,1,ARL,337790737
2025-07-17T16:11:54.664134026Z,2025-07-17T16:11:54.663968656Z,160,2,1108,C,A,10,13.40,0,0,13.40,23,1,13.11,100,1,13.53,15,1,13.01,2,1,13.54,100,1,12.98,200,2,13.55,15,1,12.86,100,1,13.82,2,1,12.73,100,1,13.86,100,1,12.71,100,1,14.25,100,1,12.50,700,1,14.27,700,1,12.46,100,1,14.28,100,1,12.43,700,1,14.47,100,1,ARL,335220525
2025-07-17T16:11:54.664134026Z,2025-07-17T16:11:54.663968656Z,160,2,1108,A,A,10,13.40,0,0,13.40,23,1,13.11,100,1,13.53,15,1,13.01,2,1,13.54,100,1,12.98,200,2,13.55,15,1,12.86,100,1,13.82,2,1,12.73,100,1,13.86,100,1,12.71,100,1,14.25,100,1,12.50,700,1,14.27,700,1,12.46,100,1,14.28,100,1,12.43,700,1,14.47,100,1,ARL,337790745
2025-07-17T16:11:54.666326600Z,2025-07-17T16:11:54.666160990Z,160,2,1108,C,A,10,13.40,0,0,13.40,23,1,13.11,100,1,13.53,15,1,13.01,2,1,13.54,100,1,12.98,200,2,13.55,15,1,12.86,100,1,13.82,2,1,12.73,100,1,13.86,100,1,12.71,100,1,14.25,100,1,12.50,700,1,14.27,700,1,12.46,100,1,14.28,100,1,12.43,700,1,14.48,700,1,ARL,335220561
2025-07-17T16:11:54.666326600Z,2025-07-17T16:11:54.666160990Z,160,2,1108,A,A,10,13.40,0,0,13.40,23,1,13.11,100,1,13.53,15,1,13.01,2,1,13.54,100,1,12.98,200,2,13.55,15,1,12.86,100,1,13.82,2,1,12.73,100,1,13.86,100,1,12.71,100,1,14.25,100,1,12.50,700,1,14.27,700,1,12.46,100,1,14.28,100,1,12.43,700,1,14.33,100,1,ARL,337790761
2025-07-17T16:11:54.667504546Z,2025-07-17T16:11:54.667339002Z,160,2,1108,C,A,10,13.40,0,0,13.40,23,1,13.11,100,1,13.53,15,1,13.01,2,1,13.54,100,1,12.98,200,2,13.55,15,1,12.86,100,1,13.82,2,1,12.73,100,1,13.86,100,1,12.71,100,1,14.25,100,1,12.50,700,1,14.27,700,1,12.46,100,1,14.28,100,1,12.43,700,1,14.33,100,1,ARL,335220629
2025-07-17T16:11:54.667504546Z,2025-07-17T16:11:54.667339002Z,160,2,1108,A,A,10,13.40,0,0,13.40,23,1,13.11,100,1,13.53,15,1,13.01,2,1,13.54,100,1,12.98,200,2,13.55,15,1,12.86,100,1,13.82,2,1,12.73,100,1,13.86,100,1,12.71,100,1,14.25,100,1,12.50,700,1,14.27,700,1,12.46,100,1,14.28,100,1,12.43,700,1,14.33,100,1,ARL,337790777
2025-07-17T16:11:59.382515678Z,2025-07-17T16:11:59.382350338Z,160,2,1108,C,A,10,13.40,0,0,13.40,23,1,13.11,100,1,13.53,15,1,13.01,2,1,13.54,100,1,12.98,200,2,13.82,2,1,12.86,100,1,13.86,100,1,12.73,100,1,14.25,100,1,12.71,100,1,14.27,700,1,12.50,700,1,14.28,100,1,12.46,100,1,14.33,100,1,12.43,700,1,14.48,700,1,ARL,337690189
2025-07-17T16:12:02.982078719Z,2025-07-17T16:12:02.981913204Z,160,2,1108,A,A,10,13.40,0,0,13.40,23,1,13.11,100,1,13.51,15,1,13.01,2,1,13.53,15,1,12.98,200,2,13.54,100,1,12.86,100,1,13.82,2,1,12.73,100,1,13.86,100,1,12.71,100,1,14.25,100,1,12.50,700,1,14.27,700,1,12.46,100,1,14.28,100,1,12.43,700,1,14.33,100,1,ARL,338041605
2025-07-17T16:12:03.064162605Z,2025-07-17T16:12:03.063997054Z,160,2,1108,C,A,10,13.40,0,0,13.40,23,1,13.11,100,1,13.51,15,1,13.01,2,1,13.53,15,1,12.98,200,2,13.82,2,1,12.86,100,1,13.86,100,1,12.73,100,1,14.25,100,1,12.71,100,1,14.27,700,1,12.50,700,1,14.28,100,1,12.46,100,1,14.33,100,1,12.43,700,1,14.48,700,1,ARL,337790717
2025-07-17T16:12:03.064162605Z,2025-07-17T16:12:03.063997054Z,160,2,1108,A,A,10,13.40,0,0,13.40,23,1,13.11,100,1,13.51,15,1,13.01,2,1,13.52,100,1,12.98,200,2,13.53,15,1,12.86,100,1,13.82,2,1,12.73,100,1,13.86,100,1,12.71,100,1,14.25,100,1,12.50,700,1,14.27,700,1,12.46,100,1,14.28,100,1,12.43,700,1,14.33,100,1,ARL,338044041
2025-07-17T16:12:03.068467146Z,2025-07-17T16:12:03.068301745Z,160,2,1108,C,B,10,13.40,0,0,13.40,23,1,13.11,100,1,13.51,15,1,12.98,200,2,13.52,100,1,12.86,100,1,13.53,15,1,12.73,100,1,13.82,2,1,12.71,100,1,13.86,100,1,12.50,700,1,14.25,100,1,12.46,100,1,14.27,700,1,12.43,700,1,14.28,100,1,12.42,700,1,14.33,100,1,ARL,332494213
2025-07-17T16:12:03.068467146Z,2025-07-17T16:12:03.068301745Z,160,2,1108,A,B,10,13.40,0,0,13.40,23,1,13.11,100,1,13.51,15,1,12.98,200,2,13.52,100,1,12.92,2,1,13.53,15,1,12.86,100,1,13.82,2,1,12.73,100,1,13.86,100,1,12.71,100,1,14.25,100,1,12.50,700,1,14.27,700,1,12.46,100,1,14.28,100,1,12.43,700,1,14.33,100,1,ARL,338044113
2025-07-17T16:12:03.075200038Z,2025-07-17T16:12:03.075034550Z,160,2,1108,C,A,10,13.40,0,0,13.40,23,1,13.11,100,1,13.51,15,1,12.98,200,2,13.52,100,1,12.92,2,1,13.53,15,1,12.86,100,1,13.82,2,1,12.73,100,1,14.25,100,1,12.71,100,1,14.27,700,1,12.50,700,1,14.28,100,1,12.46,100,1,14.33,100,1,12.43,700,1,14.48,700,1,ARL,336567333
2025-07-17T16:12:03.075260529Z,2025-07-17T16:12:03.075095341Z,160,2,1108,A,A,10,13.40,0,0,13.40,23,1,13.11,100,1,13.51,15,1,12.98,200,2,13.52,100,1,12.92,2,1,13.53,15,1,12.86,100,1,13.79,100,1,12.73,100,1,13.82,2,1,12.71,100,1,14.25,100,1,12.50,700,1,14.27,700,1,12.46,100,1,14.28,100,1,12.43,700,1,14.33,100,1,ARL,338044233
2025-07-17T16:12:06.775177637Z,2025-07-17T16:12:06.775011783Z,160,2,1108,C,A,10,13.40,0,0,13.40,23,1,13.11,100,1,13.51,15,1,12.98,200,2,13.52,100,1,12.92,2,1,13.53,15,1,12.86,100,1,13.79,100,1,12.73,100,1,13.82,2,1,12.71,100,1,14.25,100,1,12.50,700,1,14.27,700,1,12.46,100,1,14.28,100,1,12.43,700,1,14.33,100,1,ARL,336259225
2025-07-17T16:12:06.775177637Z,2025-07-17T16:12:06.775011783Z,160,2,1108,A,A,10,13.40,0,0,13.40,23,1,13.11,100,1,13.51,15,1,12.98,200,2,13.52,100,1,12.92,2,1,13.53,15,1,12.86,100,1,13.79,100,1,12.73,100,1,13.82,2,1,12.71,100,1,14.25,100,1,12.50,700,1,14.27,700,1,12.46,100,1,14.28,100,1,12.43,700,1,14.33,100,1,ARL,338139585
2025-07-17T16:12:06.775614536Z,2025-07-17T16:12:06.775449017Z,160,2,1108,C,A,10,13.40,0,0,13.40,23,1,13.11,100,1,13.51,15,1,12.98,200,2,13.52,100,1,12.92,2,1,13.53,15,1,12.86,100,1,13.79,100,1,12.73,100,1,13.82,2,1,12.71,100,1,14.25,100,1,12.50,700,1,14.27,700,1,12.46,100,1,14.28,100,1,12.43,700,1,14.33,100,1,ARL,336261905
2025-07-17T16:12:06.775614536Z,2025-07-17T16:12:06.775449017Z,160,2,1108,A,A,10,13.40,0,0,13.40,23,1,13.11,100,1,13.51,15,1,12.98,200,2,13.52,100,1,12.92,2,1,13.53,15,1,12.86,100,1,13.79,100,1,12.73,100,1,13.82,2,1,12.71,100,1,14.25,100,1,12.50,700,1,14.27,700,1,12.46,100,1,14.28,100,1,12.43,700,1,14.33,100,1,ARL,338139601
2025-07-17T16:12:06.779705717Z,2025-07-17T16:12:06.779540143Z,160,2,1108,C,A,10,13.40,0,0,13.40,23,1,13.11,100,1,13.51,15,1,12.98,200,2,13.52,100,1,12.92,2,1,13.79,100,1,12.86,100,1,13.82,2,1,12.73,100,1,14.25,100,1,12.71,100,1,14.27,700,1,12.50,700,1,14.28,100,1,12.46,100,1,14.33,100,1,12.43,700,1,14.40,200,2,ARL,337772837
2025-07-17T16:12:07.784698893Z,2025-07-17T16:12:07.784533539Z,160,2,1108,A,A,10,13.40,0,0,13.40,23,1,13.11,100,1,13.49,15,1,12.98,200,2,13.51,15,1,12.92,2,1,13.52,100,1,12.86,100,1,13.79,100,1,12.73,100,1,13.82,2,1,12.71,100,1,14.25,100,1,12.50,700,1,14.27,700,1,12.46,100,1,14.28,100,1,12.43,700,1,14.33,100,1,ARL,338167057
2025-07-17T16:12:08.585194585Z,2025-07-17T16:12:08.585029039Z,160,2,1108,C,A,10,13.40,0,0,13.40,23,1,13.11,100,1,13.49,15,1,12.98,200,2,13.51,15,1,12.92,2,1,13.79,100,1,12.86,100,1,13.82,2,1,12.73,100,1,14.25,100,1,12.71,100,1,14.27,700,1,12.50,700,1,14.28,100,1,12.46,100,1,14.33,100,1,12.43,700,1,14.40,200,2,ARL,338044041
2025-07-17T16:12:08.585194585Z,2025-07-17T16:12:08.585029039Z,160,2,1108,A,A,10,13.40,0,0,13.40,23,1,13.11,100,1,13.49,15,1,12.98,200,2,13.50,100,1,12.92,2,1,13.51,15,1,12.86,100,1,13.79,100,1,12.73,100,1,13.82,2,1,12.71,100,1,14.25,100,1,12.50,700,1,14.27,700,1,12.46,100,1,14.28,100,1,12.43,700,1,14.33,100,1,ARL,338180793
2025-07-17T16:12:08.585942049Z,2025-07-17T16:12:08.585776508Z,160,2,1108,C,A,10,13.40,0,0,13.40,23,1,13.11,100,1,13.49,15,1,12.98,200,2,13.50,100,1,12.92,2,1,13.51,15,1,12.86,100,1,13.79,100,1,12.73,100,1,13.82,2,1,12.71,100,1,14.25,100,1,12.50,700,1,14.27,700,1,12.46,100,1,14.28,100,1,12.43,700,1,14.33,100,1,ARL,337790737
2025-07-17T16:12:08.585942049Z,2025-07-17T16:12:08.585776508Z,160,2,1108,A,A,10,13.40,0,0,13.40,23,1,13.11,100,1,13.49,15,1,12.98,200,2,13.50,100,1,12.92,2,1,13.51,15,1,12.86,100,1,13.79,100,1,12.73,100,1,13.82,2,1,12.71,100,1,14.25,100,1,12.50,700,1,14.27,700,1,12.46,100,1,14.28,100,1,12.43,700,1,14.33,100,1,ARL,338180841
2025-07-17T16:12:18.789922022Z,2025-07-17T16:12:18.789756367Z,160,2,1108,C,A,10,13.40,0,0,13.40,23,1,13.11,100,1,13.49,15,1,12.98,200,2,13.50,100,1,12.92,2,1,13.51,15,1,12.86,100,1,13.79,100,1,12.73,100,1,14.25,100,1,12.71,100,1,14.27,700,1,12.50,700,1,14.28,100,1,12.46,100,1,14.33,100,1,12.43,700,1,14.40,200,2,ARL,336447325
2025-07-17T16:12:18.789922022Z,2025-07-17T16:12:18.789756367Z,160,2,1108,A,A,10,13.40,0,0,13.40,23,1,13.11,100,1,13.49,15,1,12.98,200,2,13.50,100,1,12.92,2,1,13.51,15,1,12.86,100,1,13.74,2,1,12.73,100,1,13.79,100,1,12.71,100,1,14.25,100,1,12.50,700,1,14.27,700,1,12.46,100,1,14.28,100,1,12.43,700,1,14.33,100,1,ARL,338371797
2025-07-17T16:12:19.370986404Z,2025-07-17T16:12:19.370820933Z,160,2,1108,A,A,10,13.40,0,0,13.40,23,1,13.11,100,1,13.49,15,1,12.98,200,2,13.50,100,1,12.92,2,1,13.51,15,1,12.86,100,1,13.74,2,1,12.73,100,1,13.79,100,1,12.71,100,1,14.25,100,1,12.50,700,1,14.27,1400,2,12.46,100,1,14.28,100,1,12.43,700,1,14.33,100,1,ARL,338382329
2025-07-17T16:12:19.371041049Z,2025-07-17T16:12:19.370875240Z,160,2,1108,C,A,10,13.40,0,0,13.40,23,1,13.11,100,1,13.49,15,1,12.98,200,2,13.50,100,1,12.92,2,1,13.51,15,1,12.86,100,1,13.74,2,1,12.73,100,1,13.79,100,1,12.71,100,1,14.25,100,1,12.50,700,1,14.27,1400,2,12.46,100,1,14.28,100,1,12.43,700,1,14.33,100,1,ARL,282920685
2025-07-17T16:12:19.696689718Z,2025-07-17T16:12:19.696521343Z,160,2,1108,C,A,10,13.40,0,0,13.40,23,1,13.11,100,1,13.50,100,1,12.98,200,2,13.51,15,1,12.92,2,1,13.74,2,1,12.86,100,1,13.79,100,1,12.73,100,1,14.25,100,1,12.71,100,1,14.27,1400,2,12.50,700,1,14.28,100,1,12.46,100,1,14.33,100,1,12.43,700,1,14.40,200,2,ARL,338167057
2025-07-17T16:12:19.711773364Z,2025-07-17T16:12:19.711591494Z,160,2,1108,C,A,10,13.40,0,0,13.40,23,1,13.11,100,1,13.50,100,1,12.98,200,2,13.74,2,1,12.92,2,1,13.79,100,1,12.86,100,1,14.25,100,1,12.73,100,1,14.27,1400,2,12.71,100,1,14.28,100,1,12.50,700,1,14.33,100,1,12.46,100,1,14.40,200,2,12.43,700,1,14.48,700,1,ARL,338041605
2025-07-17T16:12:32.761277424Z,2025-07-17T16:12:32.761112078Z,160,2,1108,A,A,10,13.40,0,0,13.40,23,1,13.11,100,1,13.48,15,1,12.98,200,2,13.50,100,1,12.92,2,1,13.74,2,1,12.86,100,1,13.79,100,1,12.73,100,1,14.25,100,1,12.71,100,1,14.27,1400,2,12.50,700,1,14.28,100,1,12.46,100,1,14.33,100,1,12.43,700,1,14.40,200,2,ARL,338707945
2025-07-17T16:12:32.761413202Z,2025-07-17T16:12:32.761246859Z,160,2,1108,C,A,10,13.40,0,0,13.40,23,1,13.11,100,1,13.48,15,1,12.98,200,2,13.74,2,1,12.92,2,1,13.79,100,1,12.86,100,1,14.25,100,1,12.73,100,1,14.27,1400,2,12.71,100,1,14.28,100,1,12.50,700,1,14.33,100,1,12.46,100,1,14.40,200,2,12.43,700,1,14.48,700,1,ARL,338180793
2025-07-17T16:12:32.761413202Z,2025-07-17T16:12:32.761246859Z,160,2,1108,A,A,10,13.40,0,0,13.40,23,1,13.11,100,1,13.48,15,1,12.98,200,2,13.49,100,1,12.92,2,1,13.74,2,1,12.86,100,1,13.79,100,1,12.73,100,1,14.25,100,1,12.71,100,1,14.27,1400,2,12.50,700,1,14.28,100,1,12.46,100,1,14.33,100,1,12.43,700,1,14.40,200,2,ARL,338707949
2025-07-17T16:12:32.779055996Z,2025-07-17T16:12:32.778890447Z,160,2,1108,C,A,10,13.40,0,0,13.40,23,1,13.11,100,1,13.48,15,1,12.98,200,2,13.49,100,1,12.92,2,1,13.74,2,1,12.86,100,1,13.79,100,1,12.73,100,1,14.25,100,1,12.71,100,1,14.27,1400,2,12.50,700,1,14.28,100,1,12.46,100,1,14.33,100,1,12.43,700,1,14.40,200,2,ARL,296387089
2025-07-17T16:12:32.779055996Z,2025-07-17T16:12:32.778890447Z,160,2,1108,A,A,10,13.40,0,0,13.40,23,1,13.11,100,1,13.48,15,1,12.98,200,2,13.49,100,1,12.92,2,1,13.74,2,1,12.86,100,1,13.79,100,1,12.73,100,1,14.25,100,1,12.71,100,1,14.27,1400,2,12.50,700,1,14.28,100,1,12.46,100,1,14.33,100,1,12.43,700,1,14.40,200,2,ARL,338708241
2025-07-17T16:12:32.804318005Z,2025-07-17T16:12:32.804152457Z,160,2,1108,A,A,10,13.40,0,0,13.40,23,1,13.11,100,1,13.48,15,1,12.98,200,2,13.49,100,1,12.92,2,1,13.74,2,1,12.86,100,1,13.79,100,1,12.73,100,1,14.25,100,1,12.71,100,1,14.27,1400,2,12.50,700,1,14.28,100,1,12.46,100,1,14.33,100,1,12.43,700,1,14.40,200,2,ARL,338709513
2025-07-17T16:12:32.804332586Z,2025-07-17T16:12:32.804166092Z,160,2,1108,C,A,10,13.40,0,0,13.40,23,1,13.11,100,1,13.48,15,1,12.98,200,2,13.49,100,1,12.92,2,1,13.74,2,1,12.86,100,1,13.79,100,1,12.73,100,1,14.25,100,1,12.71,100,1,14.27,1400,2,12.50,700,1,14.28,100,1,12.46,100,1,14.33,100,1,12.43,700,1,14.40,200,2,ARL,326730513
2025-07-17T16:12:40.993064296Z,2025-07-17T16:12:40.992898990Z,160,2,1108,C,A,10,13.40,0,0,13.40,23,1,13.11,100,1,13.48,15,1,12.98,200,2,13.74,2,1,12.92,2,1,13.79,100,1,12.86,100,1,14.25,100,1,12.73,100,1,14.27,1400,2,12.71,100,1,14.28,100,1,12.50,700,1,14.33,100,1,12.46,100,1,14.40,200,2,12.43,700,1,14.48,700,1,ARL,338707949
2025-07-17T16:12:40.993332664Z,2025-07-17T16:12:40.993167418Z,160,2,1108,C,A,10,13.40,0,0,13.40,23,1,13.11,100,1,13.48,15,1,12.98,200,2,13.74,2,1,12.92,2,1,13.79,100,1,12.86,100,1,14.25,100,1,12.73,100,1,14.27,700,1,12.71,100,1,14.28,100,1,12.50,700,1,14.33,100,1,12.46,100,1,14.40,200,2,12.43,700,1,14.48,700,1,ARL,338382329
2025-07-17T16:12:40.993333790Z,2025-07-17T16:12:40.993168470Z,160,2,1108,C,A,10,13.40,0,0,13.40,23,1,13.11,100,1,13.48,15,1,12.98,200,2,13.74,2,1,12.92,2,1,13.79,100,1,12.86,100,1,14.25,100,1,12.73,100,1,14.28,100,1,12.71,100,1,14.33,100,1,12.50,700,1,14.40,200,2,12.46,100,1,14.48,700,1,12.43,700,1,14.49,200,2,ARL,336747457
2025-07-17T16:12:40.993379626Z,2025-07-17T16:12:40.993214193Z,160,2,1108,A,A,10,13.40,0,0,13.40,23,1,13.11,100,1,13.48,15,1,12.98,200,2,13.74,2,1,12.92,2,1,13.79,100,1,12.86,100,1,14.25,100,1,12.73,100,1,14.28,100,1,12.71,100,1,14.33,100,1,12.50,700,1,14.40,200,2,12.46,100,1,14.48,700,1,12.43,700,1,14.49,200,2,ARL,338864169
2025-07-17T16:12:40.993393440Z,2025-07-17T16:12:40.993227993Z,160,2,1108,A,A,10,13.40,0,0,13.40,23,1,13.11,100,1,13.48,15,1,12.98,200,2,13.74,2,1,12.92,2,1,13.79,100,1,12.86,100,1,14.25,100,1,12.73,100,1,14.28,100,1,12.71,100,1,14.33,100,1,12.50,700,1,14.40,200,2,12.46,100,1,14.47,700,1,12.43,700,1,14.48,700,1,ARL,338864173
2025-07-17T16:12:40.993432115Z,2025-07-17T16:12:40.993266591Z,160,2,1108,A,A,10,13.40,0,0,13.40,23,1,13.11,100,1,13.48,15,1,12.98,200,2,13.74,2,1,12.92,2,1,13.79,100,1,12.86,100,1,14.25,100,1,12.73,100,1,14.28,100,1,12.71,100,1,14.33,100,1,12.50,700,1,14.40,200,2,12.46,100,1,14.47,700,1,12.43,700,1,14.48,700,1,ARL,338864177
2025-07-17T16:12:40.993445042Z,2025-07-17T16:12:40.993279810Z,160,2,1108,C,A,10,13.40,0,0,13.40,23,1,13.11,100,1,13.48,15,1,12.98,200,2,13.74,2,1,12.92,2,1,13.79,100,1,12.86,100,1,14.25,100,1,12.73,100,1,14.28,100,1,12.71,100,1,14.33,100,1,12.50,700,1,14.40,200,2,12.46,100,1,14.47,700,1,12.43,700,1,14.48,700,1,ARL,338709513
2025-07-17T16:12:40.993818130Z,2025-07-17T16:12:40.993652511Z,160,2,1108,C,A,10,13.40,0,0,13.40,23,1,13.11,100,1,13.48,15,1,12.98,200,2,13.74,2,1,12.92,2,1,13.79,100,1,12.86,100,1,14.25,100,1,12.73,100,1,14.28,100,1,12.71,100,1,14.33,100,1,12.50,700,1,14.40,200,2,12.46,100,1,14.47,700,1,12.43,700,1,14.48,700,1,ARL,338180841
2025-07-17T16:12:40.993818130Z,2025-07-17T16:12:40.993652511Z,160,2,1108,A,A,10,13.40,0,0,13.40,23,1,13.11,100,1,13.48,15,1,12.98,200,2,13.74,2,1,12.92,2,1,13.79,100,1,12.86,100,1,14.25,100,1,12.73,100,1,14.28,100,1,12.71,100,1,14.33,100,1,12.50,700,1,14.40,200,2,12.46,100,1,14.47,700,1,12.43,700,1,14.48,700,1,ARL,338864189
2025-07-17T16:12:40.994783297Z,2025-07-17T16:12:40.994617858Z,160,2,1108,C,A,10,13.40,0,0,13.40,23,1,13.11,100,1,13.48,15,1,12.98,200,2,13.74,2,1,12.92,2,1,13.79,100,1,12.86,100,1,14.25,100,1,12.73,100,1,14.28,100,1,12.71,100,1,14.33,100,1,12.50,700,1,14.40,200,2,12.46,100,1,14.47,700,1,12.43,700,1,14.48,700,1,ARL,337790745
2025-07-17T16:12:40.994783297Z,2025-07-17T16:12:40.994617858Z,160,2,1108,A,A,10,13.40,0,0,13.40,23,1,13.11,100,1,13.48,15,1,12.98,200,2,13.74,2,1,12.92,2,1,13.79,100,1,12.86,100,1,14.25,100,1,12.73,100,1,14.28,100,1,12.71,100,1,14.33,100,1,12.50,700,1,14.40,200,2,12.46,100,1,14.47,700,1,12.43,700,1,14.48,700,1,ARL,338864217
2025-07-17T16:12:40.995078856Z,2025-07-17T16:12:40.994913404Z,160,2,1108,C,A,10,13.40,0,0,13.40,23,1,13.11,100,1,13.48,15,1,12.98,200,2,13.74,2,1,12.92,2,1,13.79,100,1,12.86,100,1,14.25,100,1,12.73,100,1,14.28,100,1,12.71,100,1,14.33,100,1,12.50,700,1,14.40,200,2,12.46,100,1,14.47,700,1,12.43,700,1,14.48,700,1,ARL,338708241
2025-07-17T16:12:40.995078856Z,2025-07-17T16:12:40.994913404Z,160,2,1108,A,A,10,13.40,0,0,13.40,23,1,13.11,100,1,13.48,15,1,12.98,200,2,13.74,2,1,12.92,2,1,13.79,100,1,12.86,100,1,14.25,100,1,12.73,100,1,14.28,100,1,12.71,100,1,14.33,100,1,12.50,700,1,14.40,200,2,12.46,100,1,14.47,700,1,12.43,700,1,14.48,700,1,ARL,338864221
2025-07-17T16:12:40.995349303Z,2025-07-17T16:12:40.995183768Z,160,2,1108,C,A,10,13.40,0,0,13.40,23,1,13.11,100,1,13.48,15,1,12.98,200,2,13.74,2,1,12.92,2,1,13.79,100,1,12.86,100,1,14.25,100,1,12.73,100,1,14.28,100,1,12.71,100,1,14.33,100,1,12.50,700,1,14.40,200,2,12.46,100,1,14.47,700,1,12.43,700,1,14.48,700,1,ARL,337690641
2025-07-17T16:12:40.995349303Z,2025-07-17T16:12:40.995183768Z,160,2,1108,A,A,10,13.40,0,0,13.40,23,1,13.11,100,1,13.48,15,1,12.98,200,2,13.74,2,1,12.92,2,1,13.79,100,1,12.86,100,1,14.25,100,1,12.73,100,1,14.28,100,1,12.71,100,1,14.33,100,1,12.50,700,1,14.40,200,2,12.46,100,1,14.47,700,1,12.43,700,1,14.48,700,1,ARL,338864245
2025-07-17T16:12:40.996460080Z,2025-07-17T16:12:40.996294601Z,160,2,1108,C,A,10,13.40,0,0,13.40,23,1,13.11,100,1,13.48,15,1,12.98,200,2,13.74,2,1,12.92,2,1,13.79,100,1,12.86,100,1,14.25,100,1,12.73,100,1,14.28,100,1,12.71,100,1,14.33,100,1,12.50,700,1,14.40,200,2,12.46,100,1,14.47,700,1,12.43,700,1,14.48,700,1,ARL,336570921
2025-07-17T16:12:40.996460080Z,2025-07-17T16:12:40.996294601Z,160,2,1108,A,A,10,13.40,0,0,13.40,23,1,13.11,100,1,13.48,15,1,12.98,200,2,13.74,2,1,12.92,2,1,13.79,100,1,12.86,100,1,14.25,100,1,12.73,100,1,14.28,100,1,12.71,100,1,14.33,100,1,12.50,700,1,14.40,200,2,12.46,100,1,14.47,700,1,12.43,700,1,14.48,700,1,ARL,338864289
2025-07-17T16:12:40.997300700Z,2025-07-17T16:12:40.997135307Z,160,2,1108,C,A,10,13.40,0,0,13.40,23,1,13.11,100,1,13.48,15,1,12.98,200,2,13.74,2,1,12.92,2,1,13.79,100,1,12.86,100,1,14.25,100,1,12.73,100,1,14.28,100,1,12.71,100,1,14.40,200,2,12.50,700,1,14.47,700,1,12.46,100,1,14.48,700,1,12.43,700,1,14.49,100,1,ARL,337790761
2025-07-17T16:12:40.997422356Z,2025-07-17T16:12:40.997257014Z,160,2,1108,A,A,10,13.40,0,0,13.40,23,1,13.11,100,1,13.48,15,1,12.98,200,2,13.74,2,1,12.92,2,1,13.79,100,1,12.86,100,1,14.25,100,1,12.73,100,1,14.28,100,1,12.71,100,1,14.40,200,2,12.50,700,1,14.47,700,1,12.46,100,1,14.48,700,1,12.43,700,1,14.49,100,1,ARL,338864317
2025-07-17T16:12:41.004229622Z,2025-07-17T16:12:41.004063876Z,160,2,1108,C,A,10,13.40,0,0,13.40,23,1,13.11,100,1,13.48,15,1,12.98,200,2,13.74,2,1,12.92,2,1,13.79,100,1,12.86,100,1,14.25,100,1,12.73,100,1,14.28,100,1,12.71,100,1,14.40,200,2,12.50,700,1,14.47,700,1,12.46,100,1,14.48,700,1,12.43,700,1,14.54,700,1,ARL,337790777
2025-07-17T16:12:41.004229622Z,2025-07-17T16:12:41.004063876Z,160,2,1108,A,A,10,13.40,0,0,13.40,23,1,13.11,100,1,13.48,15,1,12.98,200,2,13.74,2,1,12.92,2,1,13.79,100,1,12.86,100,1,14.25,100,1,12.73,100,1,14.28,100,1,12.71,100,1,14.40,200,2,12.50,700,1,14.47,700,1,12.46,100,1,14.48,700,1,12.43,700,1,14.54,700,1,ARL,338864405
2025-07-17T16:12:41.005576053Z,2025-07-17T16:12:41.005406614Z,160,2,1108,A,A,10,13.40,0,0,13.40,23,1,13.11,100,1,13.48,15,1,12.98,200,2,13.49,100,1,12.92,2,1,13.74,2,1,12.86,100,1,13.79,100,1,12.73,100,1,14.25,100,1,12.71,100,1,14.28,100,1,12.50,700,1,14.40,200,2,12.46,100,1,14.47,700,1,12.43,700,1,14.48,700,1,ARL,338864581
2025-07-17T16:12:41.010638351Z,2025-07-17T16:12:41.010473041Z,160,2,1108,C,A,10,13.40,0,0,13.40,23,1,13.11,100,1,13.48,15,1,12.98,200,2,13.49,100,1,12.92,2,1,13.74,2,1,12.86,100,1,13.79,100,1,12.73,100,1,14.25,100,1,12.71,100,1,14.28,100,1,12.50,700,1,14.40,200,2,12.46,100,1,14.47,700,1,12.43,700,1,14.48,700,1,ARL,338864405
2025-07-17T16:12:41.010638351Z,2025-07-17T16:12:41.010473041Z,160,2,1108,A,A,10,13.40,0,0,13.40,23,1,13.11,100,1,13.48,15,1,12.98,200,2,13.49,100,1,12.92,2,1,13.74,2,1,12.86,100,1,13.79,100,1,12.73,100,1,14.25,100,1,12.71,100,1,14.28,100,1,12.50,700,1,14.40,200,2,12.46,100,1,14.44,100,1,12.43,700,1,14.47,700,1,ARL,338865133
2025-07-17T16:12:41.011160341Z,2025-07-17T16:12:41.010994859Z,160,2,1108,C,A,10,13.40,0,0,13.40,23,1,13.11,100,1,13.48,15,1,12.98,200,2,13.49,100,1,12.92,2,1,13.74,2,1,12.86,100,1,14.25,100,1,12.73,100,1,14.28,100,1,12.71,100,1,14.40,200,2,12.50,700,1,14.44,100,1,12.46,100,1,14.47,700,1,12.43,700,1,14.48,700,1,ARL,338044233
2025-07-17T16:12:41.011211986Z,2025-07-17T16:12:41.011046717Z,160,2,1108,A,A,10,13.40,0,0,13.40,23,1,13.11,100,1,13.48,15,1,12.98,200,2,13.49,100,1,12.92,2,1,13.74,2,1,12.86,100,1,14.06,100,1,12.73,100,1,14.25,100,1,12.71,100,1,14.28,100,1,12.50,700,1,14.40,200,2,12.46,100,1,14.44,100,1,12.43,700,1,14.47,700,1,ARL,338865141
2025-07-17T16:12:41.011555342Z,2025-07-17T16:12:41.011390077Z,160,2,1108,C,A,10,13.40,0,0,13.40,23,1,13.11,100,1,13.48,15,1,12.98,200,2,13.49,100,1,12.92,2,1,13.74,2,1,12.86,100,1,14.06,100,1,12.73,100,1,14.25,100,1,12.71,100,1,14.28,100,1,12.50,700,1,14.40,200,2,12.46,100,1,14.44,100,1,12.43,700,1,14.47,700,1,ARL,338864217
2025-07-17T16:12:41.011555342Z,2025-07-17T16:12:41.011390077Z,160,2,1108,A,A,10,13.40,0,0,13.40,23,1,13.11,100,1,13.48,15,1,12.98,200,2,13.49,100,1,12.92,2,1,13.74,2,1,12.86,100,1,14.06,100,1,12.73,100,1,14.25,100,1,12.71,100,1,14.28,100,1,12.50,700,1,14.40,200,2,12.46,100,1,14.44,200,2,12.43,700,1,14.47,700,1,ARL,338865165
2025-07-17T16:12:41.012044919Z,2025-07-17T16:12:41.011879795Z,160,2,1108,C,A,10,13.40,0,0,13.40,23,1,13.11,100,1,13.48,15,1,12.98,200,2,13.49,100,1,12.92,2,1,13.74,2,1,12.86,100,1,14.25,100,1,12.73,100,1,14.28,100,1,12.71,100,1,14.40,200,2,12.50,700,1,14.44,200,2,12.46,100,1,14.47,700,1,12.43,700,1,14.48,700,1,ARL,338865141
2025-07-17T16:12:41.012094494Z,2025-07-17T16:12:41.011929033Z,160,2,1108,A,A,10,13.40,0,0,13.40,23,1,13.11,100,1,13.48,15,1,12.98,200,2,13.49,100,1,12.92,2,1,13.74,2,1,12.86,100,1,13.76,100,1,12.73,100,1,14.25,100,1,12.71,100,1,14.28,100,1,12.50,700,1,14.40,200,2,12.46,100,1,14.44,200,2,12.43,700,1,14.47,700,1,ARL,338865177
2025-07-17T16:12:41.014974491Z,2025-07-17T16:12:41.014809197Z,160,2,1108,C,A,10,13.40,0,0,13.40,23,1,13.11,100,1,13.48,15,1,12.98,200,2,13.49,100,1,12.92,2,1,13.74,2,1,12.86,100,1,13.76,100,1,12.73,100,1,14.25,100,1,12.71,100,1,14.28,100,1,12.50,700,1,14.40,200,2,12.46,100,1,14.44,200,2,12.43,700,1,14.47,700,1,ARL,338864289
2025-07-17T16:12:41.014974491Z,2025-07-17T16:12:41.014809197Z,160,2,1108,A,A,10,13.40,0,0,13.40,23,1,13.11,100,1,13.48,15,1,12.98,200,2,13.49,100,1,12.92,2,1,13.74,2,1,12.86,100,1,13.76,100,1,12.73,100,1,14.25,100,1,12.71,100,1,14.28,100,1,12.50,700,1,14.40,200,2,12.46,100,1,14.44,200,2,12.43,700,1,14.47,700,1,ARL,338865253
2025-07-17T16:12:41.017837378Z,2025-07-17T16:12:41.017672033Z,160,2,1108,C,A,10,13.40,0,0,13.40,23,1,13.11,100,1,13.48,15,1,12.98,200,2,13.49,100,1,12.92,2,1,13.74,2,1,12.86,100,1,13.76,100,1,12.73,100,1,14.25,100,1,12.71,100,1,14.28,100,1,12.50,700,1,14.40,200,2,12.46,100,1,14.44,200,2,12.43,700,1,14.47,700,1,ARL,338864245
2025-07-17T16:12:41.017837378Z,2025-07-17T16:12:41.017672033Z,160,2,1108,A,A,10,13.40,0,0,13.40,23,1,13.11,100,1,13.48,15,1,12.98,200,2,13.49,100,1,12.92,2,1,13.74,2,1,12.86,100,1,13.76,100,1,12.73,100,1,14.25,100,1,12.71,100,1,14.28,100,1,12.50,700,1,14.40,200,2,12.46,100,1,14.44,200,2,12.43,700,1,14.47,700,1,ARL,338865301
2025-07-17T16:12:41.032270817Z,2025-07-17T16:12:41.032105565Z,160,2,1108,C,A,10,13.40,0,0,13.40,23,1,13.11,100,1,13.48,15,1,12.98,200,2,13.49,100,1,12.92,2,1,13.74,2,1,12.86,100,1,13.76,100,1,12.73,100,1,14.25,100,1,12.71,100,1,14.28,100,1,12.50,700,1,14.40,200,2,12.46,100,1,14.44,200,2,12.43,700,1,14.47,700,1,ARL,338864221
2025-07-17T16:12:41.032270817Z,2025-07-17T16:12:41.032105565Z,160,2,1108,A,A,10,13.40,0,0,13.40,23,1,13.11,100,1,13.48,15,1,12.98,200,2,13.49,100,1,12.92,2,1,13.74,2,1,12.86,100,1,13.76,100,1,12.73,100,1,14.25,100,1,12.71,100,1,14.28,100,1,12.50,700,1,14.40,200,2,12.46,100,1,14.44,200,2,12.43,700,1,14.47,700,1,ARL,338866081
2025-07-17T16:12:41.032312420Z,2025-07-17T16:12:41.032147083Z,160,2,1108,A,A,10,13.40,0,0,13.40,23,1,13.11,100,1,13.48,15,1,12.98,200,2,13.49,100,1,12.92,2,1,13.74,2,1,12.86,100,1,13.76,100,1,12.73,100,1,14.25,100,1,12.71,100,1,14.28,100,1,12.50,700,1,14.40,200,2,12.46,100,1,14.44,200,2,12.43,700,1,14.47,700,1,ARL,338866089
2025-07-17T16:12:41.032324438Z,2025-07-17T16:12:41.032159348Z,160,2,1108,C,A,10,13.40,0,0,13.40,23,1,13.11,100,1,13.48,15,1,12.98,200,2,13.49,100,1,12.92,2,1,13.74,2,1,12.86,100,1,13.76,100,1,12.73,100,1,14.25,100,1,12.71,100,1,14.28,100,1,12.50,700,1,14.40,200,2,12.46,100,1,14.44,200,2,12.43,700,1,14.47,700,1,ARL,338864177
2025-07-17T16:12:41.043406383Z,2025-07-17T16:12:41.043241012Z,160,2,1108,C,A,10,13.40,0,0,13.40,23,1,13.11,100,1,13.48,15,1,12.98,200,2,13.49,100,1,12.92,2,1,13.74,2,1,12.86,100,1,13.76,100,1,12.73,100,1,14.25,100,1,12.71,100,1,14.28,100,1,12.50,700,1,14.40,200,2,12.46,100,1,14.44,200,2,12.43,700,1,14.47,700,1,ARL,338864189
2025-07-17T16:12:41.043406383Z,2025-07-17T16:12:41.043241012Z,160,2,1108,A,A,10,13.40,0,0,13.40,23,1,13.11,100,1,13.48,15,1,12.98,200,2,13.49,100,1,12.92,2,1,13.74,2,1,12.86,100,1,13.76,100,1,12.73,100,1,14.25,100,1,12.71,100,1,14.28,100,1,12.50,700,1,14.40,200,2,12.46,100,1,14.44,200,2,12.43,700,1,14.47,700,1,ARL,338866245
2025-07-17T16:12:42.001347844Z,2025-07-17T16:12:42.001182016Z,160,2,1108,C,A,10,13.40,0,0,13.40,23,1,13.11,100,1,13.48,15,1,12.98,200,2,13.49,100,1,12.92,2,1,13.74,2,1,12.86,100,1,13.76,100,1,12.73,100,1,14.25,100,1,12.71,100,1,14.28,100,1,12.50,700,1,14.40,200,2,12.46,100,1,14.44,200,2,12.43,700,1,14.47,700,1,ARL,338864317
2025-07-17T16:12:42.001347844Z,2025-07-17T16:12:42.001182016Z,160,2,1108,A,A,10,13.40,0,0,13.40,23,1,13.11,100,1,13.48,15,1,12.98,200,2,13.49,100,1,12.92,2,1,13.74,2,1,12.86,100,1,13.76,100,1,12.73,100,1,14.25,100,1,12.71,100,1,14.28,200,2,12.50,700,1,14.40,200,2,12.46,100,1,14.44,200,2,12.43,700,1,14.47,700,1,ARL,338894329
2025-07-17T16:12:42.762154469Z,2025-07-17T16:12:42.761989222Z,160,2,1108,A,A,10,13.40,0,0,13.40,23,1,13.11,100,1,13.46,15,1,12.98,200,2,13.48,15,1,12.92,2,1,13.49,100,1,12.86,100,1,13.74,2,1,12.73,100,1,13.76,100,1,12.71,100,1,14.25,100,1,12.50,700,1,14.28,200,2,12.46,100,1,14.40,200,2,12.43,700,1,14.44,200,2,ARL,338904977
2025-07-17T16:12:43.022127902Z,2025-07-17T16:12:43.021951997Z,160,2,1108,C,A,10,13.40,0,0,13.40,23,1,13.11,100,1,13.46,15,1,12.98,200,2,13.48,15,1,12.92,2,1,13.74,2,1,12.86,100,1,13.76,100,1,12.73,100,1,14.25,100,1,12.71,100,1,14.28,200,2,12.50,700,1,14.40,200,2,12.46,100,1,14.44,200,2,12.43,700,1,14.47,700,1,ARL,338864581
2025-07-17T16:12:43.022127902Z,2025-07-17T16:12:43.021951997Z,160,2,1108,A,A,10,13.40,0,0,13.40,23,1,13.11,100,1,13.46,15,1,12.98,200,2,13.47,100,1,12.92,2,1,13.48,15,1,12.86,100,1,13.74,2,1,12.73,100,1,13.76,100,1,12.71,100,1,14.25,100,1,12.50,700,1,14.28,200,2,12.46,100,1,14.40,200,2,12.43,700,1,14.44,200,2,ARL,338918217
2025-07-17T16:12:43.022612177Z,2025-07-17T16:12:43.022444956Z,160,2,1108,A,A,10,13.40,0,0,13.40,23,1,13.11,100,1,13.46,15,1,12.98,200,2,13.47,100,1,12.92,2,1,13.48,15,1,12.86,100,1,13.74,2,1,12.73,100,1,13.76,100,1,12.71,100,1,14.25,100,1,12.50,700,1,14.28,200,2,12.46,100,1,14.40,200,2,12.43,700,1,14.44,200,2,ARL,338918553
2025-07-17T16:12:43.022627592Z,2025-07-17T16:12:43.022461725Z,160,2,1108,C,A,10,13.40,0,0,13.40,23,1,13.11,100,1,13.46,15,1,12.98,200,2,13.47,100,1,12.92,2,1,13.48,15,1,12.86,100,1,13.74,2,1,12.73,100,1,13.76,100,1,12.71,100,1,14.25,100,1,12.50,700,1,14.28,200,2,12.46,100,1,14.40,200,2,12.43,700,1,14.44,200,2,ARL,338866089
2025-07-17T16:12:43.049284355Z,2025-07-17T16:12:43.049119139Z,160,2,1108,A,A,10,13.40,0,0,13.40,23,1,13.11,100,1,13.46,15,1,12.98,200,2,13.47,100,1,12.92,2,1,13.48,15,1,12.86,100,1,13.74,2,1,12.73,100,1,13.76,100,1,12.71,100,1,14.25,100,1,12.50,700,1,14.28,200,2,12.46,100,1,14.40,200,2,12.43,700,1,14.44,200,2,ARL,338926929
2025-07-17T16:12:43.049298989Z,2025-07-17T16:12:43.049132842Z,160,2,1108,C,A,10,13.40,0,0,13.40,23,1,13.11,100,1,13.46,15,1,12.98,200,2,13.47,100,1,12.92,2,1,13.48,15,1,12.86,100,1,13.74,2,1,12.73,100,1,13.76,100,1,12.71,100,1,14.25,100,1,12.50,700,1,14.28,200,2,12.46,100,1,14.40,200,2,12.43,700,1,14.44,200,2,ARL,338918553
2025-07-17T16:12:43.154952375Z,2025-07-17T16:12:43.154787212Z,160,2,1108,A,A,10,13.40,0,0,13.40,23,1,13.11,100,1,13.46,15,1,12.98,200,2,13.47,100,1,12.92,2,1,13.48,15,1,12.86,100,1,13.74,2,1,12.73,100,1,13.76,100,1,12.71,100,1,14.25,100,1,12.50,700,1,14.27,100,1,12.46,100,1,14.28,200,2,12.43,700,1,14.40,200,2,ARL,338932853
2025-07-17T16:12:43.154965183Z,2025-07-17T16:12:43.154800020Z,160,2,1108,C,A,10,13.40,0,0,13.40,23,1,13.11,100,1,13.46,15,1,12.98,200,2,13.47,100,1,12.92,2,1,13.48,15,1,12.86,100,1,13.74,2,1,12.73,100,1,13.76,100,1,12.71,100,1,14.25,100,1,12.50,700,1,14.27,100,1,12.46,100,1,14.28,200,2,12.43,700,1,14.40,200,2,ARL,296391881
2025-07-17T16:12:43.915552526Z,2025-07-17T16:12:43.915387059Z,160,2,1108,C,A,10,13.40,0,0,13.40,23,1,13.11,100,1,13.46,15,1,12.98,200,2,13.47,100,1,12.92,2,1,13.48,15,1,12.86,100,1,13.74,2,1,12.73,100,1,13.76,100,1,12.71,100,1,14.25,100,1,12.50,700,1,14.27,100,1,12.46,100,1,14.28,100,1,12.43,700,1,14.40,200,2,ARL,302681357
2025-07-17T16:12:43.915555340Z,2025-07-17T16:12:43.915389642Z,160,2,1108,A,A,10,13.40,0,0,13.40,23,1,13.11,100,1,13.46,15,1,12.98,200,2,13.47,100,1,12.92,2,1,13.48,15,1,12.86,100,1,13.74,2,1,12.73,100,1,13.76,100,1,12.71,100,1,14.00,100,1,12.50,700,1,14.25,100,1,12.46,100,1,14.27,100,1,12.43,700,1,14.28,100,1,ARL,338945933
2025-07-17T16:12:50.729244449Z,2025-07-17T16:12:50.729079105Z,160,2,1108,C,A,10,13.40,0,0,13.40,23,1,13.11,100,1,13.47,100,1,12.98,200,2,13.48,15,1,12.92,2,1,13.74,2,1,12.86,100,1,13.76,100,1,12.73,100,1,14.00,100,1,12.71,100,1,14.25,100,1,12.50,700,1,14.27,100,1,12.46,100,1,14.28,100,1,12.43,700,1,14.40,200,2,ARL,338904977
2025-07-17T16:12:50.729418237Z,2025-07-17T16:12:50.729252907Z,160,2,1108,C,A,10,13.40,0,0,13.40,23,1,13.11,100,1,13.47,100,1,12.98,200,2,13.74,2,1,12.92,2,1,13.76,100,1,12.86,100,1,14.00,100,1,12.73,100,1,14.25,100,1,12.71,100,1,14.27,100,1,12.50,700,1,14.28,100,1,12.46,100,1,14.40,200,2,12.43,700,1,14.44,200,2,ARL,338707945
2025-07-17T16:12:50.729575741Z,2025-07-17T16:12:50.729409745Z,160,2,1108,A,A,10,13.40,0,0,13.40,23,1,13.11,100,1,13.47,196,2,12.98,200,2,13.74,2,1,12.92,2,1,13.76,100,1,12.86,100,1,14.00,100,1,12.73,100,1,14.25,100,1,12.71,100,1,14.27,100,1,12.50,700,1,14.28,100,1,12.46,100,1,14.40,200,2,12.43,700,1,14.44,200,2,ARL,339054149
2025-07-17T16:12:53.021914652Z,2025-07-17T16:12:53.021749348Z,160,2,1108,A,A,10,13.40,0,0,13.40,23,1,13.11,100,1,13.46,15,1,12.98,200,2,13.47,196,2,12.92,2,1,13.74,2,1,12.86,100,1,13.76,100,1,12.73,100,1,14.00,100,1,12.71,100,1,14.25,100,1,12.50,700,1,14.27,100,1,12.46,100,1,14.28,100,1,12.43,700,1,14.40,200,2,ARL,339096733
2025-07-17T16:12:53.021959141Z,2025-07-17T16:12:53.021793735Z,160,2,1108,C,A,10,13.40,0,0,13.40,23,1,13.11,100,1,13.46,15,1,12.98,200,2,13.47,96,1,12.92,2,1,13.74,2,1,12.86,100,1,13.76,100,1,12.73,100,1,14.00,100,1,12.71,100,1,14.25,100,1,12.50,700,1,14.27,100,1,12.46,100,1,14.28,100,1,12.43,700,1,14.40,200,2,ARL,338918217
2025-07-17T16:12:53.022230122Z,2025-07-17T16:12:53.022064745Z,160,2,1108,C,A,10,13.40,0,0,13.40,23,1,13.11,100,1,13.46,15,1,12.98,200,2,13.74,2,1,12.92,2,1,13.76,100,1,12.86,100,1,14.00,100,1,12.73,100,1,14.25,100,1,12.71,100,1,14.27,100,1,12.50,700,1,14.28,100,1,12.46,100,1,14.40,200,2,12.43,700,1,14.44,200,2,ARL,339054149
2025-07-17T16:12:53.022572023Z,2025-07-17T16:12:53.022406202Z,160,2,1108,A,A,10,13.40,0,0,13.40,23,1,13.11,100,1,13.46,15,1,12.98,200,2,13.74,2,1,12.92,2,1,13.76,100,1,12.86,100,1,14.00,100,1,12.73,100,1,14.25,100,1,12.71,100,1,14.27,100,1,12.50,700,1,14.28,100,1,12.46,100,1,14.40,200,2,12.43,700,1,14.44,200,2,ARL,339096757
2025-07-17T16:12:53.022584264Z,2025-07-17T16:12:53.022418950Z,160,2,1108,C,A,10,13.40,0,0,13.40,23,1,13.11,100,1,13.46,15,1,12.98,200,2,13.74,2,1,12.92,2,1,13.76,100,1,12.86,100,1,14.00,100,1,12.73,100,1,14.25,100,1,12.71,100,1,14.27,100,1,12.50,700,1,14.28,100,1,12.46,100,1,14.40,200,2,12.43,700,1,14.44,200,2,ARL,338926929
2025-07-17T16:12:53.022962940Z,2025-07-17T16:12:53.022797046Z,160,2,1108,C,A,10,13.40,0,0,13.40,23,1,13.11,100,1,13.46,15,1,12.98,200,2,13.74,2,1,12.92,2,1,13.76,100,1,12.86,100,1,14.00,100,1,12.73,100,1,14.25,100,1,12.71,100,1,14.27,100,1,12.50,700,1,14.28,100,1,12.46,100,1,14.40,200,2,12.43,700,1,14.44,200,2,ARL,338866245
2025-07-17T16:12:53.022962940Z,2025-07-17T16:12:53.022797046Z,160,2,1108,A,A,10,13.40,0,0,13.40,23,1,13.11,100,1,13.46,15,1,12.98,200,2,13.74,2,1,12.92,2,1,13.76,100,1,12.86,100,1,14.00,100,1,12.73,100,1,14.25,100,1,12.71,100,1,14.27,100,1,12.50,700,1,14.28,100,1,12.46,100,1,14.40,200,2,12.43,700,1,14.44,200,2,ARL,339096773
2025-07-17T16:12:53.023589530Z,2025-07-17T16:12:53.023423468Z,160,2,1108,C,A,10,13.40,0,0,13.40,23,1,13.11,100,1,13.46,15,1,12.98,200,2,13.74,2,1,12.92,2,1,13.76,100,1,12.86,100,1,14.00,100,1,12.73,100,1,14.25,100,1,12.71,100,1,14.27,100,1,12.50,700,1,14.28,100,1,12.46,100,1,14.40,200,2,12.43,700,1,14.44,100,1,ARL,338865165
2025-07-17T16:12:53.023589530Z,2025-07-17T16:12:53.023423468Z,160,2,1108,A,A,10,13.40,0,0,13.40,23,1,13.11,100,1,13.46,15,1,12.98,200,2,13.74,2,1,12.92,2,1,13.76,100,1,12.86,100,1,14.00,100,1,12.73,100,1,14.25,100,1,12.71,100,1,14.27,100,1,12.50,700,1,14.28,100,1,12.46,100,1,14.40,200,2,12.43,700,1,14.44,100,1,ARL,339096797
2025-07-17T16:12:53.024069153Z,2025-07-17T16:12:53.023903582Z,160,2,1108,C,A,10,13.40,0,0,13.40,23,1,13.11,100,1,13.46,15,1,12.98,200,2,13.74,2,1,12.92,2,1,13.76,100,1,12.86,100,1,14.00,100,1,12.73,100,1,14.25,100,1,12.71,100,1,14.27,100,1,12.50,700,1,14.28,100,1,12.46,100,1,14.40,200,2,12.43,700,1,14.44,100,1,ARL,338865253
2025-07-17T16:12:53.024069153Z,2025-07-17T16:12:53.023903582Z,160,2,1108,A,A,10,13.40,0,0,13.40,23,1,13.11,100,1,13.46,15,1,12.98,200,2,13.74,2,1,12.92,2,1,13.76,100,1,12.86,100,1,14.00,100,1,12.73,100,1,14.25,100,1,12.71,100,1,14.27,100,1,12.50,700,1,14.28,100,1,12.46,100,1,14.40,200,2,12.43,700,1,14.44,100,1,ARL,339096809
2025-07-17T16:12:53.025583784Z,2025-07-17T16:12:53.025418159Z,160,2,1108,C,A,10,13.40,0,0,13.40,23,1,13.11,100,1,13.46,15,1,12.98,200,2,13.74,2,1,12.92,2,1,13.76,100,1,12.86,100,1,14.00,100,1,12.73,100,1,14.25,100,1,12.71,100,1,14.27,100,1,12.50,700,1,14.28,100,1,12.46,100,1,14.40,200,2,12.43,700,1,14.44,100,1,ARL,338866081
2025-07-17T16:12:53.025583784Z,2025-07-17T16:12:53.025418159Z,160,2,1108,A,A,10,13.40,0,0,13.40,23,1,13.11,100,1,13.46,15,1,12.98,200,2,13.74,2,1,12.92,2,1,13.76,100,1,12.86,100,1,14.00,100,1,12.73,100,1,14.25,100,1,12.71,100,1,14.27,100,1,12.50,700,1,14.28,100,1,12.46,100,1,14.40,200,2,12.43,700,1,14.44,100,1,ARL,339096813
2025-07-17T16:12:53.025651983Z,2025-07-17T16:12:53.025486466Z,160,2,1108,C,A,10,13.40,0,0,13.40,23,1,13.11,100,1,13.46,15,1,12.98,200,2,13.74,2,1,12.92,2,1,13.76,100,1,12.86,100,1,14.00,100,1,12.73,100,1,14.25,100,1,12.71,100,1,14.27,100,1,12.50,700,1,14.28,100,1,12.46,100,1,14.40,200,2,12.43,700,1,14.47,700,1,ARL,338865133
2025-07-17T16:12:53.025651983Z,2025-07-17T16:12:53.025486466Z,160,2,1108,A,A,10,13.40,0,0,13.40,23,1,13.11,100,1,13.46,15,1,12.98,200,2,13.74,2,1,12.92,2,1,13.76,100,1,12.86,100,1,14.00,100,1,12.73,100,1,14.25,100,1,12.71,100,1,14.27,100,1,12.50,700,1,14.28,100,1,12.46,100,1,14.40,200,2,12.43,700,1,14.47,700,1,ARL,339096817
2025-07-17T16:12:53.027715026Z,2025-07-17T16:12:53.027549524Z,160,2,1108,C,A,10,13.40,0,0,13.40,23,1,13.11,100,1,13.46,15,1,12.98,200,2,13.74,2,1,12.92,2,1,13.76,100,1,12.86,100,1,14.00,100,1,12.73,100,1,14.25,100,1,12.71,100,1,14.27,100,1,12.50,700,1,14.40,200,2,12.46,100,1,14.47,700,1,12.43,700,1,14.48,700,1,ARL,338894329
2025-07-17T16:12:53.027866777Z,2025-07-17T16:12:53.027701439Z,160,2,1108,A,A,10,13.40,0,0,13.40,23,1,13.11,100,1,13.46,15,1,12.98,200,2,13.74,2,1,12.92,2,1,13.76,100,1,12.86,100,1,14.00,100,1,12.73,100,1,14.25,100,1,12.71,100,1,14.27,100,1,12.50,700,1,14.40,200,2,12.46,100,1,14.47,700,1,12.43,700,1,14.48,700,1,ARL,339096833
2025-07-17T16:12:53.027987030Z,2025-07-17T16:12:53.027821450Z,160,2,1108,C,A,10,13.40,0,0,13.40,23,1,13.11,100,1,13.46,15,1,12.98,200,2,13.74,2,1,12.92,2,1,13.76,100,1,12.86,100,1,14.00,100,1,12.73,100,1,14.25,100,1,12.71,100,1,14.27,100,1,12.50,700,1,14.40,200,2,12.46,100,1,14.47,700,1,12.43,700,1,14.48,700,1,ARL,338865301
2025-07-17T16:12:53.027987030Z,2025-07-17T16:12:53.027821450Z,160,2,1108,A,A,10,13.40,0,0,13.40,23,1,13.11,100,1,13.46,15,1,12.98,200,2,13.74,2,1,12.92,2,1,13.76,100,1,12.86,100,1,14.00,100,1,12.73,100,1,14.25,100,1,12.71,100,1,14.27,100,1,12.50,700,1,14.40,200,2,12.46,100,1,14.47,700,1,12.43,700,1,14.48,700,1,ARL,339096837
2025-07-17T16:12:53.033266537Z,2025-07-17T16:12:53.033101265Z,160,2,1108,C,A,10,13.40,0,0,13.40,23,1,13.11,100,1,13.46,15,1,12.98,200,2,13.74,2,1,12.92,2,1,14.00,100,1,12.86,100,1,14.25,100,1,12.73,100,1,14.27,100,1,12.71,100,1,14.40,200,2,12.50,700,1,14.47,700,1,12.46,100,1,14.48,700,1,12.43,700,1,14.54,700,1,ARL,338865177
2025-07-17T16:12:53.033302848Z,2025-07-17T16:12:53.033137644Z,160,2,1108,C,A,10,13.40,0,0,13.40,23,1,13.11,100,1,13.46,15,1,12.98,200,2,13.74,2,1,12.92,2,1,14.00,100,1,12.86,100,1,14.25,100,1,12.73,100,1,14.27,100,1,12.71,100,1,14.40,200,2,12.50,700,1,14.48,700,1,12.46,100,1,14.54,700,1,12.43,700,1,14.55,100,1,ARL,338864173
2025-07-17T16:12:53.033318818Z,2025-07-17T16:12:53.033153612Z,160,2,1108,A,A,10,13.40,0,0,13.40,23,1,13.11,100,1,13.46,15,1,12.98,200,2,13.74,2,1,12.92,2,1,14.00,100,1,12.86,100,1,14.04,100,1,12.73,100,1,14.25,100,1,12.71,100,1,14.27,100,1,12.50,700,1,14.40,200,2,12.46,100,1,14.48,700,1,12.43,700,1,14.54,700,1,ARL,339096893
2025-07-17T16:12:53.033349323Z,2025-07-17T16:12:53.033183560Z,160,2,1108,A,A,10,13.40,0,0,13.40,23,1,13.11,100,1,13.46,15,1,12.98,200,2,13.74,2,1,12.92,2,1,14.00,100,1,12.86,100,1,14.04,100,1,12.73,100,1,14.25,100,1,12.71,100,1,14.27,100,1,12.50,700,1,14.40,200,2,12.46,100,1,14.48,700,1,12.43,700,1,14.54,700,1,ARL,339096897
2025-07-17T16:12:53.033762072Z,2025-07-17T16:12:53.033596046Z,160,2,1108,C,A,10,13.40,0,0,13.40,23,1,13.11,100,1,13.46,15,1,12.98,200,2,14.00,100,1,12.92,2,1,14.04,100,1,12.86,100,1,14.25,100,1,12.73,100,1,14.27,100,1,12.71,100,1,14.40,200,2,12.50,700,1,14.48,700,1,12.46,100,1,14.54,700,1,12.43,700,1,14.55,100,1,ARL,338371797
2025-07-17T16:12:53.033762072Z,2025-07-17T16:12:53.033596046Z,160,2,1108,A,A,10,13.40,0,0,13.40,23,1,13.11,100,1,13.46,15,1,12.98,200,2,13.98,2,1,12.92,2,1,14.00,100,1,12.86,100,1,14.04,100,1,12.73,100,1,14.25,100,1,12.71,100,1,14.27,100,1,12.50,700,1,14.40,200,2,12.46,100,1,14.48,700,1,12.43,700,1,14.54,700,1,ARL,339096909
2025-07-17T16:12:53.034000646Z,2025-07-17T16:12:53.033835120Z,160,2,1108,C,A,10,13.40,0,0,13.40,23,1,13.11,100,1,13.46,15,1,12.98,200,2,13.98,2,1,12.92,2,1,14.00,100,1,12.86,100,1,14.04,100,1,12.73,100,1,14.27,100,1,12.71,100,1,14.40,200,2,12.50,700,1,14.48,700,1,12.46,100,1,14.54,700,1,12.43,700,1,14.55,100,1,ARL,336161365
2025-07-17T16:12:53.034142471Z,2025-07-17T16:12:53.033977054Z,160,2,1108,C,A,10,13.40,0,0,13.40,23,1,13.11,100,1,13.46,15,1,12.98,200,2,13.98,2,1,12.92,2,1,14.00,100,1,12.86,100,1,14.04,100,1,12.73,100,1,14.27,100,1,12.71,100,1,14.40,200,2,12.50,700,1,14.48,700,1,12.46,100,1,14.54,700,1,12.43,700,1,14.55,100,1,ARL,339096797
2025-07-17T16:12:53.034142471Z,2025-07-17T16:12:53.033977054Z,160,2,1108,A,A,10,13.40,0,0,13.40,23,1,13.11,100,1,13.46,15,1,12.98,200,2,13.98,2,1,12.92,2,1,14.00,100,1,12.86,100,1,14.04,100,1,12.73,100,1,14.27,100,1,12.71,100,1,14.40,200,2,12.50,700,1,14.48,700,1,12.46,100,1,14.54,700,1,12.43,700,1,14.55,100,1,ARL,339096917
2025-07-17T16:12:53.034178176Z,2025-07-17T16:12:53.034012618Z,160,2,1108,C,A,10,13.40,0,0,13.40,23,1,13.11,100,1,13.46,15,1,12.98,200,2,13.98,2,1,12.92,2,1,14.00,100,1,12.86,100,1,14.04,100,1,12.73,100,1,14.27,100,1,12.71,100,1,14.40,200,2,12.50,700,1,14.48,700,1,12.46,100,1,14.54,700,1,12.43,700,1,14.55,100,1,ARL,339096837
2025-07-17T16:12:53.034178176Z,2025-07-17T16:12:53.034012618Z,160,2,1108,A,A,10,13.40,0,0,13.40,23,1,13.11,100,1,13.46,15,1,12.98,200,2,13.98,2,1,12.92,2,1,14.00,100,1,12.86,100,1,14.04,100,1,12.73,100,1,14.27,100,1,12.71,100,1,14.40,200,2,12.50,700,1,14.48,700,1,12.46,100,1,14.54,700,1,12.43,700,1,14.55,100,1,ARL,339096921
2025-07-17T16:12:53.034353140Z,2025-07-17T16:12:53.034187864Z,160,2,1108,A,A,10,13.40,0,0,13.40,23,1,13.11,100,1,13.46,15,1,12.98,200,2,13.98,2,1,12.92,2,1,14.00,100,1,12.86,100,1,14.04,100,1,12.73,100,1,14.27,100,1,12.71,100,1,14.40,200,2,12.50,700,1,14.48,700,1,12.46,100,1,14.54,700,1,12.43,700,1,14.55,100,1,ARL,339096925
2025-07-17T16:12:53.035411748Z,2025-07-17T16:12:53.035246187Z,160,2,1108,C,A,10,13.40,0,0,13.40,23,1,13.11,100,1,13.46,15,1,12.98,200,2,13.98,2,1,12.92,2,1,14.00,100,1,12.86,100,1,14.04,100,1,12.73,100,1,14.27,100,1,12.71,100,1,14.40,200,2,12.50,700,1,14.48,700,1,12.46,100,1,14.54,700,1,12.43,700,1,14.55,100,1,ARL,335220549
2025-07-17T16:12:53.035411748Z,2025-07-17T16:12:53.035246187Z,160,2,1108,A,A,10,13.40,0,0,13.40,23,1,13.11,100,1,13.46,15,1,12.98,200,2,13.98,2,1,12.92,2,1,14.00,100,1,12.86,100,1,14.04,100,1,12.73,100,1,14.27,100,1,12.71,100,1,14.40,200,2,12.50,700,1,14.48,700,1,12.46,100,1,14.54,700,1,12.43,700,1,14.55,100,1,ARL,339096929
2025-07-17T16:12:53.036307382Z,2025-07-17T16:12:53.036142164Z,160,2,1108,C,A,10,13.40,0,0,13.40,23,1,13.11,100,1,13.46,15,1,12.98,200,2,13.98,2,1,12.92,2,1,14.00,100,1,12.86,100,1,14.04,100,1,12.73,100,1,14.27,100,1,12.71,100,1,14.40,200,2,12.50,700,1,14.48,700,1,12.46,100,1,14.54,700,1,12.43,700,1,14.55,100,1,ARL,339096809
2025-07-17T16:12:53.036307382Z,2025-07-17T16:12:53.036142164Z,160,2,1108,A,A,10,13.40,0,0,13.40,23,1,13.11,100,1,13.46,15,1,12.98,200,2,13.98,2,1,12.92,2,1,14.00,100,1,12.86,100,1,14.04,100,1,12.73,100,1,14.27,100,1,12.71,100,1,14.40,200,2,12.50,700,1,14.48,700,1,12.46,100,1,14.54,700,1,12.43,700,1,14.55,100,1,ARL,339096949
2025-07-17T16:12:53.040045217Z,2025-07-17T16:12:53.039879965Z,160,2,1108,C,A,10,13.40,0,0,13.40,23,1,13.11,100,1,13.46,15,1,12.98,200,2,13.98,2,1,12.92,2,1,14.00,100,1,12.86,100,1,14.04,100,1,12.73,100,1,14.27,100,1,12.71,100,1,14.40,200,2,12.50,700,1,14.48,700,1,12.46,100,1,14.54,700,1,12.43,700,1,14.55,100,1,ARL,339096817
2025-07-17T16:12:53.040045217Z,2025-07-17T16:12:53.039879965Z,160,2,1108,A,A,10,13.40,0,0,13.40,23,1,13.11,100,1,13.46,15,1,12.98,200,2,13.98,2,1,12.92,2,1,14.00,100,1,12.86,100,1,14.04,100,1,12.73,100,1,14.27,100,1,12.71,100,1,14.40,200,2,12.50,700,1,14.48,700,1,12.46,100,1,14.54,700,1,12.43,700,1,14.55,100,1,ARL,339096977
2025-07-17T16:12:53.043727225Z,2025-07-17T16:12:53.043562198Z,160,2,1108,C,A,10,13.40,0,0,13.40,23,1,13.11,100,1,13.46,15,1,12.98,200,2,13.98,2,1,12.92,2,1,14.00,100,1,12.86,100,1,14.27,100,1,12.73,100,1,14.40,200,2,12.71,100,1,14.48,700,1,12.50,700,1,14.54,700,1,12.46,100,1,14.55,100,1,12.43,700,1,14.56,700,1,ARL,339096893
2025-07-17T16:12:53.043775299Z,2025-07-17T16:12:53.043610101Z,160,2,1108,A,A,10,13.40,0,0,13.40,23,1,13.11,100,1,13.46,15,1,12.98,200,2,13.98,2,1,12.92,2,1,14.00,100,1,12.86,100,1,14.26,100,1,12.73,100,1,14.27,100,1,12.71,100,1,14.40,200,2,12.50,700,1,14.48,700,1,12.46,100,1,14.54,700,1,12.43,700,1,14.55,100,1,ARL,339097005
2025-07-17T16:12:53.073052597Z,2025-07-17T16:12:53.072887133Z,160,2,1108,C,A,10,13.40,0,0,13.40,23,1,13.11,100,1,13.46,15,1,12.98,200,2,13.98,2,1,12.92,2,1,14.00,100,1,12.86,100,1,14.26,100,1,12.73,100,1,14.27,100,1,12.71,100,1,14.40,200,2,12.50,700,1,14.48,700,1,12.46,100,1,14.54,700,1,12.43,700,1,14.55,100,1,ARL,339096773
2025-07-17T16:12:53.073052597Z,2025-07-17T16:12:53.072887133Z,160,2,1108,A,A,10,13.40,0,0,13.40,23,1,13.11,100,1,13.46,15,1,12.98,200,2,13.98,2,1,12.92,2,1,14.00,100,1,12.86,100,1,14.26,100,1,12.73,100,1,14.27,100,1,12.71,100,1,14.40,200,2,12.50,700,1,14.48,700,1,12.46,100,1,14.54,700,1,12.43,700,1,14.55,100,1,ARL,339097245
2025-07-17T16:12:53.332729487Z,2025-07-17T16:12:53.332564148Z,160,2,1108,C,A,10,13.40,0,0,13.40,23,1,13.11,100,1,13.46,15,1,12.98,200,2,13.98,2,1,12.92,2,1,14.26,100,1,12.86,100,1,14.27,100,1,12.73,100,1,14.40,200,2,12.71,100,1,14.48,700,1,12.50,700,1,14.54,700,1,12.46,100,1,14.55,100,1,12.43,700,1,14.56,700,1,ARL,338945933
2025-07-17T16:12:53.332730508Z,2025-07-17T16:12:53.332565150Z,160,2,1108,A,A,10,13.40,0,0,13.40,23,1,13.11,100,1,13.46,15,1,12.98,200,2,13.98,2,1,12.92,2,1,14.26,100,1,12.86,100,1,14.27,100,1,12.73,100,1,14.40,200,2,12.71,100,1,14.48,700,1,12.50,700,1,14.53,100,1,12.46,100,1,14.54,700,1,12.43,700,1,14.55,100,1,ARL,339100477
2025-07-17T16:12:53.587788615Z,2025-07-17T16:12:53.587623157Z,160,2,1108,A,A,10,13.40,0,0,13.40,23,1,13.11,100,1,13.46,15,1,12.98,200,2,13.98,2,1,12.92,2,1,14.26,100,1,12.86,100,1,14.27,100,1,12.73,100,1,14.40,200,2,12.71,100,1,14.48,700,1,12.50,700,1,14.53,100,1,12.46,100,1,14.54,700,1,12.43,700,1,14.55,100,1,ARL,339103269
2025-07-17T16:12:53.587810242Z,2025-07-17T16:12:53.587644886Z,160,2,1108,C,A,10,13.40,0,0,13.40,23,1,13.11,100,1,13.46,15,1,12.98,200,2,13.98,2,1,12.92,2,1,14.26,100,1,12.86,100,1,14.40,200,2,12.73,100,1,14.48,700,1,12.71,100,1,14.53,100,1,12.50,700,1,14.54,700,1,12.46,100,1,14.55,100,1,12.43,700,1,14.56,700,1,ARL,338932853
2025-07-17T16:12:54.015217279Z,2025-07-17T16:12:54.015051915Z,160,2,1108,A,A,10,13.40,0,0,13.40,23,1,13.11,100,1,13.46,15,1,12.98,200,2,13.47,100,1,12.92,2,1,13.98,2,1,12.86,100,1,14.26,100,1,12.73,100,1,14.40,200,2,12.71,100,1,14.48,700,1,12.50,700,1,14.53,100,1,12.46,100,1,14.54,700,1,12.43,700,1,14.55,100,1,ARL,339110853
2025-07-17T16:12:54.015951319Z,2025-07-17T16:12:54.015785325Z,160,2,1108,C,A,10,13.40,0,0,13.40,23,1,13.11,100,1,13.46,15,1,12.98,200,2,13.47,100,1,12.92,2,1,13.98,2,1,12.86,100,1,14.26,100,1,12.73,100,1,14.40,200,2,12.71,100,1,14.48,700,1,12.50,700,1,14.53,100,1,12.46,100,1,14.54,700,1,12.43,700,1,14.55,100,1,ARL,339096925
2025-07-17T16:12:54.015954059Z,2025-07-17T16:12:54.015788678Z,160,2,1108,C,A,10,13.40,0,0,13.40,23,1,13.11,100,1,13.46,15,1,12.98,200,2,13.47,100,1,12.92,2,1,13.98,2,1,12.86,100,1,14.26,100,1,12.73,100,1,14.40,200,2,12.71,100,1,14.48,700,1,12.50,700,1,14.53,100,1,12.46,100,1,14.54,700,1,12.43,700,1,14.55,100,1,ARL,339097245
2025-07-17T16:12:54.015954059Z,2025-07-17T16:12:54.015788678Z,160,2,1108,A,A,10,13.40,0,0,13.40,23,1,13.11,100,1,13.46,15,1,12.98,200,2,13.47,100,1,12.92,2,1,13.98,2,1,12.86,100,1,14.26,100,1,12.73,100,1,14.40,200,2,12.71,100,1,14.48,700,1,12.50,700,1,14.52,100,1,12.46,100,1,14.53,100,1,12.43,700,1,14.54,700,1,ARL,339110897
2025-07-17T16:12:54.016305036Z,2025-07-17T16:12:54.016139684Z,160,2,1108,A,A,10,13.40,0,0,13.40,23,1,13.11,100,1,13.46,15,1,12.98,200,2,13.47,100,1,12.92,2,1,13.98,2,1,12.86,100,1,14.07,100,1,12.73,100,1,14.26,100,1,12.71,100,1,14.40,200,2,12.50,700,1,14.48,700,1,12.46,100,1,14.52,100,1,12.43,700,1,14.53,100,1,ARL,339110909
2025-07-17T16:12:54.017154493Z,2025-07-17T16:12:54.016988897Z,160,2,1108,C,A,10,13.40,0,0,13.40,23,1,13.11,100,1,13.46,15,1,12.98,200,2,13.47,100,1,12.92,2,1,13.98,2,1,12.86,100,1,14.07,100,1,12.73,100,1,14.26,100,1,12.71,100,1,14.40,200,2,12.50,700,1,14.48,700,1,12.46,100,1,14.52,100,1,12.43,700,1,14.53,100,1,ARL,339096917
2025-07-17T16:12:54.017154493Z,2025-07-17T16:12:54.016988897Z,160,2,1108,A,A,10,13.40,0,0,13.40,23,1,13.11,100,1,13.46,15,1,12.98,200,2,13.47,100,1,12.92,2,1,13.98,2,1,12.86,100,1,14.07,100,1,12.73,100,1,14.26,100,1,12.71,100,1,14.40,200,2,12.50,700,1,14.42,100,1,12.46,100,1,14.48,700,1,12.43,700,1,14.52,100,1,ARL,339110981
2025-07-17T16:12:54.017381126Z,2025-07-17T16:12:54.017215883Z,160,2,1108,C,A,10,13.40,0,0,13.40,23,1,13.11,100,1,13.46,15,1,12.98,200,2,13.47,100,1,12.92,2,1,14.07,100,1,12.86,100,1,14.26,100,1,12.73,100,1,14.40,200,2,12.71,100,1,14.42,100,1,12.50,700,1,14.48,700,1,12.46,100,1,14.52,100,1,12.43,700,1,14.53,100,1,ARL,339096909
2025-07-17T16:12:54.017381126Z,2025-07-17T16:12:54.017215883Z,160,2,1108,A,A,10,13.40,0,0,13.40,23,1,13.11,100,1,13.46,15,1,12.98,200,2,13.47,100,1,12.92,2,1,13.73,2,1,12.86,100,1,14.07,100,1,12.73,100,1,14.26,100,1,12.71,100,1,14.40,200,2,12.50,700,1,14.42,100,1,12.46,100,1,14.48,700,1,12.43,700,1,14.52,100,1,ARL,339110993
2025-07-17T16:12:54.017787766Z,2025-07-17T16:12:54.017622232Z,160,2,1108,C,A,10,13.40,0,0,13.40,23,1,13.11,100,1,13.46,15,1,12.98,200,2,13.47,100,1,12.92,2,1,13.73,2,1,12.86,100,1,14.07,100,1,12.73,100,1,14.26,100,1,12.71,100,1,14.40,200,2,12.50,700,1,14.42,100,1,12.46,100,1,14.48,700,1,12.43,700,1,14.52,100,1,ARL,339096929
2025-07-17T16:12:54.017787766Z,2025-07-17T16:12:54.017622232Z,160,2,1108,A,A,10,13.40,0,0,13.40,23,1,13.11,100,1,13.46,15,1,12.98,200,2,13.47,100,1,12.92,2,1,13.73,2,1,12.86,100,1,14.07,100,1,12.73,100,1,14.26,100,1,12.71,100,1,14.40,200,2,12.50,700,1,14.42,100,1,12.46,100,1,14.48,700,1,12.43,700,1,14.52,100,1,ARL,339111005
2025-07-17T16:12:54.020179178Z,2025-07-17T16:12:54.020013940Z,160,2,1108,C,A,10,13.40,0,0,13.40,23,1,13.11,100,1,13.46,15,1,12.98,200,2,13.47,100,1,12.92,2,1,13.73,2,1,12.86,100,1,14.07,100,1,12.73,100,1,14.40,200,2,12.71,100,1,14.42,100,1,12.50,700,1,14.48,700,1,12.46,100,1,14.52,100,1,12.43,700,1,14.53,100,1,ARL,339097005
2025-07-17T16:12:54.020233019Z,2025-07-17T16:12:54.020067630Z,160,2,1108,A,A,10,13.40,0,0,13.40,23,1,13.11,100,1,13.46,15,1,12.98,200,2,13.47,100,1,12.92,2,1,13.73,2,1,12.86,100,1,13.74,100,1,12.73,100,1,14.07,100,1,12.71,100,1,14.40,200,2,12.50,700,1,14.42,100,1,12.46,100,1,14.48,700,1,12.43,700,1,14.52,100,1,ARL,339111029
2025-07-17T16:12:54.023027943Z,2025-07-17T16:12:54.022862493Z,160,2,1108,C,A,10,13.40,0,0,13.40,23,1,13.11,100,1,13.46,15,1,12.98,200,2,13.47,100,1,12.92,2,1,13.73,2,1,12.86,100,1,13.74,100,1,12.73,100,1,14.07,100,1,12.71,100,1,14.40,200,2,12.50,700,1,14.42,100,1,12.46,100,1,14.48,700,1,12.43,700,1,14.52,100,1,ARL,339096949
2025-07-17T16:12:54.023027943Z,2025-07-17T16:12:54.022862493Z,160,2,1108,A,A,10,13.40,0,0,13.40,23,1,13.11,100,1,13.46,15,1,12.98,200,2,13.47,100,1,12.92,2,1,13.73,2,1,12.86,100,1,13.74,100,1,12.73,100,1,14.07,100,1,12.71,100,1,14.40,200,2,12.50,700,1,14.42,100,1,12.46,100,1,14.48,700,1,12.43,700,1,14.52,100,1,ARL,339111097
2025-07-17T16:12:54.026187354Z,2025-07-17T16:12:54.026021681Z,160,2,1108,C,A,10,13.40,0,0,13.40,23,1,13.11,100,1,13.46,15,1,12.98,200,2,13.47,100,1,12.92,2,1,13.73,2,1,12.86,100,1,13.74,100,1,12.73,100,1,14.07,100,1,12.71,100,1,14.40,200,2,12.50,700,1,14.42,100,1,12.46,100,1,14.48,700,1,12.43,700,1,14.52,100,1,ARL,339096921
2025-07-17T16:12:54.026187354Z,2025-07-17T16:12:54.026021681Z,160,2,1108,A,A,10,13.40,0,0,13.40,23,1,13.11,100,1,13.46,15,1,12.98,200,2,13.47,100,1,12.92,2,1,13.73,2,1,12.86,100,1,13.74,100,1,12.73,100,1,14.07,100,1,12.71,100,1,14.40,200,2,12.50,700,1,14.42,100,1,12.46,100,1,14.48,700,1,12.43,700,1,14.52,100,1,ARL,339111149
2025-07-17T16:12:54.029232379Z,2025-07-17T16:12:54.029066847Z,160,2,1108,C,A,10,13.40,0,0,13.40,23,1,13.11,100,1,13.46,15,1,12.98,200,2,13.47,100,1,12.92,2,1,13.73,2,1,12.86,100,1,13.74,100,1,12.73,100,1,14.07,100,1,12.71,100,1,14.40,200,2,12.50,700,1,14.42,100,1,12.46,100,1,14.48,700,1,12.43,700,1,14.52,100,1,ARL,339096833
2025-07-17T16:12:54.029232379Z,2025-07-17T16:12:54.029066847Z,160,2,1108,A,A,10,13.40,0,0,13.40,23,1,13.11,100,1,13.46,15,1,12.98,200,2,13.47,100,1,12.92,2,1,13.73,2,1,12.86,100,1,13.74,100,1,12.73,100,1,14.07,100,1,12.71,100,1,14.26,100,1,12.50,700,1,14.40,200,2,12.46,100,1,14.42,100,1,12.43,700,1,14.48,700,1,ARL,339111189
2025-07-17T16:12:54.055257401Z,2025-07-17T16:12:54.055092122Z,160,2,1108,A,A,10,13.40,0,0,13.40,23,1,13.11,100,1,13.46,15,1,12.98,200,2,13.47,100,1,12.92,2,1,13.73,2,1,12.86,100,1,13.74,100,1,12.73,100,1,14.07,100,1,12.71,100,1,14.26,100,1,12.50,700,1,14.40,200,2,12.46,100,1,14.42,100,1,12.43,700,1,14.48,700,1,ARL,339112469
2025-07-17T16:12:54.055269406Z,2025-07-17T16:12:54.055104415Z,160,2,1108,C,A,10,13.40,0,0,13.40,23,1,13.11,100,1,13.46,15,1,12.98,200,2,13.47,100,1,12.92,2,1,13.73,2,1,12.86,100,1,13.74,100,1,12.73,100,1,14.07,100,1,12.71,100,1,14.26,100,1,12.50,700,1,14.40,200,2,12.46,100,1,14.42,100,1,12.43,700,1,14.48,700,1,ARL,339096757
2025-07-17T16:12:54.069779810Z,2025-07-17T16:12:54.069614114Z,160,2,1108,C,A,10,13.40,0,0,13.40,23,1,13.11,100,1,13.46,15,1,12.98,200,2,13.47,100,1,12.92,2,1,13.73,2,1,12.86,100,1,13.74,100,1,12.73,100,1,14.07,100,1,12.71,100,1,14.26,100,1,12.50,700,1,14.40,200,2,12.46,100,1,14.42,100,1,12.43,700,1,14.48,700,1,ARL,339096977
2025-07-17T16:12:54.069779810Z,2025-07-17T16:12:54.069614114Z,160,2,1108,A,A,10,13.40,0,0,13.40,23,1,13.11,100,1,13.46,15,1,12.98,200,2,13.47,100,1,12.92,2,1,13.73,2,1,12.86,100,1,13.74,100,1,12.73,100,1,14.07,100,1,12.71,100,1,14.26,100,1,12.50,700,1,14.40,200,2,12.46,100,1,14.42,200,2,12.43,700,1,14.48,700,1,ARL,339112945
2025-07-17T16:12:54.072881596Z,2025-07-17T16:12:54.072716256Z,160,2,1108,C,A,10,13.40,0,0,13.40,23,1,13.11,100,1,13.46,15,1,12.98,200,2,13.47,100,1,12.92,2,1,13.73,2,1,12.86,100,1,13.74,100,1,12.73,100,1,14.07,100,1,12.71,100,1,14.26,100,1,12.50,700,1,14.40,200,2,12.46,100,1,14.42,200,2,12.43,700,1,14.48,700,1,ARL,339096813
2025-07-17T16:12:54.072881596Z,2025-07-17T16:12:54.072716256Z,160,2,1108,A,A,10,13.40,0,0,13.40,23,1,13.11,100,1,13.46,15,1,12.98,200,2,13.47,100,1,12.92,2,1,13.73,2,1,12.86,100,1,13.74,100,1,12.73,100,1,14.07,100,1,12.71,100,1,14.26,100,1,12.50,700,1,14.40,200,2,12.46,100,1,14.42,200,2,12.43,700,1,14.48,700,1,ARL,339112981
2025-07-17T16:12:54.694796063Z,2025-07-17T16:12:54.694630780Z,160,2,1108,A,A,10,13.40,0,0,13.40,23,1,13.11,100,1,13.46,15,1,12.98,200,2,13.47,100,1,12.92,2,1,13.73,2,1,12.86,100,1,13.74,100,1,12.73,100,1,14.07,100,1,12.71,100,1,14.26,100,1,12.50,700,1,14.27,100,1,12.46,100,1,14.40,200,2,12.43,700,1,14.42,200,2,ARL,339126221
2025-07-17T16:12:54.694809520Z,2025-07-17T16:12:54.694644316Z,160,2,1108,C,A,10,13.40,0,0,13.40,23,1,13.11,100,1,13.46,15,1,12.98,200,2,13.47,100,1,12.92,2,1,13.73,2,1,12.86,100,1,13.74,100,1,12.73,100,1,14.07,100,1,12.71,100,1,14.26,100,1,12.50,700,1,14.27,100,1,12.46,100,1,14.40,200,2,12.43,700,1,14.42,200,2,ARL,339103269
2025-07-17T16:12:55.255327586Z,2025-07-17T16:12:55.255162003Z,160,2,1108,A,A,10,13.40,0,0,13.40,23,1,13.11,100,1,13.46,15,1,12.98,200,2,13.47,100,1,12.92,2,1,13.73,2,1,12.86,100,1,13.74,100,1,12.73,100,1,14.00,100,1,12.71,100,1,14.07,100,1,12.50,700,1,14.26,100,1,12.46,100,1,14.27,100,1,12.43,700,1,14.40,200,2,ARL,339133353
2025-07-17T16:12:55.255328269Z,2025-07-17T16:12:55.255163083Z,160,2,1108,C,A,10,13.40,0,0,13.40,23,1,13.11,100,1,13.46,15,1,12.98,200,2,13.47,100,1,12.92,2,1,13.73,2,1,12.86,100,1,13.74,100,1,12.73,100,1,14.00,100,1,12.71,100,1,14.07,100,1,12.50,700,1,14.26,100,1,12.46,100,1,14.27,100,1,12.43,700,1,14.40,200,2,ARL,339100477
2025-07-17T16:12:58.302183447Z,2025-07-17T16:12:58.302017238Z,160,2,1108,C,A,10,13.40,0,0,13.40,23,1,13.11,100,1,13.47,100,1,12.98,200,2,13.73,2,1,12.92,2,1,13.74,100,1,12.86,100,1,14.00,100,1,12.73,100,1,14.07,100,1,12.71,100,1,14.26,100,1,12.50,700,1,14.27,100,1,12.46,100,1,14.40,200,2,12.43,700,1,14.42,200,2,ARL,339096733
2025-07-17T16:12:58.420887746Z,2025-07-17T16:12:58.420710579Z,160,2,1108,C,A,10,13.40,0,0,13.40,23,1,13.11,100,1,13.73,2,1,12.98,200,2,13.74,100,1,12.92,2,1,14.00,100,1,12.86,100,1,14.07,100,1,12.73,100,1,14.26,100,1,12.71,100,1,14.27,100,1,12.50,700,1,14.40,200,2,12.46,100,1,14.42,200,2,12.43,700,1,14.48,700,1,ARL,339110853
2025-07-17T16:12:58.420950587Z,2025-07-17T16:12:58.420776003Z,160,2,1108,A,A,10,13.40,0,0,13.40,23,1,13.11,100,1,13.47,96,1,12.98,200,2,13.73,2,1,12.92,2,1,13.74,100,1,12.86,100,1,14.00,100,1,12.73,100,1,14.07,100,1,12.71,100,1,14.26,100,1,12.50,700,1,14.27,100,1,12.46,100,1,14.40,200,2,12.43,700,1,14.42,200,2,ARL,339201549
2025-07-17T16:12:58.421338553Z,2025-07-17T16:12:58.421165414Z,160,2,1108,C,A,10,13.40,0,0,13.40,23,1,13.11,100,1,13.73,2,1,12.98,200,2,13.74,100,1,12.92,2,1,14.00,100,1,12.86,100,1,14.07,100,1,12.73,100,1,14.26,100,1,12.71,100,1,14.27,100,1,12.50,700,1,14.40,200,2,12.46,100,1,14.42,200,2,12.43,700,1,14.48,700,1,ARL,339201549
2025-07-17T16:12:58.421379924Z,2025-07-17T16:12:58.421205027Z,160,2,1108,A,A,10,13.40,0,0,13.40,23,1,13.11,100,1,13.73,2,1,12.98,200,2,13.74,100,1,12.92,2,1,14.00,100,1,12.86,100,1,14.07,100,1,12.73,100,1,14.26,100,1,12.71,100,1,14.27,100,1,12.50,700,1,14.40,200,2,12.46,100,1,14.42,200,2,12.43,700,1,14.48,700,1,ARL,339202065
2025-07-17T16:12:58.421423275Z,2025-07-17T16:12:58.421248082Z,160,2,1108,C,A,10,13.40,0,0,13.40,23,1,13.11,100,1,13.73,2,1,12.98,200,2,13.74,100,1,12.92,2,1,14.00,100,1,12.86,100,1,14.07,100,1,12.73,100,1,14.26,100,1,12.71,100,1,14.27,100,1,12.50,700,1,14.40,200,2,12.46,100,1,14.42,200,2,12.43,700,1,14.48,700,1,ARL,339112469
2025-07-17T16:12:58.421756726Z,2025-07-17T16:12:58.421581692Z,160,2,1108,C,A,10,13.40,0,0,13.40,23,1,13.11,100,1,13.73,2,1,12.98,200,2,13.74,100,1,12.92,2,1,14.00,100,1,12.86,100,1,14.26,100,1,12.73,100,1,14.27,100,1,12.71,100,1,14.40,200,2,12.50,700,1,14.42,200,2,12.46,100,1,14.48,700,1,12.43,700,1,14.52,100,1,ARL,339110909
2025-07-17T16:12:58.422145785Z,2025-07-17T16:12:58.421969675Z,160,2,1108,A,A,10,13.40,0,0,13.40,23,1,13.11,100,1,13.73,2,1,12.98,200,2,13.74,100,1,12.92,2,1,14.00,100,1,12.86,100,1,14.26,100,1,12.73,100,1,14.27,100,1,12.71,100,1,14.35,100,1,12.50,700,1,14.40,200,2,12.46,100,1,14.42,200,2,12.43,700,1,14.48,700,1,ARL,339202733
2025-07-17T16:12:58.422247877Z,2025-07-17T16:12:58.422073305Z,160,2,1108,C,A,10,13.40,0,0,13.40,23,1,13.11,100,1,13.73,2,1,12.98,200,2,13.74,100,1,12.92,2,1,14.00,100,1,12.86,100,1,14.26,100,1,12.73,100,1,14.27,100,1,12.71,100,1,14.35,100,1,12.50,700,1,14.40,200,2,12.46,100,1,14.42,200,2,12.43,700,1,14.48,700,1,ARL,339110897
2025-07-17T16:12:58.422247877Z,2025-07-17T16:12:58.422073305Z,160,2,1108,A,A,10,13.40,0,0,13.40,23,1,13.11,100,1,13.73,2,1,12.98,200,2,13.74,100,1,12.92,2,1,14.00,100,1,12.86,100,1,14.26,100,1,12.73,100,1,14.27,100,1,12.71,100,1,14.35,100,1,12.50,700,1,14.40,200,2,12.46,100,1,14.42,200,2,12.43,700,1,14.48,700,1,ARL,339202805
2025-07-17T16:12:58.424958370Z,2025-07-17T16:12:58.424789366Z,160,2,1108,C,A,10,13.40,0,0,13.40,23,1,13.11,100,1,13.73,2,1,12.98,200,2,13.74,100,1,12.92,2,1,14.00,100,1,12.86,100,1,14.26,100,1,12.73,100,1,14.27,100,1,12.71,100,1,14.35,100,1,12.50,700,1,14.40,100,1,12.46,100,1,14.42,200,2,12.43,700,1,14.48,700,1,ARL,338139585
2025-07-17T16:12:58.424958370Z,2025-07-17T16:12:58.424789366Z,160,2,1108,A,A,10,13.40,0,0,13.40,23,1,13.11,100,1,13.73,2,1,12.98,200,2,13.74,100,1,12.92,2,1,14.00,100,1,12.86,100,1,14.26,100,1,12.73,100,1,14.27,100,1,12.71,100,1,14.35,100,1,12.50,700,1,14.40,100,1,12.46,100,1,14.42,200,2,12.43,700,1,14.48,700,1,ARL,339203693
2025-07-17T16:12:58.425450176Z,2025-07-17T16:12:58.425283932Z,160,2,1108,C,A,10,13.40,0,0,13.40,23,1,13.11,100,1,13.73,2,1,12.98,200,2,13.74,100,1,12.92,2,1,14.00,100,1,12.86,100,1,14.26,100,1,12.73,100,1,14.27,100,1,12.71,100,1,14.35,100,1,12.50,700,1,14.42,200,2,12.46,100,1,14.48,700,1,12.43,700,1,14.54,700,1,ARL,338139601
2025-07-17T16:12:58.425450176Z,2025-07-17T16:12:58.425283932Z,160,2,1108,A,A,10,13.40,0,0,13.40,23,1,13.11,100,1,13.73,2,1,12.98,200,2,13.74,100,1,12.92,2,1,14.00,100,1,12.86,100,1,14.26,100,1,12.73,100,1,14.27,100,1,12.71,100,1,14.35,100,1,12.50,700,1,14.42,200,2,12.46,100,1,14.48,700,1,12.43,700,1,14.54,700,1,ARL,339203897
2025-07-17T16:12:58.426423622Z,2025-07-17T16:12:58.426258092Z,160,2,1108,C,A,10,13.40,0,0,13.40,23,1,13.11,100,1,13.73,2,1,12.98,200,2,13.74,100,1,12.92,2,1,14.00,100,1,12.86,100,1,14.27,100,1,12.73,100,1,14.35,100,1,12.71,100,1,14.42,200,2,12.50,700,1,14.48,700,1,12.46,100,1,14.54,700,1,12.43,700,1,14.56,700,1,ARL,339111189
2025-07-17T16:12:58.426544477Z,2025-07-17T16:12:58.426378483Z,160,2,1108,A,A,10,13.40,0,0,13.40,23,1,13.11,100,1,13.73,2,1,12.98,200,2,13.74,100,1,12.92,2,1,14.00,100,1,12.86,100,1,14.27,100,1,12.73,100,1,14.35,100,1,12.71,100,1,14.42,200,2,12.50,700,1,14.48,700,1,12.46,100,1,14.53,100,1,12.43,700,1,14.54,700,1,ARL,339204077
2025-07-17T16:12:58.430830694Z,2025-07-17T16:12:58.430665639Z,160,2,1108,C,A,10,13.40,0,0,13.40,23,1,13.11,100,1,13.73,2,1,12.98,200,2,14.00,100,1,12.92,2,1,14.27,100,1,12.86,100,1,14.35,100,1,12.73,100,1,14.42,200,2,12.71,100,1,14.48,700,1,12.50,700,1,14.53,100,1,12.46,100,1,14.54,700,1,12.43,700,1,14.56,700,1,ARL,339111029
2025-07-17T16:12:58.430888526Z,2025-07-17T16:12:58.430720526Z,160,2,1108,A,A,10,13.40,0,0,13.40,23,1,13.11,100,1,13.73,2,1,12.98,200,2,14.00,100,1,12.92,2,1,14.01,100,1,12.86,100,1,14.27,100,1,12.73,100,1,14.35,100,1,12.71,100,1,14.42,200,2,12.50,700,1,14.48,700,1,12.46,100,1,14.53,100,1,12.43,700,1,14.54,700,1,ARL,339205213
2025-07-17T16:12:58.432901795Z,2025-07-17T16:12:58.432736189Z,160,2,1108,C,A,10,13.40,0,0,13.40,23,1,13.11,100,1,13.73,2,1,12.98,200,2,14.00,100,1,12.92,2,1,14.01,100,1,12.86,100,1,14.27,100,1,12.73,100,1,14.35,100,1,12.71,100,1,14.42,200,2,12.50,700,1,14.48,700,1,12.46,100,1,14.53,100,1,12.43,700,1,14.54,700,1,ARL,339111005
2025-07-17T16:12:58.432901795Z,2025-07-17T16:12:58.432736189Z,160,2,1108,A,A,10,13.40,0,0,13.40,23,1,13.11,100,1,13.73,2,1,12.98,200,2,14.00,100,1,12.92,2,1,14.01,100,1,12.86,100,1,14.27,100,1,12.73,100,1,14.35,100,1,12.71,100,1,14.42,200,2,12.50,700,1,14.48,700,1,12.46,100,1,14.53,100,1,12.43,700,1,14.54,700,1,ARL,339206141
2025-07-17T16:12:58.438073339Z,2025-07-17T16:12:58.437907652Z,160,2,1108,C,B,10,13.40,0,0,13.40,23,1,13.11,100,1,13.73,2,1,12.98,200,2,14.00,100,1,12.86,100,1,14.01,100,1,12.73,100,1,14.27,100,1,12.71,100,1,14.35,100,1,12.50,700,1,14.42,200,2,12.46,100,1,14.48,700,1,12.43,700,1,14.53,100,1,12.42,700,1,14.54,700,1,ARL,338044113
2025-07-17T16:12:58.438073339Z,2025-07-17T16:12:58.437907652Z,160,2,1108,A,B,10,13.40,0,0,13.40,23,1,13.11,100,1,13.73,2,1,13.02,2,1,14.00,100,1,12.98,200,2,14.01,100,1,12.86,100,1,14.27,100,1,12.73,100,1,14.35,100,1,12.71,100,1,14.42,200,2,12.50,700,1,14.48,700,1,12.46,100,1,14.53,100,1,12.43,700,1,14.54,700,1,ARL,339207125
2025-07-17T16:12:58.438076762Z,2025-07-17T16:12:58.437911392Z,160,2,1108,C,A,10,13.40,0,0,13.40,23,1,13.11,100,1,14.00,100,1,13.02,2,1,14.01,100,1,12.98,200,2,14.27,100,1,12.86,100,1,14.35,100,1,12.73,100,1,14.42,200,2,12.71,100,1,14.48,700,1,12.50,700,1,14.53,100,1,12.46,100,1,14.54,700,1,12.43,700,1,14.56,700,1,ARL,339110993
2025-07-17T16:12:58.438076762Z,2025-07-17T16:12:58.437911392Z,160,2,1108,A,A,10,13.40,0,0,13.40,23,1,13.11,100,1,13.98,2,1,13.02,2,1,14.00,100,1,12.98,200,2,14.01,100,1,12.86,100,1,14.27,100,1,12.73,100,1,14.35,100,1,12.71,100,1,14.42,200,2,12.50,700,1,14.48,700,1,12.46,100,1,14.53,100,1,12.43,700,1,14.54,700,1,ARL,339207129
2025-07-17T16:12:58.438843944Z,2025-07-17T16:12:58.438678961Z,160,2,1108,C,A,10,13.40,0,0,13.40,23,1,13.11,100,1,13.98,2,1,13.02,2,1,14.00,100,1,12.98,200,2,14.27,100,1,12.86,100,1,14.35,100,1,12.73,100,1,14.42,200,2,12.71,100,1,14.48,700,1,12.50,700,1,14.53,100,1,12.46,100,1,14.54,700,1,12.43,700,1,14.56,700,1,ARL,339205213
2025-07-17T16:12:58.438894336Z,2025-07-17T16:12:58.438728994Z,160,2,1108,A,A,10,13.40,0,0,13.40,23,1,13.11,100,1,13.98,2,1,13.02,2,1,14.00,100,1,12.98,200,2,14.24,100,1,12.86,100,1,14.27,100,1,12.73,100,1,14.35,100,1,12.71,100,1,14.42,200,2,12.50,700,1,14.48,700,1,12.46,100,1,14.53,100,1,12.43,700,1,14.54,700,1,ARL,339207197
2025-07-17T16:12:58.441834497Z,2025-07-17T16:12:58.441669159Z,160,2,1108,C,A,10,13.40,0,0,13.40,23,1,13.11,100,1,13.98,2,1,13.02,2,1,14.00,100,1,12.98,200,2,14.24,100,1,12.86,100,1,14.27,100,1,12.73,100,1,14.35,100,1,12.71,100,1,14.42,100,1,12.50,700,1,14.48,700,1,12.46,100,1,14.53,100,1,12.43,700,1,14.54,700,1,ARL,339110981
2025-07-17T16:12:58.441834497Z,2025-07-17T16:12:58.441669159Z,160,2,1108,A,A,10,13.40,0,0,13.40,23,1,13.11,100,1,13.98,2,1,13.02,2,1,14.00,100,1,12.98,200,2,14.24,100,1,12.86,100,1,14.27,100,1,12.73,100,1,14.35,100,1,12.71,100,1,14.42,100,1,12.50,700,1,14.48,700,1,12.46,100,1,14.53,100,1,12.43,700,1,14.54,700,1,ARL,339207505
2025-07-17T16:12:58.454376675Z,2025-07-17T16:12:58.454211242Z,160,2,1108,C,A,10,13.40,0,0,13.40,23,1,13.11,100,1,13.98,2,1,13.02,2,1,14.00,100,1,12.98,200,2,14.24,100,1,12.86,100,1,14.27,100,1,12.73,100,1,14.35,100,1,12.71,100,1,14.42,100,1,12.50,700,1,14.48,700,1,12.46,100,1,14.53,100,1,12.43,700,1,14.54,700,1,ARL,339111097
2025-07-17T16:12:58.454376675Z,2025-07-17T16:12:58.454211242Z,160,2,1108,A,A,10,13.40,0,0,13.40,23,1,13.11,100,1,13.98,2,1,13.02,2,1,14.00,100,1,12.98,200,2,14.24,100,1,12.86,100,1,14.27,100,1,12.73,100,1,14.35,100,1,12.71,100,1,14.42,100,1,12.50,700,1,14.48,700,1,12.46,100,1,14.53,100,1,12.43,700,1,14.54,700,1,ARL,339208377
2025-07-17T16:12:58.472292476Z,2025-07-17T16:12:58.472126777Z,160,2,1108,C,A,10,13.40,0,0,13.40,23,1,13.11,100,1,13.98,2,1,13.02,2,1,14.00,100,1,12.98,200,2,14.24,100,1,12.86,100,1,14.27,100,1,12.73,100,1,14.35,100,1,12.71,100,1,14.42,100,1,12.50,700,1,14.48,700,1,12.46,100,1,14.53,100,1,12.43,700,1,14.54,700,1,ARL,339111149
2025-07-17T16:12:58.472292476Z,2025-07-17T16:12:58.472126777Z,160,2,1108,A,A,10,13.40,0,0,13.40,23,1,13.11,100,1,13.98,2,1,13.02,2,1,14.00,100,1,12.98,200,2,14.24,100,1,12.86,100,1,14.27,100,1,12.73,100,1,14.35,100,1,12.71,100,1,14.42,100,1,12.50,700,1,14.48,700,1,12.46,100,1,14.53,100,1,12.43,700,1,14.54,700,1,ARL,339209241
2025-07-17T16:12:58.472624779Z,2025-07-17T16:12:58.472458830Z,160,2,1108,C,A,10,13.40,0,0,13.40,23,1,13.11,100,1,13.98,2,1,13.02,2,1,14.00,100,1,12.98,200,2,14.24,100,1,12.86,100,1,14.27,100,1,12.73,100,1,14.35,100,1,12.71,100,1,14.42,100,1,12.50,700,1,14.48,700,1,12.46,100,1,14.53,100,1,12.43,700,1,14.54,700,1,ARL,339202805
2025-07-17T16:12:58.472624779Z,2025-07-17T16:12:58.472458830Z,160,2,1108,A,A,10,13.40,0,0,13.40,23,1,13.11,100,1,13.98,2,1,13.02,2,1,14.00,100,1,12.98,200,2,14.24,100,1,12.86,100,1,14.27,100,1,12.73,100,1,14.35,100,1,12.71,100,1,14.42,100,1,12.50,700,1,14.48,700,1,12.46,100,1,14.53,100,1,12.43,700,1,14.54,700,1,ARL,339209257
2025-07-17T16:12:58.571845708Z,2025-07-17T16:12:58.571679985Z,160,2,1108,C,A,10,13.40,0,0,13.40,23,1,13.11,100,1,13.98,2,1,13.02,2,1,14.00,100,1,12.98,200,2,14.24,100,1,12.86,100,1,14.27,100,1,12.73,100,1,14.35,100,1,12.71,100,1,14.42,100,1,12.50,700,1,14.48,700,1,12.46,100,1,14.53,100,1,12.43,700,1,14.54,700,1,ARL,339112981
2025-07-17T16:12:58.571845708Z,2025-07-17T16:12:58.571679985Z,160,2,1108,A,A,10,13.40,0,0,13.40,23,1,13.11,100,1,13.98,2,1,13.02,2,1,14.00,100,1,12.98,200,2,14.24,100,1,12.86,100,1,14.27,100,1,12.73,100,1,14.35,100,1,12.71,100,1,14.42,100,1,12.50,700,1,14.48,700,1,12.46,100,1,14.53,100,1,12.43,700,1,14.54,700,1,ARL,339215205
2025-07-17T16:12:58.619404102Z,2025-07-17T16:12:58.619238614Z,160,2,1108,C,A,10,13.40,0,0,13.40,23,1,13.11,100,1,13.98,2,1,13.02,2,1,14.00,100,1,12.98,200,2,14.24,100,1,12.86,100,1,14.27,100,1,12.73,100,1,14.35,100,1,12.71,100,1,14.48,700,1,12.50,700,1,14.53,100,1,12.46,100,1,14.54,700,1,12.43,700,1,14.56,700,1,ARL,339112945
2025-07-17T16:12:58.619404102Z,2025-07-17T16:12:58.619238614Z,160,2,1108,A,A,10,13.40,0,0,13.40,23,1,13.11,100,1,13.98,2,1,13.02,2,1,14.00,100,1,12.98,200,2,14.24,100,1,12.86,100,1,14.27,100,1,12.73,100,1,14.35,100,1,12.71,100,1,14.48,700,1,12.50,700,1,14.53,100,1,12.46,100,1,14.54,700,1,12.43,700,1,14.56,700,1,ARL,339216161
2025-07-17T16:12:58.986093948Z,2025-07-17T16:12:58.985928594Z,160,2,1108,C,B,10,13.40,0,0,13.40,23,1,13.11,100,1,13.98,2,1,12.98,200,2,14.00,100,1,12.86,100,1,14.24,100,1,12.73,100,1,14.27,100,1,12.71,100,1,14.35,100,1,12.50,700,1,14.48,700,1,12.46,100,1,14.53,100,1,12.43,700,1,14.54,700,1,12.42,700,1,14.56,700,1,ARL,339207125
2025-07-17T16:12:58.986093948Z,2025-07-17T16:12:58.985928594Z,160,2,1108,A,B,10,13.40,0,0,13.40,23,1,13.11,100,1,13.98,2,1,12.98,200,2,14.00,100,1,12.86,102,2,14.24,100,1,12.73,100,1,14.27,100,1,12.71,100,1,14.35,100,1,12.50,700,1,14.48,700,1,12.46,100,1,14.53,100,1,12.43,700,1,14.54,700,1,12.42,700,1,14.56,700,1,ARL,339222617
2025-07-17T16:12:59.063108412Z,2025-07-17T16:12:59.062943193Z,160,2,1108,A,A,10,13.40,0,0,13.40,23,1,13.11,100,1,13.98,2,1,12.98,200,2,13.99,100,1,12.86,102,2,14.00,100,1,12.73,100,1,14.24,100,1,12.71,100,1,14.27,100,1,12.50,700,1,14.35,100,1,12.46,100,1,14.48,700,1,12.43,700,1,14.53,100,1,12.42,700,1,14.54,700,1,ARL,339224109
2025-07-17T16:12:59.082855570Z,2025-07-17T16:12:59.082690430Z,160,2,1108,C,A,10,13.40,0,0,13.40,23,1,13.11,100,1,13.98,2,1,12.98,200,2,13.99,100,1,12.86,102,2,14.24,100,1,12.73,100,1,14.27,100,1,12.71,100,1,14.35,100,1,12.50,700,1,14.48,700,1,12.46,100,1,14.53,100,1,12.43,700,1,14.54,700,1,12.42,700,1,14.56,700,1,ARL,339133353
2025-07-17T16:12:59.082856640Z,2025-07-17T16:12:59.082691385Z,160,2,1108,A,A,10,13.40,0,0,13.40,23,1,13.11,100,1,13.98,2,1,12.98,200,2,13.99,100,1,12.86,102,2,14.24,100,1,12.73,100,1,14.27,100,1,12.71,100,1,14.35,100,1,12.50,700,1,14.48,700,1,12.46,100,1,14.53,200,2,12.43,700,1,14.54,700,1,12.42,700,1,14.56,700,1,ARL,339225769
2025-07-17T16:12:59.088794570Z,2025-07-17T16:12:59.088629294Z,160,2,1108,A,A,10,13.40,0,0,13.40,23,1,13.11,100,1,13.98,2,1,12.98,200,2,13.99,100,1,12.86,102,2,14.24,100,1,12.73,100,1,14.27,100,1,12.71,100,1,14.35,100,1,12.50,700,1,14.48,700,1,12.46,100,1,14.53,200,2,12.43,700,1,14.54,700,1,12.42,700,1,14.56,700,1,ARL,339225885
2025-07-17T16:12:59.088808117Z,2025-07-17T16:12:59.088642718Z,160,2,1108,C,A,10,13.40,0,0,13.40,23,1,13.11,100,1,13.98,2,1,12.98,200,2,13.99,100,1,12.86,102,2,14.24,100,1,12.73,100,1,14.35,100,1,12.71,100,1,14.48,700,1,12.50,700,1,14.53,200,2,12.46,100,1,14.54,700,1,12.43,700,1,14.56,700,1,12.42,700,1,14.57,200,2,ARL,339126221
2025-07-17T16:12:59.092927842Z,2025-07-17T16:12:59.092762564Z,160,2,1108,C,A,10,13.40,0,0,13.40,23,1,13.11,100,1,13.98,2,1,12.98,200,2,13.99,100,1,12.86,102,2,14.24,100,1,12.73,100,1,14.48,700,1,12.71,100,1,14.53,200,2,12.50,700,1,14.54,700,1,12.46,100,1,14.56,700,1,12.43,700,1,14.57,200,2,12.42,700,1,14.68,700,1,ARL,339202733
2025-07-17T16:12:59.093278915Z,2025-07-17T16:12:59.093113488Z,160,2,1108,A,A,10,13.40,0,0,13.40,23,1,13.11,100,1,13.98,2,1,12.98,200,2,13.99,100,1,12.86,102,2,14.24,100,1,12.73,100,1,14.48,700,1,12.71,100,1,14.53,200,2,12.50,700,1,14.54,700,1,12.46,100,1,14.56,700,1,12.43,700,1,14.57,200,2,12.42,700,1,14.60,100,1,ARL,339226021
2025-07-17T16:12:59.430486012Z,2025-07-17T16:12:59.430320610Z,160,2,1108,C,A,10,13.40,0,0,13.40,23,1,13.11,100,1,13.98,2,1,12.98,200,2,13.99,100,1,12.86,102,2,14.24,100,1,12.73,100,1,14.48,700,1,12.71,100,1,14.53,100,1,12.50,700,1,14.54,700,1,12.46,100,1,14.56,700,1,12.43,700,1,14.57,200,2,12.42,700,1,14.60,100,1,ARL,339204077
2025-07-17T16:12:59.430486012Z,2025-07-17T16:12:59.430320610Z,160,2,1108,A,A,10,13.40,0,0,13.40,23,1,13.11,100,1,13.98,2,1,12.98,200,2,13.99,100,1,12.86,102,2,14.24,100,1,12.73,100,1,14.48,700,1,12.71,100,1,14.53,100,1,12.50,700,1,14.54,700,1,12.46,100,1,14.56,700,1,12.43,700,1,14.57,200,2,12.42,700,1,14.60,100,1,ARL,339232213
2025-07-17T16:13:04.825902166Z,2025-07-17T16:13:04.825736034Z,160,2,1108,A,A,10,13.40,0,0,13.40,23,1,13.11,100,1,13.66,15,1,12.98,200,2,13.98,2,1,12.86,102,2,13.99,100,1,12.73,100,1,14.24,100,1,12.71,100,1,14.48,700,1,12.50,700,1,14.53,100,1,12.46,100,1,14.54,700,1,12.43,700,1,14.56,700,1,12.42,700,1,14.57,200,2,ARL,339332865
