ts_recv,ts_event,rtype,publisher_id,instrument_id,action,side,depth,price,size,flags,ts_in_delta,sequence,bid_px_00,bid_sz_00,bid_ct_00,ask_px_00,ask_sz_00,ask_ct_00,bid_px_01,bid_sz_01,bid_ct_01,ask_px_01,ask_sz_01,ask_ct_01,bid_px_02,bid_sz_02,bid_ct_02,ask_px_02,ask_sz_02,ask_ct_02,bid_px_03,bid_sz_03,bid_ct_03,ask_px_03,ask_sz_03,ask_ct_03,bid_px_04,bid_sz_04,bid_ct_04,ask_px_04,ask_sz_04,ask_ct_04,bid_px_05,bid_sz_05,bid_ct_05,ask_px_05,ask_sz_05,ask_ct_05,bid_px_06,bid_sz_06,bid_ct_06,ask_px_06,ask_sz_06,ask_ct_06,bid_px_07,bid_sz_07,bid_ct_07,ask_px_07,ask_sz_07,ask_ct_07,bid_px_08,bid_sz_08,bid_ct_08,ask_px_08,ask_sz_08,ask_ct_08,bid_px_09,bid_sz_09,bid_ct_09,ask_px_09,ask_sz_09,ask_ct_09,symbol,order_id
2025-07-17T16:13:06.189275812Z,2025-07-17T16:13:06.189110140Z,160,2,1108,C,B,10,13.40,0,0,13.40,23,1,13.11,100,1,13.66,15,1,12.98,200,2,13.98,2,1,12.86,100,1,13.99,100,1,12.73,100,1,14.24,100,1,12.71,100,1,14.48,700,1,12.50,700,1,14.53,100,1,12.46,100,1,14.54,700,1,12.43,700,1,14.56,700,1,12.42,700,1,14.57,200,2,ARL,339222617
2025-07-17T16:13:06.189275812Z,2025-07-17T16:13:06.189110140Z,160,2,1108,A,B,10,13.40,0,0,13.40,23,1,13.11,100,1,13.66,15,1,12.98,200,2,13.98,2,1,12.96,2,1,13.99,100,1,12.86,100,1,14.24,100,1,12.73,100,1,14.48,700,1,12.71,100,1,14.53,100,1,12.50,700,1,14.54,700,1,12.46,100,1,14.56,700,1,12.43,700,1,14.57,200,2,ARL,339356397
2025-07-17T16:13:06.224898389Z,2025-07-17T16:13:06.224732787Z,160,2,1108,C,A,10,13.40,0,0,13.40,23,1,13.11,100,1,13.66,15,1,12.98,200,2,13.98,2,1,12.96,2,1,14.24,100,1,12.86,100,1,14.48,700,1,12.73,100,1,14.53,100,1,12.71,100,1,14.54,700,1,12.50,700,1,14.56,700,1,12.46,100,1,14.57,200,2,12.43,700,1,14.60,100,1,ARL,339224109
2025-07-17T16:13:06.224898389Z,2025-07-17T16:13:06.224732787Z,160,2,1108,A,A,10,13.40,0,0,13.40,23,1,13.11,100,1,13.66,15,1,12.98,200,2,13.67,100,1,12.96,2,1,13.98,2,1,12.86,100,1,14.24,100,1,12.73,100,1,14.48,700,1,12.71,100,1,14.53,100,1,12.50,700,1,14.54,700,1,12.46,100,1,14.56,700,1,12.43,700,1,14.57,200,2,ARL,339358233
2025-07-17T16:13:06.225642781Z,2025-07-17T16:13:06.225475518Z,160,2,1108,C,A,10,13.40,0,0,13.40,23,1,13.11,100,1,13.66,15,1,12.98,200,2,13.67,100,1,12.96,2,1,13.98,2,1,12.86,100,1,14.24,100,1,12.73,100,1,14.48,700,1,12.71,100,1,14.53,100,1,12.50,700,1,14.54,700,1,12.46,100,1,14.56,700,1,12.43,700,1,14.57,200,2,ARL,339209257
2025-07-17T16:13:06.225642781Z,2025-07-17T16:13:06.225475518Z,160,2,1108,A,A,10,13.40,0,0,13.40,23,1,13.11,100,1,13.66,15,1,12.98,200,2,13.67,100,1,12.96,2,1,13.98,2,1,12.86,100,1,14.24,100,1,12.73,100,1,14.48,700,1,12.71,100,1,14.53,100,1,12.50,700,1,14.54,700,1,12.46,100,1,14.56,700,1,12.43,700,1,14.57,200,2,ARL,339358293
2025-07-17T16:13:06.225642781Z,2025-07-17T16:13:06.225475906Z,160,2,1108,C,A,10,13.40,0,0,13.40,23,1,13.11,100,1,13.66,15,1,12.98,200,2,13.67,100,1,12.96,2,1,13.98,2,1,12.86,100,1,14.24,100,1,12.73,100,1,14.48,700,1,12.71,100,1,14.53,100,1,12.50,700,1,14.54,700,1,12.46,100,1,14.56,700,1,12.43,700,1,14.57,200,2,ARL,339226021
2025-07-17T16:13:06.225995297Z,2025-07-17T16:13:06.225829921Z,160,2,1108,A,A,10,13.40,0,0,13.40,23,1,13.11,100,1,13.66,15,1,12.98,200,2,13.67,100,1,12.96,2,1,13.98,2,1,12.86,100,1,14.24,100,1,12.73,100,1,14.28,100,1,12.71,100,1,14.48,700,1,12.50,700,1,14.53,100,1,12.46,100,1,14.54,700,1,12.43,700,1,14.56,700,1,ARL,339358333
2025-07-17T16:13:06.226789913Z,2025-07-17T16:13:06.226624084Z,160,2,1108,C,A,10,13.40,0,0,13.40,23,1,13.11,100,1,13.66,15,1,12.98,200,2,13.67,100,1,12.96,2,1,13.98,2,1,12.86,100,1,14.24,100,1,12.73,100,1,14.28,100,1,12.71,100,1,14.48,700,1,12.50,700,1,14.53,100,1,12.46,100,1,14.54,700,1,12.43,700,1,14.56,700,1,ARL,339206141
2025-07-17T16:13:06.226789913Z,2025-07-17T16:13:06.226624084Z,160,2,1108,A,A,10,13.40,0,0,13.40,23,1,13.11,100,1,13.66,15,1,12.98,200,2,13.67,100,1,12.96,2,1,13.98,2,1,12.86,100,1,14.24,100,1,12.73,100,1,14.28,100,1,12.71,100,1,14.48,700,1,12.50,700,1,14.53,100,1,12.46,100,1,14.54,700,1,12.43,700,1,14.56,700,1,ARL,339358349
2025-07-17T16:13:06.226882302Z,2025-07-17T16:13:06.226716697Z,160,2,1108,C,A,10,13.40,0,0,13.40,23,1,13.11,100,1,13.66,15,1,12.98,200,2,13.67,100,1,12.96,2,1,13.98,2,1,12.86,100,1,14.24,100,1,12.73,100,1,14.28,100,1,12.71,100,1,14.48,700,1,12.50,700,1,14.53,100,1,12.46,100,1,14.54,700,1,12.43,700,1,14.56,700,1,ARL,339207505
2025-07-17T16:13:06.226882302Z,2025-07-17T16:13:06.226716697Z,160,2,1108,A,A,10,13.40,0,0,13.40,23,1,13.11,100,1,13.66,15,1,12.98,200,2,13.67,100,1,12.96,2,1,13.98,2,1,12.86,100,1,14.24,100,1,12.73,100,1,14.28,100,1,12.71,100,1,14.48,700,1,12.50,700,1,14.53,100,1,12.46,100,1,14.54,700,1,12.43,700,1,14.56,700,1,ARL,339358353
2025-07-17T16:13:06.229858538Z,2025-07-17T16:13:06.229693020Z,160,2,1108,C,A,10,13.40,0,0,13.40,23,1,13.11,100,1,13.66,15,1,12.98,200,2,13.67,100,1,12.96,2,1,14.24,100,1,12.86,100,1,14.28,100,1,12.73,100,1,14.48,700,1,12.71,100,1,14.53,100,1,12.50,700,1,14.54,700,1,12.46,100,1,14.56,700,1,12.43,700,1,14.57,200,2,ARL,339207129
2025-07-17T16:13:06.229858538Z,2025-07-17T16:13:06.229693020Z,160,2,1108,A,A,10,13.40,0,0,13.40,23,1,13.11,100,1,13.66,15,1,12.98,200,2,13.67,100,1,12.96,2,1,13.81,2,1,12.86,100,1,14.24,100,1,12.73,100,1,14.28,100,1,12.71,100,1,14.48,700,1,12.50,700,1,14.53,100,1,12.46,100,1,14.54,700,1,12.43,700,1,14.56,700,1,ARL,339358409
2025-07-17T16:13:06.235594115Z,2025-07-17T16:13:06.235428434Z,160,2,1108,C,A,10,13.40,0,0,13.40,23,1,13.11,100,1,13.66,15,1,12.98,200,2,13.67,100,1,12.96,2,1,13.81,2,1,12.86,100,1,14.24,100,1,12.73,100,1,14.28,100,1,12.71,100,1,14.48,700,1,12.50,700,1,14.53,100,1,12.46,100,1,14.54,700,1,12.43,700,1,14.56,700,1,ARL,339208377
2025-07-17T16:13:06.235594115Z,2025-07-17T16:13:06.235428434Z,160,2,1108,A,A,10,13.40,0,0,13.40,23,1,13.11,100,1,13.66,15,1,12.98,200,2,13.67,100,1,12.96,2,1,13.81,2,1,12.86,100,1,14.24,100,1,12.73,100,1,14.28,100,1,12.71,100,1,14.48,700,1,12.50,700,1,14.53,100,1,12.46,100,1,14.54,700,1,12.43,700,1,14.56,700,1,ARL,339358609
2025-07-17T16:13:06.236567790Z,2025-07-17T16:13:06.236401579Z,160,2,1108,C,A,10,13.40,0,0,13.40,23,1,13.11,100,1,13.66,15,1,12.98,200,2,13.67,100,1,12.96,2,1,13.81,2,1,12.86,100,1,14.28,100,1,12.73,100,1,14.48,700,1,12.71,100,1,14.53,100,1,12.50,700,1,14.54,700,1,12.46,100,1,14.56,700,1,12.43,700,1,14.57,200,2,ARL,339207197
2025-07-17T16:13:06.236621535Z,2025-07-17T16:13:06.236456489Z,160,2,1108,A,A,10,13.40,0,0,13.40,23,1,13.11,100,1,13.66,15,1,12.98,200,2,13.67,100,1,12.96,2,1,13.81,2,1,12.86,100,1,13.94,100,1,12.73,100,1,14.28,100,1,12.71,100,1,14.48,700,1,12.50,700,1,14.53,100,1,12.46,100,1,14.54,700,1,12.43,700,1,14.56,700,1,ARL,339358741
2025-07-17T16:13:06.243909112Z,2025-07-17T16:13:06.243743642Z,160,2,1108,C,A,10,13.40,0,0,13.40,23,1,13.11,100,1,13.66,15,1,12.98,200,2,13.67,100,1,12.96,2,1,13.81,2,1,12.86,100,1,13.94,100,1,12.73,100,1,14.28,100,1,12.71,100,1,14.48,700,1,12.50,700,1,14.53,100,1,12.46,100,1,14.54,700,1,12.43,700,1,14.56,700,1,ARL,339209241
2025-07-17T16:13:06.243909112Z,2025-07-17T16:13:06.243743642Z,160,2,1108,A,A,10,13.40,0,0,13.40,23,1,13.11,100,1,13.66,15,1,12.98,200,2,13.67,100,1,12.96,2,1,13.81,2,1,12.86,100,1,13.94,100,1,12.73,100,1,14.28,100,1,12.71,100,1,14.48,700,1,12.50,700,1,14.53,100,1,12.46,100,1,14.54,700,1,12.43,700,1,14.56,700,1,ARL,339359077
2025-07-17T16:13:06.268052093Z,2025-07-17T16:13:06.267886189Z,160,2,1108,C,A,10,13.40,0,0,13.40,23,1,13.11,100,1,13.66,15,1,12.98,200,2,13.67,100,1,12.96,2,1,13.81,2,1,12.86,100,1,13.94,100,1,12.73,100,1,14.28,100,1,12.71,100,1,14.48,700,1,12.50,700,1,14.53,100,1,12.46,100,1,14.54,700,1,12.43,700,1,14.56,700,1,ARL,339215205
2025-07-17T16:13:06.268052093Z,2025-07-17T16:13:06.267886189Z,160,2,1108,A,A,10,13.40,0,0,13.40,23,1,13.11,100,1,13.66,15,1,12.98,200,2,13.67,100,1,12.96,2,1,13.81,2,1,12.86,100,1,13.94,100,1,12.73,100,1,14.28,100,1,12.71,100,1,14.48,700,1,12.50,700,1,14.53,100,1,12.46,100,1,14.54,700,1,12.43,700,1,14.56,700,1,ARL,339359357
2025-07-17T16:13:06.275886461Z,2025-07-17T16:13:06.275720866Z,160,2,1108,C,A,10,13.40,0,0,13.40,23,1,13.11,100,1,13.66,15,1,12.98,200,2,13.67,100,1,12.96,2,1,13.81,2,1,12.86,100,1,13.94,100,1,12.73,100,1,14.28,100,1,12.71,100,1,14.48,700,1,12.50,700,1,14.53,100,1,12.46,100,1,14.54,700,1,12.43,700,1,14.56,700,1,ARL,339216161
2025-07-17T16:13:06.275886461Z,2025-07-17T16:13:06.275720866Z,160,2,1108,A,A,10,13.40,0,0,13.40,23,1,13.11,100,1,13.66,15,1,12.98,200,2,13.67,100,1,12.96,2,1,13.81,2,1,12.86,100,1,13.94,100,1,12.73,100,1,14.28,100,1,12.71,100,1,14.48,700,1,12.50,700,1,14.53,100,1,12.46,100,1,14.54,700,1,12.43,700,1,14.56,700,1,ARL,339359401
2025-07-17T16:13:06.277048260Z,2025-07-17T16:13:06.276882863Z,160,2,1108,C,A,10,13.40,0,0,13.40,23,1,13.11,100,1,13.66,15,1,12.98,200,2,13.67,100,1,12.96,2,1,13.81,2,1,12.86,100,1,13.94,100,1,12.73,100,1,14.28,100,1,12.71,100,1,14.48,700,1,12.50,700,1,14.53,100,1,12.46,100,1,14.54,700,1,12.43,700,1,14.56,700,1,ARL,339232213
2025-07-17T16:13:06.277178914Z,2025-07-17T16:13:06.277013512Z,160,2,1108,A,A,10,13.40,0,0,13.40,23,1,13.11,100,1,13.66,15,1,12.98,200,2,13.67,100,1,12.96,2,1,13.81,2,1,12.86,100,1,13.94,100,1,12.73,100,1,14.28,100,1,12.71,100,1,14.46,100,1,12.50,700,1,14.48,700,1,12.46,100,1,14.53,100,1,12.43,700,1,14.54,700,1,ARL,339359421
2025-07-17T16:13:06.622659102Z,2025-07-17T16:13:06.622493734Z,160,2,1108,A,A,10,13.40,0,0,13.40,23,1,13.11,100,1,13.66,15,1,12.98,200,2,13.67,100,1,12.96,2,1,13.81,2,1,12.86,100,1,13.94,100,1,12.73,100,1,14.22,100,1,12.71,100,1,14.28,100,1,12.50,700,1,14.46,100,1,12.46,100,1,14.48,700,1,12.43,700,1,14.53,100,1,ARL,339365193
2025-07-17T16:13:06.663836744Z,2025-07-17T16:13:06.663671305Z,160,2,1108,C,A,10,13.40,0,0,13.40,23,1,13.11,100,1,13.66,15,1,12.98,200,2,13.67,100,1,12.96,2,1,13.81,2,1,12.86,100,1,13.94,100,1,12.73,100,1,14.22,100,1,12.71,100,1,14.28,100,1,12.50,700,1,14.46,100,1,12.46,100,1,14.48,700,1,12.43,700,1,14.54,700,1,ARL,339225769
2025-07-17T16:13:06.759791103Z,2025-07-17T16:13:06.759625628Z,160,2,1108,A,A,10,13.40,0,0,13.40,23,1,13.11,100,1,13.66,15,1,12.98,200,2,13.67,100,1,12.96,2,1,13.81,2,1,12.86,100,1,13.94,100,1,12.73,100,1,14.22,100,1,12.71,100,1,14.28,100,1,12.50,700,1,14.46,100,1,12.46,100,1,14.48,700,1,12.43,700,1,14.49,100,1,ARL,339366385
2025-07-17T16:13:06.759804641Z,2025-07-17T16:13:06.759638890Z,160,2,1108,C,A,10,13.40,0,0,13.40,23,1,13.11,100,1,13.66,15,1,12.98,200,2,13.67,100,1,12.96,2,1,13.81,2,1,12.86,100,1,13.94,100,1,12.73,100,1,14.22,100,1,12.71,100,1,14.28,100,1,12.50,700,1,14.46,100,1,12.46,100,1,14.48,700,1,12.43,700,1,14.49,100,1,ARL,339225885
2025-07-17T16:13:09.354048740Z,2025-07-17T16:13:09.353883614Z,160,2,1108,A,A,10,13.40,0,0,13.40,23,1,13.11,100,1,13.64,15,1,12.98,200,2,13.66,15,1,12.96,2,1,13.67,100,1,12.86,100,1,13.81,2,1,12.73,100,1,13.94,100,1,12.71,100,1,14.22,100,1,12.50,700,1,14.28,100,1,12.46,100,1,14.46,100,1,12.43,700,1,14.48,700,1,ARL,339425837
2025-07-17T16:13:09.368197659Z,2025-07-17T16:13:09.368030843Z,160,2,1108,C,A,10,13.40,0,0,13.40,23,1,13.11,100,1,13.64,15,1,12.98,200,2,13.66,15,1,12.96,2,1,13.81,2,1,12.86,100,1,13.94,100,1,12.73,100,1,14.22,100,1,12.71,100,1,14.28,100,1,12.50,700,1,14.46,100,1,12.46,100,1,14.48,700,1,12.43,700,1,14.49,100,1,ARL,339358233
2025-07-17T16:13:09.368197659Z,2025-07-17T16:13:09.368030843Z,160,2,1108,A,A,10,13.40,0,0,13.40,23,1,13.11,100,1,13.64,15,1,12.98,200,2,13.65,100,1,12.96,2,1,13.66,15,1,12.86,100,1,13.81,2,1,12.73,100,1,13.94,100,1,12.71,100,1,14.22,100,1,12.50,700,1,14.28,100,1,12.46,100,1,14.46,100,1,12.43,700,1,14.48,700,1,ARL,339427217
2025-07-17T16:13:14.046267875Z,2025-07-17T16:13:14.046102556Z,160,2,1108,C,A,10,13.40,0,0,13.40,23,1,13.11,100,1,13.64,15,1,12.98,200,2,13.65,100,1,12.96,2,1,13.81,2,1,12.86,100,1,13.94,100,1,12.73,100,1,14.22,100,1,12.71,100,1,14.28,100,1,12.50,700,1,14.46,100,1,12.46,100,1,14.48,700,1,12.43,700,1,14.49,100,1,ARL,339332865
2025-07-17T16:13:17.775210916Z,2025-07-17T16:13:17.775045316Z,160,2,1108,A,A,10,13.40,0,0,13.40,23,1,13.11,100,1,13.57,15,1,12.98,200,2,13.64,15,1,12.96,2,1,13.65,100,1,12.86,100,1,13.81,2,1,12.73,100,1,13.94,100,1,12.71,100,1,14.22,100,1,12.50,700,1,14.28,100,1,12.46,100,1,14.46,100,1,12.43,700,1,14.48,700,1,ARL,339610637
2025-07-17T16:13:19.781143691Z,2025-07-17T16:13:19.780978185Z,160,2,1108,C,A,10,13.40,0,0,13.40,23,1,13.11,100,1,13.57,15,1,12.98,200,2,13.64,15,1,12.96,2,1,13.81,2,1,12.86,100,1,13.94,100,1,12.73,100,1,14.22,100,1,12.71,100,1,14.28,100,1,12.50,700,1,14.46,100,1,12.46,100,1,14.48,700,1,12.43,700,1,14.49,100,1,ARL,339427217
2025-07-17T16:13:19.781143691Z,2025-07-17T16:13:19.780978185Z,160,2,1108,A,A,10,13.40,0,0,13.40,23,1,13.11,100,1,13.57,15,1,12.98,200,2,13.58,100,1,12.96,2,1,13.64,15,1,12.86,100,1,13.81,2,1,12.73,100,1,13.94,100,1,12.71,100,1,14.22,100,1,12.50,700,1,14.28,100,1,12.46,100,1,14.46,100,1,12.43,700,1,14.48,700,1,ARL,339641813
2025-07-17T16:13:19.781889805Z,2025-07-17T16:13:19.781723964Z,160,2,1108,C,A,10,13.40,0,0,13.40,23,1,13.11,100,1,13.57,15,1,12.98,200,2,13.58,100,1,12.96,2,1,13.64,15,1,12.86,100,1,13.81,2,1,12.73,100,1,13.94,100,1,12.71,100,1,14.22,100,1,12.50,700,1,14.28,100,1,12.46,100,1,14.46,100,1,12.43,700,1,14.48,700,1,ARL,339358293
2025-07-17T16:13:19.781889805Z,2025-07-17T16:13:19.781723964Z,160,2,1108,A,A,10,13.40,0,0,13.40,23,1,13.11,100,1,13.57,15,1,12.98,200,2,13.58,100,1,12.96,2,1,13.64,15,1,12.86,100,1,13.81,2,1,12.73,100,1,13.94,100,1,12.71,100,1,14.22,100,1,12.50,700,1,14.28,100,1,12.46,100,1,14.46,100,1,12.43,700,1,14.48,700,1,ARL,339641865
2025-07-17T16:13:19.789771458Z,2025-07-17T16:13:19.789606057Z,160,2,1108,C,A,10,13.40,0,0,13.40,23,1,13.11,100,1,13.57,15,1,12.98,200,2,13.58,100,1,12.96,2,1,13.64,15,1,12.86,100,1,13.81,2,1,12.73,100,1,14.22,100,1,12.71,100,1,14.28,100,1,12.50,700,1,14.46,100,1,12.46,100,1,14.48,700,1,12.43,700,1,14.49,100,1,ARL,339358741
2025-07-17T16:13:19.789822010Z,2025-07-17T16:13:19.789656689Z,160,2,1108,A,A,10,13.40,0,0,13.40,23,1,13.11,100,1,13.57,15,1,12.98,200,2,13.58,100,1,12.96,2,1,13.64,15,1,12.86,100,1,13.81,2,1,12.73,100,1,13.85,100,1,12.71,100,1,14.22,100,1,12.50,700,1,14.28,100,1,12.46,100,1,14.46,100,1,12.43,700,1,14.48,700,1,ARL,339642033
2025-07-17T16:13:19.863618706Z,2025-07-17T16:13:19.863452537Z,160,2,1108,C,A,10,13.40,0,0,13.40,23,1,13.11,100,1,13.58,100,1,12.98,200,2,13.64,15,1,12.96,2,1,13.81,2,1,12.86,100,1,13.85,100,1,12.73,100,1,14.22,100,1,12.71,100,1,14.28,100,1,12.50,700,1,14.46,100,1,12.46,100,1,14.48,700,1,12.43,700,1,14.49,100,1,ARL,339610637
2025-07-17T16:13:19.863790083Z,2025-07-17T16:13:19.863624798Z,160,2,1108,C,A,10,13.40,0,0,13.40,23,1,13.11,100,1,13.58,100,1,12.98,200,2,13.81,2,1,12.96,2,1,13.85,100,1,12.86,100,1,14.22,100,1,12.73,100,1,14.28,100,1,12.71,100,1,14.46,100,1,12.50,700,1,14.48,700,1,12.46,100,1,14.49,100,1,12.43,700,1,14.54,700,1,ARL,339425837
2025-07-17T16:13:19.863968792Z,2025-07-17T16:13:19.863803503Z,160,2,1108,A,A,10,13.40,0,0,13.40,23,1,13.11,100,1,13.58,196,2,12.98,200,2,13.81,2,1,12.96,2,1,13.85,100,1,12.86,100,1,14.22,100,1,12.73,100,1,14.28,100,1,12.71,100,1,14.46,100,1,12.50,700,1,14.48,700,1,12.46,100,1,14.49,100,1,12.43,700,1,14.54,700,1,ARL,339643285
2025-07-17T16:13:24.182625011Z,2025-07-17T16:13:24.182459676Z,160,2,1108,A,A,10,13.40,0,0,13.40,23,1,13.11,100,1,13.57,15,1,12.98,200,2,13.58,196,2,12.96,2,1,13.81,2,1,12.86,100,1,13.85,100,1,12.73,100,1,14.22,100,1,12.71,100,1,14.28,100,1,12.50,700,1,14.46,100,1,12.46,100,1,14.48,700,1,12.43,700,1,14.49,100,1,ARL,339710089
2025-07-17T16:13:24.182918202Z,2025-07-17T16:13:24.182753004Z,160,2,1108,C,A,10,13.40,0,0,13.40,23,1,13.11,100,1,13.57,15,1,12.98,200,2,13.58,100,1,12.96,2,1,13.81,2,1,12.86,100,1,13.85,100,1,12.73,100,1,14.22,100,1,12.71,100,1,14.28,100,1,12.50,700,1,14.46,100,1,12.46,100,1,14.48,700,1,12.43,700,1,14.49,100,1,ARL,339643285
2025-07-17T16:13:24.627374514Z,2025-07-17T16:13:24.627209125Z,160,2,1108,A,A,10,13.40,0,0,13.40,23,1,13.11,100,1,13.57,15,1,12.98,200,2,13.58,100,1,12.96,2,1,13.81,2,1,12.86,100,1,13.85,100,1,12.73,100,1,14.22,100,1,12.71,100,1,14.26,700,1,12.50,700,1,14.28,100,1,12.46,100,1,14.46,100,1,12.43,700,1,14.48,700,1,ARL,339716321
2025-07-17T16:13:24.627430447Z,2025-07-17T16:13:24.627265040Z,160,2,1108,C,A,10,13.40,0,0,13.40,23,1,13.11,100,1,13.57,15,1,12.98,200,2,13.58,100,1,12.96,2,1,13.81,2,1,12.86,100,1,13.85,100,1,12.73,100,1,14.22,100,1,12.71,100,1,14.26,700,1,12.50,700,1,14.28,100,1,12.46,100,1,14.46,100,1,12.43,700,1,14.48,700,1,ARL,339096897
2025-07-17T16:13:25.962717944Z,2025-07-17T16:13:25.962552288Z,160,2,1108,C,A,10,13.40,0,0,13.40,23,1,13.11,100,1,13.57,15,1,12.98,200,2,13.58,100,1,12.96,2,1,13.81,2,1,12.86,100,1,13.85,100,1,12.73,100,1,14.22,100,1,12.71,100,1,14.26,700,1,12.50,700,1,14.28,100,1,12.46,100,1,14.46,100,1,12.43,700,1,14.48,700,1,ARL,339203693
2025-07-17T16:13:25.962717944Z,2025-07-17T16:13:25.962552288Z,160,2,1108,A,A,10,13.40,0,0,13.40,23,1,13.11,100,1,13.57,15,1,12.98,200,2,13.58,100,1,12.96,2,1,13.81,2,1,12.86,100,1,13.85,100,1,12.73,100,1,14.22,100,1,12.71,100,1,14.26,700,1,12.50,700,1,14.28,100,1,12.46,100,1,14.46,200,2,12.43,700,1,14.48,700,1,ARL,339739285
2025-07-17T16:13:25.963209328Z,2025-07-17T16:13:25.963043858Z,160,2,1108,C,A,10,13.40,0,0,13.40,23,1,13.11,100,1,13.57,15,1,12.98,200,2,13.58,100,1,12.96,2,1,13.81,2,1,12.86,100,1,13.85,100,1,12.73,100,1,14.22,100,1,12.71,100,1,14.26,700,1,12.50,700,1,14.28,100,1,12.46,100,1,14.46,200,2,12.43,700,1,14.48,700,1,ARL,339203897
2025-07-17T16:13:25.963209328Z,2025-07-17T16:13:25.963043858Z,160,2,1108,A,A,10,13.40,0,0,13.40,23,1,13.11,100,1,13.57,15,1,12.98,200,2,13.58,100,1,12.96,2,1,13.81,2,1,12.86,100,1,13.85,100,1,12.73,100,1,14.22,100,1,12.71,100,1,14.26,700,1,12.50,700,1,14.28,100,1,12.46,100,1,14.46,300,3,12.43,700,1,14.48,700,1,ARL,339739297
2025-07-17T16:13:34.825229037Z,2025-07-17T16:13:34.825063658Z,160,2,1108,A,A,10,13.40,0,0,13.40,23,1,13.11,100,1,13.55,15,1,12.98,200,2,13.57,15,1,12.96,2,1,13.58,100,1,12.86,100,1,13.81,2,1,12.73,100,1,13.85,100,1,12.71,100,1,14.22,100,1,12.50,700,1,14.26,700,1,12.46,100,1,14.28,100,1,12.43,700,1,14.46,300,3,ARL,339897885
2025-07-17T16:13:36.525450545Z,2025-07-17T16:13:36.525285006Z,160,2,1108,C,A,10,13.40,0,0,13.40,23,1,13.11,100,1,13.55,15,1,12.98,200,2,13.57,15,1,12.96,2,1,13.81,2,1,12.86,100,1,13.85,100,1,12.73,100,1,14.22,100,1,12.71,100,1,14.26,700,1,12.50,700,1,14.28,100,1,12.46,100,1,14.46,300,3,12.43,700,1,14.48,700,1,ARL,339641813
2025-07-17T16:13:36.525450545Z,2025-07-17T16:13:36.525285006Z,160,2,1108,A,A,10,13.40,0,0,13.40,23,1,13.11,100,1,13.55,15,1,12.98,200,2,13.56,100,1,12.96,2,1,13.57,15,1,12.86,100,1,13.81,2,1,12.73,100,1,13.85,100,1,12.71,100,1,14.22,100,1,12.50,700,1,14.26,700,1,12.46,100,1,14.28,100,1,12.43,700,1,14.46,300,3,ARL,339937253
2025-07-17T16:13:36.528326337Z,2025-07-17T16:13:36.528160728Z,160,2,1108,C,A,10,13.40,0,0,13.40,23,1,13.11,100,1,13.55,15,1,12.98,200,2,13.56,100,1,12.96,2,1,13.57,15,1,12.86,100,1,13.81,2,1,12.73,100,1,13.85,100,1,12.71,100,1,14.22,100,1,12.50,700,1,14.26,700,1,12.46,100,1,14.28,100,1,12.43,700,1,14.46,300,3,ARL,339358609
2025-07-17T16:13:36.528326337Z,2025-07-17T16:13:36.528160728Z,160,2,1108,A,A,10,13.40,0,0,13.40,23,1,13.11,100,1,13.55,15,1,12.98,200,2,13.56,100,1,12.96,2,1,13.57,15,1,12.86,100,1,13.81,2,1,12.73,100,1,13.85,100,1,12.71,100,1,14.22,100,1,12.50,700,1,14.26,700,1,12.46,100,1,14.28,100,1,12.43,700,1,14.46,300,3,ARL,339937293
2025-07-17T16:13:40.166698198Z,2025-07-17T16:13:40.166532673Z,160,2,1108,C,A,10,13.40,0,0,13.40,23,1,13.11,100,1,13.55,15,1,12.98,200,2,13.56,100,1,12.96,2,1,13.81,2,1,12.86,100,1,13.85,100,1,12.73,100,1,14.22,100,1,12.71,100,1,14.26,700,1,12.50,700,1,14.28,100,1,12.46,100,1,14.46,300,3,12.43,700,1,14.48,700,1,ARL,339710089
2025-07-17T16:13:41.168681977Z,2025-07-17T16:13:41.168516592Z,160,2,1108,A,A,10,13.40,0,0,13.40,23,1,13.11,100,1,13.53,15,1,12.98,200,2,13.55,15,1,12.96,2,1,13.56,100,1,12.86,100,1,13.81,2,1,12.73,100,1,13.85,100,1,12.71,100,1,14.22,100,1,12.50,700,1,14.26,700,1,12.46,100,1,14.28,100,1,12.43,700,1,14.46,300,3,ARL,340027925
2025-07-17T16:13:41.810648775Z,2025-07-17T16:13:41.810482971Z,160,2,1108,C,A,10,13.40,0,0,13.40,23,1,13.11,100,1,13.53,15,1,12.98,200,2,13.55,15,1,12.96,2,1,13.81,2,1,12.86,100,1,13.85,100,1,12.73,100,1,14.22,100,1,12.71,100,1,14.26,700,1,12.50,700,1,14.28,100,1,12.46,100,1,14.46,300,3,12.43,700,1,14.48,700,1,ARL,339937253
2025-07-17T16:13:41.810648775Z,2025-07-17T16:13:41.810482971Z,160,2,1108,A,A,10,13.40,0,0,13.40,23,1,13.11,100,1,13.53,15,1,12.98,200,2,13.54,100,1,12.96,2,1,13.55,15,1,12.86,100,1,13.81,2,1,12.73,100,1,13.85,100,1,12.71,100,1,14.22,100,1,12.50,700,1,14.26,700,1,12.46,100,1,14.28,100,1,12.43,700,1,14.46,300,3,ARL,340046965
2025-07-17T16:13:41.811397213Z,2025-07-17T16:13:41.811231743Z,160,2,1108,C,A,10,13.40,0,0,13.40,23,1,13.11,100,1,13.53,15,1,12.98,200,2,13.54,100,1,12.96,2,1,13.55,15,1,12.86,100,1,13.81,2,1,12.73,100,1,13.85,100,1,12.71,100,1,14.22,100,1,12.50,700,1,14.26,700,1,12.46,100,1,14.28,100,1,12.43,700,1,14.46,300,3,ARL,339641865
2025-07-17T16:13:41.811397213Z,2025-07-17T16:13:41.811231743Z,160,2,1108,A,A,10,13.40,0,0,13.40,23,1,13.11,100,1,13.53,15,1,12.98,200,2,13.54,100,1,12.96,2,1,13.55,15,1,12.86,100,1,13.81,2,1,12.73,100,1,13.85,100,1,12.71,100,1,14.22,100,1,12.50,700,1,14.26,700,1,12.46,100,1,14.28,100,1,12.43,700,1,14.46,300,3,ARL,340047001
2025-07-17T16:13:41.846549822Z,2025-07-17T16:13:41.846384162Z,160,2,1108,C,A,10,13.40,0,0,13.40,23,1,13.11,100,1,13.53,15,1,12.98,200,2,13.54,100,1,12.96,2,1,13.55,15,1,12.86,100,1,13.81,2,1,12.73,100,1,13.85,100,1,12.71,100,1,14.22,100,1,12.50,700,1,14.26,700,1,12.46,100,1,14.28,100,1,12.43,700,1,14.46,300,3,ARL,339359077
2025-07-17T16:13:41.846549822Z,2025-07-17T16:13:41.846384162Z,160,2,1108,A,A,10,13.40,0,0,13.40,23,1,13.11,100,1,13.53,15,1,12.98,200,2,13.54,100,1,12.96,2,1,13.55,15,1,12.86,100,1,13.81,2,1,12.73,100,1,13.85,100,1,12.71,100,1,14.22,100,1,12.50,700,1,14.26,700,1,12.46,100,1,14.28,100,1,12.43,700,1,14.46,300,3,ARL,340047805
2025-07-17T16:13:53.138391930Z,2025-07-17T16:13:53.138226660Z,160,2,1108,C,A,10,13.40,0,0,13.40,23,1,13.11,100,1,13.54,100,1,12.98,200,2,13.55,15,1,12.96,2,1,13.81,2,1,12.86,100,1,13.85,100,1,12.73,100,1,14.22,100,1,12.71,100,1,14.26,700,1,12.50,700,1,14.28,100,1,12.46,100,1,14.46,300,3,12.43,700,1,14.48,700,1,ARL,340027925
2025-07-17T16:13:53.784302227Z,2025-07-17T16:13:53.784124590Z,160,2,1108,C,A,10,13.40,0,0,13.40,23,1,13.11,100,1,13.54,100,1,12.98,200,2,13.81,2,1,12.96,2,1,13.85,100,1,12.86,100,1,14.22,100,1,12.73,100,1,14.26,700,1,12.71,100,1,14.28,100,1,12.50,700,1,14.46,300,3,12.46,100,1,14.48,700,1,12.43,700,1,14.49,100,1,ARL,339897885
2025-07-17T16:14:06.190866982Z,2025-07-17T16:14:06.190701389Z,160,2,1108,C,A,10,13.40,0,0,13.40,23,1,13.11,100,1,13.54,100,1,12.98,200,2,13.85,100,1,12.96,2,1,14.22,100,1,12.86,100,1,14.26,700,1,12.73,100,1,14.28,100,1,12.71,100,1,14.46,300,3,12.50,700,1,14.48,700,1,12.46,100,1,14.49,100,1,12.43,700,1,14.54,700,1,ARL,339358409
2025-07-17T16:14:06.190866982Z,2025-07-17T16:14:06.190701389Z,160,2,1108,A,A,10,13.40,0,0,13.40,23,1,13.11,100,1,13.54,100,1,12.98,200,2,13.74,2,1,12.96,2,1,13.85,100,1,12.86,100,1,14.22,100,1,12.73,100,1,14.26,700,1,12.71,100,1,14.28,100,1,12.50,700,1,14.46,300,3,12.46,100,1,14.48,700,1,12.43,700,1,14.49,100,1,ARL,340449865
2025-07-17T16:14:10.827419207Z,2025-07-17T16:14:10.827253317Z,160,2,1108,A,A,10,13.40,0,0,13.40,23,1,13.11,100,1,13.51,15,1,12.98,200,2,13.54,100,1,12.96,2,1,13.74,2,1,12.86,100,1,13.85,100,1,12.73,100,1,14.22,100,1,12.71,100,1,14.26,700,1,12.50,700,1,14.28,100,1,12.46,100,1,14.46,300,3,12.43,700,1,14.48,700,1,ARL,340526285
2025-07-17T16:14:10.876894854Z,2025-07-17T16:14:10.876729278Z,160,2,1108,C,A,10,13.40,0,0,13.40,23,1,13.11,100,1,13.51,15,1,12.98,200,2,13.74,2,1,12.96,2,1,13.85,100,1,12.86,100,1,14.22,100,1,12.73,100,1,14.26,700,1,12.71,100,1,14.28,100,1,12.50,700,1,14.46,300,3,12.46,100,1,14.48,700,1,12.43,700,1,14.49,100,1,ARL,340046965
2025-07-17T16:14:10.876894854Z,2025-07-17T16:14:10.876729278Z,160,2,1108,A,A,10,13.40,0,0,13.40,23,1,13.11,100,1,13.51,15,1,12.98,200,2,13.52,100,1,12.96,2,1,13.74,2,1,12.86,100,1,13.85,100,1,12.73,100,1,14.22,100,1,12.71,100,1,14.26,700,1,12.50,700,1,14.28,100,1,12.46,100,1,14.46,300,3,12.43,700,1,14.48,700,1,ARL,340527921
2025-07-17T16:14:10.878601199Z,2025-07-17T16:14:10.878435316Z,160,2,1108,C,A,10,13.40,0,0,13.40,23,1,13.11,100,1,13.51,15,1,12.98,200,2,13.52,100,1,12.96,2,1,13.74,2,1,12.86,100,1,13.85,100,1,12.73,100,1,14.22,100,1,12.71,100,1,14.26,700,1,12.50,700,1,14.28,100,1,12.46,100,1,14.46,300,3,12.43,700,1,14.48,700,1,ARL,339358353
2025-07-17T16:14:10.878601199Z,2025-07-17T16:14:10.878435316Z,160,2,1108,A,A,10,13.40,0,0,13.40,23,1,13.11,100,1,13.51,15,1,12.98,200,2,13.52,100,1,12.96,2,1,13.74,2,1,12.86,100,1,13.85,100,1,12.73,100,1,14.22,100,1,12.71,100,1,14.26,700,1,12.50,700,1,14.28,100,1,12.46,100,1,14.46,300,3,12.43,700,1,14.47,100,1,ARL,340527969
2025-07-17T16:14:10.892679514Z,2025-07-17T16:14:10.892513823Z,160,2,1108,C,A,10,13.40,0,0,13.40,23,1,13.11,100,1,13.51,15,1,12.98,200,2,13.52,100,1,12.96,2,1,13.74,2,1,12.86,100,1,13.85,100,1,12.73,100,1,14.22,100,1,12.71,100,1,14.26,700,1,12.50,700,1,14.28,100,1,12.46,100,1,14.46,300,3,12.43,700,1,14.47,100,1,ARL,339359401
2025-07-17T16:14:10.892679514Z,2025-07-17T16:14:10.892513823Z,160,2,1108,A,A,10,13.40,0,0,13.40,23,1,13.11,100,1,13.51,15,1,12.98,200,2,13.52,100,1,12.96,2,1,13.74,2,1,12.86,100,1,13.85,100,1,12.73,100,1,14.22,100,1,12.71,100,1,14.26,700,1,12.50,700,1,14.28,100,1,12.46,100,1,14.46,300,3,12.43,700,1,14.47,200,2,ARL,340528121
2025-07-17T16:14:10.985507716Z,2025-07-17T16:14:10.985342000Z,160,2,1108,C,A,10,13.40,0,0,13.40,23,1,13.11,100,1,13.51,15,1,12.98,200,2,13.52,100,1,12.96,2,1,13.74,2,1,12.86,100,1,13.85,100,1,12.73,100,1,14.22,100,1,12.71,100,1,14.26,700,1,12.50,700,1,14.28,100,1,12.46,100,1,14.46,200,2,12.43,700,1,14.47,200,2,ARL,339359421
2025-07-17T16:14:10.985507716Z,2025-07-17T16:14:10.985342000Z,160,2,1108,A,A,10,13.40,0,0,13.40,23,1,13.11,100,1,13.51,15,1,12.98,200,2,13.52,100,1,12.96,2,1,13.74,2,1,12.86,100,1,13.85,100,1,12.73,100,1,14.22,100,1,12.71,100,1,14.26,700,1,12.50,700,1,14.28,100,1,12.46,100,1,14.31,100,1,12.43,700,1,14.46,200,2,ARL,340529021
2025-07-17T16:14:19.528488233Z,2025-07-17T16:14:19.528322793Z,160,2,1108,A,A,10,13.40,0,0,13.40,23,1,13.11,100,1,13.49,15,1,12.98,200,2,13.51,15,1,12.96,2,1,13.52,100,1,12.86,100,1,13.74,2,1,12.73,100,1,13.85,100,1,12.71,100,1,14.22,100,1,12.50,700,1,14.26,700,1,12.46,100,1,14.28,100,1,12.43,700,1,14.31,100,1,ARL,340664453
2025-07-17T16:14:21.306764970Z,2025-07-17T16:14:21.306599291Z,160,2,1108,C,A,10,13.40,0,0,13.40,23,1,13.11,100,1,13.49,15,1,12.98,200,2,13.51,15,1,12.96,2,1,13.74,2,1,12.86,100,1,13.85,100,1,12.73,100,1,14.22,100,1,12.71,100,1,14.26,700,1,12.50,700,1,14.28,100,1,12.46,100,1,14.31,100,1,12.43,700,1,14.46,200,2,ARL,340527921
2025-07-17T16:14:21.306764970Z,2025-07-17T16:14:21.306599291Z,160,2,1108,A,A,10,13.40,0,0,13.40,23,1,13.11,100,1,13.49,15,1,12.98,200,2,13.50,100,1,12.96,2,1,13.51,15,1,12.86,100,1,13.74,2,1,12.73,100,1,13.85,100,1,12.71,100,1,14.22,100,1,12.50,700,1,14.26,700,1,12.46,100,1,14.28,100,1,12.43,700,1,14.31,100,1,ARL,340704401
2025-07-17T16:14:21.307512009Z,2025-07-17T16:14:21.307346403Z,160,2,1108,C,A,10,13.40,0,0,13.40,23,1,13.11,100,1,13.49,15,1,12.98,200,2,13.50,100,1,12.96,2,1,13.51,15,1,12.86,100,1,13.74,2,1,12.73,100,1,13.85,100,1,12.71,100,1,14.22,100,1,12.50,700,1,14.26,700,1,12.46,100,1,14.28,100,1,12.43,700,1,14.31,100,1,ARL,340047001
2025-07-17T16:14:21.307512009Z,2025-07-17T16:14:21.307346403Z,160,2,1108,A,A,10,13.40,0,0,13.40,23,1,13.11,100,1,13.49,15,1,12.98,200,2,13.50,100,1,12.96,2,1,13.51,15,1,12.86,100,1,13.74,2,1,12.73,100,1,13.85,100,1,12.71,100,1,14.22,100,1,12.50,700,1,14.26,700,1,12.46,100,1,14.28,100,1,12.43,700,1,14.31,100,1,ARL,340704465
2025-07-17T16:14:21.317261991Z,2025-07-17T16:14:21.317096752Z,160,2,1108,C,A,10,13.40,0,0,13.40,23,1,13.11,100,1,13.49,15,1,12.98,200,2,13.50,100,1,12.96,2,1,13.51,15,1,12.86,100,1,13.74,2,1,12.73,100,1,14.22,100,1,12.71,100,1,14.26,700,1,12.50,700,1,14.28,100,1,12.46,100,1,14.31,100,1,12.43,700,1,14.46,200,2,ARL,339642033
2025-07-17T16:14:21.317314136Z,2025-07-17T16:14:21.317148983Z,160,2,1108,A,A,10,13.40,0,0,13.40,23,1,13.11,100,1,13.49,15,1,12.98,200,2,13.50,100,1,12.96,2,1,13.51,15,1,12.86,100,1,13.74,2,1,12.73,100,1,13.77,100,1,12.71,100,1,14.22,100,1,12.50,700,1,14.26,700,1,12.46,100,1,14.28,100,1,12.43,700,1,14.31,100,1,ARL,340705133
2025-07-17T16:14:21.343294261Z,2025-07-17T16:14:21.343129166Z,160,2,1108,A,A,10,13.40,0,0,13.40,23,1,13.11,100,1,13.49,15,1,12.98,200,2,13.50,100,1,12.96,2,1,13.51,15,1,12.86,100,1,13.74,2,1,12.73,100,1,13.77,100,1,12.71,100,1,14.22,100,1,12.50,700,1,14.26,700,1,12.46,100,1,14.28,100,1,12.43,700,1,14.31,100,1,ARL,340706373
2025-07-17T16:14:21.343307836Z,2025-07-17T16:14:21.343142096Z,160,2,1108,C,A,10,13.40,0,0,13.40,23,1,13.11,100,1,13.49,15,1,12.98,200,2,13.50,100,1,12.96,2,1,13.51,15,1,12.86,100,1,13.74,2,1,12.73,100,1,13.77,100,1,12.71,100,1,14.22,100,1,12.50,700,1,14.26,700,1,12.46,100,1,14.28,100,1,12.43,700,1,14.31,100,1,ARL,339202065
2025-07-17T16:14:36.523553349Z,2025-07-17T16:14:36.523382949Z,160,2,1108,C,A,10,13.40,0,0,13.40,23,1,13.11,100,1,13.50,100,1,12.98,200,2,13.51,15,1,12.96,2,1,13.74,2,1,12.86,100,1,13.77,100,1,12.73,100,1,14.22,100,1,12.71,100,1,14.26,700,1,12.50,700,1,14.28,100,1,12.46,100,1,14.31,100,1,12.43,700,1,14.46,200,2,ARL,340664453
2025-07-17T16:14:36.523730500Z,2025-07-17T16:14:36.523564373Z,160,2,1108,C,A,10,13.40,0,0,13.40,23,1,13.11,100,1,13.50,100,1,12.98,200,2,13.74,2,1,12.96,2,1,13.77,100,1,12.86,100,1,14.22,100,1,12.73,100,1,14.26,700,1,12.71,100,1,14.28,100,1,12.50,700,1,14.31,100,1,12.46,100,1,14.46,200,2,12.43,700,1,14.47,200,2,ARL,340526285
2025-07-17T16:14:36.523862340Z,2025-07-17T16:14:36.523696080Z,160,2,1108,A,A,10,13.40,0,0,13.40,23,1,13.11,100,1,13.50,199,2,12.98,200,2,13.74,2,1,12.96,2,1,13.77,100,1,12.86,100,1,14.22,100,1,12.73,100,1,14.26,700,1,12.71,100,1,14.28,100,1,12.50,700,1,14.31,100,1,12.46,100,1,14.46,200,2,12.43,700,1,14.47,200,2,ARL,340971661
2025-07-17T16:14:52.280593678Z,2025-07-17T16:14:52.280428336Z,160,2,1108,C,A,10,13.40,0,0,13.40,23,1,13.11,100,1,13.50,100,1,12.98,200,2,13.74,2,1,12.96,2,1,13.77,100,1,12.86,100,1,14.22,100,1,12.73,100,1,14.26,700,1,12.71,100,1,14.28,100,1,12.50,700,1,14.31,100,1,12.46,100,1,14.46,200,2,12.43,700,1,14.47,200,2,ARL,340971661
2025-07-17T16:14:52.297037125Z,2025-07-17T16:14:52.296871817Z,160,2,1108,A,A,10,13.40,0,0,13.40,23,1,13.11,100,1,13.48,15,1,12.98,200,2,13.50,100,1,12.96,2,1,13.74,2,1,12.86,100,1,13.77,100,1,12.73,100,1,14.22,100,1,12.71,100,1,14.26,700,1,12.50,700,1,14.28,100,1,12.46,100,1,14.31,100,1,12.43,700,1,14.46,200,2,ARL,341248825
2025-07-17T16:14:52.828721867Z,2025-07-17T16:14:52.828556785Z,160,2,1108,C,A,10,13.40,0,0,13.40,23,1,13.11,100,1,13.50,100,1,12.98,200,2,13.74,2,1,12.96,2,1,13.77,100,1,12.86,100,1,14.22,100,1,12.73,100,1,14.26,700,1,12.71,100,1,14.28,100,1,12.50,700,1,14.31,100,1,12.46,100,1,14.46,200,2,12.43,700,1,14.47,200,2,ARL,341248825
2025-07-17T16:14:52.829033713Z,2025-07-17T16:14:52.828868258Z,160,2,1108,A,A,10,13.40,0,0,13.40,23,1,13.11,100,1,13.50,199,2,12.98,200,2,13.74,2,1,12.96,2,1,13.77,100,1,12.86,100,1,14.22,100,1,12.73,100,1,14.26,700,1,12.71,100,1,14.28,100,1,12.50,700,1,14.31,100,1,12.46,100,1,14.46,200,2,12.43,700,1,14.47,200,2,ARL,341253573
2025-07-17T16:15:16.987369971Z,2025-07-17T16:15:16.987204735Z,160,2,1108,C,A,10,13.40,0,0,13.40,23,1,13.11,100,1,13.50,100,1,12.98,200,2,13.74,2,1,12.96,2,1,13.77,100,1,12.86,100,1,14.22,100,1,12.73,100,1,14.26,700,1,12.71,100,1,14.28,100,1,12.50,700,1,14.31,100,1,12.46,100,1,14.46,200,2,12.43,700,1,14.47,200,2,ARL,341253573
2025-07-17T16:15:16.987414675Z,2025-07-17T16:15:16.987249289Z,160,2,1108,C,A,10,13.40,0,0,13.40,23,1,13.11,100,1,13.74,2,1,12.98,200,2,13.77,100,1,12.96,2,1,14.22,100,1,12.86,100,1,14.26,700,1,12.73,100,1,14.28,100,1,12.71,100,1,14.31,100,1,12.50,700,1,14.46,200,2,12.46,100,1,14.47,200,2,12.43,700,1,14.48,700,1,ARL,340704401
2025-07-17T16:15:16.987689493Z,2025-07-17T16:15:16.987524101Z,160,2,1108,C,A,10,13.40,0,0,13.40,23,1,13.11,100,1,13.74,2,1,12.98,200,2,13.77,100,1,12.96,2,1,14.22,100,1,12.86,100,1,14.28,100,1,12.73,100,1,14.31,100,1,12.71,100,1,14.46,200,2,12.50,700,1,14.47,200,2,12.46,100,1,14.48,700,1,12.43,700,1,14.49,100,1,ARL,339716321
2025-07-17T16:15:16.987744468Z,2025-07-17T16:15:16.987579177Z,160,2,1108,A,A,10,13.40,0,0,13.40,23,1,13.11,100,1,13.74,2,1,12.98,200,2,13.77,100,1,12.96,2,1,14.22,100,1,12.86,100,1,14.28,100,1,12.73,100,1,14.31,100,1,12.71,100,1,14.46,900,3,12.50,700,1,14.47,200,2,12.46,100,1,14.48,700,1,12.43,700,1,14.49,100,1,ARL,341661841
2025-07-17T16:15:16.987772549Z,2025-07-17T16:15:16.987607468Z,160,2,1108,A,A,10,13.40,0,0,13.40,23,1,13.11,100,1,13.74,2,1,12.98,200,2,13.77,100,1,12.96,2,1,14.22,100,1,12.86,100,1,14.28,100,1,12.73,100,1,14.31,100,1,12.71,100,1,14.46,900,3,12.50,700,1,14.47,200,2,12.46,100,1,14.48,700,1,12.43,700,1,14.49,100,1,ARL,341661849
2025-07-17T16:15:16.987786087Z,2025-07-17T16:15:16.987620573Z,160,2,1108,C,A,10,13.40,0,0,13.40,23,1,13.11,100,1,13.74,2,1,12.98,200,2,13.77,100,1,12.96,2,1,14.22,100,1,12.86,100,1,14.28,100,1,12.73,100,1,14.31,100,1,12.71,100,1,14.46,900,3,12.50,700,1,14.47,200,2,12.46,100,1,14.48,700,1,12.43,700,1,14.49,100,1,ARL,340706373
2025-07-17T16:15:16.988145770Z,2025-07-17T16:15:16.987980299Z,160,2,1108,C,A,10,13.40,0,0,13.40,23,1,13.11,100,1,13.74,2,1,12.98,200,2,13.77,100,1,12.96,2,1,14.22,100,1,12.86,100,1,14.28,100,1,12.73,100,1,14.31,100,1,12.71,100,1,14.46,900,3,12.50,700,1,14.47,200,2,12.46,100,1,14.48,700,1,12.43,700,1,14.49,100,1,ARL,340704465
2025-07-17T16:15:16.988145770Z,2025-07-17T16:15:16.987980299Z,160,2,1108,A,A,10,13.40,0,0,13.40,23,1,13.11,100,1,13.74,2,1,12.98,200,2,13.77,100,1,12.96,2,1,14.22,100,1,12.86,100,1,14.28,100,1,12.73,100,1,14.31,100,1,12.71,100,1,14.46,900,3,12.50,700,1,14.47,200,2,12.46,100,1,14.48,700,1,12.43,700,1,14.49,100,1,ARL,341661869
2025-07-17T16:15:16.988410269Z,2025-07-17T16:15:16.988244795Z,160,2,1108,C,A,10,13.40,0,0,13.40,23,1,13.11,100,1,13.74,2,1,12.98,200,2,13.77,100,1,12.96,2,1,14.22,100,1,12.86,100,1,14.28,100,1,12.73,100,1,14.31,100,1,12.71,100,1,14.46,900,3,12.50,700,1,14.47,100,1,12.46,100,1,14.48,700,1,12.43,700,1,14.49,100,1,ARL,340527969
2025-07-17T16:15:16.988410269Z,2025-07-17T16:15:16.988244795Z,160,2,1108,A,A,10,13.40,0,0,13.40,23,1,13.11,100,1,13.74,2,1,12.98,200,2,13.77,100,1,12.96,2,1,14.22,100,1,12.86,100,1,14.28,100,1,12.73,100,1,14.31,100,1,12.71,100,1,14.46,900,3,12.50,700,1,14.47,100,1,12.46,100,1,14.48,700,1,12.43,700,1,14.49,100,1,ARL,341661877
2025-07-17T16:15:16.989313102Z,2025-07-17T16:15:16.989147294Z,160,2,1108,C,A,10,13.40,0,0,13.40,23,1,13.11,100,1,13.74,2,1,12.98,200,2,13.77,100,1,12.96,2,1,14.22,100,1,12.86,100,1,14.28,100,1,12.73,100,1,14.31,100,1,12.71,100,1,14.46,900,3,12.50,700,1,14.47,100,1,12.46,100,1,14.48,700,1,12.43,700,1,14.49,100,1,ARL,340047805
2025-07-17T16:15:16.989313102Z,2025-07-17T16:15:16.989147294Z,160,2,1108,A,A,10,13.40,0,0,13.40,23,1,13.11,100,1,13.74,2,1,12.98,200,2,13.77,100,1,12.96,2,1,14.22,100,1,12.86,100,1,14.28,100,1,12.73,100,1,14.31,100,1,12.71,100,1,14.46,900,3,12.50,700,1,14.47,100,1,12.46,100,1,14.48,700,1,12.43,700,1,14.49,100,1,ARL,341661893
2025-07-17T16:15:16.989763697Z,2025-07-17T16:15:16.989598095Z,160,2,1108,C,A,10,13.40,0,0,13.40,23,1,13.11,100,1,13.74,2,1,12.98,200,2,13.77,100,1,12.96,2,1,14.22,100,1,12.86,100,1,14.28,100,1,12.73,100,1,14.31,100,1,12.71,100,1,14.46,900,3,12.50,700,1,14.47,100,1,12.46,100,1,14.48,700,1,12.43,700,1,14.49,100,1,ARL,339937293
2025-07-17T16:15:16.989763697Z,2025-07-17T16:15:16.989598095Z,160,2,1108,A,A,10,13.40,0,0,13.40,23,1,13.11,100,1,13.74,2,1,12.98,200,2,13.77,100,1,12.96,2,1,14.22,100,1,12.86,100,1,14.28,100,1,12.73,100,1,14.31,100,1,12.71,100,1,14.46,900,3,12.50,700,1,14.47,100,1,12.46,100,1,14.48,700,1,12.43,700,1,14.49,100,1,ARL,341661901
2025-07-17T16:15:16.989886697Z,2025-07-17T16:15:16.989720957Z,160,2,1108,C,A,10,13.40,0,0,13.40,23,1,13.11,100,1,13.74,2,1,12.98,200,2,13.77,100,1,12.96,2,1,14.22,100,1,12.86,100,1,14.28,100,1,12.73,100,1,14.31,100,1,12.71,100,1,14.46,900,3,12.50,700,1,14.48,700,1,12.46,100,1,14.49,100,1,12.43,700,1,14.54,700,1,ARL,340528121
2025-07-17T16:15:16.989886697Z,2025-07-17T16:15:16.989720957Z,160,2,1108,A,A,10,13.40,0,0,13.40,23,1,13.11,100,1,13.74,2,1,12.98,200,2,13.77,100,1,12.96,2,1,14.22,100,1,12.86,100,1,14.28,100,1,12.73,100,1,14.31,100,1,12.71,100,1,14.46,900,3,12.50,700,1,14.48,700,1,12.46,100,1,14.49,100,1,12.43,700,1,14.54,700,1,ARL,341661905
2025-07-17T16:15:16.992804347Z,2025-07-17T16:15:16.992638952Z,160,2,1108,C,A,10,13.40,0,0,13.40,23,1,13.11,100,1,13.74,2,1,12.98,200,2,13.77,100,1,12.96,2,1,14.22,100,1,12.86,100,1,14.28,100,1,12.73,100,1,14.46,900,3,12.71,100,1,14.48,700,1,12.50,700,1,14.49,100,1,12.46,100,1,14.54,700,1,12.43,700,1,14.56,700,1,ARL,340529021
2025-07-17T16:15:16.992941967Z,2025-07-17T16:15:16.992776612Z,160,2,1108,A,A,10,13.40,0,0,13.40,23,1,13.11,100,1,13.74,2,1,12.98,200,2,13.77,100,1,12.96,2,1,14.22,100,1,12.86,100,1,14.28,100,1,12.73,100,1,14.46,900,3,12.71,100,1,14.48,700,1,12.50,700,1,14.49,100,1,12.46,100,1,14.54,700,1,12.43,700,1,14.56,800,2,ARL,341661985
2025-07-17T16:15:17.000588174Z,2025-07-17T16:15:17.000422944Z,160,2,1108,C,A,10,13.40,0,0,13.40,23,1,13.11,100,1,13.74,2,1,12.98,200,2,14.22,100,1,12.96,2,1,14.28,100,1,12.86,100,1,14.46,900,3,12.73,100,1,14.48,700,1,12.71,100,1,14.49,100,1,12.50,700,1,14.54,700,1,12.46,100,1,14.56,800,2,12.43,700,1,14.60,100,1,ARL,340705133
2025-07-17T16:15:17.000621056Z,2025-07-17T16:15:17.000456046Z,160,2,1108,C,A,10,13.40,0,0,13.40,23,1,13.11,100,1,13.74,2,1,12.98,200,2,14.22,100,1,12.96,2,1,14.28,100,1,12.86,100,1,14.46,200,2,12.73,100,1,14.48,700,1,12.71,100,1,14.49,100,1,12.50,700,1,14.54,700,1,12.46,100,1,14.56,800,2,12.43,700,1,14.60,100,1,ARL,341661841
2025-07-17T16:15:17.000640033Z,2025-07-17T16:15:17.000474862Z,160,2,1108,A,A,10,13.40,0,0,13.40,23,1,13.11,100,1,13.74,2,1,12.98,200,2,14.05,100,1,12.96,2,1,14.22,100,1,12.86,100,1,14.28,100,1,12.73,100,1,14.46,200,2,12.71,100,1,14.48,700,1,12.50,700,1,14.49,100,1,12.46,100,1,14.54,700,1,12.43,700,1,14.56,800,2,ARL,341662085
2025-07-17T16:15:17.001323406Z,2025-07-17T16:15:17.001158038Z,160,2,1108,C,A,10,13.40,0,0,13.40,23,1,13.11,100,1,13.74,2,1,12.98,200,2,14.05,100,1,12.96,2,1,14.22,100,1,12.86,100,1,14.46,200,2,12.73,100,1,14.48,700,1,12.71,100,1,14.49,100,1,12.50,700,1,14.54,700,1,12.46,100,1,14.56,800,2,12.43,700,1,14.60,100,1,ARL,339358333
2025-07-17T16:15:17.001687312Z,2025-07-17T16:15:17.001522171Z,160,2,1108,A,A,10,13.40,0,0,13.40,23,1,13.11,100,1,13.74,2,1,12.98,200,2,14.05,100,1,12.96,2,1,14.22,100,1,12.86,100,1,14.46,200,2,12.73,100,1,14.48,700,1,12.71,100,1,14.49,100,1,12.50,700,1,14.54,700,1,12.46,100,1,14.56,800,2,12.43,700,1,14.60,200,2,ARL,341662113
2025-07-17T16:15:17.002229963Z,2025-07-17T16:15:17.002064284Z,160,2,1108,C,A,10,13.40,0,0,13.40,23,1,13.11,100,1,13.74,2,1,12.98,200,2,14.05,100,1,12.96,2,1,14.22,100,1,12.86,100,1,14.46,200,2,12.73,100,1,14.48,700,1,12.71,100,1,14.49,100,1,12.50,700,1,14.54,700,1,12.46,100,1,14.56,800,2,12.43,700,1,14.60,200,2,ARL,341661905
2025-07-17T16:15:17.002229963Z,2025-07-17T16:15:17.002064284Z,160,2,1108,A,A,10,13.40,0,0,13.40,23,1,13.11,100,1,13.74,2,1,12.98,200,2,14.05,100,1,12.96,2,1,14.22,100,1,12.86,100,1,14.46,200,2,12.73,100,1,14.48,700,1,12.71,100,1,14.49,100,1,12.50,700,1,14.54,700,1,12.46,100,1,14.56,800,2,12.43,700,1,14.60,200,2,ARL,341662117
2025-07-17T16:15:17.002790290Z,2025-07-17T16:15:17.002625119Z,160,2,1108,C,A,10,13.40,0,0,13.40,23,1,13.11,100,1,13.74,2,1,12.98,200,2,14.05,100,1,12.96,2,1,14.22,100,1,12.86,100,1,14.46,200,2,12.73,100,1,14.48,700,1,12.71,100,1,14.49,100,1,12.50,700,1,14.54,700,1,12.46,100,1,14.56,800,2,12.43,700,1,14.60,200,2,ARL,341661901
2025-07-17T16:15:17.002790290Z,2025-07-17T16:15:17.002625119Z,160,2,1108,A,A,10,13.40,0,0,13.40,23,1,13.11,100,1,13.74,2,1,12.98,200,2,14.05,100,1,12.96,2,1,14.22,100,1,12.86,100,1,14.46,200,2,12.73,100,1,14.48,700,1,12.71,100,1,14.49,100,1,12.50,700,1,14.54,700,1,12.46,100,1,14.56,800,2,12.43,700,1,14.60,200,2,ARL,341662125
2025-07-17T16:15:17.003246802Z,2025-07-17T16:15:17.003081581Z,160,2,1108,C,A,10,13.40,0,0,13.40,23,1,13.11,100,1,13.74,2,1,12.98,200,2,14.05,100,1,12.96,2,1,14.22,100,1,12.86,100,1,14.46,200,2,12.73,100,1,14.48,700,1,12.71,100,1,14.49,100,1,12.50,700,1,14.54,700,1,12.46,100,1,14.56,800,2,12.43,700,1,14.60,200,2,ARL,341661877
2025-07-17T16:15:17.003246802Z,2025-07-17T16:15:17.003081581Z,160,2,1108,A,A,10,13.40,0,0,13.40,23,1,13.11,100,1,13.74,2,1,12.98,200,2,14.05,100,1,12.96,2,1,14.22,100,1,12.86,100,1,14.46,200,2,12.73,100,1,14.48,700,1,12.71,100,1,14.49,100,1,12.50,700,1,14.54,700,1,12.46,100,1,14.56,800,2,12.43,700,1,14.60,200,2,ARL,341662133
2025-07-17T16:15:17.003381863Z,2025-07-17T16:15:17.003216492Z,160,2,1108,C,A,10,13.40,0,0,13.40,23,1,13.11,100,1,13.74,2,1,12.98,200,2,14.05,100,1,12.96,2,1,14.22,100,1,12.86,100,1,14.46,200,2,12.73,100,1,14.48,700,1,12.71,100,1,14.49,100,1,12.50,700,1,14.54,700,1,12.46,100,1,14.56,800,2,12.43,700,1,14.60,200,2,ARL,341661893
2025-07-17T16:15:17.003381863Z,2025-07-17T16:15:17.003216492Z,160,2,1108,A,A,10,13.40,0,0,13.40,23,1,13.11,100,1,13.74,2,1,12.98,200,2,14.05,100,1,12.96,2,1,14.22,100,1,12.86,100,1,14.46,200,2,12.73,100,1,14.48,700,1,12.71,100,1,14.49,100,1,12.50,700,1,14.54,700,1,12.46,100,1,14.56,800,2,12.43,700,1,14.60,200,2,ARL,341662137
2025-07-17T16:15:17.003874553Z,2025-07-17T16:15:17.003708485Z,160,2,1108,C,A,10,13.40,0,0,13.40,23,1,13.11,100,1,13.74,2,1,12.98,200,2,14.05,100,1,12.96,2,1,14.22,100,1,12.86,100,1,14.46,200,2,12.73,100,1,14.48,700,1,12.71,100,1,14.49,100,1,12.50,700,1,14.54,700,1,12.46,100,1,14.56,800,2,12.43,700,1,14.60,200,2,ARL,339358349
2025-07-17T16:15:17.003874553Z,2025-07-17T16:15:17.003708485Z,160,2,1108,A,A,10,13.40,0,0,13.40,23,1,13.11,100,1,13.74,2,1,12.98,200,2,14.05,100,1,12.96,2,1,14.22,100,1,12.86,100,1,14.46,200,2,12.73,100,1,14.48,700,1,12.71,100,1,14.49,100,1,12.50,700,1,14.54,700,1,12.46,100,1,14.56,800,2,12.43,700,1,14.60,200,2,ARL,341662145
2025-07-17T16:15:17.003883470Z,2025-07-17T16:15:17.003717832Z,160,2,1108,C,A,10,13.40,0,0,13.40,23,1,13.11,100,1,13.74,2,1,12.98,200,2,14.05,100,1,12.96,2,1,14.22,100,1,12.86,100,1,14.46,200,2,12.73,100,1,14.48,700,1,12.71,100,1,14.49,100,1,12.50,700,1,14.54,700,1,12.46,100,1,14.56,800,2,12.43,700,1,14.60,200,2,ARL,339359357
2025-07-17T16:15:17.003883470Z,2025-07-17T16:15:17.003717832Z,160,2,1108,A,A,10,13.40,0,0,13.40,23,1,13.11,100,1,13.74,2,1,12.98,200,2,14.05,100,1,12.96,2,1,14.22,100,1,12.86,100,1,14.46,200,2,12.73,100,1,14.48,700,1,12.71,100,1,14.49,100,1,12.50,700,1,14.54,700,1,12.46,100,1,14.56,800,2,12.43,700,1,14.60,200,2,ARL,341662149
2025-07-17T16:15:17.019567564Z,2025-07-17T16:15:17.019402521Z,160,2,1108,C,A,10,13.40,0,0,13.40,23,1,13.11,100,1,13.74,2,1,12.98,200,2,14.22,100,1,12.96,2,1,14.46,200,2,12.86,100,1,14.48,700,1,12.73,100,1,14.49,100,1,12.71,100,1,14.54,700,1,12.50,700,1,14.56,800,2,12.46,100,1,14.60,200,2,12.43,700,1,14.96,200,2,ARL,341662085
2025-07-17T16:15:17.019617602Z,2025-07-17T16:15:17.019452245Z,160,2,1108,A,A,10,13.40,0,0,13.40,23,1,13.11,100,1,13.74,2,1,12.98,200,2,14.22,100,1,12.96,2,1,14.26,100,1,12.86,100,1,14.46,200,2,12.73,100,1,14.48,700,1,12.71,100,1,14.49,100,1,12.50,700,1,14.54,700,1,12.46,100,1,14.56,800,2,12.43,700,1,14.60,200,2,ARL,341662313
2025-07-17T16:15:17.037261626Z,2025-07-17T16:15:17.037096157Z,160,2,1108,C,A,10,13.40,0,0,13.40,23,1,13.11,100,1,13.74,2,1,12.98,200,2,14.22,100,1,12.96,2,1,14.26,100,1,12.86,100,1,14.46,200,2,12.73,100,1,14.48,700,1,12.71,100,1,14.49,100,1,12.50,700,1,14.54,700,1,12.46,100,1,14.56,800,2,12.43,700,1,14.60,100,1,ARL,341661869
2025-07-17T16:15:17.037261626Z,2025-07-17T16:15:17.037096157Z,160,2,1108,A,A,10,13.40,0,0,13.40,23,1,13.11,100,1,13.74,2,1,12.98,200,2,14.22,100,1,12.96,2,1,14.26,100,1,12.86,100,1,14.46,200,2,12.73,100,1,14.48,700,1,12.71,100,1,14.49,100,1,12.50,700,1,14.54,700,1,12.46,100,1,14.56,800,2,12.43,700,1,14.60,100,1,ARL,341662429
2025-07-17T16:15:17.049066370Z,2025-07-17T16:15:17.048901142Z,160,2,1108,A,A,10,13.40,0,0,13.40,23,1,13.11,100,1,13.74,2,1,12.98,200,2,13.75,100,1,12.96,2,1,14.22,100,1,12.86,100,1,14.26,100,1,12.73,100,1,14.46,200,2,12.71,100,1,14.48,700,1,12.50,700,1,14.49,100,1,12.46,100,1,14.54,700,1,12.43,700,1,14.56,800,2,ARL,341663101
2025-07-17T16:15:17.049108554Z,2025-07-17T16:15:17.048943087Z,160,2,1108,A,A,10,13.40,0,0,13.40,23,1,13.11,100,1,13.74,2,1,12.98,200,2,13.75,100,1,12.96,2,1,14.22,100,1,12.86,100,1,14.26,100,1,12.73,100,1,14.46,200,2,12.71,100,1,14.48,700,1,12.50,700,1,14.49,100,1,12.46,100,1,14.54,700,1,12.43,700,1,14.56,800,2,ARL,341663105
2025-07-17T16:15:17.050812161Z,2025-07-17T16:15:17.050646751Z,160,2,1108,C,A,10,13.40,0,0,13.40,23,1,13.11,100,1,13.74,2,1,12.98,200,2,13.75,100,1,12.96,2,1,14.22,100,1,12.86,100,1,14.26,100,1,12.73,100,1,14.46,200,2,12.71,100,1,14.48,700,1,12.50,700,1,14.49,100,1,12.46,100,1,14.54,700,1,12.43,700,1,14.56,800,2,ARL,341662133
2025-07-17T16:15:17.050812161Z,2025-07-17T16:15:17.050646751Z,160,2,1108,A,A,10,13.40,0,0,13.40,23,1,13.11,100,1,13.74,2,1,12.98,200,2,13.75,100,1,12.96,2,1,14.22,100,1,12.86,100,1,14.26,100,1,12.73,100,1,14.46,200,2,12.71,100,1,14.48,700,1,12.50,700,1,14.49,100,1,12.46,100,1,14.54,700,1,12.43,700,1,14.56,800,2,ARL,341663261
2025-07-17T16:15:17.051644859Z,2025-07-17T16:15:17.051479522Z,160,2,1108,C,A,10,13.40,0,0,13.40,23,1,13.11,100,1,13.74,2,1,12.98,200,2,13.75,100,1,12.96,2,1,14.22,100,1,12.86,100,1,14.26,100,1,12.73,100,1,14.46,200,2,12.71,100,1,14.48,700,1,12.50,700,1,14.49,100,1,12.46,100,1,14.54,700,1,12.43,700,1,14.56,800,2,ARL,341662125
2025-07-17T16:15:17.051644859Z,2025-07-17T16:15:17.051479522Z,160,2,1108,A,A,10,13.40,0,0,13.40,23,1,13.11,100,1,13.74,2,1,12.98,200,2,13.75,100,1,12.96,2,1,14.22,100,1,12.86,100,1,14.26,100,1,12.73,100,1,14.46,200,2,12.71,100,1,14.48,700,1,12.50,700,1,14.49,100,1,12.46,100,1,14.54,700,1,12.43,700,1,14.56,800,2,ARL,341663289
2025-07-17T16:15:17.054159307Z,2025-07-17T16:15:17.053993491Z,160,2,1108,C,A,10,13.40,0,0,13.40,23,1,13.11,100,1,13.74,2,1,12.98,200,2,13.75,100,1,12.96,2,1,14.22,100,1,12.86,100,1,14.26,100,1,12.73,100,1,14.46,200,2,12.71,100,1,14.48,700,1,12.50,700,1,14.49,100,1,12.46,100,1,14.54,700,1,12.43,700,1,14.56,800,2,ARL,341662137
2025-07-17T16:15:17.054159307Z,2025-07-17T16:15:17.053993491Z,160,2,1108,A,A,10,13.40,0,0,13.40,23,1,13.11,100,1,13.74,2,1,12.98,200,2,13.75,100,1,12.96,2,1,14.22,100,1,12.86,100,1,14.26,100,1,12.73,100,1,14.46,200,2,12.71,100,1,14.48,700,1,12.50,700,1,14.49,100,1,12.46,100,1,14.54,700,1,12.43,700,1,14.56,800,2,ARL,341663317
2025-07-17T16:15:17.059504149Z,2025-07-17T16:15:17.059338704Z,160,2,1108,C,A,10,13.40,0,0,13.40,23,1,13.11,100,1,13.74,2,1,12.98,200,2,13.75,100,1,12.96,2,1,14.22,100,1,12.86,100,1,14.46,200,2,12.73,100,1,14.48,700,1,12.71,100,1,14.49,100,1,12.50,700,1,14.54,700,1,12.46,100,1,14.56,800,2,12.43,700,1,14.60,100,1,ARL,341662313
2025-07-17T16:15:17.059552653Z,2025-07-17T16:15:17.059387360Z,160,2,1108,A,A,10,13.40,0,0,13.40,23,1,13.11,100,1,13.74,2,1,12.98,200,2,13.75,100,1,12.96,2,1,14.03,100,1,12.86,100,1,14.22,100,1,12.73,100,1,14.46,200,2,12.71,100,1,14.48,700,1,12.50,700,1,14.49,100,1,12.46,100,1,14.54,700,1,12.43,700,1,14.56,800,2,ARL,341663401
2025-07-17T16:15:17.084101480Z,2025-07-17T16:15:17.083936164Z,160,2,1108,C,A,10,13.40,0,0,13.40,23,1,13.11,100,1,13.74,2,1,12.98,200,2,13.75,100,1,12.96,2,1,14.03,100,1,12.86,100,1,14.22,100,1,12.73,100,1,14.46,200,2,12.71,100,1,14.48,700,1,12.50,700,1,14.49,100,1,12.46,100,1,14.54,700,1,12.43,700,1,14.56,800,2,ARL,341662117
2025-07-17T16:15:17.084101480Z,2025-07-17T16:15:17.083936164Z,160,2,1108,A,A,10,13.40,0,0,13.40,23,1,13.11,100,1,13.74,2,1,12.98,200,2,13.75,100,1,12.96,2,1,14.03,100,1,12.86,100,1,14.22,100,1,12.73,100,1,14.46,200,2,12.71,100,1,14.48,700,1,12.50,700,1,14.49,100,1,12.46,100,1,14.54,700,1,12.43,700,1,14.56,800,2,ARL,341663737
2025-07-17T16:15:17.087853488Z,2025-07-17T16:15:17.087688271Z,160,2,1108,C,A,10,13.40,0,0,13.40,23,1,13.11,100,1,13.74,2,1,12.98,200,2,13.75,100,1,12.96,2,1,14.03,100,1,12.86,100,1,14.22,100,1,12.73,100,1,14.46,200,2,12.71,100,1,14.48,700,1,12.50,700,1,14.49,100,1,12.46,100,1,14.54,700,1,12.43,700,1,14.56,800,2,ARL,341662429
2025-07-17T16:15:17.087853488Z,2025-07-17T16:15:17.087688271Z,160,2,1108,A,A,10,13.40,0,0,13.40,23,1,13.11,100,1,13.74,2,1,12.98,200,2,13.75,100,1,12.96,2,1,14.03,100,1,12.86,100,1,14.22,100,1,12.73,100,1,14.46,200,2,12.71,100,1,14.48,700,1,12.50,700,1,14.49,100,1,12.46,100,1,14.54,700,1,12.43,700,1,14.56,800,2,ARL,341663749
2025-07-17T16:15:17.643818240Z,2025-07-17T16:15:17.643653020Z,160,2,1108,C,A,10,13.40,0,0,13.40,23,1,13.11,100,1,13.74,2,1,12.98,200,2,13.75,100,1,12.96,2,1,14.03,100,1,12.86,100,1,14.22,100,1,12.73,100,1,14.46,200,2,12.71,100,1,14.48,700,1,12.50,700,1,14.49,100,1,12.46,100,1,14.54,700,1,12.43,700,1,14.56,800,2,ARL,341662113
2025-07-17T16:15:17.644168944Z,2025-07-17T16:15:17.644003726Z,160,2,1108,A,A,10,13.40,0,0,13.40,23,1,13.11,100,1,13.74,2,1,12.98,200,2,13.75,100,1,12.96,2,1,14.03,100,1,12.86,100,1,14.22,100,1,12.73,100,1,14.36,100,1,12.71,100,1,14.46,200,2,12.50,700,1,14.48,700,1,12.46,100,1,14.49,100,1,12.43,700,1,14.54,700,1,ARL,341671053
2025-07-17T16:15:35.998576859Z,2025-07-17T16:15:35.998410310Z,160,2,1108,T,N,10,13.40,0,0,13.40,23,1,13.11,100,1,13.74,2,1,12.98,200,2,13.75,100,1,12.96,2,1,14.03,100,1,12.86,100,1,14.22,100,1,12.73,100,1,14.36,100,1,12.71,100,1,14.46,200,2,12.50,700,1,14.48,700,1,12.46,100,1,14.49,100,1,12.43,700,1,14.54,700,1,ARL,0
2025-07-17T16:15:35.999140348Z,2025-07-17T16:15:35.998974923Z,160,2,1108,C,B,10,13.40,0,0,13.40,23,1,13.11,100,1,13.74,2,1,12.98,200,2,13.75,100,1,12.96,2,1,14.03,100,1,12.86,100,1,14.22,100,1,12.73,100,1,14.36,100,1,12.71,100,1,14.46,200,2,12.50,700,1,14.48,700,1,12.46,100,1,14.49,100,1,12.43,700,1,14.54,700,1,ARL,336572057
2025-07-17T16:15:35.999140348Z,2025-07-17T16:15:35.998974923Z,160,2,1108,A,B,10,13.40,0,0,13.40,23,1,13.11,100,1,13.74,2,1,12.98,200,2,13.75,100,1,12.96,2,1,14.03,100,1,12.86,100,1,14.22,100,1,12.73,100,1,14.36,100,1,12.71,100,1,14.46,200,2,12.50,700,1,14.48,700,1,12.46,100,1,14.49,100,1,12.43,700,1,14.54,700,1,ARL,342029561
2025-07-17T16:15:35.999762137Z,2025-07-17T16:15:35.999596382Z,160,2,1108,C,B,10,13.40,0,0,13.40,23,1,13.11,100,1,13.74,2,1,12.98,200,2,13.75,100,1,12.96,2,1,14.03,100,1,12.86,100,1,14.22,100,1,12.73,100,1,14.36,100,1,12.71,100,1,14.46,200,2,12.50,700,1,14.48,700,1,12.46,100,1,14.49,100,1,12.43,700,1,14.54,700,1,ARL,336572069
2025-07-17T16:15:35.999762137Z,2025-07-17T16:15:35.999596382Z,160,2,1108,A,B,10,13.40,0,0,13.40,23,1,13.11,100,1,13.74,2,1,12.98,200,2,13.75,100,1,12.96,2,1,14.03,100,1,12.86,100,1,14.22,100,1,12.73,100,1,14.36,100,1,12.71,100,1,14.46,200,2,12.50,700,1,14.48,700,1,12.46,100,1,14.49,100,1,12.43,700,1,14.54,700,1,ARL,342029581
2025-07-17T16:16:30.787448429Z,2025-07-17T16:16:30.787282866Z,160,2,1108,C,B,10,13.40,0,0,13.40,23,1,13.11,100,1,13.74,2,1,12.98,200,2,13.75,100,1,12.86,100,1,14.03,100,1,12.73,100,1,14.22,100,1,12.71,100,1,14.36,100,1,12.50,700,1,14.46,200,2,12.46,100,1,14.48,700,1,12.43,700,1,14.49,100,1,12.42,700,1,14.54,700,1,ARL,339356397
2025-07-17T16:16:30.787448429Z,2025-07-17T16:16:30.787282866Z,160,2,1108,A,B,10,13.40,0,0,13.40,23,1,13.11,100,1,13.74,2,1,13.03,2,1,13.75,100,1,12.98,200,2,14.03,100,1,12.86,100,1,14.22,100,1,12.73,100,1,14.36,100,1,12.71,100,1,14.46,200,2,12.50,700,1,14.48,700,1,12.46,100,1,14.49,100,1,12.43,700,1,14.54,700,1,ARL,343084165
2025-07-17T16:17:22.832948558Z,2025-07-17T16:17:22.832783132Z,160,2,1108,A,A,10,13.40,0,0,13.40,23,1,13.11,100,1,13.47,15,1,13.03,2,1,13.74,2,1,12.98,200,2,13.75,100,1,12.86,100,1,14.03,100,1,12.73,100,1,14.22,100,1,12.71,100,1,14.36,100,1,12.50,700,1,14.46,200,2,12.46,100,1,14.48,700,1,12.43,700,1,14.49,100,1,ARL,344211173
2025-07-17T16:17:23.620456421Z,2025-07-17T16:17:23.620290881Z,160,2,1108,C,A,10,13.40,0,0,13.40,23,1,13.11,100,1,13.47,15,1,13.03,2,1,13.74,2,1,12.98,200,2,14.03,100,1,12.86,100,1,14.22,100,1,12.73,100,1,14.36,100,1,12.71,100,1,14.46,200,2,12.50,700,1,14.48,700,1,12.46,100,1,14.49,100,1,12.43,700,1,14.54,700,1,ARL,341663101
2025-07-17T16:17:23.620456421Z,2025-07-17T16:17:23.620290881Z,160,2,1108,A,A,10,13.40,0,0,13.40,23,1,13.11,100,1,13.47,15,1,13.03,2,1,13.48,100,1,12.98,200,2,13.74,2,1,12.86,100,1,14.03,100,1,12.73,100,1,14.22,100,1,12.71,100,1,14.36,100,1,12.50,700,1,14.46,200,2,12.46,100,1,14.48,700,1,12.43,700,1,14.49,100,1,ARL,344225341
2025-07-17T16:17:23.621199578Z,2025-07-17T16:17:23.621034171Z,160,2,1108,C,A,10,13.40,0,0,13.40,23,1,13.11,100,1,13.47,15,1,13.03,2,1,13.48,100,1,12.98,200,2,13.74,2,1,12.86,100,1,14.03,100,1,12.73,100,1,14.22,100,1,12.71,100,1,14.46,200,2,12.50,700,1,14.48,700,1,12.46,100,1,14.49,100,1,12.43,700,1,14.54,700,1,ARL,341671053
2025-07-17T16:17:23.621205573Z,2025-07-17T16:17:23.621040069Z,160,2,1108,C,A,10,13.40,0,0,13.40,23,1,13.11,100,1,13.47,15,1,13.03,2,1,13.48,100,1,12.98,200,2,13.74,2,1,12.86,100,1,14.03,100,1,12.73,100,1,14.22,100,1,12.71,100,1,14.46,200,2,12.50,700,1,14.48,700,1,12.46,100,1,14.49,100,1,12.43,700,1,14.54,700,1,ARL,341663749
2025-07-17T16:17:23.621205573Z,2025-07-17T16:17:23.621040069Z,160,2,1108,A,A,10,13.40,0,0,13.40,23,1,13.11,100,1,13.47,15,1,13.03,2,1,13.48,100,1,12.98,200,2,13.74,2,1,12.86,100,1,14.03,100,1,12.73,100,1,14.22,100,1,12.71,100,1,14.46,200,2,12.50,700,1,14.48,700,1,12.46,100,1,14.49,100,1,12.43,700,1,14.53,100,1,ARL,344225385
2025-07-17T16:17:23.621387062Z,2025-07-17T16:17:23.621221535Z,160,2,1108,C,A,10,13.40,0,0,13.40,23,1,13.11,100,1,13.47,15,1,13.03,2,1,13.48,100,1,12.98,200,2,13.74,2,1,12.86,100,1,14.03,100,1,12.73,100,1,14.22,100,1,12.71,100,1,14.46,200,2,12.50,700,1,14.48,700,1,12.46,100,1,14.49,100,1,12.43,700,1,14.53,100,1,ARL,341663317
2025-07-17T16:17:23.621387062Z,2025-07-17T16:17:23.621221535Z,160,2,1108,A,A,10,13.40,0,0,13.40,23,1,13.11,100,1,13.47,15,1,13.03,2,1,13.48,100,1,12.98,200,2,13.74,2,1,12.86,100,1,14.03,100,1,12.73,100,1,14.22,100,1,12.71,100,1,14.46,200,2,12.50,700,1,14.48,700,1,12.46,100,1,14.49,100,1,12.43,700,1,14.53,100,1,ARL,344225393
2025-07-17T16:17:23.621555609Z,2025-07-17T16:17:23.621389325Z,160,2,1108,A,A,10,13.40,0,0,13.40,23,1,13.11,100,1,13.47,15,1,13.03,2,1,13.48,100,1,12.98,200,2,13.74,2,1,12.86,100,1,14.03,100,1,12.73,100,1,14.08,100,1,12.71,100,1,14.22,100,1,12.50,700,1,14.46,200,2,12.46,100,1,14.48,700,1,12.43,700,1,14.49,100,1,ARL,344225397
2025-07-17T16:17:23.621978089Z,2025-07-17T16:17:23.621812403Z,160,2,1108,C,A,10,13.40,0,0,13.40,23,1,13.11,100,1,13.47,15,1,13.03,2,1,13.48,100,1,12.98,200,2,13.74,2,1,12.86,100,1,14.03,100,1,12.73,100,1,14.08,100,1,12.71,100,1,14.22,100,1,12.50,700,1,14.46,200,2,12.46,100,1,14.48,700,1,12.43,700,1,14.49,100,1,ARL,341662145
2025-07-17T16:17:23.621978089Z,2025-07-17T16:17:23.621812403Z,160,2,1108,A,A,10,13.40,0,0,13.40,23,1,13.11,100,1,13.47,15,1,13.03,2,1,13.48,100,1,12.98,200,2,13.74,2,1,12.86,100,1,14.03,100,1,12.73,100,1,14.08,100,1,12.71,100,1,14.22,100,1,12.50,700,1,14.46,200,2,12.46,100,1,14.48,700,1,12.43,700,1,14.49,100,1,ARL,344225405
2025-07-17T16:17:23.622834183Z,2025-07-17T16:17:23.622668656Z,160,2,1108,C,A,10,13.40,0,0,13.40,23,1,13.11,100,1,13.47,15,1,13.03,2,1,13.48,100,1,12.98,200,2,13.74,2,1,12.86,100,1,14.03,100,1,12.73,100,1,14.08,100,1,12.71,100,1,14.22,100,1,12.50,700,1,14.46,200,2,12.46,100,1,14.48,700,1,12.43,700,1,14.49,100,1,ARL,341663261
2025-07-17T16:17:23.622834183Z,2025-07-17T16:17:23.622668656Z,160,2,1108,A,A,10,13.40,0,0,13.40,23,1,13.11,100,1,13.47,15,1,13.03,2,1,13.48,100,1,12.98,200,2,13.74,2,1,12.86,100,1,14.03,100,1,12.73,100,1,14.08,100,1,12.71,100,1,14.22,100,1,12.50,700,1,14.43,100,1,12.46,100,1,14.46,200,2,12.43,700,1,14.48,700,1,ARL,344225449
2025-07-17T16:17:23.623011421Z,2025-07-17T16:17:23.622845856Z,160,2,1108,C,A,10,13.40,0,0,13.40,23,1,13.11,100,1,13.47,15,1,13.03,2,1,13.48,100,1,12.98,200,2,13.74,2,1,12.86,100,1,14.03,100,1,12.73,100,1,14.08,100,1,12.71,100,1,14.22,100,1,12.50,700,1,14.43,100,1,12.46,100,1,14.46,200,2,12.43,700,1,14.48,700,1,ARL,341661985
2025-07-17T16:17:23.623011421Z,2025-07-17T16:17:23.622845856Z,160,2,1108,A,A,10,13.40,0,0,13.40,23,1,13.11,100,1,13.47,15,1,13.03,2,1,13.48,100,1,12.98,200,2,13.74,2,1,12.86,100,1,14.03,100,1,12.73,100,1,14.08,100,1,12.71,100,1,14.22,100,1,12.50,700,1,14.27,100,1,12.46,100,1,14.43,100,1,12.43,700,1,14.46,200,2,ARL,344225453
2025-07-17T16:17:23.623052802Z,2025-07-17T16:17:23.622887237Z,160,2,1108,C,A,10,13.40,0,0,13.40,23,1,13.11,100,1,13.47,15,1,13.03,2,1,13.48,100,1,12.98,200,2,13.74,2,1,12.86,100,1,14.03,100,1,12.73,100,1,14.08,100,1,12.71,100,1,14.22,100,1,12.50,700,1,14.27,100,1,12.46,100,1,14.43,100,1,12.43,700,1,14.46,200,2,ARL,341663289
2025-07-17T16:17:23.623052802Z,2025-07-17T16:17:23.622887237Z,160,2,1108,A,A,10,13.40,0,0,13.40,23,1,13.11,100,1,13.47,15,1,13.03,2,1,13.48,100,1,12.98,200,2,13.74,2,1,12.86,100,1,14.03,100,1,12.73,100,1,14.08,100,1,12.71,100,1,14.22,100,1,12.50,700,1,14.27,100,1,12.46,100,1,14.43,100,1,12.43,700,1,14.46,200,2,ARL,344225457
2025-07-17T16:17:23.624578699Z,2025-07-17T16:17:23.624413295Z,160,2,1108,C,A,10,13.40,0,0,13.40,23,1,13.11,100,1,13.47,15,1,13.03,2,1,13.48,100,1,12.98,200,2,13.74,2,1,12.86,100,1,14.03,100,1,12.73,100,1,14.08,100,1,12.71,100,1,14.22,100,1,12.50,700,1,14.27,100,1,12.46,100,1,14.43,100,1,12.43,700,1,14.46,200,2,ARL,341662149
2025-07-17T16:17:23.624578699Z,2025-07-17T16:17:23.624413295Z,160,2,1108,A,A,10,13.40,0,0,13.40,23,1,13.11,100,1,13.47,15,1,13.03,2,1,13.48,100,1,12.98,200,2,13.74,2,1,12.86,100,1,14.03,100,1,12.73,100,1,14.08,100,1,12.71,100,1,14.22,100,1,12.50,700,1,14.27,100,1,12.46,100,1,14.43,100,1,12.43,700,1,14.46,200,2,ARL,344225485
2025-07-17T16:17:23.624638111Z,2025-07-17T16:17:23.624472504Z,160,2,1108,C,A,10,13.40,0,0,13.40,23,1,13.11,100,1,13.47,15,1,13.03,2,1,13.48,100,1,12.98,200,2,13.74,2,1,12.86,100,1,14.03,100,1,12.73,100,1,14.08,100,1,12.71,100,1,14.22,100,1,12.50,700,1,14.27,100,1,12.46,100,1,14.43,100,1,12.43,700,1,14.46,200,2,ARL,341663737
2025-07-17T16:17:23.624638111Z,2025-07-17T16:17:23.624472504Z,160,2,1108,A,A,10,13.40,0,0,13.40,23,1,13.11,100,1,13.47,15,1,13.03,2,1,13.48,100,1,12.98,200,2,13.74,2,1,12.86,100,1,14.03,100,1,12.73,100,1,14.08,100,1,12.71,100,1,14.22,100,1,12.50,700,1,14.27,100,1,12.46,100,1,14.43,200,2,12.43,700,1,14.46,200,2,ARL,344225489
2025-07-17T16:17:23.627653611Z,2025-07-17T16:17:23.627488304Z,160,2,1108,C,A,10,13.40,0,0,13.40,23,1,13.11,100,1,13.47,15,1,13.03,2,1,13.48,100,1,12.98,200,2,13.74,2,1,12.86,100,1,14.08,100,1,12.73,100,1,14.22,100,1,12.71,100,1,14.27,100,1,12.50,700,1,14.43,200,2,12.46,100,1,14.46,200,2,12.43,700,1,14.48,700,1,ARL,341663401
2025-07-17T16:17:23.627704598Z,2025-07-17T16:17:23.627539425Z,160,2,1108,A,A,10,13.40,0,0,13.40,23,1,13.11,100,1,13.47,15,1,13.03,2,1,13.48,100,1,12.98,200,2,13.74,2,1,12.86,100,1,13.75,100,1,12.73,100,1,14.08,100,1,12.71,100,1,14.22,100,1,12.50,700,1,14.27,100,1,12.46,100,1,14.43,200,2,12.43,700,1,14.46,200,2,ARL,344225533
2025-07-17T16:17:23.653807815Z,2025-07-17T16:17:23.653641816Z,160,2,1108,A,A,10,13.40,0,0,13.40,23,1,13.11,100,1,13.47,15,1,13.03,2,1,13.48,100,1,12.98,200,2,13.74,2,1,12.86,100,1,13.75,100,1,12.73,100,1,14.08,100,1,12.71,100,1,14.22,100,1,12.50,700,1,14.27,100,1,12.46,100,1,14.43,200,2,12.43,700,1,14.46,200,2,ARL,344225829
2025-07-17T16:17:23.653821034Z,2025-07-17T16:17:23.653655443Z,160,2,1108,C,A,10,13.40,0,0,13.40,23,1,13.11,100,1,13.47,15,1,13.03,2,1,13.48,100,1,12.98,200,2,13.74,2,1,12.86,100,1,13.75,100,1,12.73,100,1,14.08,100,1,12.71,100,1,14.22,100,1,12.50,700,1,14.27,100,1,12.46,100,1,14.43,200,2,12.43,700,1,14.46,200,2,ARL,341661849
2025-07-17T16:17:24.832340976Z,2025-07-17T16:17:24.832175508Z,160,2,1108,C,A,10,13.40,0,0,13.40,23,1,13.11,100,1,13.48,100,1,13.03,2,1,13.74,2,1,12.98,200,2,13.75,100,1,12.86,100,1,14.08,100,1,12.73,100,1,14.22,100,1,12.71,100,1,14.27,100,1,12.50,700,1,14.43,200,2,12.46,100,1,14.46,200,2,12.43,700,1,14.48,700,1,ARL,344211173
2025-07-17T16:17:26.823562625Z,2025-07-17T16:17:26.823396428Z,160,2,1108,C,A,10,13.40,0,0,13.40,23,1,13.11,100,1,13.74,2,1,13.03,2,1,13.75,100,1,12.98,200,2,14.08,100,1,12.86,100,1,14.22,100,1,12.73,100,1,14.27,100,1,12.71,100,1,14.43,200,2,12.50,700,1,14.46,200,2,12.46,100,1,14.48,700,1,12.43,700,1,14.49,100,1,ARL,344225341
2025-07-17T16:17:26.823923686Z,2025-07-17T16:17:26.823758552Z,160,2,1108,A,A,10,13.40,0,0,13.40,23,1,13.11,100,1,13.74,2,1,13.03,2,1,13.75,100,1,12.98,200,2,14.08,100,1,12.86,100,1,14.22,100,1,12.73,100,1,14.27,100,1,12.71,100,1,14.43,200,2,12.50,700,1,14.46,200,2,12.46,100,1,14.48,700,1,12.43,700,1,14.49,100,1,ARL,344280537
2025-07-17T16:17:26.823937553Z,2025-07-17T16:17:26.823771696Z,160,2,1108,C,A,10,13.40,0,0,13.40,23,1,13.11,100,1,13.74,2,1,13.03,2,1,13.75,100,1,12.98,200,2,14.08,100,1,12.86,100,1,14.22,100,1,12.73,100,1,14.27,100,1,12.71,100,1,14.43,200,2,12.50,700,1,14.46,200,2,12.46,100,1,14.48,700,1,12.43,700,1,14.49,100,1,ARL,344225829
2025-07-17T16:17:26.824304510Z,2025-07-17T16:17:26.824137854Z,160,2,1108,C,A,10,13.40,0,0,13.40,23,1,13.11,100,1,13.74,2,1,13.03,2,1,13.75,100,1,12.98,200,2,14.08,100,1,12.86,100,1,14.22,100,1,12.73,100,1,14.27,100,1,12.71,100,1,14.43,200,2,12.50,700,1,14.46,200,2,12.46,100,1,14.48,700,1,12.43,700,1,14.49,100,1,ARL,344225385
2025-07-17T16:17:26.824304510Z,2025-07-17T16:17:26.824137854Z,160,2,1108,A,A,10,13.40,0,0,13.40,23,1,13.11,100,1,13.74,2,1,13.03,2,1,13.75,100,1,12.98,200,2,14.08,100,1,12.86,100,1,14.22,100,1,12.73,100,1,14.27,100,1,12.71,100,1,14.43,200,2,12.50,700,1,14.46,200,2,12.46,100,1,14.48,700,1,12.43,700,1,14.49,100,1,ARL,344280577
2025-07-17T16:17:26.824304510Z,2025-07-17T16:17:26.824138799Z,160,2,1108,C,A,10,13.40,0,0,13.40,23,1,13.11,100,1,13.74,2,1,13.03,2,1,13.75,100,1,12.98,200,2,14.22,100,1,12.86,100,1,14.27,100,1,12.73,100,1,14.43,200,2,12.71,100,1,14.46,200,2,12.50,700,1,14.48,700,1,12.46,100,1,14.49,100,1,12.43,700,1,14.54,700,1,ARL,344225397
2025-07-17T16:17:26.824657956Z,2025-07-17T16:17:26.824492765Z,160,2,1108,A,A,10,13.40,0,0,13.40,23,1,13.11,100,1,13.74,2,1,13.03,2,1,13.75,100,1,12.98,200,2,14.22,100,1,12.86,100,1,14.27,100,1,12.73,100,1,14.36,100,1,12.71,100,1,14.43,200,2,12.50,700,1,14.46,200,2,12.46,100,1,14.48,700,1,12.43,700,1,14.49,100,1,ARL,344280617
2025-07-17T16:17:26.825988253Z,2025-07-17T16:17:26.825823014Z,160,2,1108,C,A,10,13.40,0,0,13.40,23,1,13.11,100,1,13.74,2,1,13.03,2,1,13.75,100,1,12.98,200,2,14.22,100,1,12.86,100,1,14.36,100,1,12.73,100,1,14.43,200,2,12.71,100,1,14.46,200,2,12.50,700,1,14.48,700,1,12.46,100,1,14.49,100,1,12.43,700,1,14.54,700,1,ARL,344225453
2025-07-17T16:17:26.826051208Z,2025-07-17T16:17:26.825885765Z,160,2,1108,C,A,10,13.40,0,0,13.40,23,1,13.11,100,1,13.74,2,1,13.03,2,1,13.75,100,1,12.98,200,2,14.22,100,1,12.86,100,1,14.36,100,1,12.73,100,1,14.43,100,1,12.71,100,1,14.46,200,2,12.50,700,1,14.48,700,1,12.46,100,1,14.49,100,1,12.43,700,1,14.54,700,1,ARL,344225449
2025-07-17T16:17:26.826051208Z,2025-07-17T16:17:26.825885765Z,160,2,1108,A,A,10,13.40,0,0,13.40,23,1,13.11,100,1,13.74,2,1,13.03,2,1,13.75,100,1,12.98,200,2,14.22,100,1,12.86,100,1,14.36,100,1,12.73,100,1,14.43,100,1,12.71,100,1,14.46,200,2,12.50,700,1,14.48,700,1,12.46,100,1,14.49,100,1,12.43,700,1,14.54,700,1,ARL,344280641
2025-07-17T16:17:26.826159189Z,2025-07-17T16:17:26.825993909Z,160,2,1108,A,A,10,13.40,0,0,13.40,23,1,13.11,100,1,13.74,2,1,13.03,2,1,13.75,100,1,12.98,200,2,14.22,100,1,12.86,100,1,14.36,100,1,12.73,100,1,14.43,100,1,12.71,100,1,14.46,200,2,12.50,700,1,14.48,700,1,12.46,100,1,14.49,100,1,12.43,700,1,14.54,800,2,ARL,344280645
2025-07-17T16:17:26.826294122Z,2025-07-17T16:17:26.826128663Z,160,2,1108,C,A,10,13.40,0,0,13.40,23,1,13.11,100,1,13.74,2,1,13.03,2,1,13.75,100,1,12.98,200,2,14.22,100,1,12.86,100,1,14.36,100,1,12.73,100,1,14.43,100,1,12.71,100,1,14.46,200,2,12.50,700,1,14.48,700,1,12.46,100,1,14.49,100,1,12.43,700,1,14.54,800,2,ARL,344225405
2025-07-17T16:17:26.826294122Z,2025-07-17T16:17:26.826128663Z,160,2,1108,A,A,10,13.40,0,0,13.40,23,1,13.11,100,1,13.74,2,1,13.03,2,1,13.75,100,1,12.98,200,2,14.22,100,1,12.86,100,1,14.36,100,1,12.73,100,1,14.43,100,1,12.71,100,1,14.46,200,2,12.50,700,1,14.48,700,1,12.46,100,1,14.49,100,1,12.43,700,1,14.54,800,2,ARL,344280653
2025-07-17T16:17:26.828538841Z,2025-07-17T16:17:26.828373551Z,160,2,1108,C,A,10,13.40,0,0,13.40,23,1,13.11,100,1,13.74,2,1,13.03,2,1,14.22,100,1,12.98,200,2,14.36,100,1,12.86,100,1,14.43,100,1,12.73,100,1,14.46,200,2,12.71,100,1,14.48,700,1,12.50,700,1,14.49,100,1,12.46,100,1,14.54,800,2,12.43,700,1,14.56,700,1,ARL,344225533
2025-07-17T16:17:26.828589142Z,2025-07-17T16:17:26.828423432Z,160,2,1108,A,A,10,13.40,0,0,13.40,23,1,13.11,100,1,13.74,2,1,13.03,2,1,14.03,100,1,12.98,200,2,14.22,100,1,12.86,100,1,14.36,100,1,12.73,100,1,14.43,100,1,12.71,100,1,14.46,200,2,12.50,700,1,14.48,700,1,12.46,100,1,14.49,100,1,12.43,700,1,14.54,800,2,ARL,344280689
2025-07-17T16:17:26.828846606Z,2025-07-17T16:17:26.828681062Z,160,2,1108,C,A,10,13.40,0,0,13.40,23,1,13.11,100,1,14.03,100,1,13.03,2,1,14.22,100,1,12.98,200,2,14.36,100,1,12.86,100,1,14.43,100,1,12.73,100,1,14.46,200,2,12.71,100,1,14.48,700,1,12.50,700,1,14.49,100,1,12.46,100,1,14.54,800,2,12.43,700,1,14.56,700,1,ARL,340449865
2025-07-17T16:17:26.828846606Z,2025-07-17T16:17:26.828681062Z,160,2,1108,A,A,10,13.40,0,0,13.40,23,1,13.11,100,1,13.97,2,1,13.03,2,1,14.03,100,1,12.98,200,2,14.22,100,1,12.86,100,1,14.36,100,1,12.73,100,1,14.43,100,1,12.71,100,1,14.46,200,2,12.50,700,1,14.48,700,1,12.46,100,1,14.49,100,1,12.43,700,1,14.54,800,2,ARL,344280721
2025-07-17T16:17:26.830066702Z,2025-07-17T16:17:26.829901530Z,160,2,1108,C,A,10,13.40,0,0,13.40,23,1,13.11,100,1,13.97,2,1,13.03,2,1,14.03,100,1,12.98,200,2,14.22,100,1,12.86,100,1,14.36,100,1,12.73,100,1,14.43,100,1,12.71,100,1,14.46,200,2,12.50,700,1,14.48,700,1,12.46,100,1,14.49,100,1,12.43,700,1,14.54,800,2,ARL,344280641
2025-07-17T16:17:26.830066702Z,2025-07-17T16:17:26.829901530Z,160,2,1108,A,A,10,13.40,0,0,13.40,23,1,13.11,100,1,13.97,2,1,13.03,2,1,14.03,100,1,12.98,200,2,14.22,100,1,12.86,100,1,14.36,100,1,12.73,100,1,14.43,100,1,12.71,100,1,14.46,200,2,12.50,700,1,14.48,700,1,12.46,100,1,14.49,100,1,12.43,700,1,14.54,800,2,ARL,344280825
2025-07-17T16:17:26.832026257Z,2025-07-17T16:17:26.831860798Z,160,2,1108,C,A,10,13.40,0,0,13.40,23,1,13.11,100,1,13.97,2,1,13.03,2,1,14.03,100,1,12.98,200,2,14.22,100,1,12.86,100,1,14.36,100,1,12.73,100,1,14.43,100,1,12.71,100,1,14.46,200,2,12.50,700,1,14.48,700,1,12.46,100,1,14.49,100,1,12.43,700,1,14.54,800,2,ARL,344225457
2025-07-17T16:17:26.832026257Z,2025-07-17T16:17:26.831860798Z,160,2,1108,A,A,10,13.40,0,0,13.40,23,1,13.11,100,1,13.97,2,1,13.03,2,1,14.03,100,1,12.98,200,2,14.22,100,1,12.86,100,1,14.36,100,1,12.73,100,1,14.43,100,1,12.71,100,1,14.46,200,2,12.50,700,1,14.48,700,1,12.46,100,1,14.49,100,1,12.43,700,1,14.54,800,2,ARL,344280917
2025-07-17T16:17:26.833194882Z,2025-07-17T16:17:26.833029512Z,160,2,1108,C,A,10,13.40,0,0,13.40,23,1,13.11,100,1,13.97,2,1,13.03,2,1,14.03,100,1,12.98,200,2,14.22,100,1,12.86,100,1,14.36,100,1,12.73,100,1,14.43,100,1,12.71,100,1,14.46,200,2,12.50,700,1,14.48,700,1,12.46,100,1,14.49,100,1,12.43,700,1,14.54,800,2,ARL,344225393
2025-07-17T16:17:26.833194882Z,2025-07-17T16:17:26.833029512Z,160,2,1108,A,A,10,13.40,0,0,13.40,23,1,13.11,100,1,13.97,2,1,13.03,2,1,14.03,100,1,12.98,200,2,14.22,100,1,12.86,100,1,14.36,100,1,12.73,100,1,14.43,100,1,12.71,100,1,14.46,200,2,12.50,700,1,14.48,700,1,12.46,100,1,14.49,100,1,12.43,700,1,14.54,800,2,ARL,344280941
2025-07-17T16:17:26.834911649Z,2025-07-17T16:17:26.834746475Z,160,2,1108,C,A,10,13.40,0,0,13.40,23,1,13.11,100,1,13.97,2,1,13.03,2,1,14.22,100,1,12.98,200,2,14.36,100,1,12.86,100,1,14.43,100,1,12.73,100,1,14.46,200,2,12.71,100,1,14.48,700,1,12.50,700,1,14.49,100,1,12.46,100,1,14.54,800,2,12.43,700,1,14.56,700,1,ARL,344280689
2025-07-17T16:17:26.834961494Z,2025-07-17T16:17:26.834796238Z,160,2,1108,A,A,10,13.40,0,0,13.40,23,1,13.11,100,1,13.97,2,1,13.03,2,1,14.22,100,1,12.98,200,2,14.25,100,1,12.86,100,1,14.36,100,1,12.73,100,1,14.43,100,1,12.71,100,1,14.46,200,2,12.50,700,1,14.48,700,1,12.46,100,1,14.49,100,1,12.43,700,1,14.54,800,2,ARL,344280953
2025-07-17T16:17:26.846567340Z,2025-07-17T16:17:26.846401696Z,160,2,1108,C,A,10,13.40,0,0,13.40,23,1,13.11,100,1,13.97,2,1,13.03,2,1,14.22,100,1,12.98,200,2,14.25,100,1,12.86,100,1,14.36,100,1,12.73,100,1,14.43,100,1,12.71,100,1,14.46,200,2,12.50,700,1,14.48,700,1,12.46,100,1,14.49,100,1,12.43,700,1,14.54,800,2,ARL,344225485
2025-07-17T16:17:26.846567340Z,2025-07-17T16:17:26.846401696Z,160,2,1108,A,A,10,13.40,0,0,13.40,23,1,13.11,100,1,13.97,2,1,13.03,2,1,14.22,100,1,12.98,200,2,14.25,100,1,12.86,100,1,14.36,100,1,12.73,100,1,14.43,100,1,12.71,100,1,14.46,200,2,12.50,700,1,14.48,700,1,12.46,100,1,14.49,100,1,12.43,700,1,14.54,800,2,ARL,344281229
2025-07-17T16:17:26.849670659Z,2025-07-17T16:17:26.849505109Z,160,2,1108,C,A,10,13.40,0,0,13.40,23,1,13.11,100,1,13.97,2,1,13.03,2,1,14.22,100,1,12.98,200,2,14.25,100,1,12.86,100,1,14.36,100,1,12.73,100,1,14.46,200,2,12.71,100,1,14.48,700,1,12.50,700,1,14.49,100,1,12.46,100,1,14.54,800,2,12.43,700,1,14.56,700,1,ARL,344225489
2025-07-17T16:17:26.849670659Z,2025-07-17T16:17:26.849505109Z,160,2,1108,A,A,10,13.40,0,0,13.40,23,1,13.11,100,1,13.97,2,1,13.03,2,1,14.22,100,1,12.98,200,2,14.25,100,1,12.86,100,1,14.36,100,1,12.73,100,1,14.46,200,2,12.71,100,1,14.48,700,1,12.50,700,1,14.49,100,1,12.46,100,1,14.54,800,2,12.43,700,1,14.56,700,1,ARL,344281257
2025-07-17T16:17:26.874430238Z,2025-07-17T16:17:26.874264677Z,160,2,1108,C,A,10,13.40,0,0,13.40,23,1,13.11,100,1,13.97,2,1,13.03,2,1,14.22,100,1,12.98,200,2,14.25,100,1,12.86,100,1,14.36,100,1,12.73,100,1,14.46,200,2,12.71,100,1,14.48,700,1,12.50,700,1,14.49,100,1,12.46,100,1,14.54,800,2,12.43,700,1,14.56,700,1,ARL,344280577
2025-07-17T16:17:26.874430238Z,2025-07-17T16:17:26.874264677Z,160,2,1108,A,A,10,13.40,0,0,13.40,23,1,13.11,100,1,13.97,2,1,13.03,2,1,14.22,100,1,12.98,200,2,14.25,100,1,12.86,100,1,14.36,100,1,12.73,100,1,14.46,200,2,12.71,100,1,14.48,700,1,12.50,700,1,14.49,100,1,12.46,100,1,14.54,800,2,12.43,700,1,14.56,700,1,ARL,344281457
2025-07-17T16:17:27.000782790Z,2025-07-17T16:17:27.000617575Z,160,2,1108,A,A,10,13.40,0,0,13.40,23,1,13.11,100,1,13.97,2,1,13.03,2,1,13.98,100,1,12.98,200,2,14.22,100,1,12.86,100,1,14.25,100,1,12.73,100,1,14.36,100,1,12.71,100,1,14.46,200,2,12.50,700,1,14.48,700,1,12.46,100,1,14.49,100,1,12.43,700,1,14.54,800,2,ARL,344283633
2025-07-17T16:17:27.204893988Z,2025-07-17T16:17:27.204728176Z,160,2,1108,C,A,10,13.40,0,0,13.40,23,1,13.11,100,1,13.97,2,1,13.03,2,1,13.98,100,1,12.98,200,2,14.25,100,1,12.86,100,1,14.36,100,1,12.73,100,1,14.46,200,2,12.71,100,1,14.48,700,1,12.50,700,1,14.49,100,1,12.46,100,1,14.54,800,2,12.43,700,1,14.56,700,1,ARL,339365193
2025-07-17T16:17:27.204895267Z,2025-07-17T16:17:27.204730160Z,160,2,1108,A,A,10,13.40,0,0,13.40,23,1,13.11,100,1,13.97,2,1,13.03,2,1,13.98,100,1,12.98,200,2,14.25,100,1,12.86,100,1,14.36,100,1,12.73,100,1,14.46,200,2,12.71,100,1,14.48,700,1,12.50,700,1,14.49,100,1,12.46,100,1,14.53,100,1,12.43,700,1,14.54,800,2,ARL,344288585
2025-07-17T16:17:27.381792167Z,2025-07-17T16:17:27.381626601Z,160,2,1108,A,A,10,13.40,0,0,13.40,23,1,13.11,100,1,13.97,2,1,13.03,2,1,13.98,100,1,12.98,200,2,14.25,100,1,12.86,100,1,14.36,100,1,12.73,100,1,14.46,200,2,12.71,100,1,14.48,700,1,12.50,700,1,14.49,100,1,12.46,100,1,14.53,100,1,12.43,700,1,14.54,800,2,ARL,344292849
2025-07-17T16:17:27.381809823Z,2025-07-17T16:17:27.381644366Z,160,2,1108,C,A,10,13.40,0,0,13.40,23,1,13.11,100,1,13.97,2,1,13.03,2,1,13.98,100,1,12.98,200,2,14.25,100,1,12.86,100,1,14.36,100,1,12.73,100,1,14.46,200,2,12.71,100,1,14.48,700,1,12.50,700,1,14.53,100,1,12.46,100,1,14.54,800,2,12.43,700,1,14.56,700,1,ARL,339366385
2025-07-17T16:17:27.443162448Z,2025-07-17T16:17:27.442997426Z,160,2,1108,C,A,10,13.40,0,0,13.40,23,1,13.11,100,1,13.97,2,1,13.03,2,1,13.98,100,1,12.98,200,2,14.25,100,1,12.86,100,1,14.46,200,2,12.73,100,1,14.48,700,1,12.71,100,1,14.53,100,1,12.50,700,1,14.54,800,2,12.46,100,1,14.56,700,1,12.43,700,1,14.68,700,1,ARL,344280617
2025-07-17T16:17:27.443512590Z,2025-07-17T16:17:27.443347265Z,160,2,1108,A,A,10,13.40,0,0,13.40,23,1,13.11,100,1,13.97,2,1,13.03,2,1,13.98,100,1,12.98,200,2,14.25,100,1,12.86,100,1,14.46,200,2,12.73,100,1,14.48,700,1,12.71,100,1,14.53,100,1,12.50,700,1,14.54,800,2,12.46,100,1,14.56,700,1,12.43,700,1,14.60,100,1,ARL,344294245
2025-07-17T16:17:27.829055288Z,2025-07-17T16:17:27.828890080Z,160,2,1108,C,A,10,13.40,0,0,13.40,23,1,13.11,100,1,13.97,2,1,13.03,2,1,13.98,100,1,12.98,200,2,14.25,100,1,12.86,100,1,14.46,200,2,12.73,100,1,14.48,700,1,12.71,100,1,14.53,100,1,12.50,700,1,14.54,700,1,12.46,100,1,14.56,700,1,12.43,700,1,14.60,100,1,ARL,344280645
2025-07-17T16:17:27.829055288Z,2025-07-17T16:17:27.828890080Z,160,2,1108,A,A,10,13.40,0,0,13.40,23,1,13.11,100,1,13.97,2,1,13.03,2,1,13.98,100,1,12.98,200,2,14.25,100,1,12.86,100,1,14.46,200,2,12.73,100,1,14.48,700,1,12.71,100,1,14.53,100,1,12.50,700,1,14.54,700,1,12.46,100,1,14.56,700,1,12.43,700,1,14.60,100,1,ARL,344300085
2025-07-17T16:17:39.514690751Z,2025-07-17T16:17:39.514525397Z,160,2,1108,A,A,10,13.40,0,0,13.40,23,1,13.11,100,1,13.47,15,1,13.03,2,1,13.97,2,1,12.98,200,2,13.98,100,1,12.86,100,1,14.25,100,1,12.73,100,1,14.46,200,2,12.71,100,1,14.48,700,1,12.50,700,1,14.53,100,1,12.46,100,1,14.54,700,1,12.43,700,1,14.56,700,1,ARL,344587533
2025-07-17T16:17:39.829017289Z,2025-07-17T16:17:39.828851797Z,160,2,1108,C,A,10,13.40,0,0,13.40,23,1,13.11,100,1,13.47,15,1,13.03,2,1,13.97,2,1,12.98,200,2,13.98,100,1,12.86,100,1,14.25,100,1,12.73,100,1,14.46,100,1,12.71,100,1,14.48,700,1,12.50,700,1,14.53,100,1,12.46,100,1,14.54,700,1,12.43,700,1,14.56,700,1,ARL,339739285
2025-07-17T16:17:39.829017289Z,2025-07-17T16:17:39.828851797Z,160,2,1108,A,A,10,13.40,0,0,13.40,23,1,13.11,100,1,13.47,15,1,13.03,2,1,13.97,2,1,12.98,200,2,13.98,100,1,12.86,100,1,14.25,100,1,12.73,100,1,14.35,100,1,12.71,100,1,14.46,100,1,12.50,700,1,14.48,700,1,12.46,100,1,14.53,100,1,12.43,700,1,14.54,700,1,ARL,344593405
2025-07-17T16:17:39.829247357Z,2025-07-17T16:17:39.829081898Z,160,2,1108,C,A,10,13.40,0,0,13.40,23,1,13.11,100,1,13.47,15,1,13.03,2,1,13.97,2,1,12.98,200,2,13.98,100,1,12.86,100,1,14.25,100,1,12.73,100,1,14.35,100,1,12.71,100,1,14.48,700,1,12.50,700,1,14.53,100,1,12.46,100,1,14.54,700,1,12.43,700,1,14.56,700,1,ARL,339739297
2025-07-17T16:17:39.829247357Z,2025-07-17T16:17:39.829081898Z,160,2,1108,A,A,10,13.40,0,0,13.40,23,1,13.11,100,1,13.47,15,1,13.03,2,1,13.97,2,1,12.98,200,2,13.98,100,1,12.86,100,1,14.25,100,1,12.73,100,1,14.35,200,2,12.71,100,1,14.48,700,1,12.50,700,1,14.53,100,1,12.46,100,1,14.54,700,1,12.43,700,1,14.56,700,1,ARL,344593409
2025-07-17T16:17:40.321326768Z,2025-07-17T16:17:40.321161439Z,160,2,1108,C,A,10,13.40,0,0,13.40,23,1,13.11,100,1,13.47,15,1,13.03,2,1,13.97,2,1,12.98,200,2,14.25,100,1,12.86,100,1,14.35,200,2,12.73,100,1,14.48,700,1,12.71,100,1,14.53,100,1,12.50,700,1,14.54,700,1,12.46,100,1,14.56,700,1,12.43,700,1,14.60,100,1,ARL,344283633
2025-07-17T16:17:40.321326768Z,2025-07-17T16:17:40.321161439Z,160,2,1108,A,A,10,13.40,0,0,13.40,23,1,13.11,100,1,13.47,15,1,13.03,2,1,13.48,100,1,12.98,200,2,13.97,2,1,12.86,100,1,14.25,100,1,12.73,100,1,14.35,200,2,12.71,100,1,14.48,700,1,12.50,700,1,14.53,100,1,12.46,100,1,14.54,700,1,12.43,700,1,14.56,700,1,ARL,344607833
2025-07-17T16:17:40.322064038Z,2025-07-17T16:17:40.321898765Z,160,2,1108,C,A,10,13.40,0,0,13.40,23,1,13.11,100,1,13.47,15,1,13.03,2,1,13.48,100,1,12.98,200,2,13.97,2,1,12.86,100,1,14.25,100,1,12.73,100,1,14.35,200,2,12.71,100,1,14.48,700,1,12.50,700,1,14.53,100,1,12.46,100,1,14.54,700,1,12.43,700,1,14.56,700,1,ARL,344294245
2025-07-17T16:17:40.322069742Z,2025-07-17T16:17:40.321903984Z,160,2,1108,C,A,10,13.40,0,0,13.40,23,1,13.11,100,1,13.47,15,1,13.03,2,1,13.48,100,1,12.98,200,2,13.97,2,1,12.86,100,1,14.25,100,1,12.73,100,1,14.35,200,2,12.71,100,1,14.48,700,1,12.50,700,1,14.53,100,1,12.46,100,1,14.54,700,1,12.43,700,1,14.56,700,1,ARL,344281457
2025-07-17T16:17:40.322069742Z,2025-07-17T16:17:40.321903984Z,160,2,1108,A,A,10,13.40,0,0,13.40,23,1,13.11,100,1,13.47,15,1,13.03,2,1,13.48,100,1,12.98,200,2,13.97,2,1,12.86,100,1,14.25,100,1,12.73,100,1,14.35,200,2,12.71,100,1,14.48,700,1,12.50,700,1,14.53,200,2,12.46,100,1,14.54,700,1,12.43,700,1,14.56,700,1,ARL,344607889
2025-07-17T16:17:40.322416015Z,2025-07-17T16:17:40.322250847Z,160,2,1108,A,A,10,13.40,0,0,13.40,23,1,13.11,100,1,13.47,15,1,13.03,2,1,13.48,100,1,12.98,200,2,13.97,2,1,12.86,100,1,14.08,100,1,12.73,100,1,14.25,100,1,12.71,100,1,14.35,200,2,12.50,700,1,14.48,700,1,12.46,100,1,14.53,200,2,12.43,700,1,14.54,700,1,ARL,344607893
2025-07-17T16:17:40.329180897Z,2025-07-17T16:17:40.329015669Z,160,2,1108,C,A,10,13.40,0,0,13.40,23,1,13.11,100,1,13.47,15,1,13.03,2,1,13.48,100,1,12.98,200,2,13.97,2,1,12.86,100,1,14.08,100,1,12.73,100,1,14.35,200,2,12.71,100,1,14.48,700,1,12.50,700,1,14.53,200,2,12.46,100,1,14.54,700,1,12.43,700,1,14.56,700,1,ARL,344280953
2025-07-17T16:17:40.329233157Z,2025-07-17T16:17:40.329067996Z,160,2,1108,A,A,10,13.40,0,0,13.40,23,1,13.11,100,1,13.47,15,1,13.03,2,1,13.48,100,1,12.98,200,2,13.75,100,1,12.86,100,1,13.97,2,1,12.73,100,1,14.08,100,1,12.71,100,1,14.35,200,2,12.50,700,1,14.48,700,1,12.46,100,1,14.53,200,2,12.43,700,1,14.54,700,1,ARL,344608193
2025-07-17T16:17:40.330448099Z,2025-07-17T16:17:40.330282519Z,160,2,1108,C,A,10,13.40,0,0,13.40,23,1,13.11,100,1,13.47,15,1,13.03,2,1,13.48,100,1,12.98,200,2,13.75,100,1,12.86,100,1,13.97,2,1,12.73,100,1,14.08,100,1,12.71,100,1,14.35,200,2,12.50,700,1,14.48,700,1,12.46,100,1,14.53,200,2,12.43,700,1,14.54,700,1,ARL,344280653
2025-07-17T16:17:40.330448099Z,2025-07-17T16:17:40.330282519Z,160,2,1108,A,A,10,13.40,0,0,13.40,23,1,13.11,100,1,13.47,15,1,13.03,2,1,13.48,100,1,12.98,200,2,13.75,100,1,12.86,100,1,13.97,2,1,12.73,100,1,14.08,100,1,12.71,100,1,14.35,200,2,12.50,700,1,14.48,700,1,12.46,100,1,14.53,200,2,12.43,700,1,14.54,700,1,ARL,344608205
2025-07-17T16:17:40.331429414Z,2025-07-17T16:17:40.331264268Z,160,2,1108,C,A,10,13.40,0,0,13.40,23,1,13.11,100,1,13.47,15,1,13.03,2,1,13.48,100,1,12.98,200,2,13.75,100,1,12.86,100,1,13.97,2,1,12.73,100,1,14.08,100,1,12.71,100,1,14.35,200,2,12.50,700,1,14.48,700,1,12.46,100,1,14.53,200,2,12.43,700,1,14.54,700,1,ARL,344300085
2025-07-17T16:17:40.331551656Z,2025-07-17T16:17:40.331386492Z,160,2,1108,A,A,10,13.40,0,0,13.40,23,1,13.11,100,1,13.47,15,1,13.03,2,1,13.48,100,1,12.98,200,2,13.75,100,1,12.86,100,1,13.97,2,1,12.73,100,1,14.08,100,1,12.71,100,1,14.27,100,1,12.50,700,1,14.35,200,2,12.46,100,1,14.48,700,1,12.43,700,1,14.53,200,2,ARL,344608225
2025-07-17T16:17:40.333679181Z,2025-07-17T16:17:40.333513866Z,160,2,1108,C,A,10,13.40,0,0,13.40,23,1,13.11,100,1,13.47,15,1,13.03,2,1,13.48,100,1,12.98,200,2,13.75,100,1,12.86,100,1,13.97,2,1,12.73,100,1,14.08,100,1,12.71,100,1,14.27,100,1,12.50,700,1,14.35,200,2,12.46,100,1,14.48,700,1,12.43,700,1,14.53,200,2,ARL,344280825
2025-07-17T16:17:40.333679181Z,2025-07-17T16:17:40.333513866Z,160,2,1108,A,A,10,13.40,0,0,13.40,23,1,13.11,100,1,13.47,15,1,13.03,2,1,13.48,100,1,12.98,200,2,13.75,100,1,12.86,100,1,13.97,2,1,12.73,100,1,14.08,100,1,12.71,100,1,14.27,100,1,12.50,700,1,14.35,200,2,12.46,100,1,14.43,100,1,12.43,700,1,14.48,700,1,ARL,344608253
2025-07-17T16:17:40.348996221Z,2025-07-17T16:17:40.348830748Z,160,2,1108,C,A,10,13.40,0,0,13.40,23,1,13.11,100,1,13.47,15,1,13.03,2,1,13.48,100,1,12.98,200,2,13.75,100,1,12.86,100,1,13.97,2,1,12.73,100,1,14.08,100,1,12.71,100,1,14.27,100,1,12.50,700,1,14.35,200,2,12.46,100,1,14.43,100,1,12.43,700,1,14.48,700,1,ARL,344280917
2025-07-17T16:17:40.348996221Z,2025-07-17T16:17:40.348830748Z,160,2,1108,A,A,10,13.40,0,0,13.40,23,1,13.11,100,1,13.47,15,1,13.03,2,1,13.48,100,1,12.98,200,2,13.75,100,1,12.86,100,1,13.97,2,1,12.73,100,1,14.08,100,1,12.71,100,1,14.27,100,1,12.50,700,1,14.35,200,2,12.46,100,1,14.43,100,1,12.43,700,1,14.48,700,1,ARL,344608637
2025-07-17T16:17:40.349081921Z,2025-07-17T16:17:40.348916703Z,160,2,1108,A,A,10,13.40,0,0,13.40,23,1,13.11,100,1,13.47,15,1,13.03,2,1,13.48,100,1,12.98,200,2,13.75,100,1,12.86,100,1,13.97,2,1,12.73,100,1,14.08,100,1,12.71,100,1,14.27,100,1,12.50,700,1,14.35,200,2,12.46,100,1,14.43,100,1,12.43,700,1,14.48,700,1,ARL,344608641
2025-07-17T16:17:40.349095477Z,2025-07-17T16:17:40.348930117Z,160,2,1108,C,A,10,13.40,0,0,13.40,23,1,13.11,100,1,13.47,15,1,13.03,2,1,13.48,100,1,12.98,200,2,13.75,100,1,12.86,100,1,13.97,2,1,12.73,100,1,14.08,100,1,12.71,100,1,14.27,100,1,12.50,700,1,14.35,200,2,12.46,100,1,14.43,100,1,12.43,700,1,14.48,700,1,ARL,344280537
2025-07-17T16:17:40.357367234Z,2025-07-17T16:17:40.357201846Z,160,2,1108,C,A,10,13.40,0,0,13.40,23,1,13.11,100,1,13.47,15,1,13.03,2,1,13.48,100,1,12.98,200,2,13.75,100,1,12.86,100,1,13.97,2,1,12.73,100,1,14.08,100,1,12.71,100,1,14.27,100,1,12.50,700,1,14.35,200,2,12.46,100,1,14.43,100,1,12.43,700,1,14.48,700,1,ARL,344280941
2025-07-17T16:17:40.357367234Z,2025-07-17T16:17:40.357201846Z,160,2,1108,A,A,10,13.40,0,0,13.40,23,1,13.11,100,1,13.47,15,1,13.03,2,1,13.48,100,1,12.98,200,2,13.75,100,1,12.86,100,1,13.97,2,1,12.73,100,1,14.08,100,1,12.71,100,1,14.27,100,1,12.50,700,1,14.35,200,2,12.46,100,1,14.43,100,1,12.43,700,1,14.48,700,1,ARL,344608797
2025-07-17T16:17:40.403239477Z,2025-07-17T16:17:40.403073956Z,160,2,1108,C,A,10,13.40,0,0,13.40,23,1,13.11,100,1,13.47,15,1,13.03,2,1,13.48,100,1,12.98,200,2,13.75,100,1,12.86,100,1,13.97,2,1,12.73,100,1,14.08,100,1,12.71,100,1,14.27,100,1,12.50,700,1,14.35,200,2,12.46,100,1,14.43,100,1,12.43,700,1,14.48,700,1,ARL,344281229
2025-07-17T16:17:40.403239477Z,2025-07-17T16:17:40.403073956Z,160,2,1108,A,A,10,13.40,0,0,13.40,23,1,13.11,100,1,13.47,15,1,13.03,2,1,13.48,100,1,12.98,200,2,13.75,100,1,12.86,100,1,13.97,2,1,12.73,100,1,14.08,100,1,12.71,100,1,14.27,100,1,12.50,700,1,14.35,200,2,12.46,100,1,14.43,100,1,12.43,700,1,14.48,700,1,ARL,344609897
2025-07-17T16:17:40.426590567Z,2025-07-17T16:17:40.426425205Z,160,2,1108,C,A,10,13.40,0,0,13.40,23,1,13.11,100,1,13.47,15,1,13.03,2,1,13.48,100,1,12.98,200,2,13.75,100,1,12.86,100,1,13.97,2,1,12.73,100,1,14.08,100,1,12.71,100,1,14.27,100,1,12.50,700,1,14.35,200,2,12.46,100,1,14.43,100,1,12.43,700,1,14.48,700,1,ARL,344281257
2025-07-17T16:17:40.426590567Z,2025-07-17T16:17:40.426425205Z,160,2,1108,A,A,10,13.40,0,0,13.40,23,1,13.11,100,1,13.47,15,1,13.03,2,1,13.48,100,1,12.98,200,2,13.75,100,1,12.86,100,1,13.97,2,1,12.73,100,1,14.08,100,1,12.71,100,1,14.27,100,1,12.50,700,1,14.35,200,2,12.46,100,1,14.43,200,2,12.43,700,1,14.48,700,1,ARL,344610073
2025-07-17T16:17:40.474841118Z,2025-07-17T16:17:40.474675991Z,160,2,1108,A,A,10,13.40,0,0,13.40,23,1,13.11,100,1,13.47,15,1,13.03,2,1,13.48,100,1,12.98,200,2,13.75,100,1,12.86,100,1,13.97,2,1,12.73,100,1,14.01,100,1,12.71,100,1,14.08,100,1,12.50,700,1,14.27,100,1,12.46,100,1,14.35,200,2,12.43,700,1,14.43,200,2,ARL,344612049
2025-07-17T16:17:40.474842468Z,2025-07-17T16:17:40.474677082Z,160,2,1108,C,A,10,13.40,0,0,13.40,23,1,13.11,100,1,13.47,15,1,13.03,2,1,13.48,100,1,12.98,200,2,13.75,100,1,12.86,100,1,13.97,2,1,12.73,100,1,14.01,100,1,12.71,100,1,14.08,100,1,12.50,700,1,14.27,100,1,12.46,100,1,14.35,200,2,12.43,700,1,14.43,200,2,ARL,344288585
2025-07-17T16:17:40.697721205Z,2025-07-17T16:17:40.697555911Z,160,2,1108,A,A,10,13.40,0,0,13.40,23,1,13.11,100,1,13.47,15,1,13.03,2,1,13.48,100,1,12.98,200,2,13.75,100,1,12.86,100,1,13.97,2,1,12.73,100,1,14.01,100,1,12.71,100,1,14.08,100,1,12.50,700,1,14.27,100,1,12.46,100,1,14.28,100,1,12.43,700,1,14.35,200,2,ARL,344615393
2025-07-17T16:17:40.697733924Z,2025-07-17T16:17:40.697568713Z,160,2,1108,C,A,10,13.40,0,0,13.40,23,1,13.11,100,1,13.47,15,1,13.03,2,1,13.48,100,1,12.98,200,2,13.75,100,1,12.86,100,1,13.97,2,1,12.73,100,1,14.01,100,1,12.71,100,1,14.08,100,1,12.50,700,1,14.27,100,1,12.46,100,1,14.28,100,1,12.43,700,1,14.35,200,2,ARL,344292849
2025-07-17T16:17:41.586151161Z,2025-07-17T16:17:41.585985709Z,160,2,1108,C,A,10,13.40,0,0,13.40,23,1,13.11,100,1,13.47,15,1,13.03,2,1,13.48,100,1,12.98,200,2,13.75,100,1,12.86,100,1,14.01,100,1,12.73,100,1,14.08,100,1,12.71,100,1,14.27,100,1,12.50,700,1,14.28,100,1,12.46,100,1,14.35,200,2,12.43,700,1,14.43,200,2,ARL,344280721
2025-07-17T16:17:41.586151161Z,2025-07-17T16:17:41.585985709Z,160,2,1108,A,A,10,13.40,0,0,13.40,23,1,13.11,100,1,13.47,15,1,13.03,2,1,13.48,100,1,12.98,200,2,13.75,100,1,12.86,100,1,13.87,2,1,12.73,100,1,14.01,100,1,12.71,100,1,14.08,100,1,12.50,700,1,14.27,100,1,12.46,100,1,14.28,100,1,12.43,700,1,14.35,200,2,ARL,344631921
2025-07-17T16:17:42.553133650Z,2025-07-17T16:17:42.552968542Z,160,2,1108,A,A,10,13.40,0,0,13.40,23,1,13.11,100,1,13.45,15,1,13.03,2,1,13.47,15,1,12.98,200,2,13.48,100,1,12.86,100,1,13.75,100,1,12.73,100,1,13.87,2,1,12.71,100,1,14.01,100,1,12.50,700,1,14.08,100,1,12.46,100,1,14.27,100,1,12.43,700,1,14.28,100,1,ARL,344653009
2025-07-17T16:17:44.014614049Z,2025-07-17T16:17:44.014448587Z,160,2,1108,C,A,10,13.40,0,0,13.40,23,1,13.11,100,1,13.45,15,1,13.03,2,1,13.47,15,1,12.98,200,2,13.75,100,1,12.86,100,1,13.87,2,1,12.73,100,1,14.01,100,1,12.71,100,1,14.08,100,1,12.50,700,1,14.27,100,1,12.46,100,1,14.28,100,1,12.43,700,1,14.35,200,2,ARL,344607833
2025-07-17T16:17:44.014614049Z,2025-07-17T16:17:44.014448587Z,160,2,1108,A,A,10,13.40,0,0,13.40,23,1,13.11,100,1,13.45,15,1,13.03,2,1,13.46,100,1,12.98,200,2,13.47,15,1,12.86,100,1,13.75,100,1,12.73,100,1,13.87,2,1,12.71,100,1,14.01,100,1,12.50,700,1,14.08,100,1,12.46,100,1,14.27,100,1,12.43,700,1,14.28,100,1,ARL,344673481
2025-07-17T16:17:44.014977545Z,2025-07-17T16:17:44.014812396Z,160,2,1108,A,A,10,13.40,0,0,13.40,23,1,13.11,100,1,13.45,15,1,13.03,2,1,13.46,100,1,12.98,200,2,13.47,15,1,12.86,100,1,13.75,100,1,12.73,100,1,13.87,2,1,12.71,100,1,14.01,100,1,12.50,700,1,14.08,100,1,12.46,100,1,14.27,100,1,12.43,700,1,14.28,100,1,ARL,344673501
2025-07-17T16:17:44.014991037Z,2025-07-17T16:17:44.014825581Z,160,2,1108,C,A,10,13.40,0,0,13.40,23,1,13.11,100,1,13.45,15,1,13.03,2,1,13.46,100,1,12.98,200,2,13.47,15,1,12.86,100,1,13.75,100,1,12.73,100,1,13.87,2,1,12.71,100,1,14.01,100,1,12.50,700,1,14.08,100,1,12.46,100,1,14.27,100,1,12.43,700,1,14.28,100,1,ARL,344608641
2025-07-17T16:17:44.042976984Z,2025-07-17T16:17:44.042811526Z,160,2,1108,A,A,10,13.40,0,0,13.40,23,1,13.11,100,1,13.45,15,1,13.03,2,1,13.46,100,1,12.98,200,2,13.47,15,1,12.86,100,1,13.75,100,1,12.73,100,1,13.87,2,1,12.71,100,1,14.01,100,1,12.50,700,1,14.08,100,1,12.46,100,1,14.27,100,1,12.43,700,1,14.28,100,1,ARL,344674517
2025-07-17T16:17:44.042989197Z,2025-07-17T16:17:44.042824242Z,160,2,1108,C,A,10,13.40,0,0,13.40,23,1,13.11,100,1,13.45,15,1,13.03,2,1,13.46,100,1,12.98,200,2,13.47,15,1,12.86,100,1,13.75,100,1,12.73,100,1,13.87,2,1,12.71,100,1,14.01,100,1,12.50,700,1,14.08,100,1,12.46,100,1,14.27,100,1,12.43,700,1,14.28,100,1,ARL,344673501
2025-07-17T16:17:46.828260391Z,2025-07-17T16:17:46.828095134Z,160,2,1108,A,A,10,13.40,0,0,13.40,23,1,13.11,100,1,13.45,15,1,13.03,2,1,13.46,100,1,12.98,200,2,13.47,15,1,12.86,100,1,13.75,100,1,12.73,100,1,13.87,2,1,12.71,100,1,14.01,100,1,12.50,700,1,14.08,100,1,12.46,100,1,14.18,700,1,12.43,700,1,14.27,100,1,ARL,344724301
2025-07-17T16:17:46.828325564Z,2025-07-17T16:17:46.828160338Z,160,2,1108,C,A,10,13.40,0,0,13.40,23,1,13.11,100,1,13.45,15,1,13.03,2,1,13.46,100,1,12.98,200,2,13.47,15,1,12.86,100,1,13.75,100,1,12.73,100,1,13.87,2,1,12.71,100,1,14.01,100,1,12.50,700,1,14.08,100,1,12.46,100,1,14.18,700,1,12.43,700,1,14.27,100,1,ARL,341663105
2025-07-17T16:17:49.387530942Z,2025-07-17T16:17:49.387365405Z,160,2,1108,C,A,10,13.40,0,0,13.40,23,1,13.11,100,1,13.45,15,1,13.03,2,1,13.46,100,1,12.98,200,2,13.47,15,1,12.86,100,1,13.75,100,1,12.73,100,1,14.01,100,1,12.71,100,1,14.08,100,1,12.50,700,1,14.18,700,1,12.46,100,1,14.27,100,1,12.43,700,1,14.28,100,1,ARL,344631921
2025-07-17T16:17:49.387530942Z,2025-07-17T16:17:49.387365405Z,160,2,1108,A,A,10,13.40,0,0,13.40,23,1,13.11,100,1,13.45,15,1,13.03,2,1,13.46,100,1,12.98,200,2,13.47,15,1,12.86,100,1,13.75,100,1,12.73,100,1,13.79,2,1,12.71,100,1,14.01,100,1,12.50,700,1,14.08,100,1,12.46,100,1,14.18,700,1,12.43,700,1,14.27,100,1,ARL,344765077
2025-07-17T16:17:52.834173973Z,2025-07-17T16:17:52.834008196Z,160,2,1108,C,A,10,13.40,0,0,13.40,23,1,13.11,100,1,13.45,15,1,13.03,2,1,13.46,100,1,12.98,200,2,13.75,100,1,12.86,100,1,13.79,2,1,12.73,100,1,14.01,100,1,12.71,100,1,14.08,100,1,12.50,700,1,14.18,700,1,12.46,100,1,14.27,100,1,12.43,700,1,14.28,100,1,ARL,344587533
2025-07-17T16:17:58.033327053Z,2025-07-17T16:17:58.033161898Z,160,2,1108,C,A,10,13.40,0,0,13.40,23,1,13.11,100,1,13.46,100,1,13.03,2,1,13.75,100,1,12.98,200,2,13.79,2,1,12.86,100,1,14.01,100,1,12.73,100,1,14.08,100,1,12.71,100,1,14.18,700,1,12.50,700,1,14.27,100,1,12.46,100,1,14.28,100,1,12.43,700,1,14.35,200,2,ARL,344653009
2025-07-17T16:17:58.036588469Z,2025-07-17T16:17:58.036423237Z,160,2,1108,C,A,10,13.40,0,0,13.40,23,1,13.11,100,1,13.75,100,1,13.03,2,1,13.79,2,1,12.98,200,2,14.01,100,1,12.86,100,1,14.08,100,1,12.73,100,1,14.18,700,1,12.71,100,1,14.27,100,1,12.50,700,1,14.28,100,1,12.46,100,1,14.35,200,2,12.43,700,1,14.43,200,2,ARL,344673481
2025-07-17T16:17:58.036861922Z,2025-07-17T16:17:58.036696806Z,160,2,1108,C,A,10,13.40,0,0,13.40,23,1,13.11,100,1,13.75,100,1,13.03,2,1,13.79,2,1,12.98,200,2,14.01,100,1,12.86,100,1,14.08,100,1,12.73,100,1,14.27,100,1,12.71,100,1,14.28,100,1,12.50,700,1,14.35,200,2,12.46,100,1,14.43,200,2,12.43,700,1,14.48,700,1,ARL,344724301
2025-07-17T16:17:58.036914002Z,2025-07-17T16:17:58.036748831Z,160,2,1108,A,A,10,13.40,0,0,13.40,23,1,13.11,100,1,13.75,100,1,13.03,2,1,13.79,2,1,12.98,200,2,14.01,100,1,12.86,100,1,14.08,100,1,12.73,100,1,14.27,100,1,12.71,100,1,14.28,100,1,12.50,700,1,14.35,200,2,12.46,100,1,14.43,200,2,12.43,700,1,14.44,700,1,ARL,344897921
2025-07-17T16:17:58.036971455Z,2025-07-17T16:17:58.036806229Z,160,2,1108,A,A,10,13.40,0,0,13.40,23,1,13.11,100,1,13.75,100,1,13.03,2,1,13.79,2,1,12.98,200,2,14.01,100,1,12.86,100,1,14.08,100,1,12.73,100,1,14.27,100,1,12.71,100,1,14.28,100,1,12.50,700,1,14.35,200,2,12.46,100,1,14.43,200,2,12.43,700,1,14.44,700,1,ARL,344897933
2025-07-17T16:17:58.036983460Z,2025-07-17T16:17:58.036818196Z,160,2,1108,C,A,10,13.40,0,0,13.40,23,1,13.11,100,1,13.75,100,1,13.03,2,1,13.79,2,1,12.98,200,2,14.01,100,1,12.86,100,1,14.08,100,1,12.73,100,1,14.27,100,1,12.71,100,1,14.28,100,1,12.50,700,1,14.35,200,2,12.46,100,1,14.43,200,2,12.43,700,1,14.44,700,1,ARL,344674517
2025-07-17T16:17:58.037325671Z,2025-07-17T16:17:58.037160197Z,160,2,1108,C,A,10,13.40,0,0,13.40,23,1,13.11,100,1,13.75,100,1,13.03,2,1,13.79,2,1,12.98,200,2,14.01,100,1,12.86,100,1,14.08,100,1,12.73,100,1,14.27,100,1,12.71,100,1,14.28,100,1,12.50,700,1,14.35,200,2,12.46,100,1,14.43,200,2,12.43,700,1,14.44,700,1,ARL,344607889
2025-07-17T16:17:58.037325671Z,2025-07-17T16:17:58.037160197Z,160,2,1108,A,A,10,13.40,0,0,13.40,23,1,13.11,100,1,13.75,100,1,13.03,2,1,13.79,2,1,12.98,200,2,14.01,100,1,12.86,100,1,14.08,100,1,12.73,100,1,14.27,100,1,12.71,100,1,14.28,100,1,12.50,700,1,14.35,200,2,12.46,100,1,14.43,200,2,12.43,700,1,14.44,700,1,ARL,344897945
2025-07-17T16:17:58.037330946Z,2025-07-17T16:17:58.037165870Z,160,2,1108,C,A,10,13.40,0,0,13.40,23,1,13.11,100,1,13.75,100,1,13.03,2,1,13.79,2,1,12.98,200,2,14.01,100,1,12.86,100,1,14.27,100,1,12.73,100,1,14.28,100,1,12.71,100,1,14.35,200,2,12.50,700,1,14.43,200,2,12.46,100,1,14.44,700,1,12.43,700,1,14.48,700,1,ARL,344607893
2025-07-17T16:17:58.037686676Z,2025-07-17T16:17:58.037521442Z,160,2,1108,A,A,10,13.40,0,0,13.40,23,1,13.11,100,1,13.75,100,1,13.03,2,1,13.79,2,1,12.98,200,2,14.01,100,1,12.86,100,1,14.27,100,1,12.73,100,1,14.28,100,1,12.71,100,1,14.35,200,2,12.50,700,1,14.36,100,1,12.46,100,1,14.43,200,2,12.43,700,1,14.44,700,1,ARL,344897953
2025-07-17T16:17:58.038759735Z,2025-07-17T16:17:58.038594284Z,160,2,1108,C,A,10,13.40,0,0,13.40,23,1,13.11,100,1,13.75,100,1,13.03,2,1,13.79,2,1,12.98,200,2,14.01,100,1,12.86,100,1,14.27,100,1,12.73,100,1,14.28,100,1,12.71,100,1,14.35,200,2,12.50,700,1,14.36,100,1,12.46,100,1,14.43,100,1,12.43,700,1,14.44,700,1,ARL,344608253
2025-07-17T16:17:58.038759735Z,2025-07-17T16:17:58.038594284Z,160,2,1108,A,A,10,13.40,0,0,13.40,23,1,13.11,100,1,13.75,100,1,13.03,2,1,13.79,2,1,12.98,200,2,14.01,100,1,12.86,100,1,14.27,100,1,12.73,100,1,14.28,100,1,12.71,100,1,14.35,200,2,12.50,700,1,14.36,100,1,12.46,100,1,14.43,100,1,12.43,700,1,14.44,700,1,ARL,344897989
2025-07-17T16:17:58.039381900Z,2025-07-17T16:17:58.039215838Z,160,2,1108,C,A,10,13.40,0,0,13.40,23,1,13.11,100,1,13.75,100,1,13.03,2,1,13.79,2,1,12.98,200,2,14.01,100,1,12.86,100,1,14.27,100,1,12.73,100,1,14.28,100,1,12.71,100,1,14.35,200,2,12.50,700,1,14.36,100,1,12.46,100,1,14.43,100,1,12.43,700,1,14.44,700,1,ARL,344608205
2025-07-17T16:17:58.039381900Z,2025-07-17T16:17:58.039215838Z,160,2,1108,A,A,10,13.40,0,0,13.40,23,1,13.11,100,1,13.75,100,1,13.03,2,1,13.79,2,1,12.98,200,2,14.01,100,1,12.86,100,1,14.27,100,1,12.73,100,1,14.28,100,1,12.71,100,1,14.35,200,2,12.50,700,1,14.36,100,1,12.46,100,1,14.43,100,1,12.43,700,1,14.44,700,1,ARL,344897997
2025-07-17T16:17:58.047862207Z,2025-07-17T16:17:58.047696769Z,160,2,1108,C,A,10,13.40,0,0,13.40,23,1,13.11,100,1,13.75,100,1,13.03,2,1,13.79,2,1,12.98,200,2,14.01,100,1,12.86,100,1,14.27,100,1,12.73,100,1,14.28,100,1,12.71,100,1,14.35,200,2,12.50,700,1,14.36,100,1,12.46,100,1,14.43,100,1,12.43,700,1,14.44,700,1,ARL,344608637
2025-07-17T16:17:58.047862207Z,2025-07-17T16:17:58.047696769Z,160,2,1108,A,A,10,13.40,0,0,13.40,23,1,13.11,100,1,13.75,100,1,13.03,2,1,13.79,2,1,12.98,200,2,14.01,100,1,12.86,100,1,14.27,100,1,12.73,100,1,14.28,100,1,12.71,100,1,14.35,200,2,12.50,700,1,14.36,100,1,12.46,100,1,14.43,100,1,12.43,700,1,14.44,700,1,ARL,344898485
2025-07-17T16:17:58.051632876Z,2025-07-17T16:17:58.051466948Z,160,2,1108,C,A,10,13.40,0,0,13.40,23,1,13.11,100,1,13.75,100,1,13.03,2,1,13.79,2,1,12.98,200,2,14.01,100,1,12.86,100,1,14.27,100,1,12.73,100,1,14.28,100,1,12.71,100,1,14.35,200,2,12.50,700,1,14.36,100,1,12.46,100,1,14.43,100,1,12.43,700,1,14.44,700,1,ARL,344608797
2025-07-17T16:17:58.051632876Z,2025-07-17T16:17:58.051466948Z,160,2,1108,A,A,10,13.40,0,0,13.40,23,1,13.11,100,1,13.75,100,1,13.03,2,1,13.79,2,1,12.98,200,2,14.01,100,1,12.86,100,1,14.27,100,1,12.73,100,1,14.28,100,1,12.71,100,1,14.35,200,2,12.50,700,1,14.36,100,1,12.46,100,1,14.43,100,1,12.43,700,1,14.44,700,1,ARL,344898677
2025-07-17T16:17:58.054049362Z,2025-07-17T16:17:58.053883828Z,160,2,1108,C,A,10,13.40,0,0,13.40,23,1,13.11,100,1,13.79,2,1,13.03,2,1,14.01,100,1,12.98,200,2,14.27,100,1,12.86,100,1,14.28,100,1,12.73,100,1,14.35,200,2,12.71,100,1,14.36,100,1,12.50,700,1,14.43,100,1,12.46,100,1,14.44,700,1,12.43,700,1,14.48,700,1,ARL,344608193
2025-07-17T16:17:58.054100805Z,2025-07-17T16:17:58.053934652Z,160,2,1108,C,A,10,13.40,0,0,13.40,23,1,13.11,100,1,13.79,2,1,13.03,2,1,14.01,100,1,12.98,200,2,14.27,100,1,12.86,100,1,14.28,100,1,12.73,100,1,14.35,200,2,12.71,100,1,14.36,100,1,12.50,700,1,14.43,100,1,12.46,100,1,14.48,700,1,12.43,700,1,14.54,700,1,ARL,344897921
2025-07-17T16:17:58.054101429Z,2025-07-17T16:17:58.053935872Z,160,2,1108,A,A,10,13.40,0,0,13.40,23,1,13.11,100,1,13.79,2,1,13.03,2,1,14.01,100,1,12.98,200,2,14.03,100,1,12.86,100,1,14.27,100,1,12.73,100,1,14.28,100,1,12.71,100,1,14.35,200,2,12.50,700,1,14.36,100,1,12.46,100,1,14.43,100,1,12.43,700,1,14.48,700,1,ARL,344898949
2025-07-17T16:17:58.056965001Z,2025-07-17T16:17:58.056799769Z,160,2,1108,C,A,10,13.40,0,0,13.40,23,1,13.11,100,1,13.79,2,1,13.03,2,1,14.01,100,1,12.98,200,2,14.03,100,1,12.86,100,1,14.27,100,1,12.73,100,1,14.28,100,1,12.71,100,1,14.35,200,2,12.50,700,1,14.36,100,1,12.46,100,1,14.43,100,1,12.43,700,1,14.48,700,1,ARL,344897989
2025-07-17T16:17:58.056965001Z,2025-07-17T16:17:58.056799769Z,160,2,1108,A,A,10,13.40,0,0,13.40,23,1,13.11,100,1,13.79,2,1,13.03,2,1,14.01,100,1,12.98,200,2,14.03,100,1,12.86,100,1,14.27,100,1,12.73,100,1,14.28,100,1,12.71,100,1,14.35,200,2,12.50,700,1,14.36,100,1,12.46,100,1,14.43,100,1,12.43,700,1,14.48,700,1,ARL,344899081
2025-07-17T16:17:58.057809322Z,2025-07-17T16:17:58.057644161Z,160,2,1108,C,A,10,13.40,0,0,13.40,23,1,13.11,100,1,13.79,2,1,13.03,2,1,14.01,100,1,12.98,200,2,14.03,100,1,12.86,100,1,14.27,100,1,12.73,100,1,14.28,100,1,12.71,100,1,14.35,200,2,12.50,700,1,14.36,100,1,12.46,100,1,14.43,100,1,12.43,700,1,14.48,700,1,ARL,344898677
2025-07-17T16:17:58.057809322Z,2025-07-17T16:17:58.057644161Z,160,2,1108,A,A,10,13.40,0,0,13.40,23,1,13.11,100,1,13.79,2,1,13.03,2,1,14.01,100,1,12.98,200,2,14.03,100,1,12.86,100,1,14.27,100,1,12.73,100,1,14.28,100,1,12.71,100,1,14.35,200,2,12.50,700,1,14.36,100,1,12.46,100,1,14.43,100,1,12.43,700,1,14.48,700,1,ARL,344899093
2025-07-17T16:17:58.061670860Z,2025-07-17T16:17:58.061505885Z,160,2,1108,C,A,10,13.40,0,0,13.40,23,1,13.11,100,1,13.79,2,1,13.03,2,1,14.01,100,1,12.98,200,2,14.27,100,1,12.86,100,1,14.28,100,1,12.73,100,1,14.35,200,2,12.71,100,1,14.36,100,1,12.50,700,1,14.43,100,1,12.46,100,1,14.48,700,1,12.43,700,1,14.54,700,1,ARL,344898949
2025-07-17T16:17:58.061730836Z,2025-07-17T16:17:58.061563628Z,160,2,1108,A,A,10,13.40,0,0,13.40,23,1,13.11,100,1,13.79,2,1,13.03,2,1,14.01,100,1,12.98,200,2,14.25,100,1,12.86,100,1,14.27,100,1,12.73,100,1,14.28,100,1,12.71,100,1,14.35,200,2,12.50,700,1,14.36,100,1,12.46,100,1,14.43,100,1,12.43,700,1,14.48,700,1,ARL,344899417
2025-07-17T16:17:58.062137122Z,2025-07-17T16:17:58.061971960Z,160,2,1108,C,A,10,13.40,0,0,13.40,23,1,13.11,100,1,13.79,2,1,13.03,2,1,14.01,100,1,12.98,200,2,14.25,100,1,12.86,100,1,14.27,100,1,12.73,100,1,14.28,100,1,12.71,100,1,14.35,200,2,12.50,700,1,14.36,100,1,12.46,100,1,14.43,100,1,12.43,700,1,14.48,700,1,ARL,344898485
2025-07-17T16:17:58.062137122Z,2025-07-17T16:17:58.061971960Z,160,2,1108,A,A,10,13.40,0,0,13.40,23,1,13.11,100,1,13.79,2,1,13.03,2,1,14.01,100,1,12.98,200,2,14.25,100,1,12.86,100,1,14.27,100,1,12.73,100,1,14.28,100,1,12.71,100,1,14.35,200,2,12.50,700,1,14.36,100,1,12.46,100,1,14.43,100,1,12.43,700,1,14.48,700,1,ARL,344899449
2025-07-17T16:17:58.086582033Z,2025-07-17T16:17:58.086415950Z,160,2,1108,C,A,10,13.40,0,0,13.40,23,1,13.11,100,1,13.79,2,1,13.03,2,1,14.01,100,1,12.98,200,2,14.25,100,1,12.86,100,1,14.28,100,1,12.73,100,1,14.35,200,2,12.71,100,1,14.36,100,1,12.50,700,1,14.43,100,1,12.46,100,1,14.48,700,1,12.43,700,1,14.54,700,1,ARL,344608225
2025-07-17T16:17:58.086582033Z,2025-07-17T16:17:58.086415950Z,160,2,1108,A,A,10,13.40,0,0,13.40,23,1,13.11,100,1,13.79,2,1,13.03,2,1,14.01,100,1,12.98,200,2,14.25,100,1,12.86,100,1,14.28,100,1,12.73,100,1,14.35,200,2,12.71,100,1,14.36,100,1,12.50,700,1,14.43,100,1,12.46,100,1,14.48,700,1,12.43,700,1,14.54,800,2,ARL,344899913
2025-07-17T16:17:58.087829372Z,2025-07-17T16:17:58.087663773Z,160,2,1108,C,A,10,13.40,0,0,13.40,23,1,13.11,100,1,13.79,2,1,13.03,2,1,14.01,100,1,12.98,200,2,14.25,100,1,12.86,100,1,14.28,100,1,12.73,100,1,14.35,200,2,12.71,100,1,14.36,100,1,12.50,700,1,14.43,100,1,12.46,100,1,14.48,700,1,12.43,700,1,14.54,800,2,ARL,344897945
2025-07-17T16:17:58.087829372Z,2025-07-17T16:17:58.087663773Z,160,2,1108,A,A,10,13.40,0,0,13.40,23,1,13.11,100,1,13.79,2,1,13.03,2,1,14.01,100,1,12.98,200,2,14.25,100,1,12.86,100,1,14.28,100,1,12.73,100,1,14.35,200,2,12.71,100,1,14.36,100,1,12.50,700,1,14.43,100,1,12.46,100,1,14.48,700,1,12.43,700,1,14.54,800,2,ARL,344899937
2025-07-17T16:17:58.113382320Z,2025-07-17T16:17:58.113216665Z,160,2,1108,C,A,10,13.40,0,0,13.40,23,1,13.11,100,1,13.79,2,1,13.03,2,1,14.01,100,1,12.98,200,2,14.25,100,1,12.86,100,1,14.28,100,1,12.73,100,1,14.35,200,2,12.71,100,1,14.36,100,1,12.50,700,1,14.43,100,1,12.46,100,1,14.48,700,1,12.43,700,1,14.54,800,2,ARL,344609897
2025-07-17T16:17:58.113382320Z,2025-07-17T16:17:58.113216665Z,160,2,1108,A,A,10,13.40,0,0,13.40,23,1,13.11,100,1,13.79,2,1,13.03,2,1,14.01,100,1,12.98,200,2,14.25,100,1,12.86,100,1,14.28,100,1,12.73,100,1,14.35,200,2,12.71,100,1,14.36,100,1,12.50,700,1,14.43,100,1,12.46,100,1,14.48,700,1,12.43,700,1,14.54,800,2,ARL,344900289
2025-07-17T16:17:58.145548497Z,2025-07-17T16:17:58.145382853Z,160,2,1108,C,A,10,13.40,0,0,13.40,23,1,13.11,100,1,13.79,2,1,13.03,2,1,14.01,100,1,12.98,200,2,14.25,100,1,12.86,100,1,14.28,100,1,12.73,100,1,14.35,200,2,12.71,100,1,14.36,100,1,12.50,700,1,14.48,700,1,12.46,100,1,14.54,800,2,12.43,700,1,14.56,700,1,ARL,344610073
2025-07-17T16:17:58.145548497Z,2025-07-17T16:17:58.145382853Z,160,2,1108,A,A,10,13.40,0,0,13.40,23,1,13.11,100,1,13.79,2,1,13.03,2,1,14.01,100,1,12.98,200,2,14.25,100,1,12.86,100,1,14.28,100,1,12.73,100,1,14.35,200,2,12.71,100,1,14.36,100,1,12.50,700,1,14.48,700,1,12.46,100,1,14.54,800,2,12.43,700,1,14.56,700,1,ARL,344900597
2025-07-17T16:17:58.173831273Z,2025-07-17T16:17:58.173665745Z,160,2,1108,A,A,10,13.40,0,0,13.40,23,1,13.11,100,1,13.79,2,1,13.03,2,1,14.01,100,1,12.98,200,2,14.25,100,1,12.86,100,1,14.28,100,1,12.73,100,1,14.35,200,2,12.71,100,1,14.36,100,1,12.50,700,1,14.48,700,1,12.46,100,1,14.54,800,2,12.43,700,1,14.56,700,1,ARL,344900925
2025-07-17T16:17:58.173852767Z,2025-07-17T16:17:58.173687330Z,160,2,1108,C,A,10,13.40,0,0,13.40,23,1,13.11,100,1,13.79,2,1,13.03,2,1,14.01,100,1,12.98,200,2,14.25,100,1,12.86,100,1,14.35,200,2,12.73,100,1,14.36,100,1,12.71,100,1,14.48,700,1,12.50,700,1,14.54,800,2,12.46,100,1,14.56,700,1,12.43,700,1,14.81,100,1,ARL,344615393
2025-07-17T16:17:58.235788576Z,2025-07-17T16:17:58.235623452Z,160,2,1108,A,A,10,13.40,0,0,13.40,23,1,13.11,100,1,13.79,2,1,13.03,2,1,14.01,100,1,12.98,200,2,14.25,100,1,12.86,100,1,14.35,200,2,12.73,100,1,14.36,100,1,12.71,100,1,14.48,700,1,12.50,700,1,14.54,800,2,12.46,100,1,14.56,700,1,12.43,700,1,14.68,700,1,ARL,344902153
2025-07-17T16:17:58.502856372Z,2025-07-17T16:17:58.502691073Z,160,2,1108,A,A,10,13.40,0,0,13.40,23,1,13.11,100,1,13.79,2,1,13.03,2,1,14.01,100,1,12.98,200,2,14.25,100,1,12.86,100,1,14.35,200,2,12.73,100,1,14.36,100,1,12.71,100,1,14.48,700,1,12.50,700,1,14.53,100,1,12.46,100,1,14.54,800,2,12.43,700,1,14.56,700,1,ARL,344905321
2025-07-17T16:17:58.502858100Z,2025-07-17T16:17:58.502692641Z,160,2,1108,C,A,10,13.40,0,0,13.40,23,1,13.11,100,1,13.79,2,1,13.03,2,1,14.25,100,1,12.98,200,2,14.35,200,2,12.86,100,1,14.36,100,1,12.73,100,1,14.48,700,1,12.71,100,1,14.53,100,1,12.50,700,1,14.54,800,2,12.46,100,1,14.56,700,1,12.43,700,1,14.68,700,1,ARL,344612049
2025-07-17T16:17:58.704865076Z,2025-07-17T16:17:58.704699676Z,160,2,1108,C,A,10,13.40,0,0,13.40,23,1,13.11,100,1,13.79,2,1,13.03,2,1,14.25,100,1,12.98,200,2,14.35,200,2,12.86,100,1,14.48,700,1,12.73,100,1,14.53,100,1,12.71,100,1,14.54,800,2,12.50,700,1,14.56,700,1,12.46,100,1,14.68,700,1,12.43,700,1,14.81,100,1,ARL,344897953
2025-07-17T16:17:58.705216838Z,2025-07-17T16:17:58.705051532Z,160,2,1108,A,A,10,13.40,0,0,13.40,23,1,13.11,100,1,13.79,2,1,13.03,2,1,14.25,100,1,12.98,200,2,14.35,200,2,12.86,100,1,14.48,700,1,12.73,100,1,14.53,100,1,12.71,100,1,14.54,800,2,12.50,700,1,14.56,700,1,12.46,100,1,14.60,100,1,12.43,700,1,14.68,700,1,ARL,344906945
2025-07-17T16:17:59.086439158Z,2025-07-17T16:17:59.086273873Z,160,2,1108,C,A,10,13.40,0,0,13.40,23,1,13.11,100,1,13.79,2,1,13.03,2,1,14.25,100,1,12.98,200,2,14.35,200,2,12.86,100,1,14.48,700,1,12.73,100,1,14.53,100,1,12.71,100,1,14.54,700,1,12.50,700,1,14.56,700,1,12.46,100,1,14.60,100,1,12.43,700,1,14.68,700,1,ARL,344899913
2025-07-17T16:17:59.086561438Z,2025-07-17T16:17:59.086395964Z,160,2,1108,A,A,10,13.40,0,0,13.40,23,1,13.11,100,1,13.79,2,1,13.03,2,1,14.25,100,1,12.98,200,2,14.35,200,2,12.86,100,1,14.48,700,1,12.73,100,1,14.53,100,1,12.71,100,1,14.54,700,1,12.50,700,1,14.56,700,1,12.46,100,1,14.60,100,1,12.43,700,1,14.68,700,1,ARL,344914361
2025-07-17T16:18:02.178629167Z,2025-07-17T16:18:02.178463984Z,160,2,1108,A,A,10,13.40,0,0,13.40,23,1,13.11,100,1,13.79,2,1,13.03,2,1,13.80,100,1,12.98,200,2,14.25,100,1,12.86,100,1,14.35,200,2,12.73,100,1,14.48,700,1,12.71,100,1,14.53,100,1,12.50,700,1,14.54,700,1,12.46,100,1,14.56,700,1,12.43,700,1,14.60,100,1,ARL,344989393
2025-07-17T16:18:02.179379565Z,2025-07-17T16:18:02.179214149Z,160,2,1108,C,A,10,13.40,0,0,13.40,23,1,13.11,100,1,13.79,2,1,13.03,2,1,13.80,100,1,12.98,200,2,14.25,100,1,12.86,100,1,14.35,200,2,12.73,100,1,14.48,700,1,12.71,100,1,14.53,100,1,12.50,700,1,14.54,700,1,12.46,100,1,14.56,700,1,12.43,700,1,14.60,100,1,ARL,344899937
2025-07-17T16:18:02.179379565Z,2025-07-17T16:18:02.179214149Z,160,2,1108,A,A,10,13.40,0,0,13.40,23,1,13.11,100,1,13.79,2,1,13.03,2,1,13.80,100,1,12.98,200,2,14.25,100,1,12.86,100,1,14.35,200,2,12.73,100,1,14.48,700,1,12.71,100,1,14.53,100,1,12.50,700,1,14.54,700,1,12.46,100,1,14.56,700,1,12.43,700,1,14.60,100,1,ARL,344989421
2025-07-17T16:18:02.181473898Z,2025-07-17T16:18:02.181307241Z,160,2,1108,C,A,10,13.40,0,0,13.40,23,1,13.11,100,1,13.79,2,1,13.03,2,1,13.80,100,1,12.98,200,2,14.25,100,1,12.86,100,1,14.35,200,2,12.73,100,1,14.48,700,1,12.71,100,1,14.53,100,1,12.50,700,1,14.54,700,1,12.46,100,1,14.56,700,1,12.43,700,1,14.60,100,1,ARL,344899081
2025-07-17T16:18:02.181473898Z,2025-07-17T16:18:02.181307241Z,160,2,1108,A,A,10,13.40,0,0,13.40,23,1,13.11,100,1,13.79,2,1,13.03,2,1,13.80,100,1,12.98,200,2,14.25,100,1,12.86,100,1,14.35,200,2,12.73,100,1,14.48,700,1,12.71,100,1,14.53,100,1,12.50,700,1,14.54,700,1,12.46,100,1,14.56,700,1,12.43,700,1,14.60,100,1,ARL,344989525
2025-07-17T16:18:02.182474498Z,2025-07-17T16:18:02.182309015Z,160,2,1108,C,A,10,13.40,0,0,13.40,23,1,13.11,100,1,13.79,2,1,13.03,2,1,13.80,100,1,12.98,200,2,14.25,100,1,12.86,100,1,14.35,200,2,12.73,100,1,14.48,700,1,12.71,100,1,14.53,100,1,12.50,700,1,14.54,700,1,12.46,100,1,14.56,700,1,12.43,700,1,14.60,100,1,ARL,344899449
2025-07-17T16:18:02.182474498Z,2025-07-17T16:18:02.182309015Z,160,2,1108,A,A,10,13.40,0,0,13.40,23,1,13.11,100,1,13.79,2,1,13.03,2,1,13.80,100,1,12.98,200,2,14.25,100,1,12.86,100,1,14.35,200,2,12.73,100,1,14.48,700,1,12.71,100,1,14.53,100,1,12.50,700,1,14.54,700,1,12.46,100,1,14.56,700,1,12.43,700,1,14.60,100,1,ARL,344989557
2025-07-17T16:18:02.184788371Z,2025-07-17T16:18:02.184622698Z,160,2,1108,C,A,10,13.40,0,0,13.40,23,1,13.11,100,1,13.79,2,1,13.03,2,1,13.80,100,1,12.98,200,2,14.35,200,2,12.86,100,1,14.48,700,1,12.73,100,1,14.53,100,1,12.71,100,1,14.54,700,1,12.50,700,1,14.56,700,1,12.46,100,1,14.60,100,1,12.43,700,1,14.68,700,1,ARL,344899417
2025-07-17T16:18:02.184840010Z,2025-07-17T16:18:02.184674810Z,160,2,1108,A,A,10,13.40,0,0,13.40,23,1,13.11,100,1,13.79,2,1,13.03,2,1,13.80,100,1,12.98,200,2,14.08,100,1,12.86,100,1,14.35,200,2,12.73,100,1,14.48,700,1,12.71,100,1,14.53,100,1,12.50,700,1,14.54,700,1,12.46,100,1,14.56,700,1,12.43,700,1,14.60,100,1,ARL,344989601
2025-07-17T16:18:02.186910586Z,2025-07-17T16:18:02.186745185Z,160,2,1108,C,A,10,13.40,0,0,13.40,23,1,13.11,100,1,13.79,2,1,13.03,2,1,13.80,100,1,12.98,200,2,14.08,100,1,12.86,100,1,14.35,200,2,12.73,100,1,14.48,700,1,12.71,100,1,14.53,100,1,12.50,700,1,14.54,700,1,12.46,100,1,14.56,700,1,12.43,700,1,14.60,100,1,ARL,344914361
2025-07-17T16:18:02.186910586Z,2025-07-17T16:18:02.186745185Z,160,2,1108,A,A,10,13.40,0,0,13.40,23,1,13.11,100,1,13.79,2,1,13.03,2,1,13.80,100,1,12.98,200,2,14.08,100,1,12.86,100,1,14.35,200,2,12.73,100,1,14.48,700,1,12.71,100,1,14.53,100,1,12.50,700,1,14.54,700,1,12.46,100,1,14.56,700,1,12.43,700,1,14.59,100,1,ARL,344989661
2025-07-17T16:18:02.189536873Z,2025-07-17T16:18:02.189371317Z,160,2,1108,C,A,10,13.40,0,0,13.40,23,1,13.11,100,1,13.79,2,1,13.03,2,1,13.80,100,1,12.98,200,2,14.08,100,1,12.86,100,1,14.35,200,2,12.73,100,1,14.48,700,1,12.71,100,1,14.53,100,1,12.50,700,1,14.54,700,1,12.46,100,1,14.56,700,1,12.43,700,1,14.59,100,1,ARL,344899093
2025-07-17T16:18:02.189536873Z,2025-07-17T16:18:02.189371317Z,160,2,1108,A,A,10,13.40,0,0,13.40,23,1,13.11,100,1,13.79,2,1,13.03,2,1,13.80,100,1,12.98,200,2,14.08,100,1,12.86,100,1,14.35,200,2,12.73,100,1,14.48,700,1,12.71,100,1,14.53,100,1,12.50,700,1,14.54,700,1,12.46,100,1,14.56,700,1,12.43,700,1,14.59,100,1,ARL,344989713
2025-07-17T16:18:02.271602472Z,2025-07-17T16:18:02.271437003Z,160,2,1108,C,A,10,13.40,0,0,13.40,23,1,13.11,100,1,13.79,2,1,13.03,2,1,13.80,100,1,12.98,200,2,14.08,100,1,12.86,100,1,14.35,200,2,12.73,100,1,14.48,700,1,12.71,100,1,14.53,100,1,12.50,700,1,14.54,700,1,12.46,100,1,14.56,700,1,12.43,700,1,14.59,100,1,ARL,344900597
2025-07-17T16:18:02.271602472Z,2025-07-17T16:18:02.271437003Z,160,2,1108,A,A,10,13.40,0,0,13.40,23,1,13.11,100,1,13.79,2,1,13.03,2,1,13.80,100,1,12.98,200,2,14.08,100,1,12.86,100,1,14.35,200,2,12.73,100,1,14.48,700,1,12.71,100,1,14.53,100,1,12.50,700,1,14.54,700,1,12.46,100,1,14.56,700,1,12.43,700,1,14.59,100,1,ARL,344990837
2025-07-17T16:18:44.836233374Z,2025-07-17T16:18:44.836067409Z,160,2,1108,A,A,10,13.40,0,0,13.40,23,1,13.11,100,1,13.47,15,1,13.03,2,1,13.79,2,1,12.98,200,2,13.80,100,1,12.86,100,1,14.08,100,1,12.73,100,1,14.35,200,2,12.71,100,1,14.48,700,1,12.50,700,1,14.53,100,1,12.46,100,1,14.54,700,1,12.43,700,1,14.56,700,1,ARL,345869437
2025-07-17T16:18:45.977564112Z,2025-07-17T16:18:45.977398557Z,160,2,1108,C,A,10,13.40,0,0,13.40,23,1,13.11,100,1,13.47,15,1,13.03,2,1,13.79,2,1,12.98,200,2,14.08,100,1,12.86,100,1,14.35,200,2,12.73,100,1,14.48,700,1,12.71,100,1,14.53,100,1,12.50,700,1,14.54,700,1,12.46,100,1,14.56,700,1,12.43,700,1,14.59,100,1,ARL,344989393
2025-07-17T16:18:45.977564112Z,2025-07-17T16:18:45.977398557Z,160,2,1108,A,A,10,13.40,0,0,13.40,23,1,13.11,100,1,13.47,15,1,13.03,2,1,13.48,100,1,12.98,200,2,13.79,2,1,12.86,100,1,14.08,100,1,12.73,100,1,14.35,200,2,12.71,100,1,14.48,700,1,12.50,700,1,14.53,100,1,12.46,100,1,14.54,700,1,12.43,700,1,14.56,700,1,ARL,345889137
2025-07-17T16:18:45.978304784Z,2025-07-17T16:18:45.978139497Z,160,2,1108,C,A,10,13.40,0,0,13.40,23,1,13.11,100,1,13.47,15,1,13.03,2,1,13.48,100,1,12.98,200,2,13.79,2,1,12.86,100,1,14.08,100,1,12.73,100,1,14.35,200,2,12.71,100,1,14.48,700,1,12.50,700,1,14.53,100,1,12.46,100,1,14.54,700,1,12.43,700,1,14.56,700,1,ARL,344906945
2025-07-17T16:18:45.978307201Z,2025-07-17T16:18:45.978141738Z,160,2,1108,C,A,10,13.40,0,0,13.40,23,1,13.11,100,1,13.47,15,1,13.03,2,1,13.48,100,1,12.98,200,2,13.79,2,1,12.86,100,1,14.08,100,1,12.73,100,1,14.35,200,2,12.71,100,1,14.48,700,1,12.50,700,1,14.53,100,1,12.46,100,1,14.54,700,1,12.43,700,1,14.56,700,1,ARL,344989421
2025-07-17T16:18:45.978307201Z,2025-07-17T16:18:45.978141738Z,160,2,1108,A,A,10,13.40,0,0,13.40,23,1,13.11,100,1,13.47,15,1,13.03,2,1,13.48,100,1,12.98,200,2,13.79,2,1,12.86,100,1,14.08,100,1,12.73,100,1,14.35,200,2,12.71,100,1,14.48,700,1,12.50,700,1,14.53,200,2,12.46,100,1,14.54,700,1,12.43,700,1,14.56,700,1,ARL,345889161
2025-07-17T16:18:45.978659056Z,2025-07-17T16:18:45.978493799Z,160,2,1108,A,A,10,13.40,0,0,13.40,23,1,13.11,100,1,13.47,15,1,13.03,2,1,13.48,100,1,12.98,200,2,13.79,2,1,12.86,100,1,14.08,200,2,12.73,100,1,14.35,200,2,12.71,100,1,14.48,700,1,12.50,700,1,14.53,200,2,12.46,100,1,14.54,700,1,12.43,700,1,14.56,700,1,ARL,345889165
2025-07-17T16:18:45.979197330Z,2025-07-17T16:18:45.979031886Z,160,2,1108,C,A,10,13.40,0,0,13.40,23,1,13.11,100,1,13.47,15,1,13.03,2,1,13.48,100,1,12.98,200,2,13.79,2,1,12.86,100,1,14.08,200,2,12.73,100,1,14.35,200,2,12.71,100,1,14.48,700,1,12.50,700,1,14.53,200,2,12.46,100,1,14.54,700,1,12.43,700,1,14.56,700,1,ARL,344897997
2025-07-17T16:18:45.979197330Z,2025-07-17T16:18:45.979031886Z,160,2,1108,A,A,10,13.40,0,0,13.40,23,1,13.11,100,1,13.47,15,1,13.03,2,1,13.48,100,1,12.98,200,2,13.79,2,1,12.86,100,1,14.08,200,2,12.73,100,1,14.35,200,2,12.71,100,1,14.48,700,1,12.50,700,1,14.53,200,2,12.46,100,1,14.54,700,1,12.43,700,1,14.56,700,1,ARL,345889185
2025-07-17T16:18:45.979453023Z,2025-07-17T16:18:45.979287575Z,160,2,1108,C,A,10,13.40,0,0,13.40,23,1,13.11,100,1,13.47,15,1,13.03,2,1,13.48,100,1,12.98,200,2,13.79,2,1,12.86,100,1,14.08,200,2,12.73,100,1,14.35,200,2,12.71,100,1,14.48,700,1,12.50,700,1,14.53,200,2,12.46,100,1,14.54,700,1,12.43,700,1,14.56,700,1,ARL,344990837
2025-07-17T16:18:45.979453023Z,2025-07-17T16:18:45.979287575Z,160,2,1108,A,A,10,13.40,0,0,13.40,23,1,13.11,100,1,13.47,15,1,13.03,2,1,13.48,100,1,12.98,200,2,13.79,2,1,12.86,100,1,14.08,200,2,12.73,100,1,14.35,200,2,12.71,100,1,14.43,100,1,12.50,700,1,14.48,700,1,12.46,100,1,14.53,200,2,12.43,700,1,14.54,700,1,ARL,345889189
2025-07-17T16:18:45.979897527Z,2025-07-17T16:18:45.979732081Z,160,2,1108,C,A,10,13.40,0,0,13.40,23,1,13.11,100,1,13.47,15,1,13.03,2,1,13.48,100,1,12.98,200,2,13.79,2,1,12.86,100,1,14.08,200,2,12.73,100,1,14.35,200,2,12.71,100,1,14.43,100,1,12.50,700,1,14.48,700,1,12.46,100,1,14.53,200,2,12.43,700,1,14.54,700,1,ARL,344989713
2025-07-17T16:18:45.979897527Z,2025-07-17T16:18:45.979732081Z,160,2,1108,A,A,10,13.40,0,0,13.40,23,1,13.11,100,1,13.47,15,1,13.03,2,1,13.48,100,1,12.98,200,2,13.79,2,1,12.86,100,1,14.08,200,2,12.73,100,1,14.35,200,2,12.71,100,1,14.43,100,1,12.50,700,1,14.48,700,1,12.46,100,1,14.53,200,2,12.43,700,1,14.54,700,1,ARL,345889193
2025-07-17T16:18:45.980137835Z,2025-07-17T16:18:45.979972220Z,160,2,1108,C,A,10,13.40,0,0,13.40,23,1,13.11,100,1,13.47,15,1,13.03,2,1,13.48,100,1,12.98,200,2,13.79,2,1,12.86,100,1,14.08,200,2,12.73,100,1,14.35,200,2,12.71,100,1,14.43,100,1,12.50,700,1,14.48,700,1,12.46,100,1,14.53,200,2,12.43,700,1,14.54,700,1,ARL,344989525
2025-07-17T16:18:45.980137835Z,2025-07-17T16:18:45.979972220Z,160,2,1108,A,A,10,13.40,0,0,13.40,23,1,13.11,100,1,13.47,15,1,13.03,2,1,13.48,100,1,12.98,200,2,13.79,2,1,12.86,100,1,14.08,200,2,12.73,100,1,14.35,200,2,12.71,100,1,14.43,200,2,12.50,700,1,14.48,700,1,12.46,100,1,14.53,200,2,12.43,700,1,14.54,700,1,ARL,345889201
2025-07-17T16:18:45.980197213Z,2025-07-17T16:18:45.980031732Z,160,2,1108,C,A,10,13.40,0,0,13.40,23,1,13.11,100,1,13.47,15,1,13.03,2,1,13.48,100,1,12.98,200,2,13.79,2,1,12.86,100,1,14.08,200,2,12.73,100,1,14.35,200,2,12.71,100,1,14.43,200,2,12.50,700,1,14.48,700,1,12.46,100,1,14.53,200,2,12.43,700,1,14.54,700,1,ARL,344989557
2025-07-17T16:18:45.980197213Z,2025-07-17T16:18:45.980031732Z,160,2,1108,A,A,10,13.40,0,0,13.40,23,1,13.11,100,1,13.47,15,1,13.03,2,1,13.48,100,1,12.98,200,2,13.79,2,1,12.86,100,1,14.08,200,2,12.73,100,1,14.35,200,2,12.71,100,1,14.43,200,2,12.50,700,1,14.48,700,1,12.46,100,1,14.53,200,2,12.43,700,1,14.54,700,1,ARL,345889205
2025-07-17T16:18:45.980205832Z,2025-07-17T16:18:45.980040000Z,160,2,1108,C,A,10,13.40,0,0,13.40,23,1,13.11,100,1,13.47,15,1,13.03,2,1,13.48,100,1,12.98,200,2,13.79,2,1,12.86,100,1,14.08,200,2,12.73,100,1,14.35,200,2,12.71,100,1,14.43,200,2,12.50,700,1,14.48,700,1,12.46,100,1,14.53,200,2,12.43,700,1,14.54,700,1,ARL,344900289
2025-07-17T16:18:45.980205832Z,2025-07-17T16:18:45.980040000Z,160,2,1108,A,A,10,13.40,0,0,13.40,23,1,13.11,100,1,13.47,15,1,13.03,2,1,13.48,100,1,12.98,200,2,13.79,2,1,12.86,100,1,14.08,200,2,12.73,100,1,14.35,200,2,12.71,100,1,14.43,200,2,12.50,700,1,14.48,700,1,12.46,100,1,14.53,200,2,12.43,700,1,14.54,700,1,ARL,345889209
2025-07-17T16:18:45.982963696Z,2025-07-17T16:18:45.982798406Z,160,2,1108,C,A,10,13.40,0,0,13.40,23,1,13.11,100,1,13.47,15,1,13.03,2,1,13.48,100,1,12.98,200,2,13.79,2,1,12.86,100,1,14.08,200,2,12.73,100,1,14.35,200,2,12.71,100,1,14.43,200,2,12.50,700,1,14.48,700,1,12.46,100,1,14.53,200,2,12.43,700,1,14.54,700,1,ARL,344989661
2025-07-17T16:18:45.983098604Z,2025-07-17T16:18:45.982933040Z,160,2,1108,A,A,10,13.40,0,0,13.40,23,1,13.11,100,1,13.47,15,1,13.03,2,1,13.48,100,1,12.98,200,2,13.79,2,1,12.86,100,1,14.08,200,2,12.73,100,1,14.27,100,1,12.71,100,1,14.35,200,2,12.50,700,1,14.43,200,2,12.46,100,1,14.48,700,1,12.43,700,1,14.53,200,2,ARL,345889277
2025-07-17T16:18:45.994306597Z,2025-07-17T16:18:45.994141218Z,160,2,1108,C,A,10,13.40,0,0,13.40,23,1,13.11,100,1,13.47,15,1,13.03,2,1,13.48,100,1,12.98,200,2,13.79,2,1,12.86,100,1,14.08,100,1,12.73,100,1,14.27,100,1,12.71,100,1,14.35,200,2,12.50,700,1,14.43,200,2,12.46,100,1,14.48,700,1,12.43,700,1,14.53,200,2,ARL,344989601
2025-07-17T16:18:45.994356983Z,2025-07-17T16:18:45.994191684Z,160,2,1108,A,A,10,13.40,0,0,13.40,23,1,13.11,100,1,13.47,15,1,13.03,2,1,13.48,100,1,12.98,200,2,13.75,100,1,12.86,100,1,13.79,2,1,12.73,100,1,14.08,100,1,12.71,100,1,14.27,100,1,12.50,700,1,14.35,200,2,12.46,100,1,14.43,200,2,12.43,700,1,14.48,700,1,ARL,345889457
2025-07-17T16:18:46.020770846Z,2025-07-17T16:18:46.020605332Z,160,2,1108,A,A,10,13.40,0,0,13.40,23,1,13.11,100,1,13.47,15,1,13.03,2,1,13.48,100,1,12.98,200,2,13.75,100,1,12.86,100,1,13.79,2,1,12.73,100,1,14.08,100,1,12.71,100,1,14.27,100,1,12.50,700,1,14.35,200,2,12.46,100,1,14.43,200,2,12.43,700,1,14.48,700,1,ARL,345889897
2025-07-17T16:18:46.020783162Z,2025-07-17T16:18:46.020617704Z,160,2,1108,C,A,10,13.40,0,0,13.40,23,1,13.11,100,1,13.47,15,1,13.03,2,1,13.48,100,1,12.98,200,2,13.75,100,1,12.86,100,1,13.79,2,1,12.73,100,1,14.08,100,1,12.71,100,1,14.27,100,1,12.50,700,1,14.35,200,2,12.46,100,1,14.43,200,2,12.43,700,1,14.48,700,1,ARL,344897933
2025-07-17T16:18:46.583802176Z,2025-07-17T16:18:46.583636828Z,160,2,1108,A,A,10,13.40,0,0,13.40,23,1,13.11,100,1,13.47,15,1,13.03,2,1,13.48,100,1,12.98,200,2,13.75,100,1,12.86,100,1,13.79,2,1,12.73,100,1,14.08,100,1,12.71,100,1,14.27,100,1,12.50,700,1,14.28,100,1,12.46,100,1,14.35,200,2,12.43,700,1,14.43,200,2,ARL,345903265
2025-07-17T16:18:46.583815469Z,2025-07-17T16:18:46.583649620Z,160,2,1108,C,A,10,13.40,0,0,13.40,23,1,13.11,100,1,13.47,15,1,13.03,2,1,13.48,100,1,12.98,200,2,13.75,100,1,12.86,100,1,13.79,2,1,12.73,100,1,14.08,100,1,12.71,100,1,14.27,100,1,12.50,700,1,14.28,100,1,12.46,100,1,14.35,200,2,12.43,700,1,14.43,200,2,ARL,344900925
2025-07-17T16:18:46.972854044Z,2025-07-17T16:18:46.972688613Z,160,2,1108,C,A,10,13.40,0,0,13.40,23,1,13.11,100,1,13.47,15,1,13.03,2,1,13.48,100,1,12.98,200,2,13.75,100,1,12.86,100,1,13.79,2,1,12.73,100,1,14.08,100,1,12.71,100,1,14.27,100,1,12.50,700,1,14.28,100,1,12.46,100,1,14.35,200,2,12.43,700,1,14.43,200,2,ARL,344905321
2025-07-17T16:18:46.972855248Z,2025-07-17T16:18:46.972689989Z,160,2,1108,A,A,10,13.40,0,0,13.40,23,1,13.11,100,1,13.47,15,1,13.03,2,1,13.48,100,1,12.98,200,2,13.75,100,1,12.86,100,1,13.79,2,1,12.73,100,1,14.01,100,1,12.71,100,1,14.08,100,1,12.50,700,1,14.27,100,1,12.46,100,1,14.28,100,1,12.43,700,1,14.35,200,2,ARL,345911213
2025-07-17T16:18:47.836167832Z,2025-07-17T16:18:47.836002486Z,160,2,1108,A,A,10,13.40,0,0,13.40,23,1,13.11,100,1,13.45,15,1,13.03,2,1,13.47,15,1,12.98,200,2,13.48,100,1,12.86,100,1,13.75,100,1,12.73,100,1,13.79,2,1,12.71,100,1,14.01,100,1,12.50,700,1,14.08,100,1,12.46,100,1,14.27,100,1,12.43,700,1,14.28,100,1,ARL,345924181
2025-07-17T16:18:47.956236479Z,2025-07-17T16:18:47.956070064Z,160,2,1108,C,A,10,13.40,0,0,13.40,23,1,13.11,100,1,13.45,15,1,13.03,2,1,13.47,15,1,12.98,200,2,13.75,100,1,12.86,100,1,13.79,2,1,12.73,100,1,14.01,100,1,12.71,100,1,14.08,100,1,12.50,700,1,14.27,100,1,12.46,100,1,14.28,100,1,12.43,700,1,14.35,200,2,ARL,345889137
2025-07-17T16:18:47.956236479Z,2025-07-17T16:18:47.956070064Z,160,2,1108,A,A,10,13.40,0,0,13.40,23,1,13.11,100,1,13.45,15,1,13.03,2,1,13.46,100,1,12.98,200,2,13.47,15,1,12.86,100,1,13.75,100,1,12.73,100,1,13.79,2,1,12.71,100,1,14.01,100,1,12.50,700,1,14.08,100,1,12.46,100,1,14.27,100,1,12.43,700,1,14.28,100,1,ARL,345926413
2025-07-17T16:18:47.956614041Z,2025-07-17T16:18:47.956448830Z,160,2,1108,A,A,10,13.40,0,0,13.40,23,1,13.11,100,1,13.45,15,1,13.03,2,1,13.46,100,1,12.98,200,2,13.47,15,1,12.86,100,1,13.75,100,1,12.73,100,1,13.79,2,1,12.71,100,1,14.01,100,1,12.50,700,1,14.08,100,1,12.46,100,1,14.27,100,1,12.43,700,1,14.28,100,1,ARL,345926449
2025-07-17T16:18:47.956628879Z,2025-07-17T16:18:47.956462726Z,160,2,1108,C,A,10,13.40,0,0,13.40,23,1,13.11,100,1,13.45,15,1,13.03,2,1,13.46,100,1,12.98,200,2,13.47,15,1,12.86,100,1,13.75,100,1,12.73,100,1,13.79,2,1,12.71,100,1,14.01,100,1,12.50,700,1,14.08,100,1,12.46,100,1,14.27,100,1,12.43,700,1,14.28,100,1,ARL,345889897
2025-07-17T16:18:47.983287076Z,2025-07-17T16:18:47.983119698Z,160,2,1108,A,A,10,13.40,0,0,13.40,23,1,13.11,100,1,13.45,15,1,13.03,2,1,13.46,100,1,12.98,200,2,13.47,15,1,12.86,100,1,13.75,100,1,12.73,100,1,13.79,2,1,12.71,100,1,14.01,100,1,12.50,700,1,14.08,100,1,12.46,100,1,14.27,100,1,12.43,700,1,14.28,100,1,ARL,345930785
2025-07-17T16:18:47.983312942Z,2025-07-17T16:18:47.983140841Z,160,2,1108,C,A,10,13.40,0,0,13.40,23,1,13.11,100,1,13.45,15,1,13.03,2,1,13.46,100,1,12.98,200,2,13.47,15,1,12.86,100,1,13.75,100,1,12.73,100,1,13.79,2,1,12.71,100,1,14.01,100,1,12.50,700,1,14.08,100,1,12.46,100,1,14.27,100,1,12.43,700,1,14.28,100,1,ARL,345926449
2025-07-17T16:18:51.228439638Z,2025-07-17T16:18:51.228274415Z,160,2,1108,A,A,10,13.40,0,0,13.40,23,1,13.11,100,1,13.45,15,1,13.03,2,1,13.46,100,1,12.98,200,2,13.47,15,1,12.86,100,1,13.75,100,1,12.73,100,1,13.79,2,1,12.71,100,1,14.01,100,1,12.50,700,1,14.08,100,1,12.46,100,1,14.18,700,1,12.43,700,1,14.27,100,1,ARL,345998433
2025-07-17T16:18:51.228516429Z,2025-07-17T16:18:51.228351310Z,160,2,1108,C,A,10,13.40,0,0,13.40,23,1,13.11,100,1,13.45,15,1,13.03,2,1,13.46,100,1,12.98,200,2,13.47,15,1,12.86,100,1,13.75,100,1,12.73,100,1,13.79,2,1,12.71,100,1,14.01,100,1,12.50,700,1,14.08,100,1,12.46,100,1,14.18,700,1,12.43,700,1,14.27,100,1,ARL,344902153
2025-07-17T16:18:57.882365457Z,2025-07-17T16:18:57.882196648Z,160,2,1108,C,A,10,13.40,0,0,13.40,23,1,13.11,100,1,13.45,15,1,13.03,2,1,13.46,100,1,12.98,200,2,13.75,100,1,12.86,100,1,13.79,2,1,12.73,100,1,14.01,100,1,12.71,100,1,14.08,100,1,12.50,700,1,14.18,700,1,12.46,100,1,14.27,100,1,12.43,700,1,14.28,100,1,ARL,345869437
2025-07-17T16:19:04.990890102Z,2025-07-17T16:19:04.990724544Z,160,2,1108,C,A,10,13.40,0,0,13.40,23,1,13.11,100,1,13.45,15,1,13.03,2,1,13.46,100,1,12.98,200,2,13.75,100,1,12.86,100,1,14.01,100,1,12.73,100,1,14.08,100,1,12.71,100,1,14.18,700,1,12.50,700,1,14.27,100,1,12.46,100,1,14.28,100,1,12.43,700,1,14.35,200,2,ARL,344765077
2025-07-17T16:19:04.990890102Z,2025-07-17T16:19:04.990724544Z,160,2,1108,A,A,10,13.40,0,0,13.40,23,1,13.11,100,1,13.45,15,1,13.03,2,1,13.46,100,1,12.98,200,2,13.72,2,1,12.86,100,1,13.75,100,1,12.73,100,1,14.01,100,1,12.71,100,1,14.08,100,1,12.50,700,1,14.18,700,1,12.46,100,1,14.27,100,1,12.43,700,1,14.28,100,1,ARL,346423105
2025-07-17T16:19:08.837286193Z,2025-07-17T16:19:08.837120837Z,160,2,1108,A,A,10,13.40,0,0,13.40,23,1,13.11,100,1,13.43,15,1,13.03,2,1,13.45,15,1,12.98,200,2,13.46,100,1,12.86,100,1,13.72,2,1,12.73,100,1,13.75,100,1,12.71,100,1,14.01,100,1,12.50,700,1,14.08,100,1,12.46,100,1,14.18,700,1,12.43,700,1,14.27,100,1,ARL,346492493
2025-07-17T16:19:11.008353202Z,2025-07-17T16:19:11.008187551Z,160,2,1108,C,A,10,13.40,0,0,13.40,23,1,13.11,100,1,13.43,15,1,13.03,2,1,13.45,15,1,12.98,200,2,13.72,2,1,12.86,100,1,13.75,100,1,12.73,100,1,14.01,100,1,12.71,100,1,14.08,100,1,12.50,700,1,14.18,700,1,12.46,100,1,14.27,100,1,12.43,700,1,14.28,100,1,ARL,345926413
2025-07-17T16:19:11.008353202Z,2025-07-17T16:19:11.008187551Z,160,2,1108,A,A,10,13.40,0,0,13.40,23,1,13.11,100,1,13.43,15,1,13.03,2,1,13.44,100,1,12.98,200,2,13.45,15,1,12.86,100,1,13.72,2,1,12.73,100,1,13.75,100,1,12.71,100,1,14.01,100,1,12.50,700,1,14.08,100,1,12.46,100,1,14.18,700,1,12.43,700,1,14.27,100,1,ARL,346562289
2025-07-17T16:19:11.008765986Z,2025-07-17T16:19:11.008600601Z,160,2,1108,A,A,10,13.40,0,0,13.40,23,1,13.11,100,1,13.43,15,1,13.03,2,1,13.44,100,1,12.98,200,2,13.45,15,1,12.86,100,1,13.72,2,1,12.73,100,1,13.75,100,1,12.71,100,1,14.01,100,1,12.50,700,1,14.08,100,1,12.46,100,1,14.18,700,1,12.43,700,1,14.27,100,1,ARL,346562317
2025-07-17T16:19:11.008779449Z,2025-07-17T16:19:11.008613992Z,160,2,1108,C,A,10,13.40,0,0,13.40,23,1,13.11,100,1,13.43,15,1,13.03,2,1,13.44,100,1,12.98,200,2,13.45,15,1,12.86,100,1,13.72,2,1,12.73,100,1,13.75,100,1,12.71,100,1,14.01,100,1,12.50,700,1,14.08,100,1,12.46,100,1,14.18,700,1,12.43,700,1,14.27,100,1,ARL,345930785
2025-07-17T16:19:11.009089771Z,2025-07-17T16:19:11.008923390Z,160,2,1108,C,A,10,13.40,0,0,13.40,23,1,13.11,100,1,13.43,15,1,13.03,2,1,13.44,100,1,12.98,200,2,13.45,15,1,12.86,100,1,13.72,2,1,12.73,100,1,13.75,100,1,12.71,100,1,14.01,100,1,12.50,700,1,14.08,100,1,12.46,100,1,14.18,700,1,12.43,700,1,14.27,100,1,ARL,345889161
2025-07-17T16:19:11.009089771Z,2025-07-17T16:19:11.008923390Z,160,2,1108,A,A,10,13.40,0,0,13.40,23,1,13.11,100,1,13.43,15,1,13.03,2,1,13.44,100,1,12.98,200,2,13.45,15,1,12.86,100,1,13.72,2,1,12.73,100,1,13.75,100,1,12.71,100,1,14.01,100,1,12.50,700,1,14.08,100,1,12.46,100,1,14.18,700,1,12.43,700,1,14.27,100,1,ARL,346562329
2025-07-17T16:19:11.035380853Z,2025-07-17T16:19:11.035215637Z,160,2,1108,A,A,10,13.40,0,0,13.40,23,1,13.11,100,1,13.43,15,1,13.03,2,1,13.44,100,1,12.98,200,2,13.45,15,1,12.86,100,1,13.72,2,1,12.73,100,1,13.75,100,1,12.71,100,1,14.01,100,1,12.50,700,1,14.08,100,1,12.46,100,1,14.18,700,1,12.43,700,1,14.27,100,1,ARL,346563437
2025-07-17T16:19:11.035392933Z,2025-07-17T16:19:11.035227814Z,160,2,1108,C,A,10,13.40,0,0,13.40,23,1,13.11,100,1,13.43,15,1,13.03,2,1,13.44,100,1,12.98,200,2,13.45,15,1,12.86,100,1,13.72,2,1,12.73,100,1,13.75,100,1,12.71,100,1,14.01,100,1,12.50,700,1,14.08,100,1,12.46,100,1,14.18,700,1,12.43,700,1,14.27,100,1,ARL,346562317
2025-07-17T16:19:20.837507906Z,2025-07-17T16:19:20.837342130Z,160,2,1108,C,A,10,13.40,0,0,13.40,23,1,13.11,100,1,13.43,15,1,13.03,2,1,13.44,100,1,12.98,200,2,13.72,2,1,12.86,100,1,13.75,100,1,12.73,100,1,14.01,100,1,12.71,100,1,14.08,100,1,12.50,700,1,14.18,700,1,12.46,100,1,14.27,100,1,12.43,700,1,14.28,100,1,ARL,345924181
2025-07-17T16:19:26.654075072Z,2025-07-17T16:19:26.653909048Z,160,2,1108,A,A,10,13.40,0,0,13.40,23,1,13.11,100,1,13.41,15,1,13.03,2,1,13.43,15,1,12.98,200,2,13.44,100,1,12.86,100,1,13.72,2,1,12.73,100,1,13.75,100,1,12.71,100,1,14.01,100,1,12.50,700,1,14.08,100,1,12.46,100,1,14.18,700,1,12.43,700,1,14.27,100,1,ARL,346891037
2025-07-17T16:19:27.200595996Z,2025-07-17T16:19:27.200430092Z,160,2,1108,C,A,10,13.40,0,0,13.40,23,1,13.11,100,1,13.41,15,1,13.03,2,1,13.43,15,1,12.98,200,2,13.72,2,1,12.86,100,1,13.75,100,1,12.73,100,1,14.01,100,1,12.71,100,1,14.08,100,1,12.50,700,1,14.18,700,1,12.46,100,1,14.27,100,1,12.43,700,1,14.28,100,1,ARL,346562289
2025-07-17T16:19:27.200595996Z,2025-07-17T16:19:27.200430092Z,160,2,1108,A,A,10,13.40,0,0,13.40,23,1,13.11,100,1,13.41,15,1,13.03,2,1,13.42,100,1,12.98,200,2,13.43,15,1,12.86,100,1,13.72,2,1,12.73,100,1,13.75,100,1,12.71,100,1,14.01,100,1,12.50,700,1,14.08,100,1,12.46,100,1,14.18,700,1,12.43,700,1,14.27,100,1,ARL,346904153
2025-07-17T16:19:27.200986286Z,2025-07-17T16:19:27.200820552Z,160,2,1108,A,A,10,13.40,0,0,13.40,23,1,13.11,100,1,13.41,15,1,13.03,2,1,13.42,100,1,12.98,200,2,13.43,15,1,12.86,100,1,13.72,2,1,12.73,100,1,13.75,100,1,12.71,100,1,14.01,100,1,12.50,700,1,14.08,100,1,12.46,100,1,14.18,700,1,12.43,700,1,14.27,100,1,ARL,346904169
2025-07-17T16:19:27.201000330Z,2025-07-17T16:19:27.200833294Z,160,2,1108,C,A,10,13.40,0,0,13.40,23,1,13.11,100,1,13.41,15,1,13.03,2,1,13.42,100,1,12.98,200,2,13.43,15,1,12.86,100,1,13.72,2,1,12.73,100,1,13.75,100,1,12.71,100,1,14.01,100,1,12.50,700,1,14.08,100,1,12.46,100,1,14.18,700,1,12.43,700,1,14.27,100,1,ARL,346563437
2025-07-17T16:19:27.201378249Z,2025-07-17T16:19:27.201212584Z,160,2,1108,A,A,10,13.40,0,0,13.40,23,1,13.11,100,1,13.41,15,1,13.03,2,1,13.42,100,1,12.98,200,2,13.43,15,1,12.86,100,1,13.72,2,1,12.73,100,1,13.75,100,1,12.71,100,1,14.01,100,1,12.50,700,1,14.08,100,1,12.46,100,1,14.18,700,1,12.43,700,1,14.19,700,1,ARL,346904221
2025-07-17T16:19:27.201777312Z,2025-07-17T16:19:27.201611743Z,160,2,1108,C,A,10,13.40,0,0,13.40,23,1,13.11,100,1,13.41,15,1,13.03,2,1,13.42,100,1,12.98,200,2,13.43,15,1,12.86,100,1,13.72,2,1,12.73,100,1,13.75,100,1,12.71,100,1,14.01,100,1,12.50,700,1,14.08,100,1,12.46,100,1,14.18,700,1,12.43,700,1,14.19,700,1,ARL,282969973
2025-07-17T16:19:27.228463152Z,2025-07-17T16:19:27.228297629Z,160,2,1108,A,A,10,13.40,0,0,13.40,23,1,13.11,100,1,13.41,15,1,13.03,2,1,13.42,100,1,12.98,200,2,13.43,15,1,12.86,100,1,13.72,2,1,12.73,100,1,13.75,100,1,12.71,100,1,14.01,100,1,12.50,700,1,14.08,100,1,12.46,100,1,14.18,700,1,12.43,700,1,14.19,700,1,ARL,346904561
2025-07-17T16:19:27.228473898Z,2025-07-17T16:19:27.228308764Z,160,2,1108,C,A,10,13.40,0,0,13.40,23,1,13.11,100,1,13.41,15,1,13.03,2,1,13.42,100,1,12.98,200,2,13.43,15,1,12.86,100,1,13.72,2,1,12.73,100,1,13.75,100,1,12.71,100,1,14.01,100,1,12.50,700,1,14.08,100,1,12.46,100,1,14.18,700,1,12.43,700,1,14.19,700,1,ARL,346904169
2025-07-17T16:19:28.991308227Z,2025-07-17T16:19:28.991142567Z,160,2,1108,C,B,10,13.40,0,0,13.40,23,1,13.11,100,1,13.41,15,1,12.98,200,2,13.42,100,1,12.86,100,1,13.43,15,1,12.73,100,1,13.72,2,1,12.71,100,1,13.75,100,1,12.50,700,1,14.01,100,1,12.46,100,1,14.08,100,1,12.43,700,1,14.18,700,1,12.42,700,1,14.19,700,1,ARL,343084165
2025-07-17T16:19:28.991308227Z,2025-07-17T16:19:28.991142567Z,160,2,1108,A,B,10,13.40,0,0,13.40,23,1,13.11,100,1,13.41,15,1,12.98,200,2,13.42,100,1,12.95,2,1,13.43,15,1,12.86,100,1,13.72,2,1,12.73,100,1,13.75,100,1,12.71,100,1,14.01,100,1,12.50,700,1,14.08,100,1,12.46,100,1,14.18,700,1,12.43,700,1,14.19,700,1,ARL,346942181
2025-07-17T16:19:30.834459284Z,2025-07-17T16:19:30.834293908Z,160,2,1108,C,A,10,13.40,0,0,13.40,23,1,13.11,100,1,13.42,100,1,12.98,200,2,13.43,15,1,12.95,2,1,13.72,2,1,12.86,100,1,13.75,100,1,12.73,100,1,14.01,100,1,12.71,100,1,14.08,100,1,12.50,700,1,14.18,700,1,12.46,100,1,14.19,700,1,12.43,700,1,14.27,100,1,ARL,346891037
2025-07-17T16:19:30.835008022Z,2025-07-17T16:19:30.834842536Z,160,2,1108,C,A,10,13.40,0,0,13.40,23,1,13.11,100,1,13.43,15,1,12.98,200,2,13.72,2,1,12.95,2,1,13.75,100,1,12.86,100,1,14.01,100,1,12.73,100,1,14.08,100,1,12.71,100,1,14.18,700,1,12.50,700,1,14.19,700,1,12.46,100,1,14.27,100,1,12.43,700,1,14.28,100,1,ARL,346904153
2025-07-17T16:19:30.835569072Z,2025-07-17T16:19:30.835403659Z,160,2,1108,C,A,10,13.40,0,0,13.40,23,1,13.11,100,1,13.72,2,1,12.98,200,2,13.75,100,1,12.95,2,1,14.01,100,1,12.86,100,1,14.08,100,1,12.73,100,1,14.18,700,1,12.71,100,1,14.19,700,1,12.50,700,1,14.27,100,1,12.46,100,1,14.28,100,1,12.43,700,1,14.35,200,2,ARL,346492493
2025-07-17T16:19:32.547487183Z,2025-07-17T16:19:32.547320695Z,160,2,1108,C,A,10,13.40,0,0,13.40,23,1,13.11,100,1,13.72,2,1,12.98,200,2,13.75,100,1,12.95,2,1,14.01,100,1,12.86,100,1,14.08,100,1,12.73,100,1,14.19,700,1,12.71,100,1,14.27,100,1,12.50,700,1,14.28,100,1,12.46,100,1,14.35,200,2,12.43,700,1,14.43,200,2,ARL,345998433
2025-07-17T16:19:32.547527626Z,2025-07-17T16:19:32.547362298Z,160,2,1108,A,A,10,13.40,0,0,13.40,23,1,13.11,100,1,13.72,2,1,12.98,200,2,13.75,100,1,12.95,2,1,14.01,100,1,12.86,100,1,14.08,100,1,12.73,100,1,14.19,700,1,12.71,100,1,14.27,100,1,12.50,700,1,14.28,100,1,12.46,100,1,14.35,200,2,12.43,700,1,14.43,200,2,ARL,347022701
2025-07-17T16:19:32.547597224Z,2025-07-17T16:19:32.547432031Z,160,2,1108,A,A,10,13.40,0,0,13.40,23,1,13.11,100,1,13.72,2,1,12.98,200,2,13.75,100,1,12.95,2,1,14.01,100,1,12.86,100,1,14.08,100,1,12.73,100,1,14.19,700,1,12.71,100,1,14.27,100,1,12.50,700,1,14.28,100,1,12.46,100,1,14.35,200,2,12.43,700,1,14.43,200,2,ARL,347022705
2025-07-17T16:19:32.547609689Z,2025-07-17T16:19:32.547444392Z,160,2,1108,C,A,10,13.40,0,0,13.40,23,1,13.11,100,1,13.72,2,1,12.98,200,2,13.75,100,1,12.95,2,1,14.01,100,1,12.86,100,1,14.08,100,1,12.73,100,1,14.19,700,1,12.71,100,1,14.27,100,1,12.50,700,1,14.28,100,1,12.46,100,1,14.35,200,2,12.43,700,1,14.43,200,2,ARL,346904561
2025-07-17T16:19:32.548069205Z,2025-07-17T16:19:32.547904024Z,160,2,1108,C,A,10,13.40,0,0,13.40,23,1,13.11,100,1,13.72,2,1,12.98,200,2,13.75,100,1,12.95,2,1,14.01,100,1,12.86,100,1,14.19,700,1,12.73,100,1,14.27,100,1,12.71,100,1,14.28,100,1,12.50,700,1,14.35,200,2,12.46,100,1,14.43,200,2,12.43,700,1,14.44,700,1,ARL,345889165
2025-07-17T16:19:32.548096238Z,2025-07-17T16:19:32.547930966Z,160,2,1108,C,A,10,13.40,0,0,13.40,23,1,13.11,100,1,13.72,2,1,12.98,200,2,13.75,100,1,12.95,2,1,14.01,100,1,12.86,100,1,14.27,100,1,12.73,100,1,14.28,100,1,12.71,100,1,14.35,200,2,12.50,700,1,14.43,200,2,12.46,100,1,14.44,700,1,12.43,700,1,14.48,800,2,ARL,346904221
2025-07-17T16:19:32.548113549Z,2025-07-17T16:19:32.547947865Z,160,2,1108,C,A,10,13.40,0,0,13.40,23,1,13.11,100,1,13.72,2,1,12.98,200,2,13.75,100,1,12.95,2,1,14.01,100,1,12.86,100,1,14.27,100,1,12.73,100,1,14.28,100,1,12.71,100,1,14.35,200,2,12.50,700,1,14.43,200,2,12.46,100,1,14.44,700,1,12.43,700,1,14.48,700,1,ARL,346562329
2025-07-17T16:19:32.548113549Z,2025-07-17T16:19:32.547947865Z,160,2,1108,A,A,10,13.40,0,0,13.40,23,1,13.11,100,1,13.72,2,1,12.98,200,2,13.75,100,1,12.95,2,1,14.01,100,1,12.86,100,1,14.27,100,1,12.73,100,1,14.28,100,1,12.71,100,1,14.35,200,2,12.50,700,1,14.43,200,2,12.46,100,1,14.44,700,1,12.43,700,1,14.48,700,1,ARL,347022737
2025-07-17T16:19:32.548423905Z,2025-07-17T16:19:32.548258519Z,160,2,1108,A,A,10,13.40,0,0,13.40,23,1,13.11,100,1,13.72,2,1,12.98,200,2,13.75,100,1,12.95,2,1,14.01,100,1,12.86,100,1,14.27,100,1,12.73,100,1,14.28,100,1,12.71,100,1,14.35,200,2,12.50,700,1,14.36,100,1,12.46,100,1,14.43,200,2,12.43,700,1,14.44,700,1,ARL,347022741
2025-07-17T16:19:32.548503722Z,2025-07-17T16:19:32.548338068Z,160,2,1108,A,A,10,13.40,0,0,13.40,23,1,13.11,100,1,13.72,2,1,12.98,200,2,13.75,100,1,12.95,2,1,14.01,100,1,12.86,100,1,14.27,100,1,12.73,100,1,14.28,100,1,12.71,100,1,14.35,200,2,12.50,700,1,14.36,100,1,12.46,100,1,14.43,200,2,12.43,700,1,14.44,700,1,ARL,347022749
2025-07-17T16:19:32.548575405Z,2025-07-17T16:19:32.548409803Z,160,2,1108,C,A,10,13.40,0,0,13.40,23,1,13.11,100,1,13.72,2,1,12.98,200,2,13.75,100,1,12.95,2,1,14.01,100,1,12.86,100,1,14.27,100,1,12.73,100,1,14.28,100,1,12.71,100,1,14.35,200,2,12.50,700,1,14.36,100,1,12.46,100,1,14.43,200,2,12.43,700,1,14.44,700,1,ARL,345889185
2025-07-17T16:19:32.548575405Z,2025-07-17T16:19:32.548409803Z,160,2,1108,A,A,10,13.40,0,0,13.40,23,1,13.11,100,1,13.72,2,1,12.98,200,2,13.75,100,1,12.95,2,1,14.01,100,1,12.86,100,1,14.27,100,1,12.73,100,1,14.28,100,1,12.71,100,1,14.35,200,2,12.50,700,1,14.36,100,1,12.46,100,1,14.43,200,2,12.43,700,1,14.44,700,1,ARL,347022753
2025-07-17T16:19:32.548583352Z,2025-07-17T16:19:32.548417853Z,160,2,1108,C,A,10,13.40,0,0,13.40,23,1,13.11,100,1,13.72,2,1,12.98,200,2,13.75,100,1,12.95,2,1,14.01,100,1,12.86,100,1,14.27,100,1,12.73,100,1,14.28,100,1,12.71,100,1,14.35,200,2,12.50,700,1,14.36,100,1,12.46,100,1,14.43,200,2,12.43,700,1,14.44,700,1,ARL,345889205
2025-07-17T16:19:32.548583352Z,2025-07-17T16:19:32.548417853Z,160,2,1108,A,A,10,13.40,0,0,13.40,23,1,13.11,100,1,13.72,2,1,12.98,200,2,13.75,100,1,12.95,2,1,14.01,100,1,12.86,100,1,14.27,100,1,12.73,100,1,14.28,100,1,12.71,100,1,14.35,200,2,12.50,700,1,14.36,100,1,12.46,100,1,14.43,200,2,12.43,700,1,14.44,700,1,ARL,347022757
2025-07-17T16:19:32.549166752Z,2025-07-17T16:19:32.549001387Z,160,2,1108,C,A,10,13.40,0,0,13.40,23,1,13.11,100,1,13.72,2,1,12.98,200,2,13.75,100,1,12.95,2,1,14.01,100,1,12.86,100,1,14.28,100,1,12.73,100,1,14.35,200,2,12.71,100,1,14.36,100,1,12.50,700,1,14.43,200,2,12.46,100,1,14.44,700,1,12.43,700,1,14.48,1400,2,ARL,345889277
2025-07-17T16:19:32.549166752Z,2025-07-17T16:19:32.549001387Z,160,2,1108,A,A,10,13.40,0,0,13.40,23,1,13.11,100,1,13.72,2,1,12.98,200,2,13.75,100,1,12.95,2,1,14.01,100,1,12.86,100,1,14.28,100,1,12.73,100,1,14.35,200,2,12.71,100,1,14.36,100,1,12.50,700,1,14.43,200,2,12.46,100,1,14.44,700,1,12.43,700,1,14.48,1400,2,ARL,347022789
2025-07-17T16:19:32.549433234Z,2025-07-17T16:19:32.549267465Z,160,2,1108,C,A,10,13.40,0,0,13.40,23,1,13.11,100,1,13.72,2,1,12.98,200,2,13.75,100,1,12.95,2,1,14.01,100,1,12.86,100,1,14.28,100,1,12.73,100,1,14.35,200,2,12.71,100,1,14.36,100,1,12.50,700,1,14.43,100,1,12.46,100,1,14.44,700,1,12.43,700,1,14.48,1400,2,ARL,345889201
2025-07-17T16:19:32.549433234Z,2025-07-17T16:19:32.549267465Z,160,2,1108,A,A,10,13.40,0,0,13.40,23,1,13.11,100,1,13.72,2,1,12.98,200,2,13.75,100,1,12.95,2,1,14.01,100,1,12.86,100,1,14.28,100,1,12.73,100,1,14.35,200,2,12.71,100,1,14.36,100,1,12.50,700,1,14.43,100,1,12.46,100,1,14.44,700,1,12.43,700,1,14.48,1400,2,ARL,347022797
2025-07-17T16:19:32.550149522Z,2025-07-17T16:19:32.549983550Z,160,2,1108,C,A,10,13.40,0,0,13.40,23,1,13.11,100,1,13.72,2,1,12.98,200,2,13.75,100,1,12.95,2,1,14.01,100,1,12.86,100,1,14.28,100,1,12.73,100,1,14.35,200,2,12.71,100,1,14.36,100,1,12.50,700,1,14.43,100,1,12.46,100,1,14.44,700,1,12.43,700,1,14.48,1400,2,ARL,345889193
2025-07-17T16:19:32.550149522Z,2025-07-17T16:19:32.549983550Z,160,2,1108,A,A,10,13.40,0,0,13.40,23,1,13.11,100,1,13.72,2,1,12.98,200,2,13.75,100,1,12.95,2,1,14.01,100,1,12.86,100,1,14.28,100,1,12.73,100,1,14.35,200,2,12.71,100,1,14.36,100,1,12.50,700,1,14.43,100,1,12.46,100,1,14.44,700,1,12.43,700,1,14.48,1400,2,ARL,347022817
2025-07-17T16:19:32.551870451Z,2025-07-17T16:19:32.551704711Z,160,2,1108,C,A,10,13.40,0,0,13.40,23,1,13.11,100,1,13.72,2,1,12.98,200,2,13.75,100,1,12.95,2,1,14.01,100,1,12.86,100,1,14.28,100,1,12.73,100,1,14.35,200,2,12.71,100,1,14.36,100,1,12.50,700,1,14.43,100,1,12.46,100,1,14.44,700,1,12.43,700,1,14.48,1400,2,ARL,345889209
2025-07-17T16:19:32.551870451Z,2025-07-17T16:19:32.551704711Z,160,2,1108,A,A,10,13.40,0,0,13.40,23,1,13.11,100,1,13.72,2,1,12.98,200,2,13.75,100,1,12.95,2,1,14.01,100,1,12.86,100,1,14.28,100,1,12.73,100,1,14.35,200,2,12.71,100,1,14.36,100,1,12.50,700,1,14.43,100,1,12.46,100,1,14.44,700,1,12.43,700,1,14.48,1400,2,ARL,347022865
2025-07-17T16:19:32.554564549Z,2025-07-17T16:19:32.554398971Z,160,2,1108,C,A,10,13.40,0,0,13.40,23,1,13.11,100,1,13.72,2,1,12.98,200,2,13.75,100,1,12.95,2,1,14.01,100,1,12.86,100,1,14.28,100,1,12.73,100,1,14.35,200,2,12.71,100,1,14.36,100,1,12.50,700,1,14.44,700,1,12.46,100,1,14.48,1400,2,12.43,700,1,14.54,800,2,ARL,345889189
2025-07-17T16:19:32.554564549Z,2025-07-17T16:19:32.554398971Z,160,2,1108,A,A,10,13.40,0,0,13.40,23,1,13.11,100,1,13.72,2,1,12.98,200,2,13.75,100,1,12.95,2,1,14.01,100,1,12.86,100,1,14.28,100,1,12.73,100,1,14.35,200,2,12.71,100,1,14.36,100,1,12.50,700,1,14.44,700,1,12.46,100,1,14.48,1400,2,12.43,700,1,14.54,800,2,ARL,347022893
2025-07-17T16:19:32.566140694Z,2025-07-17T16:19:32.565975313Z,160,2,1108,C,A,10,13.40,0,0,13.40,23,1,13.11,100,1,13.72,2,1,12.98,200,2,14.01,100,1,12.95,2,1,14.28,100,1,12.86,100,1,14.35,200,2,12.73,100,1,14.36,100,1,12.71,100,1,14.44,700,1,12.50,700,1,14.48,1400,2,12.46,100,1,14.54,800,2,12.43,700,1,14.72,200,2,ARL,345889457
2025-07-17T16:19:32.566174380Z,2025-07-17T16:19:32.566009468Z,160,2,1108,C,A,10,13.40,0,0,13.40,23,1,13.11,100,1,13.72,2,1,12.98,200,2,14.01,100,1,12.95,2,1,14.28,100,1,12.86,100,1,14.35,200,2,12.73,100,1,14.36,100,1,12.71,100,1,14.48,1400,2,12.50,700,1,14.54,800,2,12.46,100,1,14.72,200,2,12.43,700,1,14.82,100,1,ARL,347022701
2025-07-17T16:19:32.566193866Z,2025-07-17T16:19:32.566028302Z,160,2,1108,A,A,10,13.40,0,0,13.40,23,1,13.11,100,1,13.72,2,1,12.98,200,2,14.01,100,1,12.95,2,1,14.03,100,1,12.86,100,1,14.28,100,1,12.73,100,1,14.35,200,2,12.71,100,1,14.36,100,1,12.50,700,1,14.48,1400,2,12.46,100,1,14.54,800,2,12.43,700,1,14.72,200,2,ARL,347023005
2025-07-17T16:19:32.567048160Z,2025-07-17T16:19:32.566882768Z,160,2,1108,C,A,10,13.40,0,0,13.40,23,1,13.11,100,1,13.72,2,1,12.98,200,2,14.01,100,1,12.95,2,1,14.03,100,1,12.86,100,1,14.28,100,1,12.73,100,1,14.35,200,2,12.71,100,1,14.36,100,1,12.50,700,1,14.48,1400,2,12.46,100,1,14.54,800,2,12.43,700,1,14.72,100,1,ARL,347022893
2025-07-17T16:19:32.567048160Z,2025-07-17T16:19:32.566882768Z,160,2,1108,A,A,10,13.40,0,0,13.40,23,1,13.11,100,1,13.72,2,1,12.98,200,2,14.01,100,1,12.95,2,1,14.03,100,1,12.86,100,1,14.28,100,1,12.73,100,1,14.35,200,2,12.71,100,1,14.36,100,1,12.50,700,1,14.48,1400,2,12.46,100,1,14.54,800,2,12.43,700,1,14.72,100,1,ARL,347023021
2025-07-17T16:19:32.567810828Z,2025-07-17T16:19:32.567645036Z,160,2,1108,C,A,10,13.40,0,0,13.40,23,1,13.11,100,1,13.72,2,1,12.98,200,2,14.01,100,1,12.95,2,1,14.03,100,1,12.86,100,1,14.28,100,1,12.73,100,1,14.35,200,2,12.71,100,1,14.36,100,1,12.50,700,1,14.48,1400,2,12.46,100,1,14.54,800,2,12.43,700,1,14.72,100,1,ARL,347022757
2025-07-17T16:19:32.567810828Z,2025-07-17T16:19:32.567645036Z,160,2,1108,A,A,10,13.40,0,0,13.40,23,1,13.11,100,1,13.72,2,1,12.98,200,2,14.01,100,1,12.95,2,1,14.03,100,1,12.86,100,1,14.28,100,1,12.73,100,1,14.35,200,2,12.71,100,1,14.36,100,1,12.50,700,1,14.48,1400,2,12.46,100,1,14.54,800,2,12.43,700,1,14.72,100,1,ARL,347023037
2025-07-17T16:19:32.567981668Z,2025-07-17T16:19:32.567816385Z,160,2,1108,C,A,10,13.40,0,0,13.40,23,1,13.11,100,1,13.72,2,1,12.98,200,2,14.01,100,1,12.95,2,1,14.03,100,1,12.86,100,1,14.28,100,1,12.73,100,1,14.35,200,2,12.71,100,1,14.36,100,1,12.50,700,1,14.48,1400,2,12.46,100,1,14.54,800,2,12.43,700,1,14.82,100,1,ARL,347022797
2025-07-17T16:19:32.567981668Z,2025-07-17T16:19:32.567816385Z,160,2,1108,A,A,10,13.40,0,0,13.40,23,1,13.11,100,1,13.72,2,1,12.98,200,2,14.01,100,1,12.95,2,1,14.03,100,1,12.86,100,1,14.28,100,1,12.73,100,1,14.35,200,2,12.71,100,1,14.36,100,1,12.50,700,1,14.48,1400,2,12.46,100,1,14.54,800,2,12.43,700,1,14.82,100,1,ARL,347023045
2025-07-17T16:19:32.568776675Z,2025-07-17T16:19:32.568611131Z,160,2,1108,C,A,10,13.40,0,0,13.40,23,1,13.11,100,1,14.01,100,1,12.98,200,2,14.03,100,1,12.95,2,1,14.28,100,1,12.86,100,1,14.35,200,2,12.73,100,1,14.36,100,1,12.71,100,1,14.48,1400,2,12.50,700,1,14.54,800,2,12.46,100,1,14.82,100,1,12.43,700,1,14.95,100,1,ARL,346423105
2025-07-17T16:19:32.568776675Z,2025-07-17T16:19:32.568611131Z,160,2,1108,A,A,10,13.40,0,0,13.40,23,1,13.11,100,1,13.98,2,1,12.98,200,2,14.01,100,1,12.95,2,1,14.03,100,1,12.86,100,1,14.28,100,1,12.73,100,1,14.35,200,2,12.71,100,1,14.36,100,1,12.50,700,1,14.48,1400,2,12.46,100,1,14.54,800,2,12.43,700,1,14.82,100,1,ARL,347023061
2025-07-17T16:19:32.568800112Z,2025-07-17T16:19:32.568634829Z,160,2,1108,C,A,10,13.40,0,0,13.40,23,1,13.11,100,1,13.98,2,1,12.98,200,2,14.01,100,1,12.95,2,1,14.03,100,1,12.86,100,1,14.28,100,1,12.73,100,1,14.35,200,2,12.71,100,1,14.36,100,1,12.50,700,1,14.48,1400,2,12.46,100,1,14.54,800,2,12.43,700,1,14.82,100,1,ARL,347022817
2025-07-17T16:19:32.568800112Z,2025-07-17T16:19:32.568634829Z,160,2,1108,A,A,10,13.40,0,0,13.40,23,1,13.11,100,1,13.98,2,1,12.98,200,2,14.01,100,1,12.95,2,1,14.03,100,1,12.86,100,1,14.28,100,1,12.73,100,1,14.35,200,2,12.71,100,1,14.36,100,1,12.50,700,1,14.48,1400,2,12.46,100,1,14.54,800,2,12.43,700,1,14.82,100,1,ARL,347023065
2025-07-17T16:19:32.586782162Z,2025-07-17T16:19:32.586617069Z,160,2,1108,C,A,10,13.40,0,0,13.40,23,1,13.11,100,1,13.98,2,1,12.98,200,2,14.01,100,1,12.95,2,1,14.28,100,1,12.86,100,1,14.35,200,2,12.73,100,1,14.36,100,1,12.71,100,1,14.48,1400,2,12.50,700,1,14.54,800,2,12.46,100,1,14.82,100,1,12.43,700,1,14.95,100,1,ARL,347023005
2025-07-17T16:19:32.586832073Z,2025-07-17T16:19:32.586666869Z,160,2,1108,A,A,10,13.40,0,0,13.40,23,1,13.11,100,1,13.98,2,1,12.98,200,2,14.01,100,1,12.95,2,1,14.25,100,1,12.86,100,1,14.28,100,1,12.73,100,1,14.35,200,2,12.71,100,1,14.36,100,1,12.50,700,1,14.48,1400,2,12.46,100,1,14.54,800,2,12.43,700,1,14.82,100,1,ARL,347023197
2025-07-17T16:19:32.597958839Z,2025-07-17T16:19:32.597793442Z,160,2,1108,C,A,10,13.40,0,0,13.40,23,1,13.11,100,1,13.98,2,1,12.98,200,2,14.01,100,1,12.95,2,1,14.25,100,1,12.86,100,1,14.28,100,1,12.73,100,1,14.35,200,2,12.71,100,1,14.36,100,1,12.50,700,1,14.48,1400,2,12.46,100,1,14.54,800,2,12.43,700,1,14.95,100,1,ARL,347022737
2025-07-17T16:19:32.597958839Z,2025-07-17T16:19:32.597793442Z,160,2,1108,A,A,10,13.40,0,0,13.40,23,1,13.11,100,1,13.98,2,1,12.98,200,2,14.01,100,1,12.95,2,1,14.25,100,1,12.86,100,1,14.28,100,1,12.73,100,1,14.35,200,2,12.71,100,1,14.36,100,1,12.50,700,1,14.48,1400,2,12.46,100,1,14.54,800,2,12.43,700,1,14.95,100,1,ARL,347023333
2025-07-17T16:19:32.602447841Z,2025-07-17T16:19:32.602282571Z,160,2,1108,A,A,10,13.40,0,0,13.40,23,1,13.11,100,1,13.98,2,1,12.98,200,2,14.01,100,1,12.95,2,1,14.25,100,1,12.86,100,1,14.28,100,1,12.73,100,1,14.35,200,2,12.71,100,1,14.36,100,1,12.50,700,1,14.48,1400,2,12.46,100,1,14.54,800,2,12.43,700,1,14.68,700,1,ARL,347023357
2025-07-17T16:19:32.706223822Z,2025-07-17T16:19:32.706057444Z,160,2,1108,A,A,10,13.40,0,0,13.40,23,1,13.11,100,1,13.98,2,1,12.98,200,2,14.01,100,1,12.95,2,1,14.25,100,1,12.86,100,1,14.28,100,1,12.73,100,1,14.35,200,2,12.71,100,1,14.36,100,1,12.50,700,1,14.48,1400,2,12.46,100,1,14.53,100,1,12.43,700,1,14.54,800,2,ARL,347025333
2025-07-17T16:19:32.706223822Z,2025-07-17T16:19:32.706057831Z,160,2,1108,C,A,10,13.40,0,0,13.40,23,1,13.11,100,1,13.98,2,1,12.98,200,2,14.25,100,1,12.95,2,1,14.28,100,1,12.86,100,1,14.35,200,2,12.73,100,1,14.36,100,1,12.71,100,1,14.48,1400,2,12.50,700,1,14.53,100,1,12.46,100,1,14.54,800,2,12.43,700,1,14.68,700,1,ARL,345911213
2025-07-17T16:19:32.857787299Z,2025-07-17T16:19:32.857621837Z,160,2,1108,A,A,10,13.40,0,0,13.40,23,1,13.11,100,1,13.98,2,1,12.98,200,2,14.25,100,1,12.95,2,1,14.28,100,1,12.86,100,1,14.35,200,2,12.73,100,1,14.36,100,1,12.71,100,1,14.48,1400,2,12.50,700,1,14.53,100,1,12.46,100,1,14.54,800,2,12.43,700,1,14.68,700,1,ARL,347027121
2025-07-17T16:19:32.857804235Z,2025-07-17T16:19:32.857638959Z,160,2,1108,C,A,10,13.40,0,0,13.40,23,1,13.11,100,1,13.98,2,1,12.98,200,2,14.25,100,1,12.95,2,1,14.35,200,2,12.86,100,1,14.36,100,1,12.73,100,1,14.48,1400,2,12.71,100,1,14.53,100,1,12.50,700,1,14.54,800,2,12.46,100,1,14.68,700,1,12.43,700,1,14.81,100,1,ARL,345903265
2025-07-17T16:19:32.887058748Z,2025-07-17T16:19:32.886893433Z,160,2,1108,A,A,10,13.40,0,0,13.40,23,1,13.11,100,1,13.98,2,1,12.98,200,2,13.99,100,1,12.95,2,1,14.25,100,1,12.86,100,1,14.35,200,2,12.73,100,1,14.36,100,1,12.71,100,1,14.48,1400,2,12.50,700,1,14.53,100,1,12.46,100,1,14.54,800,2,12.43,700,1,14.68,700,1,ARL,347030085
2025-07-17T16:19:33.241360545Z,2025-07-17T16:19:33.241195095Z,160,2,1108,C,A,10,13.40,0,0,13.40,23,1,13.11,100,1,13.98,2,1,12.98,200,2,13.99,100,1,12.95,2,1,14.25,100,1,12.86,100,1,14.35,200,2,12.73,100,1,14.48,1400,2,12.71,100,1,14.53,100,1,12.50,700,1,14.54,800,2,12.46,100,1,14.68,700,1,12.43,700,1,14.81,100,1,ARL,347022741
2025-07-17T16:19:33.241714286Z,2025-07-17T16:19:33.241548838Z,160,2,1108,A,A,10,13.40,0,0,13.40,23,1,13.11,100,1,13.98,2,1,12.98,200,2,13.99,100,1,12.95,2,1,14.25,100,1,12.86,100,1,14.35,200,2,12.73,100,1,14.48,1400,2,12.71,100,1,14.53,100,1,12.50,700,1,14.54,800,2,12.46,100,1,14.60,100,1,12.43,700,1,14.68,700,1,ARL,347045237
2025-07-17T16:19:33.550443222Z,2025-07-17T16:19:33.550277249Z,160,2,1108,C,A,10,13.40,0,0,13.40,23,1,13.11,100,1,13.98,2,1,12.98,200,2,13.99,100,1,12.95,2,1,14.25,100,1,12.86,100,1,14.35,200,2,12.73,100,1,14.48,1400,2,12.71,100,1,14.53,100,1,12.50,700,1,14.54,700,1,12.46,100,1,14.60,100,1,12.43,700,1,14.68,700,1,ARL,347022789
2025-07-17T16:19:33.550630659Z,2025-07-17T16:19:33.550465490Z,160,2,1108,A,A,10,13.40,0,0,13.40,23,1,13.11,100,1,13.98,2,1,12.98,200,2,13.99,100,1,12.95,2,1,14.25,100,1,12.86,100,1,14.35,200,2,12.73,100,1,14.48,1400,2,12.71,100,1,14.53,100,1,12.50,700,1,14.54,700,1,12.46,100,1,14.60,100,1,12.43,700,1,14.68,700,1,ARL,347052337
2025-07-17T16:19:42.789662492Z,2025-07-17T16:19:42.789496729Z,160,2,1108,C,B,10,13.40,0,0,13.40,23,1,13.11,100,1,13.98,2,1,12.98,200,2,13.99,100,1,12.86,100,1,14.25,100,1,12.73,100,1,14.35,200,2,12.71,100,1,14.48,1400,2,12.50,700,1,14.53,100,1,12.46,100,1,14.54,700,1,12.43,700,1,14.60,100,1,12.42,700,1,14.68,700,1,ARL,346942181
2025-07-17T16:19:42.789662492Z,2025-07-17T16:19:42.789496729Z,160,2,1108,A,B,10,13.40,0,0,13.40,23,1,13.11,100,1,13.98,2,1,13.03,2,1,13.99,100,1,12.98,200,2,14.25,100,1,12.86,100,1,14.35,200,2,12.73,100,1,14.48,1400,2,12.71,100,1,14.53,100,1,12.50,700,1,14.54,700,1,12.46,100,1,14.60,100,1,12.43,700,1,14.68,700,1,ARL,347220093
2025-07-17T16:19:50.837886219Z,2025-07-17T16:19:50.837720648Z,160,2,1108,A,A,10,13.40,0,0,13.40,23,1,13.11,100,1,13.44,15,1,13.03,2,1,13.98,2,1,12.98,200,2,13.99,100,1,12.86,100,1,14.25,100,1,12.73,100,1,14.35,200,2,12.71,100,1,14.48,1400,2,12.50,700,1,14.53,100,1,12.46,100,1,14.54,700,1,12.43,700,1,14.60,100,1,ARL,347377693
2025-07-17T16:19:51.986999699Z,2025-07-17T16:19:51.986834012Z,160,2,1108,C,A,10,13.40,0,0,13.40,23,1,13.11,100,1,13.44,15,1,13.03,2,1,13.98,2,1,12.98,200,2,14.25,100,1,12.86,100,1,14.35,200,2,12.73,100,1,14.48,1400,2,12.71,100,1,14.53,100,1,12.50,700,1,14.54,700,1,12.46,100,1,14.60,100,1,12.43,700,1,14.68,700,1,ARL,347030085
2025-07-17T16:19:51.986999699Z,2025-07-17T16:19:51.986834012Z,160,2,1108,A,A,10,13.40,0,0,13.40,23,1,13.11,100,1,13.44,15,1,13.03,2,1,13.45,100,1,12.98,200,2,13.98,2,1,12.86,100,1,14.25,100,1,12.73,100,1,14.35,200,2,12.71,100,1,14.48,1400,2,12.50,700,1,14.53,100,1,12.46,100,1,14.54,700,1,12.43,700,1,14.60,100,1,ARL,347396033
2025-07-17T16:19:51.987738024Z,2025-07-17T16:19:51.987571652Z,160,2,1108,C,A,10,13.40,0,0,13.40,23,1,13.11,100,1,13.44,15,1,13.03,2,1,13.45,100,1,12.98,200,2,13.98,2,1,12.86,100,1,14.25,100,1,12.73,100,1,14.35,200,2,12.71,100,1,14.48,1400,2,12.50,700,1,14.53,100,1,12.46,100,1,14.54,700,1,12.43,700,1,14.68,700,1,ARL,347045237
2025-07-17T16:19:51.987743715Z,2025-07-17T16:19:51.987578278Z,160,2,1108,C,A,10,13.40,0,0,13.40,23,1,13.11,100,1,13.44,15,1,13.03,2,1,13.45,100,1,12.98,200,2,13.98,2,1,12.86,100,1,14.25,100,1,12.73,100,1,14.35,200,2,12.71,100,1,14.48,1400,2,12.50,700,1,14.53,100,1,12.46,100,1,14.54,700,1,12.43,700,1,14.68,700,1,ARL,347023333
2025-07-17T16:19:51.987743715Z,2025-07-17T16:19:51.987578278Z,160,2,1108,A,A,10,13.40,0,0,13.40,23,1,13.11,100,1,13.44,15,1,13.03,2,1,13.45,100,1,12.98,200,2,13.98,2,1,12.86,100,1,14.25,100,1,12.73,100,1,14.35,200,2,12.71,100,1,14.48,1400,2,12.50,700,1,14.49,100,1,12.46,100,1,14.53,100,1,12.43,700,1,14.54,700,1,ARL,347396065
2025-07-17T16:19:51.988088818Z,2025-07-17T16:19:51.987923621Z,160,2,1108,A,A,10,13.40,0,0,13.40,23,1,13.11,100,1,13.44,15,1,13.03,2,1,13.45,100,1,12.98,200,2,13.98,2,1,12.86,100,1,14.05,100,1,12.73,100,1,14.25,100,1,12.71,100,1,14.35,200,2,12.50,700,1,14.48,1400,2,12.46,100,1,14.49,100,1,12.43,700,1,14.53,100,1,ARL,347396069
2025-07-17T16:19:51.988346300Z,2025-07-17T16:19:51.988180539Z,160,2,1108,C,A,10,13.40,0,0,13.40,23,1,13.11,100,1,13.44,15,1,13.03,2,1,13.45,100,1,12.98,200,2,13.98,2,1,12.86,100,1,14.05,100,1,12.73,100,1,14.25,100,1,12.71,100,1,14.35,200,2,12.50,700,1,14.48,1400,2,12.46,100,1,14.49,100,1,12.43,700,1,14.53,100,1,ARL,347022753
2025-07-17T16:19:51.988346300Z,2025-07-17T16:19:51.988180539Z,160,2,1108,A,A,10,13.40,0,0,13.40,23,1,13.11,100,1,13.44,15,1,13.03,2,1,13.45,100,1,12.98,200,2,13.98,2,1,12.86,100,1,14.05,100,1,12.73,100,1,14.25,100,1,12.71,100,1,14.35,200,2,12.50,700,1,14.48,1400,2,12.46,100,1,14.49,100,1,12.43,700,1,14.53,100,1,ARL,347396073
2025-07-17T16:19:51.989180674Z,2025-07-17T16:19:51.989015100Z,160,2,1108,C,A,10,13.40,0,0,13.40,23,1,13.11,100,1,13.44,15,1,13.03,2,1,13.45,100,1,12.98,200,2,13.98,2,1,12.86,100,1,14.05,100,1,12.73,100,1,14.25,100,1,12.71,100,1,14.35,200,2,12.50,700,1,14.48,1400,2,12.46,100,1,14.49,100,1,12.43,700,1,14.53,100,1,ARL,347023045
2025-07-17T16:19:51.989180674Z,2025-07-17T16:19:51.989015100Z,160,2,1108,A,A,10,13.40,0,0,13.40,23,1,13.11,100,1,13.44,15,1,13.03,2,1,13.45,100,1,12.98,200,2,13.98,2,1,12.86,100,1,14.05,100,1,12.73,100,1,14.25,100,1,12.71,100,1,14.35,200,2,12.50,700,1,14.40,100,1,12.46,100,1,14.48,1400,2,12.43,700,1,14.49,100,1,ARL,347396085
2025-07-17T16:19:51.990397633Z,2025-07-17T16:19:51.990232192Z,160,2,1108,C,A,10,13.40,0,0,13.40,23,1,13.11,100,1,13.44,15,1,13.03,2,1,13.45,100,1,12.98,200,2,13.98,2,1,12.86,100,1,14.05,100,1,12.73,100,1,14.25,100,1,12.71,100,1,14.35,200,2,12.50,700,1,14.40,100,1,12.46,100,1,14.48,1400,2,12.43,700,1,14.49,100,1,ARL,347023037
2025-07-17T16:19:51.990397633Z,2025-07-17T16:19:51.990232192Z,160,2,1108,A,A,10,13.40,0,0,13.40,23,1,13.11,100,1,13.44,15,1,13.03,2,1,13.45,100,1,12.98,200,2,13.98,2,1,12.86,100,1,14.05,100,1,12.73,100,1,14.25,100,1,12.71,100,1,14.35,200,2,12.50,700,1,14.40,100,1,12.46,100,1,14.48,1400,2,12.43,700,1,14.49,100,1,ARL,347396125
2025-07-17T16:19:51.990483745Z,2025-07-17T16:19:51.990318196Z,160,2,1108,C,A,10,13.40,0,0,13.40,23,1,13.11,100,1,13.44,15,1,13.03,2,1,13.45,100,1,12.98,200,2,13.98,2,1,12.86,100,1,14.05,100,1,12.73,100,1,14.25,100,1,12.71,100,1,14.35,200,2,12.50,700,1,14.40,100,1,12.46,100,1,14.48,1400,2,12.43,700,1,14.49,100,1,ARL,347023065
2025-07-17T16:19:51.990483745Z,2025-07-17T16:19:51.990318196Z,160,2,1108,A,A,10,13.40,0,0,13.40,23,1,13.11,100,1,13.44,15,1,13.03,2,1,13.45,100,1,12.98,200,2,13.98,2,1,12.86,100,1,14.05,100,1,12.73,100,1,14.25,100,1,12.71,100,1,14.35,200,2,12.50,700,1,14.40,100,1,12.46,100,1,14.48,1400,2,12.43,700,1,14.49,100,1,ARL,347396129
2025-07-17T16:19:51.990825106Z,2025-07-17T16:19:51.990659712Z,160,2,1108,C,A,10,13.40,0,0,13.40,23,1,13.11,100,1,13.44,15,1,13.03,2,1,13.45,100,1,12.98,200,2,14.05,100,1,12.86,100,1,14.25,100,1,12.73,100,1,14.35,200,2,12.71,100,1,14.40,100,1,12.50,700,1,14.48,1400,2,12.46,100,1,14.49,100,1,12.43,700,1,14.53,100,1,ARL,347023061
2025-07-17T16:19:51.990825106Z,2025-07-17T16:19:51.990659712Z,160,2,1108,A,A,10,13.40,0,0,13.40,23,1,13.11,100,1,13.44,15,1,13.03,2,1,13.45,100,1,12.98,200,2,13.86,2,1,12.86,100,1,14.05,100,1,12.73,100,1,14.25,100,1,12.71,100,1,14.35,200,2,12.50,700,1,14.40,100,1,12.46,100,1,14.48,1400,2,12.43,700,1,14.49,100,1,ARL,347396177
2025-07-17T16:19:52.000587632Z,2025-07-17T16:19:52.000421983Z,160,2,1108,C,A,10,13.40,0,0,13.40,23,1,13.11,100,1,13.44,15,1,13.03,2,1,13.45,100,1,12.98,200,2,13.86,2,1,12.86,100,1,14.05,100,1,12.73,100,1,14.35,200,2,12.71,100,1,14.40,100,1,12.50,700,1,14.48,1400,2,12.46,100,1,14.49,100,1,12.43,700,1,14.53,100,1,ARL,347023197
2025-07-17T16:19:52.000639640Z,2025-07-17T16:19:52.000474403Z,160,2,1108,A,A,10,13.40,0,0,13.40,23,1,13.11,100,1,13.44,15,1,13.03,2,1,13.45,100,1,12.98,200,2,13.72,100,1,12.86,100,1,13.86,2,1,12.73,100,1,14.05,100,1,12.71,100,1,14.35,200,2,12.50,700,1,14.40,100,1,12.46,100,1,14.48,1400,2,12.43,700,1,14.49,100,1,ARL,347396369
2025-07-17T16:19:52.002454838Z,2025-07-17T16:19:52.002289289Z,160,2,1108,C,A,10,13.40,0,0,13.40,23,1,13.11,100,1,13.44,15,1,13.03,2,1,13.45,100,1,12.98,200,2,13.72,100,1,12.86,100,1,13.86,2,1,12.73,100,1,14.05,100,1,12.71,100,1,14.35,200,2,12.50,700,1,14.40,100,1,12.46,100,1,14.48,1400,2,12.43,700,1,14.49,100,1,ARL,347022865
2025-07-17T16:19:52.002454838Z,2025-07-17T16:19:52.002289289Z,160,2,1108,A,A,10,13.40,0,0,13.40,23,1,13.11,100,1,13.44,15,1,13.03,2,1,13.45,100,1,12.98,200,2,13.72,100,1,12.86,100,1,13.86,2,1,12.73,100,1,14.05,100,1,12.71,100,1,14.35,200,2,12.50,700,1,14.40,100,1,12.46,100,1,14.48,1400,2,12.43,700,1,14.49,100,1,ARL,347396405
2025-07-17T16:19:52.007405432Z,2025-07-17T16:19:52.007240010Z,160,2,1108,C,A,10,13.40,0,0,13.40,23,1,13.11,100,1,13.44,15,1,13.03,2,1,13.45,100,1,12.98,200,2,13.72,100,1,12.86,100,1,13.86,2,1,12.73,100,1,14.05,100,1,12.71,100,1,14.35,200,2,12.50,700,1,14.40,100,1,12.46,100,1,14.48,1400,2,12.43,700,1,14.49,100,1,ARL,347023021
2025-07-17T16:19:52.007405432Z,2025-07-17T16:19:52.007240010Z,160,2,1108,A,A,10,13.40,0,0,13.40,23,1,13.11,100,1,13.44,15,1,13.03,2,1,13.45,100,1,12.98,200,2,13.72,100,1,12.86,100,1,13.86,2,1,12.73,100,1,14.05,100,1,12.71,100,1,14.35,200,2,12.50,700,1,14.40,200,2,12.46,100,1,14.48,1400,2,12.43,700,1,14.49,100,1,ARL,347396549
2025-07-17T16:19:52.033682506Z,2025-07-17T16:19:52.033517230Z,160,2,1108,A,A,10,13.40,0,0,13.40,23,1,13.11,100,1,13.44,15,1,13.03,2,1,13.45,100,1,12.98,200,2,13.72,100,1,12.86,100,1,13.86,2,1,12.73,100,1,14.05,100,1,12.71,100,1,14.35,200,2,12.50,700,1,14.40,200,2,12.46,100,1,14.48,1400,2,12.43,700,1,14.49,100,1,ARL,347396797
2025-07-17T16:19:52.033694906Z,2025-07-17T16:19:52.033529658Z,160,2,1108,C,A,10,13.40,0,0,13.40,23,1,13.11,100,1,13.44,15,1,13.03,2,1,13.45,100,1,12.98,200,2,13.72,100,1,12.86,100,1,13.86,2,1,12.73,100,1,14.05,100,1,12.71,100,1,14.35,200,2,12.50,700,1,14.40,200,2,12.46,100,1,14.48,1400,2,12.43,700,1,14.49,100,1,ARL,347022705
2025-07-17T16:19:52.051786264Z,2025-07-17T16:19:52.051620731Z,160,2,1108,C,A,10,13.40,0,0,13.40,23,1,13.11,100,1,13.44,15,1,13.03,2,1,13.45,100,1,12.98,200,2,13.72,100,1,12.86,100,1,13.86,2,1,12.73,100,1,14.05,100,1,12.71,100,1,14.35,200,2,12.50,700,1,14.40,200,2,12.46,100,1,14.48,1400,2,12.43,700,1,14.49,100,1,ARL,347052337
2025-07-17T16:19:52.051786264Z,2025-07-17T16:19:52.051620731Z,160,2,1108,A,A,10,13.40,0,0,13.40,23,1,13.11,100,1,13.44,15,1,13.03,2,1,13.45,100,1,12.98,200,2,13.72,100,1,12.86,100,1,13.86,2,1,12.73,100,1,14.05,100,1,12.71,100,1,14.24,100,1,12.50,700,1,14.35,200,2,12.46,100,1,14.40,200,2,12.43,700,1,14.48,1400,2,ARL,347397201
2025-07-17T16:19:52.565796243Z,2025-07-17T16:19:52.565630623Z,160,2,1108,A,A,10,13.40,0,0,13.40,23,1,13.11,100,1,13.44,15,1,13.03,2,1,13.45,100,1,12.98,200,2,13.72,100,1,12.86,100,1,13.86,2,1,12.73,100,1,14.05,100,1,12.71,100,1,14.24,100,1,12.50,700,1,14.25,100,1,12.46,100,1,14.35,200,2,12.43,700,1,14.40,200,2,ARL,347404325
2025-07-17T16:19:52.565810193Z,2025-07-17T16:19:52.565644711Z,160,2,1108,C,A,10,13.40,0,0,13.40,23,1,13.11,100,1,13.44,15,1,13.03,2,1,13.45,100,1,12.98,200,2,13.72,100,1,12.86,100,1,13.86,2,1,12.73,100,1,14.05,100,1,12.71,100,1,14.24,100,1,12.50,700,1,14.25,100,1,12.46,100,1,14.35,200,2,12.43,700,1,14.40,200,2,ARL,347027121
2025-07-17T16:19:52.662889593Z,2025-07-17T16:19:52.662723196Z,160,2,1108,A,A,10,13.40,0,0,13.40,23,1,13.11,100,1,13.44,15,1,13.03,2,1,13.45,100,1,12.98,200,2,13.72,100,1,12.86,100,1,13.86,2,1,12.73,100,1,13.98,100,1,12.71,100,1,14.05,100,1,12.50,700,1,14.24,100,1,12.46,100,1,14.25,100,1,12.43,700,1,14.35,200,2,ARL,347406169
2025-07-17T16:19:52.662889593Z,2025-07-17T16:19:52.662723667Z,160,2,1108,C,A,10,13.40,0,0,13.40,23,1,13.11,100,1,13.44,15,1,13.03,2,1,13.45,100,1,12.98,200,2,13.72,100,1,12.86,100,1,13.86,2,1,12.73,100,1,13.98,100,1,12.71,100,1,14.05,100,1,12.50,700,1,14.24,100,1,12.46,100,1,14.25,100,1,12.43,700,1,14.35,200,2,ARL,347025333
2025-07-17T16:19:53.670698618Z,2025-07-17T16:19:53.670533326Z,160,2,1108,C,A,10,13.40,0,0,13.40,23,1,13.11,100,1,13.44,15,1,13.03,2,1,13.72,100,1,12.98,200,2,13.86,2,1,12.86,100,1,13.98,100,1,12.73,100,1,14.05,100,1,12.71,100,1,14.24,100,1,12.50,700,1,14.25,100,1,12.46,100,1,14.35,200,2,12.43,700,1,14.40,200,2,ARL,347396033
2025-07-17T16:19:53.671091071Z,2025-07-17T16:19:53.670925923Z,160,2,1108,A,A,10,13.40,0,0,13.40,23,1,13.11,100,1,13.44,15,1,13.03,2,1,13.72,100,1,12.98,200,2,13.86,2,1,12.86,100,1,13.98,100,1,12.73,100,1,14.05,100,1,12.71,100,1,14.24,100,1,12.50,700,1,14.25,100,1,12.46,100,1,14.35,200,2,12.43,700,1,14.40,200,2,ARL,347422209
2025-07-17T16:19:53.671121526Z,2025-07-17T16:19:53.670956346Z,160,2,1108,C,A,10,13.40,0,0,13.40,23,1,13.11,100,1,13.44,15,1,13.03,2,1,13.72,100,1,12.98,200,2,13.86,2,1,12.86,100,1,13.98,100,1,12.73,100,1,14.05,100,1,12.71,100,1,14.24,100,1,12.50,700,1,14.25,100,1,12.46,100,1,14.35,200,2,12.43,700,1,14.40,200,2,ARL,347396797
2025-07-17T16:19:53.671439851Z,2025-07-17T16:19:53.671274370Z,160,2,1108,C,A,10,13.40,0,0,13.40,23,1,13.11,100,1,13.44,15,1,13.03,2,1,13.72,100,1,12.98,200,2,13.86,2,1,12.86,100,1,13.98,100,1,12.73,100,1,14.05,100,1,12.71,100,1,14.24,100,1,12.50,700,1,14.25,100,1,12.46,100,1,14.35,200,2,12.43,700,1,14.40,200,2,ARL,347396065
2025-07-17T16:19:53.671439851Z,2025-07-17T16:19:53.671274370Z,160,2,1108,A,A,10,13.40,0,0,13.40,23,1,13.11,100,1,13.44,15,1,13.03,2,1,13.72,100,1,12.98,200,2,13.86,2,1,12.86,100,1,13.98,100,1,12.73,100,1,14.05,100,1,12.71,100,1,14.24,100,1,12.50,700,1,14.25,100,1,12.46,100,1,14.35,200,2,12.43,700,1,14.40,200,2,ARL,347422221
2025-07-17T16:19:53.671446392Z,2025-07-17T16:19:53.671281229Z,160,2,1108,C,A,10,13.40,0,0,13.40,23,1,13.11,100,1,13.44,15,1,13.03,2,1,13.72,100,1,12.98,200,2,13.86,2,1,12.86,100,1,13.98,100,1,12.73,100,1,14.24,100,1,12.71,100,1,14.25,100,1,12.50,700,1,14.35,200,2,12.46,100,1,14.40,200,2,12.43,700,1,14.48,1400,2,ARL,347396069
2025-07-17T16:19:53.671794970Z,2025-07-17T16:19:53.671629711Z,160,2,1108,A,A,10,13.40,0,0,13.40,23,1,13.11,100,1,13.44,15,1,13.03,2,1,13.72,100,1,12.98,200,2,13.86,2,1,12.86,100,1,13.98,100,1,12.73,100,1,14.24,100,1,12.71,100,1,14.25,100,1,12.50,700,1,14.33,100,1,12.46,100,1,14.35,200,2,12.43,700,1,14.40,200,2,ARL,347422225
2025-07-17T16:19:53.672102714Z,2025-07-17T16:19:53.671937159Z,160,2,1108,C,A,10,13.40,0,0,13.40,23,1,13.11,100,1,13.44,15,1,13.03,2,1,13.72,100,1,12.98,200,2,13.86,2,1,12.86,100,1,13.98,100,1,12.73,100,1,14.24,100,1,12.71,100,1,14.25,100,1,12.50,700,1,14.33,100,1,12.46,100,1,14.35,200,2,12.43,700,1,14.40,200,2,ARL,347396073
2025-07-17T16:19:53.672102714Z,2025-07-17T16:19:53.671937159Z,160,2,1108,A,A,10,13.40,0,0,13.40,23,1,13.11,100,1,13.44,15,1,13.03,2,1,13.72,100,1,12.98,200,2,13.86,2,1,12.86,100,1,13.98,100,1,12.73,100,1,14.24,100,1,12.71,100,1,14.25,100,1,12.50,700,1,14.33,100,1,12.46,100,1,14.35,200,2,12.43,700,1,14.40,200,2,ARL,347422237
2025-07-17T16:19:53.672212827Z,2025-07-17T16:19:53.672047366Z,160,2,1108,C,A,10,13.40,0,0,13.40,23,1,13.11,100,1,13.44,15,1,13.03,2,1,13.72,100,1,12.98,200,2,13.86,2,1,12.86,100,1,13.98,100,1,12.73,100,1,14.24,100,1,12.71,100,1,14.25,100,1,12.50,700,1,14.33,100,1,12.46,100,1,14.35,200,2,12.43,700,1,14.40,200,2,ARL,347396129
2025-07-17T16:19:53.672212827Z,2025-07-17T16:19:53.672047366Z,160,2,1108,A,A,10,13.40,0,0,13.40,23,1,13.11,100,1,13.44,15,1,13.03,2,1,13.72,100,1,12.98,200,2,13.86,2,1,12.86,100,1,13.98,100,1,12.73,100,1,14.24,100,1,12.71,100,1,14.25,100,1,12.50,700,1,14.33,100,1,12.46,100,1,14.35,200,2,12.43,700,1,14.40,200,2,ARL,347422241
2025-07-17T16:19:53.673048826Z,2025-07-17T16:19:53.672883433Z,160,2,1108,C,A,10,13.40,0,0,13.40,23,1,13.11,100,1,13.44,15,1,13.03,2,1,13.72,100,1,12.98,200,2,13.86,2,1,12.86,100,1,13.98,100,1,12.73,100,1,14.24,100,1,12.71,100,1,14.25,100,1,12.50,700,1,14.33,100,1,12.46,100,1,14.35,200,2,12.43,700,1,14.40,100,1,ARL,347396085
2025-07-17T16:19:53.673048826Z,2025-07-17T16:19:53.672883433Z,160,2,1108,A,A,10,13.40,0,0,13.40,23,1,13.11,100,1,13.44,15,1,13.03,2,1,13.72,100,1,12.98,200,2,13.86,2,1,12.86,100,1,13.98,100,1,12.73,100,1,14.24,100,1,12.71,100,1,14.25,100,1,12.50,700,1,14.33,100,1,12.46,100,1,14.35,200,2,12.43,700,1,14.40,100,1,ARL,347422245
2025-07-17T16:19:53.673442999Z,2025-07-17T16:19:53.673277621Z,160,2,1108,C,A,10,13.40,0,0,13.40,23,1,13.11,100,1,13.44,15,1,13.03,2,1,13.72,100,1,12.98,200,2,13.86,2,1,12.86,100,1,13.98,100,1,12.73,100,1,14.25,100,1,12.71,100,1,14.33,100,1,12.50,700,1,14.35,200,2,12.46,100,1,14.40,100,1,12.43,700,1,14.48,1400,2,ARL,347397201
2025-07-17T16:19:53.673563265Z,2025-07-17T16:19:53.673398019Z,160,2,1108,A,A,10,13.40,0,0,13.40,23,1,13.11,100,1,13.44,15,1,13.03,2,1,13.72,100,1,12.98,200,2,13.86,2,1,12.86,100,1,13.98,100,1,12.73,100,1,14.25,100,1,12.71,100,1,14.33,100,1,12.50,700,1,14.35,200,2,12.46,100,1,14.40,100,1,12.43,700,1,14.48,1400,2,ARL,347422249
2025-07-17T16:19:53.673762180Z,2025-07-17T16:19:53.673596490Z,160,2,1108,C,A,10,13.40,0,0,13.40,23,1,13.11,100,1,13.44,15,1,13.03,2,1,13.72,100,1,12.98,200,2,13.86,2,1,12.86,100,1,13.98,100,1,12.73,100,1,14.25,100,1,12.71,100,1,14.33,100,1,12.50,700,1,14.35,200,2,12.46,100,1,14.40,100,1,12.43,700,1,14.48,1400,2,ARL,347396125
2025-07-17T16:19:53.673762180Z,2025-07-17T16:19:53.673596490Z,160,2,1108,A,A,10,13.40,0,0,13.40,23,1,13.11,100,1,13.44,15,1,13.03,2,1,13.72,100,1,12.98,200,2,13.86,2,1,12.86,100,1,13.98,100,1,12.73,100,1,14.25,100,1,12.71,100,1,14.33,100,1,12.50,700,1,14.35,200,2,12.46,100,1,14.40,100,1,12.43,700,1,14.48,1400,2,ARL,347422253
2025-07-17T16:19:53.675414447Z,2025-07-17T16:19:53.675249213Z,160,2,1108,C,A,10,13.40,0,0,13.40,23,1,13.11,100,1,13.44,15,1,13.03,2,1,13.86,2,1,12.98,200,2,13.98,100,1,12.86,100,1,14.25,100,1,12.73,100,1,14.33,100,1,12.71,100,1,14.35,200,2,12.50,700,1,14.40,100,1,12.46,100,1,14.48,1400,2,12.43,700,1,14.51,100,1,ARL,347396369
2025-07-17T16:19:53.675466833Z,2025-07-17T16:19:53.675301684Z,160,2,1108,A,A,10,13.40,0,0,13.40,23,1,13.11,100,1,13.44,15,1,13.03,2,1,13.86,2,1,12.98,200,2,13.98,100,1,12.86,100,1,13.99,100,1,12.73,100,1,14.25,100,1,12.71,100,1,14.33,100,1,12.50,700,1,14.35,200,2,12.46,100,1,14.40,100,1,12.43,700,1,14.48,1400,2,ARL,347422265
2025-07-17T16:19:53.675513622Z,2025-07-17T16:19:53.675348484Z,160,2,1108,A,A,10,13.40,0,0,13.40,23,1,13.11,100,1,13.44,15,1,13.03,2,1,13.86,2,1,12.98,200,2,13.98,100,1,12.86,100,1,13.99,100,1,12.73,100,1,14.25,100,1,12.71,100,1,14.33,100,1,12.50,700,1,14.35,200,2,12.46,100,1,14.40,100,1,12.43,700,1,14.48,1400,2,ARL,347422273
2025-07-17T16:19:53.675525392Z,2025-07-17T16:19:53.675360245Z,160,2,1108,C,A,10,13.40,0,0,13.40,23,1,13.11,100,1,13.44,15,1,13.03,2,1,13.86,2,1,12.98,200,2,13.98,100,1,12.86,100,1,13.99,100,1,12.73,100,1,14.25,100,1,12.71,100,1,14.33,100,1,12.50,700,1,14.35,200,2,12.46,100,1,14.40,100,1,12.43,700,1,14.48,1400,2,ARL,347422209
2025-07-17T16:19:53.676268880Z,2025-07-17T16:19:53.676103642Z,160,2,1108,C,A,10,13.40,0,0,13.40,23,1,13.11,100,1,13.44,15,1,13.03,2,1,13.86,2,1,12.98,200,2,13.98,100,1,12.86,100,1,13.99,100,1,12.73,100,1,14.25,100,1,12.71,100,1,14.33,100,1,12.50,700,1,14.35,200,2,12.46,100,1,14.40,100,1,12.43,700,1,14.48,1400,2,ARL,347422241
2025-07-17T16:19:53.676268880Z,2025-07-17T16:19:53.676103642Z,160,2,1108,A,A,10,13.40,0,0,13.40,23,1,13.11,100,1,13.44,15,1,13.03,2,1,13.86,2,1,12.98,200,2,13.98,100,1,12.86,100,1,13.99,100,1,12.73,100,1,14.25,100,1,12.71,100,1,14.33,100,1,12.50,700,1,14.35,200,2,12.46,100,1,14.40,100,1,12.43,700,1,14.48,1400,2,ARL,347422301
2025-07-17T16:19:53.677094265Z,2025-07-17T16:19:53.676928854Z,160,2,1108,C,A,10,13.40,0,0,13.40,23,1,13.11,100,1,13.44,15,1,13.03,2,1,13.86,2,1,12.98,200,2,13.98,100,1,12.86,100,1,13.99,100,1,12.73,100,1,14.25,100,1,12.71,100,1,14.33,100,1,12.50,700,1,14.35,200,2,12.46,100,1,14.40,100,1,12.43,700,1,14.48,1400,2,ARL,347422245
2025-07-17T16:19:53.677094265Z,2025-07-17T16:19:53.676928854Z,160,2,1108,A,A,10,13.40,0,0,13.40,23,1,13.11,100,1,13.44,15,1,13.03,2,1,13.86,2,1,12.98,200,2,13.98,100,1,12.86,100,1,13.99,100,1,12.73,100,1,14.25,100,1,12.71,100,1,14.33,100,1,12.50,700,1,14.35,200,2,12.46,100,1,14.40,100,1,12.43,700,1,14.48,1400,2,ARL,347422321
2025-07-17T16:19:53.677815834Z,2025-07-17T16:19:53.677650753Z,160,2,1108,C,A,10,13.40,0,0,13.40,23,1,13.11,100,1,13.44,15,1,13.03,2,1,13.86,2,1,12.98,200,2,13.98,100,1,12.86,100,1,13.99,100,1,12.73,100,1,14.25,100,1,12.71,100,1,14.33,100,1,12.50,700,1,14.35,200,2,12.46,100,1,14.40,100,1,12.43,700,1,14.48,1400,2,ARL,347422253
2025-07-17T16:19:53.677815834Z,2025-07-17T16:19:53.677650753Z,160,2,1108,A,A,10,13.40,0,0,13.40,23,1,13.11,100,1,13.44,15,1,13.03,2,1,13.86,2,1,12.98,200,2,13.98,100,1,12.86,100,1,13.99,100,1,12.73,100,1,14.25,100,1,12.71,100,1,14.33,100,1,12.50,700,1,14.35,200,2,12.46,100,1,14.40,100,1,12.43,700,1,14.48,1400,2,ARL,347422329
2025-07-17T16:19:53.679633024Z,2025-07-17T16:19:53.679468070Z,160,2,1108,C,A,10,13.40,0,0,13.40,23,1,13.11,100,1,13.44,15,1,13.03,2,1,13.86,2,1,12.98,200,2,13.98,100,1,12.86,100,1,14.25,100,1,12.73,100,1,14.33,100,1,12.71,100,1,14.35,200,2,12.50,700,1,14.40,100,1,12.46,100,1,14.48,1400,2,12.43,700,1,14.51,100,1,ARL,347422265
2025-07-17T16:19:53.679682575Z,2025-07-17T16:19:53.679517110Z,160,2,1108,A,A,10,13.40,0,0,13.40,23,1,13.11,100,1,13.44,15,1,13.03,2,1,13.86,2,1,12.98,200,2,13.98,100,1,12.86,100,1,14.22,100,1,12.73,100,1,14.25,100,1,12.71,100,1,14.33,100,1,12.50,700,1,14.35,200,2,12.46,100,1,14.40,100,1,12.43,700,1,14.48,1400,2,ARL,347422365
2025-07-17T16:19:53.693584804Z,2025-07-17T16:19:53.693419327Z,160,2,1108,C,A,10,13.40,0,0,13.40,23,1,13.11,100,1,13.44,15,1,13.03,2,1,13.86,2,1,12.98,200,2,13.98,100,1,12.86,100,1,14.22,100,1,12.73,100,1,14.25,100,1,12.71,100,1,14.33,100,1,12.50,700,1,14.35,200,2,12.46,100,1,14.40,100,1,12.43,700,1,14.48,1400,2,ARL,347396405
2025-07-17T16:19:53.693584804Z,2025-07-17T16:19:53.693419327Z,160,2,1108,A,A,10,13.40,0,0,13.40,23,1,13.11,100,1,13.44,15,1,13.03,2,1,13.86,2,1,12.98,200,2,13.98,100,1,12.86,100,1,14.22,100,1,12.73,100,1,14.25,100,1,12.71,100,1,14.33,100,1,12.50,700,1,14.35,200,2,12.46,100,1,14.40,100,1,12.43,700,1,14.48,1400,2,ARL,347422849
2025-07-17T16:19:53.718084751Z,2025-07-17T16:19:53.717918994Z,160,2,1108,C,A,10,13.40,0,0,13.40,23,1,13.11,100,1,13.44,15,1,13.03,2,1,13.86,2,1,12.98,200,2,13.98,100,1,12.86,100,1,14.22,100,1,12.73,100,1,14.25,100,1,12.71,100,1,14.33,100,1,12.50,700,1,14.35,200,2,12.46,100,1,14.48,1400,2,12.43,700,1,14.51,100,1,ARL,347396549
2025-07-17T16:19:53.718084751Z,2025-07-17T16:19:53.717918994Z,160,2,1108,A,A,10,13.40,0,0,13.40,23,1,13.11,100,1,13.44,15,1,13.03,2,1,13.86,2,1,12.98,200,2,13.98,100,1,12.86,100,1,14.22,100,1,12.73,100,1,14.25,100,1,12.71,100,1,14.33,100,1,12.50,700,1,14.35,200,2,12.46,100,1,14.48,1400,2,12.43,700,1,14.51,100,1,ARL,347425145
2025-07-17T16:19:53.721565807Z,2025-07-17T16:19:53.721400029Z,160,2,1108,C,A,10,13.40,0,0,13.40,23,1,13.11,100,1,13.44,15,1,13.03,2,1,13.86,2,1,12.98,200,2,13.98,100,1,12.86,100,1,14.22,100,1,12.73,100,1,14.25,100,1,12.71,100,1,14.33,100,1,12.50,700,1,14.35,200,2,12.46,100,1,14.48,1400,2,12.43,700,1,14.51,100,1,ARL,347422221
2025-07-17T16:19:53.721565807Z,2025-07-17T16:19:53.721400029Z,160,2,1108,A,A,10,13.40,0,0,13.40,23,1,13.11,100,1,13.44,15,1,13.03,2,1,13.86,2,1,12.98,200,2,13.98,100,1,12.86,100,1,14.22,100,1,12.73,100,1,14.25,100,1,12.71,100,1,14.33,100,1,12.50,700,1,14.35,200,2,12.46,100,1,14.48,1400,2,12.43,700,1,14.51,100,1,ARL,347426113
2025-07-17T16:19:54.211864515Z,2025-07-17T16:19:54.211699263Z,160,2,1108,A,A,10,13.40,0,0,13.40,23,1,13.11,100,1,13.44,15,1,13.03,2,1,13.86,2,1,12.98,200,2,13.98,100,1,12.86,100,1,14.22,100,1,12.73,100,1,14.25,100,1,12.71,100,1,14.33,100,1,12.50,700,1,14.35,200,2,12.46,100,1,14.48,1400,2,12.43,700,1,14.51,100,1,ARL,347437117
2025-07-17T16:19:54.211876077Z,2025-07-17T16:19:54.211710788Z,160,2,1108,C,A,10,13.40,0,0,13.40,23,1,13.11,100,1,13.44,15,1,13.03,2,1,13.86,2,1,12.98,200,2,13.98,100,1,12.86,100,1,14.22,100,1,12.73,100,1,14.33,100,1,12.71,100,1,14.35,200,2,12.50,700,1,14.48,1400,2,12.46,100,1,14.51,100,1,12.43,700,1,14.54,700,1,ARL,347404325
2025-07-17T16:19:54.248985468Z,2025-07-17T16:19:54.248820201Z,160,2,1108,C,A,10,13.40,0,0,13.40,23,1,13.11,100,1,13.44,15,1,13.03,2,1,13.86,2,1,12.98,200,2,13.98,100,1,12.86,100,1,14.22,100,1,12.73,100,1,14.35,200,2,12.71,100,1,14.48,1400,2,12.50,700,1,14.51,100,1,12.46,100,1,14.54,700,1,12.43,700,1,14.68,700,1,ARL,347422225
2025-07-17T16:19:54.249335716Z,2025-07-17T16:19:54.249170165Z,160,2,1108,A,A,10,13.40,0,0,13.40,23,1,13.11,100,1,13.44,15,1,13.03,2,1,13.86,2,1,12.98,200,2,13.98,100,1,12.86,100,1,14.22,100,1,12.73,100,1,14.35,200,2,12.71,100,1,14.48,1400,2,12.50,700,1,14.51,100,1,12.46,100,1,14.54,700,1,12.43,700,1,14.60,100,1,ARL,347437857
2025-07-17T16:19:54.601852935Z,2025-07-17T16:19:54.601687713Z,160,2,1108,C,A,10,13.40,0,0,13.40,23,1,13.11,100,1,13.44,15,1,13.03,2,1,13.86,2,1,12.98,200,2,14.22,100,1,12.86,100,1,14.35,200,2,12.73,100,1,14.48,1400,2,12.71,100,1,14.51,100,1,12.50,700,1,14.54,700,1,12.46,100,1,14.60,100,1,12.43,700,1,14.68,700,1,ARL,347406169
2025-07-17T16:19:54.601853940Z,2025-07-17T16:19:54.601688695Z,160,2,1108,A,A,10,13.40,0,0,13.40,23,1,13.11,100,1,13.44,15,1,13.03,2,1,13.86,2,1,12.98,200,2,14.22,100,1,12.86,100,1,14.35,200,2,12.73,100,1,14.48,1400,2,12.71,100,1,14.51,100,1,12.50,700,1,14.53,100,1,12.46,100,1,14.54,700,1,12.43,700,1,14.60,100,1,ARL,347443097
2025-07-17T16:19:54.677250454Z,2025-07-17T16:19:54.677084975Z,160,2,1108,C,A,10,13.40,0,0,13.40,23,1,13.11,100,1,13.44,15,1,13.03,2,1,13.86,2,1,12.98,200,2,14.22,100,1,12.86,100,1,14.35,200,2,12.73,100,1,14.48,1400,2,12.71,100,1,14.53,100,1,12.50,700,1,14.54,700,1,12.46,100,1,14.60,100,1,12.43,700,1,14.68,700,1,ARL,347422249
2025-07-17T16:19:54.677250454Z,2025-07-17T16:19:54.677084975Z,160,2,1108,A,A,10,13.40,0,0,13.40,23,1,13.11,100,1,13.44,15,1,13.03,2,1,13.86,2,1,12.98,200,2,14.22,100,1,12.86,100,1,14.35,200,2,12.73,100,1,14.48,1400,2,12.71,100,1,14.53,100,1,12.50,700,1,14.54,700,1,12.46,100,1,14.60,100,1,12.43,700,1,14.68,700,1,ARL,347444385
2025-07-17T16:19:54.919087937Z,2025-07-17T16:19:54.918922624Z,160,2,1108,A,A,10,13.40,0,0,13.40,23,1,13.11,100,1,13.44,15,1,13.03,2,1,13.86,2,1,12.98,200,2,13.87,100,1,12.86,100,1,14.22,100,1,12.73,100,1,14.35,200,2,12.71,100,1,14.48,1400,2,12.50,700,1,14.53,100,1,12.46,100,1,14.54,700,1,12.43,700,1,14.60,100,1,ARL,347449521
2025-07-17T16:19:54.919821816Z,2025-07-17T16:19:54.919656438Z,160,2,1108,C,A,10,13.40,0,0,13.40,23,1,13.11,100,1,13.44,15,1,13.03,2,1,13.86,2,1,12.98,200,2,13.87,100,1,12.86,100,1,14.22,100,1,12.73,100,1,14.35,200,2,12.71,100,1,14.48,1400,2,12.50,700,1,14.53,100,1,12.46,100,1,14.54,700,1,12.43,700,1,14.60,100,1,ARL,347426113
2025-07-17T16:19:54.919821816Z,2025-07-17T16:19:54.919656438Z,160,2,1108,A,A,10,13.40,0,0,13.40,23,1,13.11,100,1,13.44,15,1,13.03,2,1,13.86,2,1,12.98,200,2,13.87,100,1,12.86,100,1,14.22,100,1,12.73,100,1,14.35,200,2,12.71,100,1,14.48,1400,2,12.50,700,1,14.53,100,1,12.46,100,1,14.54,700,1,12.43,700,1,14.60,100,1,ARL,347449549
2025-07-17T16:19:54.942941458Z,2025-07-17T16:19:54.942776198Z,160,2,1108,C,A,10,13.40,0,0,13.40,23,1,13.11,100,1,13.44,15,1,13.03,2,1,13.86,2,1,12.98,200,2,13.87,100,1,12.86,100,1,14.35,200,2,12.73,100,1,14.48,1400,2,12.71,100,1,14.53,100,1,12.50,700,1,14.54,700,1,12.46,100,1,14.60,100,1,12.43,700,1,14.68,700,1,ARL,347422365
2025-07-17T16:19:54.942998015Z,2025-07-17T16:19:54.942832705Z,160,2,1108,A,A,10,13.40,0,0,13.40,23,1,13.11,100,1,13.44,15,1,13.03,2,1,13.86,2,1,12.98,200,2,13.87,100,1,12.86,100,1,14.15,100,1,12.73,100,1,14.35,200,2,12.71,100,1,14.48,1400,2,12.50,700,1,14.53,100,1,12.46,100,1,14.54,700,1,12.43,700,1,14.60,100,1,ARL,347449893
2025-07-17T16:20:02.838461207Z,2025-07-17T16:20:02.838295810Z,160,2,1108,A,A,10,13.40,0,0,13.40,38,2,13.11,100,1,13.44,15,1,13.03,2,1,13.86,2,1,12.98,200,2,13.87,100,1,12.86,100,1,14.15,100,1,12.73,100,1,14.35,200,2,12.71,100,1,14.48,1400,2,12.50,700,1,14.53,100,1,12.46,100,1,14.54,700,1,12.43,700,1,14.60,100,1,ARL,347592441
2025-07-17T16:20:03.544957156Z,2025-07-17T16:20:03.544791773Z,160,2,1108,C,A,10,13.40,0,0,13.40,38,2,13.11,100,1,13.44,15,1,13.03,2,1,13.86,2,1,12.98,200,2,14.15,100,1,12.86,100,1,14.35,200,2,12.73,100,1,14.48,1400,2,12.71,100,1,14.53,100,1,12.50,700,1,14.54,700,1,12.46,100,1,14.60,100,1,12.43,700,1,14.68,700,1,ARL,347449521
2025-07-17T16:20:03.544957156Z,2025-07-17T16:20:03.544791773Z,160,2,1108,A,A,10,13.40,0,0,13.40,38,2,13.11,100,1,13.44,15,1,13.03,2,1,13.45,100,1,12.98,200,2,13.86,2,1,12.86,100,1,14.15,100,1,12.73,100,1,14.35,200,2,12.71,100,1,14.48,1400,2,12.50,700,1,14.53,100,1,12.46,100,1,14.54,700,1,12.43,700,1,14.60,100,1,ARL,347605041
2025-07-17T16:20:03.545692221Z,2025-07-17T16:20:03.545526427Z,160,2,1108,C,A,10,13.40,0,0,13.40,38,2,13.11,100,1,13.44,15,1,13.03,2,1,13.45,100,1,12.98,200,2,13.86,2,1,12.86,100,1,14.15,100,1,12.73,100,1,14.35,200,2,12.71,100,1,14.48,1400,2,12.50,700,1,14.53,100,1,12.46,100,1,14.54,700,1,12.43,700,1,14.60,100,1,ARL,347449549
2025-07-17T16:20:03.545692221Z,2025-07-17T16:20:03.545526427Z,160,2,1108,A,A,10,13.40,0,0,13.40,38,2,13.11,100,1,13.44,15,1,13.03,2,1,13.45,100,1,12.98,200,2,13.86,2,1,12.86,100,1,14.15,100,1,12.73,100,1,14.35,200,2,12.71,100,1,14.48,1400,2,12.50,700,1,14.49,100,1,12.46,100,1,14.53,100,1,12.43,700,1,14.54,700,1,ARL,347605073
2025-07-17T16:20:03.545693843Z,2025-07-17T16:20:03.545528318Z,160,2,1108,C,A,10,13.40,0,0,13.40,38,2,13.11,100,1,13.44,15,1,13.03,2,1,13.45,100,1,12.98,200,2,13.86,2,1,12.86,100,1,14.15,100,1,12.73,100,1,14.35,200,2,12.71,100,1,14.48,1400,2,12.50,700,1,14.49,100,1,12.46,100,1,14.53,100,1,12.43,700,1,14.54,700,1,ARL,347437857
2025-07-17T16:20:03.546047231Z,2025-07-17T16:20:03.545881983Z,160,2,1108,A,A,10,13.40,0,0,13.40,38,2,13.11,100,1,13.44,15,1,13.03,2,1,13.45,100,1,12.98,200,2,13.86,2,1,12.86,100,1,14.05,100,1,12.73,100,1,14.15,100,1,12.71,100,1,14.35,200,2,12.50,700,1,14.48,1400,2,12.46,100,1,14.49,100,1,12.43,700,1,14.53,100,1,ARL,347605081
2025-07-17T16:20:03.546381253Z,2025-07-17T16:20:03.546215424Z,160,2,1108,C,A,10,13.40,0,0,13.40,38,2,13.11,100,1,13.44,15,1,13.03,2,1,13.45,100,1,12.98,200,2,13.86,2,1,12.86,100,1,14.05,100,1,12.73,100,1,14.15,100,1,12.71,100,1,14.35,200,2,12.50,700,1,14.48,1400,2,12.46,100,1,14.49,100,1,12.43,700,1,14.53,100,1,ARL,347422237
2025-07-17T16:20:03.546381253Z,2025-07-17T16:20:03.546215424Z,160,2,1108,A,A,10,13.40,0,0,13.40,38,2,13.11,100,1,13.44,15,1,13.03,2,1,13.45,100,1,12.98,200,2,13.86,2,1,12.86,100,1,14.05,100,1,12.73,100,1,14.15,100,1,12.71,100,1,14.35,200,2,12.50,700,1,14.48,1400,2,12.46,100,1,14.49,100,1,12.43,700,1,14.53,100,1,ARL,347605085
2025-07-17T16:20:03.547098908Z,2025-07-17T16:20:03.546933285Z,160,2,1108,C,A,10,13.40,0,0,13.40,38,2,13.11,100,1,13.44,15,1,13.03,2,1,13.45,100,1,12.98,200,2,13.86,2,1,12.86,100,1,14.05,100,1,12.73,100,1,14.15,100,1,12.71,100,1,14.35,200,2,12.50,700,1,14.48,1400,2,12.46,100,1,14.49,100,1,12.43,700,1,14.53,100,1,ARL,347422329
2025-07-17T16:20:03.547098908Z,2025-07-17T16:20:03.546933285Z,160,2,1108,A,A,10,13.40,0,0,13.40,38,2,13.11,100,1,13.44,15,1,13.03,2,1,13.45,100,1,12.98,200,2,13.86,2,1,12.86,100,1,14.05,100,1,12.73,100,1,14.15,100,1,12.71,100,1,14.35,200,2,12.50,700,1,14.48,1400,2,12.46,100,1,14.49,100,1,12.43,700,1,14.53,100,1,ARL,347605101
2025-07-17T16:20:03.547495212Z,2025-07-17T16:20:03.547329771Z,160,2,1108,C,A,10,13.40,0,0,13.40,38,2,13.11,100,1,13.44,15,1,13.03,2,1,13.45,100,1,12.98,200,2,13.86,2,1,12.86,100,1,14.05,100,1,12.73,100,1,14.15,100,1,12.71,100,1,14.35,200,2,12.50,700,1,14.48,1400,2,12.46,100,1,14.49,100,1,12.43,700,1,14.53,100,1,ARL,347422301
2025-07-17T16:20:03.547495212Z,2025-07-17T16:20:03.547329771Z,160,2,1108,A,A,10,13.40,0,0,13.40,38,2,13.11,100,1,13.44,15,1,13.03,2,1,13.45,100,1,12.98,200,2,13.86,2,1,12.86,100,1,14.05,100,1,12.73,100,1,14.15,100,1,12.71,100,1,14.35,200,2,12.50,700,1,14.48,1400,2,12.46,100,1,14.49,100,1,12.43,700,1,14.53,100,1,ARL,347605105
2025-07-17T16:20:03.547722218Z,2025-07-17T16:20:03.547556902Z,160,2,1108,C,A,10,13.40,0,0,13.40,38,2,13.11,100,1,13.44,15,1,13.03,2,1,13.45,100,1,12.98,200,2,13.86,2,1,12.86,100,1,14.05,100,1,12.73,100,1,14.15,100,1,12.71,100,1,14.35,200,2,12.50,700,1,14.48,1400,2,12.46,100,1,14.49,100,1,12.43,700,1,14.53,100,1,ARL,347422321
2025-07-17T16:20:03.547722218Z,2025-07-17T16:20:03.547556902Z,160,2,1108,A,A,10,13.40,0,0,13.40,38,2,13.11,100,1,13.44,15,1,13.03,2,1,13.45,100,1,12.98,200,2,13.86,2,1,12.86,100,1,14.05,100,1,12.73,100,1,14.15,100,1,12.71,100,1,14.35,200,2,12.50,700,1,14.40,100,1,12.46,100,1,14.48,1400,2,12.43,700,1,14.49,100,1,ARL,347605109
2025-07-17T16:20:03.551397729Z,2025-07-17T16:20:03.551232289Z,160,2,1108,C,A,10,13.40,0,0,13.40,38,2,13.11,100,1,13.44,15,1,13.03,2,1,13.45,100,1,12.98,200,2,13.86,2,1,12.86,100,1,14.05,100,1,12.73,100,1,14.15,100,1,12.71,100,1,14.35,200,2,12.50,700,1,14.40,100,1,12.46,100,1,14.48,1400,2,12.43,700,1,14.49,100,1,ARL,347422849
2025-07-17T16:20:03.551397729Z,2025-07-17T16:20:03.551232289Z,160,2,1108,A,A,10,13.40,0,0,13.40,38,2,13.11,100,1,13.44,15,1,13.03,2,1,13.45,100,1,12.98,200,2,13.86,2,1,12.86,100,1,14.05,100,1,12.73,100,1,14.15,100,1,12.71,100,1,14.35,200,2,12.50,700,1,14.40,100,1,12.46,100,1,14.48,1400,2,12.43,700,1,14.49,100,1,ARL,347605169
2025-07-17T16:20:03.558022065Z,2025-07-17T16:20:03.557856817Z,160,2,1108,C,A,10,13.40,0,0,13.40,38,2,13.11,100,1,13.44,15,1,13.03,2,1,13.45,100,1,12.98,200,2,13.86,2,1,12.86,100,1,14.05,100,1,12.73,100,1,14.35,200,2,12.71,100,1,14.40,100,1,12.50,700,1,14.48,1400,2,12.46,100,1,14.49,100,1,12.43,700,1,14.53,100,1,ARL,347449893
2025-07-17T16:20:03.558074886Z,2025-07-17T16:20:03.557909645Z,160,2,1108,A,A,10,13.40,0,0,13.40,38,2,13.11,100,1,13.44,15,1,13.03,2,1,13.45,100,1,12.98,200,2,13.72,100,1,12.86,100,1,13.86,2,1,12.73,100,1,14.05,100,1,12.71,100,1,14.35,200,2,12.50,700,1,14.40,100,1,12.46,100,1,14.48,1400,2,12.43,700,1,14.49,100,1,ARL,347605397
2025-07-17T16:20:03.569904581Z,2025-07-17T16:20:03.569738711Z,160,2,1108,C,A,10,13.40,0,0,13.40,38,2,13.11,100,1,13.44,15,1,13.03,2,1,13.45,100,1,12.98,200,2,13.72,100,1,12.86,100,1,13.86,2,1,12.73,100,1,14.05,100,1,12.71,100,1,14.35,200,2,12.50,700,1,14.40,100,1,12.46,100,1,14.48,1400,2,12.43,700,1,14.49,100,1,ARL,347425145
2025-07-17T16:20:03.569904581Z,2025-07-17T16:20:03.569738711Z,160,2,1108,A,A,10,13.40,0,0,13.40,38,2,13.11,100,1,13.44,15,1,13.03,2,1,13.45,100,1,12.98,200,2,13.72,100,1,12.86,100,1,13.86,2,1,12.73,100,1,14.05,100,1,12.71,100,1,14.35,200,2,12.50,700,1,14.40,200,2,12.46,100,1,14.48,1400,2,12.43,700,1,14.49,100,1,ARL,347605617
2025-07-17T16:20:03.592801539Z,2025-07-17T16:20:03.592636279Z,160,2,1108,C,A,10,13.40,0,0,13.40,38,2,13.11,100,1,13.44,15,1,13.03,2,1,13.45,100,1,12.98,200,2,13.72,100,1,12.86,100,1,13.86,2,1,12.73,100,1,14.05,100,1,12.71,100,1,14.35,200,2,12.50,700,1,14.40,200,2,12.46,100,1,14.48,1400,2,12.43,700,1,14.49,100,1,ARL,347444385
2025-07-17T16:20:03.592903833Z,2025-07-17T16:20:03.592738507Z,160,2,1108,A,A,10,13.40,0,0,13.40,38,2,13.11,100,1,13.44,15,1,13.03,2,1,13.45,100,1,12.98,200,2,13.72,100,1,12.86,100,1,13.86,2,1,12.73,100,1,14.05,100,1,12.71,100,1,14.24,100,1,12.50,700,1,14.35,200,2,12.46,100,1,14.40,200,2,12.43,700,1,14.48,1400,2,ARL,347605969
2025-07-17T16:20:03.592933652Z,2025-07-17T16:20:03.592768402Z,160,2,1108,A,A,10,13.40,0,0,13.40,38,2,13.11,100,1,13.44,15,1,13.03,2,1,13.45,100,1,12.98,200,2,13.72,100,1,12.86,100,1,13.86,2,1,12.73,100,1,14.05,100,1,12.71,100,1,14.24,100,1,12.50,700,1,14.35,200,2,12.46,100,1,14.40,200,2,12.43,700,1,14.48,1400,2,ARL,347605973
2025-07-17T16:20:03.592946817Z,2025-07-17T16:20:03.592781399Z,160,2,1108,C,A,10,13.40,0,0,13.40,38,2,13.11,100,1,13.44,15,1,13.03,2,1,13.45,100,1,12.98,200,2,13.72,100,1,12.86,100,1,13.86,2,1,12.73,100,1,14.05,100,1,12.71,100,1,14.24,100,1,12.50,700,1,14.35,200,2,12.46,100,1,14.40,200,2,12.43,700,1,14.48,1400,2,ARL,347422273
2025-07-17T16:20:04.069659336Z,2025-07-17T16:20:04.069494130Z,160,2,1108,C,A,10,13.40,0,0,13.40,38,2,13.11,100,1,13.44,15,1,13.03,2,1,13.45,100,1,12.98,200,2,13.72,100,1,12.86,100,1,13.86,2,1,12.73,100,1,14.05,100,1,12.71,100,1,14.24,100,1,12.50,700,1,14.35,200,2,12.46,100,1,14.40,200,2,12.43,700,1,14.48,1400,2,ARL,347443097
2025-07-17T16:20:04.069661713Z,2025-07-17T16:20:04.069496437Z,160,2,1108,A,A,10,13.40,0,0,13.40,38,2,13.11,100,1,13.44,15,1,13.03,2,1,13.45,100,1,12.98,200,2,13.72,100,1,12.86,100,1,13.86,2,1,12.73,100,1,13.98,100,1,12.71,100,1,14.05,100,1,12.50,700,1,14.24,100,1,12.46,100,1,14.35,200,2,12.43,700,1,14.40,200,2,ARL,347613877
2025-07-17T16:20:04.111795639Z,2025-07-17T16:20:04.111630484Z,160,2,1108,A,A,10,13.40,0,0,13.40,38,2,13.11,100,1,13.44,15,1,13.03,2,1,13.45,100,1,12.98,200,2,13.72,100,1,12.86,100,1,13.86,2,1,12.73,100,1,13.98,100,1,12.71,100,1,14.05,100,1,12.50,700,1,14.24,100,1,12.46,100,1,14.25,100,1,12.43,700,1,14.35,200,2,ARL,347615553
2025-07-17T16:20:04.111808972Z,2025-07-17T16:20:04.111643490Z,160,2,1108,C,A,10,13.40,0,0,13.40,38,2,13.11,100,1,13.44,15,1,13.03,2,1,13.45,100,1,12.98,200,2,13.72,100,1,12.86,100,1,13.86,2,1,12.73,100,1,13.98,100,1,12.71,100,1,14.05,100,1,12.50,700,1,14.24,100,1,12.46,100,1,14.25,100,1,12.43,700,1,14.35,200,2,ARL,347437117
2025-07-17T16:20:07.945427285Z,2025-07-17T16:20:07.945262120Z,160,2,1108,C,A,10,13.40,0,0,13.40,38,2,13.11,100,1,13.45,100,1,13.03,2,1,13.72,100,1,12.98,200,2,13.86,2,1,12.86,100,1,13.98,100,1,12.73,100,1,14.05,100,1,12.71,100,1,14.24,100,1,12.50,700,1,14.25,100,1,12.46,100,1,14.35,200,2,12.43,700,1,14.40,200,2,ARL,347377693
2025-07-17T16:20:08.949407416Z,2025-07-17T16:20:08.949241997Z,160,2,1108,A,A,10,13.40,0,0,13.36,15,1,13.11,100,1,13.40,38,2,13.03,2,1,13.45,100,1,12.98,200,2,13.72,100,1,12.86,100,1,13.86,2,1,12.73,100,1,13.98,100,1,12.71,100,1,14.05,100,1,12.50,700,1,14.24,100,1,12.46,100,1,14.25,100,1,12.43,700,1,14.35,200,2,ARL,347710393
2025-07-17T16:20:09.428817232Z,2025-07-17T16:20:09.428650758Z,160,2,1108,A,A,10,13.40,0,0,13.36,15,1,13.11,100,1,13.40,38,2,13.03,2,1,13.45,100,1,12.98,200,2,13.72,100,1,12.86,100,1,13.86,2,1,12.73,100,1,13.98,100,1,12.71,100,1,14.05,100,1,12.50,700,1,14.17,700,1,12.46,100,1,14.24,100,1,12.43,700,1,14.25,100,1,ARL,347717317
2025-07-17T16:20:09.428874375Z,2025-07-17T16:20:09.428709003Z,160,2,1108,C,A,10,13.40,0,0,13.36,15,1,13.11,100,1,13.40,38,2,13.03,2,1,13.45,100,1,12.98,200,2,13.72,100,1,12.86,100,1,13.86,2,1,12.73,100,1,13.98,100,1,12.71,100,1,14.05,100,1,12.50,700,1,14.17,700,1,12.46,100,1,14.24,100,1,12.43,700,1,14.25,100,1,ARL,347023357
2025-07-17T16:20:09.704859787Z,2025-07-17T16:20:09.704693450Z,160,2,1108,C,A,10,13.40,0,0,13.36,15,1,13.11,100,1,13.40,38,2,13.03,2,1,13.45,100,1,12.98,200,2,13.72,100,1,12.86,100,1,13.98,100,1,12.73,100,1,14.05,100,1,12.71,100,1,14.17,700,1,12.50,700,1,14.24,100,1,12.46,100,1,14.25,100,1,12.43,700,1,14.35,200,2,ARL,347396177
2025-07-17T16:20:09.704859787Z,2025-07-17T16:20:09.704693450Z,160,2,1108,A,A,10,13.40,0,0,13.36,15,1,13.11,100,1,13.40,38,2,13.03,2,1,13.45,100,1,12.98,200,2,13.72,100,1,12.86,100,1,13.78,2,1,12.73,100,1,13.98,100,1,12.71,100,1,14.05,100,1,12.50,700,1,14.17,700,1,12.46,100,1,14.24,100,1,12.43,700,1,14.25,100,1,ARL,347722857
2025-07-17T16:20:11.608367693Z,2025-07-17T16:20:11.608202073Z,160,2,1108,C,A,10,13.40,0,0,13.36,15,1,13.11,100,1,13.40,38,2,13.03,2,1,13.45,100,1,12.98,200,2,13.72,100,1,12.86,100,1,13.78,2,1,12.73,100,1,13.98,100,1,12.71,100,1,14.05,100,1,12.50,700,1,14.17,700,1,12.46,100,1,14.24,100,1,12.43,700,1,14.25,100,1,ARL,344593405
2025-07-17T16:20:11.608367693Z,2025-07-17T16:20:11.608202073Z,160,2,1108,A,A,10,13.40,0,0,13.36,15,1,13.11,100,1,13.40,38,2,13.03,2,1,13.45,100,1,12.98,200,2,13.72,100,1,12.86,100,1,13.78,2,1,12.73,100,1,13.98,100,1,12.71,100,1,14.05,100,1,12.50,700,1,14.17,700,1,12.46,100,1,14.24,200,2,12.43,700,1,14.25,100,1,ARL,347760469
2025-07-17T16:20:11.608472767Z,2025-07-17T16:20:11.608307409Z,160,2,1108,C,A,10,13.40,0,0,13.36,15,1,13.11,100,1,13.40,38,2,13.03,2,1,13.45,100,1,12.98,200,2,13.72,100,1,12.86,100,1,13.78,2,1,12.73,100,1,13.98,100,1,12.71,100,1,14.05,100,1,12.50,700,1,14.17,700,1,12.46,100,1,14.24,200,2,12.43,700,1,14.25,100,1,ARL,344593409
2025-07-17T16:20:11.608472767Z,2025-07-17T16:20:11.608307409Z,160,2,1108,A,A,10,13.40,0,0,13.36,15,1,13.11,100,1,13.40,38,2,13.03,2,1,13.45,100,1,12.98,200,2,13.72,100,1,12.86,100,1,13.78,2,1,12.73,100,1,13.98,100,1,12.71,100,1,14.05,100,1,12.50,700,1,14.17,700,1,12.46,100,1,14.24,300,3,12.43,700,1,14.25,100,1,ARL,347760485
2025-07-17T16:20:20.588044932Z,2025-07-17T16:20:20.587879078Z,160,2,1108,C,A,10,13.40,0,0,13.36,15,1,13.11,100,1,13.40,38,2,13.03,2,1,13.45,100,1,12.98,200,2,13.72,100,1,12.86,100,1,13.98,100,1,12.73,100,1,14.05,100,1,12.71,100,1,14.17,700,1,12.50,700,1,14.24,300,3,12.46,100,1,14.25,100,1,12.43,700,1,14.40,200,2,ARL,347722857
2025-07-17T16:20:20.588044932Z,2025-07-17T16:20:20.587879078Z,160,2,1108,A,A,10,13.40,0,0,13.36,15,1,13.11,100,1,13.40,38,2,13.03,2,1,13.45,100,1,12.98,200,2,13.71,2,1,12.86,100,1,13.72,100,1,12.73,100,1,13.98,100,1,12.71,100,1,14.05,100,1,12.50,700,1,14.17,700,1,12.46,100,1,14.24,300,3,12.43,700,1,14.25,100,1,ARL,347935421
2025-07-17T16:20:20.839245229Z,2025-07-17T16:20:20.839080003Z,160,2,1108,C,A,10,13.40,0,0,13.36,15,1,13.11,100,1,13.40,23,1,13.03,2,1,13.45,100,1,12.98,200,2,13.71,2,1,12.86,100,1,13.72,100,1,12.73,100,1,13.98,100,1,12.71,100,1,14.05,100,1,12.50,700,1,14.17,700,1,12.46,100,1,14.24,300,3,12.43,700,1,14.25,100,1,ARL,347592441
2025-07-17T16:20:21.839565900Z,2025-07-17T16:20:21.839400050Z,160,2,1108,A,A,10,13.40,0,0,13.33,15,1,13.11,100,1,13.36,15,1,13.03,2,1,13.40,23,1,12.98,200,2,13.45,100,1,12.86,100,1,13.71,2,1,12.73,100,1,13.72,100,1,12.71,100,1,13.98,100,1,12.50,700,1,14.05,100,1,12.46,100,1,14.17,700,1,12.43,700,1,14.24,300,3,ARL,347961173
2025-07-17T16:20:27.448533855Z,2025-07-17T16:20:27.448368575Z,160,2,1108,C,A,10,13.40,0,0,13.33,15,1,13.11,100,1,13.40,23,1,13.03,2,1,13.45,100,1,12.98,200,2,13.71,2,1,12.86,100,1,13.72,100,1,12.73,100,1,13.98,100,1,12.71,100,1,14.05,100,1,12.50,700,1,14.17,700,1,12.46,100,1,14.24,300,3,12.43,700,1,14.25,100,1,ARL,347710393
2025-07-17T16:20:28.452553412Z,2025-07-17T16:20:28.452388023Z,160,2,1108,A,A,10,13.40,0,0,13.31,15,1,13.11,100,1,13.33,15,1,13.03,2,1,13.40,23,1,12.98,200,2,13.45,100,1,12.86,100,1,13.71,2,1,12.73,100,1,13.72,100,1,12.71,100,1,13.98,100,1,12.50,700,1,14.05,100,1,12.46,100,1,14.17,700,1,12.43,700,1,14.24,300,3,ARL,348099617
2025-07-17T16:20:31.453437816Z,2025-07-17T16:20:31.453272244Z,160,2,1108,C,A,10,13.40,0,0,13.31,15,1,13.11,100,1,13.40,23,1,13.03,2,1,13.45,100,1,12.98,200,2,13.71,2,1,12.86,100,1,13.72,100,1,12.73,100,1,13.98,100,1,12.71,100,1,14.05,100,1,12.50,700,1,14.17,700,1,12.46,100,1,14.24,300,3,12.43,700,1,14.25,100,1,ARL,347961173
2025-07-17T16:20:42.838073701Z,2025-07-17T16:20:42.837908349Z,160,2,1108,A,A,10,13.40,0,0,13.29,15,1,13.11,100,1,13.31,15,1,13.03,2,1,13.40,23,1,12.98,200,2,13.45,100,1,12.86,100,1,13.71,2,1,12.73,100,1,13.72,100,1,12.71,100,1,13.98,100,1,12.50,700,1,14.05,100,1,12.46,100,1,14.17,700,1,12.43,700,1,14.24,300,3,ARL,348428649
2025-07-17T16:20:56.875524789Z,2025-07-17T16:20:56.875359282Z,160,2,1108,C,B,10,13.40,0,0,13.29,15,1,13.11,100,1,13.31,15,1,12.98,200,2,13.40,23,1,12.86,100,1,13.45,100,1,12.73,100,1,13.71,2,1,12.71,100,1,13.72,100,1,12.50,700,1,13.98,100,1,12.46,100,1,14.05,100,1,12.43,700,1,14.17,700,1,12.42,700,1,14.24,300,3,ARL,347220093
2025-07-17T16:20:56.875524789Z,2025-07-17T16:20:56.875359282Z,160,2,1108,A,B,10,13.40,0,0,13.29,15,1,13.11,100,1,13.31,15,1,12.98,200,2,13.40,23,1,12.96,2,1,13.45,100,1,12.86,100,1,13.71,2,1,12.73,100,1,13.72,100,1,12.71,100,1,13.98,100,1,12.50,700,1,14.05,100,1,12.46,100,1,14.17,700,1,12.43,700,1,14.24,300,3,ARL,348838809
2025-07-17T16:21:03.027643943Z,2025-07-17T16:21:03.027478065Z,160,2,1108,C,A,10,13.40,0,0,13.29,15,1,13.11,100,1,13.40,23,1,12.98,200,2,13.45,100,1,12.96,2,1,13.71,2,1,12.86,100,1,13.72,100,1,12.73,100,1,13.98,100,1,12.71,100,1,14.05,100,1,12.50,700,1,14.17,700,1,12.46,100,1,14.24,300,3,12.43,700,1,14.25,100,1,ARL,348099617
2025-07-17T16:21:03.786334915Z,2025-07-17T16:21:03.786169333Z,160,2,1108,C,A,10,13.40,0,0,13.29,15,1,13.11,100,1,13.40,23,1,12.98,200,2,13.45,100,1,12.96,2,1,13.72,100,1,12.86,100,1,13.98,100,1,12.73,100,1,14.05,100,1,12.71,100,1,14.17,700,1,12.50,700,1,14.24,300,3,12.46,100,1,14.25,100,1,12.43,700,1,14.40,200,2,ARL,347935421
2025-07-17T16:21:03.786334915Z,2025-07-17T16:21:03.786169333Z,160,2,1108,A,A,10,13.40,0,0,13.29,15,1,13.11,100,1,13.40,23,1,12.98,200,2,13.45,100,1,12.96,2,1,13.65,2,1,12.86,100,1,13.72,100,1,12.73,100,1,13.98,100,1,12.71,100,1,14.05,100,1,12.50,700,1,14.17,700,1,12.46,100,1,14.24,300,3,12.43,700,1,14.25,100,1,ARL,349094877
2025-07-17T16:21:04.031563260Z,2025-07-17T16:21:04.031397539Z,160,2,1108,A,A,10,13.40,0,0,13.27,15,1,13.11,100,1,13.29,15,1,12.98,200,2,13.40,23,1,12.96,2,1,13.45,100,1,12.86,100,1,13.65,2,1,12.73,100,1,13.72,100,1,12.71,100,1,13.98,100,1,12.50,700,1,14.05,100,1,12.46,100,1,14.17,700,1,12.43,700,1,14.24,300,3,ARL,349100269
2025-07-17T16:21:04.035799229Z,2025-07-17T16:21:04.035632459Z,160,2,1108,T,B,10,13.40,0,0,13.27,15,1,13.27,0,0,13.29,15,1,13.11,100,1,13.40,23,1,12.98,200,2,13.45,100,1,12.96,2,1,13.65,2,1,12.86,100,1,13.72,100,1,12.73,100,1,13.98,100,1,12.71,100,1,14.05,100,1,12.50,700,1,14.17,700,1,12.46,100,1,14.24,300,3,ARL,0
2025-07-17T16:21:04.035799229Z,2025-07-17T16:21:04.035632459Z,160,2,1108,F,A,10,13.40,0,0,13.27,15,1,13.27,0,0,13.29,15,1,13.11,100,1,13.40,23,1,12.98,200,2,13.45,100,1,12.96,2,1,13.65,2,1,12.86,100,1,13.72,100,1,12.73,100,1,13.98,100,1,12.71,100,1,14.05,100,1,12.50,700,1,14.17,700,1,12.46,100,1,14.24,300,3,ARL,349100269
2025-07-17T16:21:04.035799229Z,2025-07-17T16:21:04.035632459Z,160,2,1108,C,A,10,13.40,0,0,13.29,15,1,13.27,0,0,13.40,23,1,13.11,100,1,13.45,100,1,12.98,200,2,13.65,2,1,12.96,2,1,13.72,100,1,12.86,100,1,13.98,100,1,12.73,100,1,14.05,100,1,12.71,100,1,14.17,700,1,12.50,700,1,14.24,300,3,12.46,100,1,14.25,100,1,ARL,349100269
2025-07-17T16:21:04.035825836Z,2025-07-17T16:21:04.035660519Z,160,2,1108,A,B,10,13.40,0,0,13.29,15,1,13.27,0,0,13.40,23,1,13.14,11,1,13.45,100,1,13.11,100,1,13.65,2,1,12.98,200,2,13.72,100,1,12.96,2,1,13.98,100,1,12.86,100,1,14.05,100,1,12.73,100,1,14.17,700,1,12.71,100,1,14.24,300,3,12.50,700,1,14.25,100,1,ARL,349100461
2025-07-17T16:21:05.035171590Z,2025-07-17T16:21:05.035006249Z,160,2,1108,C,B,10,13.40,0,0,13.29,15,1,13.27,0,0,13.40,23,1,13.11,100,1,13.45,100,1,12.98,200,2,13.65,2,1,12.96,2,1,13.72,100,1,12.86,100,1,13.98,100,1,12.73,100,1,14.05,100,1,12.71,100,1,14.17,700,1,12.50,700,1,14.24,300,3,12.46,100,1,14.25,100,1,ARL,349100461
2025-07-17T16:21:13.027776086Z,2025-07-17T16:21:13.027610071Z,160,2,1108,C,A,10,13.40,0,0,13.40,23,1,13.27,0,0,13.45,100,1,13.11,100,1,13.65,2,1,12.98,200,2,13.72,100,1,12.96,2,1,13.98,100,1,12.86,100,1,14.05,100,1,12.73,100,1,14.17,700,1,12.71,100,1,14.24,300,3,12.50,700,1,14.25,100,1,12.46,100,1,14.40,200,2,ARL,348428649
2025-07-17T16:21:13.028208678Z,2025-07-17T16:21:13.028039954Z,160,2,1108,C,A,10,13.40,0,0,13.40,23,1,13.27,0,0,13.65,2,1,13.11,100,1,13.72,100,1,12.98,200,2,13.98,100,1,12.96,2,1,14.05,100,1,12.86,100,1,14.17,700,1,12.73,100,1,14.24,300,3,12.71,100,1,14.25,100,1,12.50,700,1,14.40,200,2,12.46,100,1,14.48,1400,2,ARL,347605041
2025-07-17T16:21:13.028616852Z,2025-07-17T16:21:13.028451265Z,160,2,1108,A,A,10,13.40,0,0,13.40,23,1,13.27,0,0,13.65,2,1,13.11,100,1,13.72,100,1,12.98,200,2,13.98,100,1,12.96,2,1,14.05,100,1,12.86,100,1,14.17,700,1,12.73,100,1,14.24,300,3,12.71,100,1,14.25,100,1,12.50,700,1,14.40,200,2,12.46,100,1,14.48,1400,2,ARL,349364025
2025-07-17T16:21:13.028629760Z,2025-07-17T16:21:13.028464223Z,160,2,1108,C,A,10,13.40,0,0,13.40,23,1,13.27,0,0,13.65,2,1,13.11,100,1,13.72,100,1,12.98,200,2,13.98,100,1,12.96,2,1,14.05,100,1,12.86,100,1,14.17,700,1,12.73,100,1,14.24,300,3,12.71,100,1,14.25,100,1,12.50,700,1,14.40,200,2,12.46,100,1,14.48,1400,2,ARL,347605973
2025-07-17T16:21:13.028929613Z,2025-07-17T16:21:13.028763898Z,160,2,1108,C,A,10,13.40,0,0,13.40,23,1,13.27,0,0,13.65,2,1,13.11,100,1,13.72,100,1,12.98,200,2,13.98,100,1,12.96,2,1,14.05,100,1,12.86,100,1,14.17,700,1,12.73,100,1,14.24,200,2,12.71,100,1,14.25,100,1,12.50,700,1,14.40,200,2,12.46,100,1,14.48,1400,2,ARL,347760485
2025-07-17T16:21:13.028929613Z,2025-07-17T16:21:13.028763898Z,160,2,1108,A,A,10,13.40,0,0,13.40,23,1,13.27,0,0,13.65,2,1,13.11,100,1,13.72,100,1,12.98,200,2,13.98,100,1,12.96,2,1,14.05,100,1,12.86,100,1,14.17,700,1,12.73,100,1,14.24,200,2,12.71,100,1,14.25,100,1,12.50,700,1,14.40,200,2,12.46,100,1,14.48,1400,2,ARL,349364085
2025-07-17T16:21:13.028960654Z,2025-07-17T16:21:13.028792918Z,160,2,1108,C,A,10,13.40,0,0,13.40,23,1,13.27,0,0,13.65,2,1,13.11,100,1,13.72,100,1,12.98,200,2,13.98,100,1,12.96,2,1,14.17,700,1,12.86,100,1,14.24,200,2,12.73,100,1,14.25,100,1,12.71,100,1,14.40,200,2,12.50,700,1,14.48,1400,2,12.46,100,1,14.49,100,1,ARL,347605081
2025-07-17T16:21:13.029314299Z,2025-07-17T16:21:13.029148929Z,160,2,1108,A,A,10,13.40,0,0,13.40,23,1,13.27,0,0,13.65,2,1,13.11,100,1,13.72,100,1,12.98,200,2,13.98,100,1,12.96,2,1,14.17,700,1,12.86,100,1,14.24,200,2,12.73,100,1,14.25,100,1,12.71,100,1,14.33,100,1,12.50,700,1,14.40,200,2,12.46,100,1,14.48,1400,2,ARL,349364205
2025-07-17T16:21:13.029395561Z,2025-07-17T16:21:13.029229862Z,160,2,1108,C,A,10,13.40,0,0,13.40,23,1,13.27,0,0,13.65,2,1,13.11,100,1,13.72,100,1,12.98,200,2,13.98,100,1,12.96,2,1,14.17,700,1,12.86,100,1,14.24,200,2,12.73,100,1,14.25,100,1,12.71,100,1,14.33,100,1,12.50,700,1,14.40,200,2,12.46,100,1,14.48,1400,2,ARL,347605073
2025-07-17T16:21:13.029395561Z,2025-07-17T16:21:13.029229862Z,160,2,1108,A,A,10,13.40,0,0,13.40,23,1,13.27,0,0,13.65,2,1,13.11,100,1,13.72,100,1,12.98,200,2,13.98,100,1,12.96,2,1,14.17,700,1,12.86,100,1,14.24,200,2,12.73,100,1,14.25,100,1,12.71,100,1,14.33,100,1,12.50,700,1,14.40,200,2,12.46,100,1,14.48,1400,2,ARL,349364213
2025-07-17T16:21:13.029433752Z,2025-07-17T16:21:13.029267150Z,160,2,1108,C,A,10,13.40,0,0,13.40,23,1,13.27,0,0,13.65,2,1,13.11,100,1,13.72,100,1,12.98,200,2,13.98,100,1,12.96,2,1,14.24,200,2,12.86,100,1,14.25,100,1,12.73,100,1,14.33,100,1,12.71,100,1,14.40,200,2,12.50,700,1,14.48,1400,2,12.46,100,1,14.54,700,1,ARL,347717317
2025-07-17T16:21:13.029461868Z,2025-07-17T16:21:13.029296174Z,160,2,1108,C,A,10,13.40,0,0,13.40,23,1,13.27,0,0,13.65,2,1,13.11,100,1,13.72,100,1,12.98,200,2,13.98,100,1,12.96,2,1,14.24,100,1,12.86,100,1,14.25,100,1,12.73,100,1,14.33,100,1,12.71,100,1,14.40,200,2,12.50,700,1,14.48,1400,2,12.46,100,1,14.54,700,1,ARL,347760469
2025-07-17T16:21:13.029461868Z,2025-07-17T16:21:13.029296174Z,160,2,1108,A,A,10,13.40,0,0,13.40,23,1,13.27,0,0,13.65,2,1,13.11,100,1,13.72,100,1,12.98,200,2,13.98,100,1,12.96,2,1,14.24,100,1,12.86,100,1,14.25,100,1,12.73,100,1,14.33,100,1,12.71,100,1,14.40,200,2,12.50,700,1,14.48,1400,2,12.46,100,1,14.54,700,1,ARL,349364233
2025-07-17T16:21:13.029500611Z,2025-07-17T16:21:13.029335284Z,160,2,1108,A,A,10,13.40,0,0,13.40,23,1,13.27,0,0,13.65,2,1,13.11,100,1,13.72,100,1,12.98,200,2,13.98,100,1,12.96,2,1,14.24,100,1,12.86,100,1,14.25,100,1,12.73,100,1,14.33,100,1,12.71,100,1,14.40,200,2,12.50,700,1,14.41,700,1,12.46,100,1,14.48,1400,2,ARL,349364241
2025-07-17T16:21:13.033525905Z,2025-07-17T16:21:13.033360385Z,160,2,1108,C,A,10,13.40,0,0,13.40,23,1,13.27,0,0,13.65,2,1,13.11,100,1,13.72,100,1,12.98,200,2,13.98,100,1,12.96,2,1,14.25,100,1,12.86,100,1,14.33,100,1,12.73,100,1,14.40,200,2,12.71,100,1,14.41,700,1,12.50,700,1,14.48,1400,2,12.46,100,1,14.54,700,1,ARL,347605969
2025-07-17T16:21:13.033525905Z,2025-07-17T16:21:13.033360385Z,160,2,1108,A,A,10,13.40,0,0,13.40,23,1,13.27,0,0,13.65,2,1,13.11,100,1,13.72,100,1,12.98,200,2,13.98,100,1,12.96,2,1,14.25,100,1,12.86,100,1,14.33,100,1,12.73,100,1,14.40,200,2,12.71,100,1,14.41,700,1,12.50,700,1,14.48,1400,2,12.46,100,1,14.51,100,1,ARL,349364905
2025-07-17T16:21:13.041339278Z,2025-07-17T16:21:13.041173935Z,160,2,1108,C,A,10,13.40,0,0,13.40,23,1,13.27,0,0,13.65,2,1,13.11,100,1,13.98,100,1,12.98,200,2,14.25,100,1,12.96,2,1,14.33,100,1,12.86,100,1,14.40,200,2,12.73,100,1,14.41,700,1,12.71,100,1,14.48,1400,2,12.50,700,1,14.51,100,1,12.46,100,1,14.54,700,1,ARL,347605397
2025-07-17T16:21:13.041376591Z,2025-07-17T16:21:13.041211567Z,160,2,1108,C,A,10,13.40,0,0,13.40,23,1,13.27,0,0,13.65,2,1,13.11,100,1,13.98,100,1,12.98,200,2,14.25,100,1,12.96,2,1,14.33,100,1,12.86,100,1,14.40,200,2,12.73,100,1,14.48,1400,2,12.71,100,1,14.51,100,1,12.50,700,1,14.54,700,1,12.46,100,1,14.63,200,2,ARL,349364241
2025-07-17T16:21:13.041396412Z,2025-07-17T16:21:13.041231123Z,160,2,1108,A,A,10,13.40,0,0,13.40,23,1,13.27,0,0,13.65,2,1,13.11,100,1,13.98,100,1,12.98,200,2,13.99,100,1,12.96,2,1,14.25,100,1,12.86,100,1,14.33,100,1,12.73,100,1,14.40,200,2,12.71,100,1,14.48,1400,2,12.50,700,1,14.51,100,1,12.46,100,1,14.54,700,1,ARL,349365741
2025-07-17T16:21:13.041424493Z,2025-07-17T16:21:13.041258565Z,160,2,1108,A,A,10,13.40,0,0,13.40,23,1,13.27,0,0,13.65,2,1,13.11,100,1,13.98,100,1,12.98,200,2,13.99,100,1,12.96,2,1,14.25,100,1,12.86,100,1,14.33,100,1,12.73,100,1,14.40,200,2,12.71,100,1,14.48,1400,2,12.50,700,1,14.51,100,1,12.46,100,1,14.54,700,1,ARL,349365749
2025-07-17T16:21:13.041438649Z,2025-07-17T16:21:13.041270862Z,160,2,1108,C,A,10,13.40,0,0,13.40,23,1,13.27,0,0,13.65,2,1,13.11,100,1,13.98,100,1,12.98,200,2,13.99,100,1,12.96,2,1,14.25,100,1,12.86,100,1,14.33,100,1,12.73,100,1,14.40,200,2,12.71,100,1,14.48,1400,2,12.50,700,1,14.51,100,1,12.46,100,1,14.54,700,1,ARL,349364025
2025-07-17T16:21:13.042377442Z,2025-07-17T16:21:13.042212059Z,160,2,1108,A,B,10,13.40,0,0,13.40,23,1,13.27,0,0,13.65,2,1,13.11,110,2,13.98,100,1,12.98,200,2,13.99,100,1,12.96,2,1,14.25,100,1,12.86,100,1,14.33,100,1,12.73,100,1,14.40,200,2,12.71,100,1,14.48,1400,2,12.50,700,1,14.51,100,1,12.46,100,1,14.54,700,1,ARL,349365825
2025-07-17T16:21:13.046254420Z,2025-07-17T16:21:13.046088887Z,160,2,1108,C,A,10,13.40,0,0,13.40,23,1,13.27,0,0,13.65,2,1,13.11,110,2,13.98,100,1,12.98,200,2,13.99,100,1,12.96,2,1,14.25,100,1,12.86,100,1,14.33,100,1,12.73,100,1,14.40,200,2,12.71,100,1,14.48,1400,2,12.50,700,1,14.51,100,1,12.46,100,1,14.54,700,1,ARL,347605085
2025-07-17T16:21:13.046254420Z,2025-07-17T16:21:13.046088887Z,160,2,1108,A,A,10,13.40,0,0,13.40,23,1,13.27,0,0,13.65,2,1,13.11,110,2,13.98,100,1,12.98,200,2,13.99,100,1,12.96,2,1,14.25,100,1,12.86,100,1,14.33,100,1,12.73,100,1,14.40,200,2,12.71,100,1,14.48,1400,2,12.50,700,1,14.51,100,1,12.46,100,1,14.54,700,1,ARL,349366105
2025-07-17T16:21:13.046293088Z,2025-07-17T16:21:13.046127777Z,160,2,1108,C,A,10,13.40,0,0,13.40,23,1,13.27,0,0,13.65,2,1,13.11,110,2,13.98,100,1,12.98,200,2,14.25,100,1,12.96,2,1,14.33,100,1,12.86,100,1,14.40,200,2,12.73,100,1,14.48,1400,2,12.71,100,1,14.51,100,1,12.50,700,1,14.54,700,1,12.46,100,1,14.63,200,2,ARL,349365741
2025-07-17T16:21:13.046345105Z,2025-07-17T16:21:13.046179769Z,160,2,1108,A,A,10,13.40,0,0,13.40,23,1,13.27,0,0,13.65,2,1,13.11,110,2,13.98,100,1,12.98,200,2,14.22,100,1,12.96,2,1,14.25,100,1,12.86,100,1,14.33,100,1,12.73,100,1,14.40,200,2,12.71,100,1,14.48,1400,2,12.50,700,1,14.51,100,1,12.46,100,1,14.54,700,1,ARL,349366121
2025-07-17T16:21:13.051207283Z,2025-07-17T16:21:13.051041384Z,160,2,1108,C,A,10,13.40,0,0,13.40,23,1,13.27,0,0,13.98,100,1,13.11,110,2,14.22,100,1,12.98,200,2,14.25,100,1,12.96,2,1,14.33,100,1,12.86,100,1,14.40,200,2,12.73,100,1,14.48,1400,2,12.71,100,1,14.51,100,1,12.50,700,1,14.54,700,1,12.46,100,1,14.63,200,2,ARL,349094877
